setblock ~ ~ ~1 command_block 0
fill ~1 ~43 ~1 ~97 ~42 ~97 air
fill ~1 ~41 ~1 ~97 ~40 ~97 air
fill ~1 ~39 ~1 ~97 ~38 ~97 air
fill ~1 ~37 ~1 ~97 ~36 ~97 air
fill ~1 ~35 ~1 ~97 ~34 ~97 air
fill ~1 ~33 ~1 ~97 ~32 ~97 air
fill ~1 ~31 ~1 ~97 ~30 ~97 air
fill ~1 ~29 ~1 ~97 ~28 ~97 air
fill ~1 ~27 ~1 ~97 ~26 ~97 air
fill ~1 ~25 ~1 ~97 ~24 ~97 air
fill ~1 ~23 ~1 ~97 ~22 ~97 air
fill ~1 ~21 ~1 ~97 ~20 ~97 air
fill ~1 ~19 ~1 ~97 ~18 ~97 air
fill ~1 ~17 ~1 ~97 ~16 ~97 air
fill ~1 ~15 ~1 ~97 ~14 ~97 air
fill ~1 ~13 ~1 ~97 ~12 ~97 air
fill ~1 ~11 ~1 ~97 ~10 ~97 air
fill ~1 ~9 ~1 ~97 ~8 ~97 air
fill ~1 ~7 ~1 ~97 ~6 ~97 air
fill ~1 ~5 ~1 ~97 ~4 ~97 air
fill ~1 ~3 ~1 ~97 ~2 ~97 air
fill ~1 ~1 ~1 ~97 ~0 ~97 air
fill ~27 ~0 ~7 ~27 ~4 ~8 stone
fill ~71 ~0 ~7 ~72 ~4 ~8 stone
fill ~26 ~0 ~8 ~27 ~4 ~8 stone
fill ~18 ~0 ~17 ~18 ~4 ~18 stone
fill ~36 ~0 ~17 ~36 ~8 ~17 stone
fill ~80 ~0 ~17 ~81 ~4 ~18 stone
fill ~17 ~0 ~18 ~18 ~4 ~18 stone
fill ~8 ~0 ~26 ~8 ~4 ~27 stone
fill ~90 ~0 ~26 ~91 ~4 ~27 stone
fill ~7 ~0 ~27 ~8 ~4 ~27 stone
fill ~63 ~0 ~31 ~63 ~8 ~33 stone
fill ~31 ~0 ~35 ~33 ~8 ~35 stone
fill ~81 ~0 ~36 ~81 ~8 ~36 stone
fill ~58 ~0 ~38 ~58 ~8 ~38 stone
fill ~38 ~0 ~40 ~38 ~8 ~40 stone
fill ~60 ~0 ~58 ~61 ~7 ~58 stone
fill ~40 ~0 ~60 ~40 ~7 ~61 stone
fill ~17 ~0 ~62 ~17 ~8 ~62 stone
fill ~65 ~0 ~63 ~67 ~8 ~63 stone
fill ~35 ~0 ~65 ~35 ~8 ~67 stone
fill ~7 ~0 ~71 ~8 ~4 ~72 stone
fill ~91 ~0 ~71 ~91 ~4 ~72 stone
fill ~90 ~0 ~72 ~92 ~4 ~72 stone
fill ~17 ~0 ~80 ~18 ~4 ~81 stone
fill ~81 ~0 ~80 ~81 ~4 ~81 stone
fill ~62 ~0 ~81 ~62 ~8 ~81 stone
fill ~80 ~0 ~81 ~82 ~4 ~81 stone
fill ~26 ~0 ~90 ~27 ~4 ~91 stone
fill ~72 ~0 ~90 ~72 ~4 ~91 stone
fill ~71 ~0 ~91 ~73 ~4 ~91 stone
fill ~26 ~1 ~6 ~27 ~4 ~8 stone
fill ~71 ~1 ~6 ~72 ~4 ~8 stone
fill ~73 ~1 ~7 ~73 ~4 ~8 stone
fill ~25 ~1 ~8 ~28 ~4 ~8 stone
fill ~70 ~1 ~8 ~73 ~4 ~8 stone
fill ~27 ~1 ~9 ~27 ~4 ~9 stone
fill ~71 ~1 ~9 ~71 ~4 ~9 stone
fill ~17 ~1 ~16 ~18 ~4 ~18 stone
fill ~80 ~1 ~16 ~81 ~4 ~18 stone
fill ~82 ~1 ~17 ~82 ~4 ~18 stone
fill ~16 ~1 ~18 ~19 ~4 ~18 stone
fill ~79 ~1 ~18 ~82 ~4 ~18 stone
fill ~18 ~1 ~19 ~18 ~4 ~19 stone
fill ~80 ~1 ~19 ~80 ~4 ~19 stone
fill ~7 ~1 ~25 ~8 ~4 ~27 stone
fill ~90 ~1 ~25 ~91 ~4 ~27 stone
fill ~92 ~1 ~26 ~92 ~4 ~27 stone
fill ~6 ~1 ~27 ~9 ~4 ~27 stone
fill ~89 ~1 ~27 ~92 ~4 ~27 stone
fill ~8 ~1 ~28 ~8 ~4 ~28 stone
fill ~28 ~1 ~28 ~28 ~8 ~28 stone
fill ~70 ~1 ~28 ~70 ~8 ~28 stone
fill ~90 ~1 ~28 ~90 ~4 ~28 stone
fill ~64 ~1 ~31 ~64 ~9 ~32 stone
fill ~62 ~1 ~32 ~64 ~8 ~32 stone
fill ~31 ~1 ~34 ~32 ~9 ~35 stone
fill ~32 ~1 ~36 ~32 ~8 ~36 stone
fill ~57 ~1 ~38 ~58 ~8 ~38 stone
fill ~38 ~1 ~41 ~38 ~8 ~41 stone
fill ~49 ~1 ~49 ~49 ~8 ~49 stone
fill ~60 ~1 ~57 ~61 ~7 ~58 stone
fill ~41 ~1 ~60 ~41 ~7 ~61 stone
fill ~66 ~1 ~62 ~66 ~8 ~64 stone
fill ~67 ~1 ~64 ~67 ~9 ~64 stone
fill ~36 ~1 ~66 ~36 ~8 ~66 stone
fill ~34 ~1 ~67 ~35 ~9 ~67 stone
fill ~8 ~1 ~70 ~8 ~4 ~73 stone
fill ~28 ~1 ~70 ~28 ~8 ~70 stone
fill ~70 ~1 ~70 ~70 ~8 ~70 stone
fill ~90 ~1 ~70 ~90 ~4 ~73 stone
fill ~6 ~1 ~71 ~8 ~4 ~72 stone
fill ~9 ~1 ~71 ~9 ~4 ~71 stone
fill ~89 ~1 ~71 ~92 ~4 ~71 stone
fill ~91 ~1 ~73 ~91 ~4 ~73 stone
fill ~18 ~1 ~79 ~18 ~4 ~82 stone
fill ~80 ~1 ~79 ~80 ~4 ~82 stone
fill ~16 ~1 ~80 ~18 ~4 ~81 stone
fill ~19 ~1 ~80 ~19 ~4 ~80 stone
fill ~79 ~1 ~80 ~82 ~4 ~80 stone
fill ~81 ~1 ~82 ~81 ~4 ~82 stone
fill ~27 ~1 ~89 ~27 ~4 ~92 stone
fill ~71 ~1 ~89 ~71 ~4 ~92 stone
fill ~25 ~1 ~90 ~27 ~4 ~91 stone
fill ~28 ~1 ~90 ~28 ~4 ~90 stone
fill ~70 ~1 ~90 ~73 ~4 ~90 stone
fill ~72 ~1 ~92 ~72 ~4 ~92 stone
fill ~26 ~2 ~5 ~26 ~4 ~8 stone
fill ~72 ~2 ~5 ~72 ~4 ~8 stone
fill ~25 ~2 ~6 ~27 ~4 ~8 stone
fill ~73 ~2 ~6 ~73 ~4 ~8 stone
fill ~24 ~2 ~7 ~27 ~4 ~7 stone
fill ~74 ~2 ~7 ~74 ~6 ~7 stone
fill ~17 ~2 ~15 ~17 ~4 ~18 stone
fill ~81 ~2 ~15 ~81 ~4 ~18 stone
fill ~16 ~2 ~16 ~18 ~4 ~18 stone
fill ~82 ~2 ~16 ~82 ~4 ~18 stone
fill ~15 ~2 ~17 ~18 ~4 ~17 stone
fill ~83 ~2 ~17 ~83 ~6 ~17 stone
fill ~49 ~2 ~23 ~49 ~10 ~23 stone
fill ~7 ~2 ~24 ~7 ~4 ~27 stone
fill ~91 ~2 ~24 ~91 ~4 ~27 stone
fill ~6 ~2 ~25 ~8 ~4 ~27 stone
fill ~92 ~2 ~25 ~92 ~4 ~27 stone
fill ~5 ~2 ~26 ~8 ~4 ~26 stone
fill ~93 ~2 ~26 ~93 ~6 ~26 stone
fill ~29 ~2 ~28 ~29 ~8 ~28 stone
fill ~70 ~2 ~29 ~70 ~8 ~29 stone
fill ~63 ~2 ~30 ~63 ~8 ~33 stone
fill ~65 ~2 ~32 ~65 ~9 ~32 stone
fill ~32 ~2 ~33 ~32 ~8 ~36 stone
fill ~62 ~2 ~33 ~64 ~7 ~33 stone
fill ~33 ~2 ~34 ~33 ~7 ~36 stone
fill ~62 ~2 ~34 ~62 ~8 ~34 stonebrick
fill ~30 ~2 ~35 ~33 ~8 ~35 stone
fill ~34 ~2 ~36 ~34 ~8 ~36 stonebrick
fill ~56 ~2 ~37 ~58 ~7 ~37 stone
fill ~38 ~2 ~38 ~38 ~8 ~38 stonebrick
fill ~59 ~2 ~38 ~59 ~8 ~38 stone
fill ~60 ~2 ~38 ~60 ~8 ~38 stonebrick
fill ~38 ~2 ~39 ~38 ~8 ~41 stone
fill ~58 ~2 ~39 ~58 ~9 ~39 stone
fill ~39 ~2 ~40 ~39 ~9 ~40 stone
fill ~37 ~2 ~42 ~37 ~7 ~42 stone
fill ~23 ~2 ~49 ~23 ~10 ~49 stone
fill ~75 ~2 ~49 ~75 ~10 ~49 stone
fill ~61 ~2 ~56 ~61 ~7 ~58 stone
fill ~59 ~2 ~58 ~61 ~7 ~58 stone
fill ~40 ~2 ~59 ~40 ~7 ~61 stone
fill ~60 ~2 ~59 ~60 ~8 ~59 stone
fill ~38 ~2 ~60 ~38 ~8 ~60 stonebrick
fill ~39 ~2 ~60 ~41 ~8 ~60 stone
fill ~60 ~2 ~60 ~60 ~8 ~60 stonebrick
fill ~42 ~2 ~61 ~42 ~7 ~61 stone
fill ~64 ~2 ~62 ~64 ~8 ~62 stonebrick
fill ~65 ~2 ~62 ~66 ~7 ~64 stone
fill ~68 ~2 ~63 ~68 ~9 ~63 stone
fill ~36 ~2 ~64 ~36 ~8 ~64 stonebrick
fill ~34 ~2 ~65 ~35 ~8 ~67 stone
fill ~36 ~2 ~65 ~36 ~7 ~66 stone
fill ~66 ~2 ~65 ~66 ~9 ~65 stone
fill ~33 ~2 ~66 ~36 ~8 ~66 stone
fill ~35 ~2 ~68 ~35 ~9 ~68 stone
fill ~28 ~2 ~69 ~28 ~8 ~70 stone
fill ~69 ~2 ~70 ~70 ~8 ~70 stone
fill ~5 ~2 ~72 ~8 ~4 ~72 stone
fill ~93 ~2 ~72 ~93 ~8 ~72 stone
fill ~6 ~2 ~73 ~8 ~4 ~73 stone
fill ~92 ~2 ~73 ~92 ~4 ~73 stone
fill ~7 ~2 ~74 ~7 ~8 ~74 stone
fill ~91 ~2 ~74 ~91 ~6 ~74 stone
fill ~49 ~2 ~75 ~49 ~10 ~75 stone
fill ~15 ~2 ~81 ~18 ~4 ~81 stone
fill ~83 ~2 ~81 ~83 ~8 ~81 stone
fill ~16 ~2 ~82 ~18 ~4 ~82 stone
fill ~82 ~2 ~82 ~82 ~4 ~82 stone
fill ~17 ~2 ~83 ~17 ~8 ~83 stone
fill ~81 ~2 ~83 ~81 ~6 ~83 stone
fill ~24 ~2 ~91 ~27 ~4 ~91 stone
fill ~74 ~2 ~91 ~74 ~8 ~91 stone
fill ~25 ~2 ~92 ~27 ~4 ~92 stone
fill ~73 ~2 ~92 ~73 ~4 ~92 stone
fill ~26 ~2 ~93 ~26 ~8 ~93 stone
fill ~72 ~2 ~93 ~72 ~6 ~93 stone
fill ~25 ~3 ~5 ~26 ~4 ~8 stone
fill ~74 ~3 ~6 ~74 ~5 ~7 stone
fill ~29 ~3 ~8 ~29 ~4 ~8 stone
fill ~69 ~3 ~8 ~73 ~4 ~8 stone
fill ~28 ~3 ~9 ~28 ~4 ~9 stone
fill ~70 ~3 ~9 ~71 ~4 ~9 stone
fill ~27 ~3 ~10 ~27 ~4 ~10 stone
fill ~71 ~3 ~10 ~71 ~4 ~10 stone
fill ~16 ~3 ~15 ~17 ~4 ~18 stone
fill ~62 ~3 ~16 ~62 ~8 ~16 stone
fill ~83 ~3 ~16 ~83 ~5 ~17 stone
fill ~20 ~3 ~18 ~20 ~4 ~18 stone
fill ~36 ~3 ~18 ~36 ~8 ~18 stone
fill ~78 ~3 ~18 ~82 ~4 ~18 stone
fill ~19 ~3 ~19 ~19 ~4 ~19 stone
fill ~79 ~3 ~19 ~80 ~4 ~19 stone
fill ~18 ~3 ~20 ~18 ~4 ~20 stone
fill ~80 ~3 ~20 ~80 ~4 ~20 stone
fill ~6 ~3 ~24 ~7 ~4 ~27 stone
fill ~93 ~3 ~25 ~93 ~5 ~26 stone
fill ~10 ~3 ~27 ~10 ~4 ~27 stone
fill ~27 ~3 ~27 ~27 ~8 ~27 stone
fill ~63 ~3 ~27 ~63 ~8 ~34 stone
fill ~71 ~3 ~27 ~71 ~8 ~27 stone
fill ~88 ~3 ~27 ~92 ~4 ~27 stone
fill ~9 ~3 ~28 ~9 ~4 ~28 stone
fill ~62 ~3 ~28 ~63 ~7 ~33 stone
fill ~69 ~3 ~28 ~70 ~8 ~28 stone
fill ~89 ~3 ~28 ~90 ~4 ~28 stone
fill ~8 ~3 ~29 ~8 ~4 ~29 stone
fill ~28 ~3 ~29 ~28 ~8 ~29 stone
fill ~64 ~3 ~29 ~64 ~9 ~33 stone
fill ~90 ~3 ~29 ~90 ~4 ~29 stone
fill ~61 ~3 ~30 ~65 ~9 ~31 stone
fill ~66 ~3 ~31 ~66 ~9 ~32 stone
fill ~31 ~3 ~32 ~32 ~8 ~36 stone
fill ~30 ~3 ~33 ~33 ~7 ~36 stone
fill ~65 ~3 ~33 ~65 ~9 ~33 stone
fill ~29 ~3 ~34 ~33 ~7 ~36 stone
fill ~27 ~3 ~35 ~34 ~8 ~35 stone
fill ~35 ~3 ~35 ~35 ~9 ~35 stonebrick
fill ~56 ~3 ~35 ~57 ~7 ~38 stone
fill ~63 ~3 ~35 ~63 ~9 ~35 stonebrick
fill ~16 ~3 ~36 ~16 ~8 ~36 stone
fill ~28 ~3 ~36 ~33 ~7 ~36 stone
fill ~55 ~3 ~36 ~58 ~7 ~37 stone
fill ~80 ~3 ~36 ~81 ~8 ~36 stone
fill ~30 ~3 ~37 ~31 ~9 ~37 stone
fill ~54 ~3 ~37 ~58 ~7 ~37 stone
fill ~59 ~3 ~37 ~59 ~7 ~37 stonebrick
fill ~39 ~3 ~38 ~42 ~8 ~38 stone
fill ~37 ~3 ~39 ~37 ~7 ~39 stonebrick
fill ~39 ~3 ~39 ~39 ~9 ~41 stone
fill ~40 ~3 ~39 ~40 ~9 ~39 stone
fill ~57 ~3 ~39 ~60 ~8 ~39 stone
fill ~36 ~3 ~40 ~39 ~7 ~41 stone
fill ~59 ~3 ~40 ~60 ~8 ~40 stone
fill ~35 ~3 ~41 ~38 ~7 ~42 stone
fill ~60 ~3 ~41 ~60 ~8 ~42 stone
fill ~36 ~3 ~43 ~37 ~7 ~43 stone
fill ~37 ~3 ~44 ~37 ~7 ~44 stone
fill ~49 ~3 ~48 ~49 ~8 ~49 stone
fill ~61 ~3 ~54 ~61 ~7 ~58 stone
fill ~62 ~3 ~55 ~62 ~7 ~58 stone
fill ~38 ~3 ~56 ~38 ~8 ~59 stone
fill ~60 ~3 ~56 ~63 ~7 ~57 stone
fill ~59 ~3 ~57 ~63 ~7 ~57 stone
fill ~39 ~3 ~58 ~39 ~8 ~60 stone
fill ~41 ~3 ~59 ~41 ~7 ~63 stone
fill ~58 ~3 ~59 ~59 ~8 ~60 stone
fill ~61 ~3 ~59 ~61 ~7 ~59 stonebrick
fill ~42 ~3 ~60 ~42 ~7 ~63 stone
fill ~56 ~3 ~60 ~59 ~8 ~60 stone
fill ~39 ~3 ~61 ~39 ~7 ~61 stonebrick
fill ~43 ~3 ~61 ~44 ~7 ~61 stone
fill ~67 ~3 ~61 ~68 ~9 ~65 stone
fill ~18 ~3 ~62 ~18 ~8 ~62 stone
fill ~40 ~3 ~62 ~43 ~7 ~62 stone
fill ~69 ~3 ~62 ~70 ~9 ~63 stone
fill ~82 ~3 ~62 ~82 ~8 ~62 stone
fill ~35 ~3 ~63 ~35 ~9 ~63 stonebrick
fill ~63 ~3 ~63 ~63 ~9 ~63 stonebrick
fill ~64 ~3 ~63 ~71 ~8 ~63 stone
fill ~35 ~3 ~64 ~35 ~8 ~71 stone
fill ~69 ~3 ~64 ~69 ~9 ~64 stone
fill ~33 ~3 ~65 ~36 ~7 ~68 stone
fill ~65 ~3 ~65 ~68 ~9 ~65 stone
fill ~32 ~3 ~66 ~36 ~8 ~67 stone
fill ~66 ~3 ~66 ~67 ~9 ~66 stone
fill ~37 ~3 ~67 ~37 ~9 ~68 stone
fill ~8 ~3 ~69 ~8 ~4 ~73 stone
fill ~34 ~3 ~69 ~36 ~9 ~69 stone
fill ~70 ~3 ~69 ~70 ~8 ~70 stone
fill ~90 ~3 ~69 ~90 ~4 ~73 stone
fill ~9 ~3 ~70 ~9 ~4 ~71 stone
fill ~29 ~3 ~70 ~29 ~8 ~70 stone
fill ~36 ~3 ~70 ~36 ~9 ~70 stone
fill ~89 ~3 ~70 ~90 ~4 ~71 stone
fill ~10 ~3 ~71 ~10 ~4 ~71 stone
fill ~27 ~3 ~71 ~27 ~8 ~71 stone
fill ~71 ~3 ~71 ~71 ~8 ~71 stone
fill ~88 ~3 ~71 ~92 ~4 ~71 stone
fill ~5 ~3 ~73 ~8 ~4 ~73 stone
fill ~92 ~3 ~74 ~92 ~5 ~74 stone
fill ~18 ~3 ~78 ~18 ~4 ~82 stone
fill ~80 ~3 ~78 ~80 ~4 ~82 stone
fill ~19 ~3 ~79 ~19 ~4 ~80 stone
fill ~79 ~3 ~79 ~80 ~4 ~80 stone
fill ~20 ~3 ~80 ~20 ~4 ~80 stone
fill ~62 ~3 ~80 ~62 ~8 ~81 stone
fill ~78 ~3 ~80 ~82 ~4 ~80 stone
fill ~15 ~3 ~82 ~18 ~4 ~82 stone
fill ~36 ~3 ~82 ~36 ~8 ~82 stone
fill ~82 ~3 ~83 ~82 ~5 ~83 stone
fill ~27 ~3 ~88 ~27 ~4 ~92 stone
fill ~71 ~3 ~88 ~71 ~4 ~92 stone
fill ~28 ~3 ~89 ~28 ~4 ~90 stone
fill ~70 ~3 ~89 ~71 ~4 ~90 stone
fill ~29 ~3 ~90 ~29 ~4 ~90 stone
fill ~69 ~3 ~90 ~73 ~4 ~90 stone
fill ~24 ~3 ~92 ~27 ~4 ~92 stone
fill ~73 ~3 ~93 ~73 ~5 ~93 stone
fill ~26 ~4 ~4 ~26 ~7 ~4 stonebrick
fill ~72 ~4 ~4 ~72 ~7 ~4 stonebrick
fill ~27 ~4 ~5 ~27 ~4 ~10 stone
fill ~71 ~4 ~5 ~73 ~4 ~8 stone
fill ~24 ~4 ~6 ~27 ~4 ~8 stone
fill ~23 ~4 ~7 ~23 ~7 ~7 stonebrick
fill ~28 ~4 ~7 ~28 ~4 ~10 stone
fill ~70 ~4 ~7 ~74 ~4 ~8 stone
fill ~75 ~4 ~7 ~75 ~7 ~7 stonebrick
fill ~26 ~4 ~9 ~29 ~4 ~9 stone
fill ~69 ~4 ~9 ~72 ~4 ~9 stone
fill ~70 ~4 ~10 ~70 ~8 ~10 stone
fill ~17 ~4 ~14 ~17 ~7 ~14 stonebrick
fill ~81 ~4 ~14 ~81 ~7 ~14 stonebrick
fill ~18 ~4 ~15 ~18 ~4 ~20 stone
fill ~80 ~4 ~15 ~82 ~4 ~18 stone
fill ~15 ~4 ~16 ~18 ~4 ~18 stone
fill ~14 ~4 ~17 ~14 ~7 ~17 stonebrick
fill ~19 ~4 ~17 ~19 ~4 ~20 stone
fill ~35 ~4 ~17 ~37 ~8 ~17 stone
fill ~62 ~4 ~17 ~62 ~8 ~17 stone
fill ~79 ~4 ~17 ~83 ~4 ~18 stone
fill ~84 ~4 ~17 ~84 ~7 ~17 stonebrick
fill ~17 ~4 ~19 ~20 ~4 ~19 stone
fill ~78 ~4 ~19 ~81 ~4 ~19 stone
fill ~79 ~4 ~20 ~79 ~8 ~20 stone
fill ~62 ~4 ~21 ~62 ~8 ~32 stone
fill ~7 ~4 ~23 ~7 ~7 ~23 stonebrick
fill ~91 ~4 ~23 ~91 ~7 ~23 stonebrick
fill ~8 ~4 ~24 ~8 ~4 ~29 stone
fill ~35 ~4 ~24 ~35 ~9 ~32 stone
fill ~63 ~4 ~24 ~63 ~8 ~34 stone
fill ~90 ~4 ~24 ~92 ~4 ~27 stone
fill ~5 ~4 ~25 ~8 ~4 ~27 stone
fill ~34 ~4 ~25 ~35 ~9 ~32 stone
fill ~4 ~4 ~26 ~4 ~7 ~26 stonebrick
fill ~9 ~4 ~26 ~9 ~4 ~29 stone
fill ~61 ~4 ~26 ~64 ~9 ~31 stone
fill ~89 ~4 ~26 ~93 ~4 ~27 stone
fill ~94 ~4 ~26 ~94 ~7 ~26 stonebrick
fill ~33 ~4 ~27 ~35 ~9 ~32 stone
fill ~65 ~4 ~27 ~65 ~9 ~34 stone
fill ~70 ~4 ~27 ~70 ~8 ~29 stone
fill ~7 ~4 ~28 ~10 ~4 ~28 stone
fill ~27 ~4 ~28 ~29 ~8 ~28 stone
fill ~32 ~4 ~28 ~36 ~8 ~32 stone
fill ~66 ~4 ~28 ~67 ~8 ~36 stone
fill ~88 ~4 ~28 ~91 ~4 ~28 stone
fill ~29 ~4 ~29 ~32 ~8 ~38 stone
fill ~60 ~4 ~29 ~66 ~9 ~31 stone
fill ~68 ~4 ~29 ~69 ~8 ~36 stone
fill ~89 ~4 ~29 ~89 ~8 ~29 stone
fill ~28 ~4 ~31 ~32 ~8 ~37 stone
fill ~60 ~4 ~32 ~70 ~7 ~33 stone
fill ~27 ~4 ~33 ~31 ~9 ~37 stone
fill ~34 ~4 ~33 ~34 ~8 ~35 stone
fill ~35 ~4 ~33 ~35 ~8 ~33 stone
fill ~58 ~4 ~33 ~71 ~7 ~33 stone
fill ~26 ~4 ~34 ~31 ~9 ~37 stone
fill ~56 ~4 ~34 ~58 ~7 ~39 stone
fill ~59 ~4 ~34 ~60 ~8 ~34 stone
fill ~61 ~4 ~34 ~62 ~7 ~34 stonebrick
fill ~64 ~4 ~34 ~73 ~9 ~34 stone
fill ~24 ~4 ~35 ~31 ~9 ~36 stone
fill ~54 ~4 ~35 ~58 ~7 ~37 stone
fill ~59 ~4 ~35 ~59 ~8 ~35 stone
fill ~65 ~4 ~35 ~74 ~8 ~35 stone
fill ~81 ~4 ~35 ~81 ~8 ~37 stone
fill ~17 ~4 ~36 ~17 ~8 ~36 stone
fill ~21 ~4 ~36 ~32 ~8 ~36 stone
fill ~53 ~4 ~36 ~58 ~7 ~37 stone
fill ~70 ~4 ~36 ~70 ~9 ~36 stone
fill ~33 ~4 ~37 ~33 ~7 ~40 stone
fill ~34 ~4 ~37 ~34 ~7 ~37 stonebrick
fill ~39 ~4 ~37 ~39 ~7 ~37 stonebrick
fill ~40 ~4 ~37 ~41 ~7 ~40 stone
fill ~34 ~4 ~38 ~34 ~8 ~42 stone
fill ~43 ~4 ~38 ~45 ~8 ~38 stone
fill ~55 ~4 ~38 ~59 ~8 ~38 stone
fill ~35 ~4 ~39 ~35 ~8 ~44 stone
fill ~42 ~4 ~39 ~43 ~9 ~39 stone
fill ~61 ~4 ~39 ~61 ~7 ~39 stonebrick
fill ~57 ~4 ~40 ~61 ~7 ~40 stone
fill ~40 ~4 ~41 ~40 ~9 ~41 stone
fill ~58 ~4 ~41 ~61 ~7 ~41 stone
fill ~39 ~4 ~42 ~39 ~9 ~42 stone
fill ~59 ~4 ~42 ~60 ~8 ~43 stone
fill ~38 ~4 ~43 ~38 ~8 ~43 stone
fill ~36 ~4 ~44 ~37 ~7 ~45 stone
setblock ~44 ~4 ~44 stone 4
setblock ~54 ~4 ~44 stone 4
fill ~60 ~4 ~44 ~60 ~8 ~45 stone
fill ~48 ~4 ~49 ~50 ~8 ~49 stone
fill ~38 ~4 ~53 ~38 ~8 ~59 stone
fill ~61 ~4 ~53 ~62 ~7 ~58 stone
setblock ~44 ~4 ~54 stone 4
setblock ~54 ~4 ~54 stone 4
fill ~63 ~4 ~54 ~63 ~8 ~59 stone
fill ~39 ~4 ~55 ~39 ~9 ~59 stone
fill ~60 ~4 ~55 ~63 ~7 ~58 stone
fill ~59 ~4 ~56 ~64 ~7 ~58 stone
fill ~37 ~4 ~57 ~40 ~7 ~58 stone
fill ~58 ~4 ~57 ~64 ~7 ~58 stone
fill ~41 ~4 ~58 ~41 ~7 ~64 stone
fill ~57 ~4 ~58 ~65 ~7 ~58 stone
fill ~37 ~4 ~59 ~37 ~7 ~59 stonebrick
fill ~42 ~4 ~59 ~42 ~7 ~64 stone
fill ~55 ~4 ~59 ~59 ~8 ~60 stone
fill ~64 ~4 ~59 ~65 ~8 ~60 stone
fill ~43 ~4 ~60 ~43 ~7 ~63 stone
fill ~53 ~4 ~60 ~59 ~8 ~60 stone
fill ~66 ~4 ~60 ~69 ~8 ~69 stone
fill ~17 ~4 ~61 ~17 ~8 ~63 stone
fill ~45 ~4 ~61 ~45 ~7 ~62 stone
fill ~57 ~4 ~61 ~58 ~7 ~61 stone
fill ~59 ~4 ~61 ~59 ~7 ~61 stonebrick
fill ~64 ~4 ~61 ~64 ~7 ~62 stonebrick
fill ~65 ~4 ~61 ~72 ~7 ~64 stone
fill ~28 ~4 ~62 ~32 ~8 ~66 stone
fill ~44 ~4 ~62 ~45 ~7 ~62 stone
fill ~73 ~4 ~62 ~77 ~8 ~62 stone
fill ~81 ~4 ~62 ~82 ~8 ~62 stone
fill ~24 ~4 ~63 ~32 ~9 ~63 stone
fill ~33 ~4 ~63 ~33 ~8 ~71 stone
fill ~39 ~4 ~63 ~44 ~8 ~63 stone
fill ~73 ~4 ~63 ~74 ~9 ~63 stone
fill ~25 ~4 ~64 ~34 ~9 ~64 stone
fill ~37 ~4 ~64 ~37 ~7 ~64 stonebrick
fill ~38 ~4 ~64 ~38 ~8 ~69 stone
fill ~39 ~4 ~64 ~42 ~10 ~64 stone
fill ~64 ~4 ~64 ~64 ~9 ~73 stone
fill ~27 ~4 ~65 ~40 ~7 ~65 stone
fill ~63 ~4 ~65 ~63 ~8 ~74 stone
fill ~70 ~4 ~65 ~70 ~8 ~67 stone
fill ~71 ~4 ~65 ~71 ~9 ~65 stone
fill ~37 ~4 ~66 ~38 ~8 ~69 stone
fill ~62 ~4 ~66 ~66 ~8 ~70 stone
fill ~29 ~4 ~67 ~38 ~8 ~69 stone
fill ~9 ~4 ~69 ~9 ~8 ~69 stone
fill ~89 ~4 ~69 ~90 ~4 ~72 stone
fill ~7 ~4 ~70 ~8 ~4 ~74 stone
fill ~10 ~4 ~70 ~10 ~6 ~70 stone
fill ~31 ~4 ~70 ~37 ~8 ~70 stone
fill ~71 ~4 ~70 ~71 ~8 ~71 stone
fill ~88 ~4 ~70 ~91 ~4 ~71 stone
fill ~5 ~4 ~71 ~8 ~4 ~73 stone
fill ~28 ~4 ~71 ~28 ~8 ~71 stone
fill ~34 ~4 ~71 ~37 ~9 ~72 stone
fill ~65 ~4 ~71 ~65 ~9 ~71 stone
fill ~93 ~4 ~71 ~93 ~8 ~72 stone
fill ~4 ~4 ~72 ~4 ~7 ~72 stonebrick
setblock ~9 ~4 ~72 stone
fill ~94 ~4 ~72 ~94 ~7 ~72 stonebrick
fill ~35 ~4 ~73 ~36 ~9 ~74 stone
fill ~93 ~4 ~73 ~93 ~5 ~73 stone
fill ~6 ~4 ~74 ~8 ~5 ~74 stone
fill ~90 ~4 ~74 ~92 ~5 ~74 stone
fill ~7 ~4 ~75 ~7 ~7 ~75 stonebrick
fill ~36 ~4 ~75 ~36 ~8 ~77 stone
fill ~91 ~4 ~75 ~91 ~7 ~75 stonebrick
fill ~19 ~4 ~78 ~19 ~8 ~78 stone
fill ~79 ~4 ~78 ~80 ~4 ~81 stone
fill ~17 ~4 ~79 ~18 ~4 ~83 stone
fill ~20 ~4 ~79 ~20 ~6 ~79 stone
fill ~78 ~4 ~79 ~81 ~4 ~80 stone
fill ~15 ~4 ~80 ~18 ~4 ~82 stone
fill ~83 ~4 ~80 ~83 ~8 ~81 stone
fill ~14 ~4 ~81 ~14 ~7 ~81 stonebrick
setblock ~19 ~4 ~81 stone
fill ~36 ~4 ~81 ~36 ~8 ~82 stone
fill ~61 ~4 ~81 ~63 ~8 ~81 stone
fill ~84 ~4 ~81 ~84 ~7 ~81 stonebrick
fill ~83 ~4 ~82 ~83 ~5 ~82 stone
fill ~16 ~4 ~83 ~18 ~5 ~83 stone
fill ~80 ~4 ~83 ~82 ~5 ~83 stone
fill ~17 ~4 ~84 ~17 ~7 ~84 stonebrick
fill ~81 ~4 ~84 ~81 ~7 ~84 stonebrick
fill ~28 ~4 ~88 ~28 ~8 ~88 stone
fill ~70 ~4 ~88 ~71 ~4 ~91 stone
fill ~26 ~4 ~89 ~27 ~4 ~93 stone
fill ~29 ~4 ~89 ~29 ~6 ~89 stone
fill ~69 ~4 ~89 ~72 ~4 ~90 stone
fill ~24 ~4 ~90 ~27 ~4 ~92 stone
fill ~74 ~4 ~90 ~74 ~8 ~91 stone
fill ~23 ~4 ~91 ~23 ~7 ~91 stonebrick
setblock ~28 ~4 ~91 stone
fill ~75 ~4 ~91 ~75 ~7 ~91 stonebrick
fill ~74 ~4 ~92 ~74 ~5 ~92 stone
fill ~25 ~4 ~93 ~27 ~5 ~93 stone
fill ~71 ~4 ~93 ~73 ~5 ~93 stone
fill ~26 ~4 ~94 ~26 ~7 ~94 stonebrick
fill ~72 ~4 ~94 ~72 ~7 ~94 stonebrick
fill ~28 ~5 ~4 ~28 ~6 ~4 leaves 10
fill ~70 ~5 ~4 ~70 ~6 ~4 leaves 10
fill ~25 ~5 ~5 ~27 ~5 ~5 stone
fill ~71 ~5 ~5 ~72 ~8 ~5 stone
setblock ~73 ~5 ~5 stone
fill ~24 ~5 ~6 ~24 ~5 ~8 stone
setblock ~25 ~5 ~6 double_stone_slab
fill ~26 ~5 ~6 ~27 ~5 ~8 stone_slab
setblock ~28 ~5 ~6 stone
fill ~70 ~5 ~6 ~70 ~8 ~6 stone
fill ~71 ~5 ~6 ~72 ~5 ~8 stone_slab
setblock ~73 ~5 ~6 double_stone_slab
fill ~25 ~5 ~7 ~27 ~5 ~8 stone_slab
setblock ~28 ~5 ~7 iron_ore
setblock ~70 ~5 ~7 iron_ore
fill ~73 ~5 ~7 ~73 ~5 ~8 stone_slab
fill ~28 ~5 ~8 ~28 ~5 ~9 stone_slab
setblock ~29 ~5 ~8 double_stone_slab
fill ~30 ~5 ~8 ~30 ~8 ~8 stone
fill ~68 ~5 ~8 ~68 ~8 ~8 stone
fill ~70 ~5 ~8 ~73 ~5 ~8 stone_slab
fill ~74 ~5 ~8 ~74 ~8 ~8 stone
fill ~23 ~5 ~9 ~23 ~6 ~9 leaves 10
fill ~25 ~5 ~9 ~25 ~8 ~9 stone
setblock ~26 ~5 ~9 iron_ore
fill ~27 ~5 ~9 ~28 ~5 ~9 stone_slab
fill ~29 ~5 ~9 ~29 ~8 ~9 stone
fill ~69 ~5 ~9 ~69 ~6 ~9 stone
fill ~70 ~5 ~9 ~71 ~5 ~9 stone_slab
setblock ~72 ~5 ~9 iron_ore
setblock ~73 ~5 ~9 stone
fill ~75 ~5 ~9 ~75 ~6 ~9 leaves 10
fill ~28 ~5 ~10 ~28 ~6 ~10 stone
setblock ~71 ~5 ~10 double_stone_slab
fill ~27 ~5 ~11 ~27 ~8 ~11 stone
fill ~71 ~5 ~11 ~71 ~8 ~11 stone
fill ~19 ~5 ~14 ~19 ~6 ~14 leaves 10
fill ~79 ~5 ~14 ~79 ~6 ~14 leaves 10
fill ~16 ~5 ~15 ~18 ~5 ~15 stone
fill ~80 ~5 ~15 ~81 ~8 ~15 stone
setblock ~82 ~5 ~15 stone
fill ~15 ~5 ~16 ~15 ~5 ~18 stone
setblock ~16 ~5 ~16 double_stone_slab
fill ~17 ~5 ~16 ~18 ~5 ~18 stone_slab
setblock ~19 ~5 ~16 stone
fill ~36 ~5 ~16 ~36 ~8 ~32 stone
fill ~61 ~5 ~16 ~62 ~8 ~16 stone
fill ~79 ~5 ~16 ~79 ~8 ~16 stone
fill ~80 ~5 ~16 ~81 ~5 ~18 stone_slab
setblock ~82 ~5 ~16 double_stone_slab
fill ~16 ~5 ~17 ~18 ~5 ~18 stone_slab
setblock ~19 ~5 ~17 iron_ore
setblock ~79 ~5 ~17 iron_ore
fill ~82 ~5 ~17 ~82 ~5 ~18 stone_slab
fill ~19 ~5 ~18 ~19 ~5 ~19 stone_slab
setblock ~20 ~5 ~18 double_stone_slab
fill ~21 ~5 ~18 ~21 ~8 ~18 stone
fill ~35 ~5 ~18 ~36 ~8 ~18 stone
fill ~62 ~5 ~18 ~62 ~8 ~32 stone
fill ~77 ~5 ~18 ~77 ~8 ~18 stone
fill ~79 ~5 ~18 ~82 ~5 ~18 stone_slab
fill ~83 ~5 ~18 ~83 ~8 ~18 stone
fill ~14 ~5 ~19 ~14 ~6 ~19 leaves 10
fill ~16 ~5 ~19 ~16 ~8 ~19 stone
setblock ~17 ~5 ~19 iron_ore
fill ~18 ~5 ~19 ~19 ~5 ~19 stone_slab
fill ~20 ~5 ~19 ~20 ~8 ~19 stone
fill ~78 ~5 ~19 ~78 ~6 ~19 stone
fill ~79 ~5 ~19 ~80 ~5 ~19 stone_slab
setblock ~81 ~5 ~19 iron_ore
setblock ~82 ~5 ~19 stone
fill ~84 ~5 ~19 ~84 ~6 ~19 leaves 10
fill ~19 ~5 ~20 ~19 ~6 ~20 stone
fill ~35 ~5 ~20 ~36 ~8 ~32 stone
setblock ~80 ~5 ~20 double_stone_slab
fill ~18 ~5 ~21 ~18 ~8 ~21 stone
fill ~80 ~5 ~21 ~80 ~8 ~21 stone
fill ~61 ~5 ~22 ~63 ~8 ~32 stone
fill ~9 ~5 ~23 ~9 ~6 ~23 leaves 10
fill ~34 ~5 ~23 ~36 ~9 ~31 stone
fill ~48 ~5 ~23 ~50 ~10 ~23 stone
fill ~89 ~5 ~23 ~89 ~6 ~23 leaves 10
fill ~6 ~5 ~24 ~8 ~5 ~24 stone
fill ~64 ~5 ~24 ~64 ~9 ~34 stone
fill ~90 ~5 ~24 ~91 ~8 ~24 stone
setblock ~92 ~5 ~24 stone
fill ~5 ~5 ~25 ~5 ~5 ~27 stone
setblock ~6 ~5 ~25 double_stone_slab
fill ~7 ~5 ~25 ~8 ~5 ~27 stone_slab
setblock ~9 ~5 ~25 stone
fill ~33 ~5 ~25 ~36 ~9 ~31 stone
fill ~60 ~5 ~25 ~65 ~9 ~31 stone
fill ~89 ~5 ~25 ~89 ~8 ~25 stone
fill ~90 ~5 ~25 ~91 ~5 ~27 stone_slab
setblock ~92 ~5 ~25 double_stone_slab
fill ~6 ~5 ~26 ~8 ~5 ~27 stone_slab
setblock ~9 ~5 ~26 iron_ore
fill ~32 ~5 ~26 ~37 ~9 ~31 stone
fill ~66 ~5 ~26 ~66 ~8 ~38 stone
setblock ~89 ~5 ~26 iron_ore
fill ~92 ~5 ~26 ~92 ~5 ~27 stone_slab
fill ~9 ~5 ~27 ~9 ~5 ~28 stone_slab
setblock ~10 ~5 ~27 double_stone_slab
fill ~11 ~5 ~27 ~11 ~8 ~27 stone
fill ~28 ~5 ~27 ~28 ~8 ~38 stone
fill ~31 ~5 ~27 ~37 ~8 ~32 stone
fill ~67 ~5 ~27 ~68 ~8 ~38 stone
fill ~69 ~5 ~27 ~70 ~8 ~37 stone
fill ~87 ~5 ~27 ~87 ~8 ~27 stone
fill ~89 ~5 ~27 ~92 ~5 ~27 stone_slab
fill ~93 ~5 ~27 ~93 ~8 ~27 stone
fill ~4 ~5 ~28 ~4 ~6 ~28 leaves 10
fill ~6 ~5 ~28 ~6 ~8 ~28 stone
setblock ~7 ~5 ~28 iron_ore
fill ~8 ~5 ~28 ~9 ~5 ~28 stone_slab
fill ~10 ~5 ~28 ~10 ~8 ~28 stone
fill ~30 ~5 ~28 ~37 ~8 ~32 stone
fill ~71 ~5 ~28 ~71 ~8 ~28 stone
fill ~88 ~5 ~28 ~88 ~6 ~28 stone
fill ~89 ~5 ~28 ~90 ~5 ~28 stone_slab
setblock ~91 ~5 ~28 iron_ore
setblock ~92 ~5 ~28 stone
fill ~94 ~5 ~28 ~94 ~6 ~28 leaves 10
fill ~9 ~5 ~29 ~9 ~6 ~29 stone
fill ~27 ~5 ~29 ~32 ~8 ~38 stone
setblock ~90 ~5 ~29 double_stone_slab
fill ~8 ~5 ~30 ~8 ~8 ~30 stone
fill ~38 ~5 ~30 ~38 ~9 ~32 stone
fill ~55 ~5 ~30 ~55 ~7 ~30 leaves 10
fill ~59 ~5 ~30 ~70 ~8 ~32 stone
fill ~90 ~5 ~30 ~90 ~8 ~30 stone
fill ~71 ~5 ~31 ~71 ~8 ~37 stone
fill ~26 ~5 ~32 ~31 ~9 ~38 stone
fill ~58 ~5 ~32 ~72 ~7 ~33 stone
fill ~25 ~5 ~33 ~31 ~9 ~38 stone
fill ~36 ~5 ~33 ~37 ~7 ~33 stone
fill ~39 ~5 ~33 ~39 ~10 ~34 stone
fill ~55 ~5 ~33 ~58 ~7 ~41 stone
fill ~73 ~5 ~33 ~73 ~9 ~36 stone
fill ~24 ~5 ~34 ~31 ~9 ~37 stone
fill ~35 ~5 ~34 ~35 ~8 ~34 stone
fill ~36 ~5 ~34 ~37 ~7 ~34 stonebrick
fill ~40 ~5 ~34 ~41 ~7 ~43 stone
fill ~53 ~5 ~34 ~58 ~7 ~40 stone
fill ~74 ~5 ~34 ~75 ~9 ~36 stone
fill ~22 ~5 ~35 ~32 ~8 ~37 stone
setblock ~38 ~5 ~35 stonebrick 2
fill ~39 ~5 ~35 ~42 ~8 ~35 stone
fill ~50 ~5 ~35 ~58 ~7 ~37 stone
setblock ~60 ~5 ~35 stonebrick
fill ~64 ~5 ~35 ~78 ~8 ~35 stone
fill ~80 ~5 ~35 ~81 ~8 ~36 stone
fill ~18 ~5 ~36 ~32 ~8 ~36 stone
fill ~42 ~5 ~36 ~44 ~7 ~40 stone
fill ~48 ~5 ~36 ~58 ~7 ~37 stone
fill ~59 ~5 ~36 ~59 ~7 ~37 stonebrick
fill ~64 ~5 ~36 ~64 ~7 ~37 stonebrick
fill ~65 ~5 ~36 ~82 ~7 ~36 stone
fill ~16 ~5 ~37 ~16 ~9 ~37 stone
fill ~45 ~5 ~37 ~58 ~7 ~37 stone
fill ~65 ~5 ~37 ~72 ~7 ~37 stone
setblock ~35 ~5 ~38 stonebrick
fill ~46 ~5 ~38 ~47 ~7 ~39 stone
fill ~48 ~5 ~38 ~48 ~7 ~38 stone
fill ~51 ~5 ~38 ~59 ~7 ~38 stone
setblock ~63 ~5 ~38 stonebrick 2
fill ~30 ~5 ~39 ~34 ~10 ~39 stone
fill ~36 ~5 ~39 ~37 ~7 ~39 stonebrick
fill ~45 ~5 ~39 ~47 ~7 ~39 stone
fill ~63 ~5 ~39 ~63 ~8 ~42 stone
fill ~64 ~5 ~39 ~64 ~10 ~41 stone
fill ~65 ~5 ~39 ~65 ~10 ~39 stone
fill ~32 ~5 ~40 ~44 ~7 ~40 stone
fill ~62 ~5 ~40 ~64 ~7 ~41 stone
fill ~33 ~5 ~41 ~41 ~7 ~43 stone
fill ~42 ~5 ~41 ~42 ~9 ~41 stone
fill ~57 ~5 ~42 ~63 ~7 ~42 stone
fill ~30 ~5 ~43 ~30 ~7 ~43 leaves 10
fill ~58 ~5 ~43 ~62 ~7 ~44 stone
fill ~34 ~5 ~44 ~38 ~7 ~46 stone
fill ~39 ~5 ~44 ~40 ~8 ~45 stone
setblock ~44 ~5 ~44 stone 3
setblock ~54 ~5 ~44 stone 3
fill ~59 ~5 ~45 ~61 ~7 ~47 stone
fill ~35 ~5 ~47 ~37 ~7 ~48 stone
fill ~38 ~5 ~47 ~38 ~7 ~47 stone
fill ~62 ~5 ~47 ~62 ~7 ~58 stone
fill ~23 ~5 ~48 ~23 ~10 ~50 stone
fill ~48 ~5 ~48 ~49 ~8 ~49 stone
fill ~60 ~5 ~48 ~62 ~7 ~48 stone
fill ~75 ~5 ~48 ~75 ~10 ~50 stone
fill ~36 ~5 ~49 ~37 ~7 ~51 stone
fill ~61 ~5 ~49 ~63 ~7 ~58 stone
fill ~38 ~5 ~50 ~38 ~7 ~59 stone
fill ~49 ~5 ~50 ~49 ~8 ~50 stone
fill ~39 ~5 ~51 ~39 ~7 ~60 stone
fill ~60 ~5 ~51 ~63 ~7 ~58 stone
fill ~37 ~5 ~52 ~39 ~7 ~58 stone
fill ~58 ~5 ~53 ~64 ~7 ~58 stone
fill ~36 ~5 ~54 ~40 ~7 ~58 stone
setblock ~44 ~5 ~54 stone 3
setblock ~54 ~5 ~54 stone 3
fill ~57 ~5 ~55 ~65 ~7 ~58 stone
fill ~68 ~5 ~55 ~68 ~7 ~55 leaves 10
fill ~35 ~5 ~56 ~41 ~7 ~58 stone
fill ~34 ~5 ~57 ~43 ~7 ~58 stone
fill ~56 ~5 ~57 ~58 ~7 ~63 stone
fill ~44 ~5 ~58 ~45 ~7 ~64 stone
fill ~54 ~5 ~58 ~58 ~7 ~62 stone
fill ~66 ~5 ~58 ~66 ~8 ~72 stone
fill ~33 ~5 ~59 ~35 ~8 ~59 stone
fill ~43 ~5 ~59 ~45 ~7 ~64 stone
fill ~51 ~5 ~59 ~58 ~7 ~61 stone
fill ~62 ~5 ~59 ~62 ~7 ~59 stonebrick
fill ~67 ~5 ~59 ~68 ~8 ~70 stone
fill ~30 ~5 ~60 ~32 ~8 ~71 stone
setblock ~35 ~5 ~60 stonebrick 2
fill ~46 ~5 ~60 ~47 ~7 ~63 stone
fill ~49 ~5 ~60 ~59 ~7 ~60 stone
setblock ~63 ~5 ~60 stonebrick
fill ~70 ~5 ~60 ~73 ~9 ~65 stone
fill ~26 ~5 ~61 ~31 ~9 ~66 stone
fill ~33 ~5 ~61 ~33 ~7 ~73 stone
fill ~34 ~5 ~61 ~34 ~7 ~62 stonebrick
fill ~48 ~5 ~61 ~58 ~7 ~61 stone
fill ~74 ~5 ~61 ~76 ~8 ~63 stone
fill ~82 ~5 ~61 ~82 ~8 ~62 stone
fill ~16 ~5 ~62 ~32 ~8 ~62 stone
fill ~39 ~5 ~62 ~39 ~7 ~62 stonebrick
fill ~48 ~5 ~62 ~50 ~7 ~62 stone
fill ~78 ~5 ~62 ~82 ~8 ~62 stone
fill ~18 ~5 ~63 ~18 ~8 ~63 stone
fill ~20 ~5 ~63 ~34 ~8 ~63 stone
setblock ~38 ~5 ~63 stonebrick
fill ~48 ~5 ~63 ~48 ~8 ~63 stone
fill ~59 ~5 ~63 ~59 ~8 ~65 stone
setblock ~60 ~5 ~63 stonebrick 2
fill ~23 ~5 ~64 ~34 ~9 ~64 stone
fill ~57 ~5 ~64 ~59 ~10 ~64 stone
fill ~61 ~5 ~64 ~62 ~7 ~64 stonebrick
fill ~63 ~5 ~64 ~63 ~8 ~78 stone
fill ~74 ~5 ~64 ~74 ~9 ~64 stone
fill ~25 ~5 ~65 ~43 ~7 ~65 stone
fill ~61 ~5 ~65 ~66 ~7 ~72 stone
fill ~39 ~5 ~66 ~39 ~10 ~68 stone
fill ~40 ~5 ~66 ~40 ~10 ~66 stone
fill ~60 ~5 ~66 ~71 ~8 ~68 stone
fill ~72 ~5 ~66 ~72 ~9 ~66 stone
fill ~27 ~5 ~67 ~39 ~8 ~67 stone
fill ~8 ~5 ~68 ~8 ~8 ~68 stone
fill ~28 ~5 ~68 ~38 ~8 ~71 stone
fill ~43 ~5 ~68 ~43 ~7 ~68 leaves 10
fill ~90 ~5 ~68 ~90 ~8 ~68 stone
setblock ~8 ~5 ~69 double_stone_slab
fill ~71 ~5 ~69 ~71 ~8 ~71 stone
fill ~89 ~5 ~69 ~89 ~6 ~69 stone
fill ~4 ~5 ~70 ~4 ~6 ~70 leaves 10
setblock ~6 ~5 ~70 stone
setblock ~7 ~5 ~70 iron_ore
fill ~8 ~5 ~70 ~9 ~5 ~71 stone_slab
fill ~27 ~5 ~70 ~38 ~8 ~71 stone
fill ~88 ~5 ~70 ~88 ~8 ~70 stone
fill ~89 ~5 ~70 ~90 ~5 ~71 stone_slab
setblock ~91 ~5 ~70 iron_ore
fill ~92 ~5 ~70 ~92 ~8 ~70 stone
fill ~94 ~5 ~70 ~94 ~6 ~70 leaves 10
fill ~5 ~5 ~71 ~5 ~8 ~71 stone
fill ~6 ~5 ~71 ~8 ~5 ~72 stone_slab
fill ~11 ~5 ~71 ~11 ~8 ~71 stone
fill ~67 ~5 ~71 ~67 ~8 ~71 stone
fill ~70 ~5 ~71 ~71 ~8 ~71 stone
fill ~87 ~5 ~71 ~87 ~8 ~71 stone
setblock ~88 ~5 ~71 double_stone_slab
fill ~91 ~5 ~71 ~92 ~5 ~72 stone_slab
fill ~5 ~5 ~72 ~5 ~6 ~72 stone
setblock ~9 ~5 ~72 iron_ore
fill ~32 ~5 ~72 ~38 ~9 ~72 stone
setblock ~89 ~5 ~72 iron_ore
fill ~90 ~5 ~72 ~91 ~5 ~73 stone_slab
setblock ~5 ~5 ~73 stone
setblock ~6 ~5 ~73 double_stone_slab
fill ~7 ~5 ~73 ~8 ~5 ~73 stone_slab
fill ~9 ~5 ~73 ~9 ~8 ~73 stone
fill ~34 ~5 ~73 ~37 ~9 ~74 stone
fill ~38 ~5 ~73 ~38 ~10 ~73 stone
fill ~62 ~5 ~73 ~64 ~9 ~75 stone
fill ~65 ~5 ~73 ~65 ~9 ~73 stone
setblock ~89 ~5 ~73 stone
setblock ~92 ~5 ~73 double_stone_slab
fill ~9 ~5 ~75 ~9 ~6 ~75 leaves 10
fill ~35 ~5 ~75 ~37 ~8 ~76 stone
fill ~48 ~5 ~75 ~50 ~10 ~75 stone
fill ~89 ~5 ~75 ~89 ~6 ~75 leaves 10
fill ~62 ~5 ~76 ~62 ~8 ~82 stone
fill ~18 ~5 ~77 ~18 ~8 ~77 stone
fill ~80 ~5 ~77 ~80 ~8 ~77 stone
setblock ~18 ~5 ~78 double_stone_slab
fill ~36 ~5 ~78 ~36 ~8 ~82 stone
fill ~79 ~5 ~78 ~79 ~6 ~78 stone
fill ~14 ~5 ~79 ~14 ~6 ~79 leaves 10
setblock ~16 ~5 ~79 stone
setblock ~17 ~5 ~79 iron_ore
fill ~18 ~5 ~79 ~19 ~5 ~80 stone_slab
fill ~78 ~5 ~79 ~78 ~8 ~79 stone
fill ~79 ~5 ~79 ~80 ~5 ~80 stone_slab
setblock ~81 ~5 ~79 iron_ore
fill ~82 ~5 ~79 ~82 ~8 ~79 stone
fill ~84 ~5 ~79 ~84 ~6 ~79 leaves 10
fill ~15 ~5 ~80 ~15 ~8 ~80 stone
fill ~16 ~5 ~80 ~18 ~5 ~81 stone_slab
fill ~21 ~5 ~80 ~21 ~8 ~80 stone
fill ~63 ~5 ~80 ~63 ~8 ~81 stone
fill ~77 ~5 ~80 ~77 ~8 ~80 stone
setblock ~78 ~5 ~80 double_stone_slab
fill ~81 ~5 ~80 ~82 ~5 ~81 stone_slab
fill ~15 ~5 ~81 ~15 ~6 ~81 stone
setblock ~19 ~5 ~81 iron_ore
setblock ~79 ~5 ~81 iron_ore
fill ~80 ~5 ~81 ~81 ~5 ~82 stone_slab
setblock ~15 ~5 ~82 stone
setblock ~16 ~5 ~82 double_stone_slab
fill ~17 ~5 ~82 ~18 ~5 ~82 stone_slab
fill ~19 ~5 ~82 ~19 ~8 ~82 stone
fill ~37 ~5 ~82 ~37 ~9 ~82 stone
setblock ~79 ~5 ~82 stone
setblock ~82 ~5 ~82 double_stone_slab
fill ~19 ~5 ~84 ~19 ~6 ~84 leaves 10
fill ~79 ~5 ~84 ~79 ~6 ~84 leaves 10
fill ~27 ~5 ~87 ~27 ~8 ~87 stone
fill ~71 ~5 ~87 ~71 ~8 ~87 stone
setblock ~27 ~5 ~88 double_stone_slab
fill ~70 ~5 ~88 ~70 ~6 ~88 stone
fill ~23 ~5 ~89 ~23 ~6 ~89 leaves 10
setblock ~25 ~5 ~89 stone
setblock ~26 ~5 ~89 iron_ore
fill ~27 ~5 ~89 ~28 ~5 ~90 stone_slab
fill ~69 ~5 ~89 ~69 ~8 ~89 stone
fill ~70 ~5 ~89 ~71 ~5 ~90 stone_slab
setblock ~72 ~5 ~89 iron_ore
fill ~73 ~5 ~89 ~73 ~8 ~89 stone
fill ~75 ~5 ~89 ~75 ~6 ~89 leaves 10
fill ~24 ~5 ~90 ~24 ~8 ~90 stone
fill ~25 ~5 ~90 ~27 ~5 ~91 stone_slab
fill ~30 ~5 ~90 ~30 ~8 ~90 stone
fill ~68 ~5 ~90 ~68 ~8 ~90 stone
setblock ~69 ~5 ~90 double_stone_slab
fill ~72 ~5 ~90 ~73 ~5 ~91 stone_slab
fill ~24 ~5 ~91 ~24 ~6 ~91 stone
setblock ~28 ~5 ~91 iron_ore
setblock ~70 ~5 ~91 iron_ore
fill ~71 ~5 ~91 ~72 ~5 ~92 stone_slab
setblock ~24 ~5 ~92 stone
setblock ~25 ~5 ~92 double_stone_slab
fill ~26 ~5 ~92 ~27 ~5 ~92 stone_slab
fill ~28 ~5 ~92 ~28 ~8 ~92 stone
setblock ~70 ~5 ~92 stone
setblock ~73 ~5 ~92 double_stone_slab
fill ~28 ~5 ~94 ~28 ~6 ~94 leaves 10
fill ~70 ~5 ~94 ~70 ~6 ~94 leaves 10
fill ~28 ~6 ~3 ~28 ~8 ~3 leaves 10
setblock ~25 ~6 ~4 stone
fill ~69 ~6 ~4 ~69 ~8 ~4 leaves 10
setblock ~73 ~6 ~4 stone
fill ~25 ~6 ~5 ~25 ~9 ~5 stonebrick
fill ~26 ~6 ~5 ~27 ~6 ~5 stone
fill ~28 ~6 ~5 ~28 ~10 ~5 stonebrick
fill ~70 ~6 ~5 ~70 ~10 ~5 stonebrick
fill ~73 ~6 ~5 ~73 ~9 ~5 stonebrick
setblock ~23 ~6 ~6 stone
fill ~24 ~6 ~6 ~24 ~9 ~6 stonebrick
setblock ~28 ~6 ~6 iron_ore
fill ~74 ~6 ~6 ~74 ~9 ~6 stonebrick
setblock ~75 ~6 ~6 stone
fill ~24 ~6 ~7 ~24 ~8 ~8 stone
setblock ~28 ~6 ~7 chest 4
setblock ~29 ~6 ~7 coal_ore
fill ~31 ~6 ~7 ~31 ~7 ~7 leaves 10
setblock ~69 ~6 ~7 coal_ore
setblock ~29 ~6 ~8 furnace 4
setblock ~69 ~6 ~8 crafting_table
fill ~24 ~6 ~9 ~24 ~10 ~9 stonebrick
fill ~30 ~6 ~9 ~30 ~7 ~10 stone
fill ~68 ~6 ~9 ~69 ~6 ~10 stone
setblock ~72 ~6 ~9 chest 2
setblock ~73 ~6 ~9 iron_ore
fill ~74 ~6 ~9 ~74 ~10 ~9 stonebrick
fill ~76 ~6 ~9 ~76 ~8 ~9 leaves 10
fill ~23 ~6 ~10 ~23 ~8 ~10 leaves 10
setblock ~26 ~6 ~10 coal_ore
setblock ~27 ~6 ~10 crafting_table
fill ~29 ~6 ~10 ~30 ~7 ~10 stone
setblock ~71 ~6 ~10 furnace 2
setblock ~72 ~6 ~10 coal_ore
fill ~28 ~6 ~11 ~29 ~7 ~11 stone
fill ~69 ~6 ~11 ~71 ~7 ~11 stone
fill ~72 ~6 ~12 ~72 ~7 ~12 leaves 10
fill ~19 ~6 ~13 ~19 ~8 ~13 leaves 10
setblock ~16 ~6 ~14 stone
fill ~78 ~6 ~14 ~78 ~8 ~14 leaves 10
setblock ~82 ~6 ~14 stone
fill ~16 ~6 ~15 ~16 ~9 ~15 stonebrick
fill ~17 ~6 ~15 ~18 ~6 ~15 stone
fill ~19 ~6 ~15 ~19 ~10 ~15 stonebrick
fill ~37 ~6 ~15 ~37 ~8 ~18 stone
fill ~61 ~6 ~15 ~61 ~14 ~15 stone
fill ~79 ~6 ~15 ~79 ~10 ~15 stonebrick
fill ~82 ~6 ~15 ~82 ~9 ~15 stonebrick
setblock ~14 ~6 ~16 stone
fill ~15 ~6 ~16 ~15 ~9 ~16 stonebrick
setblock ~19 ~6 ~16 iron_ore
fill ~63 ~6 ~16 ~63 ~8 ~16 stone
fill ~83 ~6 ~16 ~83 ~9 ~16 stonebrick
setblock ~84 ~6 ~16 stone
fill ~15 ~6 ~17 ~15 ~8 ~18 stone
setblock ~19 ~6 ~17 chest 4
setblock ~20 ~6 ~17 coal_ore
fill ~22 ~6 ~17 ~22 ~7 ~17 leaves 10
setblock ~78 ~6 ~17 coal_ore
setblock ~20 ~6 ~18 furnace 4
setblock ~78 ~6 ~18 crafting_table
fill ~15 ~6 ~19 ~15 ~10 ~19 stonebrick
fill ~21 ~6 ~19 ~21 ~7 ~20 stone
fill ~61 ~6 ~19 ~62 ~8 ~32 stone
fill ~77 ~6 ~19 ~78 ~6 ~20 stone
setblock ~81 ~6 ~19 chest 2
setblock ~82 ~6 ~19 iron_ore
fill ~83 ~6 ~19 ~83 ~10 ~19 stonebrick
fill ~85 ~6 ~19 ~85 ~8 ~19 leaves 10
fill ~14 ~6 ~20 ~14 ~8 ~20 leaves 10
setblock ~17 ~6 ~20 coal_ore
setblock ~18 ~6 ~20 crafting_table
fill ~20 ~6 ~20 ~21 ~7 ~20 stone
fill ~37 ~6 ~20 ~37 ~8 ~32 stone
fill ~60 ~6 ~20 ~63 ~8 ~32 stone
setblock ~80 ~6 ~20 furnace 2
setblock ~81 ~6 ~20 coal_ore
fill ~19 ~6 ~21 ~20 ~7 ~21 stone
fill ~34 ~6 ~21 ~37 ~8 ~32 stone
fill ~64 ~6 ~21 ~64 ~8 ~35 stone
fill ~78 ~6 ~21 ~80 ~7 ~21 stone
fill ~9 ~6 ~22 ~9 ~8 ~22 leaves 10
fill ~49 ~6 ~22 ~49 ~10 ~24 stone
fill ~81 ~6 ~22 ~81 ~7 ~22 leaves 10
setblock ~6 ~6 ~23 stone
fill ~33 ~6 ~23 ~37 ~9 ~31 stone
fill ~47 ~6 ~23 ~51 ~10 ~23 stone
fill ~65 ~6 ~23 ~65 ~9 ~34 stone
fill ~88 ~6 ~23 ~88 ~8 ~23 leaves 10
setblock ~92 ~6 ~23 stone
fill ~6 ~6 ~24 ~6 ~9 ~24 stonebrick
fill ~7 ~6 ~24 ~8 ~6 ~24 stone
fill ~9 ~6 ~24 ~9 ~10 ~24 stonebrick
fill ~32 ~6 ~24 ~37 ~6 ~33 stone
fill ~89 ~6 ~24 ~89 ~10 ~24 stonebrick
fill ~92 ~6 ~24 ~92 ~9 ~24 stonebrick
setblock ~4 ~6 ~25 stone
fill ~5 ~6 ~25 ~5 ~9 ~25 stonebrick
setblock ~9 ~6 ~25 iron_ore
fill ~31 ~6 ~25 ~31 ~8 ~25 stone 6
fill ~38 ~6 ~25 ~38 ~8 ~34 stone
fill ~66 ~6 ~25 ~66 ~8 ~41 stone
fill ~67 ~6 ~25 ~67 ~8 ~25 stone 6
fill ~93 ~6 ~25 ~93 ~9 ~25 stonebrick
setblock ~94 ~6 ~25 stone
fill ~5 ~6 ~26 ~5 ~8 ~27 stone
setblock ~9 ~6 ~26 chest 4
setblock ~10 ~6 ~26 coal_ore
fill ~12 ~6 ~26 ~12 ~7 ~26 leaves 10
fill ~30 ~6 ~26 ~38 ~7 ~33 stone
fill ~59 ~6 ~26 ~69 ~7 ~33 stone
setblock ~88 ~6 ~26 coal_ore
setblock ~10 ~6 ~27 furnace 4
fill ~29 ~6 ~27 ~38 ~8 ~32 stone
setblock ~88 ~6 ~27 crafting_table
fill ~5 ~6 ~28 ~5 ~10 ~28 stonebrick
fill ~11 ~6 ~28 ~11 ~7 ~29 stone
fill ~39 ~6 ~28 ~39 ~10 ~34 stone
fill ~87 ~6 ~28 ~88 ~6 ~29 stone
setblock ~91 ~6 ~28 chest 2
setblock ~92 ~6 ~28 iron_ore
fill ~93 ~6 ~28 ~93 ~10 ~28 stonebrick
fill ~95 ~6 ~28 ~95 ~8 ~28 leaves 10
fill ~4 ~6 ~29 ~4 ~8 ~29 leaves 10
setblock ~7 ~6 ~29 coal_ore
setblock ~8 ~6 ~29 crafting_table
fill ~10 ~6 ~29 ~11 ~7 ~29 stone
fill ~26 ~6 ~29 ~33 ~7 ~39 stone
fill ~58 ~6 ~29 ~71 ~8 ~32 stone
setblock ~90 ~6 ~29 furnace 2
setblock ~91 ~6 ~29 coal_ore
fill ~9 ~6 ~30 ~10 ~7 ~30 stone
fill ~43 ~6 ~30 ~43 ~7 ~30 leaves 10
fill ~72 ~6 ~30 ~72 ~7 ~38 stone
fill ~88 ~6 ~30 ~90 ~7 ~30 stone
fill ~25 ~6 ~31 ~25 ~8 ~31 stone 6
fill ~40 ~6 ~31 ~40 ~7 ~69 stone
fill ~57 ~6 ~31 ~72 ~8 ~32 stone
fill ~73 ~6 ~31 ~73 ~8 ~31 stone 6
fill ~91 ~6 ~31 ~91 ~7 ~31 leaves 10
fill ~25 ~6 ~32 ~31 ~9 ~38 stone
fill ~41 ~6 ~32 ~41 ~10 ~34 stone
fill ~55 ~6 ~32 ~58 ~7 ~43 stone
fill ~73 ~6 ~32 ~73 ~8 ~38 stone
fill ~74 ~6 ~32 ~74 ~6 ~37 stone
fill ~23 ~6 ~33 ~31 ~9 ~38 stone
fill ~42 ~6 ~33 ~43 ~7 ~43 stone
fill ~52 ~6 ~33 ~59 ~10 ~34 stone
fill ~75 ~6 ~33 ~75 ~9 ~37 stone
fill ~21 ~6 ~34 ~32 ~8 ~38 stone
fill ~44 ~6 ~34 ~45 ~7 ~41 stone
fill ~49 ~6 ~34 ~58 ~7 ~40 stone
fill ~76 ~6 ~34 ~77 ~8 ~37 stone
fill ~16 ~6 ~35 ~16 ~8 ~37 stone
fill ~20 ~6 ~35 ~32 ~8 ~38 stone
fill ~38 ~6 ~35 ~38 ~7 ~35 stonebrick
fill ~46 ~6 ~35 ~59 ~8 ~35 stone
fill ~60 ~6 ~35 ~60 ~8 ~35 stonebrick 2
fill ~39 ~6 ~36 ~39 ~7 ~37 stonebrick
fill ~46 ~6 ~36 ~58 ~7 ~40 stone
fill ~15 ~6 ~37 ~15 ~14 ~37 stone
fill ~19 ~6 ~37 ~32 ~8 ~37 stone
fill ~78 ~6 ~37 ~78 ~8 ~37 stone
fill ~80 ~6 ~37 ~83 ~8 ~37 stone
fill ~35 ~6 ~38 ~35 ~8 ~38 stonebrick 2
fill ~63 ~6 ~38 ~63 ~7 ~38 stonebrick
fill ~64 ~6 ~38 ~73 ~8 ~38 stone
fill ~62 ~6 ~39 ~62 ~8 ~39 stonebrick
fill ~67 ~6 ~39 ~70 ~10 ~39 stone
fill ~29 ~6 ~40 ~67 ~7 ~40 stone
fill ~31 ~6 ~41 ~34 ~10 ~41 stone
setblock ~46 ~6 ~41 stone
fill ~52 ~6 ~41 ~66 ~6 ~41 stone
fill ~32 ~6 ~42 ~43 ~7 ~43 stone
fill ~44 ~6 ~42 ~44 ~7 ~42 stone
fill ~54 ~6 ~42 ~65 ~7 ~42 stone
fill ~63 ~6 ~43 ~63 ~8 ~59 stone
fill ~64 ~6 ~43 ~64 ~10 ~45 stone
fill ~65 ~6 ~43 ~65 ~10 ~43 stone
fill ~68 ~6 ~43 ~68 ~7 ~43 leaves 10
fill ~33 ~6 ~44 ~41 ~7 ~45 stone
fill ~42 ~6 ~44 ~42 ~7 ~44 stone
fill ~44 ~6 ~44 ~44 ~7 ~44 stone 4
fill ~54 ~6 ~44 ~54 ~7 ~44 stone 4
fill ~56 ~6 ~44 ~64 ~7 ~44 stone
setblock ~45 ~6 ~45 stone 4
setblock ~53 ~6 ~45 stone 4
fill ~57 ~6 ~45 ~64 ~7 ~45 stone
fill ~39 ~6 ~46 ~40 ~7 ~60 stone
setblock ~41 ~6 ~46 stone
fill ~57 ~6 ~46 ~63 ~6 ~46 stone
fill ~23 ~6 ~47 ~23 ~10 ~51 stone
fill ~34 ~6 ~47 ~40 ~7 ~47 stone
fill ~58 ~6 ~47 ~63 ~7 ~58 stone
fill ~75 ~6 ~47 ~75 ~10 ~51 stone
fill ~38 ~6 ~48 ~40 ~7 ~59 stone
fill ~50 ~6 ~48 ~50 ~8 ~50 stone
fill ~22 ~6 ~49 ~24 ~10 ~49 stone
fill ~35 ~6 ~49 ~40 ~7 ~58 stone
fill ~74 ~6 ~49 ~76 ~10 ~49 stone
fill ~64 ~6 ~50 ~64 ~8 ~60 stone
fill ~41 ~6 ~52 ~41 ~6 ~67 stone
fill ~57 ~6 ~52 ~65 ~6 ~58 stone
fill ~34 ~6 ~53 ~41 ~7 ~58 stone
setblock ~45 ~6 ~53 stone 4
setblock ~53 ~6 ~53 stone 4
fill ~42 ~6 ~54 ~42 ~7 ~66 stone
fill ~44 ~6 ~54 ~44 ~7 ~54 stone 4
fill ~54 ~6 ~54 ~54 ~7 ~54 stone 4
fill ~56 ~6 ~54 ~65 ~7 ~58 stone
fill ~30 ~6 ~55 ~30 ~7 ~55 leaves 10
fill ~33 ~6 ~55 ~43 ~7 ~58 stone
fill ~55 ~6 ~55 ~66 ~7 ~58 stone
fill ~44 ~6 ~56 ~44 ~7 ~65 stone
fill ~54 ~6 ~56 ~58 ~7 ~64 stone
fill ~32 ~6 ~57 ~33 ~7 ~73 stone
fill ~45 ~6 ~57 ~46 ~6 ~65 stone
fill ~52 ~6 ~57 ~58 ~6 ~63 stone
fill ~67 ~6 ~57 ~67 ~8 ~72 stone
fill ~31 ~6 ~58 ~33 ~7 ~72 stone
fill ~47 ~6 ~58 ~69 ~7 ~58 stone
fill ~28 ~6 ~59 ~32 ~8 ~71 stone
fill ~36 ~6 ~59 ~37 ~7 ~59 stonebrick
fill ~47 ~6 ~59 ~60 ~7 ~59 stone
fill ~69 ~6 ~59 ~71 ~8 ~71 stone
fill ~72 ~6 ~59 ~72 ~7 ~69 stone
fill ~25 ~6 ~60 ~32 ~8 ~66 stone
fill ~34 ~6 ~60 ~34 ~8 ~60 stone
fill ~35 ~6 ~60 ~35 ~7 ~60 stonebrick
fill ~48 ~6 ~60 ~58 ~7 ~63 stone
fill ~63 ~6 ~60 ~63 ~8 ~60 stonebrick 2
fill ~74 ~6 ~60 ~78 ~8 ~63 stone
fill ~15 ~6 ~61 ~18 ~8 ~61 stone
fill ~20 ~6 ~61 ~32 ~8 ~63 stone
fill ~79 ~6 ~61 ~79 ~8 ~62 stone
fill ~83 ~6 ~61 ~83 ~14 ~61 stone
fill ~59 ~6 ~62 ~59 ~8 ~62 stonebrick
fill ~38 ~6 ~63 ~38 ~8 ~63 stonebrick 2
fill ~60 ~6 ~63 ~60 ~7 ~63 stonebrick
fill ~82 ~6 ~63 ~82 ~8 ~63 stone
fill ~21 ~6 ~64 ~35 ~8 ~64 stone
fill ~47 ~6 ~64 ~47 ~10 ~64 stone
fill ~53 ~6 ~64 ~59 ~10 ~64 stone
fill ~60 ~6 ~64 ~60 ~8 ~73 stone
fill ~75 ~6 ~64 ~77 ~8 ~64 stone
fill ~23 ~6 ~65 ~46 ~7 ~65 stone
fill ~55 ~6 ~65 ~75 ~7 ~65 stone
fill ~24 ~6 ~66 ~43 ~6 ~66 stone
fill ~57 ~6 ~66 ~73 ~8 ~66 stone
fill ~7 ~6 ~67 ~7 ~7 ~67 leaves 10
fill ~25 ~6 ~67 ~25 ~8 ~67 stone 6
fill ~26 ~6 ~67 ~40 ~7 ~68 stone
fill ~58 ~6 ~67 ~72 ~8 ~67 stone
fill ~73 ~6 ~67 ~73 ~8 ~67 stone 6
fill ~9 ~6 ~68 ~10 ~7 ~69 stone
fill ~55 ~6 ~68 ~55 ~7 ~68 leaves 10
fill ~59 ~6 ~68 ~71 ~8 ~70 stone
fill ~88 ~6 ~68 ~90 ~7 ~68 stone
setblock ~7 ~6 ~69 coal_ore
setblock ~8 ~6 ~69 furnace 3
fill ~11 ~6 ~69 ~11 ~7 ~71 stone
fill ~27 ~6 ~69 ~39 ~8 ~71 stone
fill ~87 ~6 ~69 ~88 ~7 ~70 stone
setblock ~90 ~6 ~69 crafting_table
setblock ~91 ~6 ~69 coal_ore
fill ~94 ~6 ~69 ~94 ~8 ~69 leaves 10
fill ~3 ~6 ~70 ~3 ~8 ~70 leaves 10
fill ~5 ~6 ~70 ~5 ~10 ~70 stonebrick
setblock ~6 ~6 ~70 iron_ore
setblock ~7 ~6 ~70 chest 3
fill ~93 ~6 ~70 ~93 ~10 ~70 stonebrick
setblock ~10 ~6 ~71 crafting_table
fill ~68 ~6 ~71 ~71 ~8 ~71 stone
setblock ~88 ~6 ~71 furnace 5
setblock ~10 ~6 ~72 coal_ore
fill ~29 ~6 ~72 ~39 ~7 ~72 stone
fill ~68 ~6 ~72 ~68 ~7 ~72 stone
fill ~86 ~6 ~72 ~86 ~7 ~72 leaves 10
setblock ~88 ~6 ~72 coal_ore
setblock ~89 ~6 ~72 chest 5
setblock ~4 ~6 ~73 stone
fill ~5 ~6 ~73 ~5 ~9 ~73 stonebrick
fill ~31 ~6 ~73 ~31 ~8 ~73 stone 6
fill ~61 ~6 ~73 ~65 ~9 ~75 stone
fill ~66 ~6 ~73 ~66 ~8 ~73 stone
fill ~67 ~6 ~73 ~67 ~8 ~73 stone 6
setblock ~89 ~6 ~73 iron_ore
fill ~93 ~6 ~73 ~93 ~9 ~73 stonebrick
setblock ~94 ~6 ~73 stone
fill ~6 ~6 ~74 ~6 ~9 ~74 stonebrick
fill ~8 ~6 ~74 ~8 ~8 ~74 stone
fill ~9 ~6 ~74 ~9 ~10 ~74 stonebrick
fill ~33 ~6 ~74 ~38 ~9 ~75 stone
fill ~49 ~6 ~74 ~49 ~10 ~76 stone
setblock ~66 ~6 ~74 stone
fill ~89 ~6 ~74 ~89 ~10 ~74 stonebrick
fill ~90 ~6 ~74 ~90 ~8 ~74 stone
fill ~92 ~6 ~74 ~92 ~9 ~74 stonebrick
setblock ~6 ~6 ~75 stone
fill ~10 ~6 ~75 ~10 ~8 ~75 leaves 10
fill ~47 ~6 ~75 ~51 ~10 ~75 stone
setblock ~92 ~6 ~75 stone
fill ~17 ~6 ~76 ~17 ~7 ~76 leaves 10
fill ~34 ~6 ~76 ~38 ~8 ~77 stone
fill ~61 ~6 ~76 ~63 ~8 ~78 stone
fill ~64 ~6 ~76 ~64 ~8 ~77 stone
fill ~89 ~6 ~76 ~89 ~8 ~76 leaves 10
fill ~19 ~6 ~77 ~20 ~7 ~78 stone
fill ~78 ~6 ~77 ~80 ~7 ~77 stone
setblock ~17 ~6 ~78 coal_ore
setblock ~18 ~6 ~78 furnace 3
fill ~21 ~6 ~78 ~21 ~7 ~80 stone
fill ~35 ~6 ~78 ~38 ~8 ~78 stone
fill ~77 ~6 ~78 ~78 ~7 ~79 stone
setblock ~80 ~6 ~78 crafting_table
setblock ~81 ~6 ~78 coal_ore
fill ~84 ~6 ~78 ~84 ~8 ~78 leaves 10
fill ~13 ~6 ~79 ~13 ~8 ~79 leaves 10
fill ~15 ~6 ~79 ~15 ~10 ~79 stonebrick
setblock ~16 ~6 ~79 iron_ore
setblock ~17 ~6 ~79 chest 3
fill ~37 ~6 ~79 ~37 ~8 ~79 stone
fill ~83 ~6 ~79 ~83 ~10 ~79 stonebrick
setblock ~20 ~6 ~80 crafting_table
fill ~61 ~6 ~80 ~63 ~8 ~81 stone
setblock ~78 ~6 ~80 furnace 5
setblock ~20 ~6 ~81 coal_ore
fill ~76 ~6 ~81 ~76 ~7 ~81 leaves 10
setblock ~78 ~6 ~81 coal_ore
setblock ~79 ~6 ~81 chest 5
setblock ~14 ~6 ~82 stone
fill ~15 ~6 ~82 ~15 ~9 ~82 stonebrick
fill ~35 ~6 ~82 ~37 ~8 ~82 stone
fill ~61 ~6 ~82 ~61 ~9 ~83 stone
setblock ~79 ~6 ~82 iron_ore
fill ~83 ~6 ~82 ~83 ~9 ~82 stonebrick
setblock ~84 ~6 ~82 stone
fill ~16 ~6 ~83 ~16 ~9 ~83 stonebrick
fill ~18 ~6 ~83 ~18 ~8 ~83 stone
fill ~19 ~6 ~83 ~19 ~10 ~83 stonebrick
fill ~37 ~6 ~83 ~37 ~14 ~83 stone
fill ~79 ~6 ~83 ~79 ~10 ~83 stonebrick
fill ~80 ~6 ~83 ~80 ~8 ~83 stone
fill ~82 ~6 ~83 ~82 ~9 ~83 stonebrick
setblock ~16 ~6 ~84 stone
fill ~20 ~6 ~84 ~20 ~8 ~84 leaves 10
setblock ~82 ~6 ~84 stone
fill ~79 ~6 ~85 ~79 ~8 ~85 leaves 10
fill ~26 ~6 ~86 ~26 ~7 ~86 leaves 10
fill ~28 ~6 ~87 ~29 ~7 ~88 stone
fill ~69 ~6 ~87 ~71 ~7 ~87 stone
setblock ~26 ~6 ~88 coal_ore
setblock ~27 ~6 ~88 furnace 3
fill ~30 ~6 ~88 ~30 ~7 ~90 stone
fill ~68 ~6 ~88 ~69 ~7 ~89 stone
setblock ~71 ~6 ~88 crafting_table
setblock ~72 ~6 ~88 coal_ore
fill ~75 ~6 ~88 ~75 ~8 ~88 leaves 10
fill ~22 ~6 ~89 ~22 ~8 ~89 leaves 10
fill ~24 ~6 ~89 ~24 ~10 ~89 stonebrick
setblock ~25 ~6 ~89 iron_ore
setblock ~26 ~6 ~89 chest 3
fill ~74 ~6 ~89 ~74 ~10 ~89 stonebrick
setblock ~29 ~6 ~90 crafting_table
setblock ~69 ~6 ~90 furnace 5
setblock ~29 ~6 ~91 coal_ore
fill ~67 ~6 ~91 ~67 ~7 ~91 leaves 10
setblock ~69 ~6 ~91 coal_ore
setblock ~70 ~6 ~91 chest 5
setblock ~23 ~6 ~92 stone
fill ~24 ~6 ~92 ~24 ~9 ~92 stonebrick
setblock ~70 ~6 ~92 iron_ore
fill ~74 ~6 ~92 ~74 ~9 ~92 stonebrick
setblock ~75 ~6 ~92 stone
fill ~25 ~6 ~93 ~25 ~9 ~93 stonebrick
fill ~27 ~6 ~93 ~27 ~8 ~93 stone
fill ~28 ~6 ~93 ~28 ~10 ~93 stonebrick
fill ~70 ~6 ~93 ~70 ~10 ~93 stonebrick
fill ~71 ~6 ~93 ~71 ~8 ~93 stone
fill ~73 ~6 ~93 ~73 ~9 ~93 stonebrick
setblock ~25 ~6 ~94 stone
fill ~29 ~6 ~94 ~29 ~8 ~94 leaves 10
setblock ~73 ~6 ~94 stone
fill ~70 ~6 ~95 ~70 ~8 ~95 leaves 10
fill ~70 ~7 ~3 ~70 ~9 ~3 leaves 10
setblock ~25 ~7 ~4 dirt
fill ~27 ~7 ~4 ~27 ~11 ~4 stonebrick
setblock ~28 ~7 ~4 stone
fill ~29 ~7 ~4 ~29 ~9 ~4 leaves 10
setblock ~70 ~7 ~4 stone
fill ~71 ~7 ~4 ~71 ~11 ~4 stonebrick
setblock ~73 ~7 ~4 dirt
setblock ~26 ~7 ~5 gold_ore
fill ~27 ~7 ~5 ~27 ~8 ~5 stone
setblock ~23 ~7 ~6 dirt
fill ~28 ~7 ~6 ~29 ~8 ~6 stone
fill ~69 ~7 ~6 ~70 ~8 ~6 stone
setblock ~75 ~7 ~6 dirt
setblock ~29 ~7 ~7 iron_ore
fill ~69 ~7 ~7 ~69 ~8 ~7 stone
setblock ~74 ~7 ~7 gold_ore
fill ~23 ~7 ~8 ~23 ~11 ~8 stonebrick
fill ~31 ~7 ~8 ~31 ~8 ~8 stonebrick
fill ~67 ~7 ~8 ~67 ~8 ~8 stonebrick
fill ~75 ~7 ~8 ~75 ~11 ~8 stonebrick
fill ~22 ~7 ~9 ~22 ~9 ~9 leaves 10
setblock ~23 ~7 ~9 stone
fill ~68 ~7 ~9 ~68 ~8 ~9 stone
setblock ~69 ~7 ~9 gold_ore
fill ~73 ~7 ~9 ~73 ~8 ~10 stone
setblock ~75 ~7 ~9 stone
fill ~25 ~7 ~10 ~26 ~8 ~10 stone
setblock ~28 ~7 ~10 gold_ore
fill ~68 ~7 ~10 ~70 ~7 ~10 stone
setblock ~72 ~7 ~10 iron_ore
fill ~75 ~7 ~10 ~75 ~9 ~10 leaves 10
fill ~27 ~7 ~12 ~27 ~8 ~12 stonebrick
fill ~71 ~7 ~12 ~71 ~8 ~12 stonebrick
fill ~79 ~7 ~13 ~79 ~9 ~13 leaves 10
setblock ~16 ~7 ~14 dirt
fill ~18 ~7 ~14 ~18 ~11 ~14 stonebrick
setblock ~19 ~7 ~14 stone
fill ~20 ~7 ~14 ~20 ~9 ~14 leaves 10
fill ~37 ~7 ~14 ~37 ~7 ~33 stone
fill ~61 ~7 ~14 ~61 ~7 ~33 stone
setblock ~79 ~7 ~14 stone
fill ~80 ~7 ~14 ~80 ~11 ~14 stonebrick
setblock ~82 ~7 ~14 dirt
setblock ~17 ~7 ~15 gold_ore
fill ~18 ~7 ~15 ~18 ~8 ~15 stone
fill ~62 ~7 ~15 ~62 ~7 ~33 stone
setblock ~14 ~7 ~16 dirt
fill ~19 ~7 ~16 ~20 ~8 ~16 stone
fill ~35 ~7 ~16 ~37 ~8 ~32 stone
fill ~78 ~7 ~16 ~79 ~8 ~16 stone
setblock ~84 ~7 ~16 dirt
setblock ~20 ~7 ~17 iron_ore
fill ~34 ~7 ~17 ~37 ~8 ~18 stone
fill ~63 ~7 ~17 ~63 ~8 ~17 stone
fill ~78 ~7 ~17 ~78 ~8 ~17 stone
setblock ~83 ~7 ~17 gold_ore
fill ~14 ~7 ~18 ~14 ~11 ~18 stonebrick
fill ~22 ~7 ~18 ~22 ~8 ~18 stonebrick
fill ~59 ~7 ~18 ~59 ~9 ~18 leaves 10
fill ~76 ~7 ~18 ~76 ~8 ~18 stonebrick
fill ~84 ~7 ~18 ~84 ~11 ~18 stonebrick
fill ~13 ~7 ~19 ~13 ~9 ~19 leaves 10
setblock ~14 ~7 ~19 stone
fill ~39 ~7 ~19 ~39 ~9 ~19 leaves 10
fill ~77 ~7 ~19 ~77 ~8 ~19 stone
setblock ~78 ~7 ~19 gold_ore
fill ~82 ~7 ~19 ~82 ~8 ~20 stone
setblock ~84 ~7 ~19 stone
fill ~16 ~7 ~20 ~17 ~8 ~20 stone
setblock ~19 ~7 ~20 gold_ore
fill ~77 ~7 ~20 ~79 ~7 ~20 stone
setblock ~81 ~7 ~20 iron_ore
fill ~84 ~7 ~20 ~84 ~9 ~20 leaves 10
fill ~18 ~7 ~22 ~18 ~8 ~22 stonebrick
fill ~33 ~7 ~22 ~37 ~8 ~32 stone
fill ~50 ~7 ~22 ~50 ~10 ~23 stone
fill ~65 ~7 ~22 ~65 ~9 ~34 stone
fill ~80 ~7 ~22 ~80 ~8 ~22 stonebrick
fill ~89 ~7 ~22 ~89 ~9 ~22 leaves 10
setblock ~6 ~7 ~23 dirt
fill ~8 ~7 ~23 ~8 ~11 ~23 stonebrick
setblock ~9 ~7 ~23 stone
fill ~10 ~7 ~23 ~10 ~9 ~23 leaves 10
fill ~38 ~7 ~23 ~38 ~9 ~32 stone
setblock ~89 ~7 ~23 stone
fill ~90 ~7 ~23 ~90 ~11 ~23 stonebrick
setblock ~92 ~7 ~23 dirt
setblock ~7 ~7 ~24 gold_ore
fill ~8 ~7 ~24 ~8 ~8 ~24 stone
fill ~32 ~7 ~24 ~32 ~10 ~24 stone 6
fill ~48 ~7 ~24 ~49 ~10 ~24 stone
fill ~59 ~7 ~24 ~65 ~9 ~31 stone
fill ~66 ~7 ~24 ~66 ~10 ~24 stone 6
setblock ~4 ~7 ~25 dirt
fill ~9 ~7 ~25 ~10 ~8 ~25 stone
fill ~32 ~7 ~25 ~38 ~8 ~32 stone
fill ~88 ~7 ~25 ~89 ~8 ~25 stone
setblock ~94 ~7 ~25 dirt
setblock ~10 ~7 ~26 iron_ore
fill ~28 ~7 ~26 ~39 ~7 ~33 stone
fill ~70 ~7 ~26 ~71 ~8 ~39 stone
fill ~88 ~7 ~26 ~88 ~8 ~26 stone
setblock ~93 ~7 ~26 gold_ore
fill ~4 ~7 ~27 ~4 ~11 ~27 stonebrick
fill ~12 ~7 ~27 ~12 ~8 ~27 stonebrick
fill ~26 ~7 ~27 ~33 ~7 ~39 stone
fill ~58 ~7 ~27 ~71 ~8 ~32 stone
fill ~86 ~7 ~27 ~86 ~8 ~27 stonebrick
fill ~94 ~7 ~27 ~94 ~11 ~27 stonebrick
fill ~3 ~7 ~28 ~3 ~9 ~28 leaves 10
setblock ~4 ~7 ~28 stone
fill ~57 ~7 ~28 ~66 ~9 ~31 stone
fill ~72 ~7 ~28 ~72 ~7 ~39 stone
fill ~87 ~7 ~28 ~87 ~8 ~28 stone
setblock ~88 ~7 ~28 gold_ore
fill ~92 ~7 ~28 ~92 ~8 ~29 stone
setblock ~94 ~7 ~28 stone
fill ~6 ~7 ~29 ~7 ~8 ~29 stone
setblock ~9 ~7 ~29 gold_ore
fill ~40 ~7 ~29 ~40 ~7 ~71 stone
fill ~54 ~7 ~29 ~54 ~8 ~29 leaves 10
fill ~87 ~7 ~29 ~89 ~7 ~29 stone
setblock ~91 ~7 ~29 iron_ore
fill ~94 ~7 ~29 ~94 ~9 ~29 leaves 10
fill ~41 ~7 ~30 ~41 ~10 ~34 stone
fill ~8 ~7 ~31 ~8 ~8 ~31 stonebrick
fill ~55 ~7 ~31 ~59 ~10 ~34 stone
fill ~90 ~7 ~31 ~90 ~8 ~31 stonebrick
fill ~24 ~7 ~32 ~24 ~10 ~32 stone 6
fill ~42 ~7 ~32 ~42 ~7 ~44 stone
fill ~53 ~7 ~32 ~59 ~10 ~34 stone
fill ~74 ~7 ~32 ~74 ~10 ~32 stone 6
fill ~22 ~7 ~33 ~32 ~8 ~38 stone
fill ~44 ~7 ~33 ~46 ~10 ~34 stone
fill ~51 ~7 ~33 ~59 ~10 ~34 stone
fill ~74 ~7 ~33 ~75 ~9 ~38 stone
fill ~76 ~7 ~33 ~76 ~8 ~37 stone
fill ~47 ~7 ~34 ~58 ~7 ~40 stone
fill ~80 ~7 ~34 ~81 ~8 ~37 stone
fill ~17 ~7 ~35 ~17 ~8 ~37 stone
fill ~79 ~7 ~35 ~82 ~8 ~37 stone
fill ~15 ~7 ~36 ~33 ~7 ~37 stone
fill ~14 ~7 ~37 ~33 ~7 ~37 stone
fill ~84 ~7 ~37 ~84 ~10 ~37 stone
fill ~18 ~7 ~39 ~18 ~9 ~39 leaves 10
fill ~24 ~7 ~39 ~34 ~10 ~39 stone
fill ~79 ~7 ~39 ~79 ~9 ~39 leaves 10
fill ~27 ~7 ~40 ~69 ~7 ~40 stone
fill ~28 ~7 ~41 ~34 ~9 ~41 stone
setblock ~46 ~7 ~41 stonebrick
setblock ~47 ~7 ~41 stonebrick 2
setblock ~49 ~7 ~41 stone_brick_stairs 7
fill ~51 ~7 ~41 ~52 ~8 ~41 stonebrick
fill ~53 ~7 ~41 ~68 ~7 ~41 stone
fill ~31 ~7 ~42 ~34 ~10 ~43 stone
fill ~45 ~7 ~42 ~45 ~8 ~42 stonebrick
setblock ~53 ~7 ~42 stonebrick 2
fill ~66 ~7 ~42 ~66 ~10 ~42 stone
setblock ~44 ~7 ~43 stonebrick 2
fill ~54 ~7 ~43 ~54 ~8 ~43 stonebrick
fill ~29 ~7 ~44 ~29 ~8 ~44 leaves 10
fill ~32 ~7 ~44 ~34 ~10 ~45 stone
fill ~43 ~7 ~44 ~43 ~8 ~44 stonebrick
setblock ~55 ~7 ~44 stonebrick 2
fill ~65 ~7 ~44 ~65 ~10 ~46 stone
setblock ~42 ~7 ~45 stonebrick 2
fill ~45 ~7 ~45 ~45 ~9 ~45 stone 3
fill ~53 ~7 ~45 ~53 ~9 ~45 stone 3
fill ~56 ~7 ~45 ~56 ~8 ~45 stonebrick
fill ~33 ~7 ~46 ~40 ~7 ~46 stone
fill ~41 ~7 ~46 ~41 ~8 ~47 stonebrick
setblock ~57 ~7 ~46 stonebrick
fill ~58 ~7 ~46 ~58 ~7 ~69 stone
fill ~62 ~7 ~46 ~64 ~7 ~58 stone
fill ~49 ~7 ~47 ~49 ~8 ~50 stone
setblock ~57 ~7 ~47 stonebrick 2
fill ~22 ~7 ~48 ~23 ~10 ~49 stone
fill ~34 ~7 ~48 ~40 ~7 ~58 stone
fill ~74 ~7 ~48 ~75 ~10 ~49 stone
setblock ~41 ~7 ~49 stone_brick_stairs 5
fill ~47 ~7 ~49 ~51 ~8 ~49 stone
setblock ~57 ~7 ~49 stone_brick_stairs 4
fill ~65 ~7 ~49 ~65 ~10 ~59 stone
fill ~24 ~7 ~50 ~24 ~10 ~50 stone
fill ~48 ~7 ~50 ~50 ~8 ~50 stone
fill ~76 ~7 ~50 ~76 ~10 ~50 stone
setblock ~41 ~7 ~51 stonebrick 2
fill ~57 ~7 ~51 ~57 ~8 ~52 stonebrick
fill ~33 ~7 ~52 ~34 ~10 ~59 stone
setblock ~41 ~7 ~52 stonebrick
fill ~42 ~7 ~53 ~42 ~8 ~53 stonebrick
fill ~45 ~7 ~53 ~45 ~9 ~53 stone 3
fill ~53 ~7 ~53 ~53 ~9 ~53 stone 3
setblock ~56 ~7 ~53 stonebrick 2
fill ~57 ~7 ~53 ~66 ~7 ~58 stone
setblock ~43 ~7 ~54 stonebrick 2
fill ~55 ~7 ~54 ~55 ~8 ~54 stonebrick
fill ~69 ~7 ~54 ~69 ~8 ~54 leaves 10
fill ~44 ~7 ~55 ~44 ~8 ~55 stonebrick
setblock ~54 ~7 ~55 stonebrick 2
fill ~67 ~7 ~55 ~67 ~8 ~72 stone
fill ~32 ~7 ~56 ~34 ~10 ~59 stone
setblock ~45 ~7 ~56 stonebrick 2
fill ~53 ~7 ~56 ~53 ~8 ~56 stonebrick
fill ~30 ~7 ~57 ~33 ~7 ~72 stone
fill ~45 ~7 ~57 ~45 ~7 ~66 stone
fill ~46 ~7 ~57 ~47 ~8 ~57 stonebrick
setblock ~49 ~7 ~57 stone_brick_stairs 6
setblock ~51 ~7 ~57 stonebrick 2
setblock ~52 ~7 ~57 stonebrick
fill ~53 ~7 ~57 ~58 ~7 ~65 stone
fill ~68 ~7 ~57 ~70 ~9 ~66 stone
fill ~29 ~7 ~58 ~33 ~7 ~72 stone
fill ~46 ~7 ~58 ~71 ~7 ~58 stone
fill ~19 ~7 ~59 ~19 ~9 ~59 leaves 10
fill ~26 ~7 ~59 ~33 ~7 ~70 stone
fill ~46 ~7 ~59 ~60 ~7 ~59 stone
fill ~73 ~7 ~59 ~74 ~9 ~65 stone
fill ~80 ~7 ~59 ~80 ~9 ~59 leaves 10
fill ~23 ~7 ~60 ~31 ~9 ~65 stone
fill ~14 ~7 ~61 ~33 ~7 ~61 stone
fill ~80 ~7 ~61 ~83 ~8 ~62 stone
fill ~84 ~7 ~61 ~84 ~10 ~61 stone
fill ~16 ~7 ~63 ~34 ~8 ~63 stone
fill ~81 ~7 ~63 ~82 ~8 ~63 stone
fill ~17 ~7 ~64 ~18 ~8 ~64 stone
fill ~46 ~7 ~64 ~60 ~8 ~64 stone
fill ~22 ~7 ~65 ~34 ~9 ~65 stone
fill ~52 ~7 ~65 ~59 ~10 ~65 stone
fill ~76 ~7 ~65 ~76 ~9 ~65 stone
fill ~24 ~7 ~66 ~24 ~10 ~66 stone 6
fill ~41 ~7 ~66 ~45 ~10 ~66 stone
fill ~56 ~7 ~66 ~73 ~8 ~66 stone
fill ~74 ~7 ~66 ~74 ~10 ~66 stone 6
fill ~8 ~7 ~67 ~8 ~8 ~67 stonebrick
fill ~41 ~7 ~67 ~43 ~10 ~67 stone
fill ~57 ~7 ~67 ~72 ~8 ~67 stone
fill ~90 ~7 ~67 ~90 ~8 ~67 stonebrick
fill ~41 ~7 ~68 ~41 ~9 ~70 stone
fill ~57 ~7 ~68 ~72 ~7 ~68 stone
fill ~4 ~7 ~69 ~4 ~9 ~69 leaves 10
fill ~6 ~7 ~69 ~6 ~8 ~70 stone
setblock ~7 ~7 ~69 iron_ore
fill ~44 ~7 ~69 ~44 ~8 ~69 leaves 10
setblock ~89 ~7 ~69 gold_ore
fill ~91 ~7 ~69 ~92 ~8 ~69 stone
setblock ~4 ~7 ~70 stone
setblock ~10 ~7 ~70 gold_ore
fill ~72 ~7 ~70 ~72 ~8 ~71 stone
setblock ~94 ~7 ~70 stone
fill ~95 ~7 ~70 ~95 ~9 ~70 leaves 10
fill ~4 ~7 ~71 ~4 ~11 ~71 stonebrick
fill ~12 ~7 ~71 ~12 ~8 ~71 stonebrick
fill ~59 ~7 ~71 ~72 ~8 ~71 stone
fill ~86 ~7 ~71 ~86 ~8 ~71 stonebrick
fill ~94 ~7 ~71 ~94 ~11 ~71 stonebrick
setblock ~5 ~7 ~72 gold_ore
fill ~10 ~7 ~72 ~10 ~8 ~73 stone
fill ~27 ~7 ~72 ~39 ~7 ~72 stone
fill ~59 ~7 ~72 ~70 ~7 ~72 stone
setblock ~88 ~7 ~72 iron_ore
setblock ~4 ~7 ~73 dirt
fill ~39 ~7 ~73 ~39 ~10 ~74 stone
fill ~88 ~7 ~73 ~89 ~8 ~73 stone
setblock ~94 ~7 ~73 dirt
fill ~32 ~7 ~74 ~32 ~10 ~74 stone 6
fill ~50 ~7 ~74 ~50 ~10 ~75 stone
fill ~60 ~7 ~74 ~65 ~9 ~75 stone
fill ~66 ~7 ~74 ~66 ~10 ~74 stone 6
setblock ~91 ~7 ~74 gold_ore
setblock ~6 ~7 ~75 dirt
fill ~8 ~7 ~75 ~8 ~11 ~75 stonebrick
setblock ~9 ~7 ~75 stone
fill ~88 ~7 ~75 ~88 ~9 ~75 leaves 10
setblock ~89 ~7 ~75 stone
fill ~90 ~7 ~75 ~90 ~11 ~75 stonebrick
setblock ~92 ~7 ~75 dirt
fill ~9 ~7 ~76 ~9 ~9 ~76 leaves 10
fill ~18 ~7 ~76 ~18 ~8 ~76 stonebrick
fill ~33 ~7 ~76 ~38 ~8 ~76 stone
fill ~48 ~7 ~76 ~49 ~10 ~76 stone
fill ~65 ~7 ~76 ~65 ~9 ~76 stone
fill ~80 ~7 ~76 ~80 ~8 ~76 stonebrick
fill ~14 ~7 ~78 ~14 ~9 ~78 leaves 10
fill ~16 ~7 ~78 ~16 ~8 ~79 stone
setblock ~17 ~7 ~78 iron_ore
setblock ~79 ~7 ~78 gold_ore
fill ~81 ~7 ~78 ~82 ~8 ~78 stone
setblock ~14 ~7 ~79 stone
setblock ~20 ~7 ~79 gold_ore
fill ~59 ~7 ~79 ~59 ~9 ~79 leaves 10
fill ~61 ~7 ~79 ~63 ~8 ~82 stone
setblock ~84 ~7 ~79 stone
fill ~85 ~7 ~79 ~85 ~9 ~79 leaves 10
fill ~14 ~7 ~80 ~14 ~11 ~80 stonebrick
fill ~22 ~7 ~80 ~22 ~8 ~80 stonebrick
fill ~37 ~7 ~80 ~37 ~8 ~84 stone
fill ~39 ~7 ~80 ~39 ~9 ~80 leaves 10
fill ~64 ~7 ~80 ~64 ~8 ~81 stone
fill ~76 ~7 ~80 ~76 ~8 ~80 stonebrick
fill ~84 ~7 ~80 ~84 ~11 ~80 stonebrick
setblock ~15 ~7 ~81 gold_ore
fill ~20 ~7 ~81 ~20 ~8 ~82 stone
fill ~35 ~7 ~81 ~37 ~8 ~82 stone
setblock ~78 ~7 ~81 iron_ore
setblock ~14 ~7 ~82 dirt
fill ~78 ~7 ~82 ~79 ~8 ~82 stone
setblock ~84 ~7 ~82 dirt
fill ~36 ~7 ~83 ~37 ~11 ~83 stone
setblock ~81 ~7 ~83 gold_ore
setblock ~16 ~7 ~84 dirt
fill ~18 ~7 ~84 ~18 ~11 ~84 stonebrick
setblock ~19 ~7 ~84 stone
fill ~61 ~7 ~84 ~61 ~10 ~84 stone
fill ~78 ~7 ~84 ~78 ~9 ~84 leaves 10
setblock ~79 ~7 ~84 stone
fill ~80 ~7 ~84 ~80 ~11 ~84 stonebrick
setblock ~82 ~7 ~84 dirt
fill ~19 ~7 ~85 ~19 ~9 ~85 leaves 10
fill ~27 ~7 ~86 ~27 ~8 ~86 stonebrick
fill ~71 ~7 ~86 ~71 ~8 ~86 stonebrick
fill ~23 ~7 ~88 ~23 ~9 ~88 leaves 10
fill ~25 ~7 ~88 ~25 ~8 ~89 stone
setblock ~26 ~7 ~88 iron_ore
setblock ~70 ~7 ~88 gold_ore
fill ~72 ~7 ~88 ~73 ~8 ~88 stone
setblock ~23 ~7 ~89 stone
setblock ~29 ~7 ~89 gold_ore
setblock ~75 ~7 ~89 stone
fill ~76 ~7 ~89 ~76 ~9 ~89 leaves 10
fill ~23 ~7 ~90 ~23 ~11 ~90 stonebrick
fill ~31 ~7 ~90 ~31 ~8 ~90 stonebrick
fill ~67 ~7 ~90 ~67 ~8 ~90 stonebrick
fill ~75 ~7 ~90 ~75 ~11 ~90 stonebrick
setblock ~24 ~7 ~91 gold_ore
fill ~29 ~7 ~91 ~29 ~8 ~92 stone
setblock ~69 ~7 ~91 iron_ore
setblock ~23 ~7 ~92 dirt
fill ~69 ~7 ~92 ~70 ~8 ~92 stone
setblock ~75 ~7 ~92 dirt
setblock ~72 ~7 ~93 gold_ore
setblock ~25 ~7 ~94 dirt
fill ~27 ~7 ~94 ~27 ~11 ~94 stonebrick
setblock ~28 ~7 ~94 stone
fill ~69 ~7 ~94 ~69 ~9 ~94 leaves 10
setblock ~70 ~7 ~94 stone
fill ~71 ~7 ~94 ~71 ~11 ~94 stonebrick
setblock ~73 ~7 ~94 dirt
fill ~28 ~7 ~95 ~28 ~9 ~95 leaves 10
fill ~23 ~8 ~4 ~23 ~10 ~4 leaves 10
setblock ~25 ~8 ~4 grass
setblock ~26 ~8 ~4 dirt
setblock ~28 ~8 ~4 dirt
setblock ~70 ~8 ~4 dirt
fill ~72 ~8 ~4 ~72 ~8 ~5 stone
setblock ~73 ~8 ~4 grass
fill ~75 ~8 ~4 ~75 ~10 ~4 leaves 10
fill ~24 ~8 ~5 ~25 ~9 ~5 stonebrick
fill ~26 ~8 ~5 ~27 ~8 ~5 stone
setblock ~29 ~8 ~5 stone_slab 8
setblock ~69 ~8 ~5 stone_slab 8
fill ~74 ~8 ~5 ~74 ~9 ~6 stonebrick
setblock ~23 ~8 ~6 grass
setblock ~27 ~8 ~6 stone_slab 8
setblock ~30 ~8 ~6 stone_slab 8
setblock ~68 ~8 ~6 stone_slab 8
setblock ~71 ~8 ~6 stone_slab 8
setblock ~75 ~8 ~6 grass
fill ~23 ~8 ~7 ~24 ~8 ~7 stone
fill ~26 ~8 ~7 ~27 ~8 ~7 stone_slab 13
setblock ~28 ~8 ~7 double_stone_slab 5
setblock ~29 ~8 ~7 stone
fill ~30 ~8 ~7 ~30 ~10 ~7 stonebrick
fill ~32 ~8 ~7 ~32 ~9 ~7 leaves 10
fill ~68 ~8 ~7 ~68 ~8 ~9 stone
setblock ~70 ~8 ~7 double_stone_slab 5
fill ~71 ~8 ~7 ~72 ~8 ~7 stone_slab 13
fill ~74 ~8 ~7 ~74 ~8 ~8 stone
setblock ~75 ~8 ~7 dirt
setblock ~25 ~8 ~8 stone_slab 8
setblock ~26 ~8 ~8 stone_slab 13
setblock ~27 ~8 ~8 double_stone_slab 5
setblock ~28 ~8 ~8 stone_slab 13
setblock ~29 ~8 ~8 stone_slab 8
fill ~32 ~8 ~8 ~32 ~10 ~8 stonebrick
fill ~66 ~8 ~8 ~66 ~10 ~8 stonebrick
setblock ~69 ~8 ~8 stone_slab 8
setblock ~70 ~8 ~8 stone_slab 13
setblock ~71 ~8 ~8 double_stone_slab 5
setblock ~72 ~8 ~8 stone_slab 13
setblock ~73 ~8 ~8 stone_slab 8
setblock ~23 ~8 ~9 dirt
setblock ~26 ~8 ~9 double_stone_slab 5
setblock ~27 ~8 ~9 stone_slab 13
setblock ~28 ~8 ~9 diamond_ore
setblock ~30 ~8 ~9 stone
setblock ~31 ~8 ~9 dirt
fill ~67 ~8 ~9 ~69 ~8 ~9 stone
setblock ~70 ~8 ~9 diamond_ore
setblock ~71 ~8 ~9 stone_slab 13
setblock ~72 ~8 ~9 double_stone_slab 5
setblock ~75 ~8 ~9 dirt
setblock ~24 ~8 ~10 stone_slab 8
setblock ~27 ~8 ~10 stone_slab 8
fill ~28 ~8 ~10 ~28 ~8 ~12 stone
setblock ~29 ~8 ~10 stone
setblock ~30 ~8 ~10 double_stone_slab
setblock ~68 ~8 ~10 double_stone_slab
fill ~69 ~8 ~10 ~70 ~8 ~10 stone
setblock ~71 ~8 ~10 stone_slab 8
fill ~72 ~8 ~10 ~73 ~8 ~10 stone
setblock ~74 ~8 ~10 stone_slab 8
setblock ~25 ~8 ~11 stone_slab 8
fill ~26 ~8 ~11 ~28 ~8 ~11 stone
setblock ~29 ~8 ~11 double_stone_slab
setblock ~69 ~8 ~11 double_stone_slab
fill ~70 ~8 ~11 ~71 ~8 ~11 stone
fill ~72 ~8 ~11 ~72 ~10 ~11 stonebrick
setblock ~73 ~8 ~11 stone_slab 8
setblock ~70 ~8 ~12 dirt
fill ~27 ~8 ~13 ~27 ~10 ~13 stonebrick
fill ~71 ~8 ~13 ~71 ~10 ~13 stonebrick
fill ~72 ~8 ~13 ~72 ~9 ~13 leaves 10
fill ~14 ~8 ~14 ~14 ~10 ~14 leaves 10
setblock ~16 ~8 ~14 grass
setblock ~17 ~8 ~14 dirt
setblock ~19 ~8 ~14 dirt
fill ~37 ~8 ~14 ~37 ~8 ~32 stone
fill ~61 ~8 ~14 ~61 ~8 ~32 stone
setblock ~79 ~8 ~14 dirt
fill ~81 ~8 ~14 ~81 ~8 ~15 stone
setblock ~82 ~8 ~14 grass
fill ~84 ~8 ~14 ~84 ~10 ~14 leaves 10
fill ~15 ~8 ~15 ~15 ~9 ~15 stone 3
fill ~17 ~8 ~15 ~18 ~8 ~15 stone
setblock ~20 ~8 ~15 stone_slab 8
fill ~35 ~8 ~15 ~37 ~8 ~32 stone
fill ~62 ~8 ~15 ~63 ~8 ~32 stone
setblock ~78 ~8 ~15 stone_slab 8
fill ~83 ~8 ~15 ~83 ~9 ~15 stone 3
setblock ~14 ~8 ~16 grass
setblock ~18 ~8 ~16 stone_slab 8
setblock ~21 ~8 ~16 stone_slab 8
fill ~34 ~8 ~16 ~37 ~8 ~32 stone
fill ~64 ~8 ~16 ~64 ~8 ~35 stone
setblock ~77 ~8 ~16 stone_slab 8
setblock ~80 ~8 ~16 stone_slab 8
setblock ~84 ~8 ~16 grass
fill ~14 ~8 ~17 ~15 ~8 ~17 stone
fill ~17 ~8 ~17 ~18 ~8 ~17 stone_slab 13
setblock ~19 ~8 ~17 double_stone_slab 5
setblock ~20 ~8 ~17 stone
setblock ~21 ~8 ~17 stonebrick 2
fill ~23 ~8 ~17 ~23 ~9 ~17 leaves 10
fill ~38 ~8 ~17 ~38 ~9 ~17 stone 6
fill ~77 ~8 ~17 ~77 ~8 ~19 stone
setblock ~79 ~8 ~17 double_stone_slab 5
fill ~80 ~8 ~17 ~81 ~8 ~17 stone_slab 13
fill ~83 ~8 ~17 ~83 ~8 ~18 stone
setblock ~84 ~8 ~17 dirt
setblock ~16 ~8 ~18 stone_slab 8
setblock ~17 ~8 ~18 stone_slab 13
setblock ~18 ~8 ~18 double_stone_slab 5
setblock ~19 ~8 ~18 stone_slab 13
setblock ~20 ~8 ~18 stone_slab 8
fill ~23 ~8 ~18 ~23 ~9 ~18 stonebrick
fill ~75 ~8 ~18 ~75 ~10 ~18 stonebrick
setblock ~78 ~8 ~18 stone_slab 8
setblock ~79 ~8 ~18 stone_slab 13
setblock ~80 ~8 ~18 double_stone_slab 5
setblock ~81 ~8 ~18 stone_slab 13
setblock ~82 ~8 ~18 stone_slab 8
setblock ~14 ~8 ~19 dirt
setblock ~17 ~8 ~19 double_stone_slab 5
setblock ~18 ~8 ~19 stone_slab 13
setblock ~19 ~8 ~19 diamond_ore
setblock ~21 ~8 ~19 stone
setblock ~22 ~8 ~19 dirt
fill ~38 ~8 ~19 ~38 ~9 ~32 stone
fill ~60 ~8 ~19 ~64 ~8 ~32 stone
fill ~76 ~8 ~19 ~78 ~8 ~19 stone
setblock ~79 ~8 ~19 diamond_ore
setblock ~80 ~8 ~19 stone_slab 13
setblock ~81 ~8 ~19 double_stone_slab 5
setblock ~84 ~8 ~19 dirt
setblock ~15 ~8 ~20 stone_slab 8
setblock ~18 ~8 ~20 stone_slab 8
fill ~19 ~8 ~20 ~19 ~8 ~22 stone
setblock ~20 ~8 ~20 stone
setblock ~21 ~8 ~20 double_stone_slab
fill ~33 ~8 ~20 ~38 ~8 ~32 stone
fill ~65 ~8 ~20 ~65 ~8 ~35 stone
setblock ~77 ~8 ~20 double_stone_slab
fill ~78 ~8 ~20 ~79 ~8 ~20 stone
setblock ~80 ~8 ~20 stone_slab 8
fill ~81 ~8 ~20 ~82 ~8 ~20 stone
setblock ~83 ~8 ~20 stone_slab 8
setblock ~16 ~8 ~21 stone_slab 8
fill ~17 ~8 ~21 ~19 ~8 ~21 stone
setblock ~20 ~8 ~21 double_stone_slab
setblock ~78 ~8 ~21 double_stone_slab
fill ~79 ~8 ~21 ~80 ~8 ~21 stone
setblock ~81 ~8 ~21 stonebrick 2
setblock ~82 ~8 ~21 stone_slab 8
fill ~39 ~8 ~22 ~39 ~8 ~35 stone
fill ~48 ~8 ~22 ~50 ~10 ~23 stone
fill ~59 ~8 ~22 ~65 ~8 ~32 stone
setblock ~79 ~8 ~22 dirt
fill ~4 ~8 ~23 ~4 ~10 ~23 leaves 10
setblock ~6 ~8 ~23 grass
setblock ~7 ~8 ~23 dirt
setblock ~9 ~8 ~23 dirt
fill ~18 ~8 ~23 ~18 ~10 ~23 stonebrick
fill ~32 ~8 ~23 ~39 ~8 ~23 stone
fill ~46 ~8 ~23 ~52 ~10 ~23 stone
setblock ~66 ~8 ~23 stone
fill ~80 ~8 ~23 ~80 ~9 ~23 stonebrick
fill ~81 ~8 ~23 ~81 ~9 ~23 leaves 10
setblock ~89 ~8 ~23 dirt
fill ~91 ~8 ~23 ~91 ~8 ~24 stone
setblock ~92 ~8 ~23 grass
fill ~94 ~8 ~23 ~94 ~10 ~23 leaves 10
fill ~5 ~8 ~24 ~6 ~9 ~24 stonebrick
fill ~7 ~8 ~24 ~8 ~8 ~24 stone
setblock ~10 ~8 ~24 stone_slab 8
fill ~47 ~8 ~24 ~49 ~10 ~24 stone
fill ~58 ~8 ~24 ~65 ~9 ~31 stone
setblock ~88 ~8 ~24 stone_slab 8
fill ~93 ~8 ~24 ~93 ~9 ~25 stonebrick
setblock ~4 ~8 ~25 grass
setblock ~8 ~8 ~25 stone_slab 8
setblock ~11 ~8 ~25 stone_slab 8
fill ~26 ~8 ~25 ~29 ~8 ~29 stone
fill ~40 ~8 ~25 ~40 ~8 ~35 stone
fill ~49 ~8 ~25 ~49 ~10 ~25 stone
fill ~69 ~8 ~25 ~72 ~8 ~29 stone
setblock ~87 ~8 ~25 stone_slab 8
setblock ~90 ~8 ~25 stone_slab 8
setblock ~94 ~8 ~25 grass
fill ~4 ~8 ~26 ~5 ~8 ~26 stone
fill ~7 ~8 ~26 ~8 ~8 ~26 stone_slab 13
setblock ~9 ~8 ~26 double_stone_slab 5
setblock ~10 ~8 ~26 stone
fill ~11 ~8 ~26 ~11 ~10 ~26 stonebrick
fill ~13 ~8 ~26 ~13 ~9 ~26 leaves 10
fill ~25 ~8 ~26 ~29 ~8 ~29 stone
fill ~30 ~8 ~26 ~30 ~11 ~26 stone 6
fill ~31 ~8 ~26 ~40 ~8 ~32 stone
fill ~67 ~8 ~26 ~67 ~8 ~44 stone
fill ~68 ~8 ~26 ~68 ~11 ~26 stone 6
fill ~73 ~8 ~26 ~73 ~8 ~29 stone
fill ~87 ~8 ~26 ~87 ~8 ~28 stone
setblock ~89 ~8 ~26 double_stone_slab 5
fill ~90 ~8 ~26 ~91 ~8 ~26 stone_slab 13
fill ~93 ~8 ~26 ~93 ~8 ~27 stone
setblock ~94 ~8 ~26 dirt
setblock ~6 ~8 ~27 stone_slab 8
setblock ~7 ~8 ~27 stone_slab 13
setblock ~8 ~8 ~27 double_stone_slab 5
setblock ~9 ~8 ~27 stone_slab 13
setblock ~10 ~8 ~27 stone_slab 8
fill ~13 ~8 ~27 ~13 ~10 ~27 stonebrick
fill ~41 ~8 ~27 ~41 ~8 ~35 stone
fill ~57 ~8 ~27 ~73 ~8 ~29 stone
fill ~85 ~8 ~27 ~85 ~10 ~27 stonebrick
setblock ~88 ~8 ~27 stone_slab 8
setblock ~89 ~8 ~27 stone_slab 13
setblock ~90 ~8 ~27 double_stone_slab 5
setblock ~91 ~8 ~27 stone_slab 13
setblock ~92 ~8 ~27 stone_slab 8
setblock ~4 ~8 ~28 dirt
setblock ~7 ~8 ~28 double_stone_slab 5
setblock ~8 ~8 ~28 stone_slab 13
setblock ~9 ~8 ~28 diamond_ore
setblock ~11 ~8 ~28 stone
setblock ~12 ~8 ~28 dirt
fill ~86 ~8 ~28 ~88 ~8 ~28 stone
setblock ~89 ~8 ~28 diamond_ore
setblock ~90 ~8 ~28 stone_slab 13
setblock ~91 ~8 ~28 double_stone_slab 5
setblock ~94 ~8 ~28 dirt
setblock ~5 ~8 ~29 stone_slab 8
setblock ~8 ~8 ~29 stone_slab 8
fill ~9 ~8 ~29 ~9 ~8 ~31 stone
setblock ~10 ~8 ~29 stone
setblock ~11 ~8 ~29 double_stone_slab
fill ~42 ~8 ~29 ~42 ~8 ~35 stone
fill ~43 ~8 ~29 ~43 ~10 ~29 leaves 10
fill ~56 ~8 ~29 ~59 ~8 ~35 stone
setblock ~87 ~8 ~29 double_stone_slab
fill ~88 ~8 ~29 ~89 ~8 ~29 stone
setblock ~90 ~8 ~29 stone_slab 8
fill ~91 ~8 ~29 ~92 ~8 ~29 stone
setblock ~93 ~8 ~29 stone_slab 8
setblock ~6 ~8 ~30 stone_slab 8
fill ~7 ~8 ~30 ~9 ~8 ~30 stone
setblock ~10 ~8 ~30 double_stone_slab
fill ~26 ~8 ~30 ~26 ~11 ~30 stone 6
setblock ~44 ~8 ~30 leaves 10
fill ~49 ~8 ~30 ~49 ~10 ~35 stone
fill ~72 ~8 ~30 ~72 ~11 ~30 stone 6
setblock ~88 ~8 ~30 double_stone_slab
fill ~89 ~8 ~30 ~90 ~8 ~30 stone
fill ~91 ~8 ~30 ~91 ~10 ~30 stonebrick
setblock ~92 ~8 ~30 stone_slab 8
fill ~26 ~8 ~31 ~32 ~8 ~40 stone
fill ~43 ~8 ~31 ~44 ~10 ~34 stone
fill ~48 ~8 ~31 ~49 ~10 ~33 stone
fill ~54 ~8 ~31 ~59 ~9 ~34 stone
setblock ~89 ~8 ~31 dirt
fill ~8 ~8 ~32 ~8 ~10 ~32 stonebrick
fill ~23 ~8 ~32 ~23 ~8 ~39 stone
fill ~45 ~8 ~32 ~49 ~10 ~33 stone
fill ~51 ~8 ~32 ~59 ~10 ~34 stone
fill ~75 ~8 ~32 ~75 ~8 ~39 stone
fill ~90 ~8 ~32 ~90 ~10 ~32 stonebrick
fill ~91 ~8 ~32 ~91 ~9 ~32 leaves 10
fill ~20 ~8 ~33 ~32 ~8 ~38 stone
fill ~33 ~8 ~33 ~34 ~9 ~34 stone
fill ~36 ~8 ~33 ~37 ~8 ~33 stonebrick
fill ~50 ~8 ~33 ~59 ~10 ~33 stone
fill ~60 ~8 ~33 ~60 ~8 ~34 stone
fill ~61 ~8 ~33 ~61 ~8 ~34 stonebrick 2
fill ~62 ~8 ~33 ~62 ~8 ~34 stonebrick
fill ~72 ~8 ~33 ~78 ~8 ~38 stone
fill ~16 ~8 ~34 ~32 ~8 ~37 stone
setblock ~36 ~8 ~34 stonebrick 2
setblock ~37 ~8 ~34 stonebrick
fill ~47 ~8 ~34 ~59 ~8 ~35 stone
fill ~79 ~8 ~34 ~82 ~8 ~37 stone
fill ~15 ~8 ~35 ~32 ~8 ~37 stone
fill ~36 ~8 ~35 ~37 ~8 ~35 stone_slab 8
fill ~38 ~8 ~35 ~38 ~9 ~35 stonebrick 2
fill ~43 ~8 ~35 ~59 ~8 ~35 stone
fill ~61 ~8 ~35 ~62 ~8 ~35 stone_slab 8
fill ~83 ~8 ~35 ~83 ~8 ~37 stone
fill ~33 ~8 ~36 ~34 ~8 ~36 stonebrick
fill ~35 ~8 ~36 ~35 ~8 ~37 stone_slab 8
fill ~38 ~8 ~36 ~38 ~8 ~37 stone_slab 8
setblock ~39 ~8 ~36 stonebrick
fill ~40 ~8 ~36 ~41 ~8 ~36 stonebrick 2
fill ~42 ~8 ~36 ~45 ~8 ~36 stonebrick
setblock ~46 ~8 ~36 stonebrick 1
fill ~47 ~8 ~36 ~48 ~8 ~36 stonebrick
fill ~49 ~8 ~36 ~49 ~8 ~40 stone
fill ~50 ~8 ~36 ~51 ~8 ~37 stonebrick
fill ~52 ~8 ~36 ~52 ~8 ~37 stonebrick 2
fill ~53 ~8 ~36 ~53 ~8 ~37 stonebrick
fill ~54 ~8 ~36 ~55 ~8 ~36 stonebrick 1
fill ~56 ~8 ~36 ~56 ~8 ~37 stonebrick
setblock ~57 ~8 ~36 stonebrick 2
fill ~58 ~8 ~36 ~58 ~8 ~37 stonebrick
fill ~59 ~8 ~36 ~59 ~8 ~37 stonebrick 2
fill ~60 ~8 ~36 ~60 ~8 ~37 stone_slab 8
fill ~63 ~8 ~36 ~63 ~8 ~37 stone_slab 8
setblock ~64 ~8 ~36 stonebrick 2
fill ~65 ~8 ~36 ~65 ~8 ~37 stonebrick
fill ~14 ~8 ~37 ~32 ~8 ~37 stone
fill ~33 ~8 ~37 ~34 ~8 ~37 stonebrick 2
setblock ~39 ~8 ~37 stonebrick 2
setblock ~40 ~8 ~37 stonebrick 1
setblock ~41 ~8 ~37 stonebrick 2
fill ~42 ~8 ~37 ~43 ~8 ~37 stonebrick
setblock ~44 ~8 ~37 stonebrick 2
fill ~45 ~8 ~37 ~46 ~8 ~37 stonebrick
fill ~47 ~8 ~37 ~48 ~8 ~37 stonebrick 2
setblock ~54 ~8 ~37 stonebrick
setblock ~55 ~8 ~37 stonebrick 2
fill ~57 ~8 ~37 ~58 ~8 ~37 stonebrick
fill ~64 ~8 ~37 ~65 ~8 ~37 stonebrick
fill ~19 ~8 ~38 ~34 ~8 ~38 stone
fill ~36 ~8 ~38 ~37 ~8 ~38 stone_slab 8
fill ~46 ~8 ~38 ~46 ~8 ~40 stone
fill ~47 ~8 ~38 ~48 ~8 ~39 stonebrick
setblock ~50 ~8 ~38 stonebrick 1
fill ~51 ~8 ~38 ~51 ~8 ~42 stonebrick
fill ~52 ~8 ~38 ~59 ~8 ~40 stone
fill ~61 ~8 ~38 ~62 ~8 ~38 stone_slab 8
fill ~63 ~8 ~38 ~63 ~9 ~38 stonebrick 2
fill ~79 ~8 ~38 ~79 ~9 ~38 stone
fill ~81 ~8 ~38 ~81 ~9 ~38 stone 6
fill ~22 ~8 ~39 ~35 ~8 ~39 stone
fill ~36 ~8 ~39 ~37 ~8 ~39 stonebrick 2
fill ~41 ~8 ~39 ~42 ~9 ~42 stone
fill ~44 ~8 ~39 ~46 ~8 ~40 stone
setblock ~50 ~8 ~39 stonebrick 2
setblock ~61 ~8 ~39 stonebrick 2
fill ~72 ~8 ~39 ~76 ~10 ~39 stone
fill ~24 ~8 ~40 ~34 ~10 ~40 stone
fill ~36 ~8 ~40 ~37 ~8 ~40 stonebrick
fill ~40 ~8 ~40 ~43 ~9 ~40 stone
setblock ~47 ~8 ~40 stonebrick 2
fill ~48 ~8 ~40 ~48 ~8 ~41 stonebrick
fill ~50 ~8 ~40 ~51 ~8 ~40 stonebrick
setblock ~61 ~8 ~40 stonebrick 1
fill ~62 ~8 ~40 ~62 ~8 ~41 stonebrick 2
fill ~65 ~8 ~40 ~65 ~10 ~59 stone
fill ~68 ~8 ~40 ~73 ~10 ~40 stone
fill ~27 ~8 ~41 ~35 ~8 ~41 stone
setblock ~36 ~8 ~41 stonebrick 2
fill ~37 ~8 ~41 ~37 ~8 ~42 stonebrick
fill ~43 ~8 ~41 ~43 ~8 ~42 stone
setblock ~44 ~8 ~41 stonebrick 1
fill ~45 ~8 ~41 ~45 ~8 ~43 stonebrick
fill ~46 ~8 ~41 ~46 ~8 ~42 stonebrick 2
fill ~47 ~8 ~41 ~49 ~8 ~41 stonebrick
setblock ~50 ~8 ~41 stonebrick 2
setblock ~53 ~8 ~41 stonebrick 2
fill ~54 ~8 ~41 ~54 ~8 ~43 stonebrick
fill ~55 ~8 ~41 ~60 ~8 ~42 stone
fill ~61 ~8 ~41 ~62 ~8 ~41 stonebrick 2
fill ~68 ~8 ~41 ~71 ~9 ~41 stone
fill ~29 ~8 ~42 ~35 ~8 ~42 stone
fill ~36 ~8 ~42 ~37 ~8 ~42 stonebrick
fill ~38 ~8 ~42 ~40 ~8 ~46 stone
fill ~44 ~8 ~42 ~45 ~8 ~43 stonebrick
setblock ~47 ~8 ~42 stonebrick
fill ~48 ~8 ~42 ~48 ~8 ~43 stone_slab 13
fill ~49 ~8 ~42 ~49 ~8 ~43 double_stone_slab 5
fill ~50 ~8 ~42 ~50 ~8 ~43 stone_slab 13
fill ~52 ~8 ~42 ~54 ~8 ~42 stonebrick
fill ~61 ~8 ~42 ~62 ~8 ~43 stonebrick
fill ~64 ~8 ~42 ~66 ~10 ~47 stone
fill ~68 ~8 ~42 ~68 ~10 ~42 stone
setblock ~69 ~8 ~42 stone
fill ~36 ~8 ~43 ~36 ~8 ~44 stonebrick 1
setblock ~37 ~8 ~43 stonebrick 2
fill ~41 ~8 ~43 ~42 ~8 ~43 stone
fill ~43 ~8 ~43 ~45 ~8 ~43 stonebrick
setblock ~46 ~8 ~43 stone_slab 13
setblock ~52 ~8 ~43 stone_slab 13
fill ~53 ~8 ~43 ~55 ~8 ~43 stonebrick
fill ~56 ~8 ~43 ~60 ~8 ~43 stone
fill ~69 ~8 ~43 ~69 ~10 ~43 leaves 10
fill ~31 ~8 ~44 ~34 ~9 ~44 stone
fill ~37 ~8 ~44 ~37 ~8 ~45 stonebrick
fill ~41 ~8 ~44 ~43 ~8 ~44 stonebrick
setblock ~44 ~8 ~44 stonebrick 1
setblock ~45 ~8 ~44 stone_slab 13
setblock ~49 ~8 ~44 stone_slab 13
setblock ~53 ~8 ~44 stone_slab 13
setblock ~54 ~8 ~44 stonebrick 1
fill ~55 ~8 ~44 ~56 ~8 ~45 stonebrick
setblock ~57 ~8 ~44 stonebrick 1
fill ~58 ~8 ~44 ~60 ~8 ~46 stone
setblock ~61 ~8 ~44 stonebrick 2
fill ~62 ~8 ~44 ~62 ~8 ~45 stonebrick
setblock ~68 ~8 ~44 leaves 10
fill ~35 ~8 ~45 ~35 ~8 ~59 stone
fill ~36 ~8 ~45 ~37 ~8 ~45 stonebrick
setblock ~41 ~8 ~45 stonebrick 2
fill ~42 ~8 ~45 ~42 ~8 ~47 stonebrick
setblock ~43 ~8 ~45 stonebrick
setblock ~44 ~8 ~45 stone_slab 13
setblock ~54 ~8 ~45 stone_slab 13
setblock ~57 ~8 ~45 stonebrick
fill ~61 ~8 ~45 ~62 ~8 ~45 stonebrick
fill ~23 ~8 ~46 ~23 ~10 ~52 stone
fill ~33 ~8 ~46 ~35 ~8 ~59 stone
fill ~36 ~8 ~46 ~37 ~8 ~46 stonebrick 2
setblock ~43 ~8 ~46 stone_slab 13
setblock ~49 ~8 ~46 stone_slab 13
setblock ~55 ~8 ~46 stone_slab 13
fill ~56 ~8 ~46 ~57 ~8 ~46 stonebrick 2
setblock ~61 ~8 ~46 stonebrick
setblock ~62 ~8 ~46 stonebrick 1
fill ~75 ~8 ~46 ~75 ~10 ~52 stone
fill ~36 ~8 ~47 ~42 ~8 ~47 stonebrick
fill ~56 ~8 ~47 ~57 ~8 ~47 stonebrick
setblock ~58 ~8 ~47 stonebrick 2
fill ~59 ~8 ~47 ~60 ~8 ~48 stonebrick
fill ~61 ~8 ~47 ~61 ~8 ~48 stonebrick 2
fill ~62 ~8 ~47 ~62 ~8 ~48 stonebrick
fill ~74 ~8 ~47 ~75 ~10 ~49 stone
fill ~36 ~8 ~48 ~37 ~8 ~48 stonebrick
setblock ~38 ~8 ~48 stonebrick 1
setblock ~39 ~8 ~48 stonebrick 2
setblock ~40 ~8 ~48 stonebrick
setblock ~41 ~8 ~48 stonebrick 2
fill ~42 ~8 ~48 ~43 ~8 ~48 stone_slab 13
setblock ~56 ~8 ~48 stone_slab 13
fill ~57 ~8 ~48 ~60 ~8 ~48 stonebrick
fill ~64 ~8 ~48 ~65 ~8 ~60 stone
fill ~66 ~8 ~48 ~67 ~10 ~49 stone
fill ~76 ~8 ~48 ~76 ~10 ~50 stone
fill ~25 ~8 ~49 ~25 ~10 ~49 stone
fill ~30 ~8 ~49 ~35 ~10 ~49 stone
fill ~36 ~8 ~49 ~40 ~8 ~49 stone
fill ~41 ~8 ~49 ~41 ~8 ~51 stonebrick
fill ~42 ~8 ~49 ~43 ~8 ~49 double_stone_slab 5
setblock ~44 ~8 ~49 stone_slab 13
setblock ~46 ~8 ~49 stone_slab 13
setblock ~52 ~8 ~49 stone_slab 13
setblock ~55 ~8 ~49 stone_slab 13
setblock ~56 ~8 ~49 double_stone_slab 5
setblock ~57 ~8 ~49 stonebrick
fill ~58 ~8 ~49 ~68 ~8 ~49 stone
fill ~73 ~8 ~49 ~76 ~10 ~49 stone
fill ~22 ~8 ~50 ~24 ~10 ~50 stone
fill ~31 ~8 ~50 ~33 ~10 ~50 stone
fill ~36 ~8 ~50 ~36 ~8 ~51 stonebrick
fill ~37 ~8 ~50 ~37 ~8 ~51 stonebrick 2
fill ~38 ~8 ~50 ~41 ~8 ~50 stonebrick
fill ~42 ~8 ~50 ~43 ~8 ~50 stone_slab 13
setblock ~51 ~8 ~50 stone
setblock ~56 ~8 ~50 stone_slab 13
setblock ~57 ~8 ~50 stonebrick 2
fill ~58 ~8 ~50 ~58 ~8 ~51 stonebrick
setblock ~59 ~8 ~50 stonebrick 2
setblock ~60 ~8 ~50 stonebrick 1
fill ~61 ~8 ~50 ~62 ~8 ~51 stonebrick
fill ~24 ~8 ~51 ~24 ~10 ~51 stone
fill ~32 ~8 ~51 ~34 ~10 ~59 stone
fill ~38 ~8 ~51 ~39 ~8 ~51 stonebrick
setblock ~40 ~8 ~51 stonebrick 2
setblock ~42 ~8 ~51 stonebrick
setblock ~49 ~8 ~51 stone
fill ~56 ~8 ~51 ~62 ~8 ~51 stonebrick
fill ~66 ~8 ~51 ~66 ~10 ~60 stone
setblock ~36 ~8 ~52 stonebrick 1
fill ~37 ~8 ~52 ~37 ~8 ~53 stonebrick
fill ~38 ~8 ~52 ~40 ~8 ~59 stone
fill ~41 ~8 ~52 ~42 ~8 ~52 stonebrick 2
setblock ~43 ~8 ~52 stone_slab 13
setblock ~49 ~8 ~52 stone_slab 13
setblock ~55 ~8 ~52 stone_slab 13
fill ~56 ~8 ~52 ~56 ~8 ~54 stonebrick
fill ~58 ~8 ~52 ~60 ~8 ~59 stone
fill ~61 ~8 ~52 ~62 ~8 ~52 stonebrick 2
fill ~36 ~8 ~53 ~36 ~8 ~56 stonebrick
fill ~41 ~8 ~53 ~43 ~8 ~53 stonebrick
setblock ~44 ~8 ~53 stone_slab 13
setblock ~54 ~8 ~53 stone_slab 13
fill ~55 ~8 ~53 ~56 ~8 ~54 stonebrick
setblock ~57 ~8 ~53 stonebrick 2
fill ~61 ~8 ~53 ~62 ~8 ~53 stonebrick
setblock ~30 ~8 ~54 leaves 10
fill ~31 ~8 ~54 ~34 ~10 ~59 stone
setblock ~37 ~8 ~54 stonebrick 2
setblock ~41 ~8 ~54 stonebrick 1
fill ~42 ~8 ~54 ~43 ~8 ~54 stonebrick
setblock ~44 ~8 ~54 stonebrick 1
setblock ~45 ~8 ~54 stone_slab 13
fill ~49 ~8 ~54 ~49 ~8 ~55 stone_slab 13
setblock ~53 ~8 ~54 stone_slab 13
setblock ~54 ~8 ~54 stonebrick 1
setblock ~57 ~8 ~54 stonebrick
setblock ~61 ~8 ~54 stonebrick
fill ~62 ~8 ~54 ~62 ~8 ~55 stonebrick 1
fill ~67 ~8 ~54 ~67 ~9 ~68 stone
fill ~29 ~8 ~55 ~29 ~10 ~55 leaves 10
fill ~37 ~8 ~55 ~37 ~8 ~56 stonebrick
fill ~41 ~8 ~55 ~42 ~8 ~60 stone
fill ~43 ~8 ~55 ~45 ~8 ~55 stonebrick
setblock ~46 ~8 ~55 stone_slab 13
setblock ~52 ~8 ~55 stone_slab 13
fill ~53 ~8 ~55 ~55 ~8 ~55 stonebrick
fill ~56 ~8 ~55 ~60 ~8 ~59 stone
setblock ~61 ~8 ~55 stonebrick 2
fill ~29 ~8 ~56 ~35 ~8 ~59 stone
fill ~43 ~8 ~56 ~43 ~8 ~60 stone
fill ~44 ~8 ~56 ~47 ~8 ~56 stonebrick
setblock ~48 ~8 ~56 stone_slab 13
setblock ~49 ~8 ~56 double_stone_slab 5
setblock ~50 ~8 ~56 stone_slab 13
fill ~51 ~8 ~56 ~51 ~8 ~57 stonebrick
fill ~52 ~8 ~56 ~52 ~8 ~57 stonebrick 2
setblock ~54 ~8 ~56 stonebrick
fill ~55 ~8 ~56 ~59 ~8 ~60 stone
fill ~61 ~8 ~56 ~61 ~8 ~58 stonebrick
setblock ~62 ~8 ~56 stonebrick
fill ~68 ~8 ~56 ~69 ~8 ~71 stone
fill ~27 ~8 ~57 ~29 ~8 ~73 stone
fill ~36 ~8 ~57 ~37 ~8 ~57 stonebrick 2
setblock ~44 ~8 ~57 stonebrick
setblock ~45 ~8 ~57 stonebrick 2
setblock ~48 ~8 ~57 stonebrick 2
fill ~49 ~8 ~57 ~51 ~8 ~57 stonebrick
setblock ~53 ~8 ~57 stonebrick
setblock ~54 ~8 ~57 stonebrick 1
setblock ~62 ~8 ~57 stonebrick 2
fill ~71 ~8 ~57 ~71 ~8 ~73 stone
fill ~25 ~8 ~58 ~32 ~8 ~66 stone
setblock ~36 ~8 ~58 stonebrick 2
setblock ~37 ~8 ~58 stonebrick 1
fill ~44 ~8 ~58 ~46 ~8 ~60 stone
fill ~47 ~8 ~58 ~47 ~8 ~62 stonebrick
setblock ~48 ~8 ~58 stonebrick
fill ~49 ~8 ~58 ~49 ~8 ~68 stone
fill ~50 ~8 ~58 ~50 ~8 ~60 stonebrick
setblock ~51 ~8 ~58 stonebrick 2
fill ~52 ~8 ~58 ~59 ~8 ~60 stone
setblock ~62 ~8 ~58 stonebrick
fill ~72 ~8 ~58 ~74 ~9 ~65 stone
fill ~22 ~8 ~59 ~32 ~8 ~65 stone
setblock ~36 ~8 ~59 stonebrick
setblock ~37 ~8 ~59 stonebrick 2
setblock ~48 ~8 ~59 stonebrick 2
fill ~51 ~8 ~59 ~51 ~8 ~60 stonebrick
fill ~61 ~8 ~59 ~62 ~8 ~59 stonebrick 2
fill ~75 ~8 ~59 ~76 ~8 ~65 stone
fill ~17 ~8 ~60 ~17 ~9 ~60 stone 6
fill ~19 ~8 ~60 ~32 ~8 ~64 stone
fill ~33 ~8 ~60 ~34 ~8 ~60 stone
fill ~35 ~8 ~60 ~35 ~9 ~60 stonebrick 2
fill ~36 ~8 ~60 ~37 ~8 ~60 stone_slab 8
setblock ~48 ~8 ~60 stonebrick 1
fill ~61 ~8 ~60 ~62 ~8 ~60 stone_slab 8
fill ~79 ~8 ~60 ~79 ~8 ~64 stone
fill ~14 ~8 ~61 ~32 ~8 ~61 stone
fill ~33 ~8 ~61 ~34 ~8 ~61 stonebrick
fill ~35 ~8 ~61 ~35 ~8 ~62 stone_slab 8
fill ~38 ~8 ~61 ~38 ~8 ~62 stone_slab 8
fill ~39 ~8 ~61 ~39 ~8 ~62 stonebrick 2
fill ~40 ~8 ~61 ~42 ~8 ~61 stonebrick
setblock ~43 ~8 ~61 stonebrick 2
fill ~44 ~8 ~61 ~45 ~8 ~61 stonebrick
fill ~46 ~8 ~61 ~46 ~8 ~62 stonebrick 2
fill ~48 ~8 ~61 ~48 ~8 ~62 stonebrick
fill ~50 ~8 ~61 ~51 ~8 ~61 stonebrick 2
fill ~52 ~8 ~61 ~53 ~8 ~61 stonebrick
setblock ~54 ~8 ~61 stonebrick 2
fill ~55 ~8 ~61 ~56 ~8 ~62 stonebrick
fill ~57 ~8 ~61 ~57 ~8 ~62 stonebrick 2
setblock ~58 ~8 ~61 stonebrick 1
setblock ~59 ~8 ~61 stonebrick 2
fill ~60 ~8 ~61 ~60 ~8 ~62 stone_slab 8
fill ~63 ~8 ~61 ~63 ~8 ~62 stone_slab 8
fill ~64 ~8 ~61 ~65 ~8 ~61 stonebrick 2
fill ~15 ~8 ~62 ~32 ~8 ~63 stone
setblock ~33 ~8 ~62 stonebrick
setblock ~34 ~8 ~62 stonebrick 2
setblock ~40 ~8 ~62 stonebrick
setblock ~41 ~8 ~62 stonebrick 2
setblock ~42 ~8 ~62 stonebrick
fill ~43 ~8 ~62 ~44 ~8 ~62 stonebrick 1
setblock ~45 ~8 ~62 stonebrick
fill ~50 ~8 ~62 ~51 ~8 ~62 stonebrick
setblock ~52 ~8 ~62 stonebrick 1
fill ~53 ~8 ~62 ~56 ~8 ~62 stonebrick
setblock ~58 ~8 ~62 stonebrick 2
setblock ~65 ~8 ~62 stonebrick
fill ~36 ~8 ~63 ~37 ~8 ~63 stone_slab 8
fill ~45 ~8 ~63 ~59 ~8 ~65 stone
fill ~60 ~8 ~63 ~60 ~9 ~63 stonebrick 2
fill ~61 ~8 ~63 ~62 ~8 ~63 stone_slab 8
fill ~80 ~8 ~63 ~82 ~8 ~64 stone
setblock ~83 ~8 ~63 stone
fill ~16 ~8 ~64 ~35 ~8 ~64 stone
fill ~37 ~8 ~64 ~37 ~8 ~65 stonebrick 2
fill ~43 ~8 ~64 ~47 ~10 ~66 stone
fill ~61 ~8 ~64 ~61 ~8 ~65 stonebrick
setblock ~62 ~8 ~64 stonebrick 2
fill ~65 ~8 ~64 ~76 ~9 ~65 stone
fill ~78 ~8 ~64 ~82 ~8 ~64 stone
fill ~20 ~8 ~65 ~35 ~8 ~65 stone
setblock ~36 ~8 ~65 stonebrick
fill ~39 ~8 ~65 ~59 ~10 ~65 stone
setblock ~62 ~8 ~65 stonebrick
fill ~77 ~8 ~65 ~78 ~8 ~65 stone
fill ~7 ~8 ~66 ~7 ~9 ~66 leaves 10
fill ~8 ~8 ~66 ~8 ~10 ~66 stonebrick
setblock ~23 ~8 ~66 stone
fill ~50 ~8 ~66 ~59 ~10 ~66 stone
setblock ~75 ~8 ~66 stone
fill ~90 ~8 ~66 ~90 ~10 ~66 stonebrick
setblock ~9 ~8 ~67 dirt
fill ~26 ~8 ~67 ~44 ~8 ~67 stone
fill ~50 ~8 ~67 ~50 ~10 ~67 stone
fill ~54 ~8 ~67 ~60 ~10 ~67 stone
fill ~89 ~8 ~67 ~89 ~8 ~69 stone
setblock ~6 ~8 ~68 stone_slab 8
fill ~7 ~8 ~68 ~7 ~10 ~68 stonebrick
fill ~9 ~8 ~68 ~9 ~8 ~69 stone
setblock ~10 ~8 ~68 double_stone_slab
fill ~26 ~8 ~68 ~26 ~11 ~68 stone 6
fill ~40 ~8 ~68 ~40 ~10 ~74 stone
fill ~42 ~8 ~68 ~42 ~10 ~68 stone
setblock ~54 ~8 ~68 leaves 10
fill ~56 ~8 ~68 ~71 ~8 ~69 stone
fill ~72 ~8 ~68 ~72 ~11 ~68 stone 6
setblock ~88 ~8 ~68 double_stone_slab
fill ~91 ~8 ~68 ~91 ~9 ~68 stone
setblock ~92 ~8 ~68 stone_slab 8
setblock ~5 ~8 ~69 stone_slab 8
setblock ~7 ~8 ~69 stone
setblock ~8 ~8 ~69 stone_slab 8
fill ~10 ~8 ~69 ~10 ~8 ~70 stone
setblock ~11 ~8 ~69 double_stone_slab
fill ~25 ~8 ~69 ~29 ~8 ~72 stone
setblock ~42 ~8 ~69 stone
fill ~55 ~8 ~69 ~55 ~10 ~69 leaves 10
fill ~72 ~8 ~69 ~73 ~8 ~72 stone
setblock ~87 ~8 ~69 double_stone_slab
fill ~88 ~8 ~69 ~89 ~8 ~69 stone
setblock ~90 ~8 ~69 stone_slab 8
setblock ~93 ~8 ~69 stone_slab 8
setblock ~4 ~8 ~70 dirt
setblock ~7 ~8 ~70 double_stone_slab 5
setblock ~8 ~8 ~70 stone_slab 13
setblock ~9 ~8 ~70 diamond_ore
fill ~11 ~8 ~70 ~11 ~8 ~72 stone
setblock ~12 ~8 ~70 stone
fill ~57 ~8 ~70 ~66 ~9 ~71 stone
setblock ~86 ~8 ~70 dirt
fill ~87 ~8 ~70 ~88 ~8 ~70 stone
setblock ~89 ~8 ~70 diamond_ore
setblock ~90 ~8 ~70 stone_slab 13
setblock ~91 ~8 ~70 double_stone_slab 5
setblock ~94 ~8 ~70 dirt
setblock ~6 ~8 ~71 stone_slab 8
fill ~7 ~8 ~71 ~7 ~8 ~72 stone_slab 13
setblock ~8 ~8 ~71 double_stone_slab 5
setblock ~9 ~8 ~71 stone_slab 13
setblock ~10 ~8 ~71 stone_slab 8
fill ~13 ~8 ~71 ~13 ~10 ~71 stonebrick
fill ~41 ~8 ~71 ~41 ~10 ~71 stone
fill ~85 ~8 ~71 ~85 ~10 ~71 stonebrick
setblock ~88 ~8 ~71 stone_slab 8
setblock ~89 ~8 ~71 stone_slab 13
setblock ~90 ~8 ~71 double_stone_slab 5
fill ~91 ~8 ~71 ~91 ~8 ~72 stone_slab 13
setblock ~92 ~8 ~71 stone_slab 8
setblock ~4 ~8 ~72 dirt
setblock ~5 ~8 ~72 stone
setblock ~8 ~8 ~72 stone_slab 13
setblock ~9 ~8 ~72 double_stone_slab 5
fill ~30 ~8 ~72 ~30 ~11 ~72 stone 6
fill ~31 ~8 ~72 ~40 ~8 ~72 stone
fill ~58 ~8 ~72 ~60 ~10 ~73 stone
fill ~61 ~8 ~72 ~65 ~9 ~75 stone
fill ~68 ~8 ~72 ~68 ~11 ~72 stone 6
fill ~69 ~8 ~72 ~72 ~8 ~73 stone
fill ~85 ~8 ~72 ~85 ~9 ~72 leaves 10
fill ~87 ~8 ~72 ~87 ~10 ~72 stonebrick
fill ~88 ~8 ~72 ~88 ~8 ~73 stone
setblock ~89 ~8 ~72 double_stone_slab 5
fill ~90 ~8 ~72 ~91 ~8 ~72 stone_slab 13
setblock ~94 ~8 ~72 stone
setblock ~4 ~8 ~73 grass
setblock ~8 ~8 ~73 stone_slab 8
setblock ~11 ~8 ~73 stone_slab 8
fill ~26 ~8 ~73 ~29 ~8 ~73 stone
fill ~32 ~8 ~73 ~40 ~8 ~73 stone
fill ~49 ~8 ~73 ~49 ~10 ~76 stone
setblock ~87 ~8 ~73 stone_slab 8
setblock ~90 ~8 ~73 stone_slab 8
setblock ~94 ~8 ~73 grass
fill ~5 ~8 ~74 ~6 ~9 ~74 stonebrick
setblock ~10 ~8 ~74 stone_slab 8
fill ~51 ~8 ~74 ~51 ~10 ~75 stone
fill ~59 ~8 ~74 ~65 ~9 ~75 stone
setblock ~88 ~8 ~74 stone_slab 8
setblock ~91 ~8 ~74 stone
fill ~93 ~8 ~74 ~93 ~9 ~74 stonebrick
fill ~4 ~8 ~75 ~4 ~10 ~75 leaves 10
setblock ~6 ~8 ~75 grass
setblock ~7 ~8 ~75 stone
setblock ~9 ~8 ~75 dirt
fill ~17 ~8 ~75 ~17 ~9 ~75 leaves 10
fill ~18 ~8 ~75 ~18 ~9 ~75 stonebrick
fill ~32 ~8 ~75 ~39 ~8 ~75 stone
fill ~46 ~8 ~75 ~52 ~10 ~75 stone
setblock ~66 ~8 ~75 stone
fill ~80 ~8 ~75 ~80 ~10 ~75 stonebrick
setblock ~89 ~8 ~75 dirt
setblock ~91 ~8 ~75 dirt
setblock ~92 ~8 ~75 grass
fill ~94 ~8 ~75 ~94 ~10 ~75 leaves 10
setblock ~19 ~8 ~76 dirt
setblock ~39 ~8 ~76 stone
fill ~50 ~8 ~76 ~50 ~10 ~76 stone
fill ~59 ~8 ~76 ~65 ~8 ~76 stone
fill ~79 ~8 ~76 ~79 ~8 ~78 stone
setblock ~16 ~8 ~77 stone_slab 8
setblock ~17 ~8 ~77 stonebrick 2
fill ~19 ~8 ~77 ~19 ~8 ~78 stone
setblock ~20 ~8 ~77 double_stone_slab
fill ~33 ~8 ~77 ~38 ~8 ~78 stone
fill ~60 ~8 ~77 ~64 ~8 ~79 stone
fill ~65 ~8 ~77 ~65 ~8 ~78 stone
setblock ~78 ~8 ~77 double_stone_slab
fill ~81 ~8 ~77 ~81 ~9 ~77 stone
setblock ~82 ~8 ~77 stone_slab 8
setblock ~15 ~8 ~78 stone_slab 8
setblock ~17 ~8 ~78 stone
setblock ~18 ~8 ~78 stone_slab 8
fill ~20 ~8 ~78 ~20 ~8 ~79 stone
setblock ~21 ~8 ~78 double_stone_slab
setblock ~77 ~8 ~78 double_stone_slab
fill ~78 ~8 ~78 ~79 ~8 ~78 stone
setblock ~80 ~8 ~78 stone_slab 8
setblock ~83 ~8 ~78 stone_slab 8
setblock ~14 ~8 ~79 dirt
setblock ~17 ~8 ~79 double_stone_slab 5
setblock ~18 ~8 ~79 stone_slab 13
setblock ~19 ~8 ~79 diamond_ore
fill ~21 ~8 ~79 ~21 ~8 ~81 stone
setblock ~22 ~8 ~79 stone
fill ~34 ~8 ~79 ~37 ~8 ~82 stone
setblock ~38 ~8 ~79 stone
setblock ~76 ~8 ~79 dirt
fill ~77 ~8 ~79 ~78 ~8 ~79 stone
setblock ~79 ~8 ~79 diamond_ore
setblock ~80 ~8 ~79 stone_slab 13
setblock ~81 ~8 ~79 double_stone_slab 5
setblock ~84 ~8 ~79 dirt
setblock ~16 ~8 ~80 stone_slab 8
fill ~17 ~8 ~80 ~17 ~8 ~81 stone_slab 13
setblock ~18 ~8 ~80 double_stone_slab 5
setblock ~19 ~8 ~80 stone_slab 13
setblock ~20 ~8 ~80 stone_slab 8
fill ~23 ~8 ~80 ~23 ~10 ~80 stonebrick
fill ~75 ~8 ~80 ~76 ~8 ~80 stonebrick
setblock ~78 ~8 ~80 stone_slab 8
setblock ~79 ~8 ~80 stone_slab 13
setblock ~80 ~8 ~80 double_stone_slab 5
fill ~81 ~8 ~80 ~81 ~8 ~81 stone_slab 13
setblock ~82 ~8 ~80 stone_slab 8
setblock ~14 ~8 ~81 dirt
setblock ~15 ~8 ~81 stone
setblock ~18 ~8 ~81 stone_slab 13
setblock ~19 ~8 ~81 double_stone_slab 5
fill ~60 ~8 ~81 ~60 ~9 ~81 stone 6
fill ~75 ~8 ~81 ~75 ~9 ~81 leaves 10
setblock ~77 ~8 ~81 stonebrick 2
fill ~78 ~8 ~81 ~78 ~8 ~82 stone
setblock ~79 ~8 ~81 double_stone_slab 5
fill ~80 ~8 ~81 ~81 ~8 ~81 stone_slab 13
setblock ~84 ~8 ~81 stone
setblock ~14 ~8 ~82 grass
setblock ~18 ~8 ~82 stone_slab 8
setblock ~21 ~8 ~82 stone_slab 8
setblock ~64 ~8 ~82 stone
setblock ~77 ~8 ~82 stone_slab 8
setblock ~80 ~8 ~82 stone_slab 8
setblock ~84 ~8 ~82 grass
fill ~15 ~8 ~83 ~15 ~9 ~83 stone 3
setblock ~20 ~8 ~83 stone_slab 8
fill ~35 ~8 ~83 ~37 ~8 ~83 stone
fill ~62 ~8 ~83 ~62 ~11 ~83 stone
setblock ~63 ~8 ~83 stone
setblock ~78 ~8 ~83 stone_slab 8
setblock ~81 ~8 ~83 stone
fill ~83 ~8 ~83 ~83 ~9 ~83 stone 3
fill ~14 ~8 ~84 ~14 ~10 ~84 leaves 10
setblock ~16 ~8 ~84 grass
setblock ~17 ~8 ~84 stone
setblock ~19 ~8 ~84 dirt
setblock ~79 ~8 ~84 dirt
setblock ~81 ~8 ~84 dirt
setblock ~82 ~8 ~84 grass
fill ~84 ~8 ~84 ~84 ~10 ~84 leaves 10
fill ~26 ~8 ~85 ~26 ~9 ~85 leaves 10
fill ~27 ~8 ~85 ~27 ~10 ~85 stonebrick
fill ~71 ~8 ~85 ~71 ~10 ~85 stonebrick
setblock ~28 ~8 ~86 dirt
fill ~70 ~8 ~86 ~70 ~8 ~88 stone
setblock ~25 ~8 ~87 stone_slab 8
fill ~26 ~8 ~87 ~26 ~10 ~87 stonebrick
fill ~28 ~8 ~87 ~28 ~8 ~88 stone
setblock ~29 ~8 ~87 double_stone_slab
setblock ~69 ~8 ~87 double_stone_slab
fill ~72 ~8 ~87 ~72 ~9 ~87 stone
setblock ~73 ~8 ~87 stone_slab 8
setblock ~24 ~8 ~88 stone_slab 8
setblock ~26 ~8 ~88 stone
setblock ~27 ~8 ~88 stone_slab 8
fill ~29 ~8 ~88 ~29 ~8 ~89 stone
setblock ~30 ~8 ~88 double_stone_slab
setblock ~68 ~8 ~88 double_stone_slab
fill ~69 ~8 ~88 ~70 ~8 ~88 stone
setblock ~71 ~8 ~88 stone_slab 8
setblock ~74 ~8 ~88 stone_slab 8
setblock ~23 ~8 ~89 dirt
setblock ~26 ~8 ~89 double_stone_slab 5
setblock ~27 ~8 ~89 stone_slab 13
setblock ~28 ~8 ~89 diamond_ore
fill ~30 ~8 ~89 ~30 ~8 ~91 stone
setblock ~31 ~8 ~89 stone
setblock ~67 ~8 ~89 dirt
fill ~68 ~8 ~89 ~69 ~8 ~89 stone
setblock ~70 ~8 ~89 diamond_ore
setblock ~71 ~8 ~89 stone_slab 13
setblock ~72 ~8 ~89 double_stone_slab 5
setblock ~75 ~8 ~89 dirt
setblock ~25 ~8 ~90 stone_slab 8
fill ~26 ~8 ~90 ~26 ~8 ~91 stone_slab 13
setblock ~27 ~8 ~90 double_stone_slab 5
setblock ~28 ~8 ~90 stone_slab 13
setblock ~29 ~8 ~90 stone_slab 8
fill ~32 ~8 ~90 ~32 ~10 ~90 stonebrick
fill ~66 ~8 ~90 ~66 ~10 ~90 stonebrick
setblock ~69 ~8 ~90 stone_slab 8
setblock ~70 ~8 ~90 stone_slab 13
setblock ~71 ~8 ~90 double_stone_slab 5
fill ~72 ~8 ~90 ~72 ~8 ~91 stone_slab 13
setblock ~73 ~8 ~90 stone_slab 8
setblock ~23 ~8 ~91 dirt
setblock ~24 ~8 ~91 stone
setblock ~27 ~8 ~91 stone_slab 13
setblock ~28 ~8 ~91 double_stone_slab 5
fill ~66 ~8 ~91 ~66 ~9 ~91 leaves 10
fill ~68 ~8 ~91 ~68 ~10 ~91 stonebrick
fill ~69 ~8 ~91 ~69 ~8 ~92 stone
setblock ~70 ~8 ~91 double_stone_slab 5
fill ~71 ~8 ~91 ~72 ~8 ~91 stone_slab 13
setblock ~75 ~8 ~91 stone
setblock ~23 ~8 ~92 grass
setblock ~27 ~8 ~92 stone_slab 8
setblock ~30 ~8 ~92 stone_slab 8
setblock ~68 ~8 ~92 stone_slab 8
setblock ~71 ~8 ~92 stone_slab 8
setblock ~75 ~8 ~92 grass
fill ~24 ~8 ~93 ~25 ~9 ~93 stonebrick
setblock ~29 ~8 ~93 stone_slab 8
setblock ~69 ~8 ~93 stone_slab 8
setblock ~72 ~8 ~93 stone
fill ~74 ~8 ~93 ~74 ~9 ~93 stonebrick
fill ~23 ~8 ~94 ~23 ~10 ~94 leaves 10
setblock ~25 ~8 ~94 grass
setblock ~26 ~8 ~94 stone
setblock ~28 ~8 ~94 dirt
setblock ~70 ~8 ~94 dirt
setblock ~72 ~8 ~94 dirt
setblock ~73 ~8 ~94 grass
fill ~75 ~8 ~94 ~75 ~10 ~94 leaves 10
fill ~25 ~9 ~2 ~25 ~12 ~2 leaves 10
fill ~26 ~9 ~4 ~26 ~9 ~5 grass
setblock ~28 ~9 ~4 grass
setblock ~70 ~9 ~4 grass
fill ~72 ~9 ~4 ~72 ~9 ~5 grass
fill ~27 ~9 ~5 ~27 ~10 ~5 log 0
fill ~71 ~9 ~5 ~71 ~10 ~5 log 0
fill ~26 ~9 ~6 ~26 ~9 ~7 stonebrick
setblock ~27 ~9 ~6 grass
fill ~28 ~9 ~6 ~28 ~9 ~8 stonebrick
setblock ~29 ~9 ~6 stone_slab
setblock ~69 ~9 ~6 stone_slab
fill ~70 ~9 ~6 ~70 ~9 ~8 stonebrick
setblock ~71 ~9 ~6 grass
fill ~72 ~9 ~6 ~72 ~9 ~7 stonebrick
fill ~77 ~9 ~6 ~77 ~12 ~6 leaves 10
fill ~23 ~9 ~7 ~24 ~9 ~7 grass
fill ~25 ~9 ~7 ~26 ~9 ~7 stonebrick
fill ~27 ~9 ~7 ~27 ~9 ~8 stone 6
fill ~29 ~9 ~7 ~30 ~9 ~7 stonebrick
fill ~31 ~9 ~7 ~31 ~9 ~9 grass
fill ~67 ~9 ~7 ~67 ~9 ~9 grass
setblock ~68 ~9 ~7 stone
fill ~69 ~9 ~7 ~70 ~9 ~7 stonebrick
fill ~71 ~9 ~7 ~71 ~9 ~8 stone 6
setblock ~73 ~9 ~7 stonebrick
fill ~74 ~9 ~7 ~75 ~9 ~7 grass
fill ~24 ~9 ~8 ~24 ~10 ~8 log 0
setblock ~25 ~9 ~8 grass
fill ~26 ~9 ~8 ~27 ~9 ~8 stone 6
fill ~29 ~9 ~8 ~31 ~9 ~8 grass
fill ~68 ~9 ~8 ~69 ~9 ~8 grass
setblock ~72 ~9 ~8 stone 6
setblock ~73 ~9 ~8 grass
fill ~74 ~9 ~8 ~74 ~10 ~8 log 0
setblock ~23 ~9 ~9 grass
fill ~25 ~9 ~9 ~27 ~9 ~9 stonebrick
setblock ~28 ~9 ~9 stone 6
setblock ~29 ~9 ~9 stonebrick
fill ~30 ~9 ~9 ~31 ~9 ~9 grass
setblock ~68 ~9 ~9 grass
setblock ~69 ~9 ~9 stonebrick
setblock ~70 ~9 ~9 stone 6
fill ~71 ~9 ~9 ~74 ~9 ~9 stonebrick
setblock ~75 ~9 ~9 grass
setblock ~25 ~9 ~10 stone_slab
setblock ~26 ~9 ~10 stonebrick
fill ~27 ~9 ~10 ~27 ~9 ~12 grass
setblock ~28 ~9 ~10 stonebrick
fill ~29 ~9 ~10 ~30 ~9 ~10 stone_slab
fill ~68 ~9 ~10 ~69 ~9 ~10 stone_slab
setblock ~70 ~9 ~10 stonebrick
fill ~71 ~9 ~10 ~71 ~9 ~12 grass
fill ~72 ~9 ~10 ~72 ~9 ~11 stonebrick
setblock ~73 ~9 ~10 stone_slab
setblock ~26 ~9 ~11 stone
fill ~28 ~9 ~11 ~28 ~9 ~12 grass
setblock ~29 ~9 ~11 stone_slab
setblock ~69 ~9 ~11 stone_slab
fill ~70 ~9 ~11 ~71 ~9 ~12 grass
fill ~16 ~9 ~12 ~16 ~12 ~12 leaves 10
fill ~26 ~9 ~12 ~28 ~9 ~12 grass
setblock ~72 ~9 ~12 grass
fill ~17 ~9 ~14 ~17 ~9 ~15 grass
setblock ~19 ~9 ~14 grass
fill ~37 ~9 ~14 ~37 ~10 ~15 stone
fill ~61 ~9 ~14 ~61 ~10 ~15 stone
setblock ~79 ~9 ~14 grass
fill ~81 ~9 ~14 ~81 ~9 ~15 grass
fill ~18 ~9 ~15 ~18 ~10 ~15 log 0
fill ~35 ~9 ~15 ~35 ~9 ~16 stone_slab
fill ~36 ~9 ~15 ~38 ~11 ~15 stone
fill ~62 ~9 ~15 ~62 ~11 ~15 stone
fill ~63 ~9 ~15 ~63 ~9 ~16 stone_slab
fill ~80 ~9 ~15 ~80 ~10 ~15 log 0
fill ~17 ~9 ~16 ~17 ~9 ~17 stonebrick
setblock ~18 ~9 ~16 grass
fill ~19 ~9 ~16 ~19 ~9 ~18 stonebrick
setblock ~20 ~9 ~16 stone_slab
fill ~34 ~9 ~16 ~35 ~9 ~16 stone_slab
fill ~36 ~9 ~16 ~36 ~9 ~17 stonebrick
setblock ~37 ~9 ~16 stone
setblock ~61 ~9 ~16 stone
fill ~62 ~9 ~16 ~62 ~9 ~17 stonebrick
fill ~64 ~9 ~16 ~64 ~9 ~17 stone_slab
setblock ~78 ~9 ~16 stone_slab
fill ~79 ~9 ~16 ~79 ~9 ~18 stonebrick
setblock ~80 ~9 ~16 grass
fill ~81 ~9 ~16 ~81 ~9 ~17 stonebrick
fill ~86 ~9 ~16 ~86 ~12 ~16 leaves 10
fill ~14 ~9 ~17 ~15 ~9 ~17 grass
fill ~16 ~9 ~17 ~17 ~9 ~17 stonebrick
fill ~18 ~9 ~17 ~18 ~9 ~18 stone 6
fill ~20 ~9 ~17 ~21 ~9 ~17 stonebrick
fill ~22 ~9 ~17 ~22 ~9 ~19 grass
setblock ~34 ~9 ~17 stone_slab
setblock ~35 ~9 ~17 stonebrick 2
fill ~37 ~9 ~17 ~37 ~9 ~20 grass
fill ~60 ~9 ~17 ~60 ~11 ~17 stonebrick
fill ~61 ~9 ~17 ~61 ~9 ~20 grass
fill ~63 ~9 ~17 ~63 ~9 ~19 stonebrick
fill ~76 ~9 ~17 ~76 ~9 ~19 grass
setblock ~77 ~9 ~17 stone
fill ~78 ~9 ~17 ~79 ~9 ~17 stonebrick
fill ~80 ~9 ~17 ~80 ~9 ~18 stone 6
setblock ~82 ~9 ~17 stonebrick
fill ~83 ~9 ~17 ~84 ~9 ~17 grass
fill ~15 ~9 ~18 ~15 ~10 ~18 log 0
setblock ~16 ~9 ~18 grass
fill ~17 ~9 ~18 ~18 ~9 ~18 stone 6
fill ~20 ~9 ~18 ~22 ~9 ~18 grass
fill ~34 ~9 ~18 ~34 ~9 ~20 stonebrick
setblock ~35 ~9 ~18 stonebrick
fill ~36 ~9 ~18 ~36 ~9 ~19 stone 6
fill ~38 ~9 ~18 ~38 ~10 ~18 stonebrick
fill ~39 ~9 ~18 ~39 ~11 ~18 leaves 10
fill ~60 ~9 ~18 ~60 ~11 ~18 stonebrick 2
fill ~62 ~9 ~18 ~62 ~9 ~19 stone 6
fill ~64 ~9 ~18 ~64 ~9 ~19 stonebrick
fill ~77 ~9 ~18 ~78 ~9 ~18 grass
setblock ~81 ~9 ~18 stone 6
setblock ~82 ~9 ~18 grass
fill ~83 ~9 ~18 ~83 ~10 ~18 log 0
setblock ~14 ~9 ~19 grass
fill ~16 ~9 ~19 ~18 ~9 ~19 stonebrick
setblock ~19 ~9 ~19 stone 6
setblock ~20 ~9 ~19 stonebrick 2
fill ~21 ~9 ~19 ~22 ~9 ~19 grass
setblock ~35 ~9 ~19 stonebrick 2
fill ~59 ~9 ~19 ~59 ~11 ~19 leaves 10
fill ~60 ~9 ~19 ~60 ~11 ~20 stonebrick
setblock ~77 ~9 ~19 grass
setblock ~78 ~9 ~19 stonebrick 2
setblock ~79 ~9 ~19 stone 6
fill ~80 ~9 ~19 ~83 ~9 ~19 stonebrick
setblock ~84 ~9 ~19 grass
setblock ~16 ~9 ~20 stone_slab
setblock ~17 ~9 ~20 stonebrick
fill ~18 ~9 ~20 ~18 ~9 ~22 grass
setblock ~19 ~9 ~20 stonebrick 2
fill ~20 ~9 ~20 ~21 ~9 ~20 stone_slab
fill ~33 ~9 ~20 ~33 ~9 ~21 dirt
setblock ~35 ~9 ~20 stone 6
setblock ~36 ~9 ~20 stonebrick
setblock ~62 ~9 ~20 stonebrick
setblock ~63 ~9 ~20 stone 6
setblock ~64 ~9 ~20 stonebrick 2
fill ~65 ~9 ~20 ~65 ~9 ~21 dirt
fill ~77 ~9 ~20 ~78 ~9 ~20 stone_slab
setblock ~79 ~9 ~20 stonebrick 2
fill ~80 ~9 ~20 ~80 ~9 ~22 grass
fill ~81 ~9 ~20 ~81 ~9 ~21 stonebrick
setblock ~82 ~9 ~20 stone_slab
fill ~6 ~9 ~21 ~6 ~12 ~21 leaves 10
setblock ~17 ~9 ~21 stone
fill ~19 ~9 ~21 ~19 ~9 ~22 grass
setblock ~20 ~9 ~21 stone_slab
fill ~34 ~9 ~21 ~37 ~9 ~21 dirt
fill ~39 ~9 ~21 ~39 ~10 ~34 stone
fill ~49 ~9 ~21 ~49 ~10 ~35 stone
fill ~59 ~9 ~21 ~59 ~10 ~21 stone
fill ~60 ~9 ~21 ~60 ~10 ~21 stonebrick 2
fill ~61 ~9 ~21 ~63 ~9 ~22 dirt
fill ~64 ~9 ~21 ~65 ~9 ~21 dirt
setblock ~78 ~9 ~21 stone_slab
fill ~79 ~9 ~21 ~80 ~9 ~22 grass
fill ~17 ~9 ~22 ~19 ~9 ~22 grass
fill ~33 ~9 ~22 ~34 ~9 ~34 stone
fill ~35 ~9 ~22 ~37 ~9 ~22 dirt
fill ~40 ~9 ~22 ~40 ~10 ~34 stone
fill ~47 ~9 ~22 ~51 ~10 ~23 stone
setblock ~59 ~9 ~22 stonebrick
fill ~60 ~9 ~22 ~60 ~9 ~32 stone
fill ~64 ~9 ~22 ~65 ~9 ~34 stone
setblock ~81 ~9 ~22 grass
fill ~7 ~9 ~23 ~7 ~9 ~24 grass
setblock ~9 ~9 ~23 grass
setblock ~32 ~9 ~23 dirt
fill ~41 ~9 ~23 ~41 ~11 ~23 stone
fill ~45 ~9 ~23 ~53 ~10 ~23 stone
fill ~57 ~9 ~23 ~65 ~9 ~23 stone
setblock ~66 ~9 ~23 dirt
setblock ~89 ~9 ~23 grass
fill ~91 ~9 ~23 ~91 ~9 ~24 grass
fill ~8 ~9 ~24 ~8 ~10 ~24 log 0
fill ~90 ~9 ~24 ~90 ~10 ~24 log 0
fill ~7 ~9 ~25 ~7 ~9 ~26 stonebrick
setblock ~8 ~9 ~25 grass
fill ~9 ~9 ~25 ~9 ~9 ~27 stonebrick
setblock ~10 ~9 ~25 stone_slab
fill ~26 ~9 ~25 ~27 ~9 ~25 stone_slab
fill ~28 ~9 ~25 ~29 ~9 ~25 grass
fill ~32 ~9 ~25 ~32 ~10 ~25 prismarine 2
fill ~48 ~9 ~25 ~49 ~10 ~25 stone
fill ~66 ~9 ~25 ~66 ~10 ~25 prismarine 2
fill ~69 ~9 ~25 ~70 ~9 ~25 grass
fill ~71 ~9 ~25 ~72 ~9 ~25 stone_slab
setblock ~88 ~9 ~25 stone_slab
fill ~89 ~9 ~25 ~89 ~9 ~27 stonebrick
setblock ~90 ~9 ~25 grass
fill ~91 ~9 ~25 ~91 ~9 ~26 stonebrick
fill ~96 ~9 ~25 ~96 ~12 ~25 leaves 10
fill ~4 ~9 ~26 ~5 ~9 ~26 grass
fill ~6 ~9 ~26 ~7 ~9 ~26 stonebrick
fill ~8 ~9 ~26 ~8 ~9 ~27 stone 6
fill ~10 ~9 ~26 ~11 ~9 ~26 stonebrick
fill ~12 ~9 ~26 ~12 ~9 ~28 grass
fill ~25 ~9 ~26 ~26 ~9 ~26 stone_slab
fill ~27 ~9 ~26 ~28 ~9 ~26 stonebrick
setblock ~29 ~9 ~26 grass
fill ~31 ~9 ~26 ~31 ~11 ~26 prismarine 2
fill ~41 ~9 ~26 ~41 ~9 ~34 stone
fill ~57 ~9 ~26 ~66 ~9 ~31 stone
fill ~67 ~9 ~26 ~67 ~11 ~26 prismarine 2
setblock ~69 ~9 ~26 grass
fill ~70 ~9 ~26 ~71 ~9 ~26 stonebrick
fill ~72 ~9 ~26 ~73 ~9 ~26 stone_slab
fill ~86 ~9 ~26 ~86 ~9 ~28 grass
setblock ~87 ~9 ~26 stone
fill ~88 ~9 ~26 ~89 ~9 ~26 stonebrick
fill ~90 ~9 ~26 ~90 ~9 ~27 stone 6
setblock ~92 ~9 ~26 stonebrick
fill ~93 ~9 ~26 ~94 ~9 ~26 grass
fill ~5 ~9 ~27 ~5 ~10 ~27 log 0
setblock ~6 ~9 ~27 grass
fill ~7 ~9 ~27 ~8 ~9 ~27 stone 6
fill ~10 ~9 ~27 ~12 ~9 ~27 grass
setblock ~25 ~9 ~27 stone_slab
fill ~26 ~9 ~27 ~26 ~9 ~28 stonebrick
setblock ~27 ~9 ~27 stone 6
setblock ~28 ~9 ~27 stonebrick 2
fill ~29 ~9 ~27 ~30 ~9 ~27 stonebrick
fill ~31 ~9 ~27 ~31 ~9 ~29 dirt
fill ~67 ~9 ~27 ~67 ~9 ~29 dirt
fill ~68 ~9 ~27 ~69 ~9 ~27 stonebrick 2
setblock ~70 ~9 ~27 stonebrick
setblock ~71 ~9 ~27 stone 6
fill ~72 ~9 ~27 ~72 ~9 ~28 stonebrick
setblock ~73 ~9 ~27 stone_slab
fill ~87 ~9 ~27 ~88 ~9 ~27 grass
setblock ~91 ~9 ~27 stone 6
setblock ~92 ~9 ~27 grass
fill ~93 ~9 ~27 ~93 ~10 ~27 log 0
setblock ~4 ~9 ~28 grass
fill ~6 ~9 ~28 ~8 ~9 ~28 stonebrick
setblock ~9 ~9 ~28 stone 6
setblock ~10 ~9 ~28 stonebrick
fill ~11 ~9 ~28 ~12 ~9 ~28 grass
fill ~25 ~9 ~28 ~25 ~9 ~29 grass
setblock ~27 ~9 ~28 stonebrick
fill ~28 ~9 ~28 ~29 ~9 ~28 stone 6
setblock ~30 ~9 ~28 stonebrick 2
setblock ~68 ~9 ~28 stonebrick
fill ~69 ~9 ~28 ~70 ~9 ~28 stone 6
setblock ~71 ~9 ~28 stonebrick 2
fill ~73 ~9 ~28 ~73 ~9 ~29 grass
setblock ~87 ~9 ~28 grass
setblock ~88 ~9 ~28 stonebrick
setblock ~89 ~9 ~28 stone 6
fill ~90 ~9 ~28 ~93 ~9 ~28 stonebrick
setblock ~94 ~9 ~28 grass
setblock ~6 ~9 ~29 stone_slab
setblock ~7 ~9 ~29 stonebrick
fill ~8 ~9 ~29 ~8 ~9 ~31 grass
setblock ~9 ~9 ~29 stonebrick
fill ~10 ~9 ~29 ~11 ~9 ~29 stone_slab
setblock ~26 ~9 ~29 grass
fill ~27 ~9 ~29 ~27 ~9 ~30 stonebrick 2
setblock ~28 ~9 ~29 stone 6
setblock ~29 ~9 ~29 prismarine 2
setblock ~30 ~9 ~29 prismarine
fill ~42 ~9 ~29 ~42 ~10 ~29 dirt
fill ~48 ~9 ~29 ~50 ~10 ~33 stone
fill ~55 ~9 ~29 ~55 ~11 ~29 leaves 10
fill ~56 ~9 ~29 ~56 ~10 ~29 dirt
setblock ~68 ~9 ~29 prismarine
setblock ~69 ~9 ~29 prismarine 2
setblock ~70 ~9 ~29 stone 6
fill ~71 ~9 ~29 ~71 ~9 ~30 stonebrick
fill ~72 ~9 ~29 ~73 ~9 ~29 grass
fill ~87 ~9 ~29 ~88 ~9 ~29 stone_slab
setblock ~89 ~9 ~29 stonebrick
fill ~90 ~9 ~29 ~90 ~9 ~31 grass
fill ~91 ~9 ~29 ~91 ~9 ~30 stonebrick
setblock ~92 ~9 ~29 stone_slab
setblock ~7 ~9 ~30 stone
fill ~9 ~9 ~30 ~9 ~9 ~31 grass
setblock ~10 ~9 ~30 stone_slab
setblock ~28 ~9 ~30 stonebrick
setblock ~29 ~9 ~30 prismarine
setblock ~30 ~9 ~30 dirt
fill ~31 ~9 ~30 ~43 ~9 ~31 stone
fill ~54 ~9 ~30 ~54 ~10 ~30 leaves 10
fill ~55 ~9 ~30 ~67 ~9 ~31 stone
setblock ~68 ~9 ~30 dirt
setblock ~69 ~9 ~30 prismarine
setblock ~70 ~9 ~30 stonebrick 2
setblock ~88 ~9 ~30 stone_slab
fill ~89 ~9 ~30 ~90 ~9 ~31 grass
fill ~7 ~9 ~31 ~9 ~9 ~31 grass
fill ~25 ~9 ~31 ~25 ~10 ~31 prismarine 2
fill ~26 ~9 ~31 ~26 ~9 ~41 stone
fill ~27 ~9 ~31 ~29 ~9 ~31 dirt
fill ~30 ~9 ~31 ~31 ~9 ~43 stone
fill ~45 ~9 ~31 ~46 ~10 ~34 stone
fill ~52 ~9 ~31 ~59 ~9 ~34 stone
fill ~68 ~9 ~31 ~68 ~9 ~43 stone
fill ~69 ~9 ~31 ~71 ~9 ~31 dirt
fill ~72 ~9 ~31 ~72 ~11 ~31 prismarine 2
setblock ~91 ~9 ~31 grass
setblock ~23 ~9 ~32 dirt
fill ~32 ~9 ~32 ~35 ~9 ~32 stone
fill ~36 ~9 ~32 ~37 ~9 ~32 stonebrick
fill ~42 ~9 ~32 ~60 ~10 ~32 stone
fill ~61 ~9 ~32 ~62 ~9 ~32 stonebrick
fill ~67 ~9 ~32 ~72 ~9 ~41 stone
fill ~73 ~9 ~32 ~73 ~10 ~32 prismarine 2
setblock ~75 ~9 ~32 dirt
fill ~20 ~9 ~33 ~21 ~9 ~33 dirt
fill ~22 ~9 ~33 ~34 ~9 ~34 stone
fill ~35 ~9 ~33 ~37 ~9 ~33 stonebrick 2
fill ~38 ~9 ~33 ~38 ~10 ~34 stonebrick
fill ~42 ~9 ~33 ~59 ~10 ~33 stone
fill ~60 ~9 ~33 ~60 ~9 ~35 stonebrick
setblock ~61 ~9 ~33 stonebrick
fill ~62 ~9 ~33 ~63 ~9 ~33 stonebrick 2
fill ~66 ~9 ~33 ~75 ~9 ~35 stone
fill ~76 ~9 ~33 ~76 ~9 ~34 stone
fill ~77 ~9 ~33 ~77 ~9 ~37 dirt
setblock ~78 ~9 ~33 dirt
fill ~16 ~9 ~34 ~17 ~9 ~34 stone_slab
fill ~18 ~9 ~34 ~19 ~9 ~35 stonebrick
setblock ~20 ~9 ~34 stonebrick 2
fill ~21 ~9 ~34 ~21 ~9 ~37 dirt
fill ~35 ~9 ~34 ~35 ~10 ~34 stonebrick 2
setblock ~36 ~9 ~34 stone_slab 5
setblock ~37 ~9 ~34 stone_brick_stairs 0
fill ~42 ~9 ~34 ~47 ~10 ~34 stone
setblock ~61 ~9 ~34 stone_brick_stairs 1
fill ~63 ~9 ~34 ~63 ~10 ~34 stonebrick
fill ~78 ~9 ~34 ~80 ~9 ~34 stonebrick
fill ~81 ~9 ~34 ~82 ~9 ~34 stone_slab
fill ~15 ~9 ~35 ~16 ~9 ~35 stone_slab
fill ~17 ~9 ~35 ~19 ~9 ~35 stonebrick
setblock ~20 ~9 ~35 stone 6
fill ~22 ~9 ~35 ~22 ~9 ~37 dirt
fill ~33 ~9 ~35 ~33 ~10 ~35 stonebrick 2
fill ~34 ~9 ~35 ~35 ~9 ~35 stonebrick
setblock ~39 ~9 ~35 stonebrick 2
setblock ~40 ~9 ~35 stonebrick
fill ~41 ~9 ~35 ~41 ~10 ~35 stonebrick 2
fill ~42 ~9 ~35 ~45 ~10 ~35 stonebrick
setblock ~46 ~9 ~35 stonebrick 2
setblock ~47 ~9 ~35 stonebrick 1
fill ~48 ~9 ~35 ~48 ~10 ~35 stonebrick
fill ~50 ~9 ~35 ~50 ~10 ~35 stonebrick
setblock ~51 ~9 ~35 stonebrick 1
fill ~52 ~9 ~35 ~56 ~9 ~35 stonebrick
setblock ~57 ~9 ~35 stonebrick 2
fill ~58 ~9 ~35 ~60 ~10 ~35 stonebrick
fill ~64 ~9 ~35 ~65 ~9 ~35 stonebrick 2
fill ~76 ~9 ~35 ~77 ~9 ~37 dirt
setblock ~78 ~9 ~35 stone 6
setblock ~79 ~9 ~35 stonebrick 2
setblock ~80 ~9 ~35 stonebrick
setblock ~81 ~9 ~35 stonebrick 2
fill ~82 ~9 ~35 ~83 ~9 ~35 stone_slab
fill ~15 ~9 ~36 ~15 ~11 ~37 stone
fill ~16 ~9 ~36 ~17 ~9 ~36 stonebrick
fill ~18 ~9 ~36 ~19 ~9 ~36 stone 6
setblock ~20 ~9 ~36 stonebrick
fill ~32 ~9 ~36 ~32 ~9 ~37 stonebrick
setblock ~33 ~9 ~36 stonebrick 2
fill ~49 ~9 ~36 ~49 ~10 ~36 stonebrick
setblock ~64 ~9 ~36 stone_slab 5
fill ~65 ~9 ~36 ~65 ~9 ~37 stonebrick 2
fill ~66 ~9 ~36 ~66 ~9 ~37 stonebrick
setblock ~78 ~9 ~36 stonebrick
fill ~79 ~9 ~36 ~80 ~9 ~36 stone 6
fill ~81 ~9 ~36 ~82 ~9 ~36 stonebrick
fill ~83 ~9 ~36 ~83 ~11 ~38 stone
fill ~14 ~9 ~37 ~15 ~10 ~37 stone
fill ~17 ~9 ~37 ~20 ~9 ~37 grass
fill ~33 ~9 ~37 ~33 ~9 ~38 stonebrick
setblock ~34 ~9 ~37 stone_brick_stairs 2
setblock ~49 ~9 ~37 stonebrick 2
setblock ~64 ~9 ~37 stone_brick_stairs 2
fill ~73 ~9 ~37 ~75 ~9 ~40 stone
fill ~78 ~9 ~37 ~81 ~9 ~37 grass
fill ~82 ~9 ~37 ~84 ~9 ~37 stone
fill ~17 ~9 ~38 ~17 ~11 ~38 stonebrick
fill ~18 ~9 ~38 ~18 ~11 ~38 stonebrick 2
fill ~19 ~9 ~38 ~20 ~11 ~38 stonebrick
fill ~21 ~9 ~38 ~21 ~10 ~38 stonebrick 2
fill ~22 ~9 ~38 ~32 ~9 ~38 stone
fill ~34 ~9 ~38 ~35 ~9 ~38 stonebrick
fill ~38 ~9 ~38 ~39 ~9 ~38 stonebrick 1
setblock ~40 ~9 ~38 stonebrick 2
fill ~41 ~9 ~38 ~41 ~10 ~38 stonebrick
fill ~42 ~9 ~38 ~43 ~9 ~38 stonebrick 2
fill ~44 ~9 ~38 ~46 ~10 ~38 stonebrick
fill ~49 ~9 ~38 ~49 ~10 ~39 stonebrick
fill ~52 ~9 ~38 ~53 ~10 ~38 stonebrick
fill ~54 ~9 ~38 ~55 ~9 ~38 stonebrick 2
fill ~56 ~9 ~38 ~56 ~10 ~38 stonebrick
setblock ~57 ~9 ~38 stonebrick 1
fill ~58 ~9 ~38 ~58 ~10 ~38 stonebrick
setblock ~59 ~9 ~38 stonebrick 2
fill ~60 ~9 ~38 ~60 ~9 ~39 stonebrick 1
fill ~64 ~9 ~38 ~65 ~10 ~38 stonebrick
fill ~66 ~9 ~38 ~66 ~9 ~60 stone
fill ~76 ~9 ~38 ~79 ~9 ~38 stone
fill ~80 ~9 ~38 ~80 ~10 ~38 stonebrick
fill ~19 ~9 ~39 ~19 ~11 ~39 leaves 10
fill ~21 ~9 ~39 ~21 ~10 ~39 stone
setblock ~22 ~9 ~39 stonebrick
fill ~23 ~9 ~39 ~34 ~10 ~40 stone
fill ~35 ~9 ~39 ~35 ~10 ~40 stonebrick
setblock ~38 ~9 ~39 stonebrick 2
fill ~44 ~9 ~39 ~44 ~10 ~39 stone
fill ~46 ~9 ~39 ~46 ~10 ~39 stonebrick
fill ~52 ~9 ~39 ~52 ~10 ~39 stonebrick
fill ~53 ~9 ~39 ~59 ~9 ~39 stone
setblock ~63 ~9 ~39 stonebrick 2
fill ~77 ~9 ~39 ~77 ~10 ~39 stone
fill ~80 ~9 ~39 ~80 ~11 ~39 leaves 10
fill ~38 ~9 ~40 ~38 ~10 ~40 stonebrick
fill ~44 ~9 ~40 ~45 ~9 ~40 stonebrick
setblock ~46 ~9 ~40 stonebrick 2
fill ~49 ~9 ~40 ~49 ~12 ~40 stone 6
setblock ~52 ~9 ~40 stonebrick
setblock ~53 ~9 ~40 stonebrick 2
setblock ~54 ~9 ~40 stonebrick 1
fill ~55 ~9 ~40 ~59 ~9 ~40 stone
setblock ~60 ~9 ~40 stonebrick 2
setblock ~63 ~9 ~40 stonebrick
fill ~76 ~9 ~40 ~76 ~11 ~40 stone
fill ~23 ~9 ~41 ~23 ~10 ~41 stone
fill ~27 ~9 ~41 ~34 ~9 ~41 stone
setblock ~35 ~9 ~41 stonebrick 2
setblock ~38 ~9 ~41 stonebrick 1
fill ~43 ~9 ~41 ~43 ~10 ~42 stonebrick
fill ~55 ~9 ~41 ~55 ~10 ~42 stonebrick
fill ~56 ~9 ~41 ~59 ~9 ~42 stone
fill ~60 ~9 ~41 ~60 ~10 ~41 stonebrick
fill ~63 ~9 ~41 ~63 ~10 ~41 stonebrick 2
fill ~75 ~9 ~41 ~75 ~11 ~41 stone
fill ~29 ~9 ~42 ~29 ~10 ~42 dirt
fill ~35 ~9 ~42 ~35 ~9 ~46 stonebrick
fill ~38 ~9 ~42 ~38 ~10 ~42 stonebrick
fill ~40 ~9 ~42 ~42 ~9 ~42 stone
fill ~60 ~9 ~42 ~60 ~9 ~43 stonebrick 2
fill ~63 ~9 ~42 ~63 ~10 ~45 stonebrick
fill ~67 ~9 ~42 ~67 ~10 ~46 stone
fill ~69 ~9 ~42 ~69 ~10 ~42 dirt
fill ~29 ~9 ~43 ~29 ~11 ~43 leaves 10
fill ~38 ~9 ~43 ~38 ~9 ~44 stonebrick 2
fill ~39 ~9 ~43 ~39 ~9 ~45 stone
setblock ~40 ~9 ~43 stone
fill ~41 ~9 ~43 ~42 ~10 ~43 stonebrick
fill ~43 ~9 ~43 ~43 ~11 ~43 iron_bars
fill ~55 ~9 ~43 ~55 ~11 ~43 iron_bars
fill ~56 ~9 ~43 ~57 ~10 ~43 stonebrick
fill ~58 ~9 ~43 ~59 ~9 ~43 stone
fill ~30 ~9 ~44 ~30 ~10 ~44 leaves 10
setblock ~40 ~9 ~44 stonebrick 1
fill ~45 ~9 ~44 ~45 ~12 ~44 iron_bars
fill ~48 ~9 ~44 ~50 ~9 ~44 stone_brick_stairs 2
fill ~53 ~9 ~44 ~53 ~12 ~44 iron_bars
fill ~58 ~9 ~44 ~58 ~10 ~44 stonebrick
fill ~59 ~9 ~44 ~59 ~10 ~44 stone
fill ~60 ~9 ~44 ~60 ~10 ~46 stonebrick
fill ~23 ~9 ~45 ~23 ~10 ~53 stone
fill ~31 ~9 ~45 ~34 ~10 ~46 stone
fill ~38 ~9 ~45 ~38 ~10 ~46 stonebrick
setblock ~40 ~9 ~45 stonebrick 2
fill ~44 ~9 ~45 ~44 ~12 ~45 iron_bars
fill ~48 ~9 ~45 ~48 ~9 ~46 stone_slab 13
setblock ~49 ~9 ~45 double_stone_slab 5
fill ~50 ~9 ~45 ~50 ~9 ~46 stone_slab 13
fill ~54 ~9 ~45 ~54 ~12 ~45 iron_bars
setblock ~58 ~9 ~45 stonebrick
fill ~75 ~9 ~45 ~75 ~10 ~53 stone
fill ~39 ~9 ~46 ~40 ~9 ~46 stonebrick
fill ~49 ~9 ~46 ~49 ~9 ~48 stone 6
setblock ~58 ~9 ~46 stonebrick 2
fill ~59 ~9 ~46 ~60 ~10 ~46 stonebrick
setblock ~63 ~9 ~46 stonebrick 2
fill ~22 ~9 ~47 ~23 ~10 ~51 stone
fill ~32 ~9 ~47 ~33 ~10 ~59 stone
fill ~34 ~9 ~47 ~34 ~10 ~47 stone
setblock ~35 ~9 ~47 stonebrick 1
setblock ~47 ~9 ~47 stone_slab 13
setblock ~48 ~9 ~47 stonebrick
setblock ~50 ~9 ~47 stonebrick
setblock ~51 ~9 ~47 stone_slab 13
setblock ~63 ~9 ~47 stonebrick 1
fill ~76 ~9 ~47 ~76 ~10 ~51 stone
fill ~29 ~9 ~48 ~33 ~10 ~50 stone
fill ~35 ~9 ~48 ~35 ~10 ~48 stonebrick
fill ~44 ~9 ~48 ~44 ~9 ~50 stone_brick_stairs 0
fill ~45 ~9 ~48 ~46 ~9 ~48 stone_slab 13
setblock ~47 ~9 ~48 stonebrick
fill ~48 ~9 ~48 ~50 ~9 ~48 stone 6
setblock ~51 ~9 ~48 stonebrick
fill ~52 ~9 ~48 ~54 ~9 ~48 stone_slab 13
fill ~55 ~9 ~48 ~55 ~9 ~50 stone_slab 5
fill ~63 ~9 ~48 ~63 ~10 ~48 stonebrick
fill ~68 ~9 ~48 ~69 ~10 ~50 stone
fill ~73 ~9 ~48 ~76 ~10 ~49 stone
fill ~21 ~9 ~49 ~35 ~10 ~49 stone
fill ~36 ~9 ~49 ~36 ~10 ~49 stonebrick
setblock ~37 ~9 ~49 stonebrick 2
fill ~38 ~9 ~49 ~39 ~10 ~49 stonebrick
fill ~40 ~9 ~49 ~40 ~12 ~49 stone 6
setblock ~45 ~9 ~49 double_stone_slab 5
fill ~46 ~9 ~49 ~48 ~9 ~49 stone 6
setblock ~49 ~9 ~49 chest 3
