setblock ~25 ~4 ~5 stone
setblock ~16 ~4 ~15 stone
setblock ~6 ~4 ~24 stone
setblock ~65 ~4 ~61 stone
setblock ~33 ~4 ~66 stone
setblock ~7 ~4 ~69 stone
setblock ~17 ~4 ~78 stone
setblock ~26 ~4 ~88 stone
setblock ~24 ~5 ~5 stone
setblock ~72 ~5 ~5 stone
setblock ~15 ~5 ~15 stone
setblock ~81 ~5 ~15 stone
setblock ~5 ~5 ~24 stone
setblock ~91 ~5 ~24 stone
setblock ~29 ~5 ~34 stone
setblock ~37 ~5 ~38 stone
setblock ~5 ~5 ~72 stone
setblock ~15 ~5 ~81 stone
setblock ~24 ~5 ~91 stone
setblock ~61 ~6 ~15 stone
setblock ~26 ~6 ~26 stone
setblock ~56 ~6 ~34 stone
setblock ~57 ~6 ~35 stone
setblock ~41 ~6 ~59 stone
setblock ~55 ~6 ~59 stone
setblock ~57 ~6 ~59 stone
setblock ~67 ~6 ~60 stone
setblock ~31 ~6 ~65 stone
setblock ~31 ~7 ~30 stone
setblock ~59 ~7 ~32 stone
setblock ~25 ~7 ~33 stone
setblock ~71 ~7 ~33 stone
setblock ~53 ~7 ~34 stone
setblock ~39 ~7 ~36 stone
setblock ~43 ~7 ~43 stone 4
setblock ~53 ~7 ~43 stone 4
setblock ~43 ~7 ~53 stone 4
setblock ~53 ~7 ~53 stone 4
setblock ~62 ~7 ~53 stone
setblock ~42 ~7 ~59 stone
setblock ~52 ~7 ~59 stone
setblock ~71 ~7 ~60 stone
setblock ~29 ~7 ~61 stone
setblock ~26 ~7 ~64 stone
setblock ~69 ~7 ~64 stone
setblock ~27 ~7 ~65 stone
setblock ~34 ~7 ~73 stone
setblock ~24 ~8 ~5 double_stone_block_slab
setblock ~27 ~8 ~5 stone
setblock ~72 ~8 ~5 double_stone_block_slab
setblock ~27 ~8 ~6 iron_ore
setblock ~69 ~8 ~6 iron_ore
setblock ~28 ~8 ~7 double_stone_block_slab
setblock ~68 ~8 ~7 smooth_stone
setblock ~69 ~8 ~7 stone_block_slab
setblock ~25 ~8 ~8 iron_ore
setblock ~71 ~8 ~8 iron_ore
setblock ~72 ~8 ~8 stone
setblock ~26 ~8 ~9 smooth_stone
setblock ~28 ~8 ~9 smooth_stone
setblock ~68 ~8 ~9 smooth_stone
setblock ~70 ~8 ~9 double_stone_block_slab
setblock ~15 ~8 ~15 double_stone_block_slab
setblock ~18 ~8 ~15 stone
setblock ~81 ~8 ~15 double_stone_block_slab
setblock ~18 ~8 ~16 iron_ore
setblock ~78 ~8 ~16 iron_ore
setblock ~19 ~8 ~17 double_stone_block_slab
setblock ~77 ~8 ~17 smooth_stone
setblock ~78 ~8 ~17 stone_block_slab
setblock ~16 ~8 ~18 iron_ore
setblock ~80 ~8 ~18 iron_ore
setblock ~81 ~8 ~18 stone
setblock ~17 ~8 ~19 smooth_stone
setblock ~19 ~8 ~19 smooth_stone
setblock ~77 ~8 ~19 smooth_stone
setblock ~79 ~8 ~19 double_stone_block_slab
setblock ~5 ~8 ~24 double_stone_block_slab
setblock ~8 ~8 ~24 stone
setblock ~91 ~8 ~24 double_stone_block_slab
setblock ~8 ~8 ~25 iron_ore
setblock ~88 ~8 ~25 iron_ore
setblock ~9 ~8 ~26 double_stone_block_slab
setblock ~87 ~8 ~26 smooth_stone
setblock ~88 ~8 ~26 stone_block_slab
setblock ~6 ~8 ~27 iron_ore
setblock ~90 ~8 ~27 iron_ore
setblock ~91 ~8 ~27 stone
setblock ~7 ~8 ~28 smooth_stone
setblock ~9 ~8 ~28 smooth_stone
setblock ~87 ~8 ~28 smooth_stone
setblock ~89 ~8 ~28 double_stone_block_slab
setblock ~38 ~8 ~32 stone
setblock ~37 ~8 ~34 stonebrick 2
setblock ~50 ~8 ~34 stone
setblock ~59 ~8 ~34 stonebrick
setblock ~76 ~8 ~34 stone
setblock ~64 ~8 ~35 stone
setblock ~77 ~8 ~35 stone
setblock ~42 ~8 ~36 stone
setblock ~34 ~8 ~37 stonebrick
setblock ~62 ~8 ~37 stonebrick 2
setblock ~64 ~8 ~38 stone
setblock ~43 ~8 ~39 stone
setblock ~40 ~8 ~42 stone
setblock ~43 ~8 ~43 stone 3
setblock ~53 ~8 ~43 stone 3
setblock ~43 ~8 ~53 stone 3
setblock ~53 ~8 ~53 stone 3
setblock ~56 ~8 ~54 stone
setblock ~57 ~8 ~55 stone
setblock ~34 ~8 ~57 stone
setblock ~34 ~8 ~59 stonebrick 2
setblock ~43 ~8 ~59 stone
setblock ~48 ~8 ~59 stone
setblock ~62 ~8 ~59 stonebrick
setblock ~69 ~8 ~59 stone
setblock ~27 ~8 ~60 stone
setblock ~21 ~8 ~61 stone
setblock ~23 ~8 ~61 stone
setblock ~37 ~8 ~62 stonebrick
setblock ~59 ~8 ~62 stonebrick 2
setblock ~69 ~8 ~67 stone
setblock ~7 ~8 ~68 double_stone_block_slab
setblock ~9 ~8 ~68 smooth_stone
setblock ~70 ~8 ~68 stone
setblock ~87 ~8 ~68 smooth_stone
setblock ~89 ~8 ~68 smooth_stone
setblock ~5 ~8 ~69 stone
setblock ~6 ~8 ~69 iron_ore
setblock ~66 ~8 ~69 stone
setblock ~90 ~8 ~69 iron_ore
setblock ~5 ~8 ~70 stone_block_slab
setblock ~9 ~8 ~70 smooth_stone
setblock ~87 ~8 ~70 double_stone_block_slab
setblock ~8 ~8 ~71 iron_ore
setblock ~88 ~8 ~71 iron_ore
setblock ~5 ~8 ~72 double_stone_block_slab
setblock ~88 ~8 ~72 stone
setblock ~91 ~8 ~72 double_stone_block_slab
setblock ~36 ~8 ~75 stone
setblock ~17 ~8 ~77 double_stone_block_slab
setblock ~19 ~8 ~77 smooth_stone
setblock ~77 ~8 ~77 smooth_stone
setblock ~79 ~8 ~77 smooth_stone
setblock ~15 ~8 ~78 stone
setblock ~16 ~8 ~78 iron_ore
setblock ~80 ~8 ~78 iron_ore
setblock ~15 ~8 ~79 stone_block_slab
setblock ~19 ~8 ~79 smooth_stone
setblock ~62 ~8 ~79 stone
setblock ~77 ~8 ~79 double_stone_block_slab
setblock ~18 ~8 ~80 iron_ore
setblock ~78 ~8 ~80 iron_ore
setblock ~15 ~8 ~81 double_stone_block_slab
setblock ~78 ~8 ~81 stone
setblock ~81 ~8 ~81 double_stone_block_slab
setblock ~26 ~8 ~87 double_stone_block_slab
setblock ~28 ~8 ~87 smooth_stone
setblock ~68 ~8 ~87 smooth_stone
setblock ~70 ~8 ~87 smooth_stone
setblock ~24 ~8 ~88 stone
setblock ~25 ~8 ~88 iron_ore
setblock ~71 ~8 ~88 iron_ore
setblock ~24 ~8 ~89 stone_block_slab
setblock ~28 ~8 ~89 smooth_stone
setblock ~68 ~8 ~89 double_stone_block_slab
setblock ~27 ~8 ~90 iron_ore
setblock ~69 ~8 ~90 iron_ore
setblock ~24 ~8 ~91 double_stone_block_slab
setblock ~69 ~8 ~91 stone
setblock ~72 ~8 ~91 double_stone_block_slab
setblock ~24 ~9 ~3 stone
setblock ~72 ~9 ~3 stone
setblock ~22 ~9 ~5 stone
setblock ~27 ~9 ~5 iron_ore
setblock ~74 ~9 ~5 stone
setblock ~27 ~9 ~6 chest 4
setblock ~28 ~9 ~6 coal_ore
setblock ~68 ~9 ~6 coal_ore
setblock ~28 ~9 ~7 furnace 4
setblock ~68 ~9 ~7 crafting_table
setblock ~71 ~9 ~8 chest 2
setblock ~72 ~9 ~8 iron_ore
setblock ~25 ~9 ~9 coal_ore
setblock ~26 ~9 ~9 crafting_table
setblock ~67 ~9 ~9 stone
setblock ~70 ~9 ~9 furnace 2
setblock ~71 ~9 ~9 coal_ore
setblock ~68 ~9 ~10 stone
setblock ~15 ~9 ~13 stone
setblock ~81 ~9 ~13 stone
setblock ~13 ~9 ~15 stone
setblock ~18 ~9 ~15 iron_ore
setblock ~62 ~9 ~15 stone
setblock ~83 ~9 ~15 stone
setblock ~18 ~9 ~16 chest 4
setblock ~19 ~9 ~16 coal_ore
setblock ~77 ~9 ~16 coal_ore
setblock ~19 ~9 ~17 furnace 4
setblock ~77 ~9 ~17 crafting_table
setblock ~80 ~9 ~18 chest 2
setblock ~81 ~9 ~18 iron_ore
setblock ~16 ~9 ~19 coal_ore
setblock ~17 ~9 ~19 crafting_table
setblock ~76 ~9 ~19 stone
setblock ~79 ~9 ~19 furnace 2
setblock ~80 ~9 ~19 coal_ore
setblock ~77 ~9 ~20 stone
setblock ~48 ~9 ~21 stone
setblock ~5 ~9 ~22 stone
setblock ~91 ~9 ~22 stone
setblock ~3 ~9 ~24 stone
setblock ~8 ~9 ~24 iron_ore
setblock ~93 ~9 ~24 stone
setblock ~8 ~9 ~25 chest 4
setblock ~9 ~9 ~25 coal_ore
setblock ~87 ~9 ~25 coal_ore
setblock ~9 ~9 ~26 furnace 4
setblock ~87 ~9 ~26 crafting_table
setblock ~90 ~9 ~27 chest 2
setblock ~91 ~9 ~27 iron_ore
setblock ~6 ~9 ~28 coal_ore
setblock ~7 ~9 ~28 crafting_table
setblock ~86 ~9 ~28 stone
setblock ~89 ~9 ~28 furnace 2
setblock ~90 ~9 ~28 coal_ore
setblock ~57 ~9 ~29 stone
setblock ~87 ~9 ~29 stone
setblock ~43 ~9 ~33 stone
setblock ~15 ~9 ~34 stone
setblock ~19 ~9 ~34 stone
setblock ~44 ~9 ~39 stone
setblock ~46 ~9 ~39 stone
setblock ~45 ~9 ~40 stone
setblock ~51 ~9 ~40 stone
setblock ~53 ~9 ~40 stone
setblock ~54 ~9 ~41 stone
setblock ~55 ~9 ~42 stone
setblock ~56 ~9 ~43 stone
setblock ~44 ~9 ~44 stone 4
setblock ~52 ~9 ~44 stone 4
setblock ~40 ~9 ~45 stone
setblock ~56 ~9 ~45 stone
setblock ~39 ~9 ~46 stone
setblock ~56 ~9 ~51 stone
setblock ~44 ~9 ~52 stone 4
setblock ~52 ~9 ~52 stone 4
setblock ~41 ~9 ~53 stone
setblock ~32 ~9 ~54 stone
setblock ~42 ~9 ~54 stone
setblock ~33 ~9 ~55 stone
setblock ~51 ~9 ~56 stone
setblock ~52 ~9 ~57 stone
setblock ~73 ~9 ~59 stone
setblock ~19 ~9 ~60 stone
setblock ~76 ~9 ~62 stone
setblock ~59 ~9 ~63 stone
setblock ~23 ~9 ~65 stone
setblock ~40 ~9 ~65 stone
setblock ~9 ~9 ~67 stone
setblock ~87 ~9 ~67 stone
setblock ~6 ~9 ~68 coal_ore
setblock ~7 ~9 ~68 furnace 3
setblock ~10 ~9 ~68 stone
setblock ~86 ~9 ~68 stone
setblock ~89 ~9 ~68 crafting_table
setblock ~90 ~9 ~68 coal_ore
setblock ~5 ~9 ~69 iron_ore
setblock ~6 ~9 ~69 chest 3
setblock ~9 ~9 ~70 crafting_table
setblock ~87 ~9 ~70 furnace 5
setblock ~9 ~9 ~71 coal_ore
setblock ~28 ~9 ~71 stone
setblock ~87 ~9 ~71 coal_ore
setblock ~88 ~9 ~71 chest 5
setblock ~3 ~9 ~72 stone
setblock ~88 ~9 ~72 iron_ore
setblock ~93 ~9 ~72 stone
setblock ~65 ~9 ~73 stone
setblock ~5 ~9 ~74 stone
setblock ~91 ~9 ~74 stone
setblock ~63 ~9 ~75 stone
setblock ~19 ~9 ~76 stone
setblock ~37 ~9 ~76 stone
setblock ~77 ~9 ~76 stone
setblock ~16 ~9 ~77 coal_ore
setblock ~17 ~9 ~77 furnace 3
setblock ~20 ~9 ~77 stone
setblock ~76 ~9 ~77 stone
setblock ~79 ~9 ~77 crafting_table
setblock ~80 ~9 ~77 coal_ore
setblock ~15 ~9 ~78 iron_ore
setblock ~16 ~9 ~78 chest 3
setblock ~19 ~9 ~79 crafting_table
setblock ~77 ~9 ~79 furnace 5
setblock ~19 ~9 ~80 coal_ore
setblock ~77 ~9 ~80 coal_ore
setblock ~78 ~9 ~80 chest 5
setblock ~13 ~9 ~81 stone
setblock ~78 ~9 ~81 iron_ore
setblock ~83 ~9 ~81 stone
setblock ~15 ~9 ~83 stone
setblock ~81 ~9 ~83 stone
setblock ~28 ~9 ~86 stone
setblock ~68 ~9 ~86 stone
setblock ~25 ~9 ~87 coal_ore
setblock ~26 ~9 ~87 furnace 3
setblock ~29 ~9 ~87 stone
setblock ~67 ~9 ~87 stone
setblock ~70 ~9 ~87 crafting_table
setblock ~71 ~9 ~87 coal_ore
setblock ~24 ~9 ~88 iron_ore
setblock ~25 ~9 ~88 chest 3
setblock ~28 ~9 ~89 crafting_table
setblock ~68 ~9 ~89 furnace 5
setblock ~28 ~9 ~90 coal_ore
setblock ~68 ~9 ~90 coal_ore
setblock ~69 ~9 ~90 chest 5
setblock ~22 ~9 ~91 stone
setblock ~69 ~9 ~91 iron_ore
setblock ~74 ~9 ~91 stone
setblock ~24 ~9 ~93 stone
setblock ~72 ~9 ~93 stone
setblock ~24 ~10 ~3 dirt
setblock ~27 ~10 ~3 stone
setblock ~69 ~10 ~3 stone
setblock ~72 ~10 ~3 dirt
setblock ~25 ~10 ~4 gold_ore
setblock ~22 ~10 ~5 dirt
setblock ~28 ~10 ~5 stone
setblock ~68 ~10 ~5 stone
setblock ~74 ~10 ~5 dirt
setblock ~28 ~10 ~6 iron_ore
setblock ~73 ~10 ~6 gold_ore
setblock ~22 ~10 ~8 stone
setblock ~68 ~10 ~8 gold_ore
setblock ~72 ~10 ~8 stone
setblock ~74 ~10 ~8 stone
setblock ~24 ~10 ~9 stone
setblock ~27 ~10 ~9 gold_ore
setblock ~71 ~10 ~9 iron_ore
setblock ~15 ~10 ~13 dirt
setblock ~18 ~10 ~13 stone
setblock ~78 ~10 ~13 stone
setblock ~81 ~10 ~13 dirt
setblock ~16 ~10 ~14 gold_ore
setblock ~13 ~10 ~15 dirt
setblock ~19 ~10 ~15 stone
setblock ~77 ~10 ~15 stone
setblock ~83 ~10 ~15 dirt
setblock ~19 ~10 ~16 iron_ore
setblock ~82 ~10 ~16 gold_ore
setblock ~13 ~10 ~18 stone
setblock ~77 ~10 ~18 gold_ore
setblock ~81 ~10 ~18 stone
setblock ~83 ~10 ~18 stone
setblock ~15 ~10 ~19 stone
setblock ~18 ~10 ~19 gold_ore
setblock ~80 ~10 ~19 iron_ore
setblock ~5 ~10 ~22 dirt
setblock ~8 ~10 ~22 stone
setblock ~37 ~10 ~22 stone
setblock ~88 ~10 ~22 stone
setblock ~91 ~10 ~22 dirt
setblock ~6 ~10 ~23 gold_ore
setblock ~3 ~10 ~24 dirt
setblock ~9 ~10 ~24 stone
setblock ~87 ~10 ~24 stone
setblock ~93 ~10 ~24 dirt
setblock ~9 ~10 ~25 iron_ore
setblock ~92 ~10 ~25 gold_ore
setblock ~3 ~10 ~27 stone
setblock ~56 ~10 ~27 stone
setblock ~87 ~10 ~27 gold_ore
setblock ~91 ~10 ~27 stone
setblock ~93 ~10 ~27 stone
setblock ~5 ~10 ~28 stone
setblock ~8 ~10 ~28 gold_ore
setblock ~90 ~10 ~28 iron_ore
setblock ~47 ~10 ~33 stone
setblock ~81 ~10 ~34 stone
setblock ~45 ~10 ~40 stonebrick
setblock ~46 ~10 ~40 stonebrick 2
setblock ~48 ~10 ~40 stone_brick_stairs 3
setblock ~50 ~10 ~40 stonebrick
setblock ~44 ~10 ~41 stonebrick
setblock ~52 ~10 ~41 stonebrick 2
setblock ~43 ~10 ~42 stonebrick 2
setblock ~53 ~10 ~42 stonebrick
setblock ~42 ~10 ~43 stonebrick
setblock ~54 ~10 ~43 stonebrick 2
setblock ~41 ~10 ~44 stonebrick 2
setblock ~55 ~10 ~44 stonebrick
setblock ~56 ~10 ~45 stonebrick
setblock ~40 ~10 ~46 stonebrick
setblock ~56 ~10 ~46 stonebrick 2
setblock ~33 ~10 ~47 stone
setblock ~40 ~10 ~48 stone_brick_stairs 1
setblock ~50 ~10 ~48 stone
setblock ~56 ~10 ~48 stone_brick_stairs 0
setblock ~40 ~10 ~50 stonebrick 2
setblock ~56 ~10 ~50 stonebrick
setblock ~40 ~10 ~51 stonebrick
setblock ~41 ~10 ~52 stonebrick
setblock ~55 ~10 ~52 stonebrick 2
setblock ~42 ~10 ~53 stonebrick 2
setblock ~54 ~10 ~53 stonebrick
setblock ~43 ~10 ~54 stonebrick
setblock ~53 ~10 ~54 stonebrick 2
setblock ~44 ~10 ~55 stonebrick 2
setblock ~52 ~10 ~55 stonebrick
setblock ~30 ~10 ~56 stone
setblock ~46 ~10 ~56 stonebrick
setblock ~48 ~10 ~56 stone_brick_stairs 2
setblock ~50 ~10 ~56 stonebrick 2
setblock ~51 ~10 ~56 stonebrick
setblock ~67 ~10 ~56 stone
setblock ~73 ~10 ~58 stone
setblock ~18 ~10 ~60 stone
setblock ~79 ~10 ~60 stone
setblock ~18 ~10 ~62 stone
setblock ~5 ~10 ~68 stone
setblock ~6 ~10 ~68 iron_ore
setblock ~88 ~10 ~68 gold_ore
setblock ~91 ~10 ~68 stone
setblock ~3 ~10 ~69 stone
setblock ~9 ~10 ~69 gold_ore
setblock ~93 ~10 ~69 stone
setblock ~4 ~10 ~71 gold_ore
setblock ~9 ~10 ~71 stone
setblock ~26 ~10 ~71 stone
setblock ~87 ~10 ~71 iron_ore
setblock ~3 ~10 ~72 dirt
setblock ~87 ~10 ~72 stone
setblock ~93 ~10 ~72 dirt
setblock ~90 ~10 ~73 gold_ore
setblock ~5 ~10 ~74 dirt
setblock ~8 ~10 ~74 stone
setblock ~88 ~10 ~74 stone
setblock ~91 ~10 ~74 dirt
setblock ~32 ~10 ~75 stone
setblock ~15 ~10 ~77 stone
setblock ~16 ~10 ~77 iron_ore
setblock ~78 ~10 ~77 gold_ore
setblock ~81 ~10 ~77 stone
setblock ~13 ~10 ~78 stone
setblock ~19 ~10 ~78 gold_ore
setblock ~83 ~10 ~78 stone
setblock ~14 ~10 ~80 gold_ore
setblock ~19 ~10 ~80 stone
setblock ~77 ~10 ~80 iron_ore
setblock ~13 ~10 ~81 dirt
setblock ~77 ~10 ~81 stone
setblock ~83 ~10 ~81 dirt
setblock ~80 ~10 ~82 gold_ore
setblock ~15 ~10 ~83 dirt
setblock ~18 ~10 ~83 stone
setblock ~78 ~10 ~83 stone
setblock ~81 ~10 ~83 dirt
setblock ~24 ~10 ~87 stone
setblock ~25 ~10 ~87 iron_ore
setblock ~69 ~10 ~87 gold_ore
setblock ~72 ~10 ~87 stone
setblock ~22 ~10 ~88 stone
setblock ~28 ~10 ~88 gold_ore
setblock ~74 ~10 ~88 stone
setblock ~23 ~10 ~90 gold_ore
setblock ~28 ~10 ~90 stone
setblock ~68 ~10 ~90 iron_ore
setblock ~22 ~10 ~91 dirt
setblock ~68 ~10 ~91 stone
setblock ~74 ~10 ~91 dirt
setblock ~71 ~10 ~92 gold_ore
setblock ~24 ~10 ~93 dirt
setblock ~27 ~10 ~93 stone
setblock ~69 ~10 ~93 stone
setblock ~72 ~10 ~93 dirt
setblock ~24 ~11 ~3 grass
setblock ~25 ~11 ~3 dirt
setblock ~27 ~11 ~3 dirt
setblock ~69 ~11 ~3 dirt
setblock ~72 ~11 ~3 grass
setblock ~23 ~11 ~4 stonebrick
setblock ~28 ~11 ~4 stone_block_slab 8
setblock ~68 ~11 ~4 stone_block_slab 8
setblock ~73 ~11 ~4 stonebrick
setblock ~22 ~11 ~5 grass
setblock ~26 ~11 ~5 stone_block_slab 8
setblock ~29 ~11 ~5 stone_block_slab 8
setblock ~67 ~11 ~5 stone_block_slab 8
setblock ~70 ~11 ~5 stone_block_slab 8
setblock ~74 ~11 ~5 grass
setblock ~22 ~11 ~6 stone
setblock ~26 ~11 ~6 stone_block_slab 13
setblock ~27 ~11 ~6 double_stone_block_slab 5
setblock ~69 ~11 ~6 double_stone_block_slab 5
setblock ~70 ~11 ~6 stone_block_slab 13
setblock ~74 ~11 ~6 dirt
setblock ~24 ~11 ~7 stone_block_slab 8
setblock ~26 ~11 ~7 double_stone_block_slab 5
setblock ~27 ~11 ~7 stone_block_slab 13
setblock ~28 ~11 ~7 stone_block_slab 8
setblock ~68 ~11 ~7 stone_block_slab 8
setblock ~69 ~11 ~7 stone_block_slab 13
setblock ~70 ~11 ~7 double_stone_block_slab 5
setblock ~72 ~11 ~7 stone_block_slab 8
setblock ~22 ~11 ~8 dirt
setblock ~25 ~11 ~8 double_stone_block_slab 5
setblock ~26 ~11 ~8 stone_block_slab 13
setblock ~27 ~11 ~8 diamond_ore
setblock ~30 ~11 ~8 dirt
setblock ~69 ~11 ~8 diamond_ore
setblock ~70 ~11 ~8 stone_block_slab 13
setblock ~71 ~11 ~8 double_stone_block_slab 5
setblock ~74 ~11 ~8 dirt
setblock ~23 ~11 ~9 stone_block_slab 8
setblock ~26 ~11 ~9 stone_block_slab 8
setblock ~29 ~11 ~9 double_stone_block_slab
setblock ~67 ~11 ~9 double_stone_block_slab
setblock ~70 ~11 ~9 stone_block_slab 8
setblock ~73 ~11 ~9 stone_block_slab 8
setblock ~24 ~11 ~10 stone_block_slab 8
setblock ~28 ~11 ~10 double_stone_block_slab
setblock ~68 ~11 ~10 double_stone_block_slab
setblock ~72 ~11 ~10 stone_block_slab 8
setblock ~69 ~11 ~11 dirt
setblock ~15 ~11 ~13 grass
setblock ~16 ~11 ~13 dirt
setblock ~18 ~11 ~13 dirt
setblock ~78 ~11 ~13 dirt
setblock ~81 ~11 ~13 grass
setblock ~19 ~11 ~14 stone_block_slab 8
setblock ~77 ~11 ~14 stone_block_slab 8
setblock ~13 ~11 ~15 grass
setblock ~17 ~11 ~15 stone_block_slab 8
setblock ~20 ~11 ~15 stone_block_slab 8
setblock ~76 ~11 ~15 stone_block_slab 8
setblock ~79 ~11 ~15 stone_block_slab 8
setblock ~83 ~11 ~15 grass
setblock ~13 ~11 ~16 stone
setblock ~17 ~11 ~16 stone_block_slab 13
setblock ~18 ~11 ~16 double_stone_block_slab 5
setblock ~20 ~11 ~16 stonebrick 2
setblock ~78 ~11 ~16 double_stone_block_slab 5
setblock ~79 ~11 ~16 stone_block_slab 13
setblock ~83 ~11 ~16 dirt
setblock ~15 ~11 ~17 stone_block_slab 8
setblock ~17 ~11 ~17 double_stone_block_slab 5
setblock ~18 ~11 ~17 stone_block_slab 13
setblock ~19 ~11 ~17 stone_block_slab 8
setblock ~77 ~11 ~17 stone_block_slab 8
setblock ~78 ~11 ~17 stone_block_slab 13
setblock ~79 ~11 ~17 double_stone_block_slab 5
setblock ~81 ~11 ~17 stone_block_slab 8
setblock ~13 ~11 ~18 dirt
setblock ~16 ~11 ~18 double_stone_block_slab 5
setblock ~17 ~11 ~18 stone_block_slab 13
setblock ~18 ~11 ~18 diamond_ore
setblock ~21 ~11 ~18 dirt
setblock ~78 ~11 ~18 diamond_ore
setblock ~79 ~11 ~18 stone_block_slab 13
setblock ~80 ~11 ~18 double_stone_block_slab 5
setblock ~83 ~11 ~18 dirt
setblock ~14 ~11 ~19 stone_block_slab 8
setblock ~17 ~11 ~19 stone_block_slab 8
setblock ~20 ~11 ~19 double_stone_block_slab
setblock ~76 ~11 ~19 double_stone_block_slab
setblock ~79 ~11 ~19 stone_block_slab 8
setblock ~82 ~11 ~19 stone_block_slab 8
setblock ~15 ~11 ~20 stone_block_slab 8
setblock ~19 ~11 ~20 double_stone_block_slab
setblock ~77 ~11 ~20 double_stone_block_slab
setblock ~80 ~11 ~20 stonebrick 2
setblock ~81 ~11 ~20 stone_block_slab 8
setblock ~78 ~11 ~21 dirt
setblock ~5 ~11 ~22 grass
setblock ~6 ~11 ~22 dirt
setblock ~8 ~11 ~22 dirt
setblock ~31 ~11 ~22 stone
setblock ~65 ~11 ~22 stone
setblock ~88 ~11 ~22 dirt
setblock ~91 ~11 ~22 grass
setblock ~4 ~11 ~23 stonebrick
setblock ~9 ~11 ~23 stone_block_slab 8
setblock ~87 ~11 ~23 stone_block_slab 8
setblock ~92 ~11 ~23 stonebrick
setblock ~3 ~11 ~24 grass
setblock ~7 ~11 ~24 stone_block_slab 8
setblock ~10 ~11 ~24 stone_block_slab 8
setblock ~86 ~11 ~24 stone_block_slab 8
setblock ~89 ~11 ~24 stone_block_slab 8
setblock ~93 ~11 ~24 grass
setblock ~3 ~11 ~25 stone
setblock ~7 ~11 ~25 stone_block_slab 13
setblock ~8 ~11 ~25 double_stone_block_slab 5
setblock ~39 ~11 ~25 stone
setblock ~88 ~11 ~25 double_stone_block_slab 5
setblock ~89 ~11 ~25 stone_block_slab 13
setblock ~93 ~11 ~25 dirt
setblock ~5 ~11 ~26 stone_block_slab 8
setblock ~7 ~11 ~26 double_stone_block_slab 5
setblock ~8 ~11 ~26 stone_block_slab 13
setblock ~9 ~11 ~26 stone_block_slab 8
setblock ~87 ~11 ~26 stone_block_slab 8
setblock ~88 ~11 ~26 stone_block_slab 13
setblock ~89 ~11 ~26 double_stone_block_slab 5
setblock ~91 ~11 ~26 stone_block_slab 8
setblock ~3 ~11 ~27 dirt
setblock ~6 ~11 ~27 double_stone_block_slab 5
setblock ~7 ~11 ~27 stone_block_slab 13
setblock ~8 ~11 ~27 diamond_ore
setblock ~11 ~11 ~27 dirt
setblock ~88 ~11 ~27 diamond_ore
setblock ~89 ~11 ~27 stone_block_slab 13
setblock ~90 ~11 ~27 double_stone_block_slab 5
setblock ~93 ~11 ~27 dirt
setblock ~4 ~11 ~28 stone_block_slab 8
setblock ~7 ~11 ~28 stone_block_slab 8
setblock ~10 ~11 ~28 double_stone_block_slab
setblock ~41 ~11 ~28 stone
setblock ~55 ~11 ~28 stone
setblock ~86 ~11 ~28 double_stone_block_slab
setblock ~89 ~11 ~28 stone_block_slab 8
setblock ~92 ~11 ~28 stone_block_slab 8
setblock ~5 ~11 ~29 stone_block_slab 8
setblock ~9 ~11 ~29 double_stone_block_slab
setblock ~43 ~11 ~29 leaves 3
setblock ~87 ~11 ~29 double_stone_block_slab
setblock ~91 ~11 ~29 stone_block_slab 8
setblock ~53 ~11 ~30 stone
setblock ~88 ~11 ~30 dirt
setblock ~45 ~11 ~31 stone
setblock ~48 ~11 ~31 stone
setblock ~35 ~11 ~32 stonebrick
setblock ~35 ~11 ~33 stonebrick 2
setblock ~37 ~11 ~34 stonebrick 2
setblock ~82 ~11 ~34 stone
setblock ~39 ~11 ~35 stonebrick 2
setblock ~41 ~11 ~35 stonebrick
setblock ~45 ~11 ~35 stonebrick 1
setblock ~52 ~11 ~35 stonebrick
setblock ~55 ~11 ~35 stonebrick
setblock ~56 ~11 ~35 stonebrick 2
setblock ~63 ~11 ~35 stonebrick 2
setblock ~38 ~11 ~36 stonebrick 2
setblock ~39 ~11 ~36 stonebrick 1
setblock ~43 ~11 ~36 stonebrick 2
setblock ~54 ~11 ~36 stonebrick 2
setblock ~49 ~11 ~37 stonebrick 1
setblock ~62 ~11 ~37 stonebrick 2
setblock ~49 ~11 ~38 stonebrick 2
setblock ~60 ~11 ~38 stonebrick 2
setblock ~35 ~11 ~39 stonebrick
setblock ~46 ~11 ~39 stonebrick 2
setblock ~60 ~11 ~39 stonebrick 1
setblock ~35 ~11 ~40 stonebrick 2
setblock ~43 ~11 ~40 stonebrick 1
setblock ~49 ~11 ~40 stonebrick 2
setblock ~52 ~11 ~40 stonebrick 2
setblock ~28 ~11 ~41 stone
setblock ~43 ~11 ~41 stonebrick
setblock ~68 ~11 ~41 stone
setblock ~36 ~11 ~42 stonebrick 2
setblock ~45 ~11 ~42 stone_block_slab 13
setblock ~51 ~11 ~42 stone_block_slab 13
setblock ~30 ~11 ~43 stone
setblock ~40 ~11 ~43 stonebrick
setblock ~43 ~11 ~43 stonebrick 1
setblock ~44 ~11 ~43 stone_block_slab 13
setblock ~48 ~11 ~43 stone_block_slab 13
setblock ~52 ~11 ~43 stone_block_slab 13
setblock ~53 ~11 ~43 stonebrick 1
setblock ~56 ~11 ~43 stonebrick 1
setblock ~60 ~11 ~43 stonebrick 2
setblock ~67 ~11 ~43 leaves 3
setblock ~40 ~11 ~44 stonebrick 2
setblock ~43 ~11 ~44 stone_block_slab 13
setblock ~53 ~11 ~44 stone_block_slab 13
setblock ~42 ~11 ~45 stone_block_slab 13
setblock ~48 ~11 ~45 stone_block_slab 13
setblock ~54 ~11 ~45 stone_block_slab 13
setblock ~61 ~11 ~45 stonebrick 1
setblock ~35 ~11 ~46 stonebrick
setblock ~55 ~11 ~46 stonebrick
setblock ~57 ~11 ~46 stonebrick 2
setblock ~58 ~11 ~46 stonebrick
setblock ~37 ~11 ~47 stonebrick 1
setblock ~38 ~11 ~47 stonebrick 2
setblock ~40 ~11 ~47 stonebrick 2
setblock ~55 ~11 ~47 stone_block_slab 13
setblock ~24 ~11 ~48 stone
setblock ~43 ~11 ~48 stone_block_slab 13
setblock ~45 ~11 ~48 stone_block_slab 13
setblock ~51 ~11 ~48 stone_block_slab 13
setblock ~54 ~11 ~48 stone_block_slab 13
setblock ~55 ~11 ~48 double_stone_block_slab 5
setblock ~37 ~11 ~49 stonebrick
setblock ~55 ~11 ~49 stone_block_slab 13
setblock ~56 ~11 ~49 stonebrick 2
setblock ~57 ~11 ~49 stonebrick
setblock ~58 ~11 ~49 stonebrick 2
setblock ~59 ~11 ~49 stonebrick 1
setblock ~60 ~11 ~49 stonebrick
setblock ~39 ~11 ~50 stonebrick 2
setblock ~35 ~11 ~51 stonebrick 1
setblock ~42 ~11 ~51 stone_block_slab 13
setblock ~48 ~11 ~51 stone_block_slab 13
setblock ~54 ~11 ~51 stone_block_slab 13
setblock ~40 ~11 ~52 stonebrick
setblock ~43 ~11 ~52 stone_block_slab 13
setblock ~53 ~11 ~52 stone_block_slab 13
setblock ~56 ~11 ~52 stonebrick 2
setblock ~61 ~11 ~52 stonebrick
setblock ~29 ~11 ~53 leaves 3
setblock ~36 ~11 ~53 stonebrick 2
setblock ~40 ~11 ~53 stonebrick 1
setblock ~43 ~11 ~53 stonebrick 1
setblock ~44 ~11 ~53 stone_block_slab 13
setblock ~52 ~11 ~53 stone_block_slab 13
setblock ~53 ~11 ~53 stonebrick 1
setblock ~45 ~11 ~54 stone_block_slab 13
setblock ~51 ~11 ~54 stone_block_slab 13
setblock ~60 ~11 ~54 stonebrick 2
setblock ~28 ~11 ~55 stone
setblock ~47 ~11 ~55 stone_block_slab 13
setblock ~48 ~11 ~55 double_stone_block_slab 5
setblock ~49 ~11 ~55 stone_block_slab 13
setblock ~61 ~11 ~55 stonebrick
setblock ~68 ~11 ~55 stone
setblock ~36 ~11 ~56 stonebrick 2
setblock ~44 ~11 ~56 stonebrick 2
setblock ~47 ~11 ~56 stonebrick 2
setblock ~48 ~11 ~56 stonebrick
setblock ~53 ~11 ~56 stonebrick 1
setblock ~61 ~11 ~56 stonebrick 2
setblock ~25 ~11 ~57 stone
setblock ~36 ~11 ~57 stonebrick 1
setblock ~47 ~11 ~57 stonebrick
setblock ~50 ~11 ~57 stonebrick 2
setblock ~22 ~11 ~58 stone
setblock ~36 ~11 ~58 stonebrick 2
setblock ~47 ~11 ~58 stonebrick 2
setblock ~75 ~11 ~58 stone
setblock ~47 ~11 ~59 stonebrick 1
setblock ~40 ~11 ~60 stonebrick
setblock ~42 ~11 ~60 stonebrick 2
setblock ~43 ~11 ~60 stonebrick
setblock ~53 ~11 ~60 stonebrick 2
setblock ~54 ~11 ~60 stonebrick
setblock ~56 ~11 ~60 stonebrick 2
setblock ~57 ~11 ~60 stonebrick 1
setblock ~58 ~11 ~60 stonebrick 2
setblock ~33 ~11 ~61 stonebrick 2
setblock ~40 ~11 ~61 stonebrick 2
setblock ~51 ~11 ~61 stonebrick 1
setblock ~82 ~11 ~62 stone
setblock ~61 ~11 ~63 stonebrick 2
setblock ~50 ~11 ~64 stone
setblock ~8 ~11 ~66 dirt
setblock ~43 ~11 ~66 stone
setblock ~5 ~11 ~67 stone_block_slab 8
setblock ~9 ~11 ~67 double_stone_block_slab
setblock ~53 ~11 ~67 leaves 3
setblock ~87 ~11 ~67 double_stone_block_slab
setblock ~91 ~11 ~67 stone_block_slab 8
setblock ~4 ~11 ~68 stone_block_slab 8
setblock ~6 ~11 ~68 stone
setblock ~7 ~11 ~68 stone_block_slab 8
setblock ~10 ~11 ~68 double_stone_block_slab
setblock ~24 ~11 ~68 stone
setblock ~41 ~11 ~68 stone
setblock ~55 ~11 ~68 stone
setblock ~86 ~11 ~68 double_stone_block_slab
setblock ~89 ~11 ~68 stone_block_slab 8
setblock ~92 ~11 ~68 stone_block_slab 8
setblock ~3 ~11 ~69 dirt
setblock ~6 ~11 ~69 double_stone_block_slab 5
setblock ~7 ~11 ~69 stone_block_slab 13
setblock ~8 ~11 ~69 diamond_ore
setblock ~11 ~11 ~69 stone
setblock ~85 ~11 ~69 dirt
setblock ~88 ~11 ~69 diamond_ore
setblock ~89 ~11 ~69 stone_block_slab 13
setblock ~90 ~11 ~69 double_stone_block_slab 5
setblock ~93 ~11 ~69 dirt
setblock ~5 ~11 ~70 stone_block_slab 8
setblock ~6 ~11 ~70 stone_block_slab 13
setblock ~7 ~11 ~70 double_stone_block_slab 5
setblock ~8 ~11 ~70 stone_block_slab 13
setblock ~9 ~11 ~70 stone_block_slab 8
setblock ~87 ~11 ~70 stone_block_slab 8
setblock ~88 ~11 ~70 stone_block_slab 13
setblock ~89 ~11 ~70 double_stone_block_slab 5
setblock ~91 ~11 ~70 stone_block_slab 8
setblock ~3 ~11 ~71 dirt
setblock ~8 ~11 ~71 double_stone_block_slab 5
setblock ~87 ~11 ~71 stone
setblock ~88 ~11 ~71 double_stone_block_slab 5
setblock ~3 ~11 ~72 grass
setblock ~7 ~11 ~72 stone_block_slab 8
setblock ~10 ~11 ~72 stone_block_slab 8
setblock ~48 ~11 ~72 stone
setblock ~86 ~11 ~72 stone_block_slab 8
setblock ~89 ~11 ~72 stone_block_slab 8
setblock ~93 ~11 ~72 grass
setblock ~4 ~11 ~73 stonebrick
setblock ~9 ~11 ~73 stone_block_slab 8
setblock ~87 ~11 ~73 stone_block_slab 8
setblock ~5 ~11 ~74 grass
setblock ~8 ~11 ~74 dirt
setblock ~31 ~11 ~74 stone
setblock ~88 ~11 ~74 dirt
setblock ~90 ~11 ~74 dirt
setblock ~91 ~11 ~74 grass
setblock ~18 ~11 ~75 dirt
setblock ~38 ~11 ~75 stone
setblock ~15 ~11 ~76 stone_block_slab 8
setblock ~16 ~11 ~76 stonebrick 2
setblock ~19 ~11 ~76 double_stone_block_slab
setblock ~77 ~11 ~76 double_stone_block_slab
setblock ~81 ~11 ~76 stone_block_slab 8
setblock ~14 ~11 ~77 stone_block_slab 8
setblock ~16 ~11 ~77 stone
setblock ~17 ~11 ~77 stone_block_slab 8
setblock ~20 ~11 ~77 double_stone_block_slab
setblock ~76 ~11 ~77 double_stone_block_slab
setblock ~79 ~11 ~77 stone_block_slab 8
setblock ~82 ~11 ~77 stone_block_slab 8
setblock ~13 ~11 ~78 dirt
setblock ~16 ~11 ~78 double_stone_block_slab 5
setblock ~17 ~11 ~78 stone_block_slab 13
setblock ~18 ~11 ~78 diamond_ore
setblock ~21 ~11 ~78 stone
setblock ~75 ~11 ~78 dirt
setblock ~78 ~11 ~78 diamond_ore
setblock ~79 ~11 ~78 stone_block_slab 13
setblock ~80 ~11 ~78 double_stone_block_slab 5
setblock ~83 ~11 ~78 dirt
setblock ~15 ~11 ~79 stone_block_slab 8
setblock ~16 ~11 ~79 stone_block_slab 13
setblock ~17 ~11 ~79 double_stone_block_slab 5
setblock ~18 ~11 ~79 stone_block_slab 13
setblock ~19 ~11 ~79 stone_block_slab 8
setblock ~77 ~11 ~79 stone_block_slab 8
setblock ~78 ~11 ~79 stone_block_slab 13
setblock ~79 ~11 ~79 double_stone_block_slab 5
setblock ~81 ~11 ~79 stone_block_slab 8
setblock ~13 ~11 ~80 dirt
setblock ~18 ~11 ~80 double_stone_block_slab 5
setblock ~76 ~11 ~80 stonebrick 2
setblock ~77 ~11 ~80 stone
setblock ~78 ~11 ~80 double_stone_block_slab 5
setblock ~13 ~11 ~81 grass
setblock ~17 ~11 ~81 stone_block_slab 8
setblock ~20 ~11 ~81 stone_block_slab 8
setblock ~76 ~11 ~81 stone_block_slab 8
setblock ~79 ~11 ~81 stone_block_slab 8
setblock ~83 ~11 ~81 grass
setblock ~19 ~11 ~82 stone_block_slab 8
setblock ~77 ~11 ~82 stone_block_slab 8
setblock ~15 ~11 ~83 grass
setblock ~18 ~11 ~83 dirt
setblock ~78 ~11 ~83 dirt
setblock ~80 ~11 ~83 dirt
setblock ~81 ~11 ~83 grass
setblock ~27 ~11 ~85 dirt
setblock ~24 ~11 ~86 stone_block_slab 8
setblock ~28 ~11 ~86 double_stone_block_slab
setblock ~68 ~11 ~86 double_stone_block_slab
setblock ~72 ~11 ~86 stone_block_slab 8
setblock ~23 ~11 ~87 stone_block_slab 8
setblock ~25 ~11 ~87 stone
setblock ~26 ~11 ~87 stone_block_slab 8
setblock ~29 ~11 ~87 double_stone_block_slab
setblock ~67 ~11 ~87 double_stone_block_slab
setblock ~70 ~11 ~87 stone_block_slab 8
setblock ~73 ~11 ~87 stone_block_slab 8
setblock ~22 ~11 ~88 dirt
setblock ~25 ~11 ~88 double_stone_block_slab 5
setblock ~26 ~11 ~88 stone_block_slab 13
setblock ~27 ~11 ~88 diamond_ore
setblock ~30 ~11 ~88 stone
setblock ~66 ~11 ~88 dirt
setblock ~69 ~11 ~88 diamond_ore
setblock ~70 ~11 ~88 stone_block_slab 13
setblock ~71 ~11 ~88 double_stone_block_slab 5
setblock ~74 ~11 ~88 dirt
setblock ~24 ~11 ~89 stone_block_slab 8
setblock ~25 ~11 ~89 stone_block_slab 13
setblock ~26 ~11 ~89 double_stone_block_slab 5
setblock ~27 ~11 ~89 stone_block_slab 13
setblock ~28 ~11 ~89 stone_block_slab 8
setblock ~68 ~11 ~89 stone_block_slab 8
setblock ~69 ~11 ~89 stone_block_slab 13
setblock ~70 ~11 ~89 double_stone_block_slab 5
setblock ~72 ~11 ~89 stone_block_slab 8
setblock ~22 ~11 ~90 dirt
setblock ~27 ~11 ~90 double_stone_block_slab 5
setblock ~68 ~11 ~90 stone
setblock ~69 ~11 ~90 double_stone_block_slab 5
setblock ~22 ~11 ~91 grass
setblock ~26 ~11 ~91 stone_block_slab 8
setblock ~29 ~11 ~91 stone_block_slab 8
setblock ~67 ~11 ~91 stone_block_slab 8
setblock ~70 ~11 ~91 stone_block_slab 8
setblock ~74 ~11 ~91 grass
setblock ~23 ~11 ~92 stonebrick
setblock ~28 ~11 ~92 stone_block_slab 8
setblock ~68 ~11 ~92 stone_block_slab 8
setblock ~24 ~11 ~93 grass
setblock ~27 ~11 ~93 dirt
setblock ~69 ~11 ~93 dirt
setblock ~71 ~11 ~93 dirt
setblock ~72 ~11 ~93 grass
setblock ~27 ~12 ~3 grass
setblock ~69 ~12 ~3 grass
setblock ~26 ~12 ~5 grass
setblock ~28 ~12 ~5 stone_block_slab
setblock ~68 ~12 ~5 stone_block_slab
setblock ~70 ~12 ~5 grass
setblock ~71 ~12 ~5 stonebrick
setblock ~28 ~12 ~6 stonebrick
setblock ~68 ~12 ~6 stonebrick
setblock ~70 ~12 ~6 stone 6
setblock ~24 ~12 ~7 grass
setblock ~68 ~12 ~7 grass
setblock ~72 ~12 ~7 grass
setblock ~22 ~12 ~8 grass
setblock ~24 ~12 ~8 stonebrick
setblock ~26 ~12 ~8 stonebrick
setblock ~27 ~12 ~8 stone 6
setblock ~28 ~12 ~8 stonebrick
setblock ~68 ~12 ~8 stonebrick
setblock ~69 ~12 ~8 stone 6
setblock ~70 ~12 ~8 stonebrick
setblock ~72 ~12 ~8 stonebrick
setblock ~74 ~12 ~8 grass
setblock ~24 ~12 ~9 stone_block_slab
setblock ~27 ~12 ~9 stonebrick
setblock ~29 ~12 ~9 stone_block_slab
setblock ~67 ~12 ~9 stone_block_slab
setblock ~69 ~12 ~9 stonebrick
setblock ~72 ~12 ~9 stone_block_slab
setblock ~18 ~12 ~13 grass
setblock ~78 ~12 ~13 grass
setblock ~17 ~12 ~15 grass
setblock ~19 ~12 ~15 stone_block_slab
setblock ~77 ~12 ~15 stone_block_slab
setblock ~79 ~12 ~15 grass
setblock ~80 ~12 ~15 stonebrick
setblock ~19 ~12 ~16 stonebrick
setblock ~34 ~12 ~16 stonebrick 2
setblock ~77 ~12 ~16 stonebrick
setblock ~79 ~12 ~16 stone 6
setblock ~15 ~12 ~17 grass
setblock ~34 ~12 ~17 stonebrick
setblock ~77 ~12 ~17 grass
setblock ~81 ~12 ~17 grass
setblock ~13 ~12 ~18 grass
setblock ~15 ~12 ~18 stonebrick
setblock ~17 ~12 ~18 stonebrick
setblock ~18 ~12 ~18 stone 6
setblock ~19 ~12 ~18 stonebrick 2
setblock ~34 ~12 ~18 stonebrick 2
setblock ~59 ~12 ~18 stonebrick
setblock ~77 ~12 ~18 stonebrick 2
setblock ~78 ~12 ~18 stone 6
setblock ~79 ~12 ~18 stonebrick
setblock ~81 ~12 ~18 stonebrick
setblock ~83 ~12 ~18 grass
setblock ~15 ~12 ~19 stone_block_slab
setblock ~18 ~12 ~19 stonebrick 2
setblock ~20 ~12 ~19 stone_block_slab
setblock ~32 ~12 ~19 dirt
setblock ~34 ~12 ~19 stone 6
setblock ~35 ~12 ~19 stonebrick
setblock ~61 ~12 ~19 stonebrick
setblock ~62 ~12 ~19 stone 6
setblock ~63 ~12 ~19 stonebrick 2
setblock ~76 ~12 ~19 stone_block_slab
setblock ~78 ~12 ~19 stonebrick 2
setblock ~81 ~12 ~19 stone_block_slab
setblock ~58 ~12 ~21 stonebrick
setblock ~8 ~12 ~22 grass
setblock ~31 ~12 ~22 dirt
setblock ~57 ~12 ~22 stone
setblock ~65 ~12 ~22 dirt
setblock ~88 ~12 ~22 grass
setblock ~7 ~12 ~24 grass
setblock ~9 ~12 ~24 stone_block_slab
setblock ~26 ~12 ~24 stone_block_slab
setblock ~27 ~12 ~24 grass
setblock ~69 ~12 ~24 grass
setblock ~70 ~12 ~24 stone_block_slab
setblock ~87 ~12 ~24 stone_block_slab
setblock ~89 ~12 ~24 grass
setblock ~90 ~12 ~24 stonebrick
setblock ~9 ~12 ~25 stonebrick
setblock ~40 ~12 ~25 stone
setblock ~56 ~12 ~25 stone
setblock ~70 ~12 ~25 stonebrick
setblock ~87 ~12 ~25 stonebrick
setblock ~89 ~12 ~25 stone 6
setblock ~5 ~12 ~26 grass
setblock ~25 ~12 ~26 stonebrick
setblock ~26 ~12 ~26 stone 6
setblock ~27 ~12 ~26 stonebrick 2
setblock ~70 ~12 ~26 stone 6
setblock ~87 ~12 ~26 grass
setblock ~91 ~12 ~26 grass
setblock ~3 ~12 ~27 grass
setblock ~5 ~12 ~27 stonebrick
setblock ~7 ~12 ~27 stonebrick
setblock ~8 ~12 ~27 stone 6
setblock ~9 ~12 ~27 stonebrick
setblock ~24 ~12 ~27 grass
setblock ~28 ~12 ~27 stone 6
setblock ~29 ~12 ~27 stonebrick 2
setblock ~67 ~12 ~27 stonebrick
setblock ~68 ~12 ~27 stone 6
setblock ~70 ~12 ~27 stonebrick 2
setblock ~87 ~12 ~27 stonebrick
setblock ~88 ~12 ~27 stone 6
setblock ~89 ~12 ~27 stonebrick
setblock ~91 ~12 ~27 stonebrick
setblock ~93 ~12 ~27 grass
setblock ~5 ~12 ~28 stone_block_slab
setblock ~8 ~12 ~28 stonebrick
setblock ~10 ~12 ~28 stone_block_slab
setblock ~29 ~12 ~28 prismarine
setblock ~67 ~12 ~28 prismarine
setblock ~86 ~12 ~28 stone_block_slab
setblock ~88 ~12 ~28 stonebrick
setblock ~91 ~12 ~28 stone_block_slab
setblock ~27 ~12 ~29 stonebrick
setblock ~29 ~12 ~29 dirt
setblock ~47 ~12 ~29 stone
setblock ~67 ~12 ~29 dirt
setblock ~69 ~12 ~29 stonebrick 2
setblock ~51 ~12 ~30 stone
setblock ~22 ~12 ~31 dirt
setblock ~61 ~12 ~31 stonebrick
setblock ~74 ~12 ~31 dirt
setblock ~19 ~12 ~32 dirt
setblock ~61 ~12 ~32 stonebrick 2
setblock ~77 ~12 ~32 dirt
setblock ~16 ~12 ~33 stone_block_slab
setblock ~17 ~12 ~33 stonebrick
setblock ~19 ~12 ~33 stonebrick 2
setblock ~35 ~12 ~33 stone_block_slab 5
setblock ~36 ~12 ~33 stone_brick_stairs 0
setblock ~37 ~12 ~33 stonebrick
setblock ~59 ~12 ~33 stonebrick
setblock ~60 ~12 ~33 stone_brick_stairs 1
setblock ~19 ~12 ~34 stone 6
setblock ~39 ~12 ~34 stonebrick
setblock ~45 ~12 ~34 stonebrick 2
setblock ~46 ~12 ~34 stonebrick 1
setblock ~49 ~12 ~34 stonebrick
setblock ~50 ~12 ~34 stonebrick 1
setblock ~52 ~12 ~34 stonebrick
setblock ~54 ~12 ~34 stonebrick
setblock ~56 ~12 ~34 stonebrick 2
setblock ~57 ~12 ~34 stonebrick
setblock ~77 ~12 ~34 stone 6
setblock ~78 ~12 ~34 stonebrick 2
setblock ~80 ~12 ~34 stonebrick 2
setblock ~19 ~12 ~35 stonebrick
setblock ~31 ~12 ~35 stonebrick
setblock ~32 ~12 ~35 stonebrick 2
setblock ~48 ~12 ~35 stonebrick
setblock ~63 ~12 ~35 stone_block_slab 5
setblock ~77 ~12 ~35 stonebrick
setblock ~33 ~12 ~36 stone_brick_stairs 2
setblock ~48 ~12 ~36 stonebrick 2
setblock ~63 ~12 ~36 stone_brick_stairs 2
setblock ~18 ~12 ~37 stonebrick
setblock ~33 ~12 ~37 stonebrick
setblock ~39 ~12 ~37 stonebrick 2
setblock ~40 ~12 ~37 stonebrick
setblock ~43 ~12 ~37 stonebrick
setblock ~48 ~12 ~37 stonebrick
setblock ~55 ~12 ~37 stonebrick
setblock ~56 ~12 ~37 stonebrick 1
setblock ~57 ~12 ~37 stonebrick
setblock ~58 ~12 ~37 stonebrick 2
setblock ~21 ~12 ~38 stonebrick
setblock ~34 ~12 ~38 stonebrick
setblock ~37 ~12 ~38 stonebrick 2
setblock ~37 ~12 ~39 stonebrick
setblock ~44 ~12 ~39 stonebrick
setblock ~45 ~12 ~39 stonebrick 2
setblock ~51 ~12 ~39 stonebrick
setblock ~52 ~12 ~39 stonebrick 2
setblock ~53 ~12 ~39 stonebrick 1
setblock ~59 ~12 ~39 stonebrick 2
setblock ~62 ~12 ~39 stonebrick
setblock ~25 ~12 ~40 stone
setblock ~34 ~12 ~40 stonebrick 2
setblock ~37 ~12 ~40 stonebrick 1
setblock ~59 ~12 ~40 stonebrick
setblock ~71 ~12 ~40 stone
setblock ~37 ~12 ~41 stonebrick
setblock ~29 ~12 ~42 stone
setblock ~34 ~12 ~42 stonebrick
setblock ~62 ~12 ~42 stonebrick
setblock ~67 ~12 ~42 stone
setblock ~39 ~12 ~43 stonebrick 1
setblock ~34 ~12 ~44 stonebrick
setblock ~39 ~12 ~44 stonebrick 2
setblock ~48 ~12 ~44 double_stone_block_slab 5
setblock ~57 ~12 ~44 stonebrick
setblock ~37 ~12 ~45 stonebrick
setblock ~39 ~12 ~45 stonebrick
setblock ~57 ~12 ~45 stonebrick 2
setblock ~58 ~12 ~45 stonebrick
setblock ~62 ~12 ~45 stonebrick 2
setblock ~34 ~12 ~46 stonebrick 1
setblock ~46 ~12 ~46 stone_block_slab 13
setblock ~47 ~12 ~46 stonebrick
setblock ~49 ~12 ~46 stonebrick
setblock ~50 ~12 ~46 stone_block_slab 13
setblock ~62 ~12 ~46 stonebrick 1
setblock ~29 ~12 ~47 stone
setblock ~46 ~12 ~47 stonebrick
setblock ~50 ~12 ~47 stonebrick
setblock ~72 ~12 ~47 stone
setblock ~20 ~12 ~48 stone
setblock ~35 ~12 ~48 stonebrick
setblock ~36 ~12 ~48 stonebrick 2
setblock ~37 ~12 ~48 stonebrick
setblock ~44 ~12 ~48 double_stone_block_slab 5
setblock ~48 ~12 ~48 chest 3
setblock ~60 ~12 ~48 stonebrick 2
setblock ~76 ~12 ~48 stone
setblock ~50 ~12 ~49 stonebrick
setblock ~62 ~12 ~49 stonebrick
setblock ~34 ~12 ~50 stonebrick 1
setblock ~49 ~12 ~50 stonebrick
setblock ~50 ~12 ~50 stone_block_slab 13
setblock ~62 ~12 ~50 stonebrick 1
setblock ~34 ~12 ~51 stonebrick 2
setblock ~38 ~12 ~51 stonebrick
setblock ~39 ~12 ~51 stonebrick 2
setblock ~57 ~12 ~51 stonebrick
setblock ~66 ~12 ~51 stone
setblock ~39 ~12 ~52 stonebrick
setblock ~48 ~12 ~52 double_stone_block_slab 5
setblock ~57 ~12 ~52 stonebrick 2
setblock ~62 ~12 ~52 stonebrick
setblock ~57 ~12 ~53 stonebrick 1
setblock ~62 ~12 ~54 stonebrick
setblock ~59 ~12 ~55 stonebrick
setblock ~34 ~12 ~56 stonebrick 2
setblock ~37 ~12 ~56 stonebrick
setblock ~59 ~12 ~56 stonebrick 1
setblock ~62 ~12 ~56 stonebrick 2
setblock ~21 ~12 ~57 stone
setblock ~34 ~12 ~57 stonebrick
setblock ~37 ~12 ~57 stonebrick 2
setblock ~43 ~12 ~57 stonebrick 1
setblock ~44 ~12 ~57 stonebrick 2
setblock ~51 ~12 ~57 stonebrick 2
setblock ~52 ~12 ~57 stonebrick
setblock ~59 ~12 ~57 stonebrick
setblock ~62 ~12 ~57 stonebrick
setblock ~48 ~12 ~58 stonebrick 1
setblock ~59 ~12 ~58 stonebrick 2
setblock ~75 ~12 ~58 stonebrick
setblock ~38 ~12 ~59 stonebrick 2
setblock ~39 ~12 ~59 stonebrick
setblock ~40 ~12 ~59 stonebrick 1
setblock ~41 ~12 ~59 stonebrick
setblock ~44 ~12 ~59 stonebrick
setblock ~48 ~12 ~59 stonebrick
setblock ~56 ~12 ~59 stonebrick
setblock ~57 ~12 ~59 stonebrick 2
setblock ~63 ~12 ~59 stonebrick
setblock ~33 ~12 ~60 stone_brick_stairs 3
setblock ~48 ~12 ~60 stonebrick 2
setblock ~63 ~12 ~60 stone_brick_stairs 3
setblock ~64 ~12 ~60 stonebrick
setblock ~19 ~12 ~61 stonebrick
setblock ~33 ~12 ~61 stone_block_slab 5
setblock ~64 ~12 ~61 stonebrick 2
setblock ~77 ~12 ~61 stonebrick
setblock ~81 ~12 ~61 stonebrick
setblock ~16 ~12 ~62 stonebrick 2
setblock ~17 ~12 ~62 stonebrick
setblock ~18 ~12 ~62 stonebrick 2
setblock ~19 ~12 ~62 stone 6
setblock ~38 ~12 ~62 stonebrick
setblock ~40 ~12 ~62 stonebrick 2
setblock ~42 ~12 ~62 stonebrick
setblock ~46 ~12 ~62 stonebrick 1
setblock ~47 ~12 ~62 stonebrick
setblock ~48 ~12 ~62 stonebrick 2
setblock ~50 ~12 ~62 stonebrick 1
setblock ~51 ~12 ~62 stonebrick 2
setblock ~56 ~12 ~62 stonebrick 2
setblock ~57 ~12 ~62 stonebrick
setblock ~77 ~12 ~62 stone 6
setblock ~78 ~12 ~62 stonebrick
setblock ~82 ~12 ~62 stone_block_slab
setblock ~36 ~12 ~63 stone_brick_stairs 0
setblock ~37 ~12 ~63 stonebrick
setblock ~60 ~12 ~63 stone_brick_stairs 1
setblock ~61 ~12 ~63 stone_block_slab 5
setblock ~77 ~12 ~63 stonebrick 2
setblock ~35 ~12 ~64 stonebrick 2
setblock ~22 ~12 ~65 dirt
setblock ~74 ~12 ~65 dirt
setblock ~6 ~12 ~66 grass
setblock ~90 ~12 ~66 grass
setblock ~9 ~12 ~67 stone_block_slab
setblock ~27 ~12 ~67 stonebrick 2
setblock ~28 ~12 ~67 prismarine
setblock ~29 ~12 ~67 dirt
setblock ~42 ~12 ~67 stone
setblock ~54 ~12 ~67 stone
setblock ~67 ~12 ~67 dirt
setblock ~69 ~12 ~67 stonebrick
setblock ~87 ~12 ~67 stone_block_slab
setblock ~5 ~12 ~68 stone_block_slab
setblock ~6 ~12 ~68 stonebrick
setblock ~8 ~12 ~68 stonebrick
setblock ~25 ~12 ~68 grass
setblock ~27 ~12 ~68 stone 6
setblock ~71 ~12 ~68 grass
setblock ~86 ~12 ~68 stone_block_slab
setblock ~87 ~12 ~68 stone 6
setblock ~88 ~12 ~68 stonebrick
setblock ~90 ~12 ~68 stonebrick
setblock ~91 ~12 ~68 stone_block_slab
setblock ~3 ~12 ~69 grass
setblock ~8 ~12 ~69 stone 6
setblock ~9 ~12 ~69 stonebrick
setblock ~26 ~12 ~69 stonebrick 2
setblock ~29 ~12 ~69 stonebrick
setblock ~67 ~12 ~69 stonebrick 2
setblock ~70 ~12 ~69 stonebrick
setblock ~86 ~12 ~69 grass
setblock ~87 ~12 ~69 stonebrick
setblock ~88 ~12 ~69 stone 6
setblock ~93 ~12 ~69 grass
setblock ~5 ~12 ~70 grass
setblock ~6 ~12 ~70 stone 6
setblock ~24 ~12 ~70 stone_block_slab
setblock ~26 ~12 ~70 stone 6
setblock ~69 ~12 ~70 stonebrick 2
setblock ~70 ~12 ~70 stone 6
setblock ~90 ~12 ~70 stone 6
setblock ~91 ~12 ~70 grass
setblock ~5 ~12 ~71 stonebrick
setblock ~9 ~12 ~71 stonebrick
setblock ~40 ~12 ~71 stone
setblock ~56 ~12 ~71 stone
setblock ~68 ~12 ~71 grass
setblock ~87 ~12 ~71 stonebrick
setblock ~91 ~12 ~71 stonebrick
setblock ~7 ~12 ~72 grass
setblock ~9 ~12 ~72 stone_block_slab
setblock ~87 ~12 ~72 stone_block_slab
setblock ~89 ~12 ~72 grass
setblock ~8 ~12 ~74 grass
setblock ~31 ~12 ~74 dirt
setblock ~52 ~12 ~74 stone
setblock ~65 ~12 ~74 dirt
setblock ~88 ~12 ~74 grass
setblock ~16 ~12 ~75 grass
setblock ~38 ~12 ~75 stonebrick
setblock ~46 ~12 ~75 stone
setblock ~80 ~12 ~75 grass
setblock ~19 ~12 ~76 stone_block_slab
setblock ~77 ~12 ~76 stone_block_slab
setblock ~15 ~12 ~77 stone_block_slab
setblock ~16 ~12 ~77 stonebrick
setblock ~18 ~12 ~77 stonebrick 2
setblock ~33 ~12 ~77 stonebrick 2
setblock ~34 ~12 ~77 stone 6
setblock ~35 ~12 ~77 stonebrick
setblock ~61 ~12 ~77 stonebrick
setblock ~62 ~12 ~77 stone 6
setblock ~76 ~12 ~77 stone_block_slab
setblock ~77 ~12 ~77 stone 6
setblock ~78 ~12 ~77 stonebrick 2
setblock ~80 ~12 ~77 stonebrick
setblock ~81 ~12 ~77 stone_block_slab
setblock ~13 ~12 ~78 grass
setblock ~18 ~12 ~78 stone 6
setblock ~19 ~12 ~78 stonebrick 2
setblock ~62 ~12 ~78 stonebrick 2
setblock ~76 ~12 ~78 grass
setblock ~77 ~12 ~78 stonebrick 2
setblock ~78 ~12 ~78 stone 6
setblock ~83 ~12 ~78 grass
setblock ~15 ~12 ~79 grass
setblock ~16 ~12 ~79 stone 6
setblock ~80 ~12 ~79 stone 6
setblock ~81 ~12 ~79 grass
setblock ~15 ~12 ~80 stonebrick
setblock ~19 ~12 ~80 stonebrick
setblock ~62 ~12 ~80 stonebrick 2
setblock ~77 ~12 ~80 stonebrick
setblock ~81 ~12 ~80 stonebrick
setblock ~17 ~12 ~81 grass
setblock ~19 ~12 ~81 stone_block_slab
setblock ~77 ~12 ~81 stone_block_slab
setblock ~79 ~12 ~81 grass
setblock ~18 ~12 ~83 grass
setblock ~78 ~12 ~83 grass
setblock ~25 ~12 ~85 grass
setblock ~71 ~12 ~85 grass
setblock ~28 ~12 ~86 stone_block_slab
setblock ~68 ~12 ~86 stone_block_slab
setblock ~24 ~12 ~87 stone_block_slab
setblock ~25 ~12 ~87 stonebrick
setblock ~27 ~12 ~87 stonebrick
setblock ~67 ~12 ~87 stone_block_slab
setblock ~68 ~12 ~87 stone 6
setblock ~69 ~12 ~87 stonebrick
setblock ~71 ~12 ~87 stonebrick
setblock ~72 ~12 ~87 stone_block_slab
setblock ~22 ~12 ~88 grass
setblock ~27 ~12 ~88 stone 6
setblock ~28 ~12 ~88 stonebrick
setblock ~67 ~12 ~88 grass
setblock ~68 ~12 ~88 stonebrick
setblock ~69 ~12 ~88 stone 6
setblock ~74 ~12 ~88 grass
setblock ~24 ~12 ~89 grass
setblock ~25 ~12 ~89 stone 6
setblock ~71 ~12 ~89 stone 6
setblock ~72 ~12 ~89 grass
setblock ~24 ~12 ~90 stonebrick
setblock ~28 ~12 ~90 stonebrick
setblock ~68 ~12 ~90 stonebrick
setblock ~72 ~12 ~90 stonebrick
setblock ~26 ~12 ~91 grass
setblock ~28 ~12 ~91 stone_block_slab
setblock ~68 ~12 ~91 stone_block_slab
setblock ~70 ~12 ~91 grass
setblock ~27 ~12 ~93 grass
setblock ~69 ~12 ~93 grass
setblock ~23 ~13 ~3 stone_brick_stairs 2
setblock ~27 ~13 ~3 leaves 3
setblock ~69 ~13 ~3 leaves 3
setblock ~73 ~13 ~3 stone_brick_stairs 2
setblock ~22 ~13 ~4 stone_brick_stairs 0
setblock ~23 ~13 ~4 diamond_ore
setblock ~24 ~13 ~4 stone_block_slab 8
setblock ~72 ~13 ~4 stone_block_slab 8
setblock ~73 ~13 ~4 diamond_ore
setblock ~74 ~13 ~4 stone_brick_stairs 1
setblock ~23 ~13 ~5 stone_block_slab 8
setblock ~70 ~13 ~5 leaves 2
setblock ~73 ~13 ~5 stone_block_slab 8
setblock ~30 ~13 ~6 leaves 3
setblock ~67 ~13 ~6 stonebrick
setblock ~24 ~13 ~7 leaves 2
setblock ~29 ~13 ~7 chest 4
setblock ~30 ~13 ~7 stone_block_slab 8
setblock ~66 ~13 ~7 stone_block_slab 8
setblock ~67 ~13 ~7 chest 5
setblock ~22 ~13 ~8 leaves 3
setblock ~74 ~13 ~8 leaves 3
setblock ~25 ~13 ~10 stonebrick
setblock ~26 ~13 ~10 chest 2
setblock ~70 ~13 ~10 chest 2
setblock ~26 ~13 ~11 stone_block_slab 8
setblock ~70 ~13 ~11 stone_block_slab 8
setblock ~71 ~13 ~11 leaves 3
setblock ~14 ~13 ~13 stone_brick_stairs 2
setblock ~18 ~13 ~13 leaves 3
setblock ~78 ~13 ~13 leaves 3
setblock ~82 ~13 ~13 stone_brick_stairs 2
setblock ~13 ~13 ~14 stone_brick_stairs 0
setblock ~14 ~13 ~14 diamond_ore
setblock ~15 ~13 ~14 stone_block_slab 8
setblock ~81 ~13 ~14 stone_block_slab 8
setblock ~82 ~13 ~14 diamond_ore
setblock ~83 ~13 ~14 stone_brick_stairs 1
setblock ~14 ~13 ~15 stone_block_slab 8
setblock ~79 ~13 ~15 leaves 2
setblock ~82 ~13 ~15 stone_block_slab 8
setblock ~21 ~13 ~16 leaves 3
setblock ~36 ~13 ~16 tallgrass 1
setblock ~60 ~13 ~16 tallgrass 1
setblock ~76 ~13 ~16 stonebrick
setblock ~15 ~13 ~17 leaves 2
setblock ~20 ~13 ~17 chest 4
setblock ~21 ~13 ~17 stone_block_slab 8
setblock ~22 ~13 ~17 stonebrick 2
setblock ~75 ~13 ~17 stone_block_slab 8
setblock ~76 ~13 ~17 chest 5
setblock ~13 ~13 ~18 leaves 3
setblock ~83 ~13 ~18 leaves 3
setblock ~36 ~13 ~19 tallgrass 1
setblock ~38 ~13 ~19 leaves 3
setblock ~16 ~13 ~20 stonebrick
setblock ~17 ~13 ~20 chest 2
setblock ~50 ~13 ~20 stone
setblock ~79 ~13 ~20 chest 2
setblock ~17 ~13 ~21 stone_block_slab 8
setblock ~33 ~13 ~21 stonebrick
setblock ~34 ~13 ~21 stone 6
setblock ~35 ~13 ~21 stonebrick 2
setblock ~58 ~13 ~21 stonebrick 2
setblock ~62 ~13 ~21 stone 6
setblock ~63 ~13 ~21 stonebrick
setblock ~79 ~13 ~21 stone_block_slab 8
setblock ~80 ~13 ~21 leaves 3
setblock ~4 ~13 ~22 stone_brick_stairs 2
setblock ~8 ~13 ~22 leaves 3
setblock ~31 ~13 ~22 grass
setblock ~34 ~13 ~22 stonebrick 2
setblock ~62 ~13 ~22 stonebrick
setblock ~65 ~13 ~22 grass
setblock ~79 ~13 ~22 stonebrick 2
setblock ~88 ~13 ~22 leaves 3
setblock ~92 ~13 ~22 stone_brick_stairs 2
setblock ~3 ~13 ~23 stone_brick_stairs 0
setblock ~4 ~13 ~23 diamond_ore
setblock ~5 ~13 ~23 stone_block_slab 8
setblock ~44 ~13 ~23 stone
setblock ~91 ~13 ~23 stone_block_slab 8
setblock ~92 ~13 ~23 diamond_ore
setblock ~93 ~13 ~23 stone_brick_stairs 1
setblock ~4 ~13 ~24 stone_block_slab 8
setblock ~28 ~13 ~24 tallgrass 1
setblock ~33 ~13 ~24 stonebrick
setblock ~63 ~13 ~24 stonebrick
setblock ~89 ~13 ~24 leaves 2
setblock ~92 ~13 ~24 stone_block_slab 8
setblock ~11 ~13 ~25 leaves 3
setblock ~33 ~13 ~25 stonebrick 2
setblock ~34 ~13 ~25 stonebrick
setblock ~40 ~13 ~25 grass
setblock ~56 ~13 ~25 grass
setblock ~62 ~13 ~25 stonebrick
setblock ~63 ~13 ~25 stonebrick 2
setblock ~68 ~13 ~25 tallgrass 1
setblock ~86 ~13 ~25 stonebrick
setblock ~5 ~13 ~26 leaves 2
setblock ~10 ~13 ~26 chest 4
setblock ~11 ~13 ~26 stone_block_slab 8
setblock ~62 ~13 ~26 stone 6
setblock ~63 ~13 ~26 stonebrick
setblock ~65 ~13 ~26 stonebrick 2
setblock ~85 ~13 ~26 stone_block_slab 8
setblock ~86 ~13 ~26 chest 5
setblock ~3 ~13 ~27 leaves 3
setblock ~40 ~13 ~27 dirt
setblock ~56 ~13 ~27 dirt
setblock ~93 ~13 ~27 leaves 3
setblock ~25 ~13 ~28 tallgrass 1
setblock ~35 ~13 ~28 stone 6
setblock ~61 ~13 ~28 stone 6
setblock ~62 ~13 ~28 stonebrick 2
setblock ~72 ~13 ~28 tallgrass 1
setblock ~6 ~13 ~29 stonebrick
setblock ~7 ~13 ~29 chest 2
setblock ~42 ~13 ~29 dirt
setblock ~54 ~13 ~29 dirt
setblock ~89 ~13 ~29 chest 2
setblock ~7 ~13 ~30 stone_block_slab 8
setblock ~34 ~13 ~30 dirt
setblock ~36 ~13 ~30 stonebrick 2
setblock ~53 ~13 ~30 dirt
setblock ~60 ~13 ~30 stonebrick
setblock ~62 ~13 ~30 dirt
setblock ~65 ~13 ~30 stone 4
setblock ~89 ~13 ~30 stone_block_slab 8
setblock ~90 ~13 ~30 leaves 3
setblock ~22 ~13 ~31 grass
setblock ~24 ~13 ~31 dirt
setblock ~26 ~13 ~31 stonebrick 2
setblock ~30 ~13 ~31 stone 4
setblock ~37 ~13 ~31 stonebrick 2
setblock ~60 ~13 ~31 water
setblock ~71 ~13 ~31 grass
setblock ~74 ~13 ~31 grass
setblock ~31 ~13 ~32 dirt
setblock ~34 ~13 ~32 stonebrick
setblock ~60 ~13 ~32 iron_bars
setblock ~21 ~13 ~33 stonebrick
setblock ~24 ~13 ~33 stonebrick
setblock ~25 ~13 ~33 stonebrick 2
setblock ~59 ~13 ~33 stonebrick 2
setblock ~67 ~13 ~33 stonebrick
setblock ~69 ~13 ~33 stone 6
setblock ~71 ~13 ~33 stonebrick 2
setblock ~72 ~13 ~33 stonebrick
setblock ~74 ~13 ~33 stone 6
setblock ~75 ~13 ~33 stonebrick
setblock ~21 ~13 ~34 stone 6
setblock ~22 ~13 ~34 stonebrick
setblock ~25 ~13 ~34 stonebrick
setblock ~28 ~13 ~34 stonebrick 2
setblock ~34 ~13 ~34 stonebrick 1
setblock ~46 ~13 ~34 stonebrick 2
setblock ~52 ~13 ~34 stonebrick 2
setblock ~54 ~13 ~34 stonebrick 2
setblock ~62 ~13 ~34 stonebrick 1
setblock ~64 ~13 ~34 stonebrick
setblock ~71 ~13 ~34 stonebrick
setblock ~74 ~13 ~34 stonebrick 2
setblock ~75 ~13 ~34 stone 6
setblock ~28 ~13 ~35 stone 6
setblock ~66 ~13 ~35 stonebrick
setblock ~67 ~13 ~35 dirt
setblock ~68 ~13 ~35 stone 6
setblock ~75 ~13 ~35 stonebrick 2
setblock ~16 ~13 ~36 tallgrass 1
setblock ~30 ~13 ~36 stonebrick
setblock ~32 ~13 ~36 iron_bars
setblock ~66 ~13 ~36 stonebrick 2
setblock ~71 ~13 ~36 dirt
setblock ~77 ~13 ~36 tallgrass 1
setblock ~80 ~13 ~36 tallgrass 1
setblock ~33 ~13 ~37 stonebrick 2
setblock ~65 ~13 ~37 stonebrick 2
setblock ~21 ~13 ~38 stonebrick 2
setblock ~39 ~13 ~38 dirt
setblock ~42 ~13 ~38 grass
setblock ~54 ~13 ~38 grass
setblock ~57 ~13 ~38 dirt
setblock ~62 ~13 ~38 stonebrick
setblock ~77 ~13 ~38 leaves 3
setblock ~21 ~13 ~39 stone
setblock ~42 ~13 ~39 dirt
setblock ~44 ~13 ~39 stonebrick 2
setblock ~51 ~13 ~39 stonebrick 2
setblock ~54 ~13 ~39 dirt
setblock ~25 ~13 ~40 grass
setblock ~27 ~13 ~40 dirt
setblock ~69 ~13 ~40 dirt
setblock ~71 ~13 ~40 grass
setblock ~41 ~13 ~41 dirt
setblock ~55 ~13 ~41 dirt
setblock ~29 ~13 ~42 dirt
setblock ~34 ~13 ~42 stonebrick 2
setblock ~39 ~13 ~42 dirt
setblock ~57 ~13 ~42 dirt
setblock ~67 ~13 ~42 dirt
setblock ~30 ~13 ~43 dirt
setblock ~34 ~13 ~44 stonebrick 2
setblock ~57 ~13 ~44 stonebrick 2
setblock ~39 ~13 ~45 stonebrick 2
setblock ~62 ~13 ~45 stonebrick
setblock ~62 ~13 ~46 stonebrick 2
setblock ~34 ~13 ~50 stonebrick 2
setblock ~34 ~13 ~51 stonebrick
setblock ~57 ~13 ~51 stonebrick 2
setblock ~39 ~13 ~52 stonebrick 2
setblock ~62 ~13 ~52 stonebrick 2
setblock ~66 ~13 ~53 dirt
setblock ~29 ~13 ~54 dirt
setblock ~38 ~13 ~54 grass
setblock ~39 ~13 ~54 dirt
setblock ~57 ~13 ~54 dirt
setblock ~62 ~13 ~54 stonebrick 2
setblock ~67 ~13 ~54 dirt
setblock ~41 ~13 ~55 dirt
setblock ~55 ~13 ~55 dirt
setblock ~25 ~13 ~56 grass
setblock ~27 ~13 ~56 dirt
setblock ~69 ~13 ~56 dirt
setblock ~71 ~13 ~56 grass
setblock ~38 ~13 ~57 dirt
setblock ~42 ~13 ~57 dirt
setblock ~45 ~13 ~57 stonebrick 2
setblock ~52 ~13 ~57 stonebrick 2
setblock ~54 ~13 ~57 dirt
setblock ~75 ~13 ~57 stone
setblock ~19 ~13 ~58 leaves 3
setblock ~34 ~13 ~58 stonebrick
setblock ~75 ~13 ~58 stonebrick 2
setblock ~31 ~13 ~59 stonebrick 2
setblock ~63 ~13 ~59 stonebrick 2
setblock ~16 ~13 ~60 tallgrass 1
setblock ~19 ~13 ~60 tallgrass 1
setblock ~30 ~13 ~60 stonebrick 2
setblock ~64 ~13 ~60 iron_bars
setblock ~80 ~13 ~60 tallgrass 1
setblock ~21 ~13 ~61 stonebrick 2
setblock ~28 ~13 ~61 stone 6
setblock ~68 ~13 ~61 stone 6
setblock ~75 ~13 ~61 stonebrick
setblock ~21 ~13 ~62 stone 6
setblock ~22 ~13 ~62 stonebrick 2
setblock ~24 ~13 ~62 stone 6
setblock ~26 ~13 ~62 stone 6
setblock ~32 ~13 ~62 stonebrick
setblock ~34 ~13 ~62 stonebrick 1
setblock ~42 ~13 ~62 stonebrick 2
setblock ~44 ~13 ~62 stonebrick 2
setblock ~50 ~13 ~62 stonebrick 2
setblock ~51 ~13 ~62 stonebrick
setblock ~58 ~13 ~62 stonebrick
setblock ~62 ~13 ~62 stonebrick 1
setblock ~68 ~13 ~62 stonebrick 2
setblock ~70 ~13 ~62 stone 6
setblock ~75 ~13 ~62 stone 6
setblock ~21 ~13 ~63 stonebrick
setblock ~24 ~13 ~63 stonebrick
setblock ~25 ~13 ~63 stonebrick 2
setblock ~31 ~13 ~63 dirt
setblock ~37 ~13 ~63 stonebrick 2
setblock ~65 ~13 ~63 dirt
setblock ~71 ~13 ~63 stonebrick 2
setblock ~72 ~13 ~63 stonebrick
setblock ~75 ~13 ~63 stonebrick
setblock ~36 ~13 ~64 iron_bars
setblock ~62 ~13 ~64 stonebrick
setblock ~59 ~13 ~65 stonebrick 2
setblock ~66 ~13 ~65 stone 4
setblock ~70 ~13 ~65 stonebrick 2
setblock ~6 ~13 ~66 leaves 3
setblock ~7 ~13 ~66 stone_block_slab 8
setblock ~31 ~13 ~66 stone 4
setblock ~36 ~13 ~66 stonebrick
setblock ~43 ~13 ~66 dirt
setblock ~60 ~13 ~66 stonebrick 2
setblock ~89 ~13 ~66 stone_block_slab 8
setblock ~7 ~13 ~67 chest 3
setblock ~34 ~13 ~67 stonebrick
setblock ~35 ~13 ~67 dirt
setblock ~42 ~13 ~67 dirt
setblock ~54 ~13 ~67 dirt
setblock ~61 ~13 ~67 dirt
setblock ~89 ~13 ~67 chest 3
setblock ~90 ~13 ~67 stonebrick
setblock ~24 ~13 ~68 tallgrass 1
setblock ~31 ~13 ~68 stonebrick
setblock ~34 ~13 ~68 stonebrick 2
setblock ~35 ~13 ~68 stone 6
setblock ~61 ~13 ~68 stone 6
setblock ~71 ~13 ~68 tallgrass 1
setblock ~3 ~13 ~69 leaves 3
setblock ~33 ~13 ~69 stone 6
setblock ~40 ~13 ~69 dirt
setblock ~56 ~13 ~69 dirt
setblock ~63 ~13 ~69 stone 6
setblock ~93 ~13 ~69 leaves 3
setblock ~10 ~13 ~70 chest 4
setblock ~11 ~13 ~70 stone_block_slab 8
setblock ~31 ~13 ~70 stonebrick 2
setblock ~85 ~13 ~70 stone_block_slab 8
setblock ~86 ~13 ~70 chest 5
setblock ~91 ~13 ~70 leaves 2
setblock ~10 ~13 ~71 stonebrick
setblock ~28 ~13 ~71 tallgrass 1
setblock ~31 ~13 ~71 grass
setblock ~33 ~13 ~71 stonebrick 2
setblock ~34 ~13 ~71 stonebrick
setblock ~40 ~13 ~71 grass
setblock ~56 ~13 ~71 grass
setblock ~62 ~13 ~71 stonebrick
setblock ~63 ~13 ~71 stonebrick 2
setblock ~65 ~13 ~71 grass
setblock ~85 ~13 ~71 leaves 3
setblock ~4 ~13 ~72 stone_block_slab 8
setblock ~7 ~13 ~72 leaves 2
setblock ~33 ~13 ~72 stonebrick
setblock ~63 ~13 ~72 stonebrick
setblock ~68 ~13 ~72 tallgrass 1
setblock ~92 ~13 ~72 stone_block_slab 8
setblock ~3 ~13 ~73 stone_brick_stairs 0
setblock ~4 ~13 ~73 diamond_ore
setblock ~5 ~13 ~73 stone_block_slab 8
setblock ~91 ~13 ~73 stone_block_slab 8
setblock ~92 ~13 ~73 diamond_ore
setblock ~93 ~13 ~73 stone_brick_stairs 1
setblock ~4 ~13 ~74 stone_brick_stairs 3
setblock ~8 ~13 ~74 leaves 3
setblock ~17 ~13 ~74 stonebrick 2
setblock ~31 ~13 ~74 grass
setblock ~34 ~13 ~74 stonebrick
setblock ~62 ~13 ~74 stonebrick 2
setblock ~65 ~13 ~74 grass
setblock ~88 ~13 ~74 leaves 3
setblock ~92 ~13 ~74 stone_brick_stairs 3
setblock ~16 ~13 ~75 leaves 3
setblock ~17 ~13 ~75 stone_block_slab 8
setblock ~33 ~13 ~75 stonebrick
setblock ~34 ~13 ~75 stone 6
setblock ~38 ~13 ~75 stonebrick 2
setblock ~51 ~13 ~75 stone
setblock ~61 ~13 ~75 stonebrick 2
setblock ~62 ~13 ~75 stone 6
setblock ~63 ~13 ~75 stonebrick
setblock ~79 ~13 ~75 stone_block_slab 8
setblock ~17 ~13 ~76 chest 3
setblock ~79 ~13 ~76 chest 3
setblock ~80 ~13 ~76 stonebrick
setblock ~58 ~13 ~77 leaves 3
setblock ~60 ~13 ~77 tallgrass 1
setblock ~13 ~13 ~78 leaves 3
setblock ~83 ~13 ~78 leaves 3
setblock ~20 ~13 ~79 chest 4
setblock ~21 ~13 ~79 stone_block_slab 8
setblock ~74 ~13 ~79 stonebrick 2
setblock ~75 ~13 ~79 stone_block_slab 8
setblock ~76 ~13 ~79 chest 5
setblock ~81 ~13 ~79 leaves 2
setblock ~20 ~13 ~80 stonebrick
setblock ~36 ~13 ~80 tallgrass 1
setblock ~60 ~13 ~80 tallgrass 1
setblock ~75 ~13 ~80 leaves 3
setblock ~14 ~13 ~81 stone_block_slab 8
setblock ~17 ~13 ~81 leaves 2
setblock ~82 ~13 ~81 stone_block_slab 8
setblock ~13 ~13 ~82 stone_brick_stairs 0
setblock ~14 ~13 ~82 diamond_ore
setblock ~15 ~13 ~82 stone_block_slab 8
setblock ~81 ~13 ~82 stone_block_slab 8
setblock ~82 ~13 ~82 diamond_ore
setblock ~83 ~13 ~82 stone_brick_stairs 1
setblock ~14 ~13 ~83 stone_brick_stairs 3
setblock ~18 ~13 ~83 leaves 3
setblock ~78 ~13 ~83 leaves 3
setblock ~82 ~13 ~83 stone_brick_stairs 3
setblock ~25 ~13 ~85 leaves 3
setblock ~26 ~13 ~85 stone_block_slab 8
setblock ~70 ~13 ~85 stone_block_slab 8
setblock ~26 ~13 ~86 chest 3
setblock ~70 ~13 ~86 chest 3
setblock ~71 ~13 ~86 stonebrick
setblock ~22 ~13 ~88 leaves 3
setblock ~74 ~13 ~88 leaves 3
setblock ~29 ~13 ~89 chest 4
setblock ~30 ~13 ~89 stone_block_slab 8
setblock ~66 ~13 ~89 stone_block_slab 8
setblock ~67 ~13 ~89 chest 5
setblock ~72 ~13 ~89 leaves 2
setblock ~29 ~13 ~90 stonebrick
setblock ~66 ~13 ~90 leaves 3
setblock ~23 ~13 ~91 stone_block_slab 8
setblock ~26 ~13 ~91 leaves 2
setblock ~73 ~13 ~91 stone_block_slab 8
setblock ~22 ~13 ~92 stone_brick_stairs 0
setblock ~23 ~13 ~92 diamond_ore
setblock ~24 ~13 ~92 stone_block_slab 8
setblock ~72 ~13 ~92 stone_block_slab 8
setblock ~73 ~13 ~92 diamond_ore
setblock ~74 ~13 ~92 stone_brick_stairs 1
setblock ~23 ~13 ~93 stone_brick_stairs 3
setblock ~27 ~13 ~93 leaves 3
setblock ~69 ~13 ~93 leaves 3
setblock ~73 ~13 ~93 stone_brick_stairs 3
setblock ~23 ~14 ~2 stone_brick_stairs 0
setblock ~73 ~14 ~2 stone_brick_stairs 1
setblock ~22 ~14 ~3 stone_block_slab 8
setblock ~24 ~14 ~3 stone_block_slab 8
setblock ~72 ~14 ~3 stone_block_slab 8
setblock ~74 ~14 ~3 stone_block_slab 8
setblock ~21 ~14 ~4 stone_brick_stairs 2
setblock ~27 ~14 ~4 stone_block_slab
setblock ~69 ~14 ~4 stone_block_slab
setblock ~75 ~14 ~4 stone_brick_stairs 2
setblock ~22 ~14 ~5 stone_block_slab 8
setblock ~74 ~14 ~5 stone_block_slab 8
setblock ~23 ~14 ~8 stone_block_slab
setblock ~73 ~14 ~8 stone_block_slab
setblock ~14 ~14 ~12 stone_brick_stairs 0
setblock ~82 ~14 ~12 stone_brick_stairs 1
setblock ~13 ~14 ~13 stone_block_slab 8
setblock ~15 ~14 ~13 stone_block_slab 8
setblock ~81 ~14 ~13 stone_block_slab 8
setblock ~83 ~14 ~13 stone_block_slab 8
setblock ~12 ~14 ~14 stone_brick_stairs 2
setblock ~14 ~14 ~14 stone 3
setblock ~18 ~14 ~14 stone_block_slab
setblock ~78 ~14 ~14 stone_block_slab
setblock ~82 ~14 ~14 stone 3
setblock ~84 ~14 ~14 stone_brick_stairs 2
setblock ~13 ~14 ~15 stone_block_slab 8
setblock ~83 ~14 ~15 stone_block_slab 8
setblock ~37 ~14 ~17 stonebrick 2
setblock ~14 ~14 ~18 stone_block_slab
setblock ~82 ~14 ~18 stone_block_slab
setblock ~46 ~14 ~19 stonebrick
setblock ~49 ~14 ~19 stonebrick
setblock ~50 ~14 ~19 stonebrick 2
setblock ~64 ~14 ~19 tallgrass 1
setblock ~38 ~14 ~20 leaves 3
setblock ~48 ~14 ~20 stone 6
setblock ~4 ~14 ~21 stone_brick_stairs 0
setblock ~46 ~14 ~21 stonebrick 2
setblock ~47 ~14 ~21 stone 6
setblock ~48 ~14 ~21 double_stone_block_slab
setblock ~49 ~14 ~21 stone 6
setblock ~50 ~14 ~21 stonebrick 2
setblock ~56 ~14 ~21 stone
setblock ~57 ~14 ~21 stonebrick 2
setblock ~92 ~14 ~21 stone_brick_stairs 1
setblock ~3 ~14 ~22 stone_block_slab 8
setblock ~5 ~14 ~22 stone_block_slab 8
setblock ~32 ~14 ~22 tallgrass 1
setblock ~36 ~14 ~22 leaves 3
setblock ~46 ~14 ~22 stonebrick
setblock ~47 ~14 ~22 stone_brick_stairs 1
setblock ~48 ~14 ~22 chest 3
setblock ~49 ~14 ~22 stone_brick_stairs 0
setblock ~56 ~14 ~22 dirt
setblock ~60 ~14 ~22 leaves 3
setblock ~64 ~14 ~22 tallgrass 1
setblock ~91 ~14 ~22 stone_block_slab 8
setblock ~93 ~14 ~22 stone_block_slab 8
setblock ~2 ~14 ~23 stone_brick_stairs 2
setblock ~8 ~14 ~23 stone_block_slab
setblock ~46 ~14 ~23 stonebrick 2
setblock ~47 ~14 ~23 stonebrick
setblock ~48 ~14 ~23 double_stone_block_slab
setblock ~49 ~14 ~23 stonebrick 2
setblock ~56 ~14 ~23 stone
setblock ~60 ~14 ~23 tallgrass 2
setblock ~88 ~14 ~23 stone_block_slab
setblock ~94 ~14 ~23 stone_brick_stairs 2
setblock ~3 ~14 ~24 stone_block_slab 8
setblock ~45 ~14 ~24 stonebrick 2
setblock ~59 ~14 ~24 stonebrick 2
setblock ~64 ~14 ~24 tallgrass 1
setblock ~93 ~14 ~24 stone_block_slab 8
setblock ~31 ~14 ~25 tallgrass 1
setblock ~39 ~14 ~25 stonebrick 2
setblock ~40 ~14 ~25 tallgrass 1
setblock ~65 ~14 ~25 tallgrass 2
setblock ~39 ~14 ~26 stonebrick
setblock ~47 ~14 ~26 stonebrick
setblock ~4 ~14 ~27 stone_block_slab
setblock ~38 ~14 ~27 stonebrick
setblock ~39 ~14 ~27 stonebrick 2
setblock ~92 ~14 ~27 stone_block_slab
setblock ~38 ~14 ~28 stonebrick 2
setblock ~49 ~14 ~28 stonebrick 2
setblock ~31 ~14 ~29 tallgrass 1
setblock ~64 ~14 ~29 tallgrass 2
setblock ~32 ~14 ~30 grass
setblock ~33 ~14 ~30 stonebrick
setblock ~34 ~14 ~30 stonebrick 2
setblock ~44 ~14 ~30 grass
setblock ~45 ~14 ~30 stonebrick
setblock ~51 ~14 ~30 stonebrick
setblock ~52 ~14 ~30 grass
setblock ~57 ~14 ~30 stonebrick 2
setblock ~59 ~14 ~30 stonebrick 2
setblock ~63 ~14 ~30 stonebrick
setblock ~64 ~14 ~30 grass
setblock ~65 ~14 ~30 double_stone_block_slab
setblock ~25 ~14 ~31 tallgrass 2
setblock ~30 ~14 ~31 double_stone_block_slab
setblock ~32 ~14 ~31 stone 4
setblock ~33 ~14 ~31 stone 6
setblock ~35 ~14 ~31 stone 6
setblock ~37 ~14 ~31 stone 6
setblock ~38 ~14 ~31 stonebrick
setblock ~39 ~14 ~31 stonebrick 2
setblock ~49 ~14 ~31 stonebrick 2
setblock ~57 ~14 ~31 stonebrick
setblock ~59 ~14 ~31 stone 6
setblock ~61 ~14 ~31 stone 6
setblock ~63 ~14 ~31 stone 6
setblock ~64 ~14 ~31 stone 4
setblock ~67 ~14 ~31 tallgrass 1
setblock ~71 ~14 ~31 tallgrass 1
setblock ~19 ~14 ~32 tallgrass 1
setblock ~22 ~14 ~32 tallgrass 1
setblock ~24 ~14 ~32 tallgrass 1
setblock ~29 ~14 ~32 tallgrass 2
setblock ~30 ~14 ~32 grass
setblock ~31 ~14 ~32 stone 4
setblock ~33 ~14 ~32 prismarine
setblock ~35 ~14 ~32 stonebrick
setblock ~36 ~14 ~32 stone 6
setblock ~38 ~14 ~32 stonebrick 2
setblock ~39 ~14 ~32 dirt
setblock ~41 ~14 ~32 dirt
setblock ~47 ~14 ~32 grass
setblock ~48 ~14 ~32 dirt
setblock ~49 ~14 ~32 grass
setblock ~55 ~14 ~32 dirt
setblock ~57 ~14 ~32 dirt
setblock ~59 ~14 ~32 stonebrick 2
setblock ~61 ~14 ~32 stonebrick
setblock ~62 ~14 ~32 stone 6
setblock ~63 ~14 ~32 prismarine
setblock ~65 ~14 ~32 stone 4
setblock ~66 ~14 ~32 grass
setblock ~74 ~14 ~32 tallgrass 1
setblock ~31 ~14 ~33 stone 6
setblock ~32 ~14 ~33 prismarine
setblock ~35 ~14 ~33 stone_brick_stairs 1
setblock ~39 ~14 ~33 stonebrick 2
setblock ~41 ~14 ~33 grass
setblock ~42 ~14 ~33 stonebrick
setblock ~44 ~14 ~33 stone 6
setblock ~46 ~14 ~33 grass
setblock ~47 ~14 ~33 dirt
setblock ~49 ~14 ~33 dirt
setblock ~50 ~14 ~33 grass
setblock ~51 ~14 ~33 stonebrick
setblock ~52 ~14 ~33 stone 6
setblock ~55 ~14 ~33 grass
setblock ~61 ~14 ~33 stone_brick_stairs 0
setblock ~64 ~14 ~33 prismarine
setblock ~65 ~14 ~33 stone 6
setblock ~66 ~14 ~33 stonebrick
setblock ~34 ~14 ~34 double_stone_block_slab 5
setblock ~39 ~14 ~34 stone 6
setblock ~46 ~14 ~34 dirt
setblock ~50 ~14 ~34 dirt
setblock ~55 ~14 ~34 stonebrick 2
setblock ~57 ~14 ~34 stone 6
setblock ~58 ~14 ~34 stonebrick 2
setblock ~62 ~14 ~34 double_stone_block_slab 5
setblock ~66 ~14 ~34 stonebrick 2
setblock ~31 ~14 ~35 stone 6
setblock ~32 ~14 ~35 stonebrick
setblock ~33 ~14 ~35 stone_brick_stairs 3
setblock ~63 ~14 ~35 stone_brick_stairs 3
setblock ~64 ~14 ~35 stonebrick
setblock ~65 ~14 ~35 stone 6
setblock ~22 ~14 ~36 leaves 3
setblock ~23 ~14 ~36 tallgrass 2
setblock ~31 ~14 ~36 stonebrick 2
setblock ~32 ~14 ~36 stone 6
setblock ~64 ~14 ~36 stone 6
setblock ~74 ~14 ~36 leaves 3
setblock ~22 ~14 ~37 stonebrick
setblock ~24 ~14 ~37 stonebrick 2
setblock ~29 ~14 ~37 stonebrick
setblock ~31 ~14 ~37 stone 6
setblock ~32 ~14 ~37 stonebrick 2
setblock ~37 ~14 ~37 stone 6
setblock ~44 ~14 ~37 dirt
setblock ~52 ~14 ~37 dirt
setblock ~59 ~14 ~37 stone 6
setblock ~65 ~14 ~37 stone 6
setblock ~71 ~14 ~37 dirt
setblock ~72 ~14 ~37 stonebrick
setblock ~74 ~14 ~37 stonebrick
setblock ~79 ~14 ~37 stonebrick 2
setblock ~21 ~14 ~38 stonebrick
setblock ~32 ~14 ~38 stonebrick
setblock ~34 ~14 ~38 stonebrick 2
setblock ~39 ~14 ~38 stone 6
setblock ~42 ~14 ~38 tallgrass 2
setblock ~44 ~14 ~38 stonebrick 2
setblock ~52 ~14 ~38 stonebrick
setblock ~54 ~14 ~38 tallgrass 2
setblock ~56 ~14 ~38 tallgrass 2
setblock ~57 ~14 ~38 stone 6
setblock ~64 ~14 ~38 stonebrick 2
setblock ~65 ~14 ~38 stonebrick
setblock ~68 ~14 ~38 stonebrick 2
setblock ~76 ~14 ~38 leaves 3
setblock ~21 ~14 ~39 stonebrick 2
setblock ~30 ~14 ~39 stonebrick 2
setblock ~34 ~14 ~39 stone 6
setblock ~42 ~14 ~39 double_stone_block_slab
setblock ~44 ~14 ~39 stonebrick
setblock ~45 ~14 ~39 stonebrick 2
setblock ~51 ~14 ~39 stonebrick
setblock ~54 ~14 ~39 double_stone_block_slab
setblock ~55 ~14 ~39 tallgrass 1
setblock ~62 ~14 ~39 stone 6
setblock ~63 ~14 ~39 stonebrick 2
setblock ~65 ~14 ~39 stonebrick 2
setblock ~69 ~14 ~39 stonebrick 2
setblock ~70 ~14 ~39 stonebrick
setblock ~71 ~14 ~39 stonebrick 2
setblock ~21 ~14 ~40 stone
setblock ~23 ~14 ~40 stone
setblock ~31 ~14 ~40 dirt
setblock ~33 ~14 ~40 dirt
setblock ~38 ~14 ~40 tallgrass 2
setblock ~42 ~14 ~40 stone_block_slab
setblock ~53 ~14 ~40 stone_brick_stairs 0
setblock ~54 ~14 ~40 stone_block_slab
setblock ~63 ~14 ~40 dirt
setblock ~65 ~14 ~40 dirt
setblock ~71 ~14 ~40 tallgrass 1
setblock ~73 ~14 ~40 stone
setblock ~33 ~14 ~41 grass
setblock ~34 ~14 ~41 stonebrick 2
setblock ~39 ~14 ~41 tallgrass 1
setblock ~41 ~14 ~41 diamond_ore
setblock ~55 ~14 ~41 diamond_ore
setblock ~63 ~14 ~41 grass
setblock ~32 ~14 ~42 grass
setblock ~38 ~14 ~42 tallgrass 2
setblock ~39 ~14 ~42 double_stone_block_slab
setblock ~40 ~14 ~42 stone_block_slab
setblock ~56 ~14 ~42 stone_block_slab
setblock ~57 ~14 ~42 double_stone_block_slab
setblock ~58 ~14 ~42 tallgrass 2
setblock ~62 ~14 ~42 stonebrick 2
setblock ~63 ~14 ~42 stonebrick
setblock ~64 ~14 ~42 grass
setblock ~21 ~14 ~43 stone
setblock ~40 ~14 ~43 stone_brick_stairs 3
setblock ~64 ~14 ~43 stonebrick
setblock ~73 ~14 ~43 stone
setblock ~33 ~14 ~44 stone 6
setblock ~37 ~14 ~44 dirt
setblock ~38 ~14 ~44 stonebrick
setblock ~45 ~14 ~44 stone_block_slab 13
setblock ~51 ~14 ~44 stone_block_slab 13
setblock ~57 ~14 ~44 stonebrick
setblock ~58 ~14 ~44 stonebrick 2
setblock ~59 ~14 ~44 dirt
setblock ~63 ~14 ~44 stone 6
setblock ~30 ~14 ~45 stonebrick
setblock ~39 ~14 ~45 stonebrick
setblock ~44 ~14 ~45 stone_block_slab 13
setblock ~45 ~14 ~45 stonebrick
setblock ~51 ~14 ~45 stonebrick
setblock ~52 ~14 ~45 stone_block_slab 13
setblock ~57 ~14 ~45 stonebrick 2
setblock ~66 ~14 ~45 stonebrick
setblock ~72 ~14 ~45 stonebrick 2
setblock ~19 ~14 ~46 stonebrick 2
setblock ~21 ~14 ~46 stonebrick 2
setblock ~33 ~14 ~46 grass
setblock ~34 ~14 ~46 dirt
setblock ~62 ~14 ~46 dirt
setblock ~63 ~14 ~46 grass
setblock ~64 ~14 ~46 stonebrick
setblock ~73 ~14 ~46 stonebrick 2
setblock ~74 ~14 ~46 stonebrick
setblock ~75 ~14 ~46 stonebrick 2
setblock ~76 ~14 ~46 stonebrick
setblock ~21 ~14 ~47 stone 6
setblock ~22 ~14 ~47 stone_brick_stairs 3
setblock ~23 ~14 ~47 stonebrick 2
setblock ~28 ~14 ~47 stonebrick 2
setblock ~31 ~14 ~47 stonebrick 2
setblock ~32 ~14 ~47 grass
setblock ~33 ~14 ~47 dirt
setblock ~63 ~14 ~47 dirt
setblock ~64 ~14 ~47 grass
setblock ~70 ~14 ~47 stonebrick
setblock ~73 ~14 ~47 stonebrick
setblock ~74 ~14 ~47 stone_brick_stairs 3
setblock ~75 ~14 ~47 stone 6
setblock ~20 ~14 ~48 stone 6
setblock ~21 ~14 ~48 double_stone_block_slab
setblock ~22 ~14 ~48 chest 5
setblock ~23 ~14 ~48 double_stone_block_slab
setblock ~32 ~14 ~48 dirt
setblock ~64 ~14 ~48 dirt
setblock ~73 ~14 ~48 double_stone_block_slab
setblock ~74 ~14 ~48 chest 4
setblock ~75 ~14 ~48 double_stone_block_slab
setblock ~76 ~14 ~48 stone 6
setblock ~19 ~14 ~49 stonebrick
setblock ~21 ~14 ~49 stone 6
setblock ~22 ~14 ~49 stone_brick_stairs 2
setblock ~23 ~14 ~49 stonebrick
setblock ~26 ~14 ~49 stonebrick
setblock ~32 ~14 ~49 grass
setblock ~33 ~14 ~49 dirt
setblock ~63 ~14 ~49 dirt
setblock ~64 ~14 ~49 grass
setblock ~65 ~14 ~49 stonebrick 2
setblock ~68 ~14 ~49 stonebrick 2
setblock ~73 ~14 ~49 stonebrick 2
setblock ~74 ~14 ~49 stone_brick_stairs 2
setblock ~75 ~14 ~49 stone 6
setblock ~77 ~14 ~49 stonebrick
setblock ~21 ~14 ~50 stonebrick 2
setblock ~22 ~14 ~50 stonebrick
setblock ~23 ~14 ~50 stonebrick 2
setblock ~33 ~14 ~50 grass
setblock ~34 ~14 ~50 dirt
setblock ~62 ~14 ~50 dirt
setblock ~63 ~14 ~50 grass
setblock ~75 ~14 ~50 stonebrick 2
setblock ~77 ~14 ~50 stonebrick 2
setblock ~24 ~14 ~51 stonebrick 2
setblock ~30 ~14 ~51 stonebrick
setblock ~33 ~14 ~51 stonebrick
setblock ~39 ~14 ~51 stonebrick 2
setblock ~44 ~14 ~51 stone_block_slab 13
setblock ~45 ~14 ~51 stonebrick
setblock ~51 ~14 ~51 stonebrick
setblock ~52 ~14 ~51 stone_block_slab 13
setblock ~57 ~14 ~51 stonebrick
setblock ~63 ~14 ~51 stonebrick
setblock ~66 ~14 ~51 stonebrick
setblock ~73 ~14 ~51 stone
setblock ~31 ~14 ~52 stonebrick
setblock ~33 ~14 ~52 stone 6
setblock ~37 ~14 ~52 dirt
setblock ~38 ~14 ~52 stonebrick 2
setblock ~39 ~14 ~52 stonebrick
setblock ~45 ~14 ~52 stone_block_slab 13
setblock ~51 ~14 ~52 stone_block_slab 13
setblock ~58 ~14 ~52 stonebrick
setblock ~59 ~14 ~52 dirt
setblock ~63 ~14 ~52 stone 6
setblock ~65 ~14 ~52 stonebrick
setblock ~33 ~14 ~53 stonebrick 2
setblock ~56 ~14 ~53 stone_brick_stairs 2
setblock ~32 ~14 ~54 grass
setblock ~33 ~14 ~54 stonebrick
setblock ~38 ~14 ~54 tallgrass 2
setblock ~39 ~14 ~54 double_stone_block_slab
setblock ~40 ~14 ~54 stone_block_slab
setblock ~56 ~14 ~54 stone_block_slab
setblock ~57 ~14 ~54 double_stone_block_slab
setblock ~58 ~14 ~54 tallgrass 2
setblock ~33 ~14 ~55 grass
setblock ~41 ~14 ~55 diamond_ore
setblock ~55 ~14 ~55 diamond_ore
setblock ~57 ~14 ~55 tallgrass 1
setblock ~62 ~14 ~55 stonebrick 2
setblock ~63 ~14 ~55 grass
setblock ~25 ~14 ~56 tallgrass 1
setblock ~31 ~14 ~56 dirt
setblock ~33 ~14 ~56 dirt
setblock ~42 ~14 ~56 stone_block_slab
setblock ~43 ~14 ~56 stone_brick_stairs 1
setblock ~54 ~14 ~56 stone_block_slab
setblock ~58 ~14 ~56 tallgrass 2
setblock ~63 ~14 ~56 dirt
setblock ~65 ~14 ~56 dirt
setblock ~73 ~14 ~56 stone
setblock ~75 ~14 ~56 stone
setblock ~25 ~14 ~57 stonebrick 2
setblock ~26 ~14 ~57 stonebrick
setblock ~27 ~14 ~57 stonebrick 2
setblock ~31 ~14 ~57 stonebrick 2
setblock ~33 ~14 ~57 stonebrick 2
setblock ~34 ~14 ~57 stone 6
setblock ~38 ~14 ~57 stone 6
setblock ~41 ~14 ~57 tallgrass 1
setblock ~42 ~14 ~57 double_stone_block_slab
setblock ~45 ~14 ~57 stonebrick
setblock ~51 ~14 ~57 stonebrick 2
setblock ~52 ~14 ~57 stonebrick
setblock ~54 ~14 ~57 double_stone_block_slab
setblock ~62 ~14 ~57 stone 6
setblock ~63 ~14 ~57 stonebrick
setblock ~66 ~14 ~57 stonebrick 2
setblock ~71 ~14 ~57 stonebrick
setblock ~73 ~14 ~57 dirt
setblock ~75 ~14 ~57 stonebrick 2
setblock ~20 ~14 ~58 leaves 3
setblock ~27 ~14 ~58 stonebrick
setblock ~28 ~14 ~58 stonebrick 2
setblock ~31 ~14 ~58 stonebrick
setblock ~32 ~14 ~58 stonebrick 2
setblock ~33 ~14 ~58 stonebrick
setblock ~40 ~14 ~58 tallgrass 2
setblock ~42 ~14 ~58 tallgrass 2
setblock ~44 ~14 ~58 stonebrick
setblock ~52 ~14 ~58 stonebrick 2
setblock ~54 ~14 ~58 tallgrass 2
setblock ~62 ~14 ~58 stonebrick 2
setblock ~17 ~14 ~59 stonebrick 2
setblock ~31 ~14 ~59 stone 6
setblock ~37 ~14 ~59 stone 6
setblock ~44 ~14 ~59 dirt
setblock ~52 ~14 ~59 dirt
setblock ~59 ~14 ~59 stone 6
setblock ~63 ~14 ~59 stone 6
setblock ~64 ~14 ~59 stonebrick 2
setblock ~65 ~14 ~59 stone 6
setblock ~72 ~14 ~59 stonebrick 2
setblock ~73 ~14 ~59 stonebrick
setblock ~22 ~14 ~60 leaves 3
setblock ~31 ~14 ~60 stonebrick
setblock ~73 ~14 ~60 tallgrass 2
setblock ~74 ~14 ~60 leaves 3
setblock ~31 ~14 ~61 stone 6
setblock ~32 ~14 ~61 stonebrick
setblock ~33 ~14 ~61 stone_brick_stairs 2
setblock ~63 ~14 ~61 stone_brick_stairs 2
setblock ~64 ~14 ~61 stonebrick
setblock ~65 ~14 ~61 stone 6
setblock ~30 ~14 ~62 stonebrick 2
setblock ~32 ~14 ~62 stone 6
setblock ~34 ~14 ~62 double_stone_block_slab 5
setblock ~38 ~14 ~62 stonebrick 2
setblock ~39 ~14 ~62 stone 6
setblock ~41 ~14 ~62 stonebrick 2
setblock ~44 ~14 ~62 stonebrick
setblock ~46 ~14 ~62 dirt
setblock ~47 ~14 ~62 stone
setblock ~49 ~14 ~62 stone
setblock ~50 ~14 ~62 dirt
setblock ~54 ~14 ~62 stonebrick 2
setblock ~57 ~14 ~62 stone 6
setblock ~62 ~14 ~62 double_stone_block_slab 5
setblock ~64 ~14 ~62 stone 6
setblock ~30 ~14 ~63 stonebrick
setblock ~31 ~14 ~63 stone 6
setblock ~32 ~14 ~63 prismarine
setblock ~35 ~14 ~63 stone_brick_stairs 1
setblock ~37 ~14 ~63 stone 6
setblock ~39 ~14 ~63 stonebrick
setblock ~41 ~14 ~63 grass
setblock ~44 ~14 ~63 stone 6
setblock ~46 ~14 ~63 grass
setblock ~47 ~14 ~63 dirt
setblock ~49 ~14 ~63 dirt
setblock ~50 ~14 ~63 grass
setblock ~52 ~14 ~63 stone 6
setblock ~54 ~14 ~63 stonebrick
setblock ~55 ~14 ~63 grass
setblock ~57 ~14 ~63 stonebrick 2
setblock ~59 ~14 ~63 stone 6
setblock ~61 ~14 ~63 stone_brick_stairs 0
setblock ~64 ~14 ~63 prismarine
setblock ~65 ~14 ~63 stone 6
setblock ~22 ~14 ~64 tallgrass 1
setblock ~30 ~14 ~64 grass
setblock ~31 ~14 ~64 stone 4
setblock ~33 ~14 ~64 prismarine
setblock ~35 ~14 ~64 stonebrick
setblock ~37 ~14 ~64 stonebrick 2
setblock ~39 ~14 ~64 dirt
setblock ~41 ~14 ~64 dirt
setblock ~47 ~14 ~64 grass
setblock ~48 ~14 ~64 dirt
setblock ~49 ~14 ~64 grass
setblock ~53 ~14 ~64 stonebrick
setblock ~55 ~14 ~64 dirt
setblock ~57 ~14 ~64 dirt
setblock ~58 ~14 ~64 stonebrick 2
setblock ~61 ~14 ~64 stonebrick
setblock ~63 ~14 ~64 prismarine
setblock ~65 ~14 ~64 stone 4
setblock ~66 ~14 ~64 grass
setblock ~67 ~14 ~64 tallgrass 2
setblock ~72 ~14 ~64 tallgrass 1
setblock ~74 ~14 ~64 tallgrass 1
setblock ~77 ~14 ~64 tallgrass 1
setblock ~25 ~14 ~65 tallgrass 1
setblock ~29 ~14 ~65 tallgrass 1
setblock ~32 ~14 ~65 stone 4
setblock ~33 ~14 ~65 stone 6
setblock ~35 ~14 ~65 stone 6
setblock ~36 ~14 ~65 stonebrick 2
setblock ~37 ~14 ~65 stone 6
setblock ~43 ~14 ~65 grass
setblock ~47 ~14 ~65 stonebrick 2
setblock ~57 ~14 ~65 stonebrick 2
setblock ~58 ~14 ~65 stonebrick
setblock ~59 ~14 ~65 stone 6
setblock ~60 ~14 ~65 stonebrick
setblock ~61 ~14 ~65 stone 6
setblock ~63 ~14 ~65 stone 6
setblock ~64 ~14 ~65 stone 4
setblock ~66 ~14 ~65 double_stone_block_slab
setblock ~71 ~14 ~65 tallgrass 2
setblock ~31 ~14 ~66 double_stone_block_slab
setblock ~32 ~14 ~66 grass
setblock ~39 ~14 ~66 stonebrick 2
setblock ~45 ~14 ~66 stonebrick
setblock ~51 ~14 ~66 stonebrick
setblock ~62 ~14 ~66 stonebrick 2
setblock ~63 ~14 ~66 stonebrick
setblock ~64 ~14 ~66 grass
setblock ~32 ~14 ~67 tallgrass 2
setblock ~65 ~14 ~67 tallgrass 1
setblock ~47 ~14 ~68 stonebrick 2
setblock ~58 ~14 ~68 stonebrick 2
setblock ~4 ~14 ~69 stone_block_slab
setblock ~57 ~14 ~69 stonebrick 2
setblock ~92 ~14 ~69 stone_block_slab
setblock ~49 ~14 ~70 stonebrick
setblock ~57 ~14 ~70 stonebrick
setblock ~31 ~14 ~71 tallgrass 2
setblock ~37 ~14 ~71 dirt
setblock ~56 ~14 ~71 tallgrass 1
setblock ~57 ~14 ~71 stonebrick 2
setblock ~59 ~14 ~71 dirt
setblock ~65 ~14 ~71 tallgrass 1
setblock ~3 ~14 ~72 stone_block_slab 8
setblock ~32 ~14 ~72 tallgrass 1
setblock ~37 ~14 ~72 stonebrick 2
setblock ~51 ~14 ~72 stonebrick 2
setblock ~59 ~14 ~72 stonebrick
setblock ~93 ~14 ~72 stone_block_slab 8
setblock ~2 ~14 ~73 stone_brick_stairs 3
setblock ~8 ~14 ~73 stone_block_slab
setblock ~36 ~14 ~73 tallgrass 2
setblock ~37 ~14 ~73 stonebrick
setblock ~40 ~14 ~73 stone
setblock ~47 ~14 ~73 stonebrick 2
setblock ~48 ~14 ~73 double_stone_block_slab
setblock ~49 ~14 ~73 stonebrick
setblock ~50 ~14 ~73 stonebrick 2
setblock ~53 ~14 ~73 stone
setblock ~57 ~14 ~73 dirt
setblock ~88 ~14 ~73 stone_block_slab
setblock ~94 ~14 ~73 stone_brick_stairs 3
setblock ~3 ~14 ~74 stone_block_slab 8
setblock ~5 ~14 ~74 stone_block_slab 8
setblock ~32 ~14 ~74 tallgrass 1
setblock ~36 ~14 ~74 leaves 3
setblock ~47 ~14 ~74 stone_brick_stairs 1
setblock ~48 ~14 ~74 chest 2
setblock ~49 ~14 ~74 stone_brick_stairs 0
setblock ~50 ~14 ~74 stonebrick
setblock ~59 ~14 ~74 stonebrick
setblock ~60 ~14 ~74 leaves 3
setblock ~64 ~14 ~74 tallgrass 1
setblock ~91 ~14 ~74 stone_block_slab 8
setblock ~93 ~14 ~74 stone_block_slab 8
setblock ~4 ~14 ~75 stone_brick_stairs 0
setblock ~38 ~14 ~75 stonebrick
setblock ~39 ~14 ~75 stonebrick 2
setblock ~40 ~14 ~75 stone
setblock ~46 ~14 ~75 stonebrick 2
setblock ~47 ~14 ~75 stone 6
setblock ~48 ~14 ~75 double_stone_block_slab
setblock ~49 ~14 ~75 stone 6
setblock ~50 ~14 ~75 stonebrick 2
setblock ~92 ~14 ~75 stone_brick_stairs 1
setblock ~46 ~14 ~76 stonebrick
setblock ~48 ~14 ~76 stone 6
setblock ~49 ~14 ~76 stonebrick
setblock ~58 ~14 ~76 leaves 3
setblock ~32 ~14 ~77 tallgrass 1
setblock ~46 ~14 ~77 stonebrick 2
setblock ~14 ~14 ~78 stone_block_slab
setblock ~82 ~14 ~78 stone_block_slab
setblock ~59 ~14 ~79 stonebrick 2
setblock ~13 ~14 ~81 stone_block_slab 8
setblock ~83 ~14 ~81 stone_block_slab 8
setblock ~12 ~14 ~82 stone_brick_stairs 3
setblock ~14 ~14 ~82 stone 3
setblock ~18 ~14 ~82 stone_block_slab
setblock ~78 ~14 ~82 stone_block_slab
setblock ~82 ~14 ~82 stone 3
setblock ~84 ~14 ~82 stone_brick_stairs 3
setblock ~13 ~14 ~83 stone_block_slab 8
setblock ~15 ~14 ~83 stone_block_slab 8
setblock ~81 ~14 ~83 stone_block_slab 8
setblock ~83 ~14 ~83 stone_block_slab 8
setblock ~14 ~14 ~84 stone_brick_stairs 0
setblock ~82 ~14 ~84 stone_brick_stairs 1
setblock ~23 ~14 ~88 stone_block_slab
setblock ~73 ~14 ~88 stone_block_slab
setblock ~22 ~14 ~91 stone_block_slab 8
setblock ~74 ~14 ~91 stone_block_slab 8
setblock ~21 ~14 ~92 stone_brick_stairs 3
setblock ~27 ~14 ~92 stone_block_slab
setblock ~69 ~14 ~92 stone_block_slab
setblock ~75 ~14 ~92 stone_brick_stairs 3
setblock ~22 ~14 ~93 stone_block_slab 8
setblock ~24 ~14 ~93 stone_block_slab 8
setblock ~72 ~14 ~93 stone_block_slab 8
setblock ~74 ~14 ~93 stone_block_slab 8
setblock ~23 ~14 ~94 stone_brick_stairs 0
setblock ~73 ~14 ~94 stone_brick_stairs 1
setblock ~25 ~15 ~0 stone_brick_stairs 1
setblock ~71 ~15 ~0 stone_brick_stairs 0
setblock ~23 ~15 ~2 stonebrick
setblock ~73 ~15 ~2 stonebrick
setblock ~74 ~15 ~2 leaves 3
setblock ~21 ~15 ~3 leaves 3
setblock ~21 ~15 ~4 stonebrick
setblock ~75 ~15 ~4 stonebrick
setblock ~19 ~15 ~6 stone_brick_stairs 3
setblock ~77 ~15 ~6 stone_brick_stairs 3
setblock ~16 ~15 ~10 stone_brick_stairs 1
setblock ~80 ~15 ~10 stone_brick_stairs 0
setblock ~14 ~15 ~12 stonebrick
setblock ~82 ~15 ~12 stonebrick
setblock ~83 ~15 ~12 leaves 3
setblock ~12 ~15 ~13 leaves 3
setblock ~12 ~15 ~14 stonebrick
setblock ~14 ~15 ~14 stonebrick
setblock ~82 ~15 ~14 stonebrick
setblock ~84 ~15 ~14 stonebrick
setblock ~59 ~15 ~15 leaves 3
setblock ~10 ~15 ~16 stone_brick_stairs 3
setblock ~37 ~15 ~16 leaves 3
setblock ~86 ~15 ~16 stone_brick_stairs 3
setblock ~6 ~15 ~19 stone_brick_stairs 1
setblock ~47 ~15 ~19 stone_block_slab 13
setblock ~49 ~15 ~19 stone_block_slab 13
setblock ~59 ~15 ~19 leaves 3
setblock ~90 ~15 ~19 stone_brick_stairs 0
setblock ~4 ~15 ~21 stonebrick
setblock ~36 ~15 ~21 leaves 3
setblock ~44 ~15 ~21 stonebrick 2
setblock ~53 ~15 ~21 stonebrick 2
setblock ~54 ~15 ~21 stonebrick
setblock ~92 ~15 ~21 stonebrick
setblock ~93 ~15 ~21 leaves 3
setblock ~2 ~15 ~22 leaves 3
setblock ~37 ~15 ~22 stonebrick 2
setblock ~39 ~15 ~22 stone 6
setblock ~55 ~15 ~22 stonebrick
setblock ~56 ~15 ~22 stonebrick 2
setblock ~57 ~15 ~22 stone 6
setblock ~2 ~15 ~23 stonebrick
setblock ~39 ~15 ~23 prismarine
setblock ~42 ~15 ~23 stonebrick 2
setblock ~57 ~15 ~23 prismarine
setblock ~94 ~15 ~23 stonebrick
setblock ~38 ~15 ~24 stonebrick 2
setblock ~39 ~15 ~24 stone 6
setblock ~57 ~15 ~24 stone 6
setblock ~0 ~15 ~25 stone_brick_stairs 3
setblock ~30 ~15 ~25 stone 6
setblock ~45 ~15 ~25 stone_block_slab 8
setblock ~51 ~15 ~25 stone_block_slab 8
setblock ~66 ~15 ~25 stone 6
setblock ~96 ~15 ~25 stone_brick_stairs 3
setblock ~46 ~15 ~26 stone_block_slab 8
setblock ~50 ~15 ~26 stone_block_slab 8
setblock ~40 ~15 ~27 tallgrass 1
setblock ~56 ~15 ~27 tallgrass 1
setblock ~55 ~15 ~28 tallgrass 1
setblock ~30 ~15 ~29 double_stone_block_slab
setblock ~41 ~15 ~29 leaves 3
setblock ~42 ~15 ~29 tallgrass 1
setblock ~54 ~15 ~29 tallgrass 1
setblock ~55 ~15 ~29 leaves 3
setblock ~56 ~15 ~29 tallgrass 2
setblock ~25 ~15 ~30 stone 6
setblock ~32 ~15 ~30 tallgrass 1
setblock ~33 ~15 ~30 stone_block_slab 8
setblock ~44 ~15 ~30 tallgrass 1
setblock ~63 ~15 ~30 stone_block_slab 8
setblock ~67 ~15 ~30 double_stone_block_slab
setblock ~71 ~15 ~30 stone 6
setblock ~42 ~15 ~31 leaves 3
setblock ~43 ~15 ~31 tallgrass 1
setblock ~54 ~15 ~31 leaves 3
setblock ~39 ~15 ~32 smooth_stone
setblock ~40 ~15 ~32 stone 4
setblock ~42 ~15 ~32 tallgrass 2
setblock ~56 ~15 ~32 stone 4
setblock ~57 ~15 ~32 smooth_stone
setblock ~66 ~15 ~32 tallgrass 1
setblock ~30 ~15 ~33 stone_block_slab 8
setblock ~40 ~15 ~33 smooth_stone
setblock ~46 ~15 ~33 leaves 3
setblock ~47 ~15 ~33 smooth_stone
setblock ~48 ~15 ~33 stone 4
setblock ~49 ~15 ~33 smooth_stone
setblock ~50 ~15 ~33 leaves 3
setblock ~66 ~15 ~33 stone_block_slab 8
setblock ~45 ~15 ~35 stone_block_slab
setblock ~46 ~15 ~35 stonebrick
setblock ~47 ~15 ~35 prismarine
setblock ~49 ~15 ~35 prismarine
setblock ~50 ~15 ~35 stonebrick 2
setblock ~51 ~15 ~35 stone_block_slab
setblock ~44 ~15 ~36 stone_block_slab
setblock ~52 ~15 ~36 stone_block_slab
setblock ~75 ~15 ~36 leaves 3
setblock ~15 ~15 ~37 leaves 3
setblock ~19 ~15 ~37 leaves 3
setblock ~44 ~15 ~37 stonebrick
setblock ~45 ~15 ~37 stone 6
setblock ~47 ~15 ~37 stone 6
setblock ~48 ~15 ~37 stonebrick 2
setblock ~49 ~15 ~37 stone 6
setblock ~51 ~15 ~37 stone 6
setblock ~52 ~15 ~37 stonebrick
setblock ~74 ~15 ~37 stonebrick 2
setblock ~80 ~15 ~37 leaves 3
setblock ~23 ~15 ~38 stone 6
setblock ~44 ~15 ~38 prismarine
setblock ~45 ~15 ~38 stonebrick
setblock ~51 ~15 ~38 stonebrick
setblock ~52 ~15 ~38 prismarine
setblock ~72 ~15 ~38 stonebrick 2
setblock ~73 ~15 ~38 stone 6
setblock ~23 ~15 ~39 prismarine
setblock ~24 ~15 ~39 stone 6
setblock ~32 ~15 ~39 smooth_stone
setblock ~43 ~15 ~39 prismarine
setblock ~44 ~15 ~39 stone
setblock ~52 ~15 ~39 stone
setblock ~53 ~15 ~39 prismarine
setblock ~64 ~15 ~39 smooth_stone
setblock ~72 ~15 ~39 stone 6
setblock ~73 ~15 ~39 prismarine
setblock ~22 ~15 ~40 stonebrick 2
setblock ~27 ~15 ~40 tallgrass 1
setblock ~29 ~15 ~40 tallgrass 2
setblock ~32 ~15 ~40 stone 4
setblock ~42 ~15 ~40 smooth_stone
setblock ~43 ~15 ~40 stone 4
setblock ~45 ~15 ~40 stonebrick
setblock ~46 ~15 ~40 stonebrick 2
setblock ~50 ~15 ~40 stonebrick
setblock ~51 ~15 ~40 stonebrick 2
setblock ~52 ~15 ~40 stonebrick
setblock ~53 ~15 ~40 stone 4
setblock ~54 ~15 ~40 double_stone_block_slab
setblock ~63 ~15 ~40 smooth_stone
setblock ~64 ~15 ~40 stone 4
setblock ~69 ~15 ~40 tallgrass 1
setblock ~22 ~15 ~41 stonebrick
setblock ~28 ~15 ~41 tallgrass 1
setblock ~29 ~15 ~41 leaves 3
setblock ~41 ~15 ~41 stone_block_slab
setblock ~55 ~15 ~41 stone_block_slab
setblock ~67 ~15 ~41 leaves 3
setblock ~21 ~15 ~42 stonebrick
setblock ~29 ~15 ~42 tallgrass 1
setblock ~31 ~15 ~42 leaves 3
setblock ~40 ~15 ~42 double_stone_block_slab
setblock ~42 ~15 ~42 stonebrick 2
setblock ~43 ~15 ~42 stone_block_slab 13
setblock ~53 ~15 ~42 stone_block_slab 13
setblock ~54 ~15 ~42 stonebrick 2
setblock ~56 ~15 ~42 smooth_stone
setblock ~64 ~15 ~42 tallgrass 2
setblock ~65 ~15 ~42 leaves 3
setblock ~67 ~15 ~42 tallgrass 1
setblock ~73 ~15 ~42 stonebrick 2
setblock ~21 ~15 ~43 stonebrick 2
setblock ~39 ~15 ~43 prismarine
setblock ~40 ~15 ~43 stone 4
setblock ~42 ~15 ~43 stone_block_slab 13
setblock ~43 ~15 ~43 stonebrick 2
setblock ~53 ~15 ~43 stonebrick 2
setblock ~54 ~15 ~43 stone_block_slab 13
setblock ~57 ~15 ~43 prismarine
setblock ~65 ~15 ~43 tallgrass 1
setblock ~73 ~15 ~43 stonebrick
setblock ~36 ~15 ~44 stone_block_slab
setblock ~37 ~15 ~44 stonebrick
setblock ~38 ~15 ~44 prismarine
setblock ~39 ~15 ~44 stone
setblock ~45 ~15 ~44 stonebrick 2
setblock ~46 ~15 ~44 stone_block_slab 13
setblock ~50 ~15 ~44 stone_block_slab 13
setblock ~51 ~15 ~44 stonebrick
setblock ~57 ~15 ~44 stone
setblock ~58 ~15 ~44 prismarine
setblock ~59 ~15 ~44 stonebrick
setblock ~60 ~15 ~44 stone_block_slab
setblock ~66 ~15 ~44 tallgrass 1
setblock ~75 ~15 ~44 stonebrick 2
setblock ~25 ~15 ~45 stone_block_slab 8
setblock ~35 ~15 ~45 stone_block_slab
setblock ~38 ~15 ~45 stonebrick
setblock ~40 ~15 ~45 stonebrick 2
setblock ~44 ~15 ~45 stonebrick
setblock ~46 ~15 ~45 stonebrick
setblock ~47 ~15 ~45 stone_block_slab 13
setblock ~49 ~15 ~45 stone_block_slab 13
setblock ~50 ~15 ~45 stonebrick
setblock ~52 ~15 ~45 stonebrick 2
setblock ~56 ~15 ~45 stonebrick
setblock ~58 ~15 ~45 stonebrick
setblock ~61 ~15 ~45 stone_block_slab
setblock ~71 ~15 ~45 stone_block_slab 8
setblock ~26 ~15 ~46 stone_block_slab 8
setblock ~33 ~15 ~46 leaves 3
setblock ~35 ~15 ~46 stonebrick 2
setblock ~38 ~15 ~46 stone 6
setblock ~40 ~15 ~46 stonebrick
setblock ~44 ~15 ~46 stone_block_slab 13
setblock ~45 ~15 ~46 stonebrick
setblock ~51 ~15 ~46 stonebrick
setblock ~52 ~15 ~46 stone_block_slab 13
setblock ~56 ~15 ~46 stonebrick 2
setblock ~58 ~15 ~46 stone 6
setblock ~61 ~15 ~46 stonebrick
setblock ~63 ~15 ~46 leaves 3
setblock ~70 ~15 ~46 stone_block_slab 8
setblock ~19 ~15 ~47 stone_block_slab 13
setblock ~33 ~15 ~47 smooth_stone
setblock ~35 ~15 ~47 prismarine
setblock ~45 ~15 ~47 stone_block_slab 13
setblock ~51 ~15 ~47 stone_block_slab 13
setblock ~61 ~15 ~47 prismarine
setblock ~63 ~15 ~47 smooth_stone
setblock ~77 ~15 ~47 stone_block_slab 13
setblock ~33 ~15 ~48 stone 4
setblock ~37 ~15 ~48 stonebrick 2
setblock ~59 ~15 ~48 stonebrick 2
setblock ~63 ~15 ~48 stone 4
setblock ~19 ~15 ~49 stone_block_slab 13
setblock ~33 ~15 ~49 smooth_stone
setblock ~35 ~15 ~49 prismarine
setblock ~45 ~15 ~49 stone_block_slab 13
setblock ~51 ~15 ~49 stone_block_slab 13
setblock ~61 ~15 ~49 prismarine
setblock ~63 ~15 ~49 smooth_stone
setblock ~77 ~15 ~49 stone_block_slab 13
setblock ~26 ~15 ~50 stone_block_slab 8
setblock ~33 ~15 ~50 leaves 3
setblock ~35 ~15 ~50 stonebrick
setblock ~38 ~15 ~50 stone 6
setblock ~40 ~15 ~50 stonebrick 2
setblock ~44 ~15 ~50 stone_block_slab 13
setblock ~45 ~15 ~50 stonebrick
setblock ~51 ~15 ~50 stonebrick
setblock ~52 ~15 ~50 stone_block_slab 13
setblock ~56 ~15 ~50 stonebrick
setblock ~58 ~15 ~50 stone 6
setblock ~61 ~15 ~50 stonebrick 2
setblock ~63 ~15 ~50 leaves 3
setblock ~70 ~15 ~50 stone_block_slab 8
setblock ~25 ~15 ~51 stone_block_slab 8
setblock ~35 ~15 ~51 stone_block_slab
setblock ~38 ~15 ~51 stonebrick
setblock ~40 ~15 ~51 stonebrick
setblock ~44 ~15 ~51 stonebrick 2
setblock ~46 ~15 ~51 stonebrick
setblock ~47 ~15 ~51 stone_block_slab 13
setblock ~49 ~15 ~51 stone_block_slab 13
setblock ~50 ~15 ~51 stonebrick
setblock ~56 ~15 ~51 stonebrick 2
setblock ~58 ~15 ~51 stonebrick
setblock ~61 ~15 ~51 stone_block_slab
setblock ~71 ~15 ~51 stone_block_slab 8
setblock ~21 ~15 ~52 stonebrick 2
setblock ~22 ~15 ~52 stonebrick
setblock ~30 ~15 ~52 tallgrass 1
setblock ~36 ~15 ~52 stone_block_slab
setblock ~37 ~15 ~52 stonebrick
setblock ~38 ~15 ~52 prismarine
setblock ~39 ~15 ~52 stone
setblock ~45 ~15 ~52 stonebrick
setblock ~46 ~15 ~52 stone_block_slab 13
setblock ~50 ~15 ~52 stone_block_slab 13
setblock ~51 ~15 ~52 stonebrick 2
setblock ~57 ~15 ~52 stone
setblock ~58 ~15 ~52 prismarine
setblock ~59 ~15 ~52 stonebrick
setblock ~60 ~15 ~52 stone_block_slab
setblock ~74 ~15 ~52 stonebrick 2
setblock ~31 ~15 ~53 tallgrass 1
setblock ~39 ~15 ~53 prismarine
setblock ~40 ~15 ~53 stone 4
setblock ~42 ~15 ~53 stone_block_slab 13
setblock ~43 ~15 ~53 stonebrick 2
setblock ~53 ~15 ~53 stonebrick 2
setblock ~54 ~15 ~53 stone_block_slab 13
setblock ~57 ~15 ~53 prismarine
setblock ~23 ~15 ~54 stonebrick 2
setblock ~29 ~15 ~54 tallgrass 1
setblock ~31 ~15 ~54 leaves 3
setblock ~32 ~15 ~54 tallgrass 2
setblock ~40 ~15 ~54 smooth_stone
setblock ~42 ~15 ~54 stonebrick 2
setblock ~43 ~15 ~54 stone_block_slab 13
setblock ~53 ~15 ~54 stone_block_slab 13
setblock ~54 ~15 ~54 stonebrick 2
setblock ~56 ~15 ~54 double_stone_block_slab
setblock ~65 ~15 ~54 leaves 3
setblock ~67 ~15 ~54 tallgrass 1
setblock ~75 ~15 ~54 stonebrick
setblock ~29 ~15 ~55 leaves 3
setblock ~41 ~15 ~55 stone_block_slab
setblock ~55 ~15 ~55 stone_block_slab
setblock ~67 ~15 ~55 leaves 3
setblock ~68 ~15 ~55 tallgrass 1
setblock ~74 ~15 ~55 stonebrick
setblock ~27 ~15 ~56 tallgrass 1
setblock ~32 ~15 ~56 stone 4
setblock ~33 ~15 ~56 smooth_stone
setblock ~42 ~15 ~56 double_stone_block_slab
setblock ~45 ~15 ~56 stonebrick 2
setblock ~46 ~15 ~56 stonebrick
setblock ~50 ~15 ~56 stonebrick 2
setblock ~51 ~15 ~56 stonebrick
setblock ~54 ~15 ~56 smooth_stone
setblock ~64 ~15 ~56 stone 4
setblock ~67 ~15 ~56 tallgrass 2
setblock ~69 ~15 ~56 tallgrass 1
setblock ~74 ~15 ~56 stonebrick 2
setblock ~22 ~15 ~57 stone 6
setblock ~23 ~15 ~57 prismarine
setblock ~24 ~15 ~57 stone 6
setblock ~43 ~15 ~57 prismarine
setblock ~44 ~15 ~57 stone
setblock ~52 ~15 ~57 stone
setblock ~53 ~15 ~57 prismarine
setblock ~64 ~15 ~57 smooth_stone
setblock ~72 ~15 ~57 stone 6
setblock ~73 ~15 ~57 prismarine
setblock ~24 ~15 ~58 stonebrick 2
setblock ~44 ~15 ~58 prismarine
setblock ~45 ~15 ~58 stonebrick
setblock ~46 ~15 ~58 stone 6
setblock ~50 ~15 ~58 stone 6
setblock ~51 ~15 ~58 stonebrick
setblock ~52 ~15 ~58 prismarine
setblock ~72 ~15 ~58 stonebrick
setblock ~16 ~15 ~59 leaves 3
setblock ~22 ~15 ~59 stonebrick 2
setblock ~44 ~15 ~59 stonebrick
setblock ~48 ~15 ~59 stonebrick
setblock ~52 ~15 ~59 stonebrick
setblock ~77 ~15 ~59 leaves 3
setblock ~81 ~15 ~59 leaves 3
setblock ~21 ~15 ~60 leaves 3
setblock ~44 ~15 ~60 stone_block_slab
setblock ~51 ~15 ~60 stonebrick
setblock ~52 ~15 ~60 stone_block_slab
setblock ~45 ~15 ~61 stone_block_slab
setblock ~46 ~15 ~61 stonebrick 2
setblock ~47 ~15 ~61 prismarine
setblock ~49 ~15 ~61 prismarine
setblock ~51 ~15 ~61 stone_block_slab
setblock ~47 ~15 ~62 stone 4
setblock ~49 ~15 ~62 stone 4
setblock ~30 ~15 ~63 stone_block_slab 8
setblock ~46 ~15 ~63 leaves 3
setblock ~47 ~15 ~63 smooth_stone
setblock ~49 ~15 ~63 smooth_stone
setblock ~50 ~15 ~63 leaves 3
setblock ~56 ~15 ~63 smooth_stone
setblock ~66 ~15 ~63 stone_block_slab 8
setblock ~30 ~15 ~64 tallgrass 1
setblock ~39 ~15 ~64 smooth_stone
setblock ~40 ~15 ~64 stone 4
setblock ~54 ~15 ~64 tallgrass 2
setblock ~56 ~15 ~64 stone 4
setblock ~42 ~15 ~65 leaves 3
setblock ~53 ~15 ~65 tallgrass 1
setblock ~54 ~15 ~65 leaves 3
setblock ~25 ~15 ~66 stone 6
setblock ~29 ~15 ~66 double_stone_block_slab
setblock ~33 ~15 ~66 stone_block_slab 8
setblock ~52 ~15 ~66 tallgrass 1
setblock ~63 ~15 ~66 stone_block_slab 8
setblock ~64 ~15 ~66 tallgrass 1
setblock ~71 ~15 ~66 stone 6
setblock ~40 ~15 ~67 tallgrass 2
setblock ~41 ~15 ~67 leaves 3
setblock ~42 ~15 ~67 tallgrass 1
setblock ~54 ~15 ~67 tallgrass 1
setblock ~55 ~15 ~67 leaves 3
setblock ~66 ~15 ~67 double_stone_block_slab
setblock ~41 ~15 ~68 tallgrass 1
setblock ~40 ~15 ~69 tallgrass 1
setblock ~56 ~15 ~69 tallgrass 1
setblock ~46 ~15 ~70 stone_block_slab 8
setblock ~50 ~15 ~70 stone_block_slab 8
setblock ~0 ~15 ~71 stone_brick_stairs 2
setblock ~30 ~15 ~71 stone 6
setblock ~45 ~15 ~71 stone_block_slab 8
setblock ~51 ~15 ~71 stone_block_slab 8
setblock ~66 ~15 ~71 stone 6
setblock ~96 ~15 ~71 stone_brick_stairs 2
setblock ~38 ~15 ~72 stonebrick
setblock ~39 ~15 ~72 stone 6
setblock ~57 ~15 ~72 stone 6
setblock ~58 ~15 ~72 stonebrick 2
setblock ~2 ~15 ~73 stonebrick
setblock ~38 ~15 ~73 stone 6
setblock ~39 ~15 ~73 prismarine
setblock ~53 ~15 ~73 stonebrick
setblock ~54 ~15 ~73 stonebrick 2
setblock ~57 ~15 ~73 prismarine
setblock ~94 ~15 ~73 stonebrick
setblock ~40 ~15 ~74 stonebrick 2
setblock ~41 ~15 ~74 stonebrick
setblock ~59 ~15 ~74 stonebrick 2
setblock ~94 ~15 ~74 leaves 3
setblock ~3 ~15 ~75 leaves 3
setblock ~4 ~15 ~75 stonebrick
setblock ~42 ~15 ~75 stonebrick
setblock ~52 ~15 ~75 stonebrick 2
setblock ~60 ~15 ~75 leaves 3
setblock ~92 ~15 ~75 stonebrick
setblock ~6 ~15 ~77 stone_brick_stairs 1
setblock ~37 ~15 ~77 leaves 3
setblock ~47 ~15 ~77 stone_block_slab 13
setblock ~49 ~15 ~77 stone_block_slab 13
setblock ~90 ~15 ~77 stone_brick_stairs 0
setblock ~10 ~15 ~80 stone_brick_stairs 2
setblock ~59 ~15 ~80 leaves 3
setblock ~86 ~15 ~80 stone_brick_stairs 2
setblock ~37 ~15 ~81 leaves 3
setblock ~12 ~15 ~82 stonebrick
setblock ~14 ~15 ~82 stonebrick
setblock ~82 ~15 ~82 stonebrick
setblock ~84 ~15 ~82 stonebrick
setblock ~84 ~15 ~83 leaves 3
setblock ~13 ~15 ~84 leaves 3
setblock ~14 ~15 ~84 stonebrick
setblock ~82 ~15 ~84 stonebrick
setblock ~16 ~15 ~86 stone_brick_stairs 1
setblock ~80 ~15 ~86 stone_brick_stairs 0
setblock ~19 ~15 ~90 stone_brick_stairs 2
setblock ~77 ~15 ~90 stone_brick_stairs 2
setblock ~21 ~15 ~92 stonebrick
setblock ~75 ~15 ~92 stonebrick
setblock ~75 ~15 ~93 leaves 3
setblock ~22 ~15 ~94 leaves 3
setblock ~23 ~15 ~94 stonebrick
setblock ~73 ~15 ~94 stonebrick
setblock ~25 ~15 ~96 stone_brick_stairs 1
setblock ~71 ~15 ~96 stone_brick_stairs 0
setblock ~25 ~16 ~0 stone_block_slab 5
setblock ~71 ~16 ~0 stone_block_slab 5
setblock ~73 ~16 ~1 leaves 3
setblock ~23 ~16 ~2 stone_block_slab
setblock ~73 ~16 ~2 stone_block_slab
setblock ~25 ~16 ~3 stone_brick_stairs 1
setblock ~71 ~16 ~3 stone_brick_stairs 0
setblock ~20 ~16 ~4 leaves 3
setblock ~21 ~16 ~4 stone_block_slab
setblock ~23 ~16 ~4 stone_block_slab 5
setblock ~73 ~16 ~4 stone_block_slab 5
setblock ~75 ~16 ~4 stone_block_slab
setblock ~19 ~16 ~6 stone_block_slab 5
setblock ~22 ~16 ~6 stone_brick_stairs 3
setblock ~74 ~16 ~6 stone_brick_stairs 3
setblock ~77 ~16 ~6 stone_block_slab 5
setblock ~16 ~16 ~10 stone_block_slab 5
setblock ~80 ~16 ~10 stone_block_slab 5
setblock ~82 ~16 ~11 leaves 3
setblock ~14 ~16 ~12 stone_block_slab
setblock ~82 ~16 ~12 stone_block_slab
setblock ~16 ~16 ~13 stone_brick_stairs 1
setblock ~80 ~16 ~13 stone_brick_stairs 0
setblock ~11 ~16 ~14 leaves 3
setblock ~12 ~16 ~14 stone_block_slab
setblock ~14 ~16 ~14 stone_block_slab
setblock ~82 ~16 ~14 stone_block_slab
setblock ~84 ~16 ~14 stone_block_slab
setblock ~10 ~16 ~16 stone_block_slab 5
setblock ~13 ~16 ~16 stone_brick_stairs 3
setblock ~83 ~16 ~16 stone_brick_stairs 3
setblock ~86 ~16 ~16 stone_block_slab 5
setblock ~6 ~16 ~19 stone_block_slab 5
setblock ~46 ~16 ~19 double_stone_block_slab
setblock ~47 ~16 ~19 stone_block_slab 8
setblock ~48 ~16 ~19 anvil 2
setblock ~49 ~16 ~19 stone_block_slab 8
setblock ~50 ~16 ~19 double_stone_block_slab
setblock ~90 ~16 ~19 stone_block_slab 5
setblock ~92 ~16 ~20 leaves 3
setblock ~4 ~16 ~21 stone_block_slab
setblock ~38 ~16 ~21 stone_block_slab 8
setblock ~58 ~16 ~21 stone_block_slab 8
setblock ~92 ~16 ~21 stone_block_slab
setblock ~6 ~16 ~22 stone_brick_stairs 1
setblock ~36 ~16 ~22 leaves 3
setblock ~37 ~16 ~22 stone_block_slab 8
setblock ~59 ~16 ~22 stone_block_slab 8
setblock ~60 ~16 ~22 leaves 3
setblock ~90 ~16 ~22 stone_brick_stairs 0
setblock ~1 ~16 ~23 leaves 3
setblock ~2 ~16 ~23 stone_block_slab
setblock ~4 ~16 ~23 stone_block_slab 5
setblock ~92 ~16 ~23 stone_block_slab 5
setblock ~94 ~16 ~23 stone_block_slab
setblock ~52 ~16 ~24 stone_block_slab 8
setblock ~0 ~16 ~25 stone_block_slab 5
setblock ~3 ~16 ~25 stone_brick_stairs 3
setblock ~93 ~16 ~25 stone_brick_stairs 3
setblock ~96 ~16 ~25 stone_block_slab 5
setblock ~32 ~16 ~32 stone_block_slab
setblock ~56 ~16 ~32 smooth_stone
setblock ~57 ~16 ~32 double_stone_block_slab
setblock ~64 ~16 ~32 stone_block_slab
setblock ~47 ~16 ~33 prismarine
setblock ~49 ~16 ~33 prismarine
setblock ~47 ~16 ~34 sea_lantern
setblock ~49 ~16 ~34 sea_lantern
setblock ~47 ~16 ~35 iron_trapdoor 3
setblock ~49 ~16 ~35 iron_trapdoor 3
setblock ~22 ~16 ~36 leaves 3
setblock ~74 ~16 ~36 leaves 3
setblock ~22 ~16 ~37 stone_block_slab 8
setblock ~74 ~16 ~37 stone_block_slab 8
setblock ~21 ~16 ~38 stone_block_slab 8
setblock ~75 ~16 ~38 stone_block_slab 8
setblock ~32 ~16 ~39 double_stone_block_slab
setblock ~43 ~16 ~39 stonebrick
setblock ~44 ~16 ~39 stone_block_slab
setblock ~52 ~16 ~39 stone_block_slab
setblock ~53 ~16 ~39 stonebrick
setblock ~32 ~16 ~40 smooth_stone
setblock ~54 ~16 ~40 smooth_stone
setblock ~63 ~16 ~40 double_stone_block_slab
setblock ~41 ~16 ~41 stone_block_slab 8
setblock ~44 ~16 ~41 stone
setblock ~45 ~16 ~41 stonebrick
setblock ~46 ~16 ~41 stone_block_slab 13
setblock ~50 ~16 ~41 stone_block_slab 13
setblock ~51 ~16 ~41 stonebrick
setblock ~55 ~16 ~41 stone_block_slab 8
setblock ~40 ~16 ~42 smooth_stone
setblock ~42 ~16 ~42 stone
setblock ~43 ~16 ~42 stonebrick 2
setblock ~54 ~16 ~42 stone
setblock ~39 ~16 ~43 stonebrick
setblock ~42 ~16 ~43 stonebrick
setblock ~45 ~16 ~43 stonebrick 2
setblock ~46 ~16 ~43 stone_block_slab 13
setblock ~50 ~16 ~43 stone_block_slab 13
setblock ~51 ~16 ~43 stonebrick 2
setblock ~54 ~16 ~43 stonebrick 2
setblock ~57 ~16 ~43 stonebrick
setblock ~24 ~16 ~44 stone_block_slab 8
setblock ~39 ~16 ~44 stone_block_slab
setblock ~55 ~16 ~44 stone
setblock ~57 ~16 ~44 stone_block_slab
setblock ~43 ~16 ~45 stonebrick 2
setblock ~46 ~16 ~45 stone
setblock ~47 ~16 ~45 stone 6
setblock ~49 ~16 ~45 stone 6
setblock ~50 ~16 ~45 stone
setblock ~53 ~16 ~45 stonebrick 2
setblock ~55 ~16 ~45 stonebrick
setblock ~19 ~16 ~46 double_stone_block_slab
setblock ~41 ~16 ~46 stone_block_slab 13
setblock ~43 ~16 ~46 stone_block_slab 13
setblock ~45 ~16 ~46 stone
setblock ~46 ~16 ~46 double_stone_block_slab
setblock ~48 ~16 ~46 stone_block_slab 8
setblock ~50 ~16 ~46 double_stone_block_slab
setblock ~51 ~16 ~46 stone
setblock ~53 ~16 ~46 stone_block_slab 13
setblock ~55 ~16 ~46 stone_block_slab 13
setblock ~77 ~16 ~46 double_stone_block_slab
setblock ~19 ~16 ~47 stone_block_slab 8
setblock ~33 ~16 ~47 prismarine
setblock ~34 ~16 ~47 sea_lantern
setblock ~35 ~16 ~47 iron_trapdoor 1
setblock ~45 ~16 ~47 stone 6
setblock ~61 ~16 ~47 iron_trapdoor 0
setblock ~62 ~16 ~47 sea_lantern
setblock ~63 ~16 ~47 prismarine
setblock ~77 ~16 ~47 stone_block_slab 8
setblock ~19 ~16 ~48 anvil 1
setblock ~33 ~16 ~48 smooth_stone
setblock ~34 ~16 ~48 double_stone_block_slab
setblock ~48 ~16 ~48 iron_trapdoor 2
setblock ~63 ~16 ~48 smooth_stone
setblock ~77 ~16 ~48 anvil 3
setblock ~19 ~16 ~49 stone_block_slab 8
setblock ~33 ~16 ~49 prismarine
setblock ~34 ~16 ~49 sea_lantern
setblock ~35 ~16 ~49 iron_trapdoor 1
setblock ~45 ~16 ~49 stone 6
setblock ~61 ~16 ~49 iron_trapdoor 0
setblock ~62 ~16 ~49 sea_lantern
setblock ~63 ~16 ~49 prismarine
setblock ~77 ~16 ~49 stone_block_slab 8
setblock ~19 ~16 ~50 double_stone_block_slab
setblock ~41 ~16 ~50 stone_block_slab 13
setblock ~43 ~16 ~50 stone_block_slab 13
setblock ~45 ~16 ~50 stone
setblock ~46 ~16 ~50 double_stone_block_slab
setblock ~50 ~16 ~50 double_stone_block_slab
setblock ~51 ~16 ~50 stone
setblock ~53 ~16 ~50 stone_block_slab 13
setblock ~55 ~16 ~50 stone_block_slab 13
setblock ~77 ~16 ~50 double_stone_block_slab
setblock ~41 ~16 ~51 stonebrick
setblock ~46 ~16 ~51 stone
setblock ~50 ~16 ~51 stone
setblock ~53 ~16 ~51 stonebrick 2
setblock ~39 ~16 ~52 stone_block_slab
setblock ~41 ~16 ~52 stone
setblock ~57 ~16 ~52 stone_block_slab
setblock ~72 ~16 ~52 stone_block_slab 8
setblock ~39 ~16 ~53 stonebrick
setblock ~42 ~16 ~53 stonebrick 2
setblock ~45 ~16 ~53 stonebrick 2
setblock ~46 ~16 ~53 stone_block_slab 13
setblock ~50 ~16 ~53 stone_block_slab 13
setblock ~57 ~16 ~53 stonebrick
setblock ~42 ~16 ~54 stone
setblock ~53 ~16 ~54 stonebrick 2
setblock ~54 ~16 ~54 stone
setblock ~56 ~16 ~54 smooth_stone
setblock ~41 ~16 ~55 stone_block_slab 8
setblock ~45 ~16 ~55 stonebrick
setblock ~46 ~16 ~55 stone_block_slab 13
setblock ~50 ~16 ~55 stone_block_slab 13
setblock ~52 ~16 ~55 stone
setblock ~55 ~16 ~55 stone_block_slab 8
setblock ~42 ~16 ~56 smooth_stone
setblock ~64 ~16 ~56 smooth_stone
setblock ~43 ~16 ~57 stonebrick
setblock ~44 ~16 ~57 stone_block_slab
setblock ~52 ~16 ~57 stone_block_slab
setblock ~53 ~16 ~57 stonebrick
setblock ~64 ~16 ~57 double_stone_block_slab
setblock ~21 ~16 ~58 stone_block_slab 8
setblock ~75 ~16 ~58 stone_block_slab 8
setblock ~22 ~16 ~59 stone_block_slab 8
setblock ~74 ~16 ~59 stone_block_slab 8
setblock ~22 ~16 ~60 leaves 3
setblock ~74 ~16 ~60 leaves 3
setblock ~47 ~16 ~61 iron_trapdoor 2
setblock ~49 ~16 ~61 iron_trapdoor 2
setblock ~47 ~16 ~62 sea_lantern
setblock ~48 ~16 ~62 double_stone_block_slab
setblock ~49 ~16 ~62 sea_lantern
setblock ~47 ~16 ~63 prismarine
setblock ~48 ~16 ~63 smooth_stone
setblock ~49 ~16 ~63 prismarine
setblock ~56 ~16 ~63 double_stone_block_slab
setblock ~32 ~16 ~64 stone_block_slab
setblock ~39 ~16 ~64 double_stone_block_slab
setblock ~40 ~16 ~64 smooth_stone
setblock ~64 ~16 ~64 stone_block_slab
setblock ~0 ~16 ~71 stone_block_slab 5
setblock ~3 ~16 ~71 stone_brick_stairs 2
setblock ~93 ~16 ~71 stone_brick_stairs 2
setblock ~96 ~16 ~71 stone_block_slab 5
setblock ~44 ~16 ~72 stone_block_slab 8
setblock ~2 ~16 ~73 stone_block_slab
setblock ~4 ~16 ~73 stone_block_slab 5
setblock ~92 ~16 ~73 stone_block_slab 5
setblock ~94 ~16 ~73 stone_block_slab
setblock ~95 ~16 ~73 leaves 3
setblock ~6 ~16 ~74 stone_brick_stairs 1
setblock ~36 ~16 ~74 leaves 3
setblock ~37 ~16 ~74 stone_block_slab 8
setblock ~59 ~16 ~74 stone_block_slab 8
setblock ~60 ~16 ~74 leaves 3
setblock ~90 ~16 ~74 stone_brick_stairs 0
setblock ~4 ~16 ~75 stone_block_slab
setblock ~38 ~16 ~75 stone_block_slab 8
setblock ~58 ~16 ~75 stone_block_slab 8
setblock ~92 ~16 ~75 stone_block_slab
setblock ~4 ~16 ~76 leaves 3
setblock ~6 ~16 ~77 stone_block_slab 5
setblock ~46 ~16 ~77 double_stone_block_slab
