fill ~43 ~9 ~55 ~43 ~9 ~56 stone
fill ~36 ~7 ~56 ~36 ~9 ~56 stone
fill ~36 ~9 ~39 ~36 ~9 ~56 stone
fill ~34 ~8 ~56 ~34 ~9 ~56 stone
fill ~62 ~6 ~55 ~62 ~9 ~55 stone
fill ~62 ~9 ~49 ~62 ~9 ~55 stone
fill ~60 ~5 ~55 ~60 ~9 ~55 stone
fill ~60 ~9 ~39 ~60 ~9 ~55 stone
fill ~57 ~9 ~55 ~58 ~9 ~55 stone
fill ~58 ~7 ~55 ~58 ~9 ~55 stone
fill ~35 ~8 ~55 ~35 ~9 ~55 stone
fill ~35 ~9 ~39 ~35 ~9 ~55 stone
fill ~59 ~7 ~54 ~59 ~9 ~54 stone
fill ~59 ~9 ~46 ~59 ~9 ~54 stone
fill ~56 ~9 ~54 ~57 ~9 ~54 stone
fill ~57 ~8 ~54 ~57 ~9 ~54 stone
fill ~34 ~9 ~49 ~34 ~9 ~54 stone
fill ~55 ~9 ~53 ~56 ~9 ~53 stone
fill ~33 ~9 ~52 ~33 ~9 ~53 stone
fill ~64 ~9 ~51 ~64 ~9 ~52 stone
fill ~57 ~8 ~52 ~57 ~9 ~52 stone
fill ~57 ~9 ~44 ~57 ~9 ~52 stone
fill ~40 ~9 ~51 ~40 ~9 ~52 stone
fill ~63 ~9 ~49 ~63 ~9 ~51 stone
fill ~39 ~9 ~49 ~39 ~9 ~51 stone
fill ~37 ~8 ~51 ~37 ~9 ~51 stone
fill ~37 ~9 ~45 ~37 ~9 ~51 stone
fill ~38 ~8 ~50 ~38 ~9 ~50 stone
fill ~38 ~9 ~45 ~38 ~9 ~50 stone
fill ~74 ~8 ~49 ~74 ~9 ~49 stone
fill ~74 ~9 ~46 ~74 ~9 ~49 stone
fill ~58 ~9 ~45 ~58 ~9 ~49 stone
fill ~48 ~8 ~49 ~48 ~9 ~49 stone
fill ~22 ~8 ~49 ~22 ~9 ~49 stone
fill ~22 ~9 ~46 ~22 ~9 ~49 stone
fill ~47 ~7 ~48 ~47 ~9 ~48 stone
fill ~61 ~8 ~47 ~61 ~9 ~47 stone
fill ~48 ~6 ~47 ~48 ~9 ~47 stone
fill ~61 ~9 ~39 ~61 ~9 ~45 stone
fill ~34 ~8 ~45 ~34 ~9 ~45 stone
fill ~34 ~9 ~38 ~34 ~9 ~45 stone
fill ~62 ~9 ~38 ~62 ~9 ~44 stone
fill ~39 ~8 ~44 ~39 ~9 ~44 stone
fill ~32 ~9 ~34 ~32 ~9 ~44 stone
fill ~59 ~7 ~43 ~59 ~9 ~43 stone
fill ~59 ~9 ~38 ~59 ~9 ~43 stone
fill ~40 ~9 ~42 ~40 ~9 ~43 stone
fill ~63 ~9 ~42 ~64 ~9 ~42 stone
fill ~64 ~9 ~35 ~64 ~9 ~42 stone
fill ~37 ~7 ~42 ~37 ~9 ~42 stone
fill ~37 ~9 ~38 ~37 ~9 ~42 stone
fill ~33 ~8 ~42 ~33 ~9 ~42 stone
fill ~33 ~9 ~37 ~33 ~9 ~42 stone
fill ~31 ~9 ~35 ~31 ~9 ~42 stone
fill ~63 ~9 ~37 ~63 ~9 ~41 stone
fill ~38 ~7 ~41 ~38 ~9 ~41 stone
fill ~65 ~9 ~35 ~65 ~9 ~40 stone
fill ~43 ~9 ~39 ~43 ~9 ~40 stone
fill ~66 ~9 ~25 ~66 ~9 ~39 stone
fill ~58 ~6 ~39 ~58 ~9 ~39 stone
fill ~58 ~9 ~37 ~58 ~9 ~39 stone
fill ~52 ~8 ~39 ~52 ~9 ~39 stone
fill ~49 ~9 ~39 ~50 ~9 ~39 stone
fill ~38 ~5 ~39 ~38 ~9 ~39 stone
fill ~38 ~9 ~37 ~38 ~9 ~39 stone
fill ~57 ~5 ~38 ~57 ~9 ~38 stone
fill ~57 ~9 ~34 ~57 ~9 ~38 stone
fill ~47 ~9 ~38 ~49 ~9 ~38 stone
fill ~45 ~8 ~38 ~45 ~9 ~38 stone
fill ~41 ~7 ~38 ~41 ~9 ~38 stone
fill ~41 ~9 ~32 ~41 ~9 ~38 stone
fill ~39 ~6 ~38 ~39 ~9 ~38 stone
fill ~39 ~9 ~30 ~39 ~9 ~38 stone
fill ~35 ~8 ~38 ~35 ~9 ~38 stonebrick
fill ~30 ~8 ~38 ~30 ~9 ~38 stone
fill ~30 ~9 ~25 ~30 ~9 ~38 stone
fill ~67 ~8 ~37 ~67 ~9 ~37 stone
fill ~67 ~9 ~25 ~67 ~9 ~37 stone
fill ~56 ~4 ~37 ~56 ~9 ~37 stone
fill ~56 ~9 ~34 ~56 ~9 ~37 stone
fill ~50 ~9 ~37 ~52 ~9 ~37 stone
fill ~52 ~8 ~37 ~52 ~9 ~37 stone
fill ~46 ~9 ~37 ~48 ~9 ~37 stone
fill ~44 ~7 ~37 ~44 ~9 ~37 stone
fill ~40 ~6 ~37 ~40 ~9 ~37 stone
fill ~40 ~9 ~31 ~40 ~9 ~37 stone
fill ~29 ~7 ~37 ~29 ~9 ~37 stone
fill ~29 ~9 ~25 ~29 ~9 ~37 stone
fill ~77 ~9 ~35 ~77 ~9 ~36 stone
fill ~74 ~9 ~32 ~74 ~9 ~36 stone
fill ~70 ~8 ~36 ~70 ~9 ~36 stone
fill ~70 ~9 ~26 ~70 ~9 ~36 stone
fill ~68 ~8 ~36 ~68 ~9 ~36 stone
fill ~68 ~9 ~25 ~68 ~9 ~36 stone
fill ~55 ~5 ~36 ~55 ~9 ~36 stone
fill ~55 ~9 ~33 ~55 ~9 ~36 stone
fill ~53 ~6 ~36 ~53 ~9 ~36 stone
fill ~53 ~9 ~32 ~53 ~9 ~36 stone
fill ~49 ~9 ~36 ~51 ~9 ~36 stone
fill ~51 ~8 ~36 ~51 ~9 ~36 stone
fill ~45 ~9 ~36 ~47 ~9 ~36 stone
fill ~47 ~8 ~36 ~47 ~9 ~36 stone
fill ~47 ~9 ~35 ~47 ~9 ~36 stone
fill ~42 ~9 ~36 ~43 ~9 ~36 stone
fill ~43 ~8 ~36 ~43 ~9 ~36 stone
fill ~28 ~7 ~36 ~28 ~9 ~36 stone
fill ~28 ~9 ~26 ~28 ~9 ~36 stone
fill ~26 ~7 ~36 ~26 ~9 ~36 stone
fill ~26 ~9 ~26 ~26 ~9 ~36 stone
fill ~22 ~8 ~36 ~22 ~9 ~36 stone
fill ~22 ~9 ~32 ~22 ~9 ~36 stone
fill ~76 ~8 ~35 ~76 ~9 ~35 stone
fill ~76 ~9 ~34 ~76 ~9 ~35 stone
fill ~73 ~8 ~35 ~73 ~9 ~35 stone
fill ~73 ~9 ~31 ~73 ~9 ~35 stone
fill ~71 ~8 ~35 ~71 ~9 ~35 stone
fill ~71 ~9 ~29 ~71 ~9 ~35 stone
fill ~69 ~7 ~35 ~69 ~9 ~35 stone
fill ~69 ~9 ~26 ~69 ~9 ~35 stone
fill ~63 ~8 ~35 ~63 ~9 ~35 stonebrick
fill ~58 ~8 ~35 ~58 ~9 ~35 stonebrick
fill ~54 ~6 ~35 ~54 ~9 ~35 stone
fill ~54 ~9 ~32 ~54 ~9 ~35 stone
fill ~52 ~7 ~35 ~52 ~9 ~35 stone
fill ~52 ~9 ~32 ~52 ~9 ~35 stone
fill ~48 ~9 ~35 ~50 ~9 ~35 stone
fill ~50 ~8 ~35 ~50 ~9 ~35 stone
fill ~50 ~9 ~33 ~50 ~9 ~35 stone
fill ~44 ~9 ~35 ~46 ~9 ~35 stone
fill ~46 ~9 ~34 ~46 ~9 ~35 stone
fill ~42 ~8 ~35 ~42 ~9 ~35 stone
fill ~42 ~9 ~32 ~42 ~9 ~35 stone
fill ~27 ~6 ~35 ~27 ~9 ~35 stone
fill ~27 ~9 ~26 ~27 ~9 ~35 stone
fill ~25 ~7 ~35 ~25 ~9 ~35 stone
fill ~25 ~9 ~29 ~25 ~9 ~35 stone
fill ~23 ~7 ~35 ~23 ~9 ~35 stone
fill ~23 ~9 ~32 ~23 ~9 ~35 stone
fill ~20 ~7 ~35 ~20 ~9 ~35 stone
fill ~20 ~9 ~33 ~20 ~9 ~35 stone
fill ~15 ~9 ~35 ~16 ~9 ~35 stone
fill ~16 ~7 ~35 ~16 ~9 ~35 stone
fill ~80 ~7 ~34 ~80 ~9 ~34 stone
fill ~75 ~8 ~34 ~75 ~9 ~34 stone
fill ~72 ~7 ~34 ~72 ~9 ~34 stone
fill ~72 ~9 ~31 ~72 ~9 ~34 stone
fill ~51 ~8 ~34 ~51 ~9 ~34 stone
fill ~51 ~9 ~32 ~51 ~9 ~34 stone
fill ~49 ~8 ~34 ~49 ~9 ~34 stone
fill ~49 ~9 ~33 ~49 ~9 ~34 stone
fill ~43 ~9 ~34 ~45 ~9 ~34 stone
fill ~24 ~7 ~34 ~24 ~9 ~34 stone
fill ~24 ~9 ~31 ~24 ~9 ~34 stone
fill ~21 ~8 ~34 ~21 ~9 ~34 stone
fill ~38 ~8 ~33 ~38 ~9 ~33 stone
fill ~38 ~9 ~29 ~38 ~9 ~33 stone
fill ~59 ~9 ~32 ~61 ~9 ~32 stone
fill ~61 ~5 ~32 ~61 ~9 ~32 stone
fill ~37 ~9 ~28 ~37 ~9 ~32 stone
fill ~34 ~9 ~32 ~35 ~9 ~32 stone
fill ~35 ~8 ~32 ~35 ~9 ~32 stone
fill ~65 ~6 ~31 ~65 ~9 ~31 stone
fill ~65 ~9 ~24 ~65 ~9 ~31 stone
fill ~36 ~8 ~31 ~36 ~9 ~31 stone
fill ~36 ~9 ~27 ~36 ~9 ~31 stone
fill ~31 ~6 ~31 ~31 ~9 ~31 stone
fill ~31 ~9 ~23 ~31 ~9 ~31 stone
fill ~63 ~4 ~30 ~63 ~9 ~30 stone
fill ~63 ~9 ~20 ~63 ~9 ~30 stone
fill ~58 ~8 ~30 ~58 ~9 ~30 stone
fill ~35 ~7 ~30 ~35 ~9 ~30 stone
fill ~35 ~9 ~26 ~35 ~9 ~30 stone
fill ~32 ~9 ~30 ~33 ~9 ~30 stone
fill ~33 ~7 ~30 ~33 ~9 ~30 stone
fill ~64 ~6 ~29 ~64 ~9 ~29 stone
fill ~64 ~9 ~22 ~64 ~9 ~29 stone
fill ~34 ~7 ~29 ~34 ~9 ~29 stone
fill ~34 ~9 ~25 ~34 ~9 ~29 stone
fill ~32 ~7 ~29 ~32 ~9 ~29 stone
fill ~32 ~9 ~22 ~32 ~9 ~29 stone
fill ~8 ~9 ~28 ~8 ~9 ~29 stone
fill ~62 ~6 ~28 ~62 ~9 ~28 stone
fill ~62 ~9 ~19 ~62 ~9 ~28 stone
fill ~58 ~9 ~25 ~58 ~9 ~28 stone
fill ~33 ~7 ~28 ~33 ~9 ~28 stone
fill ~33 ~9 ~20 ~33 ~9 ~28 stone
fill ~93 ~8 ~27 ~93 ~9 ~27 leaves 3
fill ~87 ~7 ~27 ~87 ~9 ~27 stone
fill ~61 ~6 ~27 ~61 ~9 ~27 stone
fill ~61 ~9 ~15 ~61 ~9 ~27 stone
fill ~3 ~8 ~27 ~3 ~9 ~27 leaves 3
fill ~60 ~7 ~26 ~60 ~9 ~26 stone
fill ~60 ~9 ~18 ~60 ~9 ~26 stone
fill ~92 ~5 ~25 ~92 ~9 ~25 stone
fill ~6 ~5 ~23 ~6 ~9 ~23 stone
fill ~88 ~8 ~22 ~88 ~9 ~22 leaves 3
fill ~48 ~9 ~22 ~49 ~9 ~22 stone
fill ~49 ~8 ~22 ~49 ~9 ~22 stone
fill ~36 ~9 ~19 ~36 ~9 ~22 stone
fill ~34 ~8 ~22 ~34 ~9 ~22 stone
fill ~34 ~9 ~19 ~34 ~9 ~22 stone
fill ~8 ~8 ~22 ~8 ~9 ~22 leaves 3
fill ~59 ~9 ~19 ~59 ~9 ~21 stone
fill ~35 ~8 ~21 ~35 ~9 ~21 stone
fill ~35 ~9 ~15 ~35 ~9 ~21 stone
fill ~18 ~9 ~19 ~18 ~9 ~20 stone
fill ~83 ~8 ~18 ~83 ~9 ~18 leaves 3
fill ~77 ~7 ~18 ~77 ~9 ~18 stone
fill ~13 ~8 ~18 ~13 ~9 ~18 leaves 3
fill ~36 ~9 ~16 ~36 ~9 ~17 stone
fill ~34 ~8 ~17 ~34 ~9 ~17 stone
fill ~34 ~9 ~16 ~34 ~9 ~17 stone
fill ~82 ~5 ~16 ~82 ~9 ~16 stone
fill ~16 ~5 ~14 ~16 ~9 ~14 stone
fill ~78 ~8 ~13 ~78 ~9 ~13 leaves 3
fill ~18 ~8 ~13 ~18 ~9 ~13 leaves 3
fill ~27 ~9 ~9 ~27 ~9 ~10 stone
fill ~74 ~8 ~8 ~74 ~9 ~8 leaves 3
fill ~68 ~7 ~8 ~68 ~9 ~8 stone
fill ~22 ~8 ~8 ~22 ~9 ~8 leaves 3
fill ~73 ~5 ~6 ~73 ~9 ~6 stone
fill ~25 ~5 ~4 ~25 ~9 ~4 stone
fill ~69 ~8 ~3 ~69 ~9 ~3 leaves 3
fill ~27 ~8 ~3 ~27 ~9 ~3 leaves 3
fill ~72 ~6 ~92 ~72 ~8 ~92 stone
fill ~24 ~7 ~92 ~24 ~8 ~92 stone
fill ~73 ~7 ~91 ~73 ~8 ~91 stone
fill ~70 ~8 ~91 ~71 ~8 ~91 stone_block_slab
fill ~71 ~8 ~89 ~71 ~8 ~91 stone_block_slab
fill ~25 ~8 ~91 ~26 ~8 ~91 stone_block_slab
fill ~26 ~8 ~88 ~26 ~8 ~91 stone_block_slab
fill ~23 ~6 ~91 ~23 ~8 ~91 stone
fill ~72 ~8 ~89 ~72 ~8 ~90 stone_block_slab
fill ~70 ~8 ~88 ~70 ~8 ~90 stone_block_slab
fill ~24 ~8 ~90 ~25 ~8 ~90 stone_block_slab
fill ~25 ~8 ~89 ~25 ~8 ~90 stone_block_slab
fill ~69 ~8 ~88 ~69 ~8 ~89 stone_block_slab
fill ~27 ~8 ~88 ~27 ~8 ~89 stone_block_slab
fill ~81 ~6 ~82 ~81 ~8 ~82 stone
fill ~15 ~7 ~82 ~15 ~8 ~82 stone
fill ~82 ~7 ~81 ~82 ~8 ~81 stone
fill ~79 ~8 ~81 ~80 ~8 ~81 stone_block_slab
fill ~80 ~8 ~79 ~80 ~8 ~81 stone_block_slab
fill ~16 ~8 ~81 ~17 ~8 ~81 stone_block_slab
fill ~17 ~8 ~78 ~17 ~8 ~81 stone_block_slab
fill ~14 ~6 ~81 ~14 ~8 ~81 stone
fill ~81 ~8 ~79 ~81 ~8 ~80 stone_block_slab
fill ~79 ~8 ~78 ~79 ~8 ~80 stone_block_slab
fill ~15 ~8 ~80 ~16 ~8 ~80 stone_block_slab
fill ~16 ~8 ~79 ~16 ~8 ~80 stone_block_slab
fill ~78 ~8 ~78 ~78 ~8 ~79 stone_block_slab
fill ~18 ~8 ~78 ~18 ~8 ~79 stone_block_slab
fill ~61 ~8 ~73 ~61 ~8 ~78 stone
fill ~35 ~8 ~74 ~35 ~8 ~78 stone
fill ~62 ~8 ~74 ~62 ~8 ~76 stone
fill ~34 ~8 ~73 ~34 ~8 ~75 stone
fill ~91 ~6 ~73 ~91 ~8 ~73 stone
fill ~5 ~7 ~73 ~5 ~8 ~73 stone
fill ~92 ~7 ~72 ~92 ~8 ~72 stone
fill ~89 ~8 ~72 ~90 ~8 ~72 stone_block_slab
fill ~90 ~8 ~70 ~90 ~8 ~72 stone_block_slab
fill ~6 ~8 ~72 ~7 ~8 ~72 stone_block_slab
fill ~7 ~8 ~69 ~7 ~8 ~72 stone_block_slab
fill ~4 ~6 ~72 ~4 ~8 ~72 stone
fill ~91 ~8 ~70 ~91 ~8 ~71 stone_block_slab
fill ~89 ~8 ~69 ~89 ~8 ~71 stone_block_slab
fill ~33 ~7 ~71 ~33 ~8 ~71 stone
fill ~33 ~8 ~64 ~33 ~8 ~71 stone
fill ~5 ~8 ~71 ~6 ~8 ~71 stone_block_slab
fill ~6 ~8 ~70 ~6 ~8 ~71 stone_block_slab
fill ~88 ~8 ~69 ~88 ~8 ~70 stone_block_slab
fill ~64 ~7 ~70 ~64 ~8 ~70 stone
fill ~64 ~8 ~60 ~64 ~8 ~70 stone
fill ~36 ~7 ~70 ~36 ~8 ~70 stone
fill ~36 ~8 ~64 ~36 ~8 ~70 stone
fill ~32 ~7 ~70 ~32 ~8 ~70 stone
fill ~32 ~8 ~60 ~32 ~8 ~70 stone
fill ~8 ~8 ~69 ~8 ~8 ~70 stone_block_slab
fill ~63 ~7 ~69 ~63 ~8 ~69 stone
fill ~63 ~8 ~65 ~63 ~8 ~69 stone
fill ~35 ~6 ~69 ~35 ~8 ~69 stone
fill ~35 ~8 ~64 ~35 ~8 ~69 stone
fill ~65 ~7 ~68 ~65 ~8 ~68 stone
fill ~62 ~7 ~68 ~62 ~8 ~68 stone
fill ~62 ~8 ~63 ~62 ~8 ~68 stone
fill ~34 ~6 ~68 ~34 ~8 ~68 stone
fill ~34 ~8 ~63 ~34 ~8 ~68 stone
fill ~30 ~7 ~68 ~30 ~8 ~68 stone
fill ~28 ~7 ~68 ~28 ~8 ~68 stone
fill ~28 ~8 ~66 ~28 ~8 ~68 stone
fill ~61 ~7 ~67 ~61 ~8 ~67 stone
fill ~61 ~8 ~64 ~61 ~8 ~67 stone
fill ~38 ~8 ~62 ~38 ~8 ~67 stone
fill ~31 ~7 ~67 ~31 ~8 ~67 stone
fill ~31 ~8 ~60 ~31 ~8 ~67 stone
fill ~29 ~7 ~67 ~29 ~8 ~67 stone
fill ~27 ~8 ~65 ~27 ~8 ~67 stone
fill ~70 ~8 ~65 ~70 ~8 ~66 stone
fill ~68 ~7 ~66 ~68 ~8 ~66 stone
fill ~60 ~8 ~64 ~60 ~8 ~66 stone
fill ~26 ~8 ~64 ~26 ~8 ~66 stone
fill ~69 ~7 ~65 ~69 ~8 ~65 stone
fill ~69 ~8 ~64 ~69 ~8 ~65 stone
fill ~65 ~6 ~65 ~65 ~8 ~65 stone
fill ~65 ~8 ~60 ~65 ~8 ~65 stone
fill ~39 ~8 ~56 ~39 ~8 ~65 stone
fill ~68 ~7 ~64 ~68 ~8 ~64 stone
fill ~68 ~8 ~63 ~68 ~8 ~64 stone
fill ~58 ~8 ~62 ~58 ~8 ~64 stone
fill ~66 ~4 ~63 ~66 ~8 ~63 stone
fill ~66 ~8 ~59 ~66 ~8 ~63 stone
fill ~56 ~8 ~63 ~57 ~8 ~63 stone
fill ~57 ~8 ~59 ~57 ~8 ~63 stone
fill ~30 ~7 ~63 ~30 ~8 ~63 stone
fill ~30 ~8 ~60 ~30 ~8 ~63 stone
fill ~25 ~7 ~63 ~25 ~8 ~63 stone
fill ~72 ~7 ~62 ~72 ~8 ~62 stone
fill ~67 ~5 ~62 ~67 ~8 ~62 stone
fill ~67 ~8 ~60 ~67 ~8 ~62 stone
fill ~55 ~8 ~62 ~56 ~8 ~62 stone
fill ~56 ~8 ~58 ~56 ~8 ~62 stone
fill ~40 ~6 ~62 ~40 ~8 ~62 stone
fill ~40 ~8 ~57 ~40 ~8 ~62 stone
fill ~29 ~7 ~62 ~29 ~8 ~62 stone
fill ~29 ~8 ~59 ~29 ~8 ~62 stone
fill ~24 ~7 ~62 ~24 ~8 ~62 stone
fill ~22 ~8 ~61 ~22 ~8 ~62 stone
fill ~71 ~7 ~61 ~71 ~8 ~61 stone
fill ~71 ~8 ~59 ~71 ~8 ~61 stone
fill ~54 ~8 ~61 ~55 ~8 ~61 stone
fill ~55 ~8 ~57 ~55 ~8 ~61 stone
fill ~47 ~8 ~60 ~47 ~8 ~61 stone
fill ~45 ~8 ~60 ~45 ~8 ~61 stone
fill ~41 ~6 ~61 ~41 ~8 ~61 stone
fill ~41 ~8 ~58 ~41 ~8 ~61 stone
fill ~28 ~7 ~61 ~28 ~8 ~61 stone
fill ~28 ~8 ~60 ~28 ~8 ~61 stone
fill ~17 ~6 ~61 ~17 ~8 ~61 stone
fill ~70 ~7 ~60 ~70 ~8 ~60 stone
fill ~70 ~8 ~59 ~70 ~8 ~60 stone
fill ~53 ~8 ~60 ~54 ~8 ~60 stone
fill ~54 ~8 ~57 ~54 ~8 ~60 stone
fill ~51 ~8 ~58 ~51 ~8 ~60 stone
fill ~49 ~8 ~59 ~49 ~8 ~60 stone
fill ~46 ~8 ~59 ~46 ~8 ~60 stone
fill ~44 ~7 ~60 ~44 ~8 ~60 stone
fill ~44 ~8 ~59 ~44 ~8 ~60 stone
fill ~42 ~6 ~60 ~42 ~8 ~60 stone
fill ~42 ~8 ~59 ~42 ~8 ~60 stone
fill ~16 ~7 ~60 ~16 ~8 ~60 stone
fill ~52 ~8 ~59 ~53 ~8 ~59 stone
fill ~53 ~7 ~59 ~53 ~8 ~59 stone
fill ~50 ~8 ~58 ~50 ~8 ~59 stone
fill ~59 ~3 ~57 ~59 ~8 ~57 stone
fill ~38 ~6 ~57 ~38 ~8 ~57 stone
fill ~38 ~8 ~55 ~38 ~8 ~57 stone
fill ~58 ~6 ~56 ~58 ~8 ~56 stone
fill ~37 ~6 ~56 ~37 ~8 ~56 stone
fill ~37 ~8 ~54 ~37 ~8 ~56 stone
fill ~61 ~6 ~55 ~61 ~8 ~55 stone
fill ~61 ~8 ~49 ~61 ~8 ~55 stone
fill ~36 ~8 ~39 ~36 ~8 ~55 stone
fill ~62 ~7 ~54 ~62 ~8 ~54 stone
fill ~62 ~8 ~49 ~62 ~8 ~54 stone
fill ~60 ~6 ~54 ~60 ~8 ~54 stone
fill ~60 ~8 ~39 ~60 ~8 ~54 stone
fill ~35 ~8 ~53 ~35 ~8 ~54 stone
fill ~59 ~8 ~50 ~59 ~8 ~53 stone
fill ~37 ~8 ~49 ~37 ~8 ~50 stone
fill ~35 ~8 ~39 ~35 ~8 ~50 stone
fill ~74 ~5 ~48 ~74 ~8 ~48 stone
fill ~74 ~8 ~47 ~74 ~8 ~48 stone
fill ~22 ~5 ~48 ~22 ~8 ~48 stone
fill ~22 ~8 ~47 ~22 ~8 ~48 stone
fill ~59 ~8 ~46 ~59 ~8 ~47 stone
fill ~58 ~8 ~45 ~58 ~8 ~46 stone
fill ~37 ~8 ~45 ~37 ~8 ~46 stone
fill ~34 ~8 ~38 ~34 ~8 ~44 stone
fill ~61 ~8 ~39 ~61 ~8 ~43 stone
fill ~59 ~7 ~42 ~59 ~8 ~42 stone
fill ~59 ~8 ~38 ~59 ~8 ~42 stone
fill ~32 ~8 ~34 ~32 ~8 ~42 stone
fill ~62 ~8 ~38 ~62 ~8 ~41 stone
fill ~37 ~6 ~41 ~37 ~8 ~41 stone
fill ~37 ~8 ~38 ~37 ~8 ~41 stone
fill ~33 ~7 ~41 ~33 ~8 ~41 stone
fill ~33 ~8 ~37 ~33 ~8 ~41 stone
fill ~63 ~8 ~38 ~63 ~8 ~40 stone
fill ~31 ~8 ~35 ~31 ~8 ~39 stone
fill ~58 ~6 ~38 ~58 ~8 ~38 stone
fill ~58 ~8 ~37 ~58 ~8 ~38 stone
fill ~38 ~6 ~38 ~38 ~8 ~38 stone
fill ~38 ~8 ~37 ~38 ~8 ~38 stone
fill ~65 ~8 ~37 ~66 ~8 ~37 stone
fill ~66 ~8 ~26 ~66 ~8 ~37 stone
fill ~57 ~3 ~37 ~57 ~8 ~37 stone
fill ~57 ~8 ~34 ~57 ~8 ~37 stone
fill ~50 ~8 ~37 ~51 ~8 ~37 stone
fill ~46 ~8 ~37 ~47 ~8 ~37 stone
fill ~41 ~6 ~37 ~41 ~8 ~37 stone
fill ~41 ~8 ~34 ~41 ~8 ~37 stone
fill ~39 ~6 ~37 ~39 ~8 ~37 stone
fill ~39 ~8 ~33 ~39 ~8 ~37 stone
fill ~30 ~7 ~37 ~30 ~8 ~37 stone
fill ~30 ~8 ~26 ~30 ~8 ~37 stone
fill ~67 ~8 ~26 ~67 ~8 ~36 stone
fill ~64 ~8 ~36 ~65 ~8 ~36 stone
fill ~65 ~8 ~35 ~65 ~8 ~36 stone
fill ~56 ~2 ~36 ~56 ~8 ~36 stone
fill ~56 ~8 ~34 ~56 ~8 ~36 stone
fill ~49 ~8 ~36 ~50 ~8 ~36 stone
fill ~45 ~8 ~36 ~46 ~8 ~36 stone
fill ~40 ~7 ~36 ~40 ~8 ~36 stone
fill ~40 ~8 ~33 ~40 ~8 ~36 stone
fill ~29 ~6 ~36 ~29 ~8 ~36 stone
fill ~29 ~8 ~27 ~29 ~8 ~36 stone
fill ~74 ~8 ~33 ~74 ~8 ~35 stone
fill ~70 ~8 ~30 ~70 ~8 ~35 stone
fill ~68 ~7 ~35 ~68 ~8 ~35 stone
fill ~68 ~8 ~26 ~68 ~8 ~35 stone
fill ~55 ~6 ~35 ~55 ~8 ~35 stone
fill ~55 ~8 ~33 ~55 ~8 ~35 stone
fill ~53 ~7 ~35 ~53 ~8 ~35 stone
fill ~53 ~8 ~33 ~53 ~8 ~35 stone
fill ~47 ~8 ~35 ~49 ~8 ~35 stone
fill ~28 ~6 ~35 ~28 ~8 ~35 stone
fill ~28 ~8 ~27 ~28 ~8 ~35 stone
fill ~26 ~7 ~35 ~26 ~8 ~35 stone
fill ~26 ~8 ~26 ~26 ~8 ~35 stone
fill ~22 ~7 ~35 ~22 ~8 ~35 stone
fill ~22 ~8 ~34 ~22 ~8 ~35 stone
fill ~15 ~6 ~35 ~15 ~8 ~35 stone
fill ~73 ~7 ~34 ~73 ~8 ~34 stone
fill ~73 ~8 ~33 ~73 ~8 ~34 stone
fill ~71 ~7 ~34 ~71 ~8 ~34 stone
fill ~71 ~8 ~31 ~71 ~8 ~34 stone
fill ~69 ~7 ~34 ~69 ~8 ~34 stone
fill ~69 ~8 ~26 ~69 ~8 ~34 stone
fill ~54 ~7 ~34 ~54 ~8 ~34 stone
fill ~54 ~8 ~32 ~54 ~8 ~34 stone
fill ~52 ~8 ~33 ~52 ~8 ~34 stone
fill ~27 ~6 ~34 ~27 ~8 ~34 stone
fill ~27 ~8 ~26 ~27 ~8 ~34 stone
fill ~25 ~7 ~34 ~25 ~8 ~34 stone
fill ~25 ~8 ~31 ~25 ~8 ~34 stone
fill ~23 ~7 ~34 ~23 ~8 ~34 stone
fill ~23 ~8 ~33 ~23 ~8 ~34 stone
fill ~72 ~7 ~33 ~72 ~8 ~33 stone
fill ~72 ~8 ~32 ~72 ~8 ~33 stone
fill ~24 ~8 ~32 ~24 ~8 ~33 stone
fill ~59 ~8 ~32 ~60 ~8 ~32 stone
fill ~60 ~7 ~32 ~60 ~8 ~32 stone
fill ~34 ~7 ~32 ~34 ~8 ~32 stone
fill ~37 ~8 ~29 ~37 ~8 ~31 stone
fill ~65 ~6 ~30 ~65 ~8 ~30 stone
fill ~65 ~8 ~25 ~65 ~8 ~30 stone
fill ~36 ~8 ~27 ~36 ~8 ~30 stone
fill ~31 ~8 ~30 ~32 ~8 ~30 stone
fill ~32 ~7 ~30 ~32 ~8 ~30 stone
fill ~63 ~6 ~29 ~63 ~8 ~29 stone
fill ~63 ~8 ~23 ~63 ~8 ~29 stone
fill ~35 ~7 ~29 ~35 ~8 ~29 stone
fill ~35 ~8 ~26 ~35 ~8 ~29 stone
fill ~31 ~7 ~29 ~31 ~8 ~29 stone
fill ~31 ~8 ~25 ~31 ~8 ~29 stone
fill ~64 ~7 ~28 ~64 ~8 ~28 stone
fill ~64 ~8 ~24 ~64 ~8 ~28 stone
fill ~34 ~7 ~28 ~34 ~8 ~28 stone
fill ~34 ~8 ~25 ~34 ~8 ~28 stone
fill ~32 ~7 ~28 ~32 ~8 ~28 stone
fill ~32 ~8 ~24 ~32 ~8 ~28 stone
fill ~8 ~7 ~28 ~8 ~8 ~28 stone
fill ~88 ~8 ~27 ~89 ~8 ~27 stone_block_slab
fill ~89 ~8 ~24 ~89 ~8 ~27 stone_block_slab
fill ~70 ~8 ~26 ~70 ~8 ~27 stone
fill ~62 ~6 ~27 ~62 ~8 ~27 stone
fill ~62 ~8 ~21 ~62 ~8 ~27 stone
fill ~33 ~7 ~27 ~33 ~8 ~27 stone
fill ~33 ~8 ~22 ~33 ~8 ~27 stone
fill ~7 ~8 ~27 ~8 ~8 ~27 stone_block_slab
fill ~8 ~8 ~26 ~8 ~8 ~27 stone_block_slab
fill ~90 ~8 ~26 ~91 ~8 ~26 stone_block_slab
fill ~91 ~8 ~25 ~91 ~8 ~26 stone_block_slab
fill ~61 ~7 ~26 ~61 ~8 ~26 stone
fill ~61 ~8 ~15 ~61 ~8 ~26 stone
fill ~5 ~8 ~26 ~7 ~8 ~26 stone_block_slab
fill ~7 ~8 ~24 ~7 ~8 ~26 stone_block_slab
fill ~90 ~8 ~24 ~90 ~8 ~25 stone_block_slab
fill ~60 ~7 ~25 ~60 ~8 ~25 stone
fill ~60 ~8 ~21 ~60 ~8 ~25 stone
fill ~5 ~8 ~25 ~6 ~8 ~25 stone_block_slab
fill ~6 ~8 ~24 ~6 ~8 ~25 stone_block_slab
fill ~92 ~6 ~24 ~92 ~8 ~24 stone
fill ~4 ~7 ~24 ~4 ~8 ~24 stone
fill ~91 ~7 ~23 ~91 ~8 ~23 stone
fill ~5 ~6 ~23 ~5 ~8 ~23 stone
fill ~48 ~5 ~22 ~48 ~8 ~22 stone
fill ~34 ~8 ~19 ~34 ~8 ~21 stone
fill ~35 ~8 ~15 ~35 ~8 ~20 stone
fill ~18 ~7 ~19 ~18 ~8 ~19 stone
fill ~78 ~8 ~18 ~79 ~8 ~18 stone_block_slab
fill ~79 ~8 ~15 ~79 ~8 ~18 stone_block_slab
fill ~17 ~8 ~18 ~18 ~8 ~18 stone_block_slab
fill ~18 ~8 ~17 ~18 ~8 ~18 stone_block_slab
fill ~80 ~8 ~17 ~81 ~8 ~17 stone_block_slab
fill ~81 ~8 ~16 ~81 ~8 ~17 stone_block_slab
fill ~15 ~8 ~17 ~17 ~8 ~17 stone_block_slab
fill ~17 ~8 ~15 ~17 ~8 ~17 stone_block_slab
fill ~80 ~8 ~15 ~80 ~8 ~16 stone_block_slab
fill ~36 ~7 ~16 ~36 ~8 ~16 stone
fill ~34 ~7 ~16 ~34 ~8 ~16 stone
fill ~15 ~8 ~16 ~16 ~8 ~16 stone_block_slab
fill ~16 ~8 ~15 ~16 ~8 ~16 stone_block_slab
fill ~82 ~6 ~15 ~82 ~8 ~15 stone
fill ~14 ~7 ~15 ~14 ~8 ~15 stone
fill ~81 ~7 ~14 ~81 ~8 ~14 stone
fill ~15 ~6 ~14 ~15 ~8 ~14 stone
fill ~27 ~7 ~9 ~27 ~8 ~9 stone
fill ~69 ~8 ~8 ~70 ~8 ~8 stone_block_slab
fill ~70 ~8 ~5 ~70 ~8 ~8 stone_block_slab
fill ~26 ~8 ~8 ~27 ~8 ~8 stone_block_slab
fill ~27 ~8 ~7 ~27 ~8 ~8 stone_block_slab
fill ~71 ~8 ~7 ~72 ~8 ~7 stone_block_slab
fill ~72 ~8 ~6 ~72 ~8 ~7 stone_block_slab
fill ~24 ~8 ~7 ~26 ~8 ~7 stone_block_slab
fill ~26 ~8 ~5 ~26 ~8 ~7 stone_block_slab
fill ~71 ~8 ~5 ~71 ~8 ~6 stone_block_slab
fill ~24 ~8 ~6 ~25 ~8 ~6 stone_block_slab
fill ~25 ~8 ~5 ~25 ~8 ~6 stone_block_slab
fill ~73 ~6 ~5 ~73 ~8 ~5 stone
fill ~23 ~7 ~5 ~23 ~8 ~5 stone
fill ~72 ~7 ~4 ~72 ~8 ~4 stone
fill ~24 ~6 ~4 ~24 ~8 ~4 stone
fill ~70 ~7 ~91 ~72 ~7 ~91 stone
fill ~72 ~5 ~91 ~72 ~7 ~91 stone
fill ~72 ~7 ~89 ~72 ~7 ~91 stone
fill ~24 ~7 ~91 ~26 ~7 ~91 stone
fill ~26 ~4 ~91 ~26 ~7 ~91 stone
fill ~26 ~7 ~87 ~26 ~7 ~91 stone
fill ~69 ~7 ~90 ~71 ~7 ~90 stone
fill ~71 ~0 ~90 ~71 ~7 ~90 stone
fill ~71 ~7 ~88 ~71 ~7 ~90 stone
fill ~27 ~7 ~88 ~27 ~7 ~90 stone
fill ~24 ~7 ~90 ~25 ~7 ~90 stone
fill ~25 ~0 ~90 ~25 ~7 ~90 stone
fill ~25 ~7 ~88 ~25 ~7 ~90 stone
fill ~68 ~7 ~89 ~70 ~7 ~89 stone
fill ~70 ~2 ~89 ~70 ~7 ~89 stone
fill ~70 ~7 ~87 ~70 ~7 ~89 stone
fill ~28 ~6 ~89 ~28 ~7 ~89 stone
fill ~24 ~4 ~89 ~24 ~7 ~89 stone
fill ~69 ~6 ~88 ~69 ~7 ~88 stone
fill ~79 ~7 ~81 ~81 ~7 ~81 stone
fill ~81 ~5 ~81 ~81 ~7 ~81 stone
fill ~81 ~7 ~79 ~81 ~7 ~81 stone
fill ~15 ~7 ~81 ~17 ~7 ~81 stone
fill ~17 ~4 ~81 ~17 ~7 ~81 stone
fill ~17 ~7 ~77 ~17 ~7 ~81 stone
fill ~78 ~7 ~80 ~80 ~7 ~80 stone
fill ~80 ~0 ~80 ~80 ~7 ~80 stone
fill ~80 ~7 ~78 ~80 ~7 ~80 stone
fill ~18 ~7 ~78 ~18 ~7 ~80 stone
fill ~15 ~7 ~80 ~16 ~7 ~80 stone
fill ~16 ~0 ~80 ~16 ~7 ~80 stone
fill ~16 ~7 ~78 ~16 ~7 ~80 stone
fill ~77 ~7 ~79 ~79 ~7 ~79 stone
fill ~79 ~2 ~79 ~79 ~7 ~79 stone
fill ~79 ~7 ~77 ~79 ~7 ~79 stone
fill ~19 ~6 ~79 ~19 ~7 ~79 stone
fill ~15 ~4 ~79 ~15 ~7 ~79 stone
fill ~78 ~6 ~78 ~78 ~7 ~78 stone
fill ~35 ~7 ~74 ~35 ~7 ~76 stone
fill ~89 ~7 ~72 ~91 ~7 ~72 stone
fill ~91 ~5 ~72 ~91 ~7 ~72 stone
fill ~91 ~7 ~70 ~91 ~7 ~72 stone
fill ~5 ~7 ~72 ~7 ~7 ~72 stone
fill ~7 ~4 ~72 ~7 ~7 ~72 stone
fill ~7 ~7 ~68 ~7 ~7 ~72 stone
fill ~88 ~7 ~71 ~90 ~7 ~71 stone
fill ~90 ~0 ~71 ~90 ~7 ~71 stone
fill ~90 ~7 ~69 ~90 ~7 ~71 stone
fill ~8 ~7 ~69 ~8 ~7 ~71 stone
fill ~5 ~7 ~71 ~6 ~7 ~71 stone
fill ~6 ~0 ~71 ~6 ~7 ~71 stone
fill ~6 ~7 ~69 ~6 ~7 ~71 stone
fill ~87 ~7 ~70 ~89 ~7 ~70 stone
fill ~89 ~2 ~70 ~89 ~7 ~70 stone
fill ~89 ~7 ~68 ~89 ~7 ~70 stone
fill ~33 ~7 ~64 ~33 ~7 ~70 stone
fill ~9 ~6 ~70 ~9 ~7 ~70 stone
fill ~5 ~4 ~70 ~5 ~7 ~70 stone
fill ~88 ~6 ~69 ~88 ~7 ~69 stone
fill ~64 ~7 ~60 ~64 ~7 ~69 stone
fill ~36 ~7 ~64 ~36 ~7 ~69 stone
fill ~32 ~7 ~62 ~32 ~7 ~69 stone
fill ~63 ~7 ~65 ~63 ~7 ~68 stone
fill ~35 ~6 ~68 ~35 ~7 ~68 stone
fill ~35 ~7 ~64 ~35 ~7 ~68 stone
fill ~62 ~7 ~64 ~62 ~7 ~67 stone
fill ~34 ~5 ~67 ~34 ~7 ~67 stone
fill ~34 ~7 ~63 ~34 ~7 ~67 stone
fill ~28 ~7 ~66 ~28 ~7 ~67 stone
fill ~61 ~7 ~65 ~61 ~7 ~66 stone
fill ~31 ~6 ~66 ~31 ~7 ~66 stone
fill ~31 ~7 ~61 ~31 ~7 ~66 stone
fill ~65 ~5 ~64 ~65 ~7 ~64 stone
fill ~65 ~7 ~60 ~65 ~7 ~64 stone
fill ~38 ~7 ~64 ~39 ~7 ~64 stone
fill ~39 ~7 ~56 ~39 ~7 ~64 stone
fill ~68 ~6 ~63 ~68 ~7 ~63 stone
fill ~38 ~7 ~62 ~38 ~7 ~63 stone
fill ~66 ~3 ~62 ~66 ~7 ~62 stone
fill ~66 ~7 ~59 ~66 ~7 ~62 stone
fill ~30 ~7 ~61 ~30 ~7 ~62 stone
fill ~67 ~6 ~61 ~67 ~7 ~61 stone
fill ~67 ~7 ~60 ~67 ~7 ~61 stone
fill ~40 ~6 ~61 ~40 ~7 ~61 stone
fill ~40 ~7 ~57 ~40 ~7 ~61 stone
fill ~56 ~7 ~60 ~57 ~7 ~60 stone
fill ~57 ~7 ~59 ~57 ~7 ~60 stone
fill ~41 ~5 ~60 ~41 ~7 ~60 stone
fill ~41 ~7 ~58 ~41 ~7 ~60 stone
fill ~54 ~7 ~59 ~56 ~7 ~59 stone
fill ~56 ~6 ~59 ~56 ~7 ~59 stone
fill ~56 ~7 ~58 ~56 ~7 ~59 stone
fill ~54 ~7 ~58 ~55 ~7 ~58 stone
fill ~38 ~7 ~55 ~38 ~7 ~56 stone
fill ~37 ~6 ~55 ~37 ~7 ~55 stone
fill ~37 ~7 ~54 ~37 ~7 ~55 stone
fill ~61 ~6 ~54 ~61 ~7 ~54 stone
fill ~61 ~7 ~52 ~61 ~7 ~54 stone
fill ~60 ~6 ~53 ~60 ~7 ~53 stone
fill ~60 ~7 ~52 ~60 ~7 ~53 stone
fill ~35 ~7 ~44 ~36 ~7 ~44 stone
fill ~36 ~7 ~39 ~36 ~7 ~44 stone
fill ~34 ~7 ~43 ~35 ~7 ~43 stone
fill ~35 ~7 ~39 ~35 ~7 ~43 stone
fill ~34 ~7 ~38 ~34 ~7 ~42 stone
fill ~59 ~6 ~41 ~59 ~7 ~41 stone
fill ~59 ~7 ~38 ~59 ~7 ~41 stone
fill ~60 ~7 ~39 ~60 ~7 ~40 stone
fill ~37 ~4 ~40 ~37 ~7 ~40 stone
fill ~37 ~7 ~38 ~37 ~7 ~40 stone
fill ~33 ~7 ~37 ~33 ~7 ~40 stone
fill ~32 ~7 ~34 ~32 ~7 ~39 stone
fill ~58 ~5 ~37 ~58 ~7 ~37 stone
fill ~38 ~6 ~37 ~38 ~7 ~37 stone
fill ~31 ~7 ~35 ~31 ~7 ~37 stone
fill ~57 ~1 ~36 ~57 ~7 ~36 stone
fill ~57 ~7 ~34 ~57 ~7 ~36 stone
fill ~30 ~6 ~36 ~30 ~7 ~36 stone
fill ~30 ~7 ~28 ~30 ~7 ~36 stone
fill ~65 ~7 ~35 ~67 ~7 ~35 stone
fill ~67 ~7 ~28 ~67 ~7 ~35 stone
fill ~56 ~6 ~35 ~56 ~7 ~35 stone
fill ~56 ~7 ~34 ~56 ~7 ~35 stone
fill ~29 ~6 ~35 ~29 ~7 ~35 stone
fill ~29 ~7 ~28 ~29 ~7 ~35 stone
fill ~70 ~7 ~32 ~70 ~7 ~34 stone
fill ~68 ~7 ~27 ~68 ~7 ~34 stone
fill ~66 ~7 ~27 ~66 ~7 ~34 stone
fill ~55 ~6 ~34 ~55 ~7 ~34 stone
fill ~55 ~7 ~33 ~55 ~7 ~34 stone
fill ~28 ~6 ~34 ~28 ~7 ~34 stone
fill ~28 ~7 ~27 ~28 ~7 ~34 stone
fill ~26 ~6 ~34 ~26 ~7 ~34 stone
fill ~26 ~7 ~32 ~26 ~7 ~34 stone
fill ~69 ~7 ~31 ~69 ~7 ~33 stone
fill ~27 ~7 ~30 ~27 ~7 ~33 stone
fill ~65 ~7 ~27 ~65 ~7 ~29 stone
fill ~89 ~6 ~28 ~89 ~7 ~28 stone
fill ~89 ~7 ~24 ~89 ~7 ~28 stone
fill ~69 ~5 ~28 ~69 ~7 ~28 stone
fill ~69 ~7 ~26 ~69 ~7 ~28 stone
fill ~63 ~6 ~28 ~63 ~7 ~28 stone
fill ~63 ~7 ~25 ~63 ~7 ~28 stone
fill ~35 ~7 ~27 ~35 ~7 ~28 stone
fill ~31 ~7 ~27 ~31 ~7 ~28 stone
fill ~27 ~6 ~28 ~27 ~7 ~28 stone
fill ~27 ~7 ~27 ~27 ~7 ~28 stone
fill ~7 ~6 ~28 ~7 ~7 ~28 stone
fill ~7 ~7 ~24 ~7 ~7 ~28 stone
fill ~90 ~7 ~24 ~90 ~7 ~27 stone
fill ~88 ~6 ~27 ~88 ~7 ~27 stone
fill ~88 ~7 ~25 ~88 ~7 ~27 stone
fill ~64 ~7 ~26 ~64 ~7 ~27 stone
fill ~34 ~7 ~25 ~34 ~7 ~27 stone
fill ~32 ~7 ~26 ~32 ~7 ~27 stone
fill ~26 ~7 ~26 ~26 ~7 ~27 stone
fill ~8 ~6 ~27 ~8 ~7 ~27 stone
fill ~8 ~7 ~25 ~8 ~7 ~27 stone
fill ~6 ~7 ~24 ~6 ~7 ~27 stone
fill ~91 ~4 ~26 ~91 ~7 ~26 stone
fill ~91 ~7 ~24 ~91 ~7 ~26 stone
fill ~87 ~6 ~26 ~87 ~7 ~26 stone
fill ~70 ~6 ~26 ~70 ~7 ~26 stone
fill ~62 ~6 ~26 ~62 ~7 ~26 stone
fill ~62 ~7 ~23 ~62 ~7 ~26 stone
fill ~33 ~7 ~24 ~33 ~7 ~26 stone
fill ~9 ~6 ~26 ~9 ~7 ~26 stone
fill ~5 ~4 ~26 ~5 ~7 ~26 stone
fill ~5 ~7 ~24 ~5 ~7 ~26 stone
fill ~61 ~7 ~20 ~61 ~7 ~25 stone
fill ~79 ~6 ~19 ~79 ~7 ~19 stone
fill ~79 ~7 ~15 ~79 ~7 ~19 stone
fill ~17 ~6 ~19 ~17 ~7 ~19 stone
fill ~17 ~7 ~15 ~17 ~7 ~19 stone
fill ~80 ~7 ~15 ~80 ~7 ~18 stone
fill ~78 ~6 ~18 ~78 ~7 ~18 stone
fill ~78 ~7 ~16 ~78 ~7 ~18 stone
fill ~18 ~6 ~18 ~18 ~7 ~18 stone
fill ~18 ~7 ~16 ~18 ~7 ~18 stone
fill ~16 ~7 ~15 ~16 ~7 ~18 stone
fill ~81 ~4 ~17 ~81 ~7 ~17 stone
fill ~81 ~7 ~15 ~81 ~7 ~17 stone
fill ~77 ~6 ~17 ~77 ~7 ~17 stone
fill ~35 ~6 ~17 ~35 ~7 ~17 stone
fill ~35 ~7 ~16 ~35 ~7 ~17 stone
fill ~19 ~6 ~17 ~19 ~7 ~17 stone
fill ~15 ~4 ~17 ~15 ~7 ~17 stone
fill ~15 ~7 ~15 ~15 ~7 ~17 stone
fill ~61 ~7 ~15 ~61 ~7 ~16 stone
fill ~70 ~6 ~9 ~70 ~7 ~9 stone
fill ~70 ~7 ~5 ~70 ~7 ~9 stone
fill ~26 ~6 ~9 ~26 ~7 ~9 stone
fill ~26 ~7 ~5 ~26 ~7 ~9 stone
fill ~71 ~7 ~5 ~71 ~7 ~8 stone
fill ~69 ~6 ~8 ~69 ~7 ~8 stone
fill ~69 ~7 ~6 ~69 ~7 ~8 stone
fill ~27 ~6 ~8 ~27 ~7 ~8 stone
fill ~27 ~7 ~6 ~27 ~7 ~8 stone
fill ~25 ~7 ~5 ~25 ~7 ~8 stone
fill ~72 ~4 ~7 ~72 ~7 ~7 stone
fill ~72 ~7 ~5 ~72 ~7 ~7 stone
fill ~68 ~6 ~7 ~68 ~7 ~7 stone
fill ~28 ~6 ~7 ~28 ~7 ~7 stone
fill ~24 ~4 ~7 ~24 ~7 ~7 stone
fill ~24 ~7 ~5 ~24 ~7 ~7 stone
fill ~70 ~6 ~91 ~71 ~6 ~91 stone
fill ~71 ~4 ~91 ~71 ~6 ~91 stone
fill ~24 ~6 ~91 ~25 ~6 ~91 stone
fill ~25 ~2 ~91 ~25 ~6 ~91 stone
fill ~72 ~2 ~90 ~72 ~6 ~90 stone
fill ~72 ~6 ~89 ~72 ~6 ~90 stone
fill ~70 ~3 ~90 ~70 ~6 ~90 stone
fill ~26 ~3 ~90 ~26 ~6 ~90 stone
fill ~26 ~6 ~87 ~26 ~6 ~90 stone
fill ~24 ~4 ~90 ~24 ~6 ~90 stone
fill ~71 ~3 ~89 ~71 ~6 ~89 stone
fill ~68 ~6 ~89 ~69 ~6 ~89 stone
fill ~69 ~4 ~89 ~69 ~6 ~89 stone
fill ~27 ~4 ~89 ~27 ~6 ~89 stone
fill ~27 ~6 ~88 ~27 ~6 ~89 stone
fill ~25 ~3 ~89 ~25 ~6 ~89 stone
fill ~70 ~4 ~88 ~70 ~6 ~88 stone
fill ~70 ~6 ~87 ~70 ~6 ~88 stone
fill ~79 ~6 ~81 ~80 ~6 ~81 stone
fill ~80 ~4 ~81 ~80 ~6 ~81 stone
fill ~15 ~6 ~81 ~16 ~6 ~81 stone
fill ~16 ~2 ~81 ~16 ~6 ~81 stone
fill ~81 ~2 ~80 ~81 ~6 ~80 stone
fill ~81 ~6 ~79 ~81 ~6 ~80 stone
fill ~79 ~3 ~80 ~79 ~6 ~80 stone
fill ~17 ~3 ~80 ~17 ~6 ~80 stone
fill ~17 ~6 ~77 ~17 ~6 ~80 stone
fill ~15 ~4 ~80 ~15 ~6 ~80 stone
fill ~80 ~3 ~79 ~80 ~6 ~79 stone
fill ~77 ~6 ~79 ~78 ~6 ~79 stone
fill ~78 ~4 ~79 ~78 ~6 ~79 stone
fill ~18 ~4 ~79 ~18 ~6 ~79 stone
fill ~18 ~6 ~78 ~18 ~6 ~79 stone
fill ~16 ~3 ~79 ~16 ~6 ~79 stone
fill ~79 ~4 ~78 ~79 ~6 ~78 stone
fill ~79 ~6 ~77 ~79 ~6 ~78 stone
fill ~89 ~6 ~72 ~90 ~6 ~72 stone
fill ~90 ~4 ~72 ~90 ~6 ~72 stone
fill ~5 ~6 ~72 ~6 ~6 ~72 stone
fill ~6 ~2 ~72 ~6 ~6 ~72 stone
fill ~91 ~2 ~71 ~91 ~6 ~71 stone
fill ~91 ~6 ~70 ~91 ~6 ~71 stone
fill ~89 ~3 ~71 ~89 ~6 ~71 stone
fill ~7 ~3 ~71 ~7 ~6 ~71 stone
fill ~7 ~6 ~68 ~7 ~6 ~71 stone
fill ~5 ~4 ~71 ~5 ~6 ~71 stone
fill ~90 ~3 ~70 ~90 ~6 ~70 stone
fill ~87 ~6 ~70 ~88 ~6 ~70 stone
fill ~88 ~4 ~70 ~88 ~6 ~70 stone
fill ~8 ~4 ~70 ~8 ~6 ~70 stone
fill ~8 ~6 ~69 ~8 ~6 ~70 stone
fill ~6 ~3 ~70 ~6 ~6 ~70 stone
fill ~89 ~4 ~69 ~89 ~6 ~69 stone
fill ~89 ~6 ~68 ~89 ~6 ~69 stone
fill ~33 ~6 ~64 ~33 ~6 ~68 stone
fill ~35 ~6 ~67 ~36 ~6 ~67 stone
fill ~36 ~6 ~66 ~36 ~6 ~67 stone
fill ~32 ~6 ~64 ~32 ~6 ~67 stone
fill ~34 ~6 ~66 ~35 ~6 ~66 stone
fill ~35 ~6 ~64 ~35 ~6 ~66 stone
fill ~34 ~0 ~65 ~34 ~6 ~65 stone
fill ~34 ~6 ~63 ~34 ~6 ~65 stone
fill ~64 ~6 ~61 ~64 ~6 ~64 stone
fill ~65 ~1 ~63 ~65 ~6 ~63 stone
fill ~65 ~6 ~61 ~65 ~6 ~63 stone
fill ~66 ~6 ~60 ~66 ~6 ~61 stone
fill ~39 ~6 ~58 ~39 ~6 ~61 stone
fill ~40 ~2 ~60 ~40 ~6 ~60 stone
fill ~40 ~6 ~58 ~40 ~6 ~60 stone
fill ~36 ~6 ~39 ~36 ~6 ~43 stone
fill ~35 ~6 ~39 ~35 ~6 ~42 stone
fill ~34 ~6 ~40 ~34 ~6 ~41 stone
fill ~59 ~6 ~38 ~59 ~6 ~40 stone
fill ~37 ~3 ~39 ~37 ~6 ~39 stone
fill ~37 ~6 ~38 ~37 ~6 ~39 stone
fill ~30 ~6 ~35 ~32 ~6 ~35 stone
fill ~32 ~5 ~35 ~32 ~6 ~35 stone
fill ~32 ~6 ~34 ~32 ~6 ~35 stone
fill ~29 ~6 ~34 ~30 ~6 ~34 stone
fill ~30 ~3 ~34 ~30 ~6 ~34 stone
fill ~30 ~6 ~31 ~30 ~6 ~34 stone
fill ~28 ~6 ~33 ~29 ~6 ~33 stone
fill ~29 ~6 ~32 ~29 ~6 ~33 stone
fill ~89 ~4 ~27 ~89 ~6 ~27 stone
fill ~89 ~6 ~24 ~89 ~6 ~27 stone
fill ~68 ~6 ~27 ~69 ~6 ~27 stone
fill ~69 ~4 ~27 ~69 ~6 ~27 stone
fill ~27 ~6 ~27 ~28 ~6 ~27 stone
fill ~28 ~5 ~27 ~28 ~6 ~27 stone
fill ~7 ~4 ~27 ~7 ~6 ~27 stone
fill ~7 ~6 ~24 ~7 ~6 ~27 stone
fill ~90 ~3 ~26 ~90 ~6 ~26 stone
fill ~90 ~6 ~24 ~90 ~6 ~26 stone
fill ~88 ~4 ~26 ~88 ~6 ~26 stone
fill ~8 ~4 ~26 ~8 ~6 ~26 stone
fill ~6 ~3 ~26 ~6 ~6 ~26 stone
fill ~6 ~6 ~24 ~6 ~6 ~26 stone
fill ~91 ~4 ~25 ~91 ~6 ~25 stone
fill ~91 ~6 ~24 ~91 ~6 ~25 stone
fill ~5 ~2 ~25 ~5 ~6 ~25 stone
fill ~5 ~6 ~24 ~5 ~6 ~25 stone
fill ~79 ~4 ~18 ~79 ~6 ~18 stone
fill ~79 ~6 ~15 ~79 ~6 ~18 stone
fill ~17 ~4 ~18 ~17 ~6 ~18 stone
fill ~17 ~6 ~15 ~17 ~6 ~18 stone
fill ~80 ~3 ~17 ~80 ~6 ~17 stone
fill ~80 ~6 ~15 ~80 ~6 ~17 stone
fill ~78 ~4 ~17 ~78 ~6 ~17 stone
fill ~18 ~4 ~17 ~18 ~6 ~17 stone
fill ~16 ~3 ~17 ~16 ~6 ~17 stone
fill ~16 ~6 ~15 ~16 ~6 ~17 stone
fill ~81 ~4 ~16 ~81 ~6 ~16 stone
fill ~81 ~6 ~15 ~81 ~6 ~16 stone
fill ~35 ~3 ~16 ~35 ~6 ~16 stone
fill ~15 ~2 ~16 ~15 ~6 ~16 stone
fill ~15 ~6 ~15 ~15 ~6 ~16 stone
fill ~70 ~4 ~8 ~70 ~6 ~8 stone
fill ~70 ~6 ~5 ~70 ~6 ~8 stone
fill ~26 ~4 ~8 ~26 ~6 ~8 stone
fill ~26 ~6 ~5 ~26 ~6 ~8 stone
fill ~71 ~3 ~7 ~71 ~6 ~7 stone
fill ~71 ~6 ~5 ~71 ~6 ~7 stone
fill ~69 ~4 ~7 ~69 ~6 ~7 stone
fill ~27 ~4 ~7 ~27 ~6 ~7 stone
fill ~25 ~3 ~7 ~25 ~6 ~7 stone
fill ~25 ~6 ~5 ~25 ~6 ~7 stone
fill ~72 ~4 ~6 ~72 ~6 ~6 stone
fill ~72 ~6 ~5 ~72 ~6 ~6 stone
fill ~24 ~2 ~6 ~24 ~6 ~6 stone
fill ~24 ~6 ~5 ~24 ~6 ~6 stone
fill ~70 ~4 ~91 ~70 ~5 ~91 stone
fill ~72 ~4 ~89 ~72 ~5 ~89 stone
fill ~26 ~2 ~89 ~26 ~5 ~89 stone
fill ~26 ~5 ~88 ~26 ~5 ~89 stone
fill ~79 ~4 ~81 ~79 ~5 ~81 stone
fill ~81 ~4 ~79 ~81 ~5 ~79 stone
fill ~17 ~2 ~79 ~17 ~5 ~79 stone
fill ~17 ~5 ~78 ~17 ~5 ~79 stone
fill ~89 ~4 ~72 ~89 ~5 ~72 stone
fill ~91 ~4 ~70 ~91 ~5 ~70 stone
fill ~7 ~2 ~70 ~7 ~5 ~70 stone
fill ~7 ~5 ~69 ~7 ~5 ~70 stone
fill ~33 ~5 ~66 ~34 ~5 ~66 stone
fill ~34 ~3 ~66 ~34 ~5 ~66 stone
fill ~35 ~4 ~65 ~35 ~5 ~65 stone
fill ~35 ~5 ~64 ~35 ~5 ~65 stone
fill ~32 ~5 ~65 ~33 ~5 ~65 stone
fill ~33 ~1 ~65 ~33 ~5 ~65 stone
fill ~33 ~5 ~64 ~33 ~5 ~65 stone
fill ~34 ~3 ~64 ~34 ~5 ~64 stone
fill ~64 ~5 ~61 ~64 ~5 ~63 stone
fill ~65 ~0 ~62 ~65 ~5 ~62 stone
fill ~65 ~5 ~61 ~65 ~5 ~62 stone
fill ~39 ~1 ~60 ~39 ~5 ~60 stone
fill ~39 ~5 ~58 ~39 ~5 ~60 stone
fill ~40 ~4 ~59 ~40 ~5 ~59 stone
fill ~36 ~5 ~39 ~36 ~5 ~41 stone
fill ~31 ~4 ~35 ~31 ~5 ~35 stone
fill ~32 ~3 ~34 ~32 ~5 ~34 stone
fill ~30 ~4 ~33 ~30 ~5 ~33 stone
fill ~27 ~4 ~27 ~27 ~5 ~27 stone
fill ~89 ~2 ~26 ~89 ~5 ~26 stone
fill ~89 ~5 ~24 ~89 ~5 ~26 stone
fill ~7 ~2 ~26 ~7 ~5 ~26 stone
fill ~7 ~5 ~24 ~7 ~5 ~26 stone
fill ~90 ~0 ~25 ~90 ~5 ~25 stone
fill ~90 ~5 ~24 ~90 ~5 ~25 stone
fill ~6 ~0 ~25 ~6 ~5 ~25 stone
fill ~6 ~5 ~24 ~6 ~5 ~25 stone
fill ~79 ~2 ~17 ~79 ~5 ~17 stone
fill ~79 ~5 ~15 ~79 ~5 ~17 stone
fill ~17 ~2 ~17 ~17 ~5 ~17 stone
fill ~17 ~5 ~15 ~17 ~5 ~17 stone
fill ~80 ~0 ~16 ~80 ~5 ~16 stone
fill ~80 ~5 ~15 ~80 ~5 ~16 stone
fill ~16 ~0 ~16 ~16 ~5 ~16 stone
fill ~16 ~5 ~15 ~16 ~5 ~16 stone
fill ~70 ~2 ~7 ~70 ~5 ~7 stone
fill ~70 ~5 ~5 ~70 ~5 ~7 stone
fill ~26 ~2 ~7 ~26 ~5 ~7 stone
fill ~26 ~5 ~5 ~26 ~5 ~7 stone
fill ~71 ~0 ~6 ~71 ~5 ~6 stone
fill ~71 ~5 ~5 ~71 ~5 ~6 stone
fill ~25 ~0 ~6 ~25 ~5 ~6 stone
fill ~25 ~5 ~5 ~25 ~5 ~6 stone
fill ~64 ~3 ~62 ~64 ~4 ~62 stone
fill ~39 ~3 ~59 ~39 ~4 ~59 stone
fill ~36 ~2 ~40 ~36 ~4 ~40 stone
fill ~36 ~4 ~39 ~36 ~4 ~40 stone
fill ~89 ~3 ~25 ~89 ~4 ~25 stone
fill ~89 ~4 ~24 ~89 ~4 ~25 stone
fill ~7 ~3 ~25 ~7 ~4 ~25 stone
fill ~7 ~4 ~24 ~7 ~4 ~25 stone
fill ~90 ~2 ~24 ~90 ~4 ~24 stone
fill ~79 ~3 ~16 ~79 ~4 ~16 stone
fill ~79 ~4 ~15 ~79 ~4 ~16 stone
fill ~17 ~3 ~16 ~17 ~4 ~16 stone
fill ~17 ~4 ~15 ~17 ~4 ~16 stone
fill ~80 ~2 ~15 ~80 ~4 ~15 stone
fill ~70 ~3 ~6 ~70 ~4 ~6 stone
fill ~70 ~4 ~5 ~70 ~4 ~6 stone
fill ~26 ~3 ~6 ~26 ~4 ~6 stone
fill ~26 ~4 ~5 ~26 ~4 ~6 stone
fill ~71 ~2 ~5 ~71 ~4 ~5 stone
fill ~36 ~1 ~39 ~36 ~3 ~39 stone
