#Function file to spawn structure entangled
gamerule commandBlockOutput false
fill ~1 ~81 ~1 ~162 ~81 ~161 air
fill ~162 ~81 ~1 ~323 ~81 ~161 air
fill ~1 ~80 ~1 ~162 ~80 ~161 air
fill ~162 ~80 ~1 ~323 ~80 ~161 air
fill ~1 ~79 ~1 ~162 ~79 ~161 air
fill ~162 ~79 ~1 ~323 ~79 ~161 air
fill ~1 ~78 ~1 ~162 ~78 ~161 air
fill ~162 ~78 ~1 ~323 ~78 ~161 air
fill ~1 ~77 ~1 ~162 ~77 ~161 air
fill ~162 ~77 ~1 ~323 ~77 ~161 air
fill ~1 ~76 ~1 ~162 ~76 ~161 air
fill ~162 ~76 ~1 ~323 ~76 ~161 air
fill ~1 ~75 ~1 ~162 ~75 ~161 air
fill ~162 ~75 ~1 ~323 ~75 ~161 air
fill ~1 ~74 ~1 ~162 ~74 ~161 air
fill ~162 ~74 ~1 ~323 ~74 ~161 air
fill ~1 ~73 ~1 ~162 ~73 ~161 air
fill ~162 ~73 ~1 ~323 ~73 ~161 air
fill ~1 ~72 ~1 ~162 ~72 ~161 air
fill ~162 ~72 ~1 ~323 ~72 ~161 air
fill ~1 ~71 ~1 ~162 ~71 ~161 air
fill ~162 ~71 ~1 ~323 ~71 ~161 air
fill ~1 ~70 ~1 ~162 ~70 ~161 air
fill ~162 ~70 ~1 ~323 ~70 ~161 air
fill ~1 ~69 ~1 ~162 ~69 ~161 air
fill ~162 ~69 ~1 ~323 ~69 ~161 air
fill ~1 ~68 ~1 ~162 ~68 ~161 air
fill ~162 ~68 ~1 ~323 ~68 ~161 air
fill ~1 ~67 ~1 ~162 ~67 ~161 air
fill ~162 ~67 ~1 ~323 ~67 ~161 air
fill ~1 ~66 ~1 ~162 ~66 ~161 air
fill ~162 ~66 ~1 ~323 ~66 ~161 air
fill ~1 ~65 ~1 ~162 ~65 ~161 air
fill ~162 ~65 ~1 ~323 ~65 ~161 air
fill ~1 ~64 ~1 ~162 ~64 ~161 air
fill ~162 ~64 ~1 ~323 ~64 ~161 air
fill ~1 ~63 ~1 ~162 ~63 ~161 air
fill ~162 ~63 ~1 ~323 ~63 ~161 air
fill ~1 ~62 ~1 ~162 ~62 ~161 air
fill ~162 ~62 ~1 ~323 ~62 ~161 air
fill ~1 ~61 ~1 ~162 ~61 ~161 air
fill ~162 ~61 ~1 ~323 ~61 ~161 air
fill ~1 ~60 ~1 ~162 ~60 ~161 air
fill ~162 ~60 ~1 ~323 ~60 ~161 air
fill ~1 ~59 ~1 ~162 ~59 ~161 air
fill ~162 ~59 ~1 ~323 ~59 ~161 air
fill ~1 ~58 ~1 ~162 ~58 ~161 air
fill ~162 ~58 ~1 ~323 ~58 ~161 air
fill ~1 ~57 ~1 ~162 ~57 ~161 air
fill ~162 ~57 ~1 ~323 ~57 ~161 air
fill ~1 ~56 ~1 ~162 ~56 ~161 air
fill ~162 ~56 ~1 ~323 ~56 ~161 air
fill ~1 ~55 ~1 ~162 ~55 ~161 air
fill ~162 ~55 ~1 ~323 ~55 ~161 air
fill ~1 ~54 ~1 ~162 ~54 ~161 air
fill ~162 ~54 ~1 ~323 ~54 ~161 air
fill ~1 ~53 ~1 ~162 ~53 ~161 air
fill ~162 ~53 ~1 ~323 ~53 ~161 air
fill ~1 ~52 ~1 ~162 ~52 ~161 air
fill ~162 ~52 ~1 ~323 ~52 ~161 air
fill ~1 ~51 ~1 ~162 ~51 ~161 air
fill ~162 ~51 ~1 ~323 ~51 ~161 air
fill ~1 ~50 ~1 ~162 ~50 ~161 air
fill ~162 ~50 ~1 ~323 ~50 ~161 air
fill ~1 ~49 ~1 ~162 ~49 ~161 air
fill ~162 ~49 ~1 ~323 ~49 ~161 air
fill ~1 ~48 ~1 ~162 ~48 ~161 air
fill ~162 ~48 ~1 ~323 ~48 ~161 air
fill ~1 ~47 ~1 ~162 ~47 ~161 air
fill ~162 ~47 ~1 ~323 ~47 ~161 air
fill ~1 ~46 ~1 ~162 ~46 ~161 air
fill ~162 ~46 ~1 ~323 ~46 ~161 air
fill ~1 ~45 ~1 ~162 ~45 ~161 air
fill ~162 ~45 ~1 ~323 ~45 ~161 air
fill ~1 ~44 ~1 ~162 ~44 ~161 air
fill ~162 ~44 ~1 ~323 ~44 ~161 air
fill ~1 ~43 ~1 ~162 ~43 ~161 air
fill ~162 ~43 ~1 ~323 ~43 ~161 air
fill ~1 ~42 ~1 ~162 ~42 ~161 air
fill ~162 ~42 ~1 ~323 ~42 ~161 air
fill ~1 ~41 ~1 ~162 ~41 ~161 air
fill ~162 ~41 ~1 ~323 ~41 ~161 air
fill ~1 ~40 ~1 ~162 ~40 ~161 air
fill ~162 ~40 ~1 ~323 ~40 ~161 air
fill ~1 ~39 ~1 ~162 ~39 ~161 air
fill ~162 ~39 ~1 ~323 ~39 ~161 air
fill ~1 ~38 ~1 ~162 ~38 ~161 air
fill ~162 ~38 ~1 ~323 ~38 ~161 air
fill ~1 ~37 ~1 ~162 ~37 ~161 air
fill ~162 ~37 ~1 ~323 ~37 ~161 air
fill ~1 ~36 ~1 ~162 ~36 ~161 air
fill ~162 ~36 ~1 ~323 ~36 ~161 air
fill ~1 ~35 ~1 ~162 ~35 ~161 air
fill ~162 ~35 ~1 ~323 ~35 ~161 air
fill ~1 ~34 ~1 ~162 ~34 ~161 air
fill ~162 ~34 ~1 ~323 ~34 ~161 air
fill ~1 ~33 ~1 ~162 ~33 ~161 air
fill ~162 ~33 ~1 ~323 ~33 ~161 air
fill ~1 ~32 ~1 ~162 ~32 ~161 air
fill ~162 ~32 ~1 ~323 ~32 ~161 air
fill ~1 ~31 ~1 ~162 ~31 ~161 air
fill ~162 ~31 ~1 ~323 ~31 ~161 air
fill ~1 ~30 ~1 ~162 ~30 ~161 air
fill ~162 ~30 ~1 ~323 ~30 ~161 air
fill ~1 ~29 ~1 ~162 ~29 ~161 air
fill ~162 ~29 ~1 ~323 ~29 ~161 air
fill ~1 ~28 ~1 ~162 ~28 ~161 air
fill ~162 ~28 ~1 ~323 ~28 ~161 air
fill ~1 ~27 ~1 ~162 ~27 ~161 air
fill ~162 ~27 ~1 ~323 ~27 ~161 air
fill ~1 ~26 ~1 ~162 ~26 ~161 air
fill ~162 ~26 ~1 ~323 ~26 ~161 air
fill ~1 ~25 ~1 ~162 ~25 ~161 air
fill ~162 ~25 ~1 ~323 ~25 ~161 air
fill ~1 ~24 ~1 ~162 ~24 ~161 air
fill ~162 ~24 ~1 ~323 ~24 ~161 air
fill ~1 ~23 ~1 ~162 ~23 ~161 air
fill ~162 ~23 ~1 ~323 ~23 ~161 air
fill ~1 ~22 ~1 ~162 ~22 ~161 air
fill ~162 ~22 ~1 ~323 ~22 ~161 air
fill ~1 ~21 ~1 ~162 ~21 ~161 air
fill ~162 ~21 ~1 ~323 ~21 ~161 air
fill ~1 ~20 ~1 ~162 ~20 ~161 air
fill ~162 ~20 ~1 ~323 ~20 ~161 air
fill ~1 ~19 ~1 ~162 ~19 ~161 air
fill ~162 ~19 ~1 ~323 ~19 ~161 air
fill ~1 ~18 ~1 ~162 ~18 ~161 air
fill ~162 ~18 ~1 ~323 ~18 ~161 air
fill ~1 ~17 ~1 ~162 ~17 ~161 air
fill ~162 ~17 ~1 ~323 ~17 ~161 air
fill ~1 ~16 ~1 ~162 ~16 ~161 air
fill ~162 ~16 ~1 ~323 ~16 ~161 air
fill ~1 ~15 ~1 ~162 ~15 ~161 air
fill ~162 ~15 ~1 ~323 ~15 ~161 air
fill ~1 ~14 ~1 ~162 ~14 ~161 air
fill ~162 ~14 ~1 ~323 ~14 ~161 air
fill ~1 ~13 ~1 ~162 ~13 ~161 air
fill ~162 ~13 ~1 ~323 ~13 ~161 air
fill ~1 ~12 ~1 ~162 ~12 ~161 air
fill ~162 ~12 ~1 ~323 ~12 ~161 air
fill ~1 ~11 ~1 ~162 ~11 ~161 air
fill ~162 ~11 ~1 ~323 ~11 ~161 air
fill ~1 ~10 ~1 ~162 ~10 ~161 air
fill ~162 ~10 ~1 ~323 ~10 ~161 air
fill ~1 ~9 ~1 ~162 ~9 ~161 air
fill ~162 ~9 ~1 ~323 ~9 ~161 air
fill ~1 ~8 ~1 ~162 ~8 ~161 air
fill ~162 ~8 ~1 ~323 ~8 ~161 air
fill ~1 ~7 ~1 ~162 ~7 ~161 air
fill ~162 ~7 ~1 ~323 ~7 ~161 air
fill ~1 ~6 ~1 ~162 ~6 ~161 air
fill ~162 ~6 ~1 ~323 ~6 ~161 air
fill ~1 ~5 ~1 ~162 ~5 ~161 air
fill ~162 ~5 ~1 ~323 ~5 ~161 air
fill ~1 ~4 ~1 ~162 ~4 ~161 air
fill ~162 ~4 ~1 ~323 ~4 ~161 air
fill ~1 ~3 ~1 ~162 ~3 ~161 air
fill ~162 ~3 ~1 ~323 ~3 ~161 air
fill ~1 ~2 ~1 ~162 ~2 ~161 air
fill ~162 ~2 ~1 ~323 ~2 ~161 air
fill ~1 ~1 ~1 ~162 ~1 ~161 air
fill ~162 ~1 ~1 ~323 ~1 ~161 air
fill ~1 ~0 ~1 ~162 ~0 ~161 air
fill ~162 ~0 ~1 ~323 ~0 ~161 air
fill ~82 ~0 ~82 ~82 ~54 ~82 stone
fill ~82 ~3 ~81 ~82 ~54 ~82 stone
fill ~83 ~3 ~82 ~83 ~54 ~82 stone
fill ~82 ~4 ~80 ~82 ~54 ~83 stone
fill ~81 ~4 ~81 ~82 ~5 ~82 stone
fill ~83 ~5 ~81 ~83 ~54 ~82 stone
fill ~83 ~6 ~80 ~83 ~54 ~82 stone
fill ~81 ~6 ~82 ~83 ~54 ~82 stone
fill ~82 ~7 ~79 ~82 ~54 ~83 stone
fill ~81 ~7 ~80 ~83 ~54 ~83 stone
fill ~83 ~8 ~79 ~83 ~54 ~83 stone
fill ~84 ~8 ~80 ~84 ~54 ~82 stone
fill ~85 ~8 ~81 ~85 ~54 ~81 stone
fill ~82 ~10 ~78 ~82 ~54 ~83 stone
fill ~81 ~10 ~79 ~83 ~54 ~83 stone
fill ~84 ~11 ~79 ~84 ~54 ~82 stone
fill ~85 ~11 ~82 ~85 ~54 ~82 stone
fill ~83 ~12 ~78 ~83 ~54 ~83 stone
fill ~80 ~12 ~79 ~84 ~54 ~80 stone
fill ~85 ~12 ~80 ~85 ~46 ~82 stone
fill ~86 ~12 ~80 ~86 ~46 ~80 stone
fill ~84 ~12 ~83 ~84 ~55 ~83 stone
fill ~81 ~13 ~78 ~83 ~54 ~83 stone
fill ~80 ~13 ~81 ~86 ~54 ~81 stone
fill ~86 ~13 ~82 ~86 ~54 ~82 stone
fill ~85 ~13 ~83 ~85 ~15 ~83 stone
fill ~80 ~14 ~78 ~84 ~54 ~82 stone
fill ~79 ~14 ~79 ~86 ~46 ~80 stone
fill ~86 ~14 ~83 ~86 ~15 ~83 stone
fill ~82 ~15 ~76 ~82 ~54 ~83 stone
fill ~81 ~15 ~77 ~83 ~46 ~83 stone
fill ~85 ~15 ~78 ~85 ~15 ~83 stone
fill ~79 ~15 ~81 ~87 ~54 ~81 stone
fill ~82 ~15 ~84 ~83 ~15 ~84 stone
fill ~81 ~16 ~76 ~83 ~46 ~83 stone
fill ~79 ~16 ~82 ~86 ~54 ~82 stone
fill ~80 ~16 ~83 ~84 ~54 ~83 stone
fill ~83 ~16 ~84 ~83 ~55 ~84 stone
fill ~82 ~17 ~75 ~82 ~54 ~84 stone
fill ~80 ~17 ~77 ~85 ~46 ~83 stone
fill ~79 ~17 ~78 ~84 ~54 ~82 stone
fill ~81 ~17 ~84 ~84 ~54 ~84 stone
fill ~80 ~18 ~76 ~84 ~46 ~83 stone
fill ~78 ~18 ~78 ~86 ~18 ~82 stone
fill ~87 ~18 ~79 ~87 ~20 ~82 stone
fill ~79 ~18 ~83 ~86 ~54 ~83 stone
fill ~85 ~18 ~84 ~86 ~55 ~84 stone
fill ~81 ~18 ~85 ~81 ~54 ~85 stone
fill ~83 ~18 ~85 ~84 ~46 ~85 stone
fill ~81 ~19 ~75 ~82 ~46 ~85 stone
fill ~79 ~19 ~76 ~85 ~46 ~83 stone
fill ~86 ~19 ~77 ~86 ~46 ~84 stone
fill ~78 ~19 ~79 ~84 ~54 ~82 stone
fill ~88 ~19 ~80 ~88 ~21 ~82 stone
fill ~87 ~19 ~83 ~87 ~21 ~83 stone
fill ~80 ~19 ~84 ~86 ~54 ~84 stone
fill ~80 ~19 ~85 ~81 ~54 ~85 stone
setblock ~85 ~19 ~85 stone
fill ~82 ~19 ~86 ~82 ~46 ~86 stone
fill ~82 ~20 ~74 ~82 ~54 ~84 stone
fill ~83 ~20 ~75 ~83 ~46 ~86 stone
fill ~78 ~20 ~77 ~86 ~20 ~82 stone
fill ~77 ~20 ~80 ~87 ~46 ~82 stone
fill ~81 ~20 ~86 ~84 ~46 ~86 stone
fill ~80 ~21 ~75 ~84 ~46 ~86 stone
fill ~78 ~21 ~78 ~84 ~54 ~83 stone
fill ~76 ~21 ~81 ~88 ~54 ~81 stone
fill ~79 ~21 ~84 ~86 ~54 ~84 stone
fill ~85 ~21 ~85 ~85 ~47 ~85 stone
fill ~81 ~21 ~87 ~83 ~54 ~87 stone
fill ~81 ~22 ~74 ~82 ~46 ~87 stone
fill ~78 ~22 ~77 ~86 ~46 ~84 stone
fill ~87 ~22 ~78 ~87 ~54 ~82 stone
fill ~77 ~22 ~83 ~86 ~46 ~83 stone
fill ~79 ~22 ~85 ~85 ~46 ~85 stone
fill ~83 ~23 ~74 ~83 ~46 ~87 stone
fill ~86 ~23 ~76 ~86 ~55 ~77 stone
fill ~87 ~23 ~77 ~87 ~54 ~83 stone
fill ~77 ~23 ~78 ~87 ~46 ~83 stone
fill ~76 ~23 ~80 ~87 ~46 ~82 stone
setblock ~86 ~23 ~85 stone
fill ~80 ~24 ~74 ~83 ~46 ~87 stone
fill ~85 ~24 ~75 ~85 ~46 ~86 stone
fill ~78 ~24 ~76 ~86 ~46 ~84 stone
fill ~87 ~24 ~76 ~87 ~26 ~83 stone
fill ~77 ~24 ~77 ~87 ~46 ~83 stone
fill ~88 ~24 ~77 ~88 ~26 ~77 stone
setblock ~88 ~24 ~78 stone
fill ~76 ~24 ~79 ~87 ~46 ~83 stone
fill ~75 ~24 ~80 ~84 ~54 ~81 stone
fill ~88 ~24 ~80 ~88 ~26 ~81 stone
setblock ~88 ~24 ~82 stone
fill ~84 ~24 ~87 ~84 ~55 ~87 stone
fill ~82 ~24 ~88 ~83 ~54 ~88 stone
fill ~84 ~25 ~74 ~84 ~46 ~87 stone
fill ~79 ~25 ~75 ~85 ~46 ~86 stone
fill ~77 ~25 ~76 ~86 ~46 ~84 stone
fill ~75 ~25 ~82 ~87 ~46 ~82 stone
fill ~78 ~25 ~85 ~86 ~46 ~85 stone
fill ~86 ~25 ~86 ~86 ~55 ~86 stone
fill ~85 ~25 ~87 ~85 ~55 ~87 stone
fill ~81 ~26 ~73 ~83 ~46 ~88 stone
fill ~78 ~26 ~75 ~85 ~46 ~86 stone
fill ~76 ~26 ~78 ~86 ~46 ~84 stone
fill ~88 ~26 ~78 ~88 ~55 ~78 stone
fill ~75 ~26 ~79 ~87 ~46 ~82 stone
fill ~74 ~26 ~80 ~84 ~54 ~80 stone
fill ~88 ~26 ~82 ~88 ~54 ~82 stone
fill ~77 ~26 ~85 ~86 ~46 ~85 stone
fill ~79 ~26 ~87 ~79 ~55 ~87 stone
setblock ~86 ~26 ~87 stone
setblock ~85 ~26 ~88 stone
fill ~82 ~27 ~72 ~83 ~54 ~84 stone
fill ~84 ~27 ~73 ~84 ~55 ~74 stone
fill ~79 ~27 ~74 ~84 ~46 ~87 stone
fill ~77 ~27 ~75 ~85 ~46 ~86 stone
fill ~76 ~27 ~77 ~87 ~46 ~85 stone
fill ~75 ~27 ~78 ~87 ~46 ~84 stone
fill ~74 ~27 ~79 ~84 ~54 ~81 stone
fill ~88 ~27 ~79 ~88 ~55 ~79 stone
fill ~73 ~27 ~80 ~84 ~54 ~80 stone
fill ~80 ~27 ~88 ~83 ~54 ~88 stone
setblock ~84 ~27 ~88 stone
fill ~81 ~27 ~89 ~83 ~54 ~89 stone
fill ~80 ~28 ~44 ~80 ~55 ~44 stone
fill ~85 ~28 ~74 ~85 ~46 ~87 stone
fill ~76 ~28 ~76 ~86 ~46 ~86 stone
fill ~75 ~28 ~77 ~87 ~46 ~84 stone
fill ~74 ~28 ~78 ~88 ~28 ~82 stone
fill ~89 ~28 ~78 ~89 ~55 ~79 stone
fill ~118 ~28 ~80 ~118 ~55 ~80 stone
fill ~44 ~28 ~82 ~44 ~55 ~82 stone
setblock ~89 ~28 ~82 stone
fill ~88 ~28 ~83 ~88 ~55 ~83 stone
fill ~87 ~28 ~86 ~87 ~55 ~86 stone
fill ~77 ~28 ~87 ~85 ~28 ~87 stone
fill ~82 ~28 ~118 ~82 ~55 ~118 stone
fill ~104 ~29 ~56 ~104 ~30 ~56 stone
fill ~56 ~29 ~58 ~56 ~30 ~58 stone
fill ~80 ~29 ~58 ~80 ~55 ~58 stone
fill ~76 ~29 ~75 ~86 ~29 ~86 stone
fill ~87 ~29 ~76 ~87 ~47 ~87 stone
fill ~88 ~29 ~77 ~88 ~54 ~86 stone
fill ~73 ~29 ~79 ~84 ~54 ~81 stone
fill ~90 ~29 ~79 ~90 ~55 ~79 stone
fill ~89 ~29 ~80 ~89 ~54 ~81 stone
fill ~104 ~29 ~80 ~104 ~55 ~80 stone
fill ~58 ~29 ~82 ~58 ~55 ~82 stone
fill ~74 ~29 ~82 ~88 ~46 ~82 stone
fill ~75 ~29 ~85 ~88 ~46 ~86 stone
fill ~78 ~29 ~87 ~87 ~47 ~87 stone
fill ~79 ~29 ~88 ~85 ~54 ~88 stone
fill ~80 ~29 ~89 ~85 ~54 ~89 stone
fill ~81 ~29 ~90 ~81 ~55 ~90 stone
fill ~83 ~29 ~90 ~84 ~55 ~90 stone
setblock ~85 ~29 ~90 stone
fill ~82 ~29 ~104 ~82 ~55 ~104 stone
fill ~106 ~29 ~104 ~106 ~30 ~104 stone
fill ~58 ~29 ~106 ~58 ~30 ~106 stone
fill ~81 ~30 ~44 ~81 ~55 ~44 stone
fill ~81 ~30 ~72 ~83 ~46 ~90 stone
fill ~78 ~30 ~74 ~85 ~46 ~88 stone
fill ~86 ~30 ~75 ~86 ~46 ~88 stone
fill ~89 ~30 ~77 ~89 ~54 ~83 stone
fill ~74 ~30 ~78 ~89 ~46 ~83 stone
fill ~44 ~30 ~81 ~44 ~55 ~82 stone
setblock ~90 ~30 ~81 stone
fill ~118 ~30 ~81 ~118 ~55 ~81 stone
fill ~73 ~30 ~82 ~89 ~46 ~82 stone
fill ~76 ~30 ~87 ~87 ~47 ~87 stone
fill ~87 ~30 ~88 ~87 ~55 ~88 stone
fill ~79 ~30 ~89 ~85 ~54 ~89 stone
fill ~80 ~30 ~90 ~84 ~54 ~90 stone
fill ~82 ~30 ~91 ~82 ~32 ~91 stone
fill ~81 ~30 ~118 ~82 ~55 ~118 stone
fill ~81 ~31 ~32 ~81 ~55 ~32 stone
fill ~81 ~31 ~43 ~81 ~55 ~44 stone
fill ~104 ~31 ~56 ~104 ~33 ~56 sandstone
fill ~56 ~31 ~58 ~56 ~33 ~58 sandstone
fill ~81 ~31 ~58 ~81 ~56 ~58 stone
fill ~76 ~31 ~75 ~86 ~46 ~87 stone
fill ~75 ~31 ~76 ~87 ~46 ~86 stone
fill ~90 ~31 ~80 ~90 ~40 ~80 stone
fill ~32 ~31 ~81 ~32 ~55 ~81 stone
fill ~43 ~31 ~81 ~44 ~55 ~81 stone
fill ~58 ~31 ~81 ~58 ~55 ~82 stone
fill ~104 ~31 ~81 ~104 ~56 ~81 stone
fill ~119 ~31 ~81 ~119 ~55 ~81 stone
fill ~130 ~31 ~81 ~130 ~55 ~81 stone
fill ~90 ~31 ~82 ~90 ~54 ~83 stone
fill ~73 ~31 ~83 ~90 ~46 ~83 stone
fill ~74 ~31 ~84 ~89 ~46 ~84 stone
fill ~88 ~31 ~87 ~88 ~55 ~87 stone
fill ~77 ~31 ~88 ~87 ~54 ~88 stone
fill ~78 ~31 ~89 ~86 ~54 ~89 stone
fill ~79 ~31 ~90 ~84 ~54 ~90 stone
fill ~80 ~31 ~91 ~82 ~32 ~91 stone
fill ~81 ~31 ~104 ~82 ~55 ~104 stone
fill ~106 ~31 ~104 ~106 ~33 ~104 sandstone
fill ~58 ~31 ~106 ~58 ~33 ~106 sandstone
fill ~81 ~31 ~119 ~81 ~55 ~119 stone
fill ~81 ~31 ~130 ~81 ~55 ~130 stone
fill ~80 ~32 ~43 ~81 ~55 ~44 stone
fill ~79 ~32 ~44 ~82 ~55 ~44 stone
setblock ~103 ~32 ~56 end_stone
fill ~104 ~32 ~57 ~104 ~36 ~57 end_stone
fill ~57 ~32 ~58 ~57 ~36 ~58 end_stone
setblock ~56 ~32 ~59 end_stone
fill ~80 ~32 ~59 ~80 ~55 ~59 stone
fill ~81 ~32 ~71 ~81 ~46 ~91 stone
fill ~82 ~32 ~71 ~83 ~34 ~90 stone
fill ~80 ~32 ~72 ~83 ~46 ~90 stone
fill ~76 ~32 ~74 ~86 ~32 ~88 stone
fill ~75 ~32 ~75 ~87 ~46 ~86 stone
fill ~73 ~32 ~78 ~89 ~46 ~84 stone
fill ~72 ~32 ~79 ~84 ~54 ~81 stone
fill ~118 ~32 ~79 ~118 ~55 ~82 stone
fill ~44 ~32 ~80 ~44 ~55 ~83 stone
fill ~103 ~32 ~80 ~104 ~55 ~80 stone
fill ~119 ~32 ~80 ~119 ~55 ~81 stone
fill ~90 ~32 ~81 ~90 ~54 ~83 stone
fill ~43 ~32 ~82 ~44 ~55 ~82 stone
fill ~59 ~32 ~82 ~59 ~55 ~82 stone
fill ~87 ~32 ~89 ~87 ~55 ~89 stone
fill ~85 ~32 ~90 ~86 ~55 ~90 stone
fill ~82 ~32 ~103 ~82 ~55 ~104 stone
setblock ~106 ~32 ~103 end_stone
fill ~105 ~32 ~104 ~105 ~36 ~104 end_stone
fill ~58 ~32 ~105 ~58 ~36 ~105 end_stone
setblock ~59 ~32 ~106 end_stone
fill ~80 ~32 ~118 ~83 ~55 ~118 stone
fill ~82 ~32 ~119 ~82 ~55 ~119 stone
fill ~103 ~33 ~56 ~105 ~33 ~56 sandstone
fill ~56 ~33 ~57 ~56 ~33 ~59 sandstone
fill ~103 ~33 ~57 ~104 ~33 ~57 end_stone
fill ~79 ~33 ~58 ~80 ~55 ~59 stone
setblock ~57 ~33 ~59 end_stone
fill ~80 ~33 ~71 ~82 ~35 ~90 stone
fill ~79 ~33 ~72 ~83 ~46 ~90 stone
fill ~85 ~33 ~73 ~85 ~46 ~90 stone
fill ~77 ~33 ~74 ~86 ~46 ~89 stone
fill ~88 ~33 ~76 ~88 ~54 ~87 stone
fill ~90 ~33 ~78 ~90 ~40 ~83 stone
fill ~103 ~33 ~79 ~104 ~55 ~80 stone
fill ~58 ~33 ~83 ~59 ~55 ~83 stone
fill ~74 ~33 ~85 ~89 ~46 ~85 stone
fill ~75 ~33 ~87 ~88 ~47 ~87 stone
fill ~78 ~33 ~90 ~86 ~54 ~90 stone
fill ~83 ~33 ~103 ~83 ~55 ~104 stone
fill ~105 ~33 ~103 ~105 ~33 ~104 end_stone
fill ~106 ~33 ~103 ~106 ~33 ~105 sandstone
setblock ~59 ~33 ~105 end_stone
fill ~57 ~33 ~106 ~59 ~33 ~106 sandstone
fill ~81 ~34 ~31 ~81 ~54 ~32 stone
fill ~80 ~34 ~42 ~81 ~55 ~45 stone
fill ~79 ~34 ~43 ~82 ~55 ~44 stone
fill ~103 ~34 ~55 ~103 ~36 ~55 end_stone
setblock ~104 ~34 ~55 sandstone
fill ~103 ~34 ~56 ~104 ~34 ~56 end_stone
fill ~105 ~34 ~56 ~105 ~34 ~57 sandstone
fill ~56 ~34 ~57 ~57 ~34 ~57 sandstone
fill ~80 ~34 ~57 ~80 ~55 ~59 stone
fill ~103 ~34 ~57 ~103 ~37 ~57 sandstone
setblock ~55 ~34 ~58 sandstone
fill ~56 ~34 ~58 ~56 ~40 ~58 end_stone
fill ~55 ~34 ~59 ~55 ~36 ~59 end_stone
setblock ~56 ~34 ~59 end_stone
fill ~57 ~34 ~59 ~57 ~37 ~59 sandstone
fill ~81 ~34 ~59 ~81 ~55 ~59 stone
fill ~87 ~34 ~74 ~87 ~47 ~89 stone
fill ~88 ~34 ~75 ~88 ~54 ~87 stone
fill ~74 ~34 ~76 ~89 ~46 ~86 stone
fill ~90 ~34 ~77 ~90 ~55 ~79 stone
fill ~119 ~34 ~79 ~119 ~55 ~82 stone
fill ~43 ~34 ~80 ~44 ~55 ~83 stone
fill ~105 ~34 ~80 ~105 ~55 ~80 stone
fill ~117 ~34 ~80 ~120 ~55 ~81 stone
fill ~31 ~34 ~81 ~32 ~54 ~81 stone
fill ~42 ~34 ~81 ~45 ~55 ~82 stone
fill ~59 ~34 ~81 ~59 ~55 ~83 stone
fill ~103 ~34 ~81 ~104 ~55 ~81 stone
fill ~131 ~34 ~81 ~131 ~54 ~81 stone
fill ~57 ~34 ~82 ~59 ~55 ~82 stone
fill ~91 ~34 ~82 ~91 ~55 ~85 stone
fill ~90 ~34 ~84 ~91 ~55 ~85 stone
fill ~76 ~34 ~88 ~87 ~54 ~88 stone
fill ~77 ~34 ~90 ~86 ~54 ~90 stone
fill ~80 ~34 ~91 ~84 ~55 ~91 stone
fill ~82 ~34 ~92 ~82 ~36 ~92 stone
fill ~81 ~34 ~103 ~83 ~55 ~104 stone
fill ~105 ~34 ~103 ~105 ~37 ~103 sandstone
fill ~106 ~34 ~103 ~107 ~34 ~103 end_stone
fill ~106 ~34 ~104 ~106 ~40 ~104 end_stone
setblock ~107 ~34 ~104 sandstone
fill ~57 ~34 ~105 ~57 ~34 ~106 sandstone
fill ~59 ~34 ~105 ~59 ~37 ~105 sandstone
fill ~82 ~34 ~105 ~82 ~55 ~105 stone
fill ~105 ~34 ~105 ~106 ~34 ~105 sandstone
fill ~58 ~34 ~106 ~58 ~40 ~106 end_stone
fill ~59 ~34 ~106 ~59 ~34 ~107 end_stone
setblock ~58 ~34 ~107 sandstone
fill ~81 ~34 ~117 ~82 ~55 ~120 stone
fill ~80 ~34 ~119 ~83 ~55 ~119 stone
fill ~81 ~34 ~131 ~81 ~54 ~131 stone
fill ~82 ~35 ~31 ~82 ~53 ~31 stone
fill ~80 ~35 ~32 ~81 ~55 ~32 stone
fill ~83 ~35 ~44 ~83 ~55 ~44 stone
setblock ~104 ~35 ~54 sandstone
fill ~104 ~35 ~55 ~104 ~36 ~58 end_stone
fill ~56 ~35 ~56 ~56 ~37 ~56 end_stone
fill ~80 ~35 ~56 ~80 ~55 ~60 stone
fill ~103 ~35 ~56 ~103 ~37 ~57 sandstone
fill ~105 ~35 ~56 ~106 ~35 ~56 end_stone
fill ~56 ~35 ~57 ~57 ~35 ~58 end_stone
fill ~79 ~35 ~57 ~81 ~55 ~59 stone
fill ~105 ~35 ~57 ~105 ~38 ~57 end_stone
setblock ~54 ~35 ~58 sandstone
fill ~55 ~35 ~58 ~58 ~36 ~58 end_stone
fill ~78 ~35 ~58 ~82 ~55 ~58 stone
fill ~56 ~35 ~59 ~57 ~37 ~59 sandstone
fill ~84 ~35 ~72 ~84 ~46 ~91 stone
fill ~77 ~35 ~73 ~85 ~46 ~90 stone
fill ~75 ~35 ~74 ~88 ~46 ~88 stone
fill ~73 ~35 ~77 ~90 ~40 ~84 stone
fill ~104 ~35 ~78 ~104 ~55 ~82 stone
fill ~44 ~35 ~79 ~44 ~55 ~83 stone
fill ~105 ~35 ~79 ~105 ~55 ~81 stone
fill ~31 ~35 ~80 ~31 ~53 ~81 stone
fill ~58 ~35 ~80 ~58 ~55 ~84 stone
fill ~71 ~35 ~80 ~91 ~40 ~80 stone
fill ~102 ~35 ~80 ~106 ~55 ~80 stone
fill ~57 ~35 ~81 ~59 ~55 ~83 stone
fill ~91 ~35 ~81 ~91 ~54 ~86 stone
fill ~56 ~35 ~82 ~60 ~55 ~82 stone
fill ~92 ~35 ~82 ~92 ~54 ~86 stone
fill ~131 ~35 ~82 ~131 ~53 ~82 stone
fill ~118 ~35 ~83 ~118 ~55 ~83 stone
fill ~73 ~35 ~86 ~92 ~35 ~86 stone
fill ~74 ~35 ~87 ~89 ~47 ~87 stone
fill ~89 ~35 ~88 ~89 ~56 ~88 stone
fill ~76 ~35 ~89 ~87 ~54 ~89 stone
fill ~78 ~35 ~91 ~84 ~55 ~91 stone
fill ~80 ~35 ~92 ~81 ~55 ~92 stone
fill ~82 ~35 ~102 ~82 ~55 ~106 stone
fill ~106 ~35 ~103 ~106 ~38 ~103 sandstone
fill ~107 ~35 ~103 ~107 ~36 ~104 end_stone
fill ~58 ~35 ~104 ~58 ~36 ~107 end_stone
fill ~80 ~35 ~104 ~84 ~55 ~104 stone
fill ~104 ~35 ~104 ~107 ~36 ~104 end_stone
setblock ~108 ~35 ~104 sandstone
fill ~57 ~35 ~105 ~58 ~36 ~105 end_stone
fill ~81 ~35 ~105 ~83 ~55 ~105 stone
fill ~105 ~35 ~105 ~105 ~38 ~105 end_stone
fill ~106 ~35 ~105 ~106 ~35 ~106 end_stone
fill ~56 ~35 ~106 ~58 ~35 ~106 end_stone
fill ~59 ~35 ~106 ~59 ~38 ~106 sandstone
fill ~59 ~35 ~107 ~59 ~36 ~107 end_stone
setblock ~58 ~35 ~108 sandstone
fill ~79 ~35 ~118 ~83 ~55 ~118 stone
fill ~80 ~35 ~131 ~81 ~53 ~131 stone
fill ~81 ~36 ~30 ~81 ~54 ~32 stone
fill ~82 ~36 ~32 ~82 ~55 ~32 stone
fill ~81 ~36 ~33 ~81 ~41 ~33 stone
fill ~78 ~36 ~44 ~83 ~55 ~44 stone
fill ~82 ~36 ~45 ~82 ~55 ~45 stone
fill ~81 ~36 ~46 ~81 ~55 ~46 stone
fill ~104 ~36 ~54 ~104 ~37 ~56 end_stone
fill ~105 ~36 ~55 ~105 ~36 ~56 sandstone
setblock ~102 ~36 ~56 stone
fill ~106 ~36 ~56 ~106 ~37 ~56 end_stone
fill ~55 ~36 ~57 ~56 ~36 ~57 sandstone
fill ~57 ~36 ~57 ~57 ~38 ~57 end_stone
fill ~54 ~36 ~58 ~56 ~37 ~58 end_stone
setblock ~56 ~36 ~60 stone
fill ~79 ~36 ~60 ~80 ~55 ~60 stone
fill ~82 ~36 ~71 ~83 ~46 ~91 stone
fill ~85 ~36 ~72 ~85 ~46 ~90 stone
fill ~75 ~36 ~73 ~86 ~46 ~88 stone
fill ~74 ~36 ~74 ~88 ~36 ~74 stone
fill ~118 ~36 ~78 ~118 ~55 ~83 stone
fill ~91 ~36 ~79 ~91 ~54 ~86 stone
fill ~102 ~36 ~79 ~105 ~55 ~80 stone
fill ~32 ~36 ~80 ~32 ~55 ~81 stone
fill ~45 ~36 ~80 ~45 ~55 ~82 stone
fill ~92 ~36 ~80 ~92 ~54 ~86 stone
fill ~30 ~36 ~81 ~32 ~54 ~81 stone
fill ~33 ~36 ~81 ~33 ~41 ~81 stone
fill ~46 ~36 ~81 ~46 ~55 ~81 stone
fill ~116 ~36 ~81 ~120 ~55 ~81 stone
fill ~129 ~36 ~81 ~132 ~41 ~81 stone
fill ~71 ~36 ~82 ~93 ~38 ~82 stone
fill ~117 ~36 ~82 ~119 ~55 ~82 stone
fill ~130 ~36 ~82 ~131 ~53 ~82 stone
fill ~60 ~36 ~83 ~60 ~55 ~83 stone
fill ~72 ~36 ~83 ~93 ~39 ~83 stone
fill ~44 ~36 ~84 ~44 ~55 ~84 stone
fill ~93 ~36 ~84 ~93 ~55 ~84 stone
fill ~73 ~36 ~85 ~93 ~39 ~85 stone
fill ~90 ~36 ~86 ~92 ~54 ~86 stone
fill ~90 ~36 ~87 ~90 ~55 ~87 stone
fill ~74 ~36 ~88 ~89 ~54 ~88 stone
fill ~88 ~36 ~89 ~88 ~59 ~89 stone
fill ~87 ~36 ~90 ~87 ~60 ~90 stone
fill ~79 ~36 ~92 ~79 ~56 ~92 stone
fill ~83 ~36 ~102 ~83 ~55 ~105 stone
setblock ~106 ~36 ~102 stone
fill ~108 ~36 ~104 ~108 ~37 ~104 end_stone
fill ~106 ~36 ~105 ~107 ~36 ~105 sandstone
fill ~56 ~36 ~106 ~56 ~37 ~106 end_stone
fill ~57 ~36 ~106 ~57 ~37 ~106 sandstone
setblock ~60 ~36 ~106 stone
fill ~106 ~36 ~106 ~106 ~37 ~106 end_stone
setblock ~57 ~36 ~107 sandstone
fill ~58 ~36 ~108 ~58 ~37 ~108 end_stone
fill ~81 ~36 ~116 ~81 ~55 ~120 stone
fill ~80 ~36 ~117 ~82 ~55 ~119 stone
fill ~84 ~36 ~118 ~84 ~55 ~118 stone
fill ~81 ~36 ~129 ~81 ~41 ~132 stone
fill ~80 ~36 ~130 ~81 ~53 ~131 stone
fill ~80 ~37 ~31 ~82 ~53 ~32 stone
fill ~79 ~37 ~42 ~81 ~37 ~45 stone
fill ~83 ~37 ~45 ~83 ~55 ~45 stone
fill ~103 ~37 ~55 ~103 ~38 ~56 sandstone
setblock ~105 ~37 ~55 end_stone
fill ~81 ~37 ~56 ~81 ~37 ~60 stone
setblock ~102 ~37 ~56 end_stone
setblock ~105 ~37 ~56 sandstone
fill ~55 ~37 ~57 ~55 ~37 ~58 end_stone
setblock ~56 ~37 ~57 sandstone
fill ~58 ~37 ~57 ~58 ~38 ~57 end_stone
fill ~78 ~37 ~57 ~82 ~55 ~58 stone
fill ~104 ~37 ~57 ~104 ~38 ~57 sandstone
fill ~57 ~37 ~58 ~57 ~38 ~58 sandstone
setblock ~58 ~37 ~58 end_stone
fill ~83 ~37 ~58 ~83 ~55 ~58 stone
setblock ~103 ~37 ~58 sandstone
fill ~104 ~37 ~58 ~105 ~37 ~58 end_stone
fill ~55 ~37 ~59 ~58 ~37 ~59 sandstone
fill ~82 ~37 ~59 ~82 ~55 ~59 stone
setblock ~56 ~37 ~60 end_stone
fill ~76 ~37 ~72 ~85 ~46 ~89 stone
fill ~87 ~37 ~73 ~87 ~47 ~90 stone
fill ~73 ~37 ~76 ~89 ~46 ~88 stone
fill ~45 ~37 ~79 ~45 ~55 ~83 stone
fill ~58 ~37 ~79 ~58 ~55 ~84 stone
fill ~117 ~37 ~79 ~120 ~55 ~81 stone
fill ~57 ~37 ~80 ~59 ~55 ~83 stone
fill ~130 ~37 ~80 ~131 ~53 ~82 stone
fill ~56 ~37 ~81 ~60 ~37 ~82 stone
fill ~71 ~37 ~81 ~92 ~46 ~82 stone
fill ~102 ~37 ~81 ~102 ~56 ~81 stone
setblock ~106 ~37 ~81 stone
fill ~31 ~37 ~82 ~32 ~53 ~82 stone
fill ~103 ~37 ~82 ~105 ~55 ~82 stone
fill ~42 ~37 ~83 ~45 ~37 ~83 stone
fill ~104 ~37 ~83 ~104 ~55 ~83 stone
fill ~117 ~37 ~83 ~118 ~55 ~83 stone
fill ~72 ~37 ~84 ~93 ~46 ~84 stone
fill ~72 ~37 ~86 ~91 ~46 ~87 stone
fill ~90 ~37 ~88 ~90 ~55 ~88 stone
fill ~74 ~37 ~89 ~88 ~54 ~89 stone
fill ~77 ~37 ~91 ~85 ~55 ~91 stone
fill ~78 ~37 ~92 ~81 ~55 ~92 stone
fill ~81 ~37 ~102 ~83 ~55 ~105 stone
setblock ~106 ~37 ~102 end_stone
fill ~80 ~37 ~103 ~83 ~55 ~105 stone
fill ~104 ~37 ~103 ~107 ~37 ~103 sandstone
fill ~57 ~37 ~104 ~57 ~38 ~105 end_stone
setblock ~58 ~37 ~104 end_stone
fill ~59 ~37 ~104 ~59 ~37 ~107 sandstone
fill ~79 ~37 ~104 ~84 ~55 ~104 stone
fill ~104 ~37 ~104 ~104 ~37 ~105 end_stone
fill ~105 ~37 ~104 ~105 ~38 ~104 sandstone
fill ~107 ~37 ~104 ~108 ~37 ~104 end_stone
fill ~58 ~37 ~105 ~59 ~37 ~105 sandstone
setblock ~106 ~37 ~105 sandstone
setblock ~107 ~37 ~105 end_stone
setblock ~60 ~37 ~106 end_stone
fill ~81 ~37 ~106 ~82 ~37 ~106 stone
fill ~57 ~37 ~107 ~58 ~37 ~107 end_stone
fill ~79 ~37 ~117 ~83 ~55 ~118 stone
fill ~83 ~37 ~120 ~83 ~55 ~120 stone
fill ~82 ~37 ~130 ~82 ~53 ~131 stone
fill ~82 ~38 ~30 ~82 ~53 ~33 stone
fill ~79 ~38 ~32 ~83 ~54 ~32 stone
fill ~79 ~38 ~45 ~83 ~55 ~45 stone
fill ~80 ~38 ~46 ~81 ~55 ~46 stone
fill ~104 ~38 ~54 ~105 ~39 ~54 sandstone
fill ~106 ~38 ~54 ~106 ~39 ~54 end_stone
fill ~80 ~38 ~55 ~80 ~55 ~60 stone
fill ~102 ~38 ~55 ~102 ~39 ~55 stone
fill ~104 ~38 ~55 ~104 ~40 ~55 sandstone
setblock ~105 ~38 ~55 sandstone
setblock ~106 ~38 ~55 end_stone
fill ~54 ~38 ~56 ~55 ~38 ~56 end_stone
setblock ~56 ~38 ~56 sandstone
fill ~79 ~38 ~56 ~80 ~55 ~60 stone
fill ~102 ~38 ~56 ~103 ~38 ~56 sandstone
fill ~104 ~38 ~56 ~104 ~40 ~56 end_stone
fill ~105 ~38 ~56 ~105 ~38 ~58 end_stone
setblock ~106 ~38 ~56 sandstone
fill ~54 ~38 ~57 ~54 ~46 ~57 sandstone
fill ~55 ~38 ~57 ~55 ~38 ~59 sandstone
fill ~56 ~38 ~57 ~58 ~38 ~57 end_stone
fill ~102 ~38 ~57 ~102 ~39 ~57 sandstone
fill ~103 ~38 ~57 ~103 ~39 ~58 end_stone
fill ~54 ~38 ~58 ~55 ~39 ~58 sandstone
setblock ~58 ~38 ~58 sandstone
setblock ~59 ~38 ~58 end_stone
setblock ~104 ~38 ~58 sandstone
fill ~56 ~38 ~59 ~56 ~38 ~60 sandstone
fill ~57 ~38 ~59 ~58 ~39 ~59 end_stone
setblock ~104 ~38 ~59 end_stone
fill ~55 ~38 ~60 ~55 ~39 ~60 stone
fill ~57 ~38 ~60 ~57 ~39 ~60 sandstone
fill ~81 ~38 ~60 ~81 ~56 ~60 stone
fill ~80 ~38 ~71 ~83 ~46 ~91 stone
fill ~86 ~38 ~72 ~86 ~46 ~91 stone
fill ~88 ~38 ~73 ~88 ~54 ~90 stone
fill ~74 ~38 ~74 ~88 ~46 ~90 stone
fill ~73 ~38 ~75 ~89 ~46 ~89 stone
fill ~72 ~38 ~76 ~90 ~40 ~88 stone
fill ~91 ~38 ~78 ~91 ~55 ~85 stone
fill ~32 ~38 ~79 ~32 ~54 ~82 stone
fill ~71 ~38 ~79 ~91 ~40 ~82 stone
fill ~106 ~38 ~79 ~106 ~55 ~80 stone
fill ~30 ~38 ~80 ~32 ~53 ~81 stone
fill ~33 ~38 ~80 ~33 ~55 ~80 stone
fill ~107 ~38 ~80 ~107 ~55 ~80 stone
fill ~116 ~38 ~80 ~120 ~55 ~81 stone
fill ~60 ~38 ~81 ~60 ~55 ~83 stone
fill ~46 ~38 ~82 ~46 ~55 ~82 stone
fill ~55 ~38 ~82 ~60 ~55 ~82 stone
fill ~129 ~38 ~82 ~132 ~53 ~82 stone
fill ~56 ~38 ~83 ~60 ~55 ~83 stone
fill ~130 ~38 ~83 ~130 ~54 ~83 stone
fill ~71 ~38 ~87 ~91 ~47 ~87 stone
setblock ~91 ~38 ~88 stone
fill ~90 ~38 ~89 ~90 ~55 ~89 stone
fill ~76 ~38 ~91 ~87 ~54 ~91 stone
fill ~82 ~38 ~92 ~82 ~55 ~92 stone
fill ~80 ~38 ~93 ~81 ~55 ~93 stone
fill ~105 ~38 ~102 ~106 ~38 ~102 sandstone
fill ~107 ~38 ~102 ~107 ~39 ~102 stone
setblock ~58 ~38 ~103 end_stone
fill ~104 ~38 ~103 ~105 ~39 ~103 end_stone
fill ~107 ~38 ~103 ~107 ~38 ~105 sandstone
fill ~58 ~38 ~104 ~58 ~38 ~105 sandstone
fill ~59 ~38 ~104 ~59 ~39 ~105 end_stone
setblock ~103 ~38 ~104 end_stone
fill ~104 ~38 ~104 ~105 ~38 ~104 sandstone
fill ~108 ~38 ~104 ~108 ~39 ~105 sandstone
fill ~60 ~38 ~105 ~60 ~39 ~105 sandstone
fill ~104 ~38 ~105 ~106 ~38 ~105 end_stone
setblock ~56 ~38 ~106 sandstone
fill ~57 ~38 ~106 ~58 ~38 ~106 end_stone
setblock ~60 ~38 ~106 sandstone
fill ~83 ~38 ~106 ~83 ~55 ~106 stone
setblock ~106 ~38 ~106 sandstone
fill ~107 ~38 ~106 ~108 ~38 ~106 end_stone
fill ~56 ~38 ~107 ~56 ~38 ~108 end_stone
fill ~57 ~38 ~107 ~58 ~38 ~108 sandstone
setblock ~59 ~38 ~107 sandstone
fill ~60 ~38 ~107 ~60 ~39 ~107 stone
fill ~82 ~38 ~107 ~82 ~55 ~107 stone
fill ~82 ~38 ~116 ~82 ~55 ~120 stone
fill ~80 ~38 ~129 ~80 ~53 ~132 stone
fill ~79 ~38 ~130 ~82 ~54 ~130 stone
fill ~83 ~39 ~31 ~83 ~54 ~32 stone
fill ~80 ~39 ~33 ~80 ~55 ~33 stone
fill ~80 ~39 ~41 ~81 ~55 ~46 stone
fill ~79 ~39 ~42 ~82 ~55 ~46 stone
fill ~78 ~39 ~43 ~83 ~54 ~44 stone
fill ~84 ~39 ~44 ~84 ~54 ~44 stone
fill ~78 ~39 ~45 ~83 ~39 ~45 stone
fill ~83 ~39 ~46 ~83 ~55 ~46 stone
fill ~104 ~39 ~53 ~104 ~39 ~55 sandstone
fill ~102 ~39 ~54 ~102 ~40 ~54 stone
fill ~103 ~39 ~54 ~103 ~39 ~58 end_stone
fill ~55 ~39 ~55 ~55 ~39 ~56 sandstone
fill ~101 ~39 ~55 ~102 ~39 ~55 stone
setblock ~105 ~39 ~55 end_stone
fill ~106 ~39 ~55 ~107 ~39 ~55 sandstone
setblock ~54 ~39 ~56 end_stone
setblock ~56 ~39 ~56 end_stone
fill ~81 ~39 ~56 ~81 ~55 ~61 stone
fill ~102 ~39 ~56 ~104 ~39 ~56 end_stone
fill ~105 ~39 ~56 ~105 ~44 ~56 sandstone
setblock ~106 ~39 ~56 end_stone
setblock ~55 ~39 ~57 end_stone
fill ~56 ~39 ~57 ~56 ~44 ~57 sandstone
fill ~57 ~39 ~57 ~57 ~41 ~57 sandstone
setblock ~58 ~39 ~57 sandstone
fill ~104 ~39 ~57 ~104 ~39 ~58 end_stone
fill ~105 ~39 ~57 ~105 ~41 ~57 sandstone
fill ~53 ~39 ~58 ~55 ~39 ~58 sandstone
fill ~57 ~39 ~58 ~58 ~39 ~59 end_stone
fill ~59 ~39 ~58 ~59 ~40 ~58 sandstone
fill ~77 ~39 ~58 ~84 ~55 ~58 stone
setblock ~105 ~39 ~58 sandstone
fill ~54 ~39 ~59 ~58 ~39 ~59 end_stone
fill ~78 ~39 ~59 ~82 ~55 ~59 stone
fill ~104 ~39 ~59 ~104 ~40 ~59 sandstone
fill ~54 ~39 ~60 ~55 ~39 ~60 stone
setblock ~56 ~39 ~60 end_stone
fill ~82 ~39 ~60 ~82 ~55 ~60 stone
setblock ~55 ~39 ~61 stone
fill ~80 ~39 ~70 ~83 ~46 ~92 stone
fill ~76 ~39 ~71 ~84 ~46 ~91 stone
fill ~75 ~39 ~72 ~86 ~46 ~91 stone
fill ~73 ~39 ~74 ~89 ~46 ~90 stone
fill ~72 ~39 ~75 ~89 ~46 ~89 stone
fill ~91 ~39 ~76 ~91 ~54 ~87 stone
fill ~104 ~39 ~77 ~104 ~55 ~84 stone
fill ~44 ~39 ~78 ~44 ~54 ~84 stone
fill ~58 ~39 ~78 ~58 ~55 ~85 stone
fill ~71 ~39 ~78 ~91 ~40 ~87 stone
fill ~103 ~39 ~78 ~104 ~55 ~82 stone
fill ~119 ~39 ~78 ~119 ~54 ~83 stone
fill ~31 ~39 ~79 ~32 ~53 ~82 stone
fill ~43 ~39 ~79 ~46 ~55 ~83 stone
fill ~92 ~39 ~79 ~92 ~54 ~86 stone
fill ~116 ~39 ~79 ~120 ~55 ~82 stone
fill ~130 ~39 ~79 ~130 ~54 ~83 stone
fill ~42 ~39 ~80 ~46 ~55 ~83 stone
fill ~60 ~39 ~80 ~60 ~55 ~83 stone
fill ~70 ~39 ~80 ~92 ~40 ~81 stone
fill ~121 ~39 ~80 ~121 ~55 ~81 stone
fill ~129 ~39 ~80 ~131 ~53 ~80 stone
fill ~41 ~39 ~81 ~46 ~55 ~82 stone
fill ~56 ~39 ~81 ~60 ~55 ~83 stone
fill ~61 ~39 ~81 ~61 ~55 ~81 stone
fill ~69 ~39 ~81 ~92 ~54 ~81 stone
fill ~101 ~39 ~81 ~106 ~55 ~81 stone
fill ~33 ~39 ~82 ~33 ~55 ~82 stone
fill ~102 ~39 ~82 ~105 ~55 ~82 stone
fill ~32 ~39 ~83 ~32 ~54 ~83 stone
fill ~116 ~39 ~83 ~119 ~55 ~83 stone
fill ~131 ~39 ~83 ~131 ~54 ~83 stone
fill ~43 ~39 ~84 ~44 ~54 ~84 stone
setblock ~45 ~39 ~84 stone
fill ~59 ~39 ~84 ~59 ~55 ~84 stone
fill ~118 ~39 ~84 ~118 ~54 ~84 stone
fill ~71 ~39 ~88 ~90 ~39 ~88 stone
fill ~74 ~39 ~91 ~88 ~54 ~91 stone
fill ~77 ~39 ~92 ~85 ~54 ~92 stone
fill ~82 ~39 ~93 ~82 ~55 ~93 stone
fill ~81 ~39 ~101 ~81 ~55 ~106 stone
fill ~107 ~39 ~101 ~107 ~39 ~102 stone
fill ~80 ~39 ~102 ~83 ~55 ~105 stone
setblock ~105 ~39 ~102 sandstone
fill ~106 ~39 ~102 ~106 ~39 ~104 end_stone
fill ~108 ~39 ~102 ~108 ~40 ~102 stone
fill ~58 ~39 ~103 ~58 ~40 ~103 sandstone
fill ~84 ~39 ~103 ~84 ~55 ~104 stone
fill ~107 ~39 ~103 ~108 ~39 ~103 end_stone
fill ~57 ~39 ~104 ~57 ~39 ~106 sandstone
fill ~58 ~39 ~104 ~59 ~39 ~106 end_stone
fill ~78 ~39 ~104 ~85 ~55 ~104 stone
fill ~103 ~39 ~104 ~103 ~40 ~104 sandstone
fill ~104 ~39 ~104 ~106 ~39 ~104 end_stone
fill ~107 ~39 ~104 ~109 ~39 ~104 sandstone
fill ~104 ~39 ~105 ~106 ~39 ~105 sandstone
setblock ~107 ~39 ~105 end_stone
setblock ~56 ~39 ~106 end_stone
setblock ~60 ~39 ~106 end_stone
setblock ~106 ~39 ~106 end_stone
fill ~107 ~39 ~106 ~107 ~39 ~107 sandstone
setblock ~108 ~39 ~106 end_stone
fill ~55 ~39 ~107 ~56 ~39 ~107 sandstone
setblock ~57 ~39 ~107 end_stone
fill ~58 ~39 ~107 ~58 ~39 ~109 sandstone
fill ~59 ~39 ~107 ~59 ~39 ~108 end_stone
setblock ~61 ~39 ~107 stone
setblock ~56 ~39 ~108 end_stone
fill ~57 ~39 ~108 ~57 ~46 ~108 sandstone
fill ~60 ~39 ~108 ~60 ~40 ~108 stone
fill ~79 ~39 ~116 ~83 ~55 ~119 stone
fill ~84 ~39 ~117 ~84 ~54 ~119 stone
fill ~78 ~39 ~118 ~84 ~54 ~118 stone
fill ~80 ~39 ~120 ~83 ~55 ~120 stone
fill ~81 ~39 ~121 ~82 ~55 ~121 stone
fill ~82 ~39 ~129 ~82 ~53 ~131 stone
fill ~83 ~39 ~130 ~83 ~54 ~130 stone
fill ~79 ~39 ~131 ~82 ~53 ~131 stone
fill ~83 ~40 ~9 ~83 ~43 ~9 stone
fill ~65 ~40 ~16 ~65 ~43 ~16 stone
fill ~97 ~40 ~20 ~97 ~43 ~20 stone
fill ~80 ~40 ~30 ~83 ~53 ~32 stone
fill ~79 ~40 ~31 ~83 ~53 ~32 stone
fill ~81 ~40 ~34 ~81 ~55 ~34 stone
fill ~79 ~40 ~41 ~82 ~55 ~46 stone
fill ~78 ~40 ~42 ~83 ~54 ~44 stone
fill ~81 ~40 ~47 ~81 ~55 ~47 stone
fill ~102 ~40 ~53 ~103 ~51 ~53 stone
setblock ~104 ~40 ~53 sandstone
setblock ~105 ~40 ~53 end_stone
setblock ~103 ~40 ~54 stone
setblock ~104 ~40 ~54 end_stone
fill ~105 ~40 ~54 ~106 ~45 ~54 sandstone
fill ~55 ~40 ~55 ~55 ~40 ~56 end_stone
fill ~78 ~40 ~55 ~81 ~55 ~55 stone
fill ~101 ~40 ~55 ~105 ~40 ~55 sandstone
fill ~106 ~40 ~55 ~106 ~42 ~55 end_stone
setblock ~107 ~40 ~55 end_stone
fill ~54 ~40 ~56 ~54 ~45 ~57 sandstone
fill ~56 ~40 ~56 ~56 ~40 ~57 sandstone
fill ~57 ~40 ~56 ~57 ~41 ~56 end_stone
fill ~82 ~40 ~56 ~82 ~55 ~60 stone
fill ~102 ~40 ~56 ~102 ~41 ~56 sandstone
fill ~103 ~40 ~56 ~104 ~40 ~56 end_stone
setblock ~106 ~40 ~56 sandstone
setblock ~53 ~40 ~57 end_stone
fill ~55 ~40 ~57 ~55 ~40 ~61 sandstone
fill ~58 ~40 ~57 ~58 ~40 ~58 end_stone
fill ~83 ~40 ~57 ~83 ~55 ~59 stone
setblock ~102 ~40 ~57 end_stone
fill ~103 ~40 ~57 ~105 ~41 ~57 sandstone
fill ~106 ~40 ~57 ~106 ~41 ~57 end_stone
setblock ~53 ~40 ~58 sandstone
setblock ~54 ~40 ~58 end_stone
fill ~57 ~40 ~58 ~57 ~41 ~59 sandstone
fill ~103 ~40 ~58 ~103 ~41 ~58 sandstone
fill ~104 ~40 ~58 ~105 ~40 ~58 end_stone
fill ~53 ~40 ~59 ~53 ~51 ~60 stone
fill ~54 ~40 ~59 ~54 ~40 ~60 stone
fill ~56 ~40 ~59 ~56 ~41 ~59 end_stone
fill ~58 ~40 ~59 ~58 ~41 ~59 sandstone
fill ~56 ~40 ~60 ~56 ~41 ~60 sandstone
setblock ~57 ~40 ~60 end_stone
fill ~20 ~40 ~65 ~20 ~43 ~65 stone
fill ~146 ~40 ~65 ~146 ~43 ~65 stone
fill ~79 ~40 ~70 ~84 ~46 ~93 stone
fill ~75 ~40 ~71 ~85 ~46 ~91 stone
fill ~87 ~40 ~72 ~87 ~47 ~91 stone
fill ~74 ~40 ~73 ~88 ~46 ~91 stone
fill ~72 ~40 ~74 ~89 ~46 ~89 stone
fill ~90 ~40 ~74 ~90 ~59 ~74 stone
fill ~71 ~40 ~76 ~89 ~42 ~87 stone
fill ~92 ~40 ~76 ~92 ~40 ~87 stone
fill ~93 ~40 ~77 ~93 ~40 ~79 stone
fill ~70 ~40 ~78 ~71 ~55 ~84 stone
fill ~105 ~40 ~78 ~105 ~55 ~83 stone
fill ~107 ~40 ~78 ~107 ~45 ~81 stone
fill ~117 ~40 ~78 ~120 ~54 ~83 stone
fill ~9 ~40 ~79 ~9 ~43 ~79 stone
fill ~30 ~40 ~79 ~32 ~53 ~82 stone
fill ~42 ~40 ~79 ~46 ~55 ~83 stone
fill ~57 ~40 ~79 ~59 ~55 ~84 stone
fill ~121 ~40 ~79 ~121 ~55 ~82 stone
fill ~131 ~40 ~79 ~131 ~53 ~83 stone
fill ~41 ~40 ~80 ~46 ~55 ~83 stone
fill ~56 ~40 ~80 ~60 ~55 ~83 stone
fill ~69 ~40 ~80 ~71 ~55 ~81 stone
fill ~132 ~40 ~80 ~132 ~53 ~83 stone
fill ~34 ~40 ~81 ~34 ~55 ~81 stone
fill ~47 ~40 ~81 ~47 ~55 ~81 stone
fill ~55 ~40 ~81 ~60 ~55 ~83 stone
fill ~115 ~40 ~81 ~121 ~55 ~81 stone
fill ~128 ~40 ~81 ~128 ~55 ~81 stone
fill ~106 ~40 ~82 ~106 ~55 ~82 stone
fill ~31 ~40 ~83 ~32 ~54 ~83 stone
fill ~103 ~40 ~83 ~105 ~55 ~83 stone
fill ~153 ~40 ~83 ~153 ~43 ~83 stone
fill ~42 ~40 ~84 ~44 ~40 ~84 stone
fill ~55 ~40 ~84 ~55 ~45 ~84 stone
fill ~91 ~40 ~88 ~91 ~54 ~88 stone
fill ~90 ~40 ~90 ~90 ~55 ~90 stone
fill ~73 ~40 ~91 ~88 ~54 ~91 stone
fill ~86 ~40 ~92 ~86 ~57 ~92 stone
fill ~78 ~40 ~93 ~84 ~55 ~93 stone
fill ~16 ~40 ~97 ~16 ~43 ~97 stone
fill ~142 ~40 ~97 ~142 ~43 ~97 stone
fill ~107 ~40 ~101 ~107 ~44 ~101 sandstone
setblock ~105 ~40 ~102 end_stone
fill ~106 ~40 ~102 ~107 ~40 ~102 sandstone
fill ~109 ~40 ~102 ~109 ~51 ~103 stone
fill ~79 ~40 ~103 ~84 ~55 ~105 stone
fill ~104 ~40 ~103 ~105 ~41 ~103 sandstone
fill ~106 ~40 ~103 ~106 ~41 ~103 end_stone
fill ~107 ~40 ~103 ~107 ~40 ~105 sandstone
fill ~108 ~40 ~103 ~109 ~40 ~103 stone
fill ~57 ~40 ~104 ~58 ~40 ~104 end_stone
fill ~59 ~40 ~104 ~59 ~41 ~105 sandstone
fill ~104 ~40 ~104 ~104 ~41 ~104 end_stone
fill ~105 ~40 ~104 ~105 ~41 ~105 sandstone
setblock ~108 ~40 ~104 end_stone
setblock ~109 ~40 ~104 sandstone
fill ~56 ~40 ~105 ~56 ~41 ~105 end_stone
fill ~57 ~40 ~105 ~59 ~41 ~105 sandstone
setblock ~60 ~40 ~105 end_stone
setblock ~104 ~40 ~105 end_stone
fill ~106 ~40 ~105 ~106 ~44 ~105 sandstone
fill ~108 ~40 ~105 ~108 ~45 ~106 sandstone
setblock ~109 ~40 ~105 end_stone
fill ~56 ~40 ~106 ~57 ~40 ~106 sandstone
fill ~59 ~40 ~106 ~59 ~41 ~106 end_stone
fill ~60 ~40 ~106 ~60 ~41 ~106 sandstone
fill ~80 ~40 ~106 ~83 ~55 ~106 stone
fill ~105 ~40 ~106 ~105 ~41 ~106 end_stone
setblock ~106 ~40 ~106 sandstone
fill ~107 ~40 ~106 ~107 ~42 ~106 end_stone
fill ~55 ~40 ~107 ~56 ~40 ~107 end_stone
fill ~57 ~40 ~107 ~61 ~40 ~107 sandstone
fill ~81 ~40 ~107 ~83 ~55 ~107 stone
fill ~84 ~40 ~107 ~84 ~45 ~107 stone
setblock ~107 ~40 ~107 end_stone
fill ~56 ~40 ~108 ~57 ~45 ~108 sandstone
setblock ~58 ~40 ~108 end_stone
fill ~59 ~40 ~108 ~60 ~40 ~109 stone
setblock ~57 ~40 ~109 end_stone
setblock ~58 ~40 ~109 sandstone
fill ~81 ~40 ~115 ~81 ~55 ~121 stone
fill ~85 ~40 ~118 ~85 ~54 ~118 stone
fill ~79 ~40 ~120 ~84 ~54 ~120 stone
fill ~80 ~40 ~121 ~83 ~55 ~121 stone
fill ~81 ~40 ~128 ~81 ~55 ~128 stone
fill ~83 ~40 ~131 ~83 ~54 ~131 stone
fill ~79 ~40 ~132 ~82 ~53 ~132 stone
fill ~65 ~40 ~142 ~65 ~43 ~142 stone
fill ~97 ~40 ~146 ~97 ~43 ~146 stone
fill ~79 ~40 ~153 ~79 ~43 ~153 stone
fill ~80 ~41 ~29 ~82 ~53 ~32 stone
fill ~79 ~41 ~30 ~83 ~53 ~32 stone
fill ~84 ~41 ~31 ~84 ~53 ~31 stone
fill ~83 ~41 ~33 ~83 ~54 ~33 stone
fill ~80 ~41 ~40 ~80 ~55 ~47 stone
fill ~77 ~41 ~43 ~83 ~54 ~43 stone
fill ~84 ~41 ~43 ~84 ~48 ~46 stone
fill ~82 ~41 ~47 ~82 ~55 ~47 stone
fill ~104 ~41 ~52 ~104 ~42 ~54 stone
fill ~105 ~41 ~53 ~106 ~41 ~54 sandstone
fill ~101 ~41 ~54 ~101 ~43 ~55 sandstone
fill ~102 ~41 ~54 ~103 ~41 ~54 end_stone
setblock ~107 ~41 ~54 end_stone
setblock ~54 ~41 ~55 end_stone
setblock ~55 ~41 ~55 sandstone
fill ~56 ~41 ~55 ~56 ~41 ~56 end_stone
fill ~102 ~41 ~55 ~102 ~43 ~55 end_stone
setblock ~103 ~41 ~55 sandstone
fill ~104 ~41 ~55 ~106 ~41 ~55 end_stone
setblock ~107 ~41 ~55 sandstone
fill ~53 ~41 ~56 ~54 ~41 ~57 sandstone
fill ~55 ~41 ~56 ~55 ~42 ~57 end_stone
fill ~58 ~41 ~56 ~58 ~43 ~56 sandstone
fill ~78 ~41 ~56 ~82 ~55 ~60 stone
fill ~101 ~41 ~56 ~102 ~41 ~56 sandstone
setblock ~103 ~41 ~56 end_stone
fill ~104 ~41 ~56 ~105 ~42 ~56 sandstone
fill ~106 ~41 ~56 ~107 ~41 ~56 end_stone
setblock ~58 ~41 ~57 sandstone
fill ~77 ~41 ~57 ~83 ~55 ~58 stone
fill ~102 ~41 ~57 ~105 ~41 ~57 sandstone
fill ~52 ~41 ~58 ~54 ~42 ~58 stone
setblock ~55 ~41 ~58 end_stone
fill ~56 ~41 ~58 ~57 ~41 ~58 sandstone
fill ~58 ~41 ~58 ~59 ~41 ~58 end_stone
fill ~102 ~41 ~58 ~102 ~42 ~58 end_stone
fill ~104 ~41 ~58 ~104 ~41 ~59 end_stone
fill ~105 ~41 ~58 ~106 ~41 ~58 sandstone
fill ~54 ~41 ~59 ~54 ~41 ~60 end_stone
setblock ~55 ~41 ~59 sandstone
setblock ~59 ~41 ~59 end_stone
fill ~103 ~41 ~59 ~104 ~41 ~59 end_stone
fill ~55 ~41 ~60 ~55 ~43 ~60 end_stone
setblock ~57 ~41 ~60 sandstone
fill ~58 ~41 ~60 ~58 ~42 ~60 end_stone
fill ~54 ~41 ~61 ~56 ~42 ~61 sandstone
fill ~79 ~41 ~61 ~81 ~55 ~61 stone
fill ~78 ~41 ~69 ~78 ~46 ~94 stone
fill ~81 ~41 ~69 ~83 ~46 ~93 stone
fill ~75 ~41 ~70 ~85 ~46 ~92 stone
fill ~86 ~41 ~71 ~87 ~46 ~91 stone
fill ~74 ~41 ~72 ~88 ~46 ~91 stone
fill ~73 ~41 ~73 ~86 ~46 ~92 stone
fill ~89 ~41 ~73 ~89 ~54 ~91 stone
fill ~90 ~41 ~73 ~90 ~55 ~79 stone
fill ~91 ~41 ~74 ~91 ~59 ~74 stone
fill ~71 ~41 ~75 ~74 ~54 ~85 stone
fill ~70 ~41 ~76 ~91 ~46 ~76 stone
fill ~92 ~41 ~77 ~92 ~53 ~87 stone
fill ~105 ~41 ~77 ~105 ~55 ~83 stone
fill ~119 ~41 ~77 ~119 ~54 ~83 stone
fill ~31 ~41 ~78 ~31 ~53 ~83 stone
fill ~43 ~41 ~78 ~46 ~48 ~83 stone
fill ~69 ~41 ~78 ~89 ~46 ~84 stone
fill ~102 ~41 ~78 ~106 ~55 ~82 stone
fill ~33 ~41 ~79 ~33 ~54 ~80 stone
fill ~68 ~41 ~79 ~89 ~46 ~80 stone
fill ~101 ~41 ~79 ~107 ~55 ~81 stone
fill ~132 ~41 ~79 ~132 ~53 ~83 stone
fill ~29 ~41 ~80 ~32 ~53 ~82 stone
fill ~47 ~41 ~80 ~47 ~55 ~82 stone
fill ~93 ~41 ~80 ~93 ~55 ~84 stone
fill ~115 ~41 ~80 ~121 ~55 ~82 stone
fill ~122 ~41 ~80 ~122 ~55 ~80 stone
fill ~133 ~41 ~80 ~133 ~53 ~82 stone
fill ~40 ~41 ~82 ~47 ~55 ~82 stone
fill ~61 ~41 ~82 ~61 ~55 ~83 stone
fill ~30 ~41 ~83 ~32 ~53 ~83 stone
fill ~129 ~41 ~83 ~132 ~53 ~83 stone
fill ~56 ~41 ~84 ~60 ~55 ~84 stone
fill ~116 ~41 ~84 ~119 ~48 ~84 stone
fill ~131 ~41 ~84 ~131 ~53 ~84 stone
fill ~43 ~41 ~85 ~43 ~54 ~85 stone
fill ~57 ~41 ~85 ~58 ~55 ~85 stone
fill ~70 ~41 ~85 ~92 ~46 ~85 stone
fill ~71 ~41 ~88 ~91 ~54 ~88 stone
fill ~91 ~41 ~89 ~91 ~41 ~90 stone
fill ~74 ~41 ~93 ~84 ~46 ~93 stone
fill ~77 ~41 ~94 ~80 ~54 ~94 stone
fill ~82 ~41 ~101 ~83 ~55 ~107 stone
fill ~106 ~41 ~101 ~108 ~42 ~101 sandstone
fill ~84 ~41 ~102 ~84 ~55 ~106 stone
fill ~104 ~41 ~102 ~104 ~42 ~102 end_stone
fill ~105 ~41 ~102 ~105 ~41 ~105 sandstone
setblock ~106 ~41 ~102 sandstone
fill ~107 ~41 ~102 ~107 ~43 ~102 end_stone
fill ~108 ~41 ~102 ~108 ~41 ~103 end_stone
fill ~58 ~41 ~103 ~59 ~41 ~103 end_stone
fill ~103 ~41 ~103 ~103 ~41 ~104 end_stone
setblock ~107 ~41 ~103 sandstone
fill ~56 ~41 ~104 ~56 ~43 ~104 sandstone
fill ~57 ~41 ~104 ~57 ~41 ~106 sandstone
setblock ~58 ~41 ~104 end_stone
fill ~60 ~41 ~104 ~60 ~42 ~104 end_stone
fill ~106 ~41 ~104 ~106 ~42 ~105 sandstone
fill ~107 ~41 ~104 ~107 ~41 ~106 end_stone
fill ~108 ~41 ~104 ~108 ~52 ~104 stone
fill ~109 ~41 ~104 ~110 ~42 ~104 stone
fill ~60 ~41 ~105 ~60 ~41 ~106 sandstone
fill ~85 ~41 ~105 ~85 ~55 ~105 stone
fill ~104 ~41 ~105 ~106 ~41 ~105 sandstone
fill ~109 ~41 ~105 ~109 ~41 ~106 sandstone
fill ~55 ~41 ~106 ~56 ~41 ~106 end_stone
fill ~58 ~41 ~106 ~58 ~42 ~106 sandstone
fill ~61 ~41 ~106 ~61 ~42 ~108 sandstone
fill ~104 ~41 ~106 ~104 ~43 ~106 sandstone
fill ~106 ~41 ~106 ~107 ~41 ~106 end_stone
setblock ~55 ~41 ~107 sandstone
fill ~56 ~41 ~107 ~57 ~42 ~107 end_stone
setblock ~58 ~41 ~107 end_stone
setblock ~59 ~41 ~107 sandstone
fill ~60 ~41 ~107 ~60 ~43 ~107 end_stone
setblock ~106 ~41 ~107 end_stone
setblock ~107 ~41 ~107 sandstone
setblock ~108 ~41 ~107 end_stone
setblock ~55 ~41 ~108 end_stone
fill ~58 ~41 ~108 ~58 ~52 ~108 stone
fill ~59 ~41 ~108 ~60 ~41 ~108 end_stone
fill ~56 ~41 ~109 ~57 ~41 ~109 sandstone
fill ~58 ~41 ~109 ~60 ~42 ~109 stone
fill ~58 ~41 ~110 ~58 ~42 ~110 stone
fill ~80 ~41 ~115 ~82 ~55 ~121 stone
fill ~78 ~41 ~116 ~83 ~48 ~119 stone
fill ~85 ~41 ~119 ~85 ~54 ~119 stone
fill ~82 ~41 ~122 ~82 ~55 ~122 stone
fill ~79 ~41 ~129 ~80 ~53 ~132 stone
fill ~78 ~41 ~131 ~83 ~53 ~131 stone
fill ~83 ~41 ~132 ~83 ~53 ~132 stone
fill ~80 ~41 ~133 ~82 ~53 ~133 stone
fill ~78 ~42 ~9 ~78 ~43 ~9 sandstone
fill ~82 ~42 ~9 ~82 ~45 ~9 sandstone
fill ~97 ~42 ~15 ~97 ~43 ~15 sandstone
fill ~65 ~42 ~17 ~65 ~45 ~17 sandstone
fill ~97 ~42 ~19 ~97 ~45 ~19 sandstone
fill ~65 ~42 ~21 ~65 ~43 ~21 sandstone
fill ~81 ~42 ~26 ~81 ~52 ~26 stone
fill ~81 ~42 ~28 ~81 ~53 ~32 stone
fill ~83 ~42 ~29 ~83 ~53 ~33 stone
fill ~84 ~42 ~30 ~84 ~53 ~32 stone
fill ~78 ~42 ~31 ~84 ~53 ~31 stone
fill ~82 ~42 ~34 ~82 ~55 ~34 stone
fill ~80 ~42 ~39 ~80 ~55 ~47 stone
fill ~79 ~42 ~40 ~82 ~55 ~46 stone
fill ~77 ~42 ~41 ~83 ~54 ~45 stone
fill ~84 ~42 ~42 ~84 ~43 ~46 stone
fill ~76 ~42 ~43 ~83 ~54 ~43 stone
fill ~85 ~42 ~43 ~85 ~54 ~45 stone
fill ~81 ~42 ~48 ~81 ~55 ~49 stone
fill ~105 ~42 ~52 ~105 ~43 ~53 end_stone
setblock ~106 ~42 ~53 end_stone
setblock ~55 ~42 ~54 stone
fill ~102 ~42 ~54 ~103 ~42 ~54 sandstone
fill ~107 ~42 ~54 ~107 ~43 ~54 stone
fill ~54 ~42 ~55 ~54 ~43 ~55 stone
fill ~55 ~42 ~55 ~55 ~42 ~57 end_stone
fill ~56 ~42 ~55 ~56 ~42 ~59 sandstone
fill ~57 ~42 ~55 ~57 ~43 ~55 sandstone
fill ~100 ~42 ~55 ~101 ~44 ~55 sandstone
setblock ~103 ~42 ~55 end_stone
fill ~104 ~42 ~55 ~104 ~42 ~56 sandstone
fill ~105 ~42 ~55 ~107 ~42 ~55 end_stone
setblock ~108 ~42 ~55 stone
fill ~53 ~42 ~56 ~53 ~42 ~57 end_stone
fill ~57 ~42 ~56 ~58 ~42 ~56 sandstone
fill ~77 ~42 ~56 ~82 ~55 ~60 stone
setblock ~101 ~42 ~56 sandstone
fill ~102 ~42 ~56 ~102 ~42 ~58 end_stone
fill ~103 ~42 ~56 ~107 ~42 ~56 sandstone
fill ~52 ~42 ~57 ~53 ~43 ~57 end_stone
fill ~57 ~42 ~57 ~58 ~43 ~57 end_stone
fill ~59 ~42 ~57 ~59 ~42 ~59 sandstone
fill ~103 ~42 ~57 ~105 ~42 ~57 end_stone
fill ~106 ~42 ~57 ~107 ~42 ~57 sandstone
fill ~55 ~42 ~58 ~56 ~42 ~58 sandstone
fill ~57 ~42 ~58 ~57 ~42 ~60 end_stone
fill ~58 ~42 ~58 ~59 ~42 ~58 sandstone
fill ~60 ~42 ~58 ~60 ~44 ~58 stone
fill ~103 ~42 ~58 ~103 ~45 ~58 end_stone
fill ~104 ~42 ~58 ~104 ~42 ~59 sandstone
fill ~105 ~42 ~58 ~105 ~43 ~58 end_stone
fill ~106 ~42 ~58 ~106 ~43 ~58 sandstone
fill ~54 ~42 ~59 ~54 ~42 ~61 sandstone
fill ~55 ~42 ~59 ~55 ~42 ~60 end_stone
fill ~58 ~42 ~59 ~58 ~45 ~59 end_stone
fill ~103 ~42 ~59 ~104 ~44 ~59 sandstone
setblock ~105 ~42 ~59 sandstone
fill ~56 ~42 ~60 ~58 ~42 ~60 end_stone
fill ~83 ~42 ~60 ~83 ~55 ~60 stone
fill ~104 ~42 ~60 ~104 ~44 ~60 stone
fill ~78 ~42 ~61 ~81 ~55 ~61 stone
fill ~55 ~42 ~62 ~55 ~44 ~62 sandstone
fill ~15 ~42 ~65 ~15 ~43 ~65 sandstone
fill ~19 ~42 ~65 ~19 ~45 ~65 sandstone
fill ~141 ~42 ~65 ~141 ~43 ~65 sandstone
fill ~145 ~42 ~65 ~145 ~45 ~65 sandstone
fill ~77 ~42 ~69 ~83 ~46 ~93 stone
fill ~74 ~42 ~70 ~87 ~46 ~91 stone
fill ~88 ~42 ~71 ~88 ~54 ~91 stone
fill ~89 ~42 ~72 ~90 ~54 ~91 stone
fill ~91 ~42 ~73 ~91 ~54 ~88 stone
fill ~92 ~42 ~74 ~92 ~53 ~88 stone
fill ~70 ~42 ~75 ~92 ~46 ~85 stone
fill ~43 ~42 ~77 ~44 ~48 ~85 stone
fill ~45 ~42 ~77 ~45 ~54 ~84 stone
fill ~69 ~42 ~77 ~92 ~46 ~84 stone
fill ~93 ~42 ~77 ~93 ~56 ~77 stone
fill ~102 ~42 ~77 ~106 ~55 ~82 stone
fill ~118 ~42 ~77 ~120 ~54 ~83 stone
fill ~30 ~42 ~78 ~32 ~53 ~83 stone
fill ~42 ~42 ~78 ~46 ~43 ~83 stone
fill ~68 ~42 ~78 ~92 ~46 ~81 stone
fill ~101 ~42 ~78 ~106 ~55 ~81 stone
fill ~121 ~42 ~78 ~121 ~55 ~83 stone
fill ~131 ~42 ~78 ~131 ~53 ~84 stone
fill ~153 ~42 ~78 ~153 ~43 ~78 sandstone
fill ~29 ~42 ~79 ~32 ~53 ~82 stone
fill ~41 ~42 ~79 ~46 ~55 ~83 stone
fill ~60 ~42 ~79 ~60 ~55 ~85 stone
fill ~93 ~42 ~79 ~93 ~55 ~84 stone
fill ~122 ~42 ~79 ~122 ~55 ~82 stone
fill ~9 ~42 ~80 ~9 ~45 ~80 sandstone
fill ~34 ~42 ~80 ~34 ~55 ~81 stone
fill ~40 ~42 ~80 ~46 ~55 ~83 stone
fill ~67 ~42 ~80 ~93 ~46 ~81 stone
fill ~123 ~42 ~80 ~123 ~55 ~80 stone
fill ~26 ~42 ~81 ~26 ~52 ~81 stone
fill ~28 ~42 ~81 ~32 ~53 ~81 stone
fill ~48 ~42 ~81 ~49 ~55 ~81 stone
fill ~113 ~42 ~81 ~122 ~55 ~81 stone
fill ~134 ~42 ~81 ~134 ~53 ~81 stone
fill ~136 ~42 ~81 ~136 ~52 ~81 stone
fill ~39 ~42 ~82 ~47 ~55 ~82 stone
fill ~128 ~42 ~82 ~133 ~53 ~82 stone
fill ~153 ~42 ~82 ~153 ~45 ~82 sandstone
fill ~102 ~42 ~83 ~105 ~55 ~83 stone
fill ~133 ~42 ~83 ~133 ~53 ~83 stone
fill ~9 ~42 ~84 ~9 ~43 ~84 sandstone
fill ~31 ~42 ~84 ~31 ~53 ~84 stone
fill ~41 ~42 ~84 ~45 ~54 ~84 stone
fill ~61 ~42 ~84 ~61 ~55 ~84 stone
fill ~120 ~42 ~84 ~120 ~43 ~84 stone
fill ~130 ~42 ~84 ~132 ~53 ~84 stone
fill ~41 ~42 ~85 ~44 ~43 ~85 stone
setblock ~45 ~42 ~85 stone
fill ~56 ~42 ~85 ~60 ~55 ~85 stone
fill ~117 ~42 ~85 ~119 ~54 ~85 stone
fill ~70 ~42 ~88 ~92 ~42 ~88 stone
fill ~71 ~42 ~89 ~90 ~54 ~90 stone
fill ~72 ~42 ~91 ~90 ~54 ~91 stone
fill ~72 ~42 ~92 ~86 ~46 ~92 stone
fill ~85 ~42 ~93 ~85 ~56 ~93 stone
fill ~75 ~42 ~94 ~81 ~53 ~94 stone
fill ~17 ~42 ~97 ~17 ~45 ~97 sandstone
fill ~21 ~42 ~97 ~21 ~43 ~97 sandstone
fill ~143 ~42 ~97 ~143 ~45 ~97 sandstone
fill ~147 ~42 ~97 ~147 ~43 ~97 sandstone
fill ~107 ~42 ~100 ~107 ~44 ~101 sandstone
fill ~84 ~42 ~101 ~84 ~55 ~106 stone
fill ~58 ~42 ~102 ~58 ~44 ~102 stone
fill ~79 ~42 ~102 ~85 ~55 ~105 stone
fill ~105 ~42 ~102 ~105 ~42 ~105 end_stone
fill ~106 ~42 ~102 ~107 ~42 ~102 end_stone
fill ~108 ~42 ~102 ~108 ~42 ~103 sandstone
fill ~57 ~42 ~103 ~59 ~42 ~103 sandstone
fill ~103 ~42 ~103 ~103 ~44 ~104 sandstone
fill ~104 ~42 ~103 ~104 ~45 ~103 end_stone
fill ~106 ~42 ~103 ~106 ~42 ~107 sandstone
setblock ~107 ~42 ~103 end_stone
fill ~57 ~42 ~104 ~57 ~43 ~105 end_stone
setblock ~58 ~42 ~104 sandstone
fill ~59 ~42 ~104 ~60 ~42 ~105 end_stone
fill ~102 ~42 ~104 ~102 ~44 ~104 stone
setblock ~104 ~42 ~104 sandstone
setblock ~107 ~42 ~104 sandstone
fill ~55 ~42 ~105 ~56 ~42 ~106 sandstone
fill ~58 ~42 ~105 ~60 ~42 ~105 end_stone
setblock ~103 ~42 ~105 sandstone
fill ~104 ~42 ~105 ~105 ~43 ~105 end_stone
fill ~107 ~42 ~105 ~107 ~42 ~107 end_stone
fill ~109 ~42 ~105 ~110 ~43 ~105 end_stone
fill ~57 ~42 ~106 ~59 ~42 ~106 sandstone
fill ~60 ~42 ~106 ~60 ~42 ~107 end_stone
fill ~85 ~42 ~106 ~85 ~55 ~106 stone
fill ~105 ~42 ~106 ~106 ~42 ~107 sandstone
setblock ~109 ~42 ~106 end_stone
setblock ~54 ~42 ~107 stone
fill ~55 ~42 ~107 ~57 ~42 ~107 end_stone
setblock ~58 ~42 ~107 sandstone
fill ~59 ~42 ~107 ~60 ~42 ~107 end_stone
fill ~62 ~42 ~107 ~62 ~44 ~107 sandstone
fill ~108 ~42 ~107 ~108 ~43 ~107 stone
fill ~55 ~42 ~108 ~55 ~43 ~108 stone
fill ~59 ~42 ~108 ~61 ~42 ~108 sandstone
setblock ~107 ~42 ~108 stone
fill ~56 ~42 ~109 ~57 ~42 ~109 end_stone
fill ~57 ~42 ~110 ~57 ~43 ~110 end_stone
fill ~81 ~42 ~113 ~81 ~55 ~122 stone
fill ~77 ~42 ~117 ~85 ~54 ~118 stone
fill ~77 ~42 ~119 ~85 ~48 ~119 stone
fill ~78 ~42 ~120 ~85 ~43 ~120 stone
fill ~79 ~42 ~121 ~85 ~54 ~121 stone
fill ~80 ~42 ~122 ~83 ~55 ~122 stone
fill ~82 ~42 ~123 ~82 ~55 ~123 stone
fill ~80 ~42 ~128 ~80 ~53 ~133 stone
fill ~78 ~42 ~130 ~83 ~53 ~132 stone
fill ~84 ~42 ~131 ~84 ~53 ~131 stone
fill ~79 ~42 ~133 ~82 ~53 ~133 stone
fill ~81 ~42 ~134 ~81 ~53 ~134 stone
fill ~81 ~42 ~136 ~81 ~52 ~136 stone
fill ~97 ~42 ~141 ~97 ~43 ~141 sandstone
fill ~65 ~42 ~143 ~65 ~45 ~143 sandstone
fill ~97 ~42 ~145 ~97 ~45 ~145 sandstone
fill ~65 ~42 ~147 ~65 ~43 ~147 sandstone
fill ~80 ~42 ~153 ~80 ~45 ~153 sandstone
fill ~84 ~42 ~153 ~84 ~43 ~153 sandstone
fill ~83 ~43 ~8 ~83 ~45 ~8 stone
fill ~83 ~43 ~10 ~83 ~46 ~10 sandstone
fill ~64 ~43 ~16 ~64 ~45 ~16 stone
fill ~66 ~43 ~16 ~66 ~46 ~16 sandstone
fill ~96 ~43 ~20 ~96 ~46 ~20 sandstone
fill ~98 ~43 ~20 ~98 ~45 ~20 stone
fill ~82 ~43 ~28 ~82 ~53 ~35 stone
fill ~79 ~43 ~29 ~83 ~53 ~33 stone
fill ~85 ~43 ~31 ~85 ~53 ~31 stone
fill ~84 ~43 ~33 ~84 ~54 ~33 stone
fill ~80 ~43 ~34 ~83 ~55 ~34 stone
fill ~81 ~43 ~35 ~82 ~55 ~35 stone
fill ~80 ~43 ~38 ~81 ~55 ~49 stone
fill ~78 ~43 ~40 ~83 ~54 ~46 stone
fill ~84 ~43 ~41 ~84 ~55 ~41 stone
fill ~76 ~43 ~44 ~86 ~54 ~44 stone
fill ~79 ~43 ~47 ~83 ~55 ~47 stone
fill ~82 ~43 ~48 ~82 ~55 ~49 stone
fill ~103 ~43 ~52 ~103 ~45 ~53 stone
setblock ~104 ~43 ~52 sandstone
fill ~101 ~43 ~53 ~103 ~51 ~53 stone
fill ~104 ~43 ~53 ~105 ~43 ~53 end_stone
fill ~106 ~43 ~53 ~107 ~43 ~53 stone
fill ~54 ~43 ~54 ~54 ~43 ~55 stone
fill ~55 ~43 ~54 ~56 ~43 ~54 end_stone
fill ~57 ~43 ~54 ~57 ~48 ~54 sandstone
fill ~79 ~43 ~54 ~80 ~55 ~61 stone
fill ~100 ~43 ~54 ~100 ~51 ~54 stone
fill ~102 ~43 ~54 ~102 ~43 ~55 end_stone
fill ~103 ~43 ~54 ~103 ~43 ~57 sandstone
fill ~104 ~43 ~54 ~104 ~52 ~54 stone
setblock ~108 ~43 ~54 stone
fill ~53 ~43 ~55 ~54 ~43 ~55 stone
fill ~55 ~43 ~55 ~55 ~45 ~56 sandstone
fill ~56 ~43 ~55 ~56 ~43 ~56 end_stone
fill ~58 ~43 ~55 ~58 ~45 ~55 end_stone
fill ~82 ~43 ~55 ~82 ~55 ~60 stone
fill ~104 ~43 ~55 ~104 ~43 ~58 end_stone
fill ~105 ~43 ~55 ~107 ~43 ~55 sandstone
fill ~108 ~43 ~55 ~108 ~43 ~56 end_stone
setblock ~53 ~43 ~56 stone
fill ~57 ~43 ~56 ~57 ~45 ~56 end_stone
fill ~59 ~43 ~56 ~59 ~44 ~56 sandstone
setblock ~101 ~43 ~56 end_stone
fill ~102 ~43 ~56 ~102 ~45 ~56 sandstone
fill ~106 ~43 ~56 ~108 ~43 ~56 end_stone
fill ~55 ~43 ~57 ~56 ~43 ~57 sandstone
fill ~59 ~43 ~57 ~59 ~44 ~57 end_stone
fill ~101 ~43 ~57 ~101 ~44 ~57 sandstone
setblock ~102 ~43 ~57 end_stone
fill ~105 ~43 ~57 ~105 ~43 ~59 end_stone
fill ~106 ~43 ~57 ~106 ~45 ~57 end_stone
fill ~107 ~43 ~57 ~108 ~43 ~57 sandstone
setblock ~52 ~43 ~58 sandstone
setblock ~53 ~43 ~58 end_stone
fill ~54 ~43 ~58 ~54 ~52 ~58 stone
fill ~55 ~43 ~58 ~58 ~43 ~58 end_stone
fill ~59 ~43 ~58 ~59 ~47 ~58 sandstone
fill ~76 ~43 ~58 ~84 ~55 ~59 stone
setblock ~102 ~43 ~58 sandstone
fill ~107 ~43 ~58 ~107 ~45 ~58 end_stone
fill ~52 ~43 ~59 ~53 ~45 ~59 stone
fill ~54 ~43 ~59 ~57 ~43 ~59 sandstone
fill ~59 ~43 ~59 ~59 ~44 ~59 sandstone
setblock ~102 ~43 ~59 end_stone
fill ~106 ~43 ~59 ~106 ~44 ~59 sandstone
fill ~54 ~43 ~60 ~55 ~43 ~60 end_stone
fill ~56 ~43 ~60 ~56 ~45 ~60 sandstone
setblock ~57 ~43 ~60 end_stone
setblock ~58 ~43 ~60 sandstone
setblock ~59 ~43 ~60 end_stone
fill ~53 ~43 ~61 ~53 ~51 ~61 stone
fill ~54 ~43 ~61 ~55 ~43 ~61 sandstone
setblock ~56 ~43 ~61 end_stone
fill ~57 ~43 ~61 ~57 ~44 ~61 sandstone
fill ~54 ~43 ~62 ~54 ~51 ~62 stone
fill ~20 ~43 ~64 ~20 ~45 ~64 stone
fill ~146 ~43 ~64 ~146 ~45 ~64 stone
fill ~20 ~43 ~66 ~20 ~46 ~66 sandstone
fill ~146 ~43 ~66 ~146 ~46 ~66 sandstone
fill ~78 ~43 ~68 ~79 ~46 ~95 stone
fill ~75 ~43 ~69 ~83 ~46 ~94 stone
fill ~73 ~43 ~70 ~88 ~44 ~92 stone
fill ~89 ~43 ~71 ~89 ~54 ~92 stone
fill ~91 ~43 ~72 ~91 ~55 ~85 stone
fill ~72 ~43 ~73 ~89 ~46 ~92 stone
fill ~92 ~43 ~73 ~92 ~53 ~89 stone
fill ~93 ~43 ~74 ~93 ~46 ~88 stone
fill ~44 ~43 ~76 ~44 ~54 ~85 stone
fill ~94 ~43 ~76 ~94 ~55 ~81 stone
fill ~103 ~43 ~76 ~104 ~55 ~84 stone
fill ~119 ~43 ~76 ~120 ~54 ~83 stone
fill ~31 ~43 ~77 ~31 ~53 ~84 stone
fill ~117 ~43 ~77 ~121 ~54 ~83 stone
fill ~33 ~43 ~78 ~33 ~54 ~83 stone
fill ~41 ~43 ~78 ~41 ~55 ~84 stone
fill ~59 ~43 ~78 ~59 ~55 ~86 stone
fill ~116 ~43 ~78 ~122 ~54 ~83 stone
fill ~8 ~43 ~79 ~8 ~45 ~79 stone
fill ~10 ~43 ~79 ~10 ~46 ~79 sandstone
fill ~34 ~43 ~79 ~34 ~55 ~82 stone
fill ~40 ~43 ~79 ~47 ~55 ~83 stone
fill ~67 ~43 ~79 ~93 ~46 ~82 stone
fill ~95 ~43 ~79 ~95 ~55 ~79 stone
fill ~108 ~43 ~79 ~108 ~55 ~80 stone
fill ~115 ~43 ~79 ~122 ~55 ~83 stone
fill ~129 ~43 ~79 ~133 ~53 ~83 stone
fill ~28 ~43 ~80 ~35 ~53 ~81 stone
fill ~48 ~43 ~80 ~49 ~55 ~82 stone
fill ~55 ~43 ~80 ~60 ~55 ~83 stone
fill ~66 ~43 ~80 ~94 ~46 ~81 stone
fill ~113 ~43 ~80 ~122 ~55 ~82 stone
fill ~124 ~43 ~80 ~124 ~55 ~81 stone
fill ~128 ~43 ~80 ~133 ~53 ~83 stone
fill ~38 ~43 ~81 ~49 ~55 ~82 stone
fill ~123 ~43 ~81 ~124 ~55 ~81 stone
fill ~127 ~43 ~81 ~134 ~53 ~82 stone
fill ~54 ~43 ~82 ~61 ~55 ~83 stone
fill ~107 ~43 ~82 ~107 ~55 ~82 stone
fill ~29 ~43 ~83 ~33 ~53 ~83 stone
fill ~68 ~43 ~83 ~93 ~46 ~84 stone
fill ~152 ~43 ~83 ~152 ~46 ~83 sandstone
fill ~154 ~43 ~83 ~154 ~45 ~83 stone
fill ~40 ~43 ~84 ~46 ~54 ~84 stone
fill ~121 ~43 ~84 ~121 ~55 ~84 stone
fill ~129 ~43 ~84 ~132 ~53 ~84 stone
fill ~69 ~43 ~85 ~93 ~46 ~85 stone
fill ~131 ~43 ~85 ~131 ~53 ~85 stone
fill ~58 ~43 ~86 ~59 ~55 ~86 stone
fill ~70 ~43 ~86 ~70 ~57 ~86 stone
fill ~118 ~43 ~86 ~118 ~54 ~86 stone
fill ~91 ~43 ~89 ~91 ~54 ~90 stone
fill ~91 ~43 ~91 ~91 ~46 ~91 stone
fill ~73 ~43 ~93 ~86 ~46 ~93 stone
fill ~74 ~43 ~94 ~84 ~46 ~94 stone
fill ~76 ~43 ~95 ~81 ~53 ~95 stone
fill ~16 ~43 ~96 ~16 ~46 ~96 sandstone
fill ~142 ~43 ~96 ~142 ~46 ~96 sandstone
fill ~16 ~43 ~98 ~16 ~45 ~98 stone
fill ~142 ~43 ~98 ~142 ~45 ~98 stone
fill ~108 ~43 ~100 ~108 ~51 ~100 stone
fill ~105 ~43 ~101 ~105 ~44 ~101 sandstone
setblock ~106 ~43 ~101 end_stone
setblock ~108 ~43 ~101 sandstone
fill ~109 ~43 ~101 ~109 ~51 ~103 stone
setblock ~103 ~43 ~102 end_stone
setblock ~104 ~43 ~102 sandstone
setblock ~105 ~43 ~102 end_stone
fill ~106 ~43 ~102 ~106 ~45 ~102 sandstone
setblock ~108 ~43 ~102 end_stone
fill ~56 ~43 ~103 ~56 ~44 ~103 sandstone
fill ~57 ~43 ~103 ~57 ~43 ~105 end_stone
fill ~58 ~43 ~103 ~58 ~47 ~103 sandstone
fill ~59 ~43 ~103 ~59 ~44 ~103 sandstone
setblock ~60 ~43 ~103 end_stone
fill ~78 ~43 ~103 ~86 ~55 ~104 stone
fill ~105 ~43 ~103 ~108 ~43 ~103 sandstone
fill ~110 ~43 ~103 ~110 ~45 ~103 stone
fill ~55 ~43 ~104 ~55 ~45 ~104 end_stone
fill ~58 ~43 ~104 ~59 ~44 ~104 end_stone
setblock ~60 ~43 ~104 sandstone
fill ~104 ~43 ~104 ~107 ~43 ~104 end_stone
fill ~109 ~43 ~104 ~109 ~43 ~105 end_stone
setblock ~110 ~43 ~104 sandstone
fill ~54 ~43 ~105 ~54 ~48 ~105 sandstone
setblock ~55 ~43 ~105 sandstone
fill ~56 ~43 ~105 ~58 ~43 ~105 end_stone
fill ~59 ~43 ~105 ~59 ~43 ~108 sandstone
setblock ~60 ~43 ~105 end_stone
fill ~61 ~43 ~105 ~61 ~44 ~105 sandstone
fill ~103 ~43 ~105 ~105 ~43 ~105 end_stone
fill ~107 ~43 ~105 ~108 ~43 ~106 sandstone
fill ~54 ~43 ~106 ~56 ~43 ~106 end_stone
fill ~57 ~43 ~106 ~57 ~43 ~108 sandstone
fill ~58 ~43 ~106 ~58 ~43 ~107 end_stone
fill ~60 ~43 ~106 ~60 ~45 ~106 sandstone
setblock ~61 ~43 ~106 end_stone
fill ~103 ~43 ~106 ~104 ~43 ~106 sandstone
fill ~105 ~43 ~106 ~105 ~45 ~106 end_stone
fill ~106 ~43 ~106 ~106 ~43 ~108 end_stone
fill ~109 ~43 ~106 ~109 ~43 ~107 stone
setblock ~54 ~43 ~107 end_stone
fill ~55 ~43 ~107 ~56 ~45 ~107 sandstone
fill ~61 ~43 ~107 ~62 ~44 ~107 sandstone
fill ~80 ~43 ~107 ~83 ~55 ~107 stone
fill ~104 ~43 ~107 ~104 ~45 ~107 end_stone
fill ~105 ~43 ~107 ~105 ~43 ~108 sandstone
fill ~107 ~43 ~107 ~107 ~45 ~107 sandstone
fill ~54 ~43 ~108 ~55 ~43 ~108 stone
setblock ~60 ~43 ~108 end_stone
setblock ~61 ~43 ~108 sandstone
fill ~62 ~43 ~108 ~62 ~51 ~108 stone
fill ~82 ~43 ~108 ~83 ~55 ~108 stone
setblock ~107 ~43 ~108 end_stone
setblock ~108 ~43 ~108 stone
fill ~55 ~43 ~109 ~56 ~43 ~109 stone
fill ~57 ~43 ~109 ~58 ~43 ~109 end_stone
fill ~59 ~43 ~109 ~61 ~51 ~109 stone
setblock ~58 ~43 ~110 sandstone
fill ~59 ~43 ~110 ~59 ~45 ~110 stone
fill ~80 ~43 ~113 ~82 ~55 ~122 stone
fill ~79 ~43 ~115 ~83 ~55 ~122 stone
fill ~84 ~43 ~116 ~84 ~54 ~122 stone
fill ~76 ~43 ~118 ~85 ~54 ~118 stone
fill ~86 ~43 ~119 ~86 ~54 ~119 stone
fill ~78 ~43 ~121 ~85 ~54 ~121 stone
fill ~81 ~43 ~123 ~82 ~55 ~124 stone
fill ~80 ~43 ~127 ~81 ~53 ~134 stone
fill ~79 ~43 ~128 ~82 ~53 ~133 stone
fill ~78 ~43 ~129 ~83 ~53 ~132 stone
fill ~77 ~43 ~131 ~84 ~53 ~131 stone
fill ~83 ~43 ~133 ~83 ~53 ~133 stone
fill ~64 ~43 ~142 ~64 ~45 ~142 stone
fill ~66 ~43 ~142 ~66 ~46 ~142 sandstone
fill ~96 ~43 ~146 ~96 ~46 ~146 sandstone
fill ~98 ~43 ~146 ~98 ~45 ~146 stone
fill ~79 ~43 ~152 ~79 ~46 ~152 sandstone
fill ~79 ~43 ~154 ~79 ~45 ~154 stone
fill ~82 ~44 ~8 ~82 ~45 ~10 sandstone
fill ~78 ~44 ~9 ~78 ~45 ~9 stone
fill ~79 ~44 ~9 ~79 ~46 ~10 sandstone
fill ~83 ~44 ~9 ~83 ~46 ~10 sandstone
fill ~84 ~44 ~9 ~84 ~46 ~9 stone
fill ~81 ~44 ~12 ~81 ~45 ~12 sandstone
fill ~65 ~44 ~15 ~65 ~46 ~15 stone
fill ~97 ~44 ~15 ~97 ~45 ~15 stone
fill ~65 ~44 ~16 ~66 ~45 ~17 sandstone
fill ~96 ~44 ~16 ~97 ~46 ~16 sandstone
fill ~64 ~44 ~17 ~66 ~45 ~17 sandstone
fill ~68 ~44 ~18 ~68 ~45 ~18 sandstone
fill ~94 ~44 ~18 ~94 ~45 ~18 sandstone
fill ~96 ~44 ~19 ~97 ~45 ~20 sandstone
fill ~98 ~44 ~19 ~98 ~46 ~19 sandstone
fill ~65 ~44 ~20 ~66 ~46 ~20 sandstone
fill ~65 ~44 ~21 ~65 ~45 ~21 stone
fill ~97 ~44 ~21 ~97 ~46 ~21 stone
fill ~81 ~44 ~25 ~81 ~51 ~26 stone
fill ~80 ~44 ~26 ~81 ~52 ~26 stone
fill ~80 ~44 ~28 ~82 ~53 ~50 stone
fill ~78 ~44 ~30 ~84 ~53 ~33 stone
fill ~77 ~44 ~31 ~85 ~53 ~31 stone
fill ~79 ~44 ~34 ~83 ~55 ~34 stone
fill ~79 ~44 ~37 ~82 ~55 ~48 stone
fill ~83 ~44 ~37 ~83 ~55 ~38 stone
fill ~78 ~44 ~39 ~82 ~54 ~46 stone
fill ~77 ~44 ~40 ~83 ~54 ~46 stone
fill ~84 ~44 ~40 ~84 ~55 ~41 stone
fill ~76 ~44 ~42 ~83 ~54 ~44 stone
fill ~85 ~44 ~42 ~85 ~54 ~46 stone
fill ~84 ~44 ~47 ~84 ~55 ~47 stone
fill ~83 ~44 ~48 ~83 ~55 ~49 stone
fill ~84 ~44 ~49 ~84 ~55 ~49 stone
fill ~82 ~44 ~51 ~82 ~55 ~51 stone
fill ~102 ~44 ~52 ~102 ~50 ~54 stone
fill ~104 ~44 ~52 ~104 ~47 ~52 end_stone
fill ~105 ~44 ~52 ~106 ~44 ~54 sandstone
fill ~107 ~44 ~52 ~107 ~45 ~52 stone
fill ~56 ~44 ~53 ~56 ~44 ~58 sandstone
fill ~57 ~44 ~53 ~59 ~44 ~53 end_stone
fill ~80 ~44 ~53 ~80 ~55 ~62 stone
fill ~100 ~44 ~53 ~103 ~51 ~54 stone
fill ~104 ~44 ~53 ~107 ~44 ~53 sandstone
setblock ~108 ~44 ~53 stone
setblock ~53 ~44 ~54 stone
setblock ~54 ~44 ~54 end_stone
fill ~55 ~44 ~54 ~56 ~44 ~56 sandstone
fill ~58 ~44 ~54 ~58 ~45 ~56 end_stone
fill ~81 ~44 ~54 ~81 ~55 ~62 stone
fill ~107 ~44 ~54 ~107 ~44 ~56 sandstone
setblock ~108 ~44 ~54 end_stone
fill ~52 ~44 ~55 ~52 ~45 ~55 stone
fill ~53 ~44 ~55 ~56 ~44 ~56 sandstone
fill ~57 ~44 ~55 ~58 ~45 ~56 end_stone
fill ~102 ~44 ~55 ~102 ~44 ~57 sandstone
setblock ~103 ~44 ~55 sandstone
fill ~104 ~44 ~55 ~105 ~44 ~55 end_stone
fill ~106 ~44 ~55 ~107 ~45 ~56 sandstone
fill ~108 ~44 ~55 ~108 ~47 ~55 sandstone
fill ~52 ~44 ~56 ~54 ~44 ~57 sandstone
fill ~83 ~44 ~56 ~83 ~55 ~60 stone
setblock ~100 ~44 ~56 end_stone
fill ~101 ~44 ~56 ~102 ~44 ~57 sandstone
setblock ~103 ~44 ~56 end_stone
fill ~104 ~44 ~56 ~109 ~44 ~56 sandstone
fill ~55 ~44 ~57 ~55 ~44 ~58 end_stone
fill ~57 ~44 ~57 ~57 ~44 ~62 sandstone
setblock ~58 ~44 ~57 sandstone
fill ~60 ~44 ~57 ~60 ~51 ~57 stone
fill ~75 ~44 ~57 ~75 ~53 ~57 stone
fill ~84 ~44 ~57 ~84 ~55 ~60 stone
fill ~100 ~44 ~57 ~105 ~44 ~57 sandstone
fill ~107 ~44 ~57 ~107 ~47 ~57 end_stone
fill ~108 ~44 ~57 ~108 ~48 ~57 sandstone
fill ~109 ~44 ~57 ~109 ~44 ~59 end_stone
fill ~52 ~44 ~58 ~52 ~47 ~58 end_stone
setblock ~53 ~44 ~58 sandstone
fill ~58 ~44 ~58 ~58 ~44 ~61 end_stone
setblock ~61 ~44 ~58 stone
fill ~101 ~44 ~58 ~104 ~44 ~58 end_stone
setblock ~105 ~44 ~58 sandstone
fill ~106 ~44 ~58 ~108 ~45 ~58 end_stone
fill ~54 ~44 ~59 ~54 ~51 ~62 stone
fill ~55 ~44 ~59 ~55 ~44 ~62 sandstone
setblock ~56 ~44 ~59 end_stone
fill ~60 ~44 ~59 ~60 ~44 ~60 sandstone
fill ~85 ~44 ~59 ~85 ~55 ~59 stone
fill ~102 ~44 ~59 ~103 ~44 ~60 sandstone
setblock ~105 ~44 ~59 end_stone
fill ~52 ~44 ~60 ~54 ~50 ~60 stone
fill ~59 ~44 ~60 ~60 ~44 ~60 sandstone
fill ~105 ~44 ~60 ~105 ~51 ~60 stone
fill ~56 ~44 ~61 ~57 ~44 ~61 sandstone
fill ~77 ~44 ~61 ~82 ~55 ~61 stone
setblock ~104 ~44 ~61 stone
fill ~53 ~44 ~62 ~54 ~51 ~62 stone
setblock ~56 ~44 ~62 end_stone
fill ~79 ~44 ~62 ~81 ~55 ~62 stone
fill ~19 ~44 ~64 ~19 ~45 ~66 sandstone
fill ~145 ~44 ~64 ~145 ~45 ~66 sandstone
fill ~15 ~44 ~65 ~15 ~45 ~65 stone
fill ~16 ~44 ~65 ~16 ~46 ~66 sandstone
fill ~20 ~44 ~65 ~20 ~46 ~66 sandstone
fill ~21 ~44 ~65 ~21 ~46 ~65 stone
fill ~141 ~44 ~65 ~141 ~45 ~65 stone
fill ~142 ~44 ~65 ~142 ~46 ~66 sandstone
fill ~146 ~44 ~65 ~146 ~46 ~66 sandstone
fill ~147 ~44 ~65 ~147 ~46 ~65 stone
fill ~77 ~44 ~67 ~79 ~55 ~75 stone
fill ~18 ~44 ~68 ~18 ~45 ~68 sandstone
fill ~80 ~44 ~68 ~81 ~46 ~95 stone
fill ~144 ~44 ~68 ~144 ~45 ~68 sandstone
fill ~84 ~44 ~69 ~84 ~46 ~94 stone
fill ~87 ~44 ~69 ~87 ~53 ~83 stone
fill ~88 ~44 ~69 ~88 ~44 ~92 stone
fill ~89 ~44 ~70 ~89 ~53 ~92 stone
fill ~90 ~44 ~71 ~90 ~54 ~91 stone
fill ~72 ~44 ~72 ~90 ~46 ~92 stone
fill ~92 ~44 ~72 ~92 ~46 ~89 stone
fill ~70 ~44 ~74 ~92 ~44 ~89 stone
fill ~94 ~44 ~75 ~94 ~55 ~83 stone
fill ~105 ~44 ~75 ~105 ~53 ~75 stone
fill ~69 ~44 ~76 ~93 ~46 ~86 stone
fill ~95 ~44 ~76 ~95 ~47 ~82 stone
fill ~118 ~44 ~76 ~121 ~54 ~83 stone
fill ~42 ~44 ~77 ~46 ~54 ~77 stone
fill ~59 ~44 ~77 ~59 ~55 ~86 stone
fill ~68 ~44 ~77 ~93 ~46 ~85 stone
fill ~101 ~44 ~77 ~106 ~55 ~82 stone
fill ~116 ~44 ~77 ~122 ~54 ~83 stone
fill ~131 ~44 ~77 ~131 ~53 ~85 stone
fill ~9 ~44 ~78 ~9 ~46 ~78 stone
fill ~40 ~44 ~78 ~41 ~55 ~84 stone
fill ~47 ~44 ~78 ~47 ~55 ~83 stone
fill ~49 ~44 ~78 ~49 ~55 ~82 stone
fill ~57 ~44 ~78 ~60 ~55 ~85 stone
fill ~67 ~44 ~78 ~93 ~46 ~84 stone
fill ~123 ~44 ~78 ~123 ~55 ~82 stone
fill ~129 ~44 ~78 ~132 ~53 ~84 stone
fill ~153 ~44 ~78 ~153 ~45 ~78 stone
fill ~9 ~44 ~79 ~10 ~45 ~80 sandstone
fill ~37 ~44 ~79 ~37 ~55 ~83 stone
fill ~48 ~44 ~79 ~49 ~55 ~82 stone
fill ~56 ~44 ~79 ~60 ~55 ~85 stone
fill ~66 ~44 ~79 ~95 ~46 ~82 stone
fill ~100 ~44 ~79 ~108 ~55 ~81 stone
fill ~114 ~44 ~79 ~125 ~55 ~82 stone
fill ~128 ~44 ~79 ~133 ~53 ~83 stone
fill ~152 ~44 ~79 ~153 ~46 ~79 sandstone
fill ~8 ~44 ~80 ~10 ~45 ~80 sandstone
fill ~36 ~44 ~80 ~50 ~55 ~82 stone
fill ~51 ~44 ~80 ~51 ~55 ~80 stone
fill ~61 ~44 ~80 ~61 ~55 ~85 stone
fill ~65 ~44 ~80 ~96 ~46 ~81 stone
fill ~109 ~44 ~80 ~109 ~55 ~80 stone
fill ~112 ~44 ~80 ~134 ~53 ~82 stone
fill ~136 ~44 ~80 ~136 ~52 ~81 stone
fill ~12 ~44 ~81 ~12 ~45 ~81 sandstone
fill ~25 ~44 ~81 ~26 ~51 ~81 stone
fill ~54 ~44 ~81 ~62 ~55 ~83 stone
fill ~137 ~44 ~81 ~137 ~51 ~81 stone
fill ~150 ~44 ~81 ~150 ~45 ~81 sandstone
fill ~26 ~44 ~82 ~26 ~52 ~82 stone
fill ~28 ~44 ~82 ~50 ~53 ~82 stone
fill ~53 ~44 ~82 ~62 ~55 ~82 stone
fill ~111 ~44 ~82 ~134 ~53 ~82 stone
fill ~152 ~44 ~82 ~153 ~45 ~83 sandstone
fill ~154 ~44 ~82 ~154 ~46 ~82 sandstone
fill ~9 ~44 ~83 ~10 ~46 ~83 sandstone
fill ~34 ~44 ~83 ~34 ~55 ~83 stone
fill ~38 ~44 ~83 ~48 ~55 ~83 stone
fill ~106 ~44 ~83 ~106 ~55 ~83 stone
fill ~113 ~44 ~83 ~122 ~55 ~83 stone
fill ~125 ~44 ~83 ~125 ~55 ~83 stone
fill ~9 ~44 ~84 ~9 ~45 ~84 stone
fill ~30 ~44 ~84 ~33 ~53 ~84 stone
fill ~39 ~44 ~84 ~46 ~54 ~84 stone
fill ~102 ~44 ~84 ~105 ~55 ~84 stone
fill ~113 ~44 ~84 ~113 ~55 ~84 stone
fill ~115 ~44 ~84 ~117 ~55 ~84 stone
fill ~122 ~44 ~84 ~122 ~55 ~84 stone
fill ~153 ~44 ~84 ~153 ~46 ~84 stone
fill ~31 ~44 ~85 ~31 ~53 ~85 stone
fill ~40 ~44 ~85 ~40 ~54 ~85 stone
fill ~42 ~44 ~85 ~44 ~54 ~85 stone
fill ~46 ~44 ~85 ~46 ~54 ~85 stone
fill ~103 ~44 ~85 ~103 ~55 ~85 stone
fill ~116 ~44 ~85 ~120 ~54 ~85 stone
fill ~43 ~44 ~86 ~43 ~54 ~86 stone
fill ~57 ~44 ~87 ~57 ~53 ~87 stone
setblock ~92 ~44 ~90 stone
fill ~71 ~44 ~91 ~91 ~46 ~91 stone
fill ~87 ~44 ~93 ~87 ~57 ~93 stone
fill ~18 ~44 ~94 ~18 ~45 ~94 sandstone
fill ~73 ~44 ~94 ~85 ~46 ~94 stone
fill ~144 ~44 ~94 ~144 ~45 ~94 sandstone
fill ~74 ~44 ~95 ~83 ~46 ~95 stone
fill ~17 ~44 ~96 ~17 ~45 ~98 sandstone
fill ~20 ~44 ~96 ~20 ~46 ~97 sandstone
fill ~75 ~44 ~96 ~80 ~46 ~96 stone
fill ~143 ~44 ~96 ~143 ~45 ~98 sandstone
fill ~146 ~44 ~96 ~146 ~46 ~97 sandstone
fill ~15 ~44 ~97 ~15 ~46 ~97 stone
fill ~16 ~44 ~97 ~17 ~45 ~97 sandstone
fill ~21 ~44 ~97 ~21 ~45 ~97 stone
fill ~141 ~44 ~97 ~141 ~46 ~97 stone
fill ~142 ~44 ~97 ~143 ~45 ~97 sandstone
fill ~147 ~44 ~97 ~147 ~45 ~97 stone
fill ~81 ~44 ~100 ~83 ~55 ~108 stone
fill ~105 ~44 ~100 ~105 ~44 ~105 sandstone
setblock ~106 ~44 ~100 end_stone
fill ~109 ~44 ~100 ~109 ~51 ~103 stone
fill ~58 ~44 ~101 ~58 ~44 ~102 stone
fill ~80 ~44 ~101 ~85 ~55 ~106 stone
fill ~104 ~44 ~101 ~104 ~44 ~104 end_stone
fill ~106 ~44 ~101 ~107 ~44 ~102 sandstone
fill ~108 ~44 ~101 ~109 ~51 ~103 stone
fill ~57 ~44 ~102 ~57 ~51 ~102 stone
fill ~59 ~44 ~102 ~60 ~44 ~103 sandstone
fill ~78 ~44 ~102 ~85 ~55 ~105 stone
fill ~102 ~44 ~102 ~103 ~44 ~103 sandstone
fill ~110 ~44 ~102 ~110 ~50 ~102 stone
fill ~53 ~44 ~103 ~53 ~44 ~105 end_stone
setblock ~57 ~44 ~103 end_stone
fill ~77 ~44 ~103 ~86 ~55 ~103 stone
setblock ~106 ~44 ~103 end_stone
setblock ~107 ~44 ~103 sandstone
fill ~54 ~44 ~104 ~56 ~45 ~104 end_stone
fill ~57 ~44 ~104 ~57 ~44 ~106 sandstone
fill ~60 ~44 ~104 ~61 ~44 ~104 end_stone
fill ~101 ~44 ~104 ~102 ~44 ~104 stone
fill ~106 ~44 ~104 ~106 ~44 ~109 sandstone
fill ~107 ~44 ~104 ~107 ~44 ~105 end_stone
fill ~109 ~44 ~104 ~109 ~44 ~107 sandstone
fill ~110 ~44 ~104 ~110 ~47 ~104 end_stone
fill ~55 ~44 ~105 ~56 ~45 ~105 end_stone
fill ~58 ~44 ~105 ~62 ~44 ~105 sandstone
fill ~87 ~44 ~105 ~87 ~53 ~105 stone
fill ~102 ~44 ~105 ~102 ~51 ~105 stone
setblock ~103 ~44 ~105 end_stone
fill ~104 ~44 ~105 ~106 ~44 ~105 sandstone
fill ~110 ~44 ~105 ~110 ~48 ~105 sandstone
fill ~53 ~44 ~106 ~58 ~44 ~106 sandstone
setblock ~59 ~44 ~106 end_stone
fill ~61 ~44 ~106 ~61 ~44 ~107 sandstone
setblock ~62 ~44 ~106 end_stone
fill ~79 ~44 ~106 ~85 ~55 ~106 stone
setblock ~103 ~44 ~106 sandstone
fill ~104 ~44 ~106 ~105 ~45 ~107 end_stone
fill ~107 ~44 ~106 ~107 ~45 ~108 sandstone
setblock ~110 ~44 ~106 sandstone
fill ~54 ~44 ~107 ~56 ~45 ~107 sandstone
fill ~57 ~44 ~107 ~58 ~44 ~107 end_stone
fill ~59 ~44 ~107 ~62 ~44 ~107 sandstone
fill ~108 ~44 ~107 ~109 ~44 ~107 sandstone
fill ~110 ~44 ~107 ~110 ~45 ~107 stone
setblock ~54 ~44 ~108 end_stone
fill ~55 ~44 ~108 ~57 ~44 ~109 sandstone
fill ~59 ~44 ~108 ~62 ~51 ~109 stone
fill ~104 ~44 ~108 ~104 ~45 ~108 end_stone
fill ~105 ~44 ~108 ~105 ~48 ~108 sandstone
setblock ~108 ~44 ~108 end_stone
setblock ~109 ~44 ~108 stone
setblock ~54 ~44 ~109 stone
setblock ~58 ~44 ~109 sandstone
fill ~82 ~44 ~109 ~82 ~55 ~109 stone
fill ~103 ~44 ~109 ~105 ~44 ~109 end_stone
fill ~55 ~44 ~110 ~55 ~45 ~110 stone
fill ~56 ~44 ~110 ~57 ~44 ~110 sandstone
fill ~58 ~44 ~110 ~58 ~47 ~110 end_stone
fill ~60 ~44 ~110 ~60 ~50 ~110 stone
fill ~80 ~44 ~111 ~80 ~55 ~130 stone
fill ~81 ~44 ~112 ~82 ~53 ~134 stone
fill ~78 ~44 ~113 ~82 ~55 ~113 stone
fill ~79 ~44 ~114 ~83 ~55 ~122 stone
fill ~78 ~44 ~115 ~83 ~55 ~117 stone
fill ~77 ~44 ~116 ~85 ~54 ~118 stone
fill ~86 ~44 ~118 ~86 ~54 ~120 stone
fill ~77 ~44 ~120 ~77 ~54 ~120 stone
fill ~85 ~44 ~120 ~85 ~54 ~122 stone
fill ~78 ~44 ~122 ~85 ~54 ~122 stone
fill ~83 ~44 ~123 ~83 ~55 ~125 stone
fill ~84 ~44 ~123 ~84 ~55 ~123 stone
fill ~79 ~44 ~125 ~83 ~55 ~125 stone
fill ~83 ~44 ~128 ~83 ~53 ~133 stone
fill ~84 ~44 ~129 ~84 ~53 ~132 stone
fill ~85 ~44 ~131 ~85 ~53 ~131 stone
fill ~82 ~44 ~136 ~82 ~52 ~136 stone
fill ~81 ~44 ~137 ~81 ~51 ~137 stone
fill ~65 ~44 ~141 ~65 ~46 ~141 stone
fill ~97 ~44 ~141 ~97 ~45 ~141 stone
fill ~65 ~44 ~142 ~66 ~45 ~143 sandstone
fill ~96 ~44 ~142 ~97 ~46 ~142 sandstone
fill ~64 ~44 ~143 ~66 ~45 ~143 sandstone
fill ~68 ~44 ~144 ~68 ~45 ~144 sandstone
fill ~94 ~44 ~144 ~94 ~45 ~144 sandstone
fill ~96 ~44 ~145 ~97 ~45 ~146 sandstone
fill ~98 ~44 ~145 ~98 ~46 ~145 sandstone
fill ~65 ~44 ~146 ~66 ~46 ~146 sandstone
fill ~65 ~44 ~147 ~65 ~45 ~147 stone
fill ~97 ~44 ~147 ~97 ~46 ~147 stone
fill ~81 ~44 ~150 ~81 ~45 ~150 sandstone
fill ~80 ~44 ~152 ~80 ~45 ~154 sandstone
fill ~83 ~44 ~152 ~83 ~46 ~153 sandstone
fill ~78 ~44 ~153 ~78 ~46 ~153 stone
fill ~79 ~44 ~153 ~80 ~45 ~153 sandstone
fill ~84 ~44 ~153 ~84 ~45 ~153 stone
fill ~81 ~45 ~6 ~81 ~45 ~10 quartz_block
fill ~78 ~45 ~8 ~78 ~47 ~8 sandstone
fill ~84 ~45 ~8 ~84 ~49 ~8 sandstone
fill ~64 ~45 ~15 ~64 ~49 ~15 sandstone
fill ~98 ~45 ~15 ~98 ~47 ~15 sandstone
fill ~62 ~45 ~18 ~66 ~45 ~18 quartz_block
fill ~96 ~45 ~18 ~99 ~45 ~18 quartz_block
fill ~64 ~45 ~21 ~64 ~47 ~21 sandstone
fill ~98 ~45 ~21 ~98 ~49 ~21 sandstone
fill ~84 ~45 ~26 ~84 ~51 ~26 stone
fill ~81 ~45 ~27 ~81 ~52 ~51 stone
fill ~79 ~45 ~28 ~83 ~52 ~50 stone
fill ~78 ~45 ~29 ~84 ~52 ~33 stone
fill ~85 ~45 ~30 ~85 ~52 ~32 stone
fill ~78 ~45 ~37 ~83 ~54 ~48 stone
fill ~84 ~45 ~37 ~84 ~54 ~38 stone
fill ~77 ~45 ~39 ~83 ~54 ~47 stone
fill ~76 ~45 ~40 ~83 ~54 ~46 stone
fill ~75 ~45 ~42 ~83 ~53 ~44 stone
fill ~84 ~45 ~42 ~85 ~48 ~48 stone
fill ~86 ~45 ~43 ~86 ~54 ~46 stone
fill ~84 ~45 ~50 ~85 ~55 ~50 stone
fill ~80 ~45 ~51 ~80 ~55 ~62 stone
fill ~83 ~45 ~51 ~83 ~55 ~61 stone
fill ~84 ~45 ~51 ~84 ~55 ~51 stone
fill ~104 ~45 ~51 ~104 ~46 ~51 sandstone
fill ~105 ~45 ~51 ~105 ~46 ~51 end_stone
setblock ~57 ~45 ~52 end_stone
fill ~58 ~45 ~52 ~59 ~46 ~52 sandstone
fill ~79 ~45 ~52 ~80 ~55 ~62 stone
fill ~82 ~45 ~52 ~83 ~55 ~61 stone
fill ~100 ~45 ~52 ~102 ~48 ~54 stone
fill ~105 ~45 ~52 ~105 ~48 ~52 sandstone
fill ~106 ~45 ~52 ~106 ~46 ~53 end_stone
fill ~56 ~45 ~53 ~56 ~46 ~54 end_stone
fill ~57 ~45 ~53 ~58 ~45 ~53 sandstone
fill ~59 ~45 ~53 ~59 ~45 ~54 end_stone
fill ~60 ~45 ~53 ~60 ~46 ~53 sandstone
fill ~81 ~45 ~53 ~83 ~55 ~61 stone
fill ~99 ~45 ~53 ~103 ~45 ~55 stone
fill ~104 ~45 ~53 ~107 ~45 ~53 end_stone
fill ~108 ~45 ~53 ~108 ~45 ~55 sandstone
fill ~53 ~45 ~54 ~55 ~45 ~54 sandstone
fill ~60 ~45 ~54 ~60 ~45 ~55 stone
fill ~78 ~45 ~54 ~83 ~55 ~61 stone
fill ~98 ~45 ~54 ~98 ~49 ~54 sandstone
fill ~107 ~45 ~54 ~107 ~46 ~54 end_stone
fill ~53 ~45 ~55 ~53 ~45 ~58 end_stone
fill ~54 ~45 ~55 ~54 ~46 ~55 end_stone
fill ~56 ~45 ~55 ~56 ~45 ~56 sandstone
setblock ~98 ~45 ~55 end_stone
fill ~104 ~45 ~55 ~105 ~50 ~58 stone
fill ~52 ~45 ~56 ~53 ~46 ~56 end_stone
fill ~59 ~45 ~56 ~59 ~50 ~57 stone
fill ~61 ~45 ~56 ~61 ~45 ~57 stone
fill ~84 ~45 ~56 ~84 ~55 ~60 stone
fill ~99 ~45 ~56 ~99 ~46 ~56 end_stone
setblock ~100 ~45 ~56 stone
fill ~101 ~45 ~56 ~101 ~45 ~57 end_stone
setblock ~103 ~45 ~56 sandstone
fill ~108 ~45 ~56 ~109 ~46 ~56 end_stone
fill ~51 ~45 ~57 ~51 ~46 ~57 end_stone
fill ~52 ~45 ~57 ~52 ~48 ~57 sandstone
fill ~55 ~45 ~57 ~60 ~51 ~57 stone
fill ~76 ~45 ~57 ~84 ~55 ~59 stone
fill ~100 ~45 ~57 ~101 ~45 ~57 end_stone
fill ~102 ~45 ~57 ~102 ~46 ~57 sandstone
fill ~103 ~45 ~57 ~103 ~45 ~61 end_stone
fill ~109 ~45 ~57 ~109 ~45 ~58 sandstone
setblock ~110 ~45 ~57 end_stone
fill ~51 ~45 ~58 ~51 ~46 ~58 sandstone
fill ~55 ~45 ~58 ~55 ~51 ~61 stone
fill ~56 ~45 ~58 ~58 ~50 ~58 stone
fill ~60 ~45 ~58 ~61 ~45 ~58 sandstone
fill ~75 ~45 ~58 ~85 ~54 ~58 stone
fill ~101 ~45 ~58 ~102 ~45 ~58 sandstone
fill ~110 ~45 ~58 ~110 ~46 ~59 sandstone
fill ~56 ~45 ~59 ~56 ~45 ~60 sandstone
fill ~57 ~45 ~59 ~61 ~45 ~59 end_stone
fill ~86 ~45 ~59 ~86 ~55 ~59 stone
fill ~101 ~45 ~59 ~103 ~45 ~59 end_stone
fill ~104 ~45 ~59 ~104 ~47 ~59 sandstone
fill ~105 ~45 ~59 ~105 ~51 ~60 stone
fill ~106 ~45 ~59 ~106 ~50 ~59 stone
fill ~108 ~45 ~59 ~109 ~45 ~59 end_stone
fill ~57 ~45 ~60 ~58 ~45 ~60 sandstone
fill ~59 ~45 ~60 ~60 ~45 ~60 end_stone
fill ~85 ~45 ~60 ~85 ~55 ~60 stone
fill ~102 ~45 ~60 ~103 ~45 ~60 end_stone
fill ~104 ~45 ~60 ~104 ~45 ~61 sandstone
fill ~107 ~45 ~60 ~108 ~45 ~60 stone
fill ~109 ~45 ~60 ~109 ~46 ~60 sandstone
fill ~52 ~45 ~61 ~54 ~48 ~62 stone
fill ~56 ~45 ~61 ~57 ~45 ~61 end_stone
setblock ~58 ~45 ~61 sandstone
fill ~59 ~45 ~61 ~59 ~46 ~61 end_stone
fill ~105 ~45 ~61 ~106 ~45 ~61 stone
fill ~55 ~45 ~62 ~56 ~45 ~62 stone
setblock ~57 ~45 ~62 end_stone
fill ~144 ~45 ~62 ~144 ~45 ~66 quartz_block
fill ~18 ~45 ~63 ~18 ~45 ~66 quartz_block
fill ~53 ~45 ~63 ~55 ~45 ~63 stone
fill ~56 ~45 ~63 ~56 ~46 ~63 end_stone
fill ~80 ~45 ~63 ~80 ~48 ~63 stone
fill ~15 ~45 ~64 ~15 ~47 ~64 sandstone
fill ~21 ~45 ~64 ~21 ~49 ~64 sandstone
fill ~54 ~45 ~64 ~54 ~49 ~64 sandstone
setblock ~55 ~45 ~64 end_stone
fill ~141 ~45 ~64 ~141 ~47 ~64 sandstone
fill ~147 ~45 ~64 ~147 ~49 ~64 sandstone
fill ~78 ~45 ~66 ~79 ~46 ~96 stone
fill ~80 ~45 ~67 ~80 ~55 ~72 stone
fill ~75 ~45 ~68 ~83 ~46 ~95 stone
fill ~74 ~45 ~69 ~84 ~46 ~94 stone
fill ~86 ~45 ~69 ~87 ~53 ~77 stone
fill ~88 ~45 ~70 ~89 ~53 ~92 stone
fill ~73 ~45 ~71 ~90 ~46 ~92 stone
fill ~93 ~45 ~73 ~93 ~47 ~87 stone
fill ~71 ~45 ~74 ~90 ~46 ~92 stone
fill ~94 ~45 ~74 ~94 ~46 ~84 stone
fill ~69 ~45 ~75 ~74 ~53 ~86 stone
fill ~95 ~45 ~75 ~95 ~46 ~83 stone
fill ~104 ~45 ~75 ~105 ~53 ~84 stone
fill ~118 ~45 ~75 ~120 ~53 ~83 stone
fill ~43 ~45 ~76 ~46 ~48 ~86 stone
fill ~59 ~45 ~76 ~59 ~55 ~86 stone
fill ~67 ~45 ~76 ~74 ~53 ~85 stone
fill ~96 ~45 ~76 ~96 ~46 ~82 stone
fill ~116 ~45 ~76 ~122 ~54 ~83 stone
fill ~30 ~45 ~77 ~31 ~52 ~84 stone
fill ~47 ~45 ~77 ~48 ~54 ~84 stone
fill ~50 ~45 ~77 ~50 ~55 ~83 stone
fill ~58 ~45 ~77 ~60 ~55 ~85 stone
fill ~66 ~45 ~77 ~94 ~46 ~84 stone
fill ~115 ~45 ~77 ~123 ~54 ~83 stone
fill ~8 ~45 ~78 ~8 ~49 ~78 sandstone
fill ~26 ~45 ~78 ~26 ~51 ~78 stone
fill ~29 ~45 ~78 ~33 ~52 ~84 stone
fill ~37 ~45 ~78 ~37 ~54 ~84 stone
fill ~42 ~45 ~78 ~51 ~48 ~82 stone
fill ~56 ~45 ~78 ~60 ~55 ~85 stone
fill ~65 ~45 ~78 ~96 ~46 ~82 stone
fill ~97 ~45 ~78 ~97 ~46 ~78 stone
fill ~108 ~45 ~78 ~108 ~55 ~83 stone
fill ~114 ~45 ~78 ~125 ~54 ~83 stone
fill ~133 ~45 ~78 ~133 ~52 ~84 stone
fill ~154 ~45 ~78 ~154 ~47 ~78 sandstone
fill ~28 ~45 ~79 ~50 ~52 ~83 stone
fill ~52 ~45 ~79 ~61 ~55 ~80 stone
fill ~109 ~45 ~79 ~109 ~55 ~83 stone
fill ~110 ~45 ~79 ~110 ~55 ~80 stone
fill ~112 ~45 ~79 ~128 ~55 ~83 stone
fill ~134 ~45 ~79 ~134 ~52 ~83 stone
fill ~98 ~45 ~80 ~134 ~46 ~80 stone
fill ~6 ~45 ~81 ~10 ~45 ~81 quartz_block
fill ~27 ~45 ~81 ~51 ~52 ~81 stone
fill ~53 ~45 ~81 ~62 ~55 ~83 stone
fill ~64 ~45 ~81 ~96 ~47 ~81 stone
fill ~111 ~45 ~81 ~130 ~55 ~82 stone
fill ~135 ~45 ~81 ~137 ~51 ~81 stone
fill ~152 ~45 ~81 ~156 ~45 ~81 quartz_block
fill ~52 ~45 ~82 ~62 ~55 ~83 stone
fill ~63 ~45 ~82 ~63 ~48 ~82 stone
fill ~110 ~45 ~82 ~128 ~55 ~83 stone
fill ~101 ~45 ~83 ~128 ~55 ~83 stone
fill ~8 ~45 ~84 ~8 ~47 ~84 sandstone
fill ~38 ~45 ~84 ~48 ~54 ~84 stone
fill ~54 ~45 ~84 ~54 ~55 ~84 stone
fill ~106 ~45 ~84 ~106 ~55 ~84 stone
fill ~111 ~45 ~84 ~117 ~55 ~84 stone
fill ~120 ~45 ~84 ~122 ~54 ~84 stone
fill ~125 ~45 ~84 ~125 ~54 ~84 stone
fill ~136 ~45 ~84 ~136 ~51 ~84 stone
fill ~154 ~45 ~84 ~154 ~49 ~84 sandstone
fill ~39 ~45 ~85 ~47 ~54 ~85 stone
fill ~102 ~45 ~85 ~104 ~55 ~85 stone
fill ~112 ~45 ~85 ~112 ~55 ~85 stone
fill ~114 ~45 ~85 ~120 ~54 ~85 stone
fill ~132 ~45 ~85 ~132 ~52 ~85 stone
fill ~40 ~45 ~86 ~46 ~54 ~86 stone
fill ~57 ~45 ~86 ~58 ~53 ~87 stone
fill ~68 ~45 ~86 ~93 ~46 ~86 stone
fill ~103 ~45 ~86 ~103 ~55 ~86 stone
fill ~116 ~45 ~86 ~119 ~54 ~86 stone
fill ~42 ~45 ~87 ~44 ~53 ~87 stone
fill ~70 ~45 ~87 ~91 ~46 ~91 stone
fill ~69 ~45 ~88 ~92 ~47 ~89 stone
fill ~93 ~45 ~89 ~93 ~46 ~89 stone
fill ~72 ~45 ~93 ~88 ~46 ~93 stone
fill ~86 ~45 ~94 ~86 ~56 ~94 stone
fill ~18 ~45 ~96 ~18 ~45 ~100 quartz_block
fill ~74 ~45 ~96 ~81 ~46 ~96 stone
fill ~144 ~45 ~96 ~144 ~45 ~99 quartz_block
setblock ~78 ~45 ~97 stone
fill ~15 ~45 ~98 ~15 ~49 ~98 sandstone
fill ~21 ~45 ~98 ~21 ~47 ~98 sandstone
setblock ~107 ~45 ~98 end_stone
fill ~108 ~45 ~98 ~108 ~49 ~98 sandstone
fill ~141 ~45 ~98 ~141 ~49 ~98 sandstone
fill ~147 ~45 ~98 ~147 ~47 ~98 sandstone
fill ~82 ~45 ~99 ~82 ~48 ~134 stone
fill ~106 ~45 ~99 ~106 ~46 ~99 end_stone
fill ~107 ~45 ~99 ~109 ~45 ~103 stone
fill ~105 ~45 ~100 ~105 ~45 ~101 end_stone
fill ~106 ~45 ~100 ~110 ~45 ~100 stone
fill ~56 ~45 ~101 ~57 ~45 ~101 stone
fill ~58 ~45 ~101 ~58 ~45 ~103 sandstone
fill ~59 ~45 ~101 ~59 ~45 ~105 end_stone
fill ~79 ~45 ~101 ~80 ~55 ~128 stone
fill ~103 ~45 ~101 ~103 ~45 ~103 end_stone
fill ~104 ~45 ~101 ~104 ~45 ~102 sandstone
setblock ~106 ~45 ~101 end_stone
fill ~110 ~45 ~101 ~110 ~48 ~102 stone
fill ~53 ~45 ~102 ~53 ~46 ~102 sandstone
fill ~54 ~45 ~102 ~55 ~45 ~102 stone
fill ~60 ~45 ~102 ~60 ~45 ~103 end_stone
fill ~77 ~45 ~102 ~85 ~55 ~104 stone
fill ~102 ~45 ~102 ~103 ~45 ~103 end_stone
fill ~105 ~45 ~102 ~106 ~45 ~102 sandstone
fill ~52 ~45 ~103 ~52 ~46 ~104 sandstone
fill ~53 ~45 ~103 ~54 ~45 ~103 end_stone
fill ~56 ~45 ~103 ~57 ~50 ~103 stone
fill ~61 ~45 ~103 ~61 ~46 ~103 end_stone
fill ~76 ~45 ~103 ~86 ~55 ~103 stone
fill ~101 ~45 ~103 ~105 ~45 ~103 end_stone
setblock ~106 ~45 ~103 sandstone
fill ~53 ~45 ~104 ~53 ~45 ~105 sandstone
fill ~57 ~45 ~104 ~58 ~50 ~107 stone
fill ~60 ~45 ~104 ~60 ~45 ~106 sandstone
setblock ~61 ~45 ~104 sandstone
fill ~87 ~45 ~104 ~87 ~53 ~105 stone
fill ~101 ~45 ~104 ~103 ~45 ~104 sandstone
fill ~104 ~45 ~104 ~107 ~50 ~105 stone
fill ~109 ~45 ~104 ~109 ~45 ~107 end_stone
fill ~111 ~45 ~104 ~111 ~46 ~104 sandstone
setblock ~52 ~45 ~105 end_stone
fill ~61 ~45 ~105 ~62 ~45 ~105 end_stone
fill ~86 ~45 ~105 ~87 ~53 ~105 stone
fill ~101 ~45 ~105 ~107 ~45 ~105 stone
fill ~111 ~45 ~105 ~111 ~46 ~105 end_stone
fill ~53 ~45 ~106 ~54 ~46 ~106 end_stone
fill ~55 ~45 ~106 ~56 ~45 ~107 sandstone
fill ~59 ~45 ~106 ~60 ~45 ~106 sandstone
setblock ~61 ~45 ~106 end_stone
fill ~62 ~45 ~106 ~62 ~45 ~110 stone
fill ~63 ~45 ~106 ~63 ~46 ~106 end_stone
fill ~78 ~45 ~106 ~85 ~55 ~106 stone
setblock ~101 ~45 ~106 stone
fill ~103 ~45 ~106 ~103 ~50 ~106 stone
fill ~106 ~45 ~106 ~107 ~45 ~107 sandstone
fill ~110 ~45 ~106 ~110 ~46 ~106 end_stone
fill ~59 ~45 ~107 ~61 ~51 ~109 stone
fill ~63 ~45 ~107 ~63 ~45 ~109 stone
setblock ~64 ~45 ~107 end_stone
fill ~102 ~45 ~107 ~102 ~46 ~107 stone
fill ~108 ~45 ~107 ~109 ~45 ~107 end_stone
fill ~54 ~45 ~108 ~54 ~45 ~109 sandstone
fill ~55 ~45 ~108 ~55 ~46 ~108 end_stone
fill ~64 ~45 ~108 ~64 ~49 ~108 sandstone
fill ~84 ~45 ~108 ~84 ~55 ~108 stone
setblock ~102 ~45 ~108 stone
fill ~103 ~45 ~108 ~104 ~45 ~108 end_stone
fill ~106 ~45 ~108 ~106 ~46 ~109 end_stone
fill ~108 ~45 ~108 ~109 ~45 ~108 sandstone
fill ~55 ~45 ~109 ~58 ~45 ~109 end_stone
fill ~81 ~45 ~109 ~83 ~55 ~109 stone
fill ~102 ~45 ~109 ~102 ~46 ~109 sandstone
setblock ~103 ~45 ~109 end_stone
fill ~104 ~45 ~109 ~105 ~45 ~109 sandstone
fill ~56 ~45 ~110 ~56 ~46 ~110 end_stone
fill ~57 ~45 ~110 ~57 ~48 ~110 sandstone
fill ~61 ~45 ~110 ~62 ~48 ~110 stone
fill ~83 ~45 ~110 ~83 ~55 ~110 stone
fill ~103 ~45 ~110 ~104 ~46 ~110 sandstone
setblock ~105 ~45 ~110 end_stone
fill ~57 ~45 ~111 ~57 ~46 ~111 end_stone
fill ~58 ~45 ~111 ~58 ~46 ~111 sandstone
fill ~78 ~45 ~111 ~82 ~55 ~117 stone
fill ~77 ~45 ~112 ~83 ~55 ~112 stone
fill ~83 ~45 ~113 ~83 ~55 ~128 stone
fill ~77 ~45 ~114 ~84 ~48 ~120 stone
fill ~85 ~45 ~115 ~85 ~54 ~123 stone
fill ~76 ~45 ~116 ~86 ~54 ~118 stone
fill ~76 ~45 ~119 ~87 ~48 ~119 stone
fill ~87 ~45 ~120 ~87 ~53 ~120 stone
fill ~86 ~45 ~121 ~86 ~54 ~122 stone
fill ~84 ~45 ~124 ~84 ~54 ~125 stone
fill ~78 ~45 ~125 ~84 ~54 ~125 stone
fill ~77 ~45 ~132 ~84 ~52 ~132 stone
fill ~78 ~45 ~133 ~84 ~52 ~133 stone
fill ~79 ~45 ~134 ~83 ~52 ~134 stone
fill ~81 ~45 ~135 ~81 ~51 ~137 stone
fill ~78 ~45 ~136 ~78 ~51 ~136 stone
fill ~64 ~45 ~141 ~64 ~49 ~141 sandstone
fill ~98 ~45 ~141 ~98 ~47 ~141 sandstone
fill ~63 ~45 ~144 ~66 ~45 ~144 quartz_block
fill ~96 ~45 ~144 ~100 ~45 ~144 quartz_block
fill ~64 ~45 ~147 ~64 ~47 ~147 sandstone
fill ~98 ~45 ~147 ~98 ~49 ~147 sandstone
fill ~81 ~45 ~152 ~81 ~45 ~156 quartz_block
fill ~78 ~45 ~154 ~78 ~49 ~154 sandstone
fill ~84 ~45 ~154 ~84 ~47 ~154 sandstone
fill ~81 ~46 ~5 ~81 ~52 ~5 quartz_block
fill ~81 ~46 ~6 ~81 ~47 ~7 quartz_block
fill ~80 ~46 ~7 ~80 ~49 ~7 sandstone
fill ~82 ~46 ~7 ~82 ~48 ~7 sandstone
fill ~83 ~46 ~7 ~83 ~48 ~7 stone
fill ~79 ~46 ~8 ~84 ~46 ~8 sandstone
fill ~77 ~46 ~9 ~78 ~47 ~9 sandstone
fill ~80 ~46 ~9 ~82 ~46 ~9 stone
setblock ~78 ~46 ~10 stone
setblock ~80 ~46 ~10 sandstone
fill ~81 ~46 ~10 ~81 ~46 ~11 stone
fill ~82 ~46 ~10 ~83 ~46 ~10 sandstone
fill ~84 ~46 ~10 ~84 ~47 ~10 stone
fill ~79 ~46 ~11 ~81 ~46 ~11 stone
setblock ~82 ~46 ~11 sandstone
fill ~83 ~46 ~11 ~83 ~47 ~11 stone
setblock ~81 ~46 ~12 diamond_ore
fill ~81 ~46 ~13 ~81 ~48 ~13 stone
fill ~97 ~46 ~14 ~97 ~47 ~15 sandstone
fill ~66 ~46 ~15 ~66 ~47 ~15 stone
setblock ~96 ~46 ~15 stone
fill ~63 ~46 ~16 ~63 ~48 ~16 stone
fill ~64 ~46 ~16 ~64 ~46 ~21 sandstone
fill ~65 ~46 ~16 ~66 ~46 ~16 sandstone
fill ~67 ~46 ~16 ~67 ~47 ~16 stone
fill ~95 ~46 ~16 ~95 ~46 ~18 stone
fill ~98 ~46 ~16 ~98 ~46 ~21 sandstone
fill ~63 ~46 ~17 ~63 ~48 ~17 sandstone
fill ~65 ~46 ~17 ~65 ~46 ~19 stone
fill ~66 ~46 ~17 ~67 ~46 ~17 sandstone
setblock ~96 ~46 ~17 sandstone
fill ~97 ~46 ~17 ~97 ~46 ~19 stone
fill ~61 ~46 ~18 ~61 ~52 ~18 quartz_block
fill ~62 ~46 ~18 ~63 ~47 ~18 quartz_block
fill ~66 ~46 ~18 ~67 ~46 ~18 stone
setblock ~68 ~46 ~18 diamond_ore
fill ~69 ~46 ~18 ~69 ~48 ~18 stone
fill ~93 ~46 ~18 ~93 ~48 ~18 stone
setblock ~94 ~46 ~18 diamond_ore
fill ~96 ~46 ~18 ~97 ~46 ~18 stone
fill ~99 ~46 ~18 ~100 ~47 ~18 quartz_block
fill ~63 ~46 ~19 ~64 ~47 ~19 sandstone
fill ~66 ~46 ~19 ~66 ~46 ~20 sandstone
fill ~67 ~46 ~19 ~67 ~46 ~20 stone
fill ~95 ~46 ~19 ~96 ~46 ~19 sandstone
fill ~95 ~46 ~20 ~95 ~47 ~20 stone
fill ~97 ~46 ~20 ~98 ~46 ~20 sandstone
fill ~99 ~46 ~20 ~99 ~48 ~20 stone
fill ~65 ~46 ~21 ~65 ~47 ~22 sandstone
setblock ~66 ~46 ~21 stone
fill ~96 ~46 ~21 ~97 ~46 ~21 stone
fill ~81 ~46 ~24 ~81 ~51 ~62 stone
fill ~80 ~46 ~25 ~81 ~51 ~62 stone
fill ~82 ~46 ~26 ~82 ~52 ~61 stone
fill ~85 ~46 ~29 ~85 ~51 ~33 stone
fill ~77 ~46 ~30 ~85 ~52 ~31 stone
fill ~86 ~46 ~31 ~86 ~53 ~31 stone
fill ~77 ~46 ~33 ~85 ~53 ~33 stone
fill ~78 ~46 ~34 ~83 ~54 ~48 stone
fill ~84 ~46 ~34 ~84 ~54 ~42 stone
fill ~77 ~46 ~37 ~85 ~54 ~37 stone
fill ~75 ~46 ~41 ~83 ~51 ~46 stone
fill ~85 ~46 ~41 ~86 ~54 ~47 stone
fill ~87 ~46 ~44 ~87 ~54 ~44 stone
fill ~85 ~46 ~49 ~85 ~55 ~51 stone
fill ~104 ~46 ~50 ~104 ~47 ~50 end_stone
fill ~60 ~46 ~51 ~60 ~46 ~54 sandstone
fill ~79 ~46 ~51 ~81 ~55 ~62 stone
fill ~99 ~46 ~51 ~99 ~47 ~52 stone
fill ~103 ~46 ~51 ~103 ~48 ~51 end_stone
fill ~106 ~46 ~51 ~106 ~46 ~54 end_stone
fill ~56 ~46 ~52 ~62 ~46 ~52 sandstone
fill ~78 ~46 ~52 ~81 ~55 ~62 stone
fill ~84 ~46 ~52 ~84 ~55 ~54 stone
fill ~103 ~46 ~52 ~104 ~46 ~52 end_stone
fill ~107 ~46 ~52 ~107 ~47 ~53 sandstone
fill ~54 ~46 ~53 ~54 ~47 ~54 end_stone
fill ~55 ~46 ~53 ~55 ~46 ~54 sandstone
fill ~57 ~46 ~53 ~57 ~48 ~53 end_stone
setblock ~58 ~46 ~53 end_stone
fill ~59 ~46 ~53 ~60 ~46 ~54 sandstone
setblock ~61 ~46 ~53 end_stone
setblock ~62 ~46 ~53 sandstone
setblock ~98 ~46 ~53 end_stone
fill ~99 ~46 ~53 ~99 ~46 ~55 sandstone
fill ~104 ~46 ~53 ~104 ~46 ~58 stone
fill ~105 ~46 ~53 ~105 ~47 ~53 sandstone
setblock ~108 ~46 ~53 stone
setblock ~53 ~46 ~54 stone
fill ~58 ~46 ~54 ~61 ~46 ~54 sandstone
fill ~77 ~46 ~54 ~81 ~55 ~62 stone
fill ~97 ~46 ~54 ~97 ~48 ~55 end_stone
setblock ~105 ~46 ~54 sandstone
fill ~108 ~46 ~54 ~109 ~47 ~54 end_stone
fill ~52 ~46 ~55 ~53 ~47 ~55 sandstone
fill ~55 ~46 ~55 ~57 ~46 ~55 end_stone
fill ~58 ~46 ~55 ~58 ~47 ~55 sandstone
fill ~59 ~46 ~55 ~59 ~50 ~57 stone
fill ~60 ~46 ~55 ~60 ~46 ~57 stone
fill ~61 ~46 ~55 ~61 ~48 ~55 end_stone
setblock ~62 ~46 ~55 end_stone
fill ~76 ~46 ~55 ~83 ~54 ~61 stone
fill ~98 ~46 ~55 ~99 ~47 ~55 sandstone
fill ~100 ~46 ~55 ~100 ~47 ~55 end_stone
fill ~101 ~46 ~55 ~106 ~51 ~55 stone
fill ~107 ~46 ~55 ~107 ~46 ~57 end_stone
setblock ~109 ~46 ~55 sandstone
fill ~51 ~46 ~56 ~54 ~46 ~56 end_stone
fill ~55 ~46 ~56 ~57 ~51 ~57 stone
fill ~58 ~46 ~56 ~59 ~50 ~57 stone
fill ~61 ~46 ~56 ~62 ~47 ~56 sandstone
fill ~75 ~46 ~56 ~84 ~53 ~60 stone
fill ~98 ~46 ~56 ~99 ~46 ~56 end_stone
fill ~100 ~46 ~56 ~100 ~46 ~58 sandstone
fill ~101 ~46 ~56 ~106 ~46 ~56 stone
fill ~110 ~46 ~56 ~110 ~46 ~62 sandstone
fill ~53 ~46 ~57 ~54 ~46 ~57 sandstone
setblock ~61 ~46 ~57 end_stone
setblock ~62 ~46 ~57 sandstone
fill ~85 ~46 ~57 ~85 ~55 ~61 stone
fill ~98 ~46 ~57 ~98 ~47 ~57 sandstone
setblock ~99 ~46 ~57 end_stone
fill ~101 ~46 ~57 ~102 ~46 ~57 sandstone
fill ~103 ~46 ~57 ~106 ~50 ~57 stone
fill ~109 ~46 ~57 ~109 ~48 ~57 end_stone
fill ~50 ~46 ~58 ~50 ~47 ~58 end_stone
fill ~53 ~46 ~58 ~54 ~46 ~62 stone
fill ~60 ~46 ~58 ~60 ~47 ~58 end_stone
fill ~61 ~46 ~58 ~61 ~46 ~59 sandstone
fill ~86 ~46 ~58 ~86 ~55 ~60 stone
fill ~101 ~46 ~58 ~101 ~46 ~60 end_stone
setblock ~102 ~46 ~58 end_stone
setblock ~103 ~46 ~58 sandstone
fill ~106 ~46 ~58 ~106 ~50 ~59 stone
fill ~107 ~46 ~58 ~108 ~47 ~58 sandstone
setblock ~109 ~46 ~58 end_stone
fill ~51 ~46 ~59 ~51 ~48 ~59 end_stone
setblock ~52 ~46 ~59 end_stone
fill ~56 ~46 ~59 ~57 ~50 ~59 stone
setblock ~58 ~46 ~59 sandstone
setblock ~59 ~46 ~59 end_stone
fill ~60 ~46 ~59 ~61 ~46 ~59 sandstone
fill ~100 ~46 ~59 ~101 ~46 ~59 end_stone
fill ~102 ~46 ~59 ~102 ~47 ~59 sandstone
setblock ~103 ~46 ~59 end_stone
fill ~107 ~46 ~59 ~107 ~50 ~59 stone
fill ~108 ~46 ~59 ~110 ~46 ~60 sandstone
fill ~56 ~46 ~60 ~56 ~50 ~60 stone
fill ~57 ~46 ~60 ~57 ~46 ~62 sandstone
fill ~58 ~46 ~60 ~58 ~46 ~61 end_stone
fill ~59 ~46 ~60 ~60 ~46 ~60 sandstone
setblock ~61 ~46 ~60 end_stone
fill ~102 ~46 ~60 ~103 ~46 ~60 sandstone
fill ~104 ~46 ~60 ~104 ~47 ~60 end_stone
fill ~106 ~46 ~60 ~107 ~46 ~60 stone
setblock ~111 ~46 ~60 sandstone
setblock ~56 ~46 ~61 stone
setblock ~60 ~46 ~61 end_stone
fill ~84 ~46 ~61 ~85 ~55 ~61 stone
setblock ~102 ~46 ~61 end_stone
fill ~103 ~46 ~61 ~104 ~46 ~61 sandstone
setblock ~105 ~46 ~61 end_stone
fill ~106 ~46 ~61 ~106 ~47 ~62 sandstone
fill ~107 ~46 ~61 ~107 ~48 ~61 end_stone
setblock ~108 ~46 ~61 sandstone
setblock ~109 ~46 ~61 end_stone
fill ~144 ~46 ~61 ~144 ~52 ~61 quartz_block
fill ~18 ~46 ~62 ~18 ~47 ~63 quartz_block
fill ~55 ~46 ~62 ~55 ~47 ~62 end_stone
fill ~56 ~46 ~62 ~58 ~46 ~62 sandstone
setblock ~59 ~46 ~62 end_stone
fill ~76 ~46 ~62 ~81 ~55 ~62 stone
fill ~83 ~46 ~62 ~83 ~55 ~62 stone
fill ~105 ~46 ~62 ~106 ~46 ~62 sandstone
setblock ~107 ~46 ~62 end_stone
fill ~109 ~46 ~62 ~110 ~46 ~62 sandstone
fill ~144 ~46 ~62 ~144 ~47 ~63 quartz_block
fill ~20 ~46 ~63 ~20 ~48 ~63 stone
fill ~51 ~46 ~63 ~52 ~47 ~63 stone
fill ~53 ~46 ~63 ~55 ~46 ~63 sandstone
setblock ~57 ~46 ~63 end_stone
fill ~143 ~46 ~63 ~143 ~49 ~63 sandstone
fill ~145 ~46 ~63 ~145 ~48 ~63 sandstone
fill ~146 ~46 ~63 ~146 ~48 ~63 stone
fill ~16 ~46 ~64 ~21 ~46 ~64 sandstone
setblock ~53 ~46 ~64 end_stone
fill ~55 ~46 ~64 ~55 ~47 ~64 sandstone
fill ~56 ~46 ~64 ~56 ~47 ~64 end_stone
fill ~57 ~46 ~64 ~57 ~47 ~64 sandstone
setblock ~80 ~46 ~64 stone
fill ~142 ~46 ~64 ~147 ~46 ~64 sandstone
fill ~14 ~46 ~65 ~15 ~47 ~65 sandstone
fill ~17 ~46 ~65 ~19 ~46 ~65 stone
fill ~54 ~46 ~65 ~55 ~48 ~65 end_stone
fill ~140 ~46 ~65 ~141 ~47 ~65 sandstone
fill ~143 ~46 ~65 ~145 ~46 ~65 stone
setblock ~15 ~46 ~66 stone
setblock ~17 ~46 ~66 sandstone
fill ~18 ~46 ~66 ~18 ~46 ~67 stone
fill ~19 ~46 ~66 ~20 ~46 ~66 sandstone
fill ~21 ~46 ~66 ~21 ~47 ~66 stone
fill ~77 ~46 ~66 ~79 ~46 ~96 stone
setblock ~141 ~46 ~66 stone
setblock ~143 ~46 ~66 sandstone
fill ~144 ~46 ~66 ~144 ~46 ~67 stone
fill ~145 ~46 ~66 ~146 ~46 ~66 sandstone
fill ~147 ~46 ~66 ~147 ~47 ~66 stone
fill ~16 ~46 ~67 ~18 ~46 ~67 stone
setblock ~19 ~46 ~67 sandstone
fill ~20 ~46 ~67 ~20 ~47 ~67 stone
fill ~76 ~46 ~67 ~83 ~46 ~95 stone
fill ~142 ~46 ~67 ~144 ~46 ~67 stone
setblock ~145 ~46 ~67 sandstone
fill ~146 ~46 ~67 ~146 ~47 ~67 stone
setblock ~18 ~46 ~68 diamond_ore
fill ~74 ~46 ~68 ~86 ~46 ~94 stone
setblock ~144 ~46 ~68 diamond_ore
fill ~18 ~46 ~69 ~18 ~48 ~69 stone
fill ~88 ~46 ~69 ~88 ~46 ~94 stone
fill ~144 ~46 ~69 ~144 ~48 ~69 stone
fill ~73 ~46 ~70 ~90 ~46 ~93 stone
fill ~91 ~46 ~71 ~91 ~46 ~92 stone
fill ~93 ~46 ~72 ~93 ~46 ~89 stone
fill ~71 ~46 ~73 ~74 ~54 ~90 stone
fill ~70 ~46 ~74 ~74 ~53 ~89 stone
fill ~44 ~46 ~75 ~44 ~54 ~87 stone
fill ~67 ~46 ~75 ~94 ~46 ~86 stone
fill ~102 ~46 ~75 ~106 ~53 ~84 stone
fill ~116 ~46 ~75 ~122 ~51 ~83 stone
fill ~31 ~46 ~76 ~31 ~53 ~85 stone
fill ~41 ~46 ~76 ~46 ~48 ~87 stone
fill ~47 ~46 ~76 ~47 ~54 ~85 stone
fill ~58 ~46 ~76 ~60 ~55 ~86 stone
fill ~66 ~46 ~76 ~96 ~46 ~84 stone
fill ~100 ~46 ~76 ~106 ~54 ~81 stone
fill ~107 ~46 ~76 ~107 ~54 ~77 stone
fill ~29 ~46 ~77 ~31 ~51 ~84 stone
fill ~33 ~46 ~77 ~33 ~53 ~85 stone
fill ~37 ~46 ~77 ~37 ~54 ~85 stone
fill ~49 ~46 ~77 ~51 ~55 ~83 stone
fill ~57 ~46 ~77 ~61 ~55 ~86 stone
fill ~97 ~46 ~77 ~97 ~46 ~80 stone
fill ~108 ~46 ~77 ~108 ~55 ~84 stone
fill ~125 ~46 ~77 ~125 ~54 ~85 stone
fill ~129 ~46 ~77 ~129 ~53 ~85 stone
fill ~132 ~46 ~77 ~132 ~52 ~85 stone
fill ~153 ~46 ~77 ~153 ~47 ~78 sandstone
fill ~10 ~46 ~78 ~10 ~47 ~78 stone
fill ~34 ~46 ~78 ~42 ~54 ~84 stone
fill ~52 ~46 ~78 ~54 ~55 ~84 stone
fill ~109 ~46 ~78 ~110 ~55 ~84 stone
fill ~126 ~46 ~78 ~133 ~52 ~84 stone
setblock ~152 ~46 ~78 stone
fill ~7 ~46 ~79 ~7 ~48 ~79 stone
fill ~8 ~46 ~79 ~8 ~46 ~84 sandstone
fill ~9 ~46 ~79 ~10 ~46 ~79 sandstone
fill ~11 ~46 ~79 ~11 ~47 ~79 stone
fill ~62 ~46 ~79 ~62 ~55 ~79 stone
fill ~64 ~46 ~79 ~79 ~55 ~79 stone
fill ~99 ~46 ~79 ~134 ~46 ~81 stone
fill ~151 ~46 ~79 ~151 ~46 ~81 stone
fill ~154 ~46 ~79 ~154 ~46 ~84 sandstone
fill ~7 ~46 ~80 ~7 ~48 ~80 sandstone
fill ~9 ~46 ~80 ~9 ~46 ~82 stone
fill ~10 ~46 ~80 ~11 ~46 ~80 sandstone
fill ~26 ~46 ~80 ~61 ~52 ~82 stone
fill ~135 ~46 ~80 ~136 ~52 ~82 stone
fill ~137 ~46 ~80 ~137 ~51 ~81 stone
setblock ~152 ~46 ~80 sandstone
fill ~153 ~46 ~80 ~153 ~46 ~82 stone
fill ~155 ~46 ~80 ~155 ~49 ~80 sandstone
fill ~5 ~46 ~81 ~5 ~52 ~81 quartz_block
fill ~6 ~46 ~81 ~7 ~47 ~81 quartz_block
fill ~10 ~46 ~81 ~11 ~46 ~81 stone
setblock ~12 ~46 ~81 diamond_ore
fill ~13 ~46 ~81 ~13 ~48 ~81 stone
fill ~24 ~46 ~81 ~62 ~51 ~81 stone
fill ~98 ~46 ~81 ~138 ~48 ~81 stone
fill ~149 ~46 ~81 ~149 ~48 ~81 stone
setblock ~150 ~46 ~81 diamond_ore
fill ~152 ~46 ~81 ~153 ~46 ~81 stone
fill ~155 ~46 ~81 ~157 ~47 ~81 quartz_block
fill ~7 ~46 ~82 ~8 ~47 ~82 sandstone
fill ~10 ~46 ~82 ~10 ~46 ~83 sandstone
fill ~11 ~46 ~82 ~11 ~46 ~83 stone
fill ~25 ~46 ~82 ~62 ~51 ~82 stone
fill ~151 ~46 ~82 ~152 ~46 ~82 sandstone
fill ~155 ~46 ~82 ~155 ~48 ~82 sandstone
fill ~65 ~46 ~83 ~96 ~46 ~83 stone
fill ~100 ~46 ~83 ~128 ~55 ~83 stone
fill ~151 ~46 ~83 ~151 ~47 ~83 stone
fill ~153 ~46 ~83 ~154 ~46 ~83 sandstone
fill ~155 ~46 ~83 ~155 ~48 ~83 stone
fill ~9 ~46 ~84 ~9 ~47 ~85 sandstone
setblock ~10 ~46 ~84 stone
fill ~62 ~46 ~84 ~62 ~55 ~86 stone
fill ~101 ~46 ~84 ~105 ~55 ~85 stone
fill ~123 ~46 ~84 ~133 ~52 ~84 stone
fill ~152 ~46 ~84 ~153 ~46 ~84 stone
fill ~30 ~46 ~85 ~31 ~52 ~85 stone
fill ~54 ~46 ~85 ~62 ~55 ~85 stone
fill ~95 ~46 ~85 ~95 ~54 ~85 stone
fill ~111 ~46 ~85 ~121 ~54 ~85 stone
fill ~133 ~46 ~85 ~133 ~51 ~85 stone
fill ~55 ~46 ~86 ~62 ~54 ~86 stone
fill ~102 ~46 ~86 ~104 ~55 ~86 stone
fill ~115 ~46 ~86 ~121 ~54 ~86 stone
fill ~131 ~46 ~86 ~131 ~53 ~86 stone
fill ~40 ~46 ~87 ~46 ~51 ~87 stone
fill ~56 ~46 ~87 ~60 ~53 ~87 stone
fill ~94 ~46 ~87 ~94 ~53 ~87 stone
fill ~118 ~46 ~87 ~118 ~54 ~87 stone
setblock ~94 ~46 ~88 stone
fill ~69 ~46 ~90 ~92 ~46 ~90 stone
setblock ~92 ~46 ~91 stone
fill ~70 ~46 ~92 ~91 ~46 ~92 stone
fill ~18 ~46 ~93 ~18 ~48 ~93 stone
fill ~71 ~46 ~93 ~90 ~46 ~93 stone
fill ~144 ~46 ~93 ~144 ~48 ~93 stone
setblock ~18 ~46 ~94 diamond_ore
fill ~72 ~46 ~94 ~89 ~46 ~94 stone
setblock ~144 ~46 ~94 diamond_ore
fill ~16 ~46 ~95 ~16 ~47 ~95 stone
fill ~17 ~46 ~95 ~17 ~46 ~96 sandstone
fill ~18 ~46 ~95 ~20 ~46 ~95 stone
fill ~85 ~46 ~95 ~85 ~55 ~95 stone
fill ~86 ~46 ~95 ~87 ~46 ~95 stone
fill ~142 ~46 ~95 ~142 ~47 ~95 stone
fill ~143 ~46 ~95 ~143 ~46 ~96 sandstone
fill ~144 ~46 ~95 ~146 ~46 ~95 stone
fill ~15 ~46 ~96 ~15 ~47 ~96 stone
fill ~18 ~46 ~96 ~18 ~46 ~97 stone
fill ~19 ~46 ~96 ~20 ~46 ~96 sandstone
setblock ~21 ~46 ~96 stone
fill ~141 ~46 ~96 ~141 ~47 ~96 stone
fill ~144 ~46 ~96 ~144 ~46 ~97 stone
fill ~145 ~46 ~96 ~146 ~46 ~96 sandstone
setblock ~147 ~46 ~96 stone
fill ~16 ~46 ~97 ~16 ~46 ~98 sandstone
fill ~17 ~46 ~97 ~19 ~46 ~97 stone
fill ~21 ~46 ~97 ~22 ~47 ~97 sandstone
setblock ~75 ~46 ~97 stone
fill ~79 ~46 ~97 ~80 ~55 ~97 stone
fill ~107 ~46 ~97 ~108 ~48 ~97 end_stone
fill ~142 ~46 ~97 ~142 ~46 ~98 sandstone
fill ~143 ~46 ~97 ~145 ~46 ~97 stone
fill ~147 ~46 ~97 ~148 ~47 ~97 sandstone
fill ~17 ~46 ~98 ~21 ~46 ~98 sandstone
fill ~105 ~46 ~98 ~105 ~47 ~98 sandstone
fill ~106 ~46 ~98 ~106 ~47 ~98 end_stone
fill ~107 ~46 ~98 ~108 ~47 ~98 sandstone
setblock ~109 ~46 ~98 end_stone
fill ~143 ~46 ~98 ~147 ~46 ~98 sandstone
fill ~16 ~46 ~99 ~16 ~48 ~99 stone
fill ~17 ~46 ~99 ~17 ~48 ~99 sandstone
fill ~18 ~46 ~99 ~18 ~47 ~101 quartz_block
fill ~19 ~46 ~99 ~19 ~49 ~99 sandstone
fill ~105 ~46 ~99 ~106 ~46 ~99 end_stone
fill ~107 ~46 ~99 ~107 ~50 ~99 sandstone
fill ~108 ~46 ~99 ~109 ~46 ~99 sandstone
fill ~110 ~46 ~99 ~110 ~48 ~102 stone
fill ~111 ~46 ~99 ~111 ~47 ~99 stone
fill ~142 ~46 ~99 ~142 ~48 ~99 stone
fill ~144 ~46 ~99 ~144 ~47 ~100 quartz_block
fill ~52 ~46 ~100 ~52 ~46 ~106 sandstone
setblock ~53 ~46 ~100 sandstone
fill ~55 ~46 ~100 ~55 ~46 ~101 end_stone
fill ~56 ~46 ~100 ~56 ~50 ~100 sandstone
setblock ~57 ~46 ~100 sandstone
fill ~79 ~46 ~100 ~79 ~55 ~128 stone
fill ~84 ~46 ~100 ~86 ~54 ~106 stone
fill ~103 ~46 ~100 ~103 ~46 ~101 end_stone
fill ~104 ~46 ~100 ~106 ~46 ~100 sandstone
fill ~107 ~46 ~100 ~107 ~47 ~100 end_stone
setblock ~53 ~46 ~101 end_stone
fill ~54 ~46 ~101 ~54 ~46 ~105 sandstone
fill ~56 ~46 ~101 ~56 ~47 ~101 sandstone
setblock ~57 ~46 ~101 end_stone
fill ~58 ~46 ~101 ~59 ~46 ~101 sandstone
setblock ~60 ~46 ~101 end_stone
fill ~77 ~46 ~101 ~86 ~55 ~105 stone
fill ~102 ~46 ~101 ~104 ~46 ~101 end_stone
fill ~105 ~46 ~101 ~105 ~46 ~102 sandstone
fill ~106 ~46 ~101 ~107 ~46 ~106 stone
fill ~51 ~46 ~102 ~54 ~46 ~102 sandstone
fill ~55 ~46 ~102 ~57 ~46 ~103 stone
fill ~58 ~46 ~102 ~58 ~47 ~102 end_stone
fill ~59 ~46 ~102 ~60 ~46 ~102 sandstone
fill ~61 ~46 ~102 ~61 ~46 ~104 end_stone
fill ~76 ~46 ~102 ~86 ~55 ~104 stone
fill ~87 ~46 ~102 ~87 ~53 ~106 stone
setblock ~101 ~46 ~102 end_stone
fill ~102 ~46 ~102 ~103 ~46 ~102 sandstone
setblock ~104 ~46 ~102 end_stone
fill ~53 ~46 ~103 ~54 ~47 ~103 sandstone
setblock ~59 ~46 ~103 end_stone
fill ~60 ~46 ~103 ~60 ~47 ~103 sandstone
setblock ~62 ~46 ~103 end_stone
fill ~101 ~46 ~103 ~102 ~46 ~103 sandstone
setblock ~103 ~46 ~103 end_stone
setblock ~104 ~46 ~103 sandstone
fill ~105 ~46 ~103 ~107 ~50 ~106 stone
fill ~110 ~46 ~103 ~111 ~46 ~103 end_stone
fill ~53 ~46 ~104 ~53 ~46 ~106 end_stone
fill ~55 ~46 ~104 ~55 ~47 ~104 sandstone
fill ~56 ~46 ~104 ~58 ~50 ~107 stone
setblock ~59 ~46 ~104 sandstone
fill ~60 ~46 ~104 ~61 ~46 ~104 end_stone
fill ~62 ~46 ~104 ~62 ~48 ~104 sandstone
setblock ~101 ~46 ~104 sandstone
fill ~102 ~46 ~104 ~102 ~47 ~104 end_stone
fill ~103 ~46 ~104 ~103 ~47 ~104 sandstone
setblock ~109 ~46 ~104 stone
fill ~112 ~46 ~104 ~112 ~47 ~104 end_stone
fill ~55 ~46 ~105 ~55 ~46 ~108 end_stone
fill ~59 ~46 ~105 ~59 ~50 ~109 stone
fill ~60 ~46 ~105 ~62 ~46 ~105 sandstone
fill ~63 ~46 ~105 ~63 ~46 ~106 end_stone
fill ~64 ~46 ~105 ~64 ~47 ~105 sandstone
fill ~100 ~46 ~105 ~100 ~46 ~106 sandstone
setblock ~101 ~46 ~105 end_stone
fill ~103 ~46 ~105 ~107 ~50 ~106 stone
fill ~108 ~46 ~105 ~110 ~46 ~105 sandstone
fill ~60 ~46 ~106 ~60 ~50 ~110 stone
fill ~61 ~46 ~106 ~61 ~46 ~110 stone
setblock ~62 ~46 ~106 sandstone
fill ~64 ~46 ~106 ~64 ~47 ~106 end_stone
fill ~101 ~46 ~106 ~101 ~47 ~106 sandstone
fill ~102 ~46 ~106 ~107 ~46 ~106 stone
fill ~108 ~46 ~106 ~111 ~46 ~106 end_stone
fill ~53 ~46 ~107 ~54 ~46 ~107 sandstone
fill ~62 ~46 ~107 ~62 ~47 ~107 end_stone
fill ~63 ~46 ~107 ~63 ~50 ~107 sandstone
fill ~64 ~46 ~107 ~64 ~47 ~108 sandstone
fill ~65 ~46 ~107 ~65 ~48 ~108 end_stone
fill ~85 ~46 ~107 ~85 ~55 ~108 stone
fill ~86 ~46 ~107 ~86 ~54 ~107 stone
fill ~100 ~46 ~107 ~101 ~46 ~107 end_stone
fill ~103 ~46 ~107 ~103 ~50 ~107 stone
fill ~104 ~46 ~107 ~104 ~47 ~108 sandstone
fill ~105 ~46 ~107 ~108 ~46 ~107 end_stone
fill ~109 ~46 ~107 ~110 ~47 ~107 sandstone
fill ~53 ~46 ~108 ~56 ~46 ~108 end_stone
fill ~63 ~46 ~108 ~64 ~46 ~108 sandstone
fill ~78 ~46 ~108 ~83 ~55 ~117 stone
fill ~101 ~46 ~108 ~105 ~46 ~108 sandstone
fill ~107 ~46 ~108 ~107 ~47 ~108 sandstone
fill ~108 ~46 ~108 ~108 ~47 ~109 end_stone
setblock ~109 ~46 ~108 stone
setblock ~54 ~46 ~109 stone
fill ~55 ~46 ~109 ~55 ~49 ~109 sandstone
fill ~56 ~46 ~109 ~56 ~46 ~111 end_stone
fill ~57 ~46 ~109 ~57 ~47 ~110 sandstone
fill ~58 ~46 ~109 ~62 ~46 ~109 stone
setblock ~63 ~46 ~109 sandstone
setblock ~64 ~46 ~109 end_stone
fill ~84 ~46 ~109 ~84 ~55 ~110 stone
fill ~100 ~46 ~109 ~100 ~46 ~110 sandstone
setblock ~101 ~46 ~109 end_stone
fill ~103 ~46 ~109 ~103 ~47 ~109 sandstone
fill ~104 ~46 ~109 ~106 ~46 ~109 end_stone
setblock ~107 ~46 ~109 sandstone
fill ~55 ~46 ~110 ~55 ~47 ~110 sandstone
fill ~59 ~46 ~110 ~59 ~46 ~111 end_stone
fill ~63 ~46 ~110 ~63 ~47 ~111 stone
fill ~101 ~46 ~110 ~106 ~46 ~110 sandstone
fill ~77 ~46 ~111 ~83 ~55 ~114 stone
setblock ~102 ~46 ~111 sandstone
fill ~58 ~46 ~112 ~58 ~47 ~112 end_stone
fill ~76 ~46 ~115 ~85 ~54 ~118 stone
fill ~87 ~46 ~117 ~87 ~51 ~121 stone
fill ~75 ~46 ~118 ~87 ~54 ~118 stone
fill ~88 ~46 ~119 ~88 ~51 ~119 stone
fill ~76 ~46 ~120 ~86 ~54 ~121 stone
fill ~78 ~46 ~123 ~84 ~52 ~133 stone
fill ~77 ~46 ~125 ~85 ~54 ~125 stone
fill ~77 ~46 ~129 ~85 ~53 ~129 stone
fill ~76 ~46 ~131 ~85 ~53 ~131 stone
fill ~85 ~46 ~132 ~85 ~52 ~132 stone
fill ~77 ~46 ~133 ~84 ~51 ~133 stone
fill ~80 ~46 ~135 ~82 ~52 ~136 stone
fill ~82 ~46 ~137 ~82 ~51 ~137 stone
fill ~81 ~46 ~138 ~81 ~51 ~138 stone
fill ~97 ~46 ~140 ~97 ~47 ~141 sandstone
fill ~66 ~46 ~141 ~66 ~47 ~141 stone
setblock ~96 ~46 ~141 stone
fill ~63 ~46 ~142 ~63 ~48 ~142 stone
fill ~64 ~46 ~142 ~64 ~46 ~147 sandstone
fill ~65 ~46 ~142 ~66 ~46 ~142 sandstone
fill ~67 ~46 ~142 ~67 ~47 ~142 stone
fill ~95 ~46 ~142 ~95 ~46 ~144 stone
fill ~98 ~46 ~142 ~98 ~46 ~147 sandstone
fill ~65 ~46 ~143 ~65 ~46 ~145 stone
fill ~66 ~46 ~143 ~67 ~46 ~143 sandstone
setblock ~96 ~46 ~143 sandstone
fill ~97 ~46 ~143 ~97 ~46 ~145 stone
fill ~99 ~46 ~143 ~99 ~49 ~143 sandstone
fill ~62 ~46 ~144 ~63 ~47 ~144 quartz_block
fill ~66 ~46 ~144 ~67 ~46 ~144 stone
setblock ~68 ~46 ~144 diamond_ore
fill ~69 ~46 ~144 ~69 ~48 ~144 stone
fill ~93 ~46 ~144 ~93 ~48 ~144 stone
setblock ~94 ~46 ~144 diamond_ore
fill ~96 ~46 ~144 ~97 ~46 ~144 stone
fill ~99 ~46 ~144 ~101 ~47 ~144 quartz_block
fill ~66 ~46 ~145 ~66 ~46 ~146 sandstone
fill ~67 ~46 ~145 ~67 ~46 ~146 stone
fill ~95 ~46 ~145 ~96 ~46 ~145 sandstone
fill ~99 ~46 ~145 ~99 ~48 ~145 sandstone
fill ~95 ~46 ~146 ~95 ~47 ~146 stone
fill ~97 ~46 ~146 ~98 ~46 ~146 sandstone
fill ~99 ~46 ~146 ~99 ~48 ~146 stone
fill ~65 ~46 ~147 ~65 ~47 ~148 sandstone
setblock ~66 ~46 ~147 stone
fill ~96 ~46 ~147 ~97 ~46 ~147 stone
fill ~81 ~46 ~149 ~81 ~48 ~149 stone
setblock ~81 ~46 ~150 diamond_ore
fill ~79 ~46 ~151 ~79 ~47 ~151 stone
fill ~80 ~46 ~151 ~80 ~46 ~152 sandstone
fill ~81 ~46 ~151 ~83 ~46 ~151 stone
fill ~78 ~46 ~152 ~78 ~47 ~152 stone
fill ~81 ~46 ~152 ~81 ~46 ~153 stone
fill ~82 ~46 ~152 ~83 ~46 ~152 sandstone
setblock ~84 ~46 ~152 stone
fill ~79 ~46 ~153 ~79 ~46 ~154 sandstone
fill ~80 ~46 ~153 ~82 ~46 ~153 stone
fill ~84 ~46 ~153 ~85 ~47 ~153 sandstone
fill ~80 ~46 ~154 ~84 ~46 ~154 sandstone
fill ~79 ~46 ~155 ~79 ~48 ~155 stone
fill ~80 ~46 ~155 ~80 ~48 ~155 sandstone
fill ~81 ~46 ~155 ~81 ~47 ~157 quartz_block
fill ~82 ~46 ~155 ~82 ~49 ~155 sandstone
fill ~81 ~47 ~4 ~81 ~50 ~5 quartz_block
fill ~80 ~47 ~5 ~82 ~48 ~6 quartz_block
fill ~79 ~47 ~7 ~80 ~47 ~8 sandstone
fill ~77 ~47 ~8 ~80 ~47 ~8 sandstone
setblock ~81 ~47 ~8 iron_ore
fill ~82 ~47 ~8 ~82 ~48 ~8 stone
fill ~83 ~47 ~8 ~84 ~47 ~8 sandstone
setblock ~80 ~47 ~9 dropper
setblock ~83 ~47 ~9 furnace
fill ~84 ~47 ~9 ~85 ~47 ~9 sandstone
setblock ~77 ~47 ~10 sandstone
setblock ~79 ~47 ~10 dropper
fill ~85 ~47 ~10 ~85 ~48 ~10 sandstone
fill ~78 ~47 ~11 ~78 ~48 ~11 stone
fill ~82 ~47 ~11 ~84 ~47 ~11 stone
setblock ~79 ~47 ~12 stone
setblock ~80 ~47 ~12 coal_ore
fill ~82 ~47 ~12 ~82 ~47 ~13 sandstone
fill ~80 ~47 ~13 ~81 ~48 ~13 stone
fill ~65 ~47 ~14 ~66 ~47 ~14 sandstone
fill ~96 ~47 ~14 ~98 ~47 ~14 sandstone
setblock ~65 ~47 ~15 sandstone
fill ~67 ~47 ~15 ~67 ~47 ~17 stone
fill ~95 ~47 ~15 ~95 ~48 ~15 stone
setblock ~64 ~47 ~16 sandstone
setblock ~65 ~47 ~16 furnace
setblock ~94 ~47 ~16 stone
setblock ~96 ~47 ~16 dropper
fill ~98 ~47 ~16 ~99 ~47 ~17 sandstone
fill ~61 ~47 ~17 ~62 ~48 ~19 quartz_block
fill ~64 ~47 ~17 ~64 ~48 ~17 stone
fill ~68 ~47 ~17 ~69 ~47 ~17 sandstone
fill ~93 ~47 ~17 ~93 ~48 ~18 stone
setblock ~94 ~47 ~17 coal_ore
setblock ~97 ~47 ~17 dropper
fill ~100 ~47 ~17 ~101 ~48 ~19 quartz_block
fill ~60 ~47 ~18 ~61 ~50 ~18 quartz_block
setblock ~64 ~47 ~18 iron_ore
setblock ~98 ~47 ~18 iron_ore
fill ~102 ~47 ~18 ~102 ~50 ~18 quartz_block
setblock ~65 ~47 ~19 dropper
setblock ~68 ~47 ~19 coal_ore
fill ~69 ~47 ~19 ~69 ~49 ~19 stone
fill ~93 ~47 ~19 ~94 ~47 ~19 sandstone
fill ~95 ~47 ~19 ~95 ~47 ~21 stone
fill ~98 ~47 ~19 ~98 ~48 ~19 stone
fill ~99 ~47 ~19 ~99 ~48 ~19 sandstone
fill ~63 ~47 ~20 ~64 ~47 ~20 sandstone
setblock ~66 ~47 ~20 dropper
setblock ~68 ~47 ~20 stone
setblock ~97 ~47 ~20 furnace
fill ~98 ~47 ~20 ~98 ~47 ~21 sandstone
fill ~67 ~47 ~21 ~67 ~48 ~21 stone
setblock ~96 ~47 ~21 stone
fill ~97 ~47 ~21 ~98 ~47 ~21 sandstone
fill ~64 ~47 ~22 ~66 ~47 ~22 sandstone
fill ~96 ~47 ~22 ~97 ~47 ~22 sandstone
fill ~80 ~47 ~24 ~81 ~51 ~62 stone
fill ~82 ~47 ~25 ~83 ~51 ~62 stone
fill ~79 ~47 ~26 ~83 ~52 ~62 stone
