fill ~71 ~52 ~77 ~79 ~52 ~79 stone
setblock ~80 ~52 ~77 activator_rail 1
setblock ~81 ~52 ~77 stone_brick_stairs 2
setblock ~82 ~52 ~77 activator_rail 1
fill ~107 ~52 ~77 ~108 ~52 ~84 stone
fill ~109 ~52 ~77 ~110 ~52 ~77 grass
fill ~111 ~52 ~77 ~114 ~52 ~85 stone
setblock ~115 ~52 ~77 dirt
fill ~121 ~52 ~77 ~125 ~52 ~77 grass
fill ~126 ~52 ~77 ~126 ~52 ~78 log 12
fill ~127 ~52 ~77 ~129 ~52 ~77 grass
fill ~32 ~52 ~78 ~32 ~52 ~79 log 12
fill ~33 ~52 ~78 ~34 ~52 ~78 grass
fill ~35 ~52 ~78 ~35 ~52 ~84 stone
fill ~37 ~52 ~78 ~38 ~52 ~78 grass
fill ~39 ~52 ~78 ~41 ~52 ~84 stone
fill ~42 ~52 ~78 ~44 ~52 ~78 dirt
fill ~45 ~52 ~78 ~71 ~52 ~84 stone
setblock ~80 ~52 ~78 activator_rail 1
setblock ~81 ~52 ~78 stone
setblock ~82 ~52 ~78 activator_rail 1
fill ~115 ~52 ~78 ~118 ~52 ~83 stone
fill ~119 ~52 ~78 ~120 ~52 ~78 grass
fill ~122 ~52 ~78 ~123 ~52 ~84 stone
fill ~124 ~52 ~78 ~125 ~52 ~78 grass
fill ~127 ~52 ~78 ~127 ~52 ~84 stone
fill ~128 ~52 ~78 ~129 ~52 ~78 grass
fill ~130 ~52 ~78 ~130 ~52 ~79 log 12
fill ~2 ~52 ~79 ~2 ~54 ~79 fence
fill ~31 ~52 ~79 ~32 ~52 ~79 log 12
setblock ~33 ~52 ~79 grass
fill ~36 ~52 ~79 ~71 ~52 ~83 stone
setblock ~80 ~52 ~79 activator_rail 1
setblock ~81 ~52 ~79 stone_brick_stairs 2
setblock ~82 ~52 ~79 activator_rail 1
setblock ~129 ~52 ~79 grass
setblock ~131 ~52 ~79 log 12
fill ~160 ~52 ~79 ~160 ~54 ~79 fence
setblock ~72 ~52 ~80 activator_rail 1
setblock ~73 ~52 ~80 activator_rail 1
setblock ~74 ~52 ~80 activator_rail 1
setblock ~75 ~52 ~80 activator_rail 1
setblock ~76 ~52 ~80 activator_rail 1
setblock ~77 ~52 ~80 activator_rail 1
setblock ~78 ~52 ~80 activator_rail 1
setblock ~79 ~52 ~80 activator_rail 1
setblock ~80 ~52 ~80 activator_rail 1
setblock ~81 ~52 ~80 activator_rail 1
setblock ~82 ~52 ~80 activator_rail 1
setblock ~83 ~52 ~80 activator_rail 1
setblock ~84 ~52 ~80 activator_rail 1
setblock ~85 ~52 ~80 activator_rail 1
setblock ~86 ~52 ~80 activator_rail 1
setblock ~87 ~52 ~80 activator_rail 1
setblock ~88 ~52 ~80 activator_rail 1
setblock ~89 ~52 ~80 activator_rail 1
fill ~90 ~52 ~80 ~130 ~52 ~81 stone
fill ~1 ~52 ~81 ~3 ~53 ~81 quartz_block
fill ~30 ~52 ~81 ~31 ~52 ~81 log 12
fill ~33 ~52 ~81 ~72 ~52 ~82 stone
setblock ~73 ~52 ~81 stone_brick_stairs 0
setblock ~74 ~52 ~81 stone
setblock ~75 ~52 ~81 stone_brick_stairs 0
setblock ~76 ~52 ~81 stone
setblock ~77 ~52 ~81 stone_brick_stairs 0
setblock ~78 ~52 ~81 stone
setblock ~79 ~52 ~81 stone_brick_stairs 0
setblock ~80 ~52 ~81 activator_rail 1
setblock ~81 ~52 ~81 activator_rail 1
setblock ~82 ~52 ~81 activator_rail 1
setblock ~83 ~52 ~81 stone_brick_stairs 1
setblock ~84 ~52 ~81 stone
setblock ~85 ~52 ~81 stone_brick_stairs 1
setblock ~86 ~52 ~81 stone
setblock ~87 ~52 ~81 stone_brick_stairs 1
setblock ~88 ~52 ~81 stone
setblock ~89 ~52 ~81 stone_brick_stairs 1
fill ~131 ~52 ~81 ~132 ~52 ~81 log 12
fill ~161 ~52 ~81 ~161 ~53 ~81 quartz_block
fill ~32 ~52 ~82 ~72 ~52 ~82 stone
setblock ~73 ~52 ~82 activator_rail 1
setblock ~74 ~52 ~82 activator_rail 1
setblock ~75 ~52 ~82 activator_rail 1
setblock ~76 ~52 ~82 activator_rail 1
setblock ~77 ~52 ~82 activator_rail 1
setblock ~78 ~52 ~82 activator_rail 1
setblock ~79 ~52 ~82 activator_rail 1
setblock ~80 ~52 ~82 activator_rail 1
setblock ~81 ~52 ~82 activator_rail 1
setblock ~82 ~52 ~82 activator_rail 1
setblock ~83 ~52 ~82 activator_rail 1
setblock ~84 ~52 ~82 activator_rail 1
setblock ~85 ~52 ~82 activator_rail 1
setblock ~86 ~52 ~82 activator_rail 1
setblock ~87 ~52 ~82 activator_rail 1
setblock ~88 ~52 ~82 activator_rail 1
setblock ~89 ~52 ~82 activator_rail 1
setblock ~90 ~52 ~82 activator_rail 1
fill ~2 ~52 ~83 ~2 ~54 ~83 fence
fill ~31 ~52 ~83 ~32 ~52 ~83 log 12
fill ~33 ~52 ~83 ~33 ~52 ~85 grass
fill ~72 ~52 ~83 ~79 ~52 ~90 stone
setblock ~80 ~52 ~83 activator_rail 1
setblock ~81 ~52 ~83 stone_brick_stairs 3
setblock ~82 ~52 ~83 activator_rail 1
fill ~83 ~52 ~83 ~128 ~52 ~83 stone
fill ~129 ~52 ~83 ~129 ~52 ~85 grass
fill ~130 ~52 ~83 ~131 ~52 ~83 log 12
fill ~160 ~52 ~83 ~160 ~54 ~83 fence
setblock ~32 ~52 ~84 log 12
fill ~34 ~52 ~84 ~34 ~52 ~86 grass
fill ~36 ~52 ~84 ~36 ~53 ~84 log 12
fill ~37 ~52 ~84 ~38 ~52 ~86 grass
fill ~42 ~52 ~84 ~43 ~52 ~87 grass
setblock ~80 ~52 ~84 activator_rail 1
setblock ~81 ~52 ~84 stone
setblock ~82 ~52 ~84 activator_rail 1
fill ~84 ~52 ~84 ~84 ~52 ~118 stone
fill ~87 ~52 ~84 ~117 ~52 ~84 stone
fill ~118 ~52 ~84 ~120 ~52 ~84 dirt
fill ~124 ~52 ~84 ~125 ~52 ~86 grass
fill ~126 ~52 ~84 ~126 ~53 ~84 log 12
fill ~128 ~52 ~84 ~129 ~52 ~85 grass
setblock ~130 ~52 ~84 log 12
fill ~35 ~52 ~85 ~35 ~52 ~86 grass
setblock ~36 ~52 ~85 log 12
fill ~39 ~52 ~85 ~47 ~52 ~86 grass
fill ~52 ~52 ~85 ~53 ~52 ~85 grass
fill ~66 ~52 ~85 ~79 ~52 ~87 stone
setblock ~80 ~52 ~85 activator_rail 1
setblock ~81 ~52 ~85 stone_brick_stairs 3
setblock ~82 ~52 ~85 activator_rail 1
fill ~83 ~52 ~85 ~83 ~52 ~128 stone
fill ~85 ~52 ~85 ~85 ~52 ~108 stone
fill ~86 ~52 ~85 ~86 ~52 ~105 stone
fill ~87 ~52 ~85 ~87 ~52 ~97 stone
fill ~88 ~52 ~85 ~88 ~52 ~93 stone
fill ~89 ~52 ~85 ~89 ~52 ~92 stone
fill ~92 ~52 ~85 ~92 ~59 ~90 stone 3
fill ~93 ~52 ~85 ~93 ~59 ~89 stone 3
fill ~94 ~52 ~85 ~94 ~58 ~87 stone 3
fill ~95 ~52 ~85 ~96 ~55 ~85 stone 3
fill ~107 ~52 ~85 ~108 ~52 ~85 dirt
fill ~109 ~52 ~85 ~110 ~52 ~85 grass
fill ~115 ~52 ~85 ~125 ~52 ~86 grass
setblock ~126 ~52 ~85 log 12
fill ~127 ~52 ~85 ~128 ~52 ~86 grass
fill ~3 ~52 ~86 ~3 ~54 ~86 fence
fill ~36 ~52 ~86 ~47 ~52 ~86 grass
setblock ~48 ~52 ~86 dirt
fill ~49 ~52 ~86 ~52 ~52 ~86 grass
fill ~54 ~52 ~86 ~56 ~52 ~86 grass
setblock ~80 ~52 ~86 activator_rail 1
setblock ~81 ~52 ~86 stone
setblock ~82 ~52 ~86 activator_rail 1
fill ~91 ~52 ~86 ~91 ~58 ~91 stone 3
fill ~96 ~52 ~86 ~104 ~52 ~86 stone
fill ~105 ~52 ~86 ~106 ~52 ~86 dirt
fill ~107 ~52 ~86 ~108 ~52 ~86 grass
fill ~110 ~52 ~86 ~128 ~52 ~86 grass
fill ~159 ~52 ~86 ~159 ~54 ~86 fence
fill ~3 ~52 ~87 ~4 ~52 ~87 fence
setblock ~37 ~52 ~87 tallgrass 1
fill ~44 ~52 ~87 ~46 ~52 ~87 grass
fill ~47 ~52 ~87 ~48 ~52 ~87 tallgrass 1
fill ~56 ~52 ~87 ~64 ~52 ~87 grass
setblock ~80 ~52 ~87 activator_rail 1
setblock ~81 ~52 ~87 stone_brick_stairs 3
setblock ~82 ~52 ~87 activator_rail 1
fill ~96 ~52 ~87 ~97 ~53 ~87 stone
fill ~98 ~52 ~87 ~105 ~52 ~87 grass
fill ~106 ~52 ~87 ~107 ~52 ~87 tallgrass 1
setblock ~108 ~52 ~87 grass
fill ~116 ~52 ~87 ~119 ~52 ~87 grass
setblock ~120 ~52 ~87 stone
setblock ~121 ~52 ~87 grass
setblock ~125 ~52 ~87 tallgrass 1
setblock ~159 ~52 ~87 fence
fill ~62 ~52 ~88 ~67 ~52 ~88 grass
fill ~68 ~52 ~88 ~68 ~57 ~88 stone 3
fill ~69 ~52 ~88 ~73 ~55 ~88 stone
setblock ~80 ~52 ~88 activator_rail 1
setblock ~81 ~52 ~88 stone
setblock ~82 ~52 ~88 activator_rail 1
fill ~96 ~52 ~88 ~100 ~52 ~88 grass
setblock ~69 ~52 ~89 stone 3
fill ~70 ~52 ~89 ~79 ~52 ~89 stone
setblock ~80 ~52 ~89 activator_rail 1
setblock ~81 ~52 ~89 stone_brick_stairs 3
setblock ~82 ~52 ~89 activator_rail 1
fill ~34 ~52 ~90 ~34 ~54 ~90 stone 6
fill ~70 ~52 ~90 ~70 ~53 ~90 log 12
fill ~71 ~52 ~90 ~79 ~52 ~90 stone
setblock ~80 ~52 ~90 activator_rail 1
fill ~82 ~52 ~90 ~82 ~52 ~130 stone
fill ~128 ~52 ~90 ~128 ~54 ~90 stone 6
fill ~71 ~52 ~91 ~76 ~58 ~91 stone 3
fill ~72 ~52 ~92 ~77 ~59 ~92 stone 3
fill ~90 ~52 ~92 ~90 ~53 ~92 log 12
fill ~77 ~52 ~93 ~77 ~55 ~96 stone 3
setblock ~89 ~52 ~93 stone 3
fill ~78 ~52 ~94 ~84 ~52 ~117 stone
fill ~88 ~52 ~94 ~88 ~57 ~94 stone 3
fill ~88 ~52 ~95 ~88 ~52 ~100 grass
fill ~74 ~52 ~96 ~74 ~52 ~100 grass
fill ~75 ~52 ~96 ~76 ~52 ~97 stone
fill ~77 ~52 ~97 ~85 ~52 ~106 stone
fill ~75 ~52 ~98 ~75 ~52 ~105 grass
fill ~87 ~52 ~98 ~87 ~52 ~106 grass
fill ~76 ~52 ~100 ~86 ~52 ~104 stone
fill ~11 ~52 ~101 ~11 ~54 ~101 log 12
fill ~25 ~52 ~101 ~25 ~54 ~101 log 12
setblock ~53 ~52 ~101 tallgrass 1
fill ~12 ~52 ~102 ~12 ~52 ~103 fence
fill ~24 ~52 ~102 ~24 ~52 ~103 fence
fill ~138 ~52 ~102 ~138 ~52 ~103 fence
fill ~150 ~52 ~102 ~150 ~52 ~103 fence
fill ~13 ~52 ~103 ~13 ~54 ~103 fence
fill ~14 ~52 ~103 ~14 ~53 ~103 log 12
fill ~23 ~52 ~103 ~23 ~54 ~103 fence
setblock ~54 ~52 ~103 tallgrass 1
setblock ~110 ~52 ~103 tallgrass 1
fill ~139 ~52 ~103 ~139 ~54 ~103 fence
fill ~140 ~52 ~103 ~140 ~53 ~103 log 12
fill ~149 ~52 ~103 ~149 ~54 ~103 fence
fill ~16 ~52 ~104 ~16 ~54 ~104 fence
fill ~20 ~52 ~104 ~20 ~54 ~104 fence
fill ~142 ~52 ~104 ~142 ~54 ~104 fence
fill ~146 ~52 ~104 ~146 ~54 ~104 fence
fill ~18 ~52 ~105 ~18 ~53 ~105 quartz_block
fill ~76 ~52 ~105 ~76 ~52 ~106 dirt
fill ~144 ~52 ~105 ~144 ~53 ~105 quartz_block
fill ~75 ~52 ~106 ~75 ~52 ~107 tallgrass 1
fill ~86 ~52 ~106 ~86 ~52 ~108 grass
fill ~76 ~52 ~107 ~76 ~52 ~108 grass
fill ~77 ~52 ~107 ~77 ~52 ~108 dirt
fill ~75 ~52 ~108 ~76 ~52 ~108 grass
setblock ~103 ~52 ~108 tallgrass 1
fill ~77 ~52 ~109 ~77 ~52 ~110 grass
fill ~85 ~52 ~109 ~85 ~52 ~110 grass
setblock ~101 ~52 ~109 tallgrass 1
setblock ~59 ~52 ~110 tallgrass 1
fill ~76 ~52 ~110 ~76 ~52 ~128 grass
fill ~86 ~52 ~110 ~86 ~52 ~113 grass
fill ~85 ~52 ~111 ~85 ~52 ~114 stone
setblock ~86 ~52 ~114 dirt
fill ~87 ~52 ~114 ~87 ~52 ~115 tallgrass 1
fill ~77 ~52 ~115 ~77 ~52 ~125 grass
fill ~85 ~52 ~115 ~86 ~52 ~125 grass
fill ~75 ~52 ~116 ~77 ~52 ~119 grass
fill ~87 ~52 ~116 ~87 ~52 ~120 grass
fill ~78 ~52 ~118 ~78 ~52 ~120 dirt
fill ~84 ~52 ~119 ~87 ~52 ~120 grass
setblock ~75 ~52 ~120 stone
fill ~75 ~52 ~121 ~77 ~52 ~121 grass
fill ~78 ~52 ~121 ~84 ~52 ~123 stone
fill ~78 ~52 ~124 ~78 ~52 ~125 grass
fill ~84 ~52 ~124 ~86 ~52 ~125 grass
setblock ~75 ~52 ~125 tallgrass 1
setblock ~87 ~52 ~125 tallgrass 1
fill ~77 ~52 ~126 ~78 ~52 ~126 log 12
fill ~84 ~52 ~126 ~85 ~52 ~126 log 12
fill ~86 ~52 ~126 ~86 ~52 ~128 grass
fill ~77 ~52 ~127 ~77 ~52 ~129 grass
fill ~78 ~52 ~127 ~84 ~52 ~127 stone
fill ~85 ~52 ~127 ~86 ~52 ~128 grass
fill ~78 ~52 ~128 ~78 ~52 ~129 grass
fill ~84 ~52 ~128 ~85 ~52 ~129 grass
fill ~90 ~52 ~128 ~90 ~54 ~128 stone 6
setblock ~79 ~52 ~129 grass
fill ~83 ~52 ~129 ~85 ~52 ~129 grass
fill ~78 ~52 ~130 ~79 ~52 ~130 log 12
fill ~83 ~52 ~130 ~84 ~52 ~130 log 12
setblock ~79 ~52 ~131 log 12
fill ~81 ~52 ~131 ~81 ~53 ~131 log 12
setblock ~83 ~52 ~131 log 12
setblock ~81 ~52 ~132 log 12
fill ~101 ~52 ~137 ~101 ~54 ~137 log 12
fill ~59 ~52 ~138 ~60 ~52 ~138 fence
fill ~102 ~52 ~138 ~103 ~52 ~138 fence
fill ~59 ~52 ~139 ~59 ~54 ~139 fence
fill ~103 ~52 ~139 ~103 ~54 ~139 fence
fill ~58 ~52 ~142 ~58 ~54 ~142 fence
fill ~104 ~52 ~142 ~104 ~54 ~142 fence
fill ~57 ~52 ~144 ~59 ~53 ~144 quartz_block
fill ~105 ~52 ~144 ~105 ~53 ~144 quartz_block
fill ~58 ~52 ~146 ~58 ~54 ~146 fence
fill ~104 ~52 ~146 ~104 ~54 ~146 fence
fill ~59 ~52 ~149 ~59 ~54 ~149 fence
fill ~103 ~52 ~149 ~103 ~54 ~149 fence
fill ~59 ~52 ~150 ~60 ~52 ~150 fence
setblock ~103 ~52 ~150 fence
fill ~101 ~52 ~151 ~101 ~54 ~151 log 12
fill ~75 ~52 ~158 ~75 ~52 ~159 fence
fill ~87 ~52 ~158 ~87 ~52 ~159 fence
fill ~76 ~52 ~159 ~76 ~54 ~159 fence
fill ~77 ~52 ~159 ~77 ~53 ~159 log 12
fill ~86 ~52 ~159 ~86 ~54 ~159 fence
fill ~79 ~52 ~160 ~79 ~54 ~160 fence
fill ~83 ~52 ~160 ~83 ~54 ~160 fence
fill ~81 ~52 ~161 ~81 ~53 ~161 quartz_block
setblock ~77 ~53 ~2 fence
setblock ~85 ~53 ~2 fence
fill ~76 ~53 ~3 ~76 ~54 ~3 fence
fill ~78 ~53 ~3 ~79 ~53 ~3 fence
fill ~83 ~53 ~3 ~84 ~53 ~3 fence
setblock ~58 ~53 ~14 fence
setblock ~104 ~53 ~14 fence
fill ~59 ~53 ~15 ~59 ~53 ~16 fence
fill ~103 ~53 ~15 ~103 ~53 ~16 fence
fill ~59 ~53 ~20 ~59 ~53 ~21 fence
fill ~103 ~53 ~20 ~104 ~53 ~20 fence
setblock ~103 ~53 ~21 fence
setblock ~58 ~53 ~22 fence
setblock ~104 ~53 ~22 fence
fill ~81 ~53 ~31 ~81 ~53 ~35 log 12
fill ~79 ~53 ~32 ~83 ~53 ~32 log 12
fill ~80 ~53 ~33 ~82 ~66 ~33 log 12
fill ~79 ~53 ~34 ~83 ~54 ~35 log 12
fill ~78 ~53 ~35 ~84 ~53 ~35 log 12
fill ~78 ~53 ~36 ~79 ~53 ~36 log 12
fill ~80 ~53 ~36 ~82 ~53 ~36 stone
fill ~83 ~53 ~36 ~84 ~53 ~36 log 12
fill ~79 ~53 ~37 ~79 ~53 ~58 grass
setblock ~80 ~53 ~37 stone
setblock ~81 ~53 ~37 grass
setblock ~82 ~53 ~37 stone
fill ~83 ~53 ~37 ~83 ~53 ~64 grass
setblock ~80 ~53 ~38 grass
fill ~81 ~53 ~38 ~81 ~53 ~39 dirt 1
fill ~82 ~53 ~38 ~83 ~53 ~38 grass
setblock ~77 ~53 ~39 tallgrass 1
fill ~78 ~53 ~39 ~79 ~53 ~41 grass
fill ~80 ~53 ~39 ~82 ~53 ~39 dirt 1
fill ~84 ~53 ~39 ~84 ~53 ~64 grass
setblock ~80 ~53 ~40 dirt
fill ~81 ~53 ~40 ~81 ~53 ~42 grass
setblock ~82 ~53 ~40 dirt
setblock ~77 ~53 ~41 tallgrass 1
fill ~80 ~53 ~41 ~84 ~53 ~42 grass
setblock ~80 ~53 ~43 grass
fill ~81 ~53 ~43 ~82 ~53 ~43 dirt 1
setblock ~87 ~53 ~43 tallgrass 1
fill ~78 ~53 ~44 ~79 ~53 ~58 grass
fill ~80 ~53 ~44 ~82 ~53 ~44 dirt
setblock ~75 ~53 ~45 tallgrass 1
fill ~80 ~53 ~45 ~80 ~53 ~50 grass
fill ~81 ~53 ~45 ~81 ~53 ~46 dirt
setblock ~82 ~53 ~45 dirt 1
fill ~82 ~53 ~46 ~84 ~53 ~46 grass
fill ~77 ~53 ~47 ~77 ~53 ~49 stone 6
fill ~81 ~53 ~47 ~81 ~53 ~51 grass
setblock ~82 ~53 ~47 dirt 1
setblock ~85 ~53 ~47 tallgrass 1
fill ~76 ~53 ~48 ~77 ~54 ~48 stone 6
fill ~82 ~53 ~48 ~85 ~53 ~48 grass
setblock ~82 ~53 ~49 dirt
fill ~85 ~53 ~49 ~85 ~53 ~51 grass
fill ~77 ~53 ~50 ~85 ~53 ~50 grass
fill ~77 ~53 ~51 ~79 ~53 ~51 grass
setblock ~80 ~53 ~51 dirt 1
fill ~82 ~53 ~51 ~84 ~53 ~55 grass
fill ~80 ~53 ~52 ~80 ~53 ~53 grass
fill ~81 ~53 ~52 ~81 ~53 ~53 dirt 1
setblock ~85 ~53 ~52 tallgrass 1
fill ~77 ~53 ~54 ~78 ~53 ~61 grass
setblock ~80 ~53 ~54 activator_rail 1
fill ~81 ~53 ~54 ~85 ~53 ~54 grass
setblock ~76 ~53 ~55 tallgrass 1
setblock ~80 ~53 ~55 activator_rail 1
setblock ~81 ~53 ~55 stone_brick_stairs 2
fill ~85 ~53 ~55 ~85 ~53 ~57 stone 6
setblock ~86 ~53 ~55 tallgrass 1
setblock ~80 ~53 ~56 grass
setblock ~81 ~53 ~56 stone
setblock ~82 ~53 ~56 activator_rail 1
fill ~86 ~53 ~56 ~86 ~55 ~56 stone 6
fill ~76 ~53 ~57 ~79 ~53 ~58 grass
setblock ~80 ~53 ~57 activator_rail 1
setblock ~81 ~53 ~57 stone_brick_stairs 2
setblock ~82 ~53 ~57 activator_rail 1
fill ~86 ~53 ~57 ~86 ~53 ~64 grass
setblock ~14 ~53 ~58 fence
setblock ~22 ~53 ~58 fence
setblock ~80 ~53 ~58 activator_rail 1
setblock ~82 ~53 ~58 activator_rail 1
fill ~85 ~53 ~58 ~86 ~53 ~64 grass
setblock ~140 ~53 ~58 fence
setblock ~148 ~53 ~58 fence
fill ~13 ~53 ~59 ~13 ~54 ~59 fence
fill ~15 ~53 ~59 ~16 ~53 ~59 fence
fill ~20 ~53 ~59 ~21 ~53 ~59 fence
fill ~76 ~53 ~59 ~78 ~53 ~61 grass
setblock ~79 ~53 ~59 dirt 1
setblock ~80 ~53 ~59 activator_rail 1
setblock ~81 ~53 ~59 stone_brick_stairs 2
setblock ~82 ~53 ~59 activator_rail 1
fill ~139 ~53 ~59 ~139 ~54 ~59 fence
fill ~141 ~53 ~59 ~142 ~53 ~59 fence
fill ~146 ~53 ~59 ~147 ~53 ~59 fence
setblock ~79 ~53 ~60 dirt
setblock ~80 ~53 ~60 activator_rail 1
setblock ~82 ~53 ~60 activator_rail 1
fill ~79 ~53 ~61 ~79 ~53 ~64 grass
setblock ~80 ~53 ~61 activator_rail 1
setblock ~81 ~53 ~61 stone_brick_stairs 2
setblock ~82 ~53 ~61 activator_rail 1
fill ~76 ~53 ~62 ~76 ~53 ~64 grass
setblock ~77 ~53 ~62 stone 6
fill ~78 ~53 ~62 ~79 ~53 ~62 grass
setblock ~80 ~53 ~62 activator_rail 1
setblock ~81 ~53 ~62 stone
setblock ~82 ~53 ~62 activator_rail 1
setblock ~77 ~53 ~63 grass
setblock ~78 ~53 ~63 stone 6
setblock ~80 ~53 ~63 activator_rail 1
setblock ~81 ~53 ~63 stone_brick_stairs 2
setblock ~82 ~53 ~63 activator_rail 1
fill ~77 ~53 ~64 ~78 ~53 ~68 stone 3
setblock ~80 ~53 ~64 activator_rail 1
setblock ~81 ~53 ~64 stone
setblock ~82 ~53 ~64 activator_rail 1
fill ~75 ~53 ~65 ~75 ~53 ~67 grass
fill ~76 ~53 ~65 ~79 ~53 ~67 stone 3
setblock ~80 ~53 ~65 activator_rail 1
setblock ~81 ~53 ~65 stone_brick_stairs 2
setblock ~82 ~53 ~65 activator_rail 1
fill ~83 ~53 ~65 ~83 ~53 ~70 stone
setblock ~84 ~53 ~65 stone
fill ~85 ~53 ~65 ~86 ~53 ~71 stone 3
setblock ~80 ~53 ~66 activator_rail 1
setblock ~81 ~53 ~66 stone
setblock ~82 ~53 ~66 activator_rail 1
fill ~84 ~53 ~66 ~86 ~54 ~70 stone 3
setblock ~80 ~53 ~67 activator_rail 1
setblock ~81 ~53 ~67 stone_brick_stairs 2
setblock ~82 ~53 ~67 activator_rail 1
fill ~87 ~53 ~67 ~87 ~54 ~72 stone 3
fill ~75 ~53 ~68 ~76 ~53 ~71 stone
fill ~79 ~53 ~68 ~79 ~60 ~68 stone 3
setblock ~80 ~53 ~68 activator_rail 1
setblock ~81 ~53 ~68 stone
setblock ~82 ~53 ~68 activator_rail 1
fill ~88 ~53 ~68 ~88 ~57 ~72 stone 3
setblock ~73 ~53 ~69 log 12
fill ~74 ~53 ~69 ~74 ~55 ~73 stone
fill ~77 ~53 ~69 ~79 ~53 ~70 stone
setblock ~80 ~53 ~69 activator_rail 1
setblock ~81 ~53 ~69 stone_brick_stairs 2
setblock ~82 ~53 ~69 activator_rail 1
fill ~71 ~53 ~70 ~71 ~57 ~70 log 12
fill ~73 ~53 ~70 ~75 ~55 ~71 stone
setblock ~80 ~53 ~70 activator_rail 1
setblock ~81 ~53 ~70 stone
setblock ~82 ~53 ~70 activator_rail 1
fill ~72 ~53 ~71 ~72 ~55 ~75 stone 3
fill ~77 ~53 ~71 ~77 ~55 ~71 stone
setblock ~80 ~53 ~71 activator_rail 1
setblock ~81 ~53 ~71 stone_brick_stairs 2
setblock ~82 ~53 ~71 activator_rail 1
fill ~92 ~53 ~71 ~92 ~57 ~71 log 12
fill ~73 ~53 ~72 ~75 ~54 ~72 stone
setblock ~80 ~53 ~72 dropper 1
setblock ~81 ~53 ~72 rail 4
setblock ~82 ~53 ~72 dropper 1
fill ~89 ~53 ~72 ~91 ~65 ~72 stone 3
fill ~73 ~53 ~73 ~74 ~53 ~73 stone
fill ~81 ~53 ~73 ~81 ~53 ~78 rail 0
fill ~88 ~53 ~73 ~92 ~53 ~73 stone
setblock ~93 ~53 ~73 log 12
setblock ~73 ~53 ~74 stone
fill ~89 ~53 ~74 ~92 ~56 ~74 stone
fill ~93 ~53 ~74 ~93 ~53 ~79 stone
setblock ~43 ~53 ~75 tallgrass 1
fill ~65 ~53 ~75 ~66 ~53 ~75 stone
fill ~67 ~53 ~75 ~70 ~54 ~78 stone 3
fill ~90 ~53 ~75 ~94 ~53 ~75 stone
fill ~95 ~53 ~75 ~97 ~53 ~75 grass
setblock ~117 ~53 ~75 tallgrass 1
setblock ~55 ~53 ~76 tallgrass 1
fill ~56 ~53 ~76 ~56 ~54 ~77 stone 6
fill ~57 ~53 ~76 ~64 ~53 ~76 grass
fill ~65 ~53 ~76 ~71 ~53 ~77 stone 3
fill ~77 ~53 ~76 ~77 ~55 ~77 log 12
fill ~85 ~53 ~76 ~85 ~55 ~78 log 12
fill ~91 ~53 ~76 ~93 ~53 ~77 stone
setblock ~94 ~53 ~76 stone
fill ~95 ~53 ~76 ~97 ~53 ~79 stone 3
fill ~98 ~53 ~76 ~105 ~53 ~76 grass
setblock ~107 ~53 ~76 tallgrass 1
fill ~114 ~53 ~76 ~114 ~54 ~77 stone 6
setblock ~2 ~53 ~77 fence
setblock ~47 ~53 ~77 tallgrass 1
fill ~48 ~53 ~77 ~50 ~53 ~84 grass
fill ~51 ~53 ~77 ~51 ~53 ~81 grass
setblock ~52 ~53 ~77 tallgrass 1
fill ~54 ~53 ~77 ~54 ~53 ~81 grass
fill ~55 ~53 ~77 ~57 ~53 ~77 stone 6
fill ~58 ~53 ~77 ~64 ~53 ~79 grass
fill ~76 ~53 ~77 ~78 ~55 ~77 log 12
fill ~84 ~53 ~77 ~86 ~54 ~77 log 12
fill ~94 ~53 ~77 ~94 ~59 ~79 stone 3
fill ~98 ~53 ~77 ~98 ~53 ~78 stone 3
setblock ~99 ~53 ~77 grass
setblock ~100 ~53 ~77 stone 6
fill ~101 ~53 ~77 ~108 ~53 ~78 grass
fill ~111 ~53 ~77 ~112 ~53 ~79 grass
fill ~113 ~53 ~77 ~115 ~53 ~77 stone 6
setblock ~121 ~53 ~77 tallgrass 1
setblock ~123 ~53 ~77 tallgrass 1
setblock ~160 ~53 ~77 fence
fill ~3 ~53 ~78 ~3 ~53 ~79 fence
fill ~35 ~53 ~78 ~35 ~53 ~84 log 12
fill ~36 ~53 ~78 ~36 ~53 ~79 log 12
fill ~39 ~53 ~78 ~64 ~53 ~79 grass
fill ~65 ~53 ~78 ~65 ~53 ~79 stone
fill ~66 ~53 ~78 ~70 ~56 ~78 stone 3
fill ~77 ~53 ~78 ~77 ~54 ~78 log 12
fill ~92 ~53 ~78 ~93 ~53 ~79 stone
setblock ~99 ~53 ~78 stone 6
fill ~100 ~53 ~78 ~118 ~53 ~78 grass
fill ~121 ~53 ~78 ~123 ~53 ~80 grass
fill ~126 ~53 ~78 ~127 ~53 ~79 log 12
fill ~159 ~53 ~78 ~159 ~53 ~79 fence
fill ~32 ~53 ~79 ~32 ~53 ~83 log 12
fill ~34 ~53 ~79 ~35 ~54 ~83 log 12
fill ~37 ~53 ~79 ~64 ~53 ~79 grass
fill ~66 ~53 ~79 ~70 ~53 ~79 stone
fill ~98 ~53 ~79 ~101 ~53 ~79 grass
setblock ~102 ~53 ~79 dirt
setblock ~103 ~53 ~79 dirt 1
fill ~104 ~53 ~79 ~125 ~53 ~79 grass
fill ~128 ~53 ~79 ~128 ~55 ~83 log 12
fill ~130 ~53 ~79 ~130 ~53 ~83 log 12
fill ~33 ~53 ~80 ~33 ~66 ~82 log 12
fill ~36 ~53 ~80 ~36 ~53 ~82 stone
setblock ~37 ~53 ~80 stone
fill ~38 ~53 ~80 ~42 ~53 ~80 grass
fill ~43 ~53 ~80 ~43 ~53 ~81 dirt 1
fill ~44 ~53 ~80 ~44 ~53 ~81 dirt
setblock ~45 ~53 ~80 dirt 1
fill ~46 ~53 ~80 ~46 ~53 ~84 grass
setblock ~47 ~53 ~80 dirt 1
fill ~52 ~53 ~80 ~53 ~53 ~80 dirt
setblock ~55 ~53 ~80 grass
setblock ~56 ~53 ~80 activator_rail 1
setblock ~57 ~53 ~80 activator_rail 1
setblock ~58 ~53 ~80 activator_rail 1
setblock ~59 ~53 ~80 activator_rail 1
setblock ~60 ~53 ~80 activator_rail 1
setblock ~61 ~53 ~80 activator_rail 1
setblock ~62 ~53 ~80 activator_rail 1
setblock ~63 ~53 ~80 activator_rail 1
setblock ~64 ~53 ~80 activator_rail 1
setblock ~65 ~53 ~80 activator_rail 1
setblock ~66 ~53 ~80 activator_rail 1
setblock ~67 ~53 ~80 activator_rail 1
setblock ~68 ~53 ~80 activator_rail 1
setblock ~69 ~53 ~80 activator_rail 1
setblock ~70 ~53 ~80 activator_rail 1
setblock ~71 ~53 ~80 activator_rail 1
setblock ~72 ~53 ~80 dropper 1
setblock ~80 ~53 ~80 crafting_table
setblock ~81 ~53 ~80 stone_slab
setblock ~82 ~53 ~80 chest 5
setblock ~90 ~53 ~80 dropper 1
setblock ~91 ~53 ~80 activator_rail 1
setblock ~92 ~53 ~80 activator_rail 1
setblock ~93 ~53 ~80 activator_rail 1
setblock ~94 ~53 ~80 activator_rail 1
setblock ~95 ~53 ~80 activator_rail 1
setblock ~96 ~53 ~80 activator_rail 1
setblock ~97 ~53 ~80 activator_rail 1
setblock ~98 ~53 ~80 activator_rail 1
setblock ~99 ~53 ~80 activator_rail 1
setblock ~100 ~53 ~80 activator_rail 1
setblock ~101 ~53 ~80 activator_rail 1
setblock ~102 ~53 ~80 activator_rail 1
setblock ~103 ~53 ~80 activator_rail 1
setblock ~104 ~53 ~80 activator_rail 1
setblock ~105 ~53 ~80 activator_rail 1
setblock ~106 ~53 ~80 grass
setblock ~107 ~53 ~80 activator_rail 1
setblock ~108 ~53 ~80 activator_rail 1
fill ~109 ~53 ~80 ~110 ~53 ~80 grass
setblock ~111 ~53 ~80 dirt 1
setblock ~112 ~53 ~80 dirt
fill ~113 ~53 ~80 ~118 ~53 ~80 grass
setblock ~119 ~53 ~80 dirt
fill ~120 ~53 ~80 ~121 ~53 ~84 grass
fill ~124 ~53 ~80 ~124 ~53 ~81 dirt 1
fill ~125 ~53 ~80 ~126 ~53 ~80 stone
fill ~127 ~53 ~80 ~129 ~64 ~80 log 12
fill ~31 ~53 ~81 ~35 ~53 ~81 log 12
setblock ~37 ~53 ~81 grass
fill ~38 ~53 ~81 ~38 ~53 ~83 dirt 1
fill ~39 ~53 ~81 ~42 ~53 ~81 grass
fill ~45 ~53 ~81 ~50 ~53 ~84 grass
fill ~52 ~53 ~81 ~53 ~53 ~81 dirt 1
setblock ~55 ~53 ~81 stone_brick_stairs 0
setblock ~56 ~53 ~81 stone
setblock ~57 ~53 ~81 stone_brick_stairs 0
setblock ~58 ~53 ~81 stone
setblock ~59 ~53 ~81 stone_brick_stairs 0
setblock ~60 ~53 ~81 stone
setblock ~61 ~53 ~81 stone_brick_stairs 0
setblock ~62 ~53 ~81 stone
setblock ~63 ~53 ~81 stone_brick_stairs 0
setblock ~64 ~53 ~81 stone
setblock ~65 ~53 ~81 stone_brick_stairs 0
setblock ~66 ~53 ~81 stone
setblock ~67 ~53 ~81 stone_brick_stairs 0
setblock ~68 ~53 ~81 stone
setblock ~69 ~53 ~81 stone_brick_stairs 0
setblock ~70 ~53 ~81 stone
setblock ~71 ~53 ~81 stone_brick_stairs 0
setblock ~72 ~53 ~81 rail 3
setblock ~73 ~53 ~81 rail 1
setblock ~74 ~53 ~81 rail 1
setblock ~75 ~53 ~81 rail 1
setblock ~76 ~53 ~81 rail 1
setblock ~77 ~53 ~81 rail 1
setblock ~78 ~53 ~81 rail 1
setblock ~80 ~53 ~81 stone_slab
setblock ~81 ~53 ~81 double_stone_slab
setblock ~82 ~53 ~81 stone_slab
setblock ~84 ~53 ~81 rail 1
setblock ~85 ~53 ~81 rail 1
setblock ~86 ~53 ~81 rail 1
setblock ~87 ~53 ~81 rail 1
setblock ~88 ~53 ~81 rail 1
setblock ~89 ~53 ~81 rail 1
setblock ~90 ~53 ~81 rail 2
setblock ~91 ~53 ~81 stone_brick_stairs 1
setblock ~92 ~53 ~81 stone
setblock ~93 ~53 ~81 stone_brick_stairs 1
setblock ~94 ~53 ~81 stone
setblock ~95 ~53 ~81 stone_brick_stairs 1
setblock ~96 ~53 ~81 stone
setblock ~97 ~53 ~81 stone_brick_stairs 1
setblock ~98 ~53 ~81 stone
setblock ~99 ~53 ~81 stone_brick_stairs 1
setblock ~100 ~53 ~81 stone
setblock ~101 ~53 ~81 stone_brick_stairs 1
setblock ~103 ~53 ~81 stone_brick_stairs 1
setblock ~105 ~53 ~81 stone_brick_stairs 1
setblock ~106 ~53 ~81 stone
setblock ~107 ~53 ~81 stone_brick_stairs 1
fill ~108 ~53 ~81 ~108 ~53 ~85 grass
fill ~109 ~53 ~81 ~110 ~53 ~81 dirt 1
fill ~111 ~53 ~81 ~113 ~53 ~81 grass
setblock ~114 ~53 ~81 dirt
setblock ~115 ~53 ~81 grass
fill ~116 ~53 ~81 ~118 ~53 ~81 dirt
fill ~119 ~53 ~81 ~119 ~53 ~82 dirt 1
setblock ~122 ~53 ~81 dirt 1
fill ~123 ~53 ~81 ~123 ~53 ~84 grass
setblock ~125 ~53 ~81 grass
fill ~126 ~53 ~81 ~126 ~53 ~82 stone
fill ~127 ~53 ~81 ~129 ~55 ~82 log 12
setblock ~131 ~53 ~81 log 12
setblock ~37 ~53 ~82 stone
setblock ~39 ~53 ~82 dirt 1
setblock ~40 ~53 ~82 dirt
fill ~41 ~53 ~82 ~42 ~53 ~83 grass
setblock ~43 ~53 ~82 dirt
fill ~44 ~53 ~82 ~50 ~53 ~84 grass
setblock ~51 ~53 ~82 dirt 1
fill ~52 ~53 ~82 ~52 ~53 ~84 grass
setblock ~53 ~53 ~82 dirt
setblock ~54 ~53 ~82 activator_rail 1
setblock ~55 ~53 ~82 activator_rail 1
fill ~56 ~53 ~82 ~56 ~53 ~85 grass
setblock ~57 ~53 ~82 activator_rail 1
setblock ~58 ~53 ~82 activator_rail 1
setblock ~59 ~53 ~82 activator_rail 1
setblock ~60 ~53 ~82 activator_rail 1
setblock ~61 ~53 ~82 activator_rail 1
setblock ~62 ~53 ~82 activator_rail 1
setblock ~63 ~53 ~82 activator_rail 1
setblock ~64 ~53 ~82 activator_rail 1
setblock ~65 ~53 ~82 activator_rail 1
setblock ~66 ~53 ~82 activator_rail 1
setblock ~67 ~53 ~82 activator_rail 1
setblock ~68 ~53 ~82 activator_rail 1
setblock ~69 ~53 ~82 activator_rail 1
setblock ~70 ~53 ~82 activator_rail 1
setblock ~71 ~53 ~82 activator_rail 1
setblock ~72 ~53 ~82 dropper 1
setblock ~80 ~53 ~82 chest 3
setblock ~81 ~53 ~82 stone_slab
setblock ~82 ~53 ~82 crafting_table
setblock ~90 ~53 ~82 dropper 1
setblock ~91 ~53 ~82 activator_rail 1
setblock ~92 ~53 ~82 activator_rail 1
setblock ~93 ~53 ~82 activator_rail 1
setblock ~94 ~53 ~82 activator_rail 1
setblock ~95 ~53 ~82 activator_rail 1
setblock ~96 ~53 ~82 activator_rail 1
setblock ~97 ~53 ~82 activator_rail 1
setblock ~98 ~53 ~82 activator_rail 1
setblock ~99 ~53 ~82 activator_rail 1
setblock ~100 ~53 ~82 activator_rail 1
setblock ~101 ~53 ~82 activator_rail 1
setblock ~102 ~53 ~82 activator_rail 1
setblock ~103 ~53 ~82 activator_rail 1
setblock ~104 ~53 ~82 activator_rail 1
setblock ~105 ~53 ~82 activator_rail 1
setblock ~106 ~53 ~82 activator_rail 1
fill ~107 ~53 ~82 ~110 ~53 ~84 grass
setblock ~111 ~53 ~82 dirt
fill ~112 ~53 ~82 ~112 ~53 ~85 grass
setblock ~113 ~53 ~82 dirt
fill ~114 ~53 ~82 ~114 ~53 ~85 grass
setblock ~115 ~53 ~82 dirt 1
fill ~116 ~53 ~82 ~116 ~53 ~84 grass
setblock ~117 ~53 ~82 dirt 1
fill ~118 ~53 ~82 ~118 ~53 ~84 grass
fill ~122 ~53 ~82 ~123 ~53 ~84 grass
setblock ~124 ~53 ~82 dirt
fill ~125 ~53 ~82 ~126 ~53 ~82 stone
fill ~3 ~53 ~83 ~3 ~53 ~84 fence
fill ~36 ~53 ~83 ~36 ~53 ~84 log 12
setblock ~37 ~53 ~83 grass
fill ~39 ~53 ~83 ~58 ~53 ~83 grass
setblock ~59 ~53 ~83 dirt 1
setblock ~60 ~53 ~83 dirt
fill ~61 ~53 ~83 ~64 ~53 ~83 grass
fill ~65 ~53 ~83 ~68 ~53 ~85 stone 3
fill ~69 ~53 ~83 ~70 ~53 ~88 stone
fill ~92 ~53 ~83 ~97 ~53 ~83 stone
fill ~98 ~53 ~83 ~125 ~53 ~83 grass
fill ~126 ~53 ~83 ~127 ~53 ~84 log 12
fill ~159 ~53 ~83 ~160 ~53 ~83 fence
fill ~39 ~53 ~84 ~41 ~53 ~84 grass
fill ~51 ~53 ~84 ~62 ~53 ~84 grass
setblock ~63 ~53 ~84 stone 6
fill ~64 ~53 ~84 ~68 ~53 ~85 stone 3
fill ~77 ~53 ~84 ~77 ~55 ~86 log 12
fill ~81 ~53 ~84 ~81 ~53 ~88 rail 0
fill ~85 ~53 ~84 ~85 ~54 ~86 log 12
fill ~92 ~53 ~84 ~92 ~59 ~90 stone 3
fill ~93 ~53 ~84 ~93 ~59 ~89 stone 3
fill ~94 ~53 ~84 ~94 ~58 ~87 stone 3
fill ~95 ~53 ~84 ~96 ~54 ~86 stone 3
setblock ~97 ~53 ~84 stone
fill ~98 ~53 ~84 ~123 ~53 ~84 grass
setblock ~159 ~53 ~84 fence
setblock ~2 ~53 ~85 fence
setblock ~39 ~53 ~85 tallgrass 1
setblock ~41 ~53 ~85 tallgrass 1
fill ~47 ~53 ~85 ~49 ~53 ~85 stone 6
fill ~50 ~53 ~85 ~51 ~53 ~85 grass
fill ~54 ~53 ~85 ~61 ~53 ~85 grass
setblock ~62 ~53 ~85 stone 6
fill ~63 ~53 ~85 ~63 ~53 ~86 grass
fill ~71 ~53 ~85 ~71 ~53 ~89 stone
fill ~76 ~53 ~85 ~78 ~54 ~85 log 12
fill ~84 ~53 ~85 ~86 ~55 ~85 log 12
fill ~91 ~53 ~85 ~91 ~58 ~91 stone 3
fill ~97 ~53 ~85 ~97 ~53 ~86 stone 3
fill ~98 ~53 ~85 ~104 ~53 ~86 grass
fill ~105 ~53 ~85 ~107 ~53 ~85 stone 6
setblock ~110 ~53 ~85 tallgrass 1
fill ~111 ~53 ~85 ~114 ~53 ~85 grass
setblock ~115 ~53 ~85 tallgrass 1
setblock ~160 ~53 ~85 fence
fill ~48 ~53 ~86 ~48 ~55 ~86 stone 6
setblock ~55 ~53 ~86 tallgrass 1
fill ~57 ~53 ~86 ~64 ~53 ~86 grass
fill ~65 ~53 ~86 ~67 ~53 ~86 stone 3
fill ~68 ~53 ~86 ~71 ~53 ~87 stone
setblock ~105 ~53 ~86 grass
fill ~106 ~53 ~86 ~106 ~55 ~86 stone 6
setblock ~107 ~53 ~86 tallgrass 1
setblock ~45 ~53 ~87 tallgrass 1
fill ~65 ~53 ~87 ~66 ~53 ~87 grass
setblock ~67 ~53 ~87 dirt
fill ~72 ~53 ~87 ~72 ~54 ~89 stone
fill ~90 ~53 ~87 ~94 ~55 ~88 stone 3
fill ~95 ~53 ~87 ~95 ~54 ~87 stone 3
setblock ~119 ~53 ~87 tallgrass 1
setblock ~69 ~53 ~89 log 12
fill ~70 ~53 ~89 ~71 ~55 ~89 stone
fill ~73 ~53 ~89 ~74 ~53 ~89 stone
fill ~89 ~53 ~89 ~89 ~53 ~92 stone
fill ~90 ~53 ~89 ~90 ~65 ~91 stone 3
fill ~71 ~53 ~90 ~74 ~58 ~91 stone 3
fill ~75 ~53 ~90 ~75 ~55 ~94 stone 3
setblock ~80 ~53 ~90 dropper 1
setblock ~81 ~53 ~90 rail 5
setblock ~82 ~53 ~90 dropper 1
fill ~88 ~53 ~90 ~89 ~54 ~92 stone
fill ~70 ~53 ~91 ~70 ~57 ~91 log 12
fill ~77 ~53 ~91 ~77 ~65 ~91 stone 3
setblock ~80 ~53 ~91 activator_rail 1
setblock ~81 ~53 ~91 stone_brick_stairs 3
setblock ~82 ~53 ~91 activator_rail 1
fill ~85 ~53 ~91 ~88 ~53 ~93 stone
fill ~78 ~53 ~92 ~78 ~56 ~96 stone 3
setblock ~80 ~53 ~92 activator_rail 1
setblock ~81 ~53 ~92 stone
setblock ~82 ~53 ~92 activator_rail 1
fill ~83 ~53 ~92 ~88 ~53 ~93 stone
fill ~91 ~53 ~92 ~91 ~57 ~92 log 12
fill ~79 ~53 ~93 ~79 ~53 ~97 stone
setblock ~80 ~53 ~93 activator_rail 1
setblock ~81 ~53 ~93 stone_brick_stairs 3
setblock ~82 ~53 ~93 activator_rail 1
setblock ~89 ~53 ~93 log 12
setblock ~80 ~53 ~94 activator_rail 1
setblock ~81 ~53 ~94 stone
setblock ~82 ~53 ~94 activator_rail 1
fill ~83 ~53 ~94 ~85 ~59 ~94 stone 3
fill ~75 ~53 ~95 ~78 ~54 ~95 stone 3
setblock ~80 ~53 ~95 activator_rail 1
setblock ~81 ~53 ~95 stone_brick_stairs 3
setblock ~82 ~53 ~95 activator_rail 1
fill ~83 ~53 ~95 ~86 ~55 ~95 stone 3
fill ~87 ~53 ~95 ~87 ~53 ~97 grass
fill ~75 ~53 ~96 ~75 ~53 ~97 stone
fill ~76 ~53 ~96 ~78 ~54 ~96 stone 3
setblock ~80 ~53 ~96 activator_rail 1
setblock ~81 ~53 ~96 stone
setblock ~82 ~53 ~96 activator_rail 1
fill ~83 ~53 ~96 ~86 ~53 ~97 stone 3
fill ~76 ~53 ~97 ~77 ~53 ~97 stone 3
fill ~78 ~53 ~97 ~79 ~53 ~97 stone
setblock ~80 ~53 ~97 activator_rail 1
setblock ~81 ~53 ~97 stone_brick_stairs 3
setblock ~82 ~53 ~97 activator_rail 1
fill ~76 ~53 ~98 ~79 ~53 ~104 grass
setblock ~80 ~53 ~98 activator_rail 1
setblock ~81 ~53 ~98 stone
setblock ~82 ~53 ~98 activator_rail 1
fill ~83 ~53 ~98 ~83 ~53 ~102 grass
fill ~84 ~53 ~98 ~85 ~53 ~98 stone 3
fill ~86 ~53 ~98 ~86 ~53 ~105 grass
setblock ~80 ~53 ~99 activator_rail 1
setblock ~81 ~53 ~99 stone_brick_stairs 3
setblock ~82 ~53 ~99 activator_rail 1
setblock ~84 ~53 ~99 stone 6
fill ~85 ~53 ~99 ~86 ~53 ~99 grass
setblock ~80 ~53 ~100 activator_rail 1
setblock ~81 ~53 ~100 stone
setblock ~82 ~53 ~100 activator_rail 1
fill ~84 ~53 ~100 ~84 ~53 ~118 grass
setblock ~85 ~53 ~100 stone 6
setblock ~80 ~53 ~101 activator_rail 1
setblock ~81 ~53 ~101 stone_brick_stairs 3
setblock ~82 ~53 ~101 activator_rail 1
fill ~85 ~53 ~101 ~86 ~53 ~105 grass
setblock ~80 ~53 ~102 activator_rail 1
setblock ~81 ~53 ~102 stone
setblock ~82 ~53 ~102 activator_rail 1
fill ~15 ~53 ~103 ~16 ~53 ~103 fence
fill ~20 ~53 ~103 ~21 ~53 ~103 fence
setblock ~80 ~53 ~103 activator_rail 1
setblock ~81 ~53 ~103 stone_brick_stairs 3
setblock ~82 ~53 ~103 activator_rail 1
setblock ~83 ~53 ~103 dirt 1
fill ~141 ~53 ~103 ~142 ~53 ~103 fence
fill ~146 ~53 ~103 ~147 ~53 ~103 fence
setblock ~14 ~53 ~104 fence
setblock ~22 ~53 ~104 fence
setblock ~80 ~53 ~104 activator_rail 1
setblock ~81 ~53 ~104 stone
setblock ~82 ~53 ~104 activator_rail 1
fill ~83 ~53 ~104 ~83 ~53 ~125 grass
setblock ~140 ~53 ~104 fence
setblock ~148 ~53 ~104 fence
setblock ~76 ~53 ~105 grass
fill ~77 ~53 ~105 ~77 ~53 ~107 stone 6
fill ~78 ~53 ~105 ~79 ~53 ~123 grass
setblock ~80 ~53 ~105 activator_rail 1
setblock ~81 ~53 ~105 stone_brick_stairs 3
setblock ~82 ~53 ~105 activator_rail 1
fill ~76 ~53 ~106 ~77 ~54 ~106 stone 6
setblock ~80 ~53 ~106 activator_rail 1
setblock ~81 ~53 ~106 stone
fill ~82 ~53 ~106 ~85 ~53 ~106 grass
setblock ~76 ~53 ~107 tallgrass 1
fill ~80 ~53 ~107 ~80 ~53 ~108 grass
setblock ~81 ~53 ~107 stone_brick_stairs 3
setblock ~82 ~53 ~107 activator_rail 1
fill ~85 ~53 ~107 ~85 ~53 ~108 grass
setblock ~86 ~53 ~107 tallgrass 1
fill ~77 ~53 ~108 ~81 ~53 ~108 grass
setblock ~82 ~53 ~108 activator_rail 1
fill ~80 ~53 ~109 ~80 ~53 ~111 dirt
fill ~81 ~53 ~109 ~81 ~53 ~110 dirt 1
fill ~82 ~53 ~109 ~84 ~53 ~110 grass
setblock ~77 ~53 ~110 tallgrass 1
fill ~77 ~53 ~111 ~79 ~53 ~114 grass
fill ~81 ~53 ~111 ~81 ~53 ~115 grass
setblock ~82 ~53 ~111 dirt 1
fill ~85 ~53 ~111 ~85 ~53 ~112 grass
fill ~80 ~53 ~112 ~81 ~53 ~114 grass
setblock ~82 ~53 ~112 dirt
fill ~82 ~53 ~113 ~84 ~53 ~118 grass
fill ~85 ~53 ~113 ~85 ~53 ~115 stone 6
fill ~86 ~53 ~114 ~86 ~55 ~114 stone 6
setblock ~77 ~53 ~115 tallgrass 1
setblock ~80 ~53 ~115 dirt 1
setblock ~80 ~53 ~116 grass
setblock ~81 ~53 ~116 dirt
setblock ~80 ~53 ~117 dirt 1
fill ~81 ~53 ~117 ~84 ~53 ~118 grass
setblock ~87 ~53 ~117 tallgrass 1
fill ~80 ~53 ~118 ~84 ~53 ~118 grass
setblock ~75 ~53 ~119 tallgrass 1
fill ~80 ~53 ~119 ~81 ~53 ~119 dirt 1
fill ~82 ~53 ~119 ~83 ~53 ~120 grass
fill ~80 ~53 ~120 ~81 ~53 ~122 grass
setblock ~82 ~53 ~121 dirt 1
fill ~84 ~53 ~121 ~84 ~53 ~123 grass
setblock ~85 ~53 ~121 tallgrass 1
fill ~82 ~53 ~122 ~84 ~53 ~123 grass
setblock ~80 ~53 ~123 dirt 1
fill ~81 ~53 ~123 ~84 ~53 ~123 grass
setblock ~85 ~53 ~123 tallgrass 1
fill ~79 ~53 ~124 ~81 ~53 ~124 grass
setblock ~82 ~53 ~124 dirt 1
setblock ~79 ~53 ~125 grass
fill ~80 ~53 ~125 ~80 ~53 ~126 stone
setblock ~81 ~53 ~125 grass
fill ~82 ~53 ~125 ~82 ~53 ~126 stone
fill ~78 ~53 ~126 ~79 ~53 ~127 log 12
fill ~81 ~53 ~126 ~82 ~53 ~126 stone
fill ~83 ~53 ~126 ~84 ~53 ~127 log 12
fill ~80 ~53 ~127 ~80 ~64 ~129 log 12
fill ~81 ~53 ~127 ~82 ~55 ~129 log 12
fill ~79 ~53 ~128 ~83 ~55 ~128 log 12
fill ~79 ~53 ~130 ~83 ~53 ~130 log 12
setblock ~58 ~53 ~140 fence
setblock ~104 ~53 ~140 fence
fill ~59 ~53 ~141 ~59 ~53 ~142 fence
fill ~103 ~53 ~141 ~103 ~53 ~142 fence
fill ~59 ~53 ~146 ~59 ~53 ~147 fence
fill ~103 ~53 ~146 ~104 ~53 ~146 fence
setblock ~103 ~53 ~147 fence
setblock ~58 ~53 ~148 fence
setblock ~104 ~53 ~148 fence
fill ~78 ~53 ~159 ~79 ~53 ~159 fence
fill ~83 ~53 ~159 ~84 ~53 ~159 fence
setblock ~77 ~53 ~160 fence
setblock ~85 ~53 ~160 fence
setblock ~80 ~54 ~1 activator_rail 2
setblock ~81 ~54 ~1 activator_rail 2
setblock ~82 ~54 ~1 activator_rail 2
setblock ~80 ~54 ~2 activator_rail 2
setblock ~82 ~54 ~2 activator_rail 2
fill ~75 ~54 ~3 ~77 ~54 ~3 fence
setblock ~80 ~54 ~3 dropper 10
setblock ~82 ~54 ~3 dropper 10
fill ~85 ~54 ~3 ~87 ~54 ~3 fence
fill ~74 ~54 ~4 ~75 ~54 ~4 fence
fill ~87 ~54 ~4 ~88 ~54 ~4 fence
fill ~75 ~54 ~5 ~75 ~55 ~5 fence
fill ~87 ~54 ~5 ~87 ~55 ~5 fence
fill ~74 ~54 ~6 ~74 ~56 ~6 fence
fill ~88 ~54 ~6 ~88 ~56 ~6 fence
fill ~60 ~54 ~11 ~60 ~55 ~11 fence
fill ~62 ~54 ~11 ~62 ~56 ~11 fence
fill ~100 ~54 ~11 ~100 ~56 ~11 fence
fill ~102 ~54 ~11 ~102 ~55 ~11 fence
fill ~59 ~54 ~12 ~61 ~54 ~12 fence
fill ~101 ~54 ~12 ~103 ~54 ~12 fence
setblock ~59 ~54 ~14 fence
setblock ~103 ~54 ~14 fence
setblock ~57 ~54 ~17 activator_rail 2
setblock ~58 ~54 ~17 activator_rail 2
setblock ~59 ~54 ~17 dropper 10
setblock ~103 ~54 ~17 dropper 10
setblock ~104 ~54 ~17 activator_rail 2
setblock ~105 ~54 ~17 activator_rail 2
setblock ~57 ~54 ~18 activator_rail 2
fill ~104 ~54 ~18 ~104 ~58 ~18 quartz_block
setblock ~105 ~54 ~18 activator_rail 2
setblock ~57 ~54 ~19 activator_rail 2
setblock ~58 ~54 ~19 activator_rail 2
setblock ~59 ~54 ~19 dropper 10
setblock ~103 ~54 ~19 dropper 10
setblock ~104 ~54 ~19 activator_rail 2
setblock ~105 ~54 ~19 activator_rail 2
fill ~59 ~54 ~22 ~59 ~54 ~24 fence
fill ~103 ~54 ~22 ~103 ~54 ~24 fence
fill ~60 ~54 ~24 ~61 ~54 ~24 fence
fill ~101 ~54 ~24 ~103 ~54 ~24 fence
fill ~60 ~54 ~25 ~60 ~55 ~25 fence
fill ~62 ~54 ~25 ~62 ~56 ~25 fence
fill ~100 ~54 ~25 ~100 ~56 ~25 fence
fill ~102 ~54 ~25 ~102 ~55 ~25 fence
fill ~81 ~54 ~31 ~82 ~54 ~31 leaves 8
fill ~80 ~54 ~32 ~82 ~54 ~35 log 12
setblock ~75 ~54 ~34 sea_lantern
setblock ~87 ~54 ~34 sea_lantern
fill ~80 ~54 ~36 ~82 ~54 ~36 grass
setblock ~80 ~54 ~37 grass
setblock ~82 ~54 ~37 grass
setblock ~80 ~54 ~38 tallgrass 1
setblock ~82 ~54 ~38 tallgrass 1
setblock ~84 ~54 ~39 tallgrass 1
setblock ~77 ~54 ~51 tallgrass 1
fill ~81 ~54 ~54 ~81 ~54 ~56 rail 0
fill ~85 ~54 ~56 ~86 ~54 ~56 stone 6
setblock ~17 ~54 ~57 activator_rail 2
setblock ~18 ~54 ~57 activator_rail 2
setblock ~19 ~54 ~57 activator_rail 2
fill ~80 ~54 ~57 ~80 ~54 ~58 iron_trapdoor 9
setblock ~81 ~54 ~57 stone_brick_stairs 3
fill ~82 ~54 ~57 ~82 ~54 ~58 iron_trapdoor 8
setblock ~143 ~54 ~57 activator_rail 2
setblock ~144 ~54 ~57 activator_rail 2
setblock ~145 ~54 ~57 activator_rail 2
setblock ~17 ~54 ~58 activator_rail 2
setblock ~19 ~54 ~58 activator_rail 2
setblock ~77 ~54 ~58 tallgrass 1
setblock ~81 ~54 ~58 stone_brick_stairs 2
setblock ~85 ~54 ~58 tallgrass 1
fill ~102 ~54 ~58 ~102 ~56 ~58 fence
setblock ~143 ~54 ~58 activator_rail 2
setblock ~145 ~54 ~58 activator_rail 2
fill ~12 ~54 ~59 ~14 ~54 ~59 fence
setblock ~17 ~54 ~59 dropper 10
setblock ~19 ~54 ~59 dropper 10
fill ~22 ~54 ~59 ~24 ~54 ~59 fence
fill ~81 ~54 ~59 ~81 ~54 ~71 rail 0
fill ~138 ~54 ~59 ~140 ~54 ~59 fence
setblock ~143 ~54 ~59 dropper 10
setblock ~145 ~54 ~59 dropper 10
fill ~148 ~54 ~59 ~150 ~54 ~59 fence
fill ~11 ~54 ~60 ~12 ~54 ~60 fence
fill ~24 ~54 ~60 ~25 ~54 ~60 fence
fill ~58 ~54 ~60 ~58 ~56 ~60 fence
fill ~137 ~54 ~60 ~138 ~54 ~60 fence
fill ~150 ~54 ~60 ~151 ~54 ~60 fence
fill ~12 ~54 ~61 ~12 ~55 ~61 fence
fill ~24 ~54 ~61 ~24 ~55 ~61 fence
fill ~138 ~54 ~61 ~138 ~55 ~61 fence
fill ~150 ~54 ~61 ~150 ~55 ~61 fence
fill ~11 ~54 ~62 ~11 ~56 ~62 fence
fill ~25 ~54 ~62 ~25 ~56 ~62 fence
setblock ~77 ~54 ~62 gold_ore
fill ~137 ~54 ~62 ~137 ~56 ~62 fence
fill ~151 ~54 ~62 ~151 ~56 ~62 fence
setblock ~78 ~54 ~63 gold_ore
fill ~77 ~54 ~64 ~78 ~54 ~65 stone 6
fill ~76 ~54 ~65 ~78 ~54 ~65 stone 6
fill ~79 ~54 ~65 ~79 ~57 ~65 log 12
fill ~83 ~54 ~65 ~83 ~56 ~65 log 12
fill ~84 ~54 ~65 ~84 ~54 ~70 stone 3
fill ~76 ~54 ~66 ~76 ~56 ~66 stone 6
fill ~77 ~54 ~66 ~79 ~54 ~69 stone 3
setblock ~83 ~54 ~66 stone
fill ~75 ~54 ~67 ~79 ~54 ~68 stone 3
fill ~83 ~54 ~67 ~85 ~56 ~69 stone 3
setblock ~89 ~54 ~68 gold_ore
setblock ~72 ~54 ~69 log 12
fill ~73 ~54 ~69 ~73 ~56 ~69 stone 3
fill ~75 ~54 ~69 ~75 ~54 ~72 stone
fill ~76 ~54 ~69 ~79 ~63 ~69 stone 3
fill ~89 ~54 ~69 ~89 ~59 ~73 stone 3
fill ~72 ~54 ~70 ~72 ~64 ~74 stone 3
fill ~76 ~54 ~70 ~78 ~54 ~70 stone
setblock ~76 ~54 ~71 diamond_ore
fill ~85 ~54 ~71 ~91 ~58 ~71 stone 3
fill ~92 ~54 ~72 ~92 ~64 ~72 stone 3
setblock ~93 ~54 ~72 log 12
setblock ~68 ~54 ~73 gold_ore
fill ~69 ~54 ~73 ~69 ~59 ~79 stone 3
fill ~73 ~54 ~73 ~73 ~66 ~73 stone 3
fill ~88 ~54 ~73 ~89 ~55 ~73 stone 3
fill ~90 ~54 ~73 ~92 ~54 ~75 stone
fill ~93 ~54 ~73 ~93 ~56 ~73 stone 3
fill ~4 ~54 ~74 ~4 ~55 ~74 fence
fill ~6 ~54 ~74 ~6 ~56 ~74 fence
fill ~68 ~54 ~74 ~69 ~57 ~79 stone 3
fill ~73 ~54 ~74 ~73 ~55 ~74 stone 3
fill ~93 ~54 ~74 ~93 ~55 ~74 stone
fill ~156 ~54 ~74 ~156 ~56 ~74 fence
fill ~158 ~54 ~74 ~158 ~55 ~74 fence
fill ~3 ~54 ~75 ~5 ~54 ~75 fence
setblock ~34 ~54 ~75 sea_lantern
setblock ~93 ~54 ~75 stone
fill ~94 ~54 ~75 ~94 ~58 ~79 stone 3
fill ~95 ~54 ~75 ~95 ~54 ~79 stone 3
setblock ~128 ~54 ~75 sea_lantern
fill ~157 ~54 ~75 ~159 ~54 ~75 fence
fill ~66 ~54 ~76 ~70 ~54 ~78 stone 3
setblock ~91 ~54 ~76 diamond_ore
fill ~92 ~54 ~76 ~92 ~54 ~78 stone
fill ~93 ~54 ~76 ~93 ~63 ~79 stone 3
fill ~96 ~54 ~76 ~96 ~56 ~76 stone 6
fill ~97 ~54 ~76 ~97 ~54 ~78 stone 6
setblock ~3 ~54 ~77 fence
setblock ~58 ~54 ~77 tallgrass 1
fill ~71 ~54 ~77 ~71 ~65 ~77 stone 3
fill ~91 ~54 ~77 ~92 ~54 ~77 stone
fill ~96 ~54 ~77 ~96 ~54 ~79 stone 3
fill ~98 ~54 ~77 ~98 ~54 ~78 stone 6
setblock ~100 ~54 ~77 gold_ore
setblock ~104 ~54 ~77 tallgrass 1
setblock ~111 ~54 ~77 tallgrass 1
setblock ~159 ~54 ~77 fence
setblock ~39 ~54 ~78 tallgrass 1
fill ~65 ~54 ~78 ~70 ~54 ~78 stone 3
setblock ~99 ~54 ~78 gold_ore
fill ~65 ~54 ~79 ~65 ~56 ~79 log 12
setblock ~66 ~54 ~79 stone
fill ~67 ~54 ~79 ~69 ~56 ~79 stone 3
fill ~97 ~54 ~79 ~97 ~57 ~79 log 12
fill ~127 ~54 ~79 ~128 ~54 ~83 log 12
setblock ~1 ~54 ~80 activator_rail 2
setblock ~2 ~54 ~80 activator_rail 2
setblock ~3 ~54 ~80 dropper 10
fill ~31 ~54 ~80 ~31 ~54 ~81 leaves 8
fill ~32 ~54 ~80 ~35 ~54 ~82 log 12
fill ~36 ~54 ~80 ~36 ~54 ~82 grass
setblock ~37 ~54 ~80 grass
fill ~57 ~54 ~80 ~58 ~54 ~80 iron_trapdoor 11
fill ~104 ~54 ~80 ~105 ~54 ~80 iron_trapdoor 11
setblock ~124 ~54 ~80 tallgrass 1
fill ~125 ~54 ~80 ~126 ~54 ~80 grass
fill ~130 ~54 ~80 ~130 ~54 ~82 log 12
setblock ~159 ~54 ~80 dropper 10
setblock ~160 ~54 ~80 activator_rail 2
setblock ~161 ~54 ~80 activator_rail 2
setblock ~1 ~54 ~81 activator_rail 2
setblock ~54 ~54 ~81 rail 1
setblock ~55 ~54 ~81 rail 1
setblock ~56 ~54 ~81 rail 1
setblock ~57 ~54 ~81 stone_brick_stairs 1
setblock ~58 ~54 ~81 stone_brick_stairs 0
setblock ~59 ~54 ~81 rail 1
setblock ~60 ~54 ~81 rail 1
setblock ~61 ~54 ~81 rail 1
setblock ~62 ~54 ~81 rail 1
setblock ~63 ~54 ~81 rail 1
setblock ~64 ~54 ~81 rail 1
setblock ~65 ~54 ~81 rail 1
setblock ~66 ~54 ~81 rail 1
setblock ~67 ~54 ~81 rail 1
setblock ~68 ~54 ~81 rail 1
setblock ~69 ~54 ~81 rail 1
setblock ~70 ~54 ~81 rail 1
setblock ~71 ~54 ~81 rail 1
setblock ~81 ~54 ~81 enchanting_table
setblock ~91 ~54 ~81 rail 1
setblock ~92 ~54 ~81 rail 1
setblock ~93 ~54 ~81 rail 1
setblock ~94 ~54 ~81 rail 1
setblock ~95 ~54 ~81 rail 1
setblock ~96 ~54 ~81 rail 1
setblock ~97 ~54 ~81 rail 1
setblock ~98 ~54 ~81 rail 1
setblock ~99 ~54 ~81 rail 1
setblock ~100 ~54 ~81 rail 1
setblock ~101 ~54 ~81 rail 1
setblock ~102 ~54 ~81 rail 1
setblock ~103 ~54 ~81 rail 1
setblock ~104 ~54 ~81 stone_brick_stairs 1
setblock ~105 ~54 ~81 stone_brick_stairs 0
setblock ~106 ~54 ~81 rail 1
setblock ~107 ~54 ~81 rail 1
setblock ~108 ~54 ~81 rail 1
fill ~126 ~54 ~81 ~126 ~54 ~82 grass
fill ~131 ~54 ~81 ~131 ~54 ~82 leaves 8
fill ~160 ~54 ~81 ~160 ~58 ~81 quartz_block
setblock ~161 ~54 ~81 activator_rail 2
setblock ~1 ~54 ~82 activator_rail 2
setblock ~2 ~54 ~82 activator_rail 2
setblock ~3 ~54 ~82 dropper 10
setblock ~37 ~54 ~82 grass
setblock ~38 ~54 ~82 tallgrass 1
fill ~57 ~54 ~82 ~58 ~54 ~82 iron_trapdoor 10
fill ~104 ~54 ~82 ~105 ~54 ~82 iron_trapdoor 10
fill ~125 ~54 ~82 ~126 ~54 ~82 grass
setblock ~159 ~54 ~82 dropper 10
setblock ~160 ~54 ~82 activator_rail 2
setblock ~161 ~54 ~82 activator_rail 2
fill ~65 ~54 ~83 ~65 ~57 ~83 log 12
fill ~66 ~54 ~83 ~69 ~54 ~85 stone 3
fill ~93 ~54 ~83 ~93 ~59 ~89 stone 3
fill ~94 ~54 ~83 ~94 ~57 ~88 stone 3
fill ~95 ~54 ~83 ~95 ~56 ~85 stone 3
setblock ~96 ~54 ~83 stone
fill ~97 ~54 ~83 ~97 ~56 ~83 log 12
setblock ~63 ~54 ~84 gold_ore
fill ~64 ~54 ~84 ~65 ~54 ~85 stone 6
fill ~70 ~54 ~84 ~70 ~54 ~89 stone
setblock ~97 ~54 ~84 stone 3
setblock ~123 ~54 ~84 tallgrass 1
fill ~3 ~54 ~85 ~3 ~54 ~87 fence
fill ~48 ~54 ~85 ~48 ~54 ~86 stone 6
setblock ~51 ~54 ~85 tallgrass 1
setblock ~58 ~54 ~85 tallgrass 1
setblock ~62 ~54 ~85 gold_ore
fill ~71 ~54 ~85 ~71 ~55 ~85 stone
setblock ~104 ~54 ~85 tallgrass 1
fill ~106 ~54 ~85 ~106 ~54 ~86 stone 6
fill ~159 ~54 ~85 ~159 ~54 ~87 fence
fill ~65 ~54 ~86 ~66 ~54 ~86 stone 6
fill ~67 ~54 ~86 ~69 ~55 ~86 stone 3
setblock ~71 ~54 ~86 diamond_ore
fill ~4 ~54 ~87 ~5 ~54 ~87 fence
setblock ~34 ~54 ~87 sea_lantern
fill ~67 ~54 ~87 ~68 ~54 ~87 stone 3
fill ~69 ~54 ~87 ~72 ~54 ~88 stone
setblock ~128 ~54 ~87 sea_lantern
fill ~157 ~54 ~87 ~159 ~54 ~87 fence
fill ~4 ~54 ~88 ~4 ~55 ~88 fence
fill ~6 ~54 ~88 ~6 ~56 ~88 fence
fill ~89 ~54 ~88 ~93 ~55 ~89 stone 3
fill ~156 ~54 ~88 ~156 ~56 ~88 fence
fill ~158 ~54 ~88 ~158 ~55 ~88 fence
fill ~69 ~54 ~89 ~69 ~56 ~89 stone 3
fill ~73 ~54 ~89 ~73 ~59 ~93 stone 3
fill ~74 ~54 ~89 ~74 ~55 ~94 stone 3
setblock ~94 ~54 ~89 gold_ore
setblock ~69 ~54 ~90 log 12
fill ~70 ~54 ~90 ~74 ~64 ~90 stone 3
fill ~81 ~54 ~91 ~81 ~54 ~103 rail 0
fill ~85 ~54 ~91 ~85 ~55 ~91 stone
setblock ~86 ~54 ~91 diamond_ore
fill ~87 ~54 ~91 ~89 ~55 ~92 stone
fill ~84 ~54 ~92 ~89 ~54 ~92 stone
fill ~90 ~54 ~92 ~90 ~64 ~92 stone 3
fill ~79 ~54 ~93 ~79 ~56 ~95 stone 3
fill ~83 ~54 ~93 ~86 ~63 ~93 stone 3
fill ~89 ~54 ~93 ~89 ~56 ~93 stone 3
setblock ~90 ~54 ~93 log 12
setblock ~73 ~54 ~94 gold_ore
fill ~76 ~54 ~94 ~79 ~58 ~94 stone 3
fill ~86 ~54 ~94 ~88 ~57 ~94 stone 3
setblock ~87 ~54 ~95 stone 3
setblock ~79 ~54 ~96 stone
fill ~83 ~54 ~96 ~85 ~54 ~96 stone 3
fill ~86 ~54 ~96 ~86 ~56 ~96 stone 6
setblock ~78 ~54 ~97 stone 3
fill ~79 ~54 ~97 ~79 ~56 ~97 log 12
fill ~83 ~54 ~97 ~83 ~57 ~97 log 12
fill ~84 ~54 ~97 ~85 ~54 ~98 stone 6
setblock ~86 ~54 ~97 stone 6
setblock ~84 ~54 ~99 gold_ore
fill ~11 ~54 ~100 ~11 ~56 ~100 fence
fill ~25 ~54 ~100 ~25 ~56 ~100 fence
setblock ~85 ~54 ~100 gold_ore
fill ~137 ~54 ~100 ~137 ~56 ~100 fence
fill ~151 ~54 ~100 ~151 ~56 ~100 fence
fill ~12 ~54 ~101 ~12 ~54 ~103 fence
fill ~24 ~54 ~101 ~24 ~54 ~103 fence
fill ~138 ~54 ~101 ~138 ~54 ~103 fence
fill ~150 ~54 ~101 ~150 ~54 ~103 fence
fill ~11 ~54 ~102 ~12 ~54 ~102 fence
fill ~25 ~54 ~102 ~25 ~55 ~102 fence
fill ~104 ~54 ~102 ~104 ~56 ~102 fence
fill ~137 ~54 ~102 ~138 ~54 ~102 fence
fill ~151 ~54 ~102 ~151 ~55 ~102 fence
setblock ~14 ~54 ~103 fence
setblock ~17 ~54 ~103 dropper 10
setblock ~19 ~54 ~103 dropper 10
fill ~22 ~54 ~103 ~24 ~54 ~103 fence
setblock ~140 ~54 ~103 fence
setblock ~143 ~54 ~103 dropper 10
setblock ~145 ~54 ~103 dropper 10
fill ~148 ~54 ~103 ~150 ~54 ~103 fence
setblock ~17 ~54 ~104 activator_rail 2
fill ~18 ~54 ~104 ~18 ~58 ~104 quartz_block
setblock ~19 ~54 ~104 activator_rail 2
fill ~60 ~54 ~104 ~60 ~56 ~104 fence
setblock ~77 ~54 ~104 tallgrass 1
fill ~80 ~54 ~104 ~80 ~54 ~105 iron_trapdoor 9
setblock ~81 ~54 ~104 stone_brick_stairs 3
fill ~82 ~54 ~104 ~82 ~54 ~105 iron_trapdoor 8
setblock ~85 ~54 ~104 tallgrass 1
setblock ~143 ~54 ~104 activator_rail 2
fill ~144 ~54 ~104 ~144 ~58 ~104 quartz_block
setblock ~145 ~54 ~104 activator_rail 2
setblock ~17 ~54 ~105 activator_rail 2
setblock ~18 ~54 ~105 activator_rail 2
setblock ~19 ~54 ~105 activator_rail 2
setblock ~81 ~54 ~105 stone_brick_stairs 2
setblock ~143 ~54 ~105 activator_rail 2
setblock ~144 ~54 ~105 activator_rail 2
setblock ~145 ~54 ~105 activator_rail 2
fill ~81 ~54 ~106 ~81 ~54 ~108 rail 0
setblock ~85 ~54 ~111 tallgrass 1
fill ~85 ~54 ~114 ~86 ~54 ~114 stone 6
setblock ~78 ~54 ~123 tallgrass 1
setblock ~82 ~54 ~124 tallgrass 1
fill ~80 ~54 ~125 ~80 ~54 ~126 grass
fill ~82 ~54 ~125 ~82 ~54 ~126 grass
fill ~81 ~54 ~126 ~82 ~54 ~126 grass
fill ~79 ~54 ~127 ~83 ~54 ~128 log 12
setblock ~75 ~54 ~128 sea_lantern
setblock ~87 ~54 ~128 sea_lantern
fill ~80 ~54 ~130 ~82 ~54 ~130 log 12
fill ~80 ~54 ~131 ~81 ~54 ~131 leaves 8
fill ~60 ~54 ~137 ~60 ~55 ~137 fence
fill ~62 ~54 ~137 ~62 ~56 ~137 fence
fill ~100 ~54 ~137 ~100 ~56 ~137 fence
fill ~102 ~54 ~137 ~102 ~55 ~137 fence
fill ~59 ~54 ~138 ~61 ~54 ~138 fence
fill ~101 ~54 ~138 ~103 ~54 ~138 fence
setblock ~59 ~54 ~140 fence
setblock ~103 ~54 ~140 fence
setblock ~57 ~54 ~143 activator_rail 2
setblock ~58 ~54 ~143 activator_rail 2
setblock ~59 ~54 ~143 dropper 10
setblock ~103 ~54 ~143 dropper 10
setblock ~104 ~54 ~143 activator_rail 2
setblock ~105 ~54 ~143 activator_rail 2
setblock ~57 ~54 ~144 activator_rail 2
fill ~104 ~54 ~144 ~104 ~58 ~144 quartz_block
setblock ~105 ~54 ~144 activator_rail 2
setblock ~57 ~54 ~145 activator_rail 2
setblock ~58 ~54 ~145 activator_rail 2
setblock ~59 ~54 ~145 dropper 10
setblock ~103 ~54 ~145 dropper 10
setblock ~104 ~54 ~145 activator_rail 2
setblock ~105 ~54 ~145 activator_rail 2
fill ~59 ~54 ~148 ~59 ~54 ~150 fence
fill ~103 ~54 ~148 ~103 ~54 ~150 fence
fill ~60 ~54 ~150 ~61 ~54 ~150 fence
fill ~101 ~54 ~150 ~103 ~54 ~150 fence
fill ~60 ~54 ~151 ~60 ~55 ~151 fence
fill ~62 ~54 ~151 ~62 ~56 ~151 fence
fill ~100 ~54 ~151 ~100 ~56 ~151 fence
fill ~102 ~54 ~151 ~102 ~55 ~151 fence
fill ~74 ~54 ~156 ~74 ~56 ~156 fence
fill ~88 ~54 ~156 ~88 ~56 ~156 fence
fill ~75 ~54 ~157 ~75 ~54 ~159 fence
fill ~87 ~54 ~157 ~87 ~54 ~159 fence
fill ~74 ~54 ~158 ~75 ~54 ~158 fence
fill ~88 ~54 ~158 ~88 ~55 ~158 fence
setblock ~77 ~54 ~159 fence
setblock ~80 ~54 ~159 dropper 10
setblock ~82 ~54 ~159 dropper 10
fill ~85 ~54 ~159 ~87 ~54 ~159 fence
setblock ~80 ~54 ~160 activator_rail 2
fill ~81 ~54 ~160 ~81 ~58 ~160 quartz_block
setblock ~82 ~54 ~160 activator_rail 2
setblock ~80 ~54 ~161 activator_rail 2
setblock ~81 ~54 ~161 activator_rail 2
setblock ~82 ~54 ~161 activator_rail 2
fill ~81 ~55 ~1 ~81 ~55 ~2 quartz_block
fill ~80 ~55 ~2 ~82 ~57 ~2 quartz_block
setblock ~80 ~55 ~3 dropper 2
setblock ~81 ~55 ~3 activator_rail 2
setblock ~82 ~55 ~3 dropper 2
fill ~74 ~55 ~4 ~74 ~55 ~6 fence
fill ~75 ~55 ~4 ~76 ~56 ~4 wool 14
fill ~86 ~55 ~4 ~87 ~56 ~4 wool 14
fill ~88 ~55 ~4 ~88 ~55 ~6 fence
fill ~61 ~55 ~11 ~62 ~55 ~11 fence
fill ~101 ~55 ~11 ~102 ~55 ~11 fence
fill ~60 ~55 ~12 ~60 ~56 ~13 wool 14
setblock ~61 ~55 ~12 fence
setblock ~101 ~55 ~12 fence
fill ~102 ~55 ~12 ~102 ~56 ~13 wool 14
fill ~58 ~55 ~17 ~58 ~57 ~19 quartz_block
setblock ~59 ~55 ~17 dropper 2
setblock ~103 ~55 ~17 dropper 2
fill ~104 ~55 ~17 ~104 ~57 ~19 quartz_block
fill ~57 ~55 ~18 ~58 ~55 ~18 quartz_block
setblock ~59 ~55 ~18 activator_rail 2
setblock ~103 ~55 ~18 activator_rail 2
setblock ~105 ~55 ~18 quartz_block
setblock ~59 ~55 ~19 dropper 2
setblock ~103 ~55 ~19 dropper 2
fill ~60 ~55 ~23 ~60 ~56 ~24 wool 14
fill ~102 ~55 ~23 ~102 ~56 ~24 wool 14
fill ~61 ~55 ~24 ~61 ~55 ~25 fence
fill ~101 ~55 ~24 ~101 ~55 ~25 fence
fill ~80 ~55 ~31 ~80 ~55 ~32 leaves 8
fill ~81 ~55 ~32 ~81 ~66 ~33 log 12
fill ~82 ~55 ~32 ~82 ~56 ~32 leaves 8
setblock ~79 ~55 ~33 leaves 8
setblock ~83 ~55 ~33 leaves 8
setblock ~72 ~55 ~34 stone_slab
setblock ~73 ~55 ~34 double_stone_slab
setblock ~74 ~55 ~34 stone_slab 8
setblock ~75 ~55 ~34 fence
fill ~79 ~55 ~34 ~83 ~55 ~34 log 12
setblock ~87 ~55 ~34 fence
setblock ~88 ~55 ~34 stone_slab 8
setblock ~89 ~55 ~34 double_stone_slab
setblock ~90 ~55 ~34 stone_slab
fill ~80 ~55 ~35 ~80 ~64 ~35 log 12
fill ~81 ~55 ~35 ~82 ~55 ~35 log 12
fill ~75 ~55 ~48 ~75 ~57 ~48 stone 6
setblock ~76 ~55 ~48 stone 6
fill ~102 ~55 ~53 ~102 ~61 ~53 log 0
fill ~103 ~55 ~53 ~103 ~56 ~53 fence
fill ~107 ~55 ~53 ~107 ~56 ~53 fence
fill ~108 ~55 ~53 ~108 ~61 ~53 log 0
fill ~53 ~55 ~54 ~53 ~61 ~54 log 0
fill ~54 ~55 ~54 ~54 ~56 ~54 fence
fill ~58 ~55 ~54 ~58 ~56 ~54 fence
fill ~59 ~55 ~54 ~59 ~61 ~54 log 0
fill ~102 ~55 ~54 ~102 ~56 ~54 fence
fill ~108 ~55 ~54 ~108 ~56 ~54 fence
fill ~53 ~55 ~55 ~53 ~56 ~55 fence
fill ~59 ~55 ~55 ~59 ~56 ~55 fence
fill ~87 ~55 ~56 ~87 ~57 ~56 stone 6
fill ~18 ~55 ~57 ~18 ~55 ~58 quartz_block
fill ~144 ~55 ~57 ~144 ~55 ~58 quartz_block
fill ~17 ~55 ~58 ~19 ~57 ~58 quartz_block
fill ~108 ~55 ~58 ~108 ~56 ~58 fence
fill ~143 ~55 ~58 ~145 ~57 ~58 quartz_block
setblock ~17 ~55 ~59 dropper 2
setblock ~18 ~55 ~59 activator_rail 2
setblock ~19 ~55 ~59 dropper 2
fill ~53 ~55 ~59 ~53 ~56 ~59 fence
fill ~59 ~55 ~59 ~59 ~56 ~59 fence
fill ~102 ~55 ~59 ~102 ~61 ~59 log 0
fill ~103 ~55 ~59 ~103 ~56 ~59 fence
fill ~107 ~55 ~59 ~107 ~56 ~59 fence
fill ~108 ~55 ~59 ~108 ~61 ~59 log 0
setblock ~143 ~55 ~59 dropper 2
setblock ~144 ~55 ~59 activator_rail 2
setblock ~145 ~55 ~59 dropper 2
fill ~11 ~55 ~60 ~11 ~55 ~62 fence
fill ~12 ~55 ~60 ~13 ~56 ~60 wool 14
fill ~23 ~55 ~60 ~24 ~56 ~60 wool 14
fill ~25 ~55 ~60 ~25 ~55 ~62 fence
fill ~53 ~55 ~60 ~53 ~61 ~60 log 0
fill ~54 ~55 ~60 ~54 ~56 ~60 fence
fill ~59 ~55 ~60 ~59 ~61 ~60 log 0
fill ~137 ~55 ~60 ~137 ~55 ~62 fence
fill ~138 ~55 ~60 ~139 ~56 ~60 wool 14
fill ~149 ~55 ~60 ~150 ~56 ~60 wool 14
fill ~151 ~55 ~60 ~151 ~55 ~62 fence
setblock ~76 ~55 ~62 stone 6
setblock ~77 ~55 ~63 stone 6
setblock ~76 ~55 ~64 stone 6
fill ~77 ~55 ~64 ~77 ~56 ~65 gold_ore
setblock ~78 ~55 ~64 gold_ore
fill ~75 ~55 ~65 ~75 ~56 ~66 stone 6
fill ~76 ~55 ~65 ~77 ~56 ~65 gold_ore
setblock ~78 ~55 ~65 stone 6
setblock ~77 ~55 ~66 stone 6
fill ~78 ~55 ~66 ~78 ~56 ~70 stone 3
fill ~84 ~55 ~66 ~85 ~55 ~71 stone 3
fill ~76 ~55 ~67 ~79 ~55 ~69 stone 3
fill ~86 ~55 ~67 ~86 ~55 ~71 stone 3
fill ~75 ~55 ~68 ~79 ~58 ~69 stone 3
fill ~87 ~55 ~68 ~89 ~56 ~71 stone 3
fill ~71 ~55 ~69 ~71 ~56 ~70 log 12
fill ~90 ~55 ~69 ~90 ~56 ~73 stone 3
fill ~76 ~55 ~70 ~78 ~65 ~70 stone 3
fill ~76 ~55 ~71 ~78 ~55 ~71 stone
fill ~93 ~55 ~71 ~93 ~56 ~71 log 12
setblock ~34 ~55 ~72 stone_slab
fill ~69 ~55 ~72 ~73 ~56 ~73 stone 3
fill ~75 ~55 ~72 ~75 ~57 ~72 stone
fill ~87 ~55 ~72 ~92 ~55 ~72 stone 3
setblock ~128 ~55 ~72 stone_slab
setblock ~34 ~55 ~73 double_stone_slab
fill ~68 ~55 ~73 ~69 ~56 ~79 stone 3
fill ~91 ~55 ~73 ~92 ~55 ~75 stone
setblock ~128 ~55 ~73 double_stone_slab
fill ~5 ~55 ~74 ~6 ~55 ~74 fence
setblock ~34 ~55 ~74 stone_slab 8
setblock ~128 ~55 ~74 stone_slab 8
fill ~157 ~55 ~74 ~158 ~55 ~74 fence
fill ~4 ~55 ~75 ~4 ~56 ~76 wool 14
setblock ~5 ~55 ~75 fence
setblock ~34 ~55 ~75 fence
fill ~56 ~55 ~75 ~56 ~57 ~75 stone 6
fill ~90 ~55 ~75 ~92 ~55 ~75 stone
fill ~93 ~55 ~75 ~93 ~63 ~79 stone 3
fill ~96 ~55 ~75 ~97 ~56 ~75 stone 6
fill ~114 ~55 ~75 ~114 ~57 ~75 stone 6
setblock ~128 ~55 ~75 fence
setblock ~157 ~55 ~75 fence
fill ~158 ~55 ~75 ~158 ~56 ~76 wool 14
setblock ~56 ~55 ~76 stone 6
fill ~67 ~55 ~76 ~71 ~55 ~78 stone 3
fill ~91 ~55 ~76 ~91 ~55 ~78 stone
fill ~92 ~55 ~76 ~92 ~65 ~78 stone 3
fill ~95 ~55 ~76 ~95 ~55 ~79 stone 3
fill ~97 ~55 ~76 ~97 ~56 ~77 gold_ore
setblock ~98 ~55 ~76 stone 6
setblock ~100 ~55 ~76 stone 6
setblock ~114 ~55 ~76 stone 6
setblock ~86 ~55 ~77 log 12
setblock ~96 ~55 ~77 stone 6
fill ~98 ~55 ~77 ~98 ~56 ~77 gold_ore
setblock ~99 ~55 ~77 stone 6
fill ~96 ~55 ~78 ~96 ~56 ~78 stone 3
setblock ~97 ~55 ~78 stone 6
setblock ~98 ~55 ~78 gold_ore
setblock ~33 ~55 ~79 leaves 8
fill ~34 ~55 ~79 ~34 ~55 ~83 log 12
setblock ~129 ~55 ~79 leaves 8
fill ~2 ~55 ~80 ~2 ~57 ~82 quartz_block
setblock ~3 ~55 ~80 dropper 2
fill ~32 ~55 ~80 ~32 ~56 ~80 leaves 8
fill ~35 ~55 ~80 ~35 ~64 ~80 log 12
fill ~130 ~55 ~80 ~131 ~55 ~80 leaves 8
setblock ~159 ~55 ~80 dropper 2
fill ~160 ~55 ~80 ~160 ~57 ~82 quartz_block
fill ~1 ~55 ~81 ~2 ~55 ~81 quartz_block
setblock ~3 ~55 ~81 activator_rail 2
fill ~32 ~55 ~81 ~33 ~66 ~81 log 12
fill ~35 ~55 ~81 ~35 ~55 ~82 log 12
fill ~130 ~55 ~81 ~130 ~66 ~81 log 12
setblock ~159 ~55 ~81 activator_rail 2
setblock ~161 ~55 ~81 quartz_block
setblock ~3 ~55 ~82 dropper 2
fill ~31 ~55 ~82 ~32 ~55 ~82 leaves 8
fill ~130 ~55 ~82 ~130 ~56 ~82 leaves 8
setblock ~159 ~55 ~82 dropper 2
setblock ~33 ~55 ~83 leaves 8
fill ~67 ~55 ~83 ~69 ~56 ~85 stone 3
setblock ~129 ~55 ~83 leaves 8
fill ~64 ~55 ~84 ~64 ~55 ~85 gold_ore
setblock ~65 ~55 ~84 stone 6
fill ~66 ~55 ~84 ~70 ~56 ~84 stone 3
fill ~71 ~55 ~84 ~71 ~55 ~89 stone
fill ~91 ~55 ~84 ~91 ~58 ~91 stone 3
fill ~96 ~55 ~84 ~96 ~56 ~84 stone 3
setblock ~63 ~55 ~85 stone 6
fill ~65 ~55 ~85 ~65 ~56 ~86 gold_ore
fill ~66 ~55 ~85 ~66 ~55 ~87 stone 6
fill ~70 ~55 ~85 ~70 ~65 ~86 stone 3
fill ~76 ~55 ~85 ~77 ~55 ~85 log 12
fill ~4 ~55 ~86 ~4 ~56 ~87 wool 14
setblock ~62 ~55 ~86 stone 6
setblock ~64 ~55 ~86 stone 6
setblock ~85 ~55 ~86 log 12
setblock ~95 ~55 ~86 stone 3
fill ~158 ~55 ~86 ~158 ~56 ~87 wool 14
fill ~5 ~55 ~87 ~5 ~55 ~88 fence
setblock ~34 ~55 ~87 fence
fill ~48 ~55 ~87 ~48 ~57 ~87 stone 6
fill ~65 ~55 ~87 ~66 ~56 ~87 stone 6
fill ~68 ~55 ~87 ~69 ~61 ~87 stone 3
fill ~70 ~55 ~87 ~72 ~55 ~88 stone
fill ~106 ~55 ~87 ~106 ~57 ~87 stone 6
setblock ~128 ~55 ~87 fence
fill ~157 ~55 ~87 ~157 ~55 ~88 fence
setblock ~34 ~55 ~88 stone_slab 8
setblock ~128 ~55 ~88 stone_slab 8
setblock ~34 ~55 ~89 double_stone_slab
fill ~72 ~55 ~89 ~73 ~56 ~93 stone 3
fill ~94 ~55 ~89 ~94 ~56 ~89 stone 3
setblock ~128 ~55 ~89 double_stone_slab
setblock ~34 ~55 ~90 stone_slab
fill ~88 ~55 ~90 ~88 ~56 ~92 stone
fill ~89 ~55 ~90 ~89 ~67 ~90 stone 3
fill ~93 ~55 ~90 ~93 ~56 ~90 stone 3
setblock ~128 ~55 ~90 stone_slab
fill ~69 ~55 ~91 ~70 ~56 ~91 log 12
fill ~78 ~55 ~91 ~78 ~56 ~96 stone 3
fill ~84 ~55 ~91 ~89 ~55 ~91 stone
fill ~84 ~55 ~92 ~86 ~65 ~92 stone 3
fill ~87 ~55 ~93 ~87 ~61 ~94 stone 3
fill ~91 ~55 ~93 ~91 ~56 ~93 log 12
fill ~73 ~55 ~94 ~79 ~56 ~94 stone 3
fill ~76 ~55 ~95 ~79 ~55 ~95 stone 3
fill ~84 ~55 ~96 ~84 ~56 ~96 stone 3
fill ~85 ~55 ~96 ~87 ~55 ~96 stone 6
setblock ~84 ~55 ~97 stone 6
fill ~85 ~55 ~97 ~86 ~56 ~97 gold_ore
fill ~87 ~55 ~97 ~87 ~56 ~97 stone 6
fill ~84 ~55 ~98 ~85 ~55 ~98 gold_ore
setblock ~86 ~55 ~98 stone 6
setblock ~85 ~55 ~99 stone 6
setblock ~86 ~55 ~100 stone 6
fill ~11 ~55 ~101 ~12 ~55 ~101 fence
fill ~24 ~55 ~101 ~25 ~55 ~101 fence
fill ~137 ~55 ~101 ~138 ~55 ~101 fence
fill ~150 ~55 ~101 ~151 ~55 ~101 fence
setblock ~11 ~55 ~102 fence
fill ~12 ~55 ~102 ~13 ~56 ~102 wool 14
fill ~23 ~55 ~102 ~24 ~56 ~102 wool 14
fill ~103 ~55 ~102 ~103 ~61 ~102 log 0
fill ~108 ~55 ~102 ~108 ~56 ~102 fence
fill ~109 ~55 ~102 ~109 ~61 ~102 log 0
setblock ~137 ~55 ~102 fence
fill ~138 ~55 ~102 ~139 ~56 ~102 wool 14
fill ~149 ~55 ~102 ~150 ~56 ~102 wool 14
setblock ~17 ~55 ~103 dropper 2
setblock ~18 ~55 ~103 activator_rail 2
setblock ~19 ~55 ~103 dropper 2
fill ~54 ~55 ~103 ~54 ~61 ~103 log 0
fill ~55 ~55 ~103 ~55 ~56 ~103 fence
fill ~59 ~55 ~103 ~59 ~56 ~103 fence
fill ~60 ~55 ~103 ~60 ~61 ~103 log 0
fill ~103 ~55 ~103 ~103 ~56 ~103 fence
fill ~109 ~55 ~103 ~109 ~56 ~103 fence
setblock ~143 ~55 ~103 dropper 2
setblock ~144 ~55 ~103 activator_rail 2
setblock ~145 ~55 ~103 dropper 2
fill ~17 ~55 ~104 ~19 ~57 ~104 quartz_block
fill ~54 ~55 ~104 ~54 ~56 ~104 fence
fill ~143 ~55 ~104 ~145 ~57 ~104 quartz_block
setblock ~18 ~55 ~105 quartz_block
setblock ~144 ~55 ~105 quartz_block
fill ~75 ~55 ~106 ~75 ~57 ~106 stone 6
setblock ~76 ~55 ~106 stone 6
fill ~103 ~55 ~107 ~103 ~56 ~107 fence
fill ~109 ~55 ~107 ~109 ~56 ~107 fence
fill ~54 ~55 ~108 ~54 ~56 ~108 fence
fill ~60 ~55 ~108 ~60 ~56 ~108 fence
fill ~103 ~55 ~108 ~103 ~61 ~108 log 0
fill ~104 ~55 ~108 ~104 ~56 ~108 fence
fill ~108 ~55 ~108 ~108 ~56 ~108 fence
fill ~109 ~55 ~108 ~109 ~61 ~108 log 0
fill ~54 ~55 ~109 ~54 ~61 ~109 log 0
fill ~55 ~55 ~109 ~55 ~56 ~109 fence
fill ~59 ~55 ~109 ~59 ~56 ~109 fence
fill ~60 ~55 ~109 ~60 ~61 ~109 log 0
fill ~87 ~55 ~114 ~87 ~57 ~114 stone 6
setblock ~72 ~55 ~128 stone_slab
setblock ~73 ~55 ~128 double_stone_slab
setblock ~74 ~55 ~128 stone_slab 8
setblock ~75 ~55 ~128 fence
setblock ~87 ~55 ~128 fence
setblock ~88 ~55 ~128 stone_slab 8
setblock ~89 ~55 ~128 double_stone_slab
setblock ~90 ~55 ~128 stone_slab
setblock ~79 ~55 ~129 leaves 8
setblock ~83 ~55 ~129 leaves 8
fill ~80 ~55 ~130 ~80 ~56 ~130 leaves 8
fill ~81 ~55 ~130 ~81 ~66 ~130 log 12
fill ~82 ~55 ~130 ~82 ~56 ~130 leaves 8
setblock ~82 ~55 ~131 leaves 8
fill ~61 ~55 ~137 ~62 ~55 ~137 fence
fill ~101 ~55 ~137 ~102 ~55 ~137 fence
fill ~60 ~55 ~138 ~60 ~56 ~139 wool 14
setblock ~61 ~55 ~138 fence
setblock ~101 ~55 ~138 fence
fill ~102 ~55 ~138 ~102 ~56 ~139 wool 14
fill ~58 ~55 ~143 ~58 ~57 ~145 quartz_block
setblock ~59 ~55 ~143 dropper 2
setblock ~103 ~55 ~143 dropper 2
fill ~104 ~55 ~143 ~104 ~57 ~145 quartz_block
fill ~57 ~55 ~144 ~58 ~55 ~144 quartz_block
setblock ~59 ~55 ~144 activator_rail 2
setblock ~103 ~55 ~144 activator_rail 2
setblock ~105 ~55 ~144 quartz_block
setblock ~59 ~55 ~145 dropper 2
setblock ~103 ~55 ~145 dropper 2
fill ~60 ~55 ~149 ~60 ~56 ~150 wool 14
fill ~102 ~55 ~149 ~102 ~56 ~150 wool 14
fill ~61 ~55 ~150 ~61 ~55 ~151 fence
fill ~101 ~55 ~150 ~101 ~55 ~151 fence
fill ~74 ~55 ~157 ~75 ~55 ~157 fence
fill ~87 ~55 ~157 ~88 ~55 ~157 fence
setblock ~74 ~55 ~158 fence
fill ~75 ~55 ~158 ~76 ~56 ~158 wool 14
fill ~86 ~55 ~158 ~87 ~56 ~158 wool 14
setblock ~80 ~55 ~159 dropper 2
setblock ~81 ~55 ~159 activator_rail 2
setblock ~82 ~55 ~159 dropper 2
fill ~80 ~55 ~160 ~82 ~57 ~160 quartz_block
setblock ~81 ~55 ~161 quartz_block
fill ~80 ~56 ~3 ~82 ~59 ~3 quartz_block
fill ~75 ~56 ~5 ~76 ~56 ~5 wool 14
fill ~86 ~56 ~5 ~87 ~56 ~5 wool 14
fill ~75 ~56 ~6 ~75 ~57 ~6 wool 14
fill ~87 ~56 ~6 ~87 ~57 ~6 wool 14
fill ~61 ~56 ~12 ~62 ~56 ~12 wool 14
fill ~100 ~56 ~12 ~102 ~56 ~12 wool 14
setblock ~61 ~56 ~13 wool 14
fill ~101 ~56 ~13 ~102 ~56 ~13 wool 14
fill ~59 ~56 ~17 ~59 ~59 ~19 quartz_block
fill ~103 ~56 ~17 ~104 ~57 ~19 quartz_block
fill ~61 ~56 ~23 ~61 ~56 ~24 wool 14
fill ~101 ~56 ~23 ~102 ~56 ~24 wool 14
fill ~62 ~56 ~24 ~62 ~57 ~24 wool 14
fill ~100 ~56 ~24 ~102 ~56 ~24 wool 14
fill ~88 ~56 ~29 ~88 ~57 ~29 cobblestone
fill ~81 ~56 ~30 ~81 ~57 ~31 leaves 8
fill ~87 ~56 ~30 ~88 ~58 ~30 stone 5
setblock ~89 ~56 ~30 cobblestone
setblock ~88 ~56 ~31 cobblestone
fill ~79 ~56 ~32 ~79 ~58 ~32 leaves 8
setblock ~80 ~56 ~32 leaves 8
fill ~83 ~56 ~32 ~83 ~57 ~32 leaves 8
fill ~78 ~56 ~33 ~78 ~57 ~34 leaves 8
fill ~79 ~56 ~33 ~83 ~62 ~33 log 12
fill ~84 ~56 ~33 ~84 ~57 ~34 leaves 8
fill ~74 ~56 ~34 ~75 ~56 ~34 stone_slab
setblock ~79 ~56 ~34 leaves 8
fill ~80 ~56 ~34 ~82 ~65 ~34 log 12
fill ~83 ~56 ~34 ~84 ~56 ~34 leaves 8
fill ~87 ~56 ~34 ~88 ~56 ~34 stone_slab
fill ~82 ~56 ~35 ~82 ~64 ~35 log 12
fill ~80 ~56 ~36 ~80 ~59 ~36 leaves 8
fill ~82 ~56 ~36 ~82 ~59 ~36 leaves 8
fill ~104 ~56 ~53 ~104 ~58 ~53 fence
fill ~106 ~56 ~53 ~106 ~58 ~53 fence
fill ~55 ~56 ~54 ~55 ~58 ~54 fence
fill ~57 ~56 ~54 ~57 ~58 ~54 fence
fill ~102 ~56 ~55 ~102 ~59 ~55 fence
fill ~108 ~56 ~55 ~108 ~58 ~55 fence
fill ~53 ~56 ~56 ~53 ~58 ~56 fence
fill ~59 ~56 ~56 ~59 ~58 ~56 fence
fill ~102 ~56 ~57 ~102 ~58 ~57 fence
fill ~108 ~56 ~57 ~108 ~58 ~57 fence
fill ~53 ~56 ~58 ~53 ~58 ~58 fence
fill ~59 ~56 ~58 ~59 ~58 ~58 fence
fill ~17 ~56 ~59 ~19 ~59 ~59 quartz_block
fill ~104 ~56 ~59 ~104 ~58 ~59 fence
fill ~106 ~56 ~59 ~106 ~58 ~59 fence
fill ~143 ~56 ~59 ~145 ~59 ~59 quartz_block
fill ~55 ~56 ~60 ~55 ~59 ~60 fence
fill ~57 ~56 ~60 ~57 ~58 ~60 fence
fill ~12 ~56 ~61 ~13 ~56 ~61 wool 14
fill ~23 ~56 ~61 ~24 ~56 ~61 wool 14
fill ~138 ~56 ~61 ~139 ~56 ~61 wool 14
fill ~149 ~56 ~61 ~150 ~56 ~61 wool 14
fill ~12 ~56 ~62 ~12 ~57 ~62 wool 14
fill ~24 ~56 ~62 ~24 ~57 ~62 wool 14
fill ~138 ~56 ~62 ~138 ~57 ~62 wool 14
fill ~150 ~56 ~62 ~150 ~57 ~62 wool 14
fill ~75 ~56 ~64 ~75 ~56 ~67 stone 6
fill ~83 ~56 ~64 ~83 ~59 ~64 log 12
fill ~84 ~56 ~66 ~84 ~56 ~71 stone 3
setblock ~85 ~56 ~66 gold_ore
setblock ~76 ~56 ~67 stone 6
fill ~77 ~56 ~67 ~79 ~56 ~71 stone 3
fill ~87 ~56 ~67 ~87 ~57 ~67 log 12
fill ~86 ~56 ~68 ~87 ~59 ~71 stone 3
fill ~70 ~56 ~69 ~71 ~56 ~70 log 12
fill ~74 ~56 ~69 ~79 ~62 ~69 stone 3
fill ~73 ~56 ~70 ~73 ~65 ~73 stone 3
fill ~74 ~56 ~70 ~74 ~56 ~73 stone
fill ~75 ~56 ~70 ~79 ~65 ~70 stone 3
fill ~83 ~56 ~70 ~90 ~58 ~70 stone 3
fill ~92 ~56 ~70 ~92 ~61 ~70 log 12
fill ~93 ~56 ~70 ~93 ~57 ~70 log 12
fill ~75 ~56 ~71 ~75 ~56 ~72 stone
fill ~76 ~56 ~71 ~79 ~66 ~71 stone 3
setblock ~76 ~56 ~72 stone
fill ~86 ~56 ~72 ~86 ~66 ~72 stone 3
setblock ~87 ~56 ~72 diamond_ore
setblock ~30 ~56 ~73 cobblestone
setblock ~88 ~56 ~73 gold_ore
fill ~91 ~56 ~73 ~91 ~67 ~73 stone 3
fill ~92 ~56 ~73 ~92 ~65 ~73 stone 3
fill ~29 ~56 ~74 ~29 ~57 ~74 cobblestone
fill ~30 ~56 ~74 ~30 ~58 ~75 stone 5
setblock ~31 ~56 ~74 cobblestone
fill ~34 ~56 ~74 ~34 ~56 ~75 stone_slab
setblock ~73 ~56 ~74 gold_ore
fill ~93 ~56 ~74 ~93 ~62 ~79 stone 3
fill ~128 ~56 ~74 ~128 ~56 ~75 stone_slab
fill ~5 ~56 ~75 ~6 ~56 ~75 wool 14
fill ~67 ~56 ~75 ~67 ~57 ~75 log 12
setblock ~72 ~56 ~75 diamond_ore
fill ~90 ~56 ~75 ~91 ~56 ~75 stone
fill ~92 ~56 ~75 ~92 ~65 ~79 stone 3
fill ~95 ~56 ~75 ~98 ~56 ~75 stone 6
fill ~156 ~56 ~75 ~158 ~56 ~75 wool 14
setblock ~5 ~56 ~76 wool 14
fill ~72 ~56 ~76 ~72 ~66 ~76 stone 3
setblock ~90 ~56 ~76 stone
fill ~91 ~56 ~76 ~94 ~58 ~79 stone 3
fill ~95 ~56 ~76 ~96 ~56 ~76 stone 6
fill ~157 ~56 ~76 ~158 ~56 ~76 wool 14
setblock ~66 ~56 ~77 gold_ore
fill ~67 ~56 ~77 ~70 ~56 ~79 stone 3
fill ~77 ~56 ~77 ~77 ~59 ~77 log 12
fill ~85 ~56 ~77 ~85 ~59 ~77 log 12
fill ~95 ~56 ~77 ~95 ~58 ~77 stone 3
fill ~33 ~56 ~78 ~34 ~57 ~78 leaves 8
fill ~71 ~56 ~78 ~71 ~64 ~78 stone 3
fill ~95 ~56 ~78 ~96 ~56 ~78 stone 3
fill ~128 ~56 ~78 ~129 ~57 ~78 leaves 8
fill ~32 ~56 ~79 ~32 ~57 ~79 leaves 8
fill ~33 ~56 ~79 ~33 ~62 ~83 log 12
setblock ~34 ~56 ~79 leaves 8
fill ~64 ~56 ~79 ~64 ~59 ~79 log 12
setblock ~95 ~56 ~79 stone 3
setblock ~128 ~56 ~79 leaves 8
fill ~129 ~56 ~79 ~129 ~62 ~83 log 12
fill ~130 ~56 ~79 ~130 ~58 ~79 leaves 8
fill ~3 ~56 ~80 ~3 ~59 ~82 quartz_block
fill ~34 ~56 ~80 ~34 ~65 ~82 log 12
fill ~36 ~56 ~80 ~36 ~59 ~80 leaves 8
fill ~126 ~56 ~80 ~126 ~59 ~80 leaves 8
setblock ~130 ~56 ~80 leaves 8
fill ~159 ~56 ~80 ~160 ~57 ~82 quartz_block
fill ~30 ~56 ~81 ~31 ~57 ~81 leaves 8
fill ~128 ~56 ~81 ~129 ~65 ~82 log 12
fill ~131 ~56 ~81 ~132 ~57 ~81 leaves 8
fill ~32 ~56 ~82 ~32 ~56 ~83 leaves 8
fill ~35 ~56 ~82 ~35 ~64 ~82 log 12
fill ~36 ~56 ~82 ~36 ~59 ~82 leaves 8
fill ~126 ~56 ~82 ~126 ~59 ~82 leaves 8
fill ~127 ~56 ~82 ~129 ~64 ~82 log 12
fill ~34 ~56 ~83 ~34 ~56 ~84 leaves 8
fill ~70 ~56 ~83 ~71 ~65 ~86 stone 3
fill ~92 ~56 ~83 ~94 ~58 ~87 stone 3
fill ~98 ~56 ~83 ~98 ~59 ~83 log 12
fill ~128 ~56 ~83 ~128 ~56 ~84 leaves 8
fill ~130 ~56 ~83 ~130 ~57 ~83 leaves 8
fill ~33 ~56 ~84 ~34 ~57 ~84 leaves 8
fill ~129 ~56 ~84 ~129 ~58 ~84 leaves 8
fill ~64 ~56 ~85 ~65 ~56 ~85 gold_ore
fill ~77 ~56 ~85 ~77 ~59 ~85 log 12
fill ~85 ~56 ~85 ~85 ~59 ~85 log 12
setblock ~96 ~56 ~85 gold_ore
fill ~5 ~56 ~86 ~5 ~56 ~87 wool 14
fill ~66 ~56 ~86 ~67 ~56 ~87 stone 6
fill ~68 ~56 ~86 ~70 ~58 ~87 stone 3
fill ~72 ~56 ~86 ~72 ~56 ~88 stone
fill ~90 ~56 ~86 ~94 ~59 ~86 stone 3
fill ~157 ~56 ~86 ~158 ~56 ~87 wool 14
fill ~6 ~56 ~87 ~6 ~57 ~87 wool 14
fill ~34 ~56 ~87 ~34 ~56 ~88 stone_slab
fill ~64 ~56 ~87 ~67 ~56 ~87 stone 6
fill ~71 ~56 ~87 ~72 ~56 ~88 stone
setblock ~90 ~56 ~87 diamond_ore
fill ~95 ~56 ~87 ~95 ~57 ~87 log 12
fill ~128 ~56 ~87 ~128 ~56 ~88 stone_slab
fill ~132 ~56 ~87 ~132 ~58 ~88 stone 5
fill ~156 ~56 ~87 ~158 ~56 ~87 wool 14
fill ~69 ~56 ~88 ~69 ~62 ~88 stone 3
fill ~70 ~56 ~88 ~73 ~56 ~88 stone
setblock ~89 ~56 ~88 gold_ore
fill ~90 ~56 ~88 ~90 ~64 ~92 stone 3
setblock ~131 ~56 ~88 cobblestone
fill ~133 ~56 ~88 ~133 ~57 ~88 cobblestone
fill ~70 ~56 ~89 ~73 ~64 ~90 stone 3
setblock ~74 ~56 ~89 gold_ore
fill ~89 ~56 ~89 ~89 ~66 ~91 stone 3
setblock ~132 ~56 ~89 cobblestone
setblock ~75 ~56 ~90 diamond_ore
fill ~76 ~56 ~90 ~76 ~59 ~94 stone 3
fill ~86 ~56 ~90 ~88 ~56 ~90 stone
fill ~83 ~56 ~91 ~86 ~58 ~94 stone 3
fill ~87 ~56 ~91 ~88 ~56 ~91 stone
fill ~69 ~56 ~92 ~70 ~57 ~92 log 12
fill ~79 ~56 ~92 ~79 ~58 ~94 stone 3
fill ~87 ~56 ~92 ~87 ~61 ~94 stone 3
fill ~89 ~56 ~92 ~90 ~64 ~92 stone 3
fill ~92 ~56 ~92 ~92 ~61 ~92 log 12
fill ~77 ~56 ~93 ~79 ~60 ~93 stone 3
fill ~88 ~56 ~93 ~88 ~62 ~93 stone 3
fill ~92 ~56 ~93 ~92 ~57 ~93 log 12
fill ~75 ~56 ~95 ~75 ~57 ~95 log 12
fill ~77 ~56 ~95 ~79 ~56 ~95 stone 3
fill ~83 ~56 ~95 ~85 ~56 ~95 stone 3
fill ~86 ~56 ~95 ~87 ~56 ~96 stone 6
setblock ~77 ~56 ~96 gold_ore
fill ~79 ~56 ~98 ~79 ~59 ~98 log 12
setblock ~85 ~56 ~98 gold_ore
setblock ~87 ~56 ~98 stone 6
fill ~12 ~56 ~100 ~12 ~56 ~102 wool 14
fill ~24 ~56 ~100 ~24 ~56 ~102 wool 14
fill ~138 ~56 ~100 ~138 ~56 ~102 wool 14
fill ~150 ~56 ~100 ~150 ~56 ~102 wool 14
fill ~13 ~56 ~101 ~13 ~56 ~102 wool 14
fill ~23 ~56 ~101 ~24 ~56 ~102 wool 14
fill ~139 ~56 ~101 ~139 ~56 ~102 wool 14
fill ~149 ~56 ~101 ~150 ~56 ~102 wool 14
fill ~105 ~56 ~102 ~105 ~58 ~102 fence
fill ~107 ~56 ~102 ~107 ~59 ~102 fence
fill ~17 ~56 ~103 ~19 ~59 ~103 quartz_block
fill ~56 ~56 ~103 ~56 ~58 ~103 fence
fill ~58 ~56 ~103 ~58 ~58 ~103 fence
fill ~143 ~56 ~103 ~145 ~59 ~103 quartz_block
fill ~103 ~56 ~104 ~103 ~58 ~104 fence
fill ~109 ~56 ~104 ~109 ~58 ~104 fence
fill ~54 ~56 ~105 ~54 ~58 ~105 fence
fill ~60 ~56 ~105 ~60 ~58 ~105 fence
fill ~103 ~56 ~106 ~103 ~58 ~106 fence
fill ~109 ~56 ~106 ~109 ~58 ~106 fence
fill ~54 ~56 ~107 ~54 ~58 ~107 fence
fill ~60 ~56 ~107 ~60 ~59 ~107 fence
fill ~105 ~56 ~108 ~105 ~58 ~108 fence
fill ~107 ~56 ~108 ~107 ~58 ~108 fence
fill ~56 ~56 ~109 ~56 ~58 ~109 fence
fill ~58 ~56 ~109 ~58 ~58 ~109 fence
fill ~80 ~56 ~126 ~80 ~59 ~126 leaves 8
fill ~82 ~56 ~126 ~82 ~59 ~126 leaves 8
fill ~82 ~56 ~127 ~82 ~64 ~129 log 12
fill ~74 ~56 ~128 ~75 ~56 ~128 stone_slab
fill ~78 ~56 ~128 ~78 ~57 ~129 leaves 8
setblock ~79 ~56 ~128 leaves 8
fill ~81 ~56 ~128 ~82 ~65 ~129 log 12
fill ~83 ~56 ~128 ~84 ~56 ~128 leaves 8
fill ~87 ~56 ~128 ~88 ~56 ~128 stone_slab
fill ~79 ~56 ~129 ~83 ~62 ~129 log 12
fill ~84 ~56 ~129 ~84 ~58 ~129 leaves 8
fill ~79 ~56 ~130 ~80 ~56 ~130 leaves 8
fill ~83 ~56 ~130 ~83 ~58 ~130 leaves 8
setblock ~74 ~56 ~131 cobblestone
fill ~81 ~56 ~131 ~81 ~57 ~132 leaves 8
setblock ~73 ~56 ~132 cobblestone
fill ~74 ~56 ~132 ~75 ~58 ~132 stone 5
fill ~74 ~56 ~133 ~74 ~57 ~133 cobblestone
fill ~61 ~56 ~138 ~62 ~56 ~138 wool 14
fill ~100 ~56 ~138 ~102 ~56 ~138 wool 14
setblock ~61 ~56 ~139 wool 14
fill ~101 ~56 ~139 ~102 ~56 ~139 wool 14
fill ~59 ~56 ~143 ~59 ~59 ~145 quartz_block
fill ~103 ~56 ~143 ~104 ~57 ~145 quartz_block
fill ~61 ~56 ~149 ~61 ~56 ~150 wool 14
fill ~101 ~56 ~149 ~102 ~56 ~150 wool 14
fill ~62 ~56 ~150 ~62 ~57 ~150 wool 14
fill ~100 ~56 ~150 ~102 ~56 ~150 wool 14
fill ~75 ~56 ~156 ~75 ~56 ~158 wool 14
fill ~87 ~56 ~156 ~87 ~56 ~158 wool 14
fill ~76 ~56 ~157 ~76 ~56 ~158 wool 14
fill ~86 ~56 ~157 ~87 ~56 ~158 wool 14
fill ~80 ~56 ~159 ~82 ~59 ~159 quartz_block
fill ~77 ~57 ~4 ~77 ~58 ~4 wool 14
fill ~81 ~57 ~4 ~81 ~60 ~4 quartz_block
fill ~85 ~57 ~4 ~85 ~58 ~4 wool 14
setblock ~76 ~57 ~5 wool 15
setblock ~86 ~57 ~5 wool 15
setblock ~62 ~57 ~12 wool 14
setblock ~100 ~57 ~12 wool 14
setblock ~61 ~57 ~13 wool 15
setblock ~101 ~57 ~13 wool 15
fill ~60 ~57 ~14 ~60 ~58 ~14 wool 14
fill ~102 ~57 ~14 ~102 ~58 ~14 wool 14
fill ~60 ~57 ~18 ~60 ~60 ~18 quartz_block
fill ~102 ~57 ~18 ~104 ~58 ~18 quartz_block
fill ~60 ~57 ~22 ~60 ~58 ~22 wool 14
fill ~102 ~57 ~22 ~102 ~58 ~22 wool 14
setblock ~61 ~57 ~23 wool 15
setblock ~101 ~57 ~23 wool 15
setblock ~100 ~57 ~24 wool 14
fill ~87 ~57 ~29 ~88 ~57 ~29 cobblestone
fill ~89 ~57 ~29 ~89 ~57 ~30 stone 5
setblock ~72 ~57 ~30 spruce_stairs 4
setblock ~76 ~57 ~30 dropper 9
setblock ~86 ~57 ~30 dropper 9
setblock ~90 ~57 ~30 spruce_stairs 5
fill ~79 ~57 ~31 ~83 ~57 ~31 leaves 8
fill ~87 ~57 ~31 ~88 ~57 ~31 stone 5
fill ~78 ~57 ~32 ~79 ~58 ~32 leaves 8
fill ~80 ~57 ~32 ~82 ~64 ~35 log 12
fill ~84 ~57 ~32 ~84 ~57 ~34 leaves 8
fill ~79 ~57 ~34 ~83 ~64 ~34 log 12
setblock ~78 ~57 ~48 sea_lantern
fill ~105 ~57 ~53 ~106 ~58 ~53 fence
fill ~56 ~57 ~54 ~57 ~58 ~54 fence
setblock ~84 ~57 ~56 sea_lantern
fill ~102 ~57 ~56 ~102 ~58 ~57 fence
fill ~108 ~57 ~56 ~108 ~58 ~57 fence
fill ~53 ~57 ~57 ~53 ~58 ~58 fence
fill ~59 ~57 ~57 ~59 ~58 ~58 fence
fill ~105 ~57 ~59 ~106 ~58 ~59 fence
fill ~14 ~57 ~60 ~14 ~58 ~60 wool 14
fill ~18 ~57 ~60 ~18 ~60 ~60 quartz_block
fill ~22 ~57 ~60 ~22 ~58 ~60 wool 14
fill ~56 ~57 ~60 ~57 ~58 ~60 fence
fill ~140 ~57 ~60 ~140 ~58 ~60 wool 14
fill ~144 ~57 ~60 ~144 ~60 ~60 quartz_block
fill ~148 ~57 ~60 ~148 ~58 ~60 wool 14
setblock ~13 ~57 ~61 wool 15
setblock ~23 ~57 ~61 wool 15
setblock ~139 ~57 ~61 wool 15
setblock ~149 ~57 ~61 wool 15
fill ~79 ~57 ~64 ~79 ~59 ~64 log 12
setblock ~76 ~57 ~65 gold_ore
fill ~78 ~57 ~65 ~78 ~58 ~67 planks 1
fill ~84 ~57 ~65 ~84 ~58 ~67 planks 1
fill ~75 ~57 ~66 ~75 ~57 ~67 stone 6
fill ~76 ~57 ~67 ~77 ~57 ~72 stone 3
fill ~85 ~57 ~67 ~85 ~57 ~72 stone 3
fill ~86 ~57 ~67 ~88 ~57 ~67 log 12
fill ~83 ~57 ~68 ~87 ~58 ~70 stone 3
fill ~70 ~57 ~69 ~70 ~57 ~70 log 12
setblock ~90 ~57 ~69 gold_ore
fill ~74 ~57 ~70 ~79 ~65 ~71 stone 3
fill ~91 ~57 ~70 ~91 ~58 ~79 stone 3
fill ~70 ~57 ~71 ~79 ~58 ~71 stone 3
fill ~83 ~57 ~71 ~83 ~59 ~71 stone
fill ~84 ~57 ~71 ~91 ~58 ~71 stone 3
setblock ~30 ~57 ~72 spruce_stairs 6
setblock ~69 ~57 ~72 gold_ore
fill ~74 ~57 ~72 ~74 ~67 ~74 stone 3
fill ~87 ~57 ~72 ~92 ~64 ~73 stone 3
setblock ~132 ~57 ~72 spruce_stairs 6
fill ~29 ~57 ~73 ~30 ~57 ~73 stone 5
setblock ~75 ~57 ~73 stone
fill ~31 ~57 ~74 ~31 ~58 ~74 stone 5
fill ~67 ~57 ~74 ~67 ~57 ~76 log 12
fill ~73 ~57 ~74 ~74 ~64 ~74 stone 3
fill ~88 ~57 ~74 ~88 ~69 ~74 stone 3
fill ~89 ~57 ~74 ~89 ~68 ~74 stone 3
fill ~90 ~57 ~74 ~91 ~67 ~74 stone 3
fill ~92 ~57 ~74 ~92 ~65 ~79 stone 3
setblock ~6 ~57 ~75 wool 14
setblock ~29 ~57 ~75 cobblestone
setblock ~31 ~57 ~75 stone 5
fill ~72 ~57 ~75 ~72 ~66 ~77 stone 3
fill ~73 ~57 ~75 ~73 ~68 ~75 stone 3
fill ~89 ~57 ~75 ~90 ~57 ~75 stone
fill ~95 ~57 ~75 ~96 ~57 ~75 stone 6
setblock ~156 ~57 ~75 wool 14
setblock ~5 ~57 ~76 wool 15
setblock ~30 ~57 ~76 dropper 9
fill ~90 ~57 ~76 ~90 ~68 ~77 stone 3
fill ~95 ~57 ~76 ~95 ~57 ~77 stone 3
setblock ~97 ~57 ~76 gold_ore
setblock ~132 ~57 ~76 dropper 9
setblock ~157 ~57 ~76 wool 15
fill ~4 ~57 ~77 ~4 ~58 ~77 wool 14
fill ~67 ~57 ~77 ~72 ~57 ~77 stone 3
fill ~158 ~57 ~77 ~158 ~58 ~77 wool 14
fill ~32 ~57 ~78 ~34 ~57 ~78 leaves 8
setblock ~56 ~57 ~78 sea_lantern
fill ~65 ~57 ~78 ~67 ~58 ~78 planks 1
fill ~70 ~57 ~78 ~71 ~62 ~78 stone 3
fill ~95 ~57 ~78 ~97 ~58 ~78 planks 1
setblock ~114 ~57 ~78 sea_lantern
fill ~130 ~57 ~78 ~130 ~58 ~79 leaves 8
fill ~31 ~57 ~79 ~31 ~57 ~83 leaves 8
fill ~34 ~57 ~79 ~34 ~64 ~83 log 12
fill ~70 ~57 ~79 ~70 ~58 ~79 stone 3
fill ~71 ~57 ~79 ~71 ~59 ~79 stone
fill ~98 ~57 ~79 ~98 ~59 ~79 log 12
fill ~128 ~57 ~79 ~129 ~62 ~83 log 12
fill ~131 ~57 ~79 ~131 ~57 ~83 leaves 8
fill ~32 ~57 ~80 ~35 ~64 ~82 log 12
fill ~130 ~57 ~80 ~130 ~66 ~82 log 12
fill ~4 ~57 ~81 ~4 ~60 ~81 quartz_block
fill ~127 ~57 ~81 ~130 ~64 ~82 log 12
fill ~158 ~57 ~81 ~160 ~58 ~81 quartz_block
fill ~32 ~57 ~83 ~32 ~58 ~84 leaves 8
fill ~64 ~57 ~83 ~64 ~59 ~83 log 12
fill ~68 ~57 ~83 ~71 ~60 ~84 stone 3
fill ~91 ~57 ~83 ~91 ~59 ~83 stone
setblock ~48 ~57 ~84 sea_lantern
fill ~65 ~57 ~84 ~67 ~58 ~84 planks 1
fill ~95 ~57 ~84 ~97 ~58 ~84 planks 1
setblock ~106 ~57 ~84 sea_lantern
fill ~128 ~57 ~84 ~130 ~57 ~84 leaves 8
fill ~4 ~57 ~85 ~4 ~58 ~85 wool 14
fill ~67 ~57 ~85 ~72 ~58 ~85 stone 3
fill ~90 ~57 ~85 ~90 ~64 ~92 stone 3
setblock ~95 ~57 ~85 stone 3
fill ~158 ~57 ~85 ~158 ~58 ~85 wool 14
setblock ~5 ~57 ~86 wool 15
setblock ~30 ~57 ~86 dropper 9
setblock ~65 ~57 ~86 gold_ore
fill ~67 ~57 ~86 ~72 ~57 ~86 stone 3
fill ~95 ~57 ~86 ~95 ~57 ~88 log 12
setblock ~132 ~57 ~86 dropper 9
setblock ~157 ~57 ~86 wool 15
fill ~66 ~57 ~87 ~67 ~57 ~87 stone 6
fill ~71 ~57 ~87 ~71 ~67 ~89 stone 3
fill ~72 ~57 ~87 ~73 ~57 ~87 stone
fill ~89 ~57 ~87 ~90 ~64 ~92 stone 3
fill ~131 ~57 ~87 ~132 ~57 ~88 stone 5
fill ~133 ~57 ~87 ~133 ~57 ~88 cobblestone
setblock ~156 ~57 ~87 wool 14
fill ~70 ~57 ~88 ~74 ~64 ~90 stone 3
fill ~88 ~57 ~88 ~88 ~69 ~88 stone 3
fill ~75 ~57 ~89 ~75 ~59 ~94 stone 3
fill ~87 ~57 ~89 ~87 ~57 ~90 stone
fill ~88 ~57 ~89 ~93 ~59 ~89 stone 3
fill ~132 ~57 ~89 ~133 ~57 ~89 stone 5
setblock ~30 ~57 ~90 spruce_stairs 7
fill ~77 ~57 ~90 ~77 ~66 ~90 stone 3
fill ~85 ~57 ~90 ~86 ~68 ~90 stone 3
fill ~88 ~57 ~90 ~89 ~67 ~91 stone 3
setblock ~93 ~57 ~90 gold_ore
setblock ~132 ~57 ~90 spruce_stairs 7
fill ~78 ~57 ~91 ~78 ~64 ~91 stone 3
fill ~79 ~57 ~91 ~79 ~59 ~91 stone
fill ~87 ~57 ~91 ~89 ~67 ~91 stone 3
fill ~92 ~57 ~91 ~92 ~58 ~91 stone 3
fill ~71 ~57 ~92 ~79 ~58 ~92 stone 3
fill ~88 ~57 ~92 ~90 ~64 ~92 stone 3
setblock ~72 ~57 ~93 gold_ore
fill ~74 ~57 ~94 ~79 ~57 ~94 stone 3
fill ~74 ~57 ~95 ~76 ~57 ~95 log 12
setblock ~77 ~57 ~95 stone 3
fill ~78 ~57 ~95 ~78 ~58 ~97 planks 1
fill ~84 ~57 ~95 ~84 ~58 ~97 planks 1
fill ~85 ~57 ~95 ~86 ~57 ~95 stone 3
fill ~87 ~57 ~95 ~87 ~57 ~96 stone 6
setblock ~86 ~57 ~97 gold_ore
fill ~83 ~57 ~98 ~83 ~59 ~98 log 12
setblock ~12 ~57 ~100 wool 14
setblock ~24 ~57 ~100 wool 14
setblock ~138 ~57 ~100 wool 14
setblock ~150 ~57 ~100 wool 14
setblock ~13 ~57 ~101 wool 15
setblock ~23 ~57 ~101 wool 15
setblock ~139 ~57 ~101 wool 15
setblock ~149 ~57 ~101 wool 15
fill ~14 ~57 ~102 ~14 ~58 ~102 wool 14
fill ~18 ~57 ~102 ~18 ~58 ~104 quartz_block
fill ~22 ~57 ~102 ~22 ~58 ~102 wool 14
fill ~106 ~57 ~102 ~107 ~58 ~102 fence
fill ~140 ~57 ~102 ~140 ~58 ~102 wool 14
fill ~144 ~57 ~102 ~144 ~58 ~104 quartz_block
fill ~148 ~57 ~102 ~148 ~58 ~102 wool 14
fill ~57 ~57 ~103 ~58 ~58 ~103 fence
fill ~103 ~57 ~105 ~103 ~58 ~106 fence
fill ~109 ~57 ~105 ~109 ~58 ~106 fence
fill ~54 ~57 ~106 ~54 ~58 ~107 fence
fill ~60 ~57 ~106 ~60 ~58 ~107 fence
setblock ~78 ~57 ~106 sea_lantern
fill ~106 ~57 ~108 ~107 ~58 ~108 fence
fill ~57 ~57 ~109 ~58 ~58 ~109 fence
setblock ~84 ~57 ~114 sea_lantern
fill ~81 ~57 ~127 ~82 ~64 ~130 log 12
fill ~79 ~57 ~128 ~83 ~62 ~129 log 12
fill ~84 ~57 ~128 ~84 ~57 ~130 leaves 8
fill ~78 ~57 ~130 ~79 ~57 ~130 leaves 8
fill ~80 ~57 ~130 ~82 ~66 ~130 log 12
fill ~74 ~57 ~131 ~75 ~57 ~132 stone 5
fill ~79 ~57 ~131 ~83 ~57 ~131 leaves 8
setblock ~72 ~57 ~132 spruce_stairs 4
fill ~73 ~57 ~132 ~75 ~58 ~132 stone 5
setblock ~76 ~57 ~132 dropper 9
setblock ~86 ~57 ~132 dropper 9
setblock ~90 ~57 ~132 spruce_stairs 5
setblock ~73 ~57 ~133 stone 5
setblock ~75 ~57 ~133 cobblestone
setblock ~62 ~57 ~138 wool 14
setblock ~100 ~57 ~138 wool 14
setblock ~61 ~57 ~139 wool 15
setblock ~101 ~57 ~139 wool 15
fill ~60 ~57 ~140 ~60 ~58 ~140 wool 14
fill ~102 ~57 ~140 ~102 ~58 ~140 wool 14
fill ~60 ~57 ~144 ~60 ~60 ~144 quartz_block
fill ~102 ~57 ~144 ~104 ~58 ~144 quartz_block
fill ~60 ~57 ~148 ~60 ~58 ~148 wool 14
fill ~102 ~57 ~148 ~102 ~58 ~148 wool 14
setblock ~61 ~57 ~149 wool 15
setblock ~101 ~57 ~149 wool 15
setblock ~100 ~57 ~150 wool 14
setblock ~75 ~57 ~156 wool 14
setblock ~87 ~57 ~156 wool 14
setblock ~76 ~57 ~157 wool 15
setblock ~86 ~57 ~157 wool 15
fill ~77 ~57 ~158 ~77 ~58 ~158 wool 14
fill ~81 ~57 ~158 ~81 ~58 ~160 quartz_block
fill ~85 ~57 ~158 ~85 ~58 ~158 wool 14
setblock ~78 ~58 ~4 wool 14
fill ~84 ~58 ~4 ~85 ~58 ~4 wool 14
setblock ~77 ~58 ~5 wool 14
setblock ~85 ~58 ~5 wool 14
setblock ~76 ~58 ~6 wool 14
setblock ~86 ~58 ~6 wool 14
setblock ~62 ~58 ~13 wool 14
setblock ~100 ~58 ~13 wool 14
setblock ~61 ~58 ~14 wool 14
fill ~101 ~58 ~14 ~102 ~58 ~14 wool 14
setblock ~60 ~58 ~15 wool 14
setblock ~102 ~58 ~15 wool 14
fill ~103 ~58 ~17 ~103 ~59 ~19 quartz_block
fill ~60 ~58 ~21 ~60 ~58 ~22 wool 14
fill ~102 ~58 ~21 ~102 ~58 ~22 wool 14
setblock ~61 ~58 ~22 wool 14
fill ~101 ~58 ~22 ~102 ~58 ~22 wool 14
setblock ~62 ~58 ~23 wool 14
setblock ~100 ~58 ~23 wool 14
setblock ~74 ~58 ~29 activator_rail 1
setblock ~88 ~58 ~29 activator_rail 1
setblock ~72 ~58 ~30 activator_rail 1
setblock ~76 ~58 ~30 activator_rail 1
fill ~79 ~58 ~30 ~80 ~58 ~30 leaves 8
fill ~82 ~58 ~30 ~83 ~58 ~30 leaves 8
setblock ~86 ~58 ~30 activator_rail 1
setblock ~89 ~58 ~30 stone 5
setblock ~90 ~58 ~30 activator_rail 1
setblock ~73 ~58 ~31 dropper 9
setblock ~75 ~58 ~31 spruce_stairs 4
setblock ~76 ~58 ~31 dropper 9
fill ~78 ~58 ~31 ~78 ~58 ~33 leaves 8
fill ~80 ~58 ~31 ~82 ~64 ~35 log 12
setblock ~83 ~58 ~31 leaves 8
setblock ~86 ~58 ~31 dropper 9
setblock ~87 ~58 ~31 spruce_stairs 5
setblock ~88 ~58 ~31 stone 5
setblock ~89 ~58 ~31 dropper 9
fill ~77 ~58 ~33 ~77 ~60 ~33 leaves 8
fill ~84 ~58 ~33 ~85 ~58 ~33 leaves 8
fill ~78 ~58 ~35 ~79 ~58 ~35 leaves 8
fill ~83 ~58 ~35 ~83 ~59 ~35 leaves 8
setblock ~81 ~58 ~37 leaves 8
setblock ~75 ~58 ~48 stone_slab
setblock ~76 ~58 ~48 double_stone_slab
setblock ~77 ~58 ~48 stone_slab 8
setblock ~78 ~58 ~48 fence
fill ~103 ~58 ~53 ~107 ~58 ~53 fence
fill ~54 ~58 ~54 ~58 ~58 ~54 fence
fill ~102 ~58 ~54 ~102 ~58 ~58 fence
fill ~108 ~58 ~54 ~108 ~58 ~58 fence
fill ~53 ~58 ~55 ~53 ~58 ~59 fence
fill ~59 ~58 ~55 ~59 ~58 ~59 fence
setblock ~84 ~58 ~56 fence
setblock ~85 ~58 ~56 stone_slab 8
setblock ~86 ~58 ~56 double_stone_slab
setblock ~87 ~58 ~56 stone_slab
fill ~103 ~58 ~59 ~107 ~58 ~59 fence
setblock ~15 ~58 ~60 wool 14
fill ~21 ~58 ~60 ~22 ~58 ~60 wool 14
fill ~54 ~58 ~60 ~58 ~58 ~60 fence
setblock ~141 ~58 ~60 wool 14
fill ~147 ~58 ~60 ~148 ~58 ~60 wool 14
setblock ~14 ~58 ~61 wool 14
setblock ~22 ~58 ~61 wool 14
setblock ~140 ~58 ~61 wool 14
setblock ~148 ~58 ~61 wool 14
setblock ~13 ~58 ~62 wool 14
setblock ~23 ~58 ~62 wool 14
setblock ~139 ~58 ~62 wool 14
setblock ~149 ~58 ~62 wool 14
fill ~78 ~58 ~64 ~78 ~58 ~67 planks 1
fill ~84 ~58 ~64 ~84 ~58 ~67 planks 1
setblock ~81 ~58 ~65 sea_lantern
fill ~77 ~58 ~67 ~77 ~58 ~72 stone 3
fill ~85 ~58 ~67 ~86 ~58 ~67 log 12
fill ~88 ~58 ~67 ~88 ~58 ~68 log 12
fill ~89 ~58 ~68 ~90 ~58 ~68 log 12
setblock ~73 ~58 ~69 stained_glass_pane 9
fill ~80 ~58 ~69 ~80 ~61 ~71 stone 3
fill ~82 ~58 ~69 ~82 ~60 ~71 stone
fill ~88 ~58 ~69 ~90 ~59 ~74 stone 3
fill ~91 ~58 ~69 ~91 ~60 ~69 log 12
fill ~70 ~58 ~70 ~70 ~61 ~70 log 12
fill ~69 ~58 ~71 ~69 ~60 ~71 log 12
setblock ~30 ~58 ~72 activator_rail 1
fill ~68 ~58 ~72 ~68 ~58 ~74 log 12
fill ~69 ~58 ~72 ~78 ~59 ~72 stone 3
setblock ~84 ~58 ~72 stone
fill ~85 ~58 ~72 ~92 ~64 ~72 stone 3
setblock ~132 ~58 ~72 activator_rail 1
fill ~30 ~58 ~73 ~30 ~58 ~75 stone 5
setblock ~31 ~58 ~73 dropper 9
setblock ~75 ~58 ~73 gold_ore
setblock ~76 ~58 ~73 stone
fill ~86 ~58 ~73 ~92 ~64 ~73 stone 3
setblock ~93 ~58 ~73 stained_glass_pane 9
setblock ~131 ~58 ~73 dropper 9
setblock ~29 ~58 ~74 activator_rail 1
fill ~67 ~58 ~74 ~68 ~58 ~74 log 12
setblock ~133 ~58 ~74 activator_rail 1
setblock ~31 ~58 ~75 spruce_stairs 6
setblock ~56 ~58 ~75 stone_slab
fill ~68 ~58 ~75 ~73 ~59 ~76 stone 3
setblock ~89 ~58 ~75 gold_ore
fill ~90 ~58 ~75 ~90 ~68 ~78 stone 3
setblock ~114 ~58 ~75 stone_slab
setblock ~131 ~58 ~75 spruce_stairs 6
setblock ~6 ~58 ~76 wool 14
setblock ~30 ~58 ~76 activator_rail 1
setblock ~31 ~58 ~76 dropper 9
setblock ~56 ~58 ~76 double_stone_slab
fill ~67 ~58 ~76 ~67 ~58 ~77 log 12
setblock ~89 ~58 ~76 stone
setblock ~114 ~58 ~76 double_stone_slab
setblock ~131 ~58 ~76 dropper 9
setblock ~132 ~58 ~76 activator_rail 1
setblock ~156 ~58 ~76 wool 14
setblock ~5 ~58 ~77 wool 14
fill ~33 ~58 ~77 ~33 ~60 ~77 leaves 8
setblock ~56 ~58 ~77 stone_slab 8
fill ~68 ~58 ~77 ~70 ~58 ~79 stone 3
fill ~78 ~58 ~77 ~78 ~59 ~77 log 12
setblock ~114 ~58 ~77 stone_slab 8
fill ~129 ~58 ~77 ~129 ~60 ~77 leaves 8
fill ~157 ~58 ~77 ~158 ~58 ~77 wool 14
setblock ~4 ~58 ~78 wool 14
setblock ~33 ~58 ~78 leaves 8
setblock ~56 ~58 ~78 fence
fill ~64 ~58 ~78 ~67 ~58 ~78 planks 1
setblock ~72 ~58 ~78 stone
fill ~85 ~58 ~78 ~85 ~59 ~78 log 12
fill ~98 ~58 ~78 ~98 ~60 ~78 planks 1
setblock ~114 ~58 ~78 fence
fill ~127 ~58 ~78 ~127 ~58 ~79 leaves 8
fill ~129 ~58 ~78 ~131 ~58 ~78 leaves 8
setblock ~158 ~58 ~78 wool 14
fill ~30 ~58 ~79 ~31 ~58 ~79 leaves 8
fill ~35 ~58 ~79 ~35 ~59 ~79 leaves 8
fill ~132 ~58 ~79 ~132 ~58 ~80 leaves 8
setblock ~30 ~58 ~80 leaves 8
fill ~31 ~58 ~80 ~35 ~64 ~82 log 12
fill ~69 ~58 ~80 ~71 ~60 ~80 stone
fill ~91 ~58 ~80 ~93 ~61 ~80 stone 3
fill ~131 ~58 ~80 ~131 ~66 ~82 log 12
fill ~159 ~58 ~80 ~159 ~59 ~82 quartz_block
setblock ~37 ~58 ~81 leaves 8
setblock ~65 ~58 ~81 sea_lantern
setblock ~97 ~58 ~81 sea_lantern
setblock ~125 ~58 ~81 leaves 8
fill ~30 ~58 ~82 ~30 ~58 ~83 leaves 8
fill ~69 ~58 ~82 ~71 ~61 ~88 stone 3
fill ~91 ~58 ~82 ~93 ~60 ~82 stone
fill ~132 ~58 ~82 ~132 ~58 ~83 leaves 8
fill ~35 ~58 ~83 ~35 ~59 ~83 leaves 8
fill ~127 ~58 ~83 ~127 ~59 ~83 leaves 8
fill ~131 ~58 ~83 ~132 ~58 ~83 leaves 8
fill ~4 ~58 ~84 ~4 ~58 ~85 wool 14
fill ~31 ~58 ~84 ~33 ~58 ~84 leaves 8
setblock ~35 ~58 ~84 leaves 8
setblock ~48 ~58 ~84 fence
fill ~64 ~58 ~84 ~67 ~58 ~84 planks 1
fill ~72 ~58 ~84 ~72 ~68 ~87 stone 3
fill ~77 ~58 ~84 ~77 ~59 ~85 log 12
setblock ~90 ~58 ~84 stone
fill ~98 ~58 ~84 ~98 ~60 ~84 planks 1
setblock ~106 ~58 ~84 fence
fill ~158 ~58 ~84 ~158 ~58 ~85 wool 14
setblock ~5 ~58 ~85 wool 14
fill ~33 ~58 ~85 ~33 ~60 ~85 leaves 8
setblock ~48 ~58 ~85 stone_slab 8
fill ~84 ~58 ~85 ~85 ~59 ~85 log 12
fill ~95 ~58 ~85 ~95 ~59 ~85 log 12
setblock ~106 ~58 ~85 stone_slab 8
fill ~129 ~58 ~85 ~129 ~60 ~85 leaves 8
fill ~157 ~58 ~85 ~158 ~58 ~85 wool 14
setblock ~6 ~58 ~86 wool 14
setblock ~30 ~58 ~86 activator_rail 1
setblock ~31 ~58 ~86 dropper 9
setblock ~48 ~58 ~86 double_stone_slab
setblock ~73 ~58 ~86 stone
fill ~89 ~58 ~86 ~90 ~64 ~92 stone 3
setblock ~95 ~58 ~86 log 12
setblock ~106 ~58 ~86 double_stone_slab
setblock ~131 ~58 ~86 dropper 9
setblock ~132 ~58 ~86 activator_rail 1
setblock ~156 ~58 ~86 wool 14
setblock ~31 ~58 ~87 spruce_stairs 7
setblock ~48 ~58 ~87 stone_slab
setblock ~73 ~58 ~87 gold_ore
setblock ~106 ~58 ~87 stone_slab
setblock ~131 ~58 ~87 spruce_stairs 7
setblock ~29 ~58 ~88 activator_rail 1
fill ~94 ~58 ~88 ~94 ~58 ~90 log 12
setblock ~95 ~58 ~88 log 12
fill ~131 ~58 ~88 ~132 ~58 ~88 stone 5
setblock ~133 ~58 ~88 activator_rail 1
setblock ~31 ~58 ~89 dropper 9
setblock ~69 ~58 ~89 stained_glass_pane 9
fill ~76 ~58 ~89 ~76 ~59 ~94 stone 3
setblock ~86 ~58 ~89 stone
setblock ~87 ~58 ~89 gold_ore
setblock ~131 ~58 ~89 dropper 9
setblock ~132 ~58 ~89 stone 5
setblock ~30 ~58 ~90 activator_rail 1
setblock ~78 ~58 ~90 stone
fill ~84 ~58 ~90 ~87 ~68 ~90 stone 3
fill ~93 ~58 ~90 ~93 ~59 ~90 stone 3
setblock ~132 ~58 ~90 activator_rail 1
fill ~80 ~58 ~91 ~80 ~60 ~93 stone
fill ~82 ~58 ~91 ~88 ~61 ~93 stone 3
fill ~93 ~58 ~91 ~93 ~60 ~91 log 12
fill ~70 ~58 ~92 ~70 ~61 ~92 log 12
fill ~71 ~58 ~93 ~71 ~60 ~93 log 12
fill ~72 ~58 ~93 ~79 ~59 ~93 stone 3
setblock ~89 ~58 ~93 stained_glass_pane 9
fill ~72 ~58 ~94 ~74 ~58 ~94 log 12
setblock ~74 ~58 ~95 log 12
fill ~76 ~58 ~95 ~77 ~58 ~95 log 12
setblock ~85 ~58 ~95 stone 3
setblock ~81 ~58 ~97 sea_lantern
fill ~78 ~58 ~98 ~78 ~60 ~98 planks 1
fill ~84 ~58 ~98 ~84 ~60 ~98 planks 1
setblock ~13 ~58 ~100 wool 14
setblock ~23 ~58 ~100 wool 14
setblock ~139 ~58 ~100 wool 14
setblock ~149 ~58 ~100 wool 14
fill ~14 ~58 ~101 ~14 ~58 ~102 wool 14
fill ~22 ~58 ~101 ~22 ~58 ~102 wool 14
fill ~140 ~58 ~101 ~140 ~58 ~102 wool 14
fill ~148 ~58 ~101 ~148 ~58 ~102 wool 14
setblock ~15 ~58 ~102 wool 14
fill ~21 ~58 ~102 ~22 ~58 ~102 wool 14
fill ~104 ~58 ~102 ~108 ~58 ~102 fence
setblock ~141 ~58 ~102 wool 14
fill ~147 ~58 ~102 ~148 ~58 ~102 wool 14
fill ~55 ~58 ~103 ~59 ~58 ~103 fence
fill ~103 ~58 ~103 ~103 ~58 ~107 fence
fill ~109 ~58 ~103 ~109 ~58 ~107 fence
fill ~54 ~58 ~104 ~54 ~58 ~108 fence
fill ~60 ~58 ~104 ~60 ~58 ~108 fence
setblock ~75 ~58 ~106 stone_slab
setblock ~76 ~58 ~106 double_stone_slab
setblock ~77 ~58 ~106 stone_slab 8
setblock ~78 ~58 ~106 fence
fill ~104 ~58 ~108 ~108 ~58 ~108 fence
fill ~55 ~58 ~109 ~59 ~58 ~109 fence
setblock ~84 ~58 ~114 fence
setblock ~85 ~58 ~114 stone_slab 8
setblock ~86 ~58 ~114 double_stone_slab
setblock ~87 ~58 ~114 stone_slab
setblock ~81 ~58 ~125 leaves 8
fill ~79 ~58 ~127 ~79 ~59 ~127 leaves 8
fill ~83 ~58 ~127 ~84 ~58 ~127 leaves 8
fill ~77 ~58 ~129 ~77 ~60 ~129 leaves 8
setblock ~78 ~58 ~129 leaves 8
fill ~85 ~58 ~129 ~85 ~60 ~129 leaves 8
fill ~84 ~58 ~130 ~84 ~58 ~131 leaves 8
setblock ~73 ~58 ~131 dropper 9
fill ~74 ~58 ~131 ~74 ~58 ~132 stone 5
setblock ~75 ~58 ~131 spruce_stairs 4
setblock ~76 ~58 ~131 dropper 9
fill ~79 ~58 ~131 ~79 ~58 ~132 leaves 8
fill ~80 ~58 ~131 ~82 ~66 ~131 log 12
setblock ~86 ~58 ~131 dropper 9
setblock ~87 ~58 ~131 spruce_stairs 5
setblock ~89 ~58 ~131 dropper 9
setblock ~72 ~58 ~132 activator_rail 1
setblock ~76 ~58 ~132 activator_rail 1
setblock ~80 ~58 ~132 leaves 8
fill ~82 ~58 ~132 ~83 ~58 ~132 leaves 8
setblock ~86 ~58 ~132 activator_rail 1
setblock ~90 ~58 ~132 activator_rail 1
setblock ~74 ~58 ~133 activator_rail 1
setblock ~88 ~58 ~133 activator_rail 1
setblock ~62 ~58 ~139 wool 14
setblock ~100 ~58 ~139 wool 14
setblock ~61 ~58 ~140 wool 14
fill ~101 ~58 ~140 ~102 ~58 ~140 wool 14
setblock ~60 ~58 ~141 wool 14
setblock ~102 ~58 ~141 wool 14
fill ~103 ~58 ~143 ~103 ~59 ~145 quartz_block
fill ~60 ~58 ~147 ~60 ~58 ~148 wool 14
fill ~102 ~58 ~147 ~102 ~58 ~148 wool 14
setblock ~61 ~58 ~148 wool 14
fill ~101 ~58 ~148 ~102 ~58 ~148 wool 14
setblock ~62 ~58 ~149 wool 14
setblock ~100 ~58 ~149 wool 14
setblock ~76 ~58 ~156 wool 14
setblock ~86 ~58 ~156 wool 14
fill ~77 ~58 ~157 ~77 ~58 ~158 wool 14
fill ~85 ~58 ~157 ~85 ~58 ~158 wool 14
setblock ~78 ~58 ~158 wool 14
fill ~84 ~58 ~158 ~85 ~58 ~158 wool 14
fill ~80 ~59 ~4 ~82 ~59 ~4 quartz_block
fill ~78 ~59 ~5 ~78 ~59 ~6 wool 14
fill ~81 ~59 ~5 ~81 ~60 ~5 quartz_block
fill ~84 ~59 ~5 ~84 ~59 ~6 wool 14
fill ~77 ~59 ~6 ~78 ~59 ~6 wool 14
setblock ~85 ~59 ~6 wool 14
fill ~62 ~59 ~14 ~62 ~59 ~15 wool 14
fill ~100 ~59 ~14 ~100 ~59 ~15 wool 14
fill ~61 ~59 ~15 ~62 ~59 ~15 wool 14
setblock ~101 ~59 ~15 wool 14
fill ~60 ~59 ~17 ~60 ~60 ~19 quartz_block
fill ~102 ~59 ~17 ~103 ~59 ~19 quartz_block
fill ~61 ~59 ~18 ~61 ~61 ~18 quartz_block
fill ~101 ~59 ~18 ~103 ~59 ~18 quartz_block
fill ~61 ~59 ~21 ~62 ~59 ~21 wool 14
fill ~100 ~59 ~21 ~101 ~59 ~21 wool 14
setblock ~62 ~59 ~22 wool 14
setblock ~100 ~59 ~22 wool 14
setblock ~74 ~59 ~29 dropper 1
fill ~81 ~59 ~29 ~81 ~61 ~29 leaves 8
setblock ~88 ~59 ~29 dropper 1
setblock ~74 ~59 ~30 activator_rail 1
setblock ~80 ~59 ~30 spruce_stairs 4
fill ~81 ~59 ~30 ~81 ~59 ~35 log 12
setblock ~82 ~59 ~30 spruce_stairs 5
setblock ~88 ~59 ~30 activator_rail 1
setblock ~73 ~59 ~31 activator_rail 1
fill ~74 ~59 ~31 ~74 ~60 ~31 log 12
setblock ~75 ~59 ~31 activator_rail 1
setblock ~76 ~59 ~31 dropper 1
setblock ~78 ~59 ~31 leaves 8
fill ~79 ~59 ~31 ~83 ~60 ~34 log 12
setblock ~84 ~59 ~31 leaves 8
setblock ~86 ~59 ~31 dropper 1
setblock ~87 ~59 ~31 activator_rail 1
fill ~88 ~59 ~31 ~88 ~60 ~31 log 12
setblock ~89 ~59 ~31 activator_rail 1
setblock ~74 ~59 ~32 log 12
fill ~76 ~59 ~32 ~76 ~59 ~33 leaves 8
fill ~86 ~59 ~32 ~86 ~59 ~33 leaves 8
setblock ~88 ~59 ~32 log 12
fill ~85 ~59 ~33 ~86 ~59 ~33 leaves 8
setblock ~79 ~59 ~35 leaves 8
setblock ~80 ~59 ~37 leaves 8
setblock ~82 ~59 ~37 leaves 8
fill ~77 ~59 ~48 ~78 ~59 ~48 stone_slab
setblock ~103 ~59 ~53 fence
setblock ~105 ~59 ~53 fence
setblock ~107 ~59 ~53 fence
setblock ~54 ~59 ~54 fence
setblock ~56 ~59 ~54 fence
setblock ~58 ~59 ~54 fence
fill ~102 ~59 ~54 ~102 ~59 ~55 fence
setblock ~108 ~59 ~54 fence
setblock ~53 ~59 ~55 fence
setblock ~59 ~59 ~55 fence
fill ~84 ~59 ~56 ~85 ~59 ~56 stone_slab
setblock ~108 ~59 ~56 fence
setblock ~53 ~59 ~57 fence
setblock ~59 ~59 ~57 fence
setblock ~102 ~59 ~58 fence
setblock ~108 ~59 ~58 fence
setblock ~53 ~59 ~59 fence
setblock ~59 ~59 ~59 fence
setblock ~103 ~59 ~59 fence
setblock ~105 ~59 ~59 fence
setblock ~107 ~59 ~59 fence
fill ~17 ~59 ~60 ~19 ~60 ~60 quartz_block
fill ~54 ~59 ~60 ~55 ~59 ~60 fence
setblock ~58 ~59 ~60 fence
fill ~143 ~59 ~60 ~145 ~60 ~60 quartz_block
fill ~15 ~59 ~61 ~15 ~59 ~62 wool 14
fill ~18 ~59 ~61 ~18 ~61 ~61 quartz_block
fill ~21 ~59 ~61 ~21 ~59 ~62 wool 14
fill ~141 ~59 ~61 ~141 ~59 ~62 wool 14
fill ~144 ~59 ~61 ~144 ~61 ~61 quartz_block
fill ~147 ~59 ~61 ~147 ~59 ~62 wool 14
fill ~14 ~59 ~62 ~15 ~59 ~62 wool 14
setblock ~22 ~59 ~62 wool 14
fill ~140 ~59 ~62 ~141 ~59 ~62 wool 14
setblock ~148 ~59 ~62 wool 14
fill ~78 ~59 ~63 ~78 ~60 ~64 planks 1
fill ~84 ~59 ~63 ~84 ~60 ~64 planks 1
setblock ~78 ~59 ~65 planks 1
fill ~81 ~59 ~65 ~81 ~60 ~65 fence
setblock ~84 ~59 ~65 planks 1
fill ~79 ~59 ~66 ~79 ~60 ~66 planks 1
fill ~83 ~59 ~66 ~83 ~60 ~66 planks 1
setblock ~79 ~59 ~67 planks 1
setblock ~83 ~59 ~67 planks 1
fill ~84 ~59 ~67 ~85 ~59 ~67 log 12
fill ~72 ~59 ~68 ~74 ~61 ~68 stained_glass_pane 9
fill ~75 ~59 ~68 ~75 ~61 ~73 stone 3
setblock ~76 ~59 ~68 gold_ore
fill ~77 ~59 ~68 ~80 ~59 ~72 stone 3
fill ~82 ~59 ~68 ~82 ~59 ~72 stone
fill ~83 ~59 ~68 ~83 ~59 ~69 stone 3
fill ~84 ~59 ~68 ~84 ~60 ~68 log 12
setblock ~90 ~59 ~68 log 12
fill ~72 ~59 ~69 ~72 ~61 ~69 stained_glass_pane 9
fill ~73 ~59 ~69 ~81 ~59 ~72 stone 3
fill ~84 ~59 ~69 ~90 ~59 ~72 stone 3
fill ~71 ~59 ~70 ~80 ~62 ~70 stone 3
fill ~83 ~59 ~70 ~83 ~59 ~72 stone
fill ~91 ~59 ~70 ~92 ~60 ~70 log 12
fill ~70 ~59 ~71 ~70 ~60 ~71 log 12
fill ~71 ~59 ~71 ~71 ~60 ~71 stone
fill ~91 ~59 ~71 ~91 ~60 ~71 stone
fill ~92 ~59 ~71 ~92 ~62 ~80 stone 3
setblock ~68 ~59 ~72 log 12
fill ~93 ~59 ~72 ~94 ~61 ~72 stained_glass_pane 9
setblock ~31 ~59 ~73 activator_rail 1
fill ~76 ~59 ~73 ~77 ~69 ~73 stone 3
setblock ~85 ~59 ~73 gold_ore
fill ~93 ~59 ~73 ~93 ~59 ~81 stone 3
fill ~94 ~59 ~73 ~94 ~61 ~74 stained_glass_pane 9
setblock ~131 ~59 ~73 activator_rail 1
setblock ~29 ~59 ~74 dropper 1
setblock ~30 ~59 ~74 activator_rail 1
fill ~31 ~59 ~74 ~32 ~59 ~74 log 12
setblock ~75 ~59 ~74 gold_ore
fill ~87 ~59 ~74 ~93 ~62 ~74 stone 3
fill ~130 ~59 ~74 ~131 ~59 ~74 log 12
setblock ~132 ~59 ~74 activator_rail 1
setblock ~133 ~59 ~74 dropper 1
setblock ~31 ~59 ~75 activator_rail 1
fill ~74 ~59 ~75 ~74 ~69 ~75 stone 3
setblock ~88 ~59 ~75 gold_ore
fill ~89 ~59 ~75 ~93 ~63 ~77 stone 3
fill ~94 ~59 ~75 ~94 ~61 ~75 stone 3
setblock ~131 ~59 ~75 activator_rail 1
setblock ~31 ~59 ~76 dropper 1
fill ~32 ~59 ~76 ~33 ~59 ~76 leaves 8
fill ~85 ~59 ~76 ~85 ~59 ~78 log 12
setblock ~94 ~59 ~76 gold_ore
fill ~129 ~59 ~76 ~130 ~59 ~76 leaves 8
setblock ~131 ~59 ~76 dropper 1
fill ~6 ~59 ~77 ~6 ~59 ~78 wool 14
fill ~56 ~59 ~77 ~56 ~59 ~78 stone_slab
fill ~67 ~59 ~77 ~67 ~59 ~78 log 12
fill ~70 ~59 ~77 ~72 ~62 ~78 stone 3
setblock ~73 ~59 ~77 gold_ore
fill ~76 ~59 ~77 ~78 ~59 ~77 log 12
fill ~84 ~59 ~77 ~85 ~59 ~77 log 12
fill ~114 ~59 ~77 ~114 ~59 ~78 stone_slab
fill ~156 ~59 ~77 ~156 ~59 ~78 wool 14
fill ~5 ~59 ~78 ~6 ~59 ~78 wool 14
setblock ~31 ~59 ~78 leaves 8
fill ~63 ~59 ~78 ~64 ~60 ~78 planks 1
setblock ~65 ~59 ~78 planks 1
fill ~68 ~59 ~78 ~68 ~60 ~78 log 12
setblock ~77 ~59 ~78 log 12
fill ~91 ~59 ~78 ~93 ~60 ~81 stone 3
fill ~97 ~59 ~78 ~99 ~59 ~78 planks 1
setblock ~131 ~59 ~78 leaves 8
setblock ~157 ~59 ~78 wool 14
fill ~31 ~59 ~79 ~34 ~60 ~83 log 12
fill ~66 ~59 ~79 ~67 ~59 ~79 planks 1
fill ~68 ~59 ~79 ~69 ~59 ~79 stone 3
fill ~70 ~59 ~79 ~72 ~59 ~80 stone
fill ~90 ~59 ~79 ~92 ~61 ~81 stone 3
fill ~95 ~59 ~79 ~96 ~59 ~79 planks 1
setblock ~127 ~59 ~79 leaves 8
fill ~130 ~59 ~79 ~130 ~66 ~83 log 12
fill ~131 ~59 ~79 ~131 ~60 ~83 log 12
fill ~4 ~59 ~80 ~4 ~59 ~82 quartz_block
setblock ~30 ~59 ~80 spruce_stairs 6
setblock ~37 ~59 ~80 leaves 8
fill ~68 ~59 ~80 ~72 ~59 ~80 stone
setblock ~81 ~59 ~80 iron_trapdoor 11
setblock ~94 ~59 ~80 stone 3
fill ~125 ~59 ~80 ~126 ~59 ~80 leaves 8
setblock ~132 ~59 ~80 spruce_stairs 6
fill ~158 ~59 ~80 ~159 ~59 ~82 quartz_block
fill ~5 ~59 ~81 ~5 ~60 ~81 quartz_block
fill ~29 ~59 ~81 ~29 ~61 ~81 leaves 8
fill ~30 ~59 ~81 ~35 ~59 ~81 log 12
fill ~65 ~59 ~81 ~65 ~60 ~81 fence
fill ~69 ~59 ~81 ~72 ~60 ~88 stone 3
setblock ~80 ~59 ~81 iron_trapdoor 9
setblock ~81 ~59 ~81 glowstone
setblock ~82 ~59 ~81 iron_trapdoor 8
fill ~97 ~59 ~81 ~97 ~60 ~81 fence
setblock ~132 ~59 ~81 log 12
fill ~133 ~59 ~81 ~133 ~61 ~81 leaves 8
fill ~157 ~59 ~81 ~158 ~60 ~81 quartz_block
setblock ~30 ~59 ~82 spruce_stairs 7
setblock ~37 ~59 ~82 leaves 8
fill ~68 ~59 ~82 ~72 ~59 ~85 stone 3
setblock ~81 ~59 ~82 iron_trapdoor 10
fill ~90 ~59 ~82 ~92 ~61 ~82 stone
setblock ~94 ~59 ~82 stone
fill ~125 ~59 ~82 ~126 ~59 ~82 leaves 8
setblock ~132 ~59 ~82 spruce_stairs 7
fill ~66 ~59 ~83 ~67 ~59 ~83 planks 1
fill ~90 ~59 ~83 ~92 ~59 ~83 stone
setblock ~94 ~59 ~83 stone 3
fill ~95 ~59 ~83 ~96 ~59 ~83 planks 1
fill ~5 ~59 ~84 ~6 ~59 ~84 wool 14
setblock ~31 ~59 ~84 leaves 8
fill ~48 ~59 ~84 ~48 ~59 ~85 stone_slab
fill ~63 ~59 ~84 ~64 ~60 ~84 planks 1
setblock ~65 ~59 ~84 planks 1
fill ~85 ~59 ~84 ~85 ~59 ~85 log 12
fill ~90 ~59 ~84 ~90 ~64 ~92 stone 3
fill ~91 ~59 ~84 ~93 ~59 ~90 stone 3
fill ~94 ~59 ~84 ~95 ~59 ~84 log 12
fill ~97 ~59 ~84 ~99 ~59 ~84 planks 1
fill ~106 ~59 ~84 ~106 ~59 ~85 stone_slab
setblock ~131 ~59 ~84 leaves 8
fill ~156 ~59 ~84 ~157 ~59 ~84 wool 14
setblock ~6 ~59 ~85 wool 14
fill ~73 ~59 ~85 ~73 ~69 ~86 stone 3
setblock ~78 ~59 ~85 log 12
setblock ~86 ~59 ~85 log 12
setblock ~89 ~59 ~85 gold_ore
setblock ~156 ~59 ~85 wool 14
setblock ~31 ~59 ~86 dropper 1
fill ~32 ~59 ~86 ~33 ~59 ~86 leaves 8
setblock ~68 ~59 ~86 gold_ore
setblock ~77 ~59 ~86 log 12
fill ~129 ~59 ~86 ~130 ~59 ~86 leaves 8
setblock ~131 ~59 ~86 dropper 1
setblock ~31 ~59 ~87 activator_rail 1
fill ~73 ~59 ~87 ~73 ~68 ~88 stone 3
setblock ~74 ~59 ~87 gold_ore
fill ~88 ~59 ~87 ~88 ~62 ~93 stone 3
setblock ~131 ~59 ~87 activator_rail 1
setblock ~29 ~59 ~88 dropper 1
setblock ~30 ~59 ~88 activator_rail 1
fill ~31 ~59 ~88 ~32 ~59 ~88 log 12
fill ~68 ~59 ~88 ~68 ~61 ~90 stained_glass_pane 9
fill ~75 ~59 ~88 ~75 ~69 ~88 stone 3
setblock ~87 ~59 ~88 gold_ore
fill ~130 ~59 ~88 ~131 ~59 ~88 log 12
setblock ~132 ~59 ~88 activator_rail 1
setblock ~133 ~59 ~88 dropper 1
setblock ~31 ~59 ~89 activator_rail 1
fill ~69 ~59 ~89 ~76 ~59 ~89 stone 3
setblock ~77 ~59 ~89 gold_ore
fill ~85 ~59 ~89 ~86 ~69 ~89 stone 3
fill ~87 ~59 ~89 ~88 ~68 ~89 stone 3
setblock ~131 ~59 ~89 activator_rail 1
fill ~69 ~59 ~90 ~69 ~61 ~90 stained_glass_pane 9
fill ~78 ~59 ~90 ~78 ~61 ~93 stone 3
fill ~79 ~59 ~90 ~80 ~59 ~92 stone
fill ~81 ~59 ~90 ~90 ~61 ~92 stone 3
setblock ~94 ~59 ~90 log 12
fill ~70 ~59 ~91 ~70 ~62 ~91 stone 3
fill ~71 ~59 ~91 ~71 ~60 ~91 stone
fill ~72 ~59 ~91 ~78 ~59 ~93 stone 3
fill ~91 ~59 ~91 ~91 ~60 ~91 stone
fill ~92 ~59 ~91 ~93 ~60 ~91 log 12
fill ~71 ~59 ~92 ~71 ~60 ~93 log 12
fill ~91 ~59 ~92 ~91 ~62 ~92 stone 3
fill ~81 ~59 ~93 ~88 ~60 ~93 stone 3
setblock ~89 ~59 ~93 stone 3
fill ~90 ~59 ~93 ~90 ~61 ~94 stained_glass_pane 9
setblock ~72 ~59 ~94 log 12
fill ~78 ~59 ~94 ~78 ~60 ~94 log 12
setblock ~79 ~59 ~94 stone 3
setblock ~80 ~59 ~94 stone
fill ~82 ~59 ~94 ~85 ~59 ~94 stone 3
setblock ~86 ~59 ~94 gold_ore
fill ~88 ~59 ~94 ~90 ~61 ~94 stained_glass_pane 9
fill ~77 ~59 ~95 ~78 ~59 ~95 log 12
fill ~79 ~59 ~95 ~79 ~59 ~96 planks 1
fill ~83 ~59 ~95 ~83 ~59 ~96 planks 1
fill ~78 ~59 ~97 ~78 ~59 ~99 planks 1
fill ~81 ~59 ~97 ~81 ~60 ~97 fence
fill ~84 ~59 ~97 ~84 ~59 ~99 planks 1
fill ~14 ~59 ~100 ~15 ~59 ~100 wool 14
fill ~21 ~59 ~100 ~22 ~59 ~100 wool 14
fill ~140 ~59 ~100 ~141 ~59 ~100 wool 14
fill ~147 ~59 ~100 ~148 ~59 ~100 wool 14
setblock ~15 ~59 ~101 wool 14
fill ~18 ~59 ~101 ~18 ~61 ~101 quartz_block
setblock ~21 ~59 ~101 wool 14
setblock ~141 ~59 ~101 wool 14
fill ~144 ~59 ~101 ~144 ~61 ~101 quartz_block
setblock ~147 ~59 ~101 wool 14
fill ~17 ~59 ~102 ~19 ~60 ~102 quartz_block
setblock ~104 ~59 ~102 fence
setblock ~108 ~59 ~102 fence
fill ~143 ~59 ~102 ~145 ~60 ~102 quartz_block
setblock ~55 ~59 ~103 fence
setblock ~57 ~59 ~103 fence
setblock ~59 ~59 ~103 fence
setblock ~103 ~59 ~103 fence
setblock ~109 ~59 ~103 fence
setblock ~54 ~59 ~104 fence
setblock ~60 ~59 ~104 fence
setblock ~103 ~59 ~105 fence
setblock ~109 ~59 ~105 fence
setblock ~54 ~59 ~106 fence
fill ~77 ~59 ~106 ~78 ~59 ~106 stone_slab
setblock ~103 ~59 ~107 fence
setblock ~109 ~59 ~107 fence
setblock ~54 ~59 ~108 fence
setblock ~60 ~59 ~108 fence
setblock ~104 ~59 ~108 fence
setblock ~106 ~59 ~108 fence
setblock ~108 ~59 ~108 fence
setblock ~55 ~59 ~109 fence
setblock ~57 ~59 ~109 fence
setblock ~59 ~59 ~109 fence
fill ~84 ~59 ~114 ~85 ~59 ~114 stone_slab
fill ~80 ~59 ~125 ~80 ~59 ~126 leaves 8
fill ~82 ~59 ~125 ~82 ~59 ~126 leaves 8
setblock ~83 ~59 ~127 leaves 8
fill ~76 ~59 ~129 ~77 ~59 ~129 leaves 8
fill ~86 ~59 ~129 ~86 ~59 ~130 leaves 8
fill ~74 ~59 ~130 ~74 ~59 ~131 log 12
setblock ~76 ~59 ~130 leaves 8
fill ~79 ~59 ~130 ~83 ~66 ~130 log 12
fill ~88 ~59 ~130 ~88 ~59 ~131 log 12
setblock ~73 ~59 ~131 activator_rail 1
setblock ~75 ~59 ~131 activator_rail 1
setblock ~76 ~59 ~131 dropper 1
setblock ~78 ~59 ~131 leaves 8
fill ~79 ~59 ~131 ~83 ~60 ~131 log 12
setblock ~84 ~59 ~131 leaves 8
setblock ~86 ~59 ~131 dropper 1
setblock ~87 ~59 ~131 activator_rail 1
setblock ~89 ~59 ~131 activator_rail 1
setblock ~74 ~59 ~132 activator_rail 1
setblock ~80 ~59 ~132 spruce_stairs 4
setblock ~81 ~59 ~132 log 12
setblock ~82 ~59 ~132 spruce_stairs 5
setblock ~88 ~59 ~132 activator_rail 1
setblock ~74 ~59 ~133 dropper 1
fill ~81 ~59 ~133 ~81 ~61 ~133 leaves 8
setblock ~88 ~59 ~133 dropper 1
fill ~62 ~59 ~140 ~62 ~59 ~141 wool 14
fill ~100 ~59 ~140 ~100 ~59 ~141 wool 14
fill ~61 ~59 ~141 ~62 ~59 ~141 wool 14
setblock ~101 ~59 ~141 wool 14
fill ~60 ~59 ~143 ~60 ~60 ~145 quartz_block
fill ~102 ~59 ~143 ~103 ~59 ~145 quartz_block
fill ~61 ~59 ~144 ~61 ~61 ~144 quartz_block
fill ~101 ~59 ~144 ~103 ~59 ~144 quartz_block
fill ~61 ~59 ~147 ~62 ~59 ~147 wool 14
fill ~100 ~59 ~147 ~101 ~59 ~147 wool 14
setblock ~62 ~59 ~148 wool 14
setblock ~100 ~59 ~148 wool 14
fill ~77 ~59 ~156 ~78 ~59 ~156 wool 14
fill ~84 ~59 ~156 ~85 ~59 ~156 wool 14
setblock ~78 ~59 ~157 wool 14
fill ~81 ~59 ~157 ~81 ~60 ~158 quartz_block
setblock ~84 ~59 ~157 wool 14
fill ~80 ~59 ~158 ~82 ~59 ~159 quartz_block
fill ~80 ~60 ~5 ~82 ~60 ~5 quartz_block
fill ~81 ~60 ~6 ~81 ~61 ~6 quartz_block
fill ~78 ~60 ~7 ~79 ~60 ~7 wool 14
fill ~80 ~60 ~7 ~80 ~61 ~7 fence
fill ~82 ~60 ~7 ~82 ~61 ~7 fence
fill ~83 ~60 ~7 ~84 ~60 ~7 wool 14
fill ~62 ~60 ~15 ~62 ~60 ~16 wool 14
fill ~100 ~60 ~15 ~100 ~60 ~16 wool 14
fill ~62 ~60 ~17 ~62 ~61 ~17 fence
fill ~100 ~60 ~17 ~100 ~61 ~17 fence
fill ~102 ~60 ~17 ~102 ~60 ~19 quartz_block
fill ~101 ~60 ~18 ~102 ~60 ~18 quartz_block
fill ~62 ~60 ~19 ~62 ~61 ~19 fence
fill ~100 ~60 ~19 ~100 ~61 ~19 fence
fill ~62 ~60 ~20 ~62 ~60 ~21 wool 14
fill ~100 ~60 ~20 ~100 ~60 ~21 wool 14
fill ~81 ~60 ~28 ~81 ~61 ~29 leaves 8
fill ~80 ~60 ~29 ~82 ~61 ~29 leaves 8
fill ~79 ~60 ~30 ~79 ~62 ~30 leaves 8
setblock ~80 ~60 ~30 spruce_stairs 5
setblock ~82 ~60 ~30 spruce_stairs 4
fill ~83 ~60 ~30 ~83 ~62 ~30 leaves 8
setblock ~75 ~60 ~31 spruce_stairs 2
fill ~76 ~60 ~31 ~76 ~61 ~31 leaves 8
fill ~86 ~60 ~31 ~86 ~61 ~31 leaves 8
setblock ~87 ~60 ~31 spruce_stairs 2
fill ~74 ~60 ~32 ~74 ~62 ~32 leaves 8
fill ~75 ~60 ~32 ~76 ~61 ~32 log 12
