setblock ~ ~ ~1 command_block 0
fill ~1 ~78 ~1 ~162 ~78 ~161 air
fill ~162 ~78 ~1 ~323 ~78 ~161 air
fill ~1 ~77 ~1 ~162 ~77 ~161 air
fill ~162 ~77 ~1 ~323 ~77 ~161 air
fill ~1 ~76 ~1 ~162 ~76 ~161 air
fill ~162 ~76 ~1 ~323 ~76 ~161 air
fill ~1 ~75 ~1 ~162 ~75 ~161 air
fill ~162 ~75 ~1 ~323 ~75 ~161 air
fill ~1 ~74 ~1 ~162 ~74 ~161 air
fill ~162 ~74 ~1 ~323 ~74 ~161 air
fill ~1 ~73 ~1 ~162 ~73 ~161 air
fill ~162 ~73 ~1 ~323 ~73 ~161 air
fill ~1 ~72 ~1 ~162 ~72 ~161 air
fill ~162 ~72 ~1 ~323 ~72 ~161 air
fill ~1 ~71 ~1 ~162 ~71 ~161 air
fill ~162 ~71 ~1 ~323 ~71 ~161 air
fill ~1 ~70 ~1 ~162 ~70 ~161 air
fill ~162 ~70 ~1 ~323 ~70 ~161 air
fill ~1 ~69 ~1 ~162 ~69 ~161 air
fill ~162 ~69 ~1 ~323 ~69 ~161 air
fill ~1 ~68 ~1 ~162 ~68 ~161 air
fill ~162 ~68 ~1 ~323 ~68 ~161 air
fill ~1 ~67 ~1 ~162 ~67 ~161 air
fill ~162 ~67 ~1 ~323 ~67 ~161 air
fill ~1 ~66 ~1 ~162 ~66 ~161 air
fill ~162 ~66 ~1 ~323 ~66 ~161 air
fill ~1 ~65 ~1 ~162 ~65 ~161 air
fill ~162 ~65 ~1 ~323 ~65 ~161 air
fill ~1 ~64 ~1 ~162 ~64 ~161 air
fill ~162 ~64 ~1 ~323 ~64 ~161 air
fill ~1 ~63 ~1 ~162 ~63 ~161 air
fill ~162 ~63 ~1 ~323 ~63 ~161 air
fill ~1 ~62 ~1 ~162 ~62 ~161 air
fill ~162 ~62 ~1 ~323 ~62 ~161 air
fill ~1 ~61 ~1 ~162 ~61 ~161 air
fill ~162 ~61 ~1 ~323 ~61 ~161 air
fill ~1 ~60 ~1 ~162 ~60 ~161 air
fill ~162 ~60 ~1 ~323 ~60 ~161 air
fill ~1 ~59 ~1 ~162 ~59 ~161 air
fill ~162 ~59 ~1 ~323 ~59 ~161 air
fill ~1 ~58 ~1 ~162 ~58 ~161 air
fill ~162 ~58 ~1 ~323 ~58 ~161 air
fill ~1 ~57 ~1 ~162 ~57 ~161 air
fill ~162 ~57 ~1 ~323 ~57 ~161 air
fill ~1 ~56 ~1 ~162 ~56 ~161 air
fill ~162 ~56 ~1 ~323 ~56 ~161 air
fill ~1 ~55 ~1 ~162 ~55 ~161 air
fill ~162 ~55 ~1 ~323 ~55 ~161 air
fill ~1 ~54 ~1 ~162 ~54 ~161 air
fill ~162 ~54 ~1 ~323 ~54 ~161 air
fill ~1 ~53 ~1 ~162 ~53 ~161 air
fill ~162 ~53 ~1 ~323 ~53 ~161 air
fill ~1 ~52 ~1 ~162 ~52 ~161 air
fill ~162 ~52 ~1 ~323 ~52 ~161 air
fill ~1 ~51 ~1 ~162 ~51 ~161 air
fill ~162 ~51 ~1 ~323 ~51 ~161 air
fill ~1 ~50 ~1 ~162 ~50 ~161 air
fill ~162 ~50 ~1 ~323 ~50 ~161 air
fill ~1 ~49 ~1 ~162 ~49 ~161 air
fill ~162 ~49 ~1 ~323 ~49 ~161 air
fill ~1 ~48 ~1 ~162 ~48 ~161 air
fill ~162 ~48 ~1 ~323 ~48 ~161 air
fill ~1 ~47 ~1 ~162 ~47 ~161 air
fill ~162 ~47 ~1 ~323 ~47 ~161 air
fill ~1 ~46 ~1 ~162 ~46 ~161 air
fill ~162 ~46 ~1 ~323 ~46 ~161 air
fill ~1 ~45 ~1 ~162 ~45 ~161 air
fill ~162 ~45 ~1 ~323 ~45 ~161 air
fill ~1 ~44 ~1 ~162 ~44 ~161 air
fill ~162 ~44 ~1 ~323 ~44 ~161 air
fill ~1 ~43 ~1 ~162 ~43 ~161 air
fill ~162 ~43 ~1 ~323 ~43 ~161 air
fill ~1 ~42 ~1 ~162 ~42 ~161 air
fill ~162 ~42 ~1 ~323 ~42 ~161 air
fill ~1 ~41 ~1 ~162 ~41 ~161 air
fill ~162 ~41 ~1 ~323 ~41 ~161 air
fill ~1 ~40 ~1 ~162 ~40 ~161 air
fill ~162 ~40 ~1 ~323 ~40 ~161 air
fill ~1 ~39 ~1 ~162 ~39 ~161 air
fill ~162 ~39 ~1 ~323 ~39 ~161 air
fill ~1 ~38 ~1 ~162 ~38 ~161 air
fill ~162 ~38 ~1 ~323 ~38 ~161 air
fill ~1 ~37 ~1 ~162 ~37 ~161 air
fill ~162 ~37 ~1 ~323 ~37 ~161 air
fill ~1 ~36 ~1 ~162 ~36 ~161 air
fill ~162 ~36 ~1 ~323 ~36 ~161 air
fill ~1 ~35 ~1 ~162 ~35 ~161 air
fill ~162 ~35 ~1 ~323 ~35 ~161 air
fill ~1 ~34 ~1 ~162 ~34 ~161 air
fill ~162 ~34 ~1 ~323 ~34 ~161 air
fill ~1 ~33 ~1 ~162 ~33 ~161 air
fill ~162 ~33 ~1 ~323 ~33 ~161 air
fill ~1 ~32 ~1 ~162 ~32 ~161 air
fill ~162 ~32 ~1 ~323 ~32 ~161 air
fill ~1 ~31 ~1 ~162 ~31 ~161 air
fill ~162 ~31 ~1 ~323 ~31 ~161 air
fill ~1 ~30 ~1 ~162 ~30 ~161 air
fill ~162 ~30 ~1 ~323 ~30 ~161 air
fill ~1 ~29 ~1 ~162 ~29 ~161 air
fill ~162 ~29 ~1 ~323 ~29 ~161 air
fill ~1 ~28 ~1 ~162 ~28 ~161 air
fill ~162 ~28 ~1 ~323 ~28 ~161 air
fill ~1 ~27 ~1 ~162 ~27 ~161 air
fill ~162 ~27 ~1 ~323 ~27 ~161 air
fill ~1 ~26 ~1 ~162 ~26 ~161 air
fill ~162 ~26 ~1 ~323 ~26 ~161 air
fill ~1 ~25 ~1 ~162 ~25 ~161 air
fill ~162 ~25 ~1 ~323 ~25 ~161 air
fill ~1 ~24 ~1 ~162 ~24 ~161 air
fill ~162 ~24 ~1 ~323 ~24 ~161 air
fill ~1 ~23 ~1 ~162 ~23 ~161 air
fill ~162 ~23 ~1 ~323 ~23 ~161 air
fill ~1 ~22 ~1 ~162 ~22 ~161 air
fill ~162 ~22 ~1 ~323 ~22 ~161 air
fill ~1 ~21 ~1 ~162 ~21 ~161 air
fill ~162 ~21 ~1 ~323 ~21 ~161 air
fill ~1 ~20 ~1 ~162 ~20 ~161 air
fill ~162 ~20 ~1 ~323 ~20 ~161 air
fill ~1 ~19 ~1 ~162 ~19 ~161 air
fill ~162 ~19 ~1 ~323 ~19 ~161 air
fill ~1 ~18 ~1 ~162 ~18 ~161 air
fill ~162 ~18 ~1 ~323 ~18 ~161 air
fill ~1 ~17 ~1 ~162 ~17 ~161 air
fill ~162 ~17 ~1 ~323 ~17 ~161 air
fill ~1 ~16 ~1 ~162 ~16 ~161 air
fill ~162 ~16 ~1 ~323 ~16 ~161 air
fill ~1 ~15 ~1 ~162 ~15 ~161 air
fill ~162 ~15 ~1 ~323 ~15 ~161 air
fill ~1 ~14 ~1 ~162 ~14 ~161 air
fill ~162 ~14 ~1 ~323 ~14 ~161 air
fill ~1 ~13 ~1 ~162 ~13 ~161 air
fill ~162 ~13 ~1 ~323 ~13 ~161 air
fill ~1 ~12 ~1 ~162 ~12 ~161 air
fill ~162 ~12 ~1 ~323 ~12 ~161 air
fill ~1 ~11 ~1 ~162 ~11 ~161 air
fill ~162 ~11 ~1 ~323 ~11 ~161 air
fill ~1 ~10 ~1 ~162 ~10 ~161 air
fill ~162 ~10 ~1 ~323 ~10 ~161 air
fill ~1 ~9 ~1 ~162 ~9 ~161 air
fill ~162 ~9 ~1 ~323 ~9 ~161 air
fill ~1 ~8 ~1 ~162 ~8 ~161 air
fill ~162 ~8 ~1 ~323 ~8 ~161 air
fill ~1 ~7 ~1 ~162 ~7 ~161 air
fill ~162 ~7 ~1 ~323 ~7 ~161 air
fill ~1 ~6 ~1 ~162 ~6 ~161 air
fill ~162 ~6 ~1 ~323 ~6 ~161 air
fill ~1 ~5 ~1 ~162 ~5 ~161 air
fill ~162 ~5 ~1 ~323 ~5 ~161 air
fill ~1 ~4 ~1 ~162 ~4 ~161 air
fill ~162 ~4 ~1 ~323 ~4 ~161 air
fill ~1 ~3 ~1 ~162 ~3 ~161 air
fill ~162 ~3 ~1 ~323 ~3 ~161 air
fill ~1 ~2 ~1 ~162 ~2 ~161 air
fill ~162 ~2 ~1 ~323 ~2 ~161 air
fill ~1 ~1 ~1 ~162 ~1 ~161 air
fill ~162 ~1 ~1 ~323 ~1 ~161 air
fill ~1 ~0 ~1 ~162 ~0 ~161 air
fill ~162 ~0 ~1 ~323 ~0 ~161 air
fill ~82 ~0 ~81 ~82 ~51 ~82 stone
fill ~83 ~0 ~82 ~83 ~51 ~82 stone
fill ~82 ~1 ~80 ~82 ~51 ~83 stone
fill ~81 ~1 ~81 ~82 ~2 ~82 stone
fill ~83 ~2 ~81 ~83 ~51 ~82 stone
fill ~83 ~3 ~80 ~83 ~51 ~82 stone
fill ~81 ~3 ~82 ~83 ~51 ~82 stone
fill ~82 ~4 ~79 ~82 ~51 ~83 stone
fill ~81 ~4 ~80 ~83 ~51 ~83 stone
fill ~83 ~5 ~79 ~83 ~51 ~83 stone
fill ~84 ~5 ~80 ~84 ~51 ~82 stone
fill ~85 ~5 ~81 ~85 ~51 ~81 stone
fill ~82 ~7 ~78 ~82 ~51 ~83 stone
fill ~81 ~7 ~79 ~83 ~51 ~83 stone
fill ~84 ~8 ~79 ~84 ~51 ~82 stone
fill ~85 ~8 ~82 ~85 ~51 ~82 stone
fill ~83 ~9 ~78 ~83 ~51 ~83 stone
fill ~80 ~9 ~79 ~84 ~51 ~80 stone
fill ~85 ~9 ~80 ~85 ~43 ~82 stone
fill ~86 ~9 ~80 ~86 ~43 ~80 stone
fill ~84 ~9 ~83 ~84 ~52 ~83 stone
fill ~81 ~10 ~78 ~83 ~51 ~83 stone
fill ~80 ~10 ~81 ~86 ~51 ~81 stone
fill ~86 ~10 ~82 ~86 ~51 ~82 stone
fill ~85 ~10 ~83 ~85 ~12 ~83 stone
fill ~80 ~11 ~78 ~84 ~51 ~82 stone
fill ~79 ~11 ~79 ~86 ~43 ~80 stone
fill ~86 ~11 ~83 ~86 ~12 ~83 stone
fill ~82 ~12 ~76 ~82 ~51 ~83 stone
fill ~81 ~12 ~77 ~83 ~43 ~83 stone
fill ~85 ~12 ~78 ~85 ~12 ~83 stone
fill ~79 ~12 ~81 ~87 ~51 ~81 stone
fill ~82 ~12 ~84 ~83 ~12 ~84 stone
fill ~81 ~13 ~76 ~83 ~43 ~83 stone
fill ~79 ~13 ~82 ~86 ~51 ~82 stone
fill ~80 ~13 ~83 ~84 ~51 ~83 stone
fill ~83 ~13 ~84 ~83 ~52 ~84 stone
fill ~82 ~14 ~75 ~82 ~51 ~84 stone
fill ~80 ~14 ~77 ~85 ~43 ~83 stone
fill ~79 ~14 ~78 ~84 ~51 ~82 stone
fill ~81 ~14 ~84 ~84 ~51 ~84 stone
fill ~80 ~15 ~76 ~84 ~43 ~83 stone
fill ~78 ~15 ~78 ~86 ~15 ~82 stone
fill ~87 ~15 ~79 ~87 ~17 ~82 stone
fill ~79 ~15 ~83 ~86 ~51 ~83 stone
fill ~85 ~15 ~84 ~86 ~52 ~84 stone
fill ~81 ~15 ~85 ~81 ~51 ~85 stone
fill ~83 ~15 ~85 ~84 ~43 ~85 stone
fill ~81 ~16 ~75 ~82 ~43 ~85 stone
fill ~79 ~16 ~76 ~85 ~43 ~83 stone
fill ~86 ~16 ~77 ~86 ~43 ~84 stone
fill ~78 ~16 ~79 ~84 ~51 ~82 stone
fill ~88 ~16 ~80 ~88 ~18 ~82 stone
fill ~87 ~16 ~83 ~87 ~18 ~83 stone
fill ~80 ~16 ~84 ~86 ~51 ~84 stone
fill ~80 ~16 ~85 ~81 ~51 ~85 stone
setblock ~85 ~16 ~85 stone
fill ~82 ~16 ~86 ~82 ~43 ~86 stone
fill ~82 ~17 ~74 ~82 ~51 ~84 stone
fill ~83 ~17 ~75 ~83 ~43 ~86 stone
fill ~78 ~17 ~77 ~86 ~17 ~82 stone
fill ~77 ~17 ~80 ~87 ~43 ~82 stone
fill ~81 ~17 ~86 ~84 ~43 ~86 stone
fill ~80 ~18 ~75 ~84 ~43 ~86 stone
fill ~78 ~18 ~78 ~84 ~51 ~83 stone
fill ~76 ~18 ~81 ~88 ~51 ~81 stone
fill ~79 ~18 ~84 ~86 ~51 ~84 stone
fill ~85 ~18 ~85 ~85 ~44 ~85 stone
fill ~81 ~18 ~87 ~83 ~51 ~87 stone
fill ~81 ~19 ~74 ~82 ~43 ~87 stone
fill ~78 ~19 ~77 ~86 ~43 ~84 stone
fill ~87 ~19 ~78 ~87 ~51 ~82 stone
fill ~77 ~19 ~83 ~86 ~43 ~83 stone
fill ~79 ~19 ~85 ~85 ~43 ~85 stone
fill ~83 ~20 ~74 ~83 ~43 ~87 stone
fill ~86 ~20 ~76 ~86 ~52 ~77 stone
fill ~87 ~20 ~77 ~87 ~51 ~83 stone
fill ~77 ~20 ~78 ~87 ~43 ~83 stone
fill ~76 ~20 ~80 ~87 ~43 ~82 stone
setblock ~86 ~20 ~85 stone
fill ~80 ~21 ~74 ~83 ~43 ~87 stone
fill ~85 ~21 ~75 ~85 ~43 ~86 stone
fill ~78 ~21 ~76 ~86 ~43 ~84 stone
fill ~87 ~21 ~76 ~87 ~23 ~83 stone
fill ~77 ~21 ~77 ~87 ~43 ~83 stone
fill ~88 ~21 ~77 ~88 ~23 ~77 stone
setblock ~88 ~21 ~78 stone
fill ~76 ~21 ~79 ~87 ~43 ~83 stone
fill ~75 ~21 ~80 ~84 ~51 ~81 stone
fill ~88 ~21 ~80 ~88 ~23 ~81 stone
setblock ~88 ~21 ~82 stone
fill ~84 ~21 ~87 ~84 ~52 ~87 stone
fill ~82 ~21 ~88 ~83 ~51 ~88 stone
fill ~84 ~22 ~74 ~84 ~43 ~87 stone
fill ~79 ~22 ~75 ~85 ~43 ~86 stone
fill ~77 ~22 ~76 ~86 ~43 ~84 stone
fill ~75 ~22 ~82 ~87 ~43 ~82 stone
fill ~78 ~22 ~85 ~86 ~43 ~85 stone
fill ~86 ~22 ~86 ~86 ~52 ~86 stone
fill ~85 ~22 ~87 ~85 ~52 ~87 stone
fill ~81 ~23 ~73 ~83 ~43 ~88 stone
fill ~78 ~23 ~75 ~85 ~43 ~86 stone
fill ~76 ~23 ~78 ~86 ~43 ~84 stone
fill ~88 ~23 ~78 ~88 ~52 ~78 stone
fill ~75 ~23 ~79 ~87 ~43 ~82 stone
fill ~74 ~23 ~80 ~84 ~51 ~80 stone
fill ~88 ~23 ~82 ~88 ~51 ~82 stone
fill ~77 ~23 ~85 ~86 ~43 ~85 stone
fill ~79 ~23 ~87 ~79 ~52 ~87 stone
setblock ~86 ~23 ~87 stone
setblock ~85 ~23 ~88 stone
fill ~82 ~24 ~72 ~83 ~51 ~84 stone
fill ~84 ~24 ~73 ~84 ~52 ~74 stone
fill ~79 ~24 ~74 ~84 ~43 ~87 stone
fill ~77 ~24 ~75 ~85 ~43 ~86 stone
fill ~76 ~24 ~77 ~87 ~43 ~85 stone
fill ~75 ~24 ~78 ~87 ~43 ~84 stone
fill ~74 ~24 ~79 ~84 ~51 ~81 stone
fill ~88 ~24 ~79 ~88 ~52 ~79 stone
fill ~73 ~24 ~80 ~84 ~51 ~80 stone
fill ~80 ~24 ~88 ~83 ~51 ~88 stone
setblock ~84 ~24 ~88 stone
fill ~81 ~24 ~89 ~83 ~51 ~89 stone
fill ~80 ~25 ~44 ~80 ~52 ~44 stone
fill ~85 ~25 ~74 ~85 ~43 ~87 stone
fill ~76 ~25 ~76 ~86 ~43 ~86 stone
fill ~75 ~25 ~77 ~87 ~43 ~84 stone
fill ~74 ~25 ~78 ~88 ~25 ~82 stone
fill ~89 ~25 ~78 ~89 ~52 ~79 stone
fill ~118 ~25 ~80 ~118 ~52 ~80 stone
fill ~44 ~25 ~82 ~44 ~52 ~82 stone
setblock ~89 ~25 ~82 stone
fill ~88 ~25 ~83 ~88 ~52 ~83 stone
fill ~87 ~25 ~86 ~87 ~52 ~86 stone
fill ~77 ~25 ~87 ~85 ~25 ~87 stone
fill ~82 ~25 ~118 ~82 ~52 ~118 stone
fill ~104 ~26 ~56 ~104 ~27 ~56 stone
fill ~56 ~26 ~58 ~56 ~27 ~58 stone
fill ~80 ~26 ~58 ~80 ~52 ~58 stone
fill ~76 ~26 ~75 ~86 ~26 ~86 stone
fill ~87 ~26 ~76 ~87 ~44 ~87 stone
fill ~88 ~26 ~77 ~88 ~51 ~86 stone
fill ~73 ~26 ~79 ~84 ~51 ~81 stone
fill ~90 ~26 ~79 ~90 ~52 ~79 stone
fill ~89 ~26 ~80 ~89 ~51 ~81 stone
fill ~104 ~26 ~80 ~104 ~52 ~80 stone
fill ~58 ~26 ~82 ~58 ~52 ~82 stone
fill ~74 ~26 ~82 ~88 ~43 ~82 stone
fill ~75 ~26 ~85 ~88 ~43 ~86 stone
fill ~78 ~26 ~87 ~87 ~44 ~87 stone
fill ~79 ~26 ~88 ~85 ~51 ~88 stone
fill ~80 ~26 ~89 ~85 ~51 ~89 stone
fill ~81 ~26 ~90 ~81 ~52 ~90 stone
fill ~83 ~26 ~90 ~84 ~52 ~90 stone
setblock ~85 ~26 ~90 stone
fill ~82 ~26 ~104 ~82 ~52 ~104 stone
fill ~106 ~26 ~104 ~106 ~27 ~104 stone
fill ~58 ~26 ~106 ~58 ~27 ~106 stone
fill ~81 ~27 ~44 ~81 ~52 ~44 stone
fill ~81 ~27 ~72 ~83 ~43 ~90 stone
fill ~78 ~27 ~74 ~85 ~43 ~88 stone
fill ~86 ~27 ~75 ~86 ~43 ~88 stone
fill ~89 ~27 ~77 ~89 ~51 ~83 stone
fill ~74 ~27 ~78 ~89 ~43 ~83 stone
fill ~44 ~27 ~81 ~44 ~52 ~82 stone
setblock ~90 ~27 ~81 stone
fill ~118 ~27 ~81 ~118 ~52 ~81 stone
fill ~73 ~27 ~82 ~89 ~43 ~82 stone
fill ~76 ~27 ~87 ~87 ~44 ~87 stone
fill ~87 ~27 ~88 ~87 ~52 ~88 stone
fill ~79 ~27 ~89 ~85 ~51 ~89 stone
fill ~80 ~27 ~90 ~84 ~51 ~90 stone
fill ~82 ~27 ~91 ~82 ~29 ~91 stone
fill ~81 ~27 ~118 ~82 ~52 ~118 stone
fill ~81 ~28 ~32 ~81 ~52 ~32 stone
fill ~81 ~28 ~43 ~81 ~52 ~44 stone
fill ~104 ~28 ~56 ~104 ~30 ~56 sandstone
fill ~56 ~28 ~58 ~56 ~30 ~58 sandstone
fill ~81 ~28 ~58 ~81 ~53 ~58 stone
fill ~76 ~28 ~75 ~86 ~43 ~87 stone
fill ~75 ~28 ~76 ~87 ~43 ~86 stone
fill ~90 ~28 ~80 ~90 ~37 ~80 stone
fill ~32 ~28 ~81 ~32 ~52 ~81 stone
fill ~43 ~28 ~81 ~44 ~52 ~81 stone
fill ~58 ~28 ~81 ~58 ~52 ~82 stone
fill ~104 ~28 ~81 ~104 ~53 ~81 stone
fill ~119 ~28 ~81 ~119 ~52 ~81 stone
fill ~130 ~28 ~81 ~130 ~52 ~81 stone
fill ~90 ~28 ~82 ~90 ~51 ~83 stone
fill ~73 ~28 ~83 ~90 ~43 ~83 stone
fill ~74 ~28 ~84 ~89 ~43 ~84 stone
fill ~88 ~28 ~87 ~88 ~52 ~87 stone
fill ~77 ~28 ~88 ~87 ~51 ~88 stone
fill ~78 ~28 ~89 ~86 ~51 ~89 stone
fill ~79 ~28 ~90 ~84 ~51 ~90 stone
fill ~80 ~28 ~91 ~82 ~29 ~91 stone
fill ~81 ~28 ~104 ~82 ~52 ~104 stone
fill ~106 ~28 ~104 ~106 ~30 ~104 sandstone
fill ~58 ~28 ~106 ~58 ~30 ~106 sandstone
fill ~81 ~28 ~119 ~81 ~52 ~119 stone
fill ~81 ~28 ~130 ~81 ~52 ~130 stone
fill ~80 ~29 ~43 ~81 ~52 ~44 stone
fill ~79 ~29 ~44 ~82 ~52 ~44 stone
setblock ~103 ~29 ~56 end_stone
fill ~104 ~29 ~57 ~104 ~33 ~57 end_stone
fill ~57 ~29 ~58 ~57 ~33 ~58 end_stone
setblock ~56 ~29 ~59 end_stone
fill ~80 ~29 ~59 ~80 ~52 ~59 stone
fill ~81 ~29 ~71 ~81 ~43 ~91 stone
fill ~82 ~29 ~71 ~83 ~31 ~90 stone
fill ~80 ~29 ~72 ~83 ~43 ~90 stone
fill ~76 ~29 ~74 ~86 ~29 ~88 stone
fill ~75 ~29 ~75 ~87 ~43 ~86 stone
fill ~73 ~29 ~78 ~89 ~43 ~84 stone
fill ~72 ~29 ~79 ~84 ~51 ~81 stone
fill ~118 ~29 ~79 ~118 ~52 ~82 stone
fill ~44 ~29 ~80 ~44 ~52 ~83 stone
fill ~103 ~29 ~80 ~104 ~52 ~80 stone
fill ~119 ~29 ~80 ~119 ~52 ~81 stone
fill ~90 ~29 ~81 ~90 ~51 ~83 stone
fill ~43 ~29 ~82 ~44 ~52 ~82 stone
fill ~59 ~29 ~82 ~59 ~52 ~82 stone
fill ~87 ~29 ~89 ~87 ~52 ~89 stone
fill ~85 ~29 ~90 ~86 ~52 ~90 stone
fill ~82 ~29 ~103 ~82 ~52 ~104 stone
setblock ~106 ~29 ~103 end_stone
fill ~105 ~29 ~104 ~105 ~33 ~104 end_stone
fill ~58 ~29 ~105 ~58 ~33 ~105 end_stone
setblock ~59 ~29 ~106 end_stone
fill ~80 ~29 ~118 ~83 ~52 ~118 stone
fill ~82 ~29 ~119 ~82 ~52 ~119 stone
fill ~103 ~30 ~56 ~105 ~30 ~56 sandstone
fill ~56 ~30 ~57 ~56 ~30 ~59 sandstone
fill ~103 ~30 ~57 ~104 ~30 ~57 end_stone
fill ~79 ~30 ~58 ~80 ~52 ~59 stone
setblock ~57 ~30 ~59 end_stone
fill ~80 ~30 ~71 ~82 ~32 ~90 stone
fill ~79 ~30 ~72 ~83 ~43 ~90 stone
fill ~85 ~30 ~73 ~85 ~43 ~90 stone
fill ~77 ~30 ~74 ~86 ~43 ~89 stone
fill ~88 ~30 ~76 ~88 ~51 ~87 stone
fill ~90 ~30 ~78 ~90 ~37 ~83 stone
fill ~103 ~30 ~79 ~104 ~52 ~80 stone
fill ~58 ~30 ~83 ~59 ~52 ~83 stone
fill ~74 ~30 ~85 ~89 ~43 ~85 stone
fill ~75 ~30 ~87 ~88 ~44 ~87 stone
fill ~78 ~30 ~90 ~86 ~51 ~90 stone
fill ~83 ~30 ~103 ~83 ~52 ~104 stone
fill ~105 ~30 ~103 ~105 ~30 ~104 end_stone
fill ~106 ~30 ~103 ~106 ~30 ~105 sandstone
setblock ~59 ~30 ~105 end_stone
fill ~57 ~30 ~106 ~59 ~30 ~106 sandstone
fill ~81 ~31 ~31 ~81 ~51 ~32 stone
fill ~80 ~31 ~42 ~81 ~52 ~45 stone
fill ~79 ~31 ~43 ~82 ~52 ~44 stone
fill ~103 ~31 ~55 ~103 ~33 ~55 end_stone
setblock ~104 ~31 ~55 sandstone
fill ~103 ~31 ~56 ~104 ~31 ~56 end_stone
fill ~105 ~31 ~56 ~105 ~31 ~57 sandstone
fill ~56 ~31 ~57 ~57 ~31 ~57 sandstone
fill ~80 ~31 ~57 ~80 ~52 ~59 stone
fill ~103 ~31 ~57 ~103 ~34 ~57 sandstone
setblock ~55 ~31 ~58 sandstone
fill ~56 ~31 ~58 ~56 ~37 ~58 end_stone
fill ~55 ~31 ~59 ~55 ~33 ~59 end_stone
setblock ~56 ~31 ~59 end_stone
fill ~57 ~31 ~59 ~57 ~34 ~59 sandstone
fill ~81 ~31 ~59 ~81 ~52 ~59 stone
fill ~87 ~31 ~74 ~87 ~44 ~89 stone
fill ~88 ~31 ~75 ~88 ~51 ~87 stone
fill ~74 ~31 ~76 ~89 ~43 ~86 stone
fill ~90 ~31 ~77 ~90 ~52 ~79 stone
fill ~119 ~31 ~79 ~119 ~52 ~82 stone
fill ~43 ~31 ~80 ~44 ~52 ~83 stone
fill ~105 ~31 ~80 ~105 ~52 ~80 stone
fill ~117 ~31 ~80 ~120 ~52 ~81 stone
fill ~31 ~31 ~81 ~32 ~51 ~81 stone
fill ~42 ~31 ~81 ~45 ~52 ~82 stone
fill ~59 ~31 ~81 ~59 ~52 ~83 stone
fill ~103 ~31 ~81 ~104 ~52 ~81 stone
fill ~131 ~31 ~81 ~131 ~51 ~81 stone
fill ~57 ~31 ~82 ~59 ~52 ~82 stone
fill ~91 ~31 ~82 ~91 ~52 ~85 stone
fill ~90 ~31 ~84 ~91 ~52 ~85 stone
fill ~76 ~31 ~88 ~87 ~51 ~88 stone
fill ~77 ~31 ~90 ~86 ~51 ~90 stone
fill ~80 ~31 ~91 ~84 ~52 ~91 stone
fill ~82 ~31 ~92 ~82 ~33 ~92 stone
fill ~81 ~31 ~103 ~83 ~52 ~104 stone
fill ~105 ~31 ~103 ~105 ~34 ~103 sandstone
fill ~106 ~31 ~103 ~107 ~31 ~103 end_stone
fill ~106 ~31 ~104 ~106 ~37 ~104 end_stone
setblock ~107 ~31 ~104 sandstone
fill ~57 ~31 ~105 ~57 ~31 ~106 sandstone
fill ~59 ~31 ~105 ~59 ~34 ~105 sandstone
fill ~82 ~31 ~105 ~82 ~52 ~105 stone
fill ~105 ~31 ~105 ~106 ~31 ~105 sandstone
fill ~58 ~31 ~106 ~58 ~37 ~106 end_stone
fill ~59 ~31 ~106 ~59 ~31 ~107 end_stone
setblock ~58 ~31 ~107 sandstone
fill ~81 ~31 ~117 ~82 ~52 ~120 stone
fill ~80 ~31 ~119 ~83 ~52 ~119 stone
fill ~81 ~31 ~131 ~81 ~51 ~131 stone
fill ~82 ~32 ~31 ~82 ~50 ~31 stone
fill ~80 ~32 ~32 ~81 ~52 ~32 stone
fill ~83 ~32 ~44 ~83 ~52 ~44 stone
setblock ~104 ~32 ~54 sandstone
fill ~104 ~32 ~55 ~104 ~33 ~58 end_stone
fill ~56 ~32 ~56 ~56 ~34 ~56 end_stone
fill ~80 ~32 ~56 ~80 ~52 ~60 stone
fill ~103 ~32 ~56 ~103 ~34 ~57 sandstone
fill ~105 ~32 ~56 ~106 ~32 ~56 end_stone
fill ~56 ~32 ~57 ~57 ~32 ~58 end_stone
fill ~79 ~32 ~57 ~81 ~52 ~59 stone
fill ~105 ~32 ~57 ~105 ~35 ~57 end_stone
setblock ~54 ~32 ~58 sandstone
fill ~55 ~32 ~58 ~58 ~33 ~58 end_stone
fill ~78 ~32 ~58 ~82 ~52 ~58 stone
fill ~56 ~32 ~59 ~57 ~34 ~59 sandstone
fill ~84 ~32 ~72 ~84 ~43 ~91 stone
fill ~77 ~32 ~73 ~85 ~43 ~90 stone
fill ~75 ~32 ~74 ~88 ~43 ~88 stone
fill ~73 ~32 ~77 ~90 ~37 ~84 stone
fill ~104 ~32 ~78 ~104 ~52 ~82 stone
fill ~44 ~32 ~79 ~44 ~52 ~83 stone
fill ~105 ~32 ~79 ~105 ~52 ~81 stone
fill ~31 ~32 ~80 ~31 ~50 ~81 stone
fill ~58 ~32 ~80 ~58 ~52 ~84 stone
fill ~71 ~32 ~80 ~91 ~37 ~80 stone
fill ~102 ~32 ~80 ~106 ~52 ~80 stone
fill ~57 ~32 ~81 ~59 ~52 ~83 stone
fill ~91 ~32 ~81 ~91 ~51 ~86 stone
fill ~56 ~32 ~82 ~60 ~52 ~82 stone
fill ~92 ~32 ~82 ~92 ~51 ~86 stone
fill ~131 ~32 ~82 ~131 ~50 ~82 stone
fill ~118 ~32 ~83 ~118 ~52 ~83 stone
fill ~73 ~32 ~86 ~92 ~32 ~86 stone
fill ~74 ~32 ~87 ~89 ~44 ~87 stone
fill ~89 ~32 ~88 ~89 ~53 ~88 stone
fill ~76 ~32 ~89 ~87 ~51 ~89 stone
fill ~78 ~32 ~91 ~84 ~52 ~91 stone
fill ~80 ~32 ~92 ~81 ~52 ~92 stone
fill ~82 ~32 ~102 ~82 ~52 ~106 stone
fill ~106 ~32 ~103 ~106 ~35 ~103 sandstone
fill ~107 ~32 ~103 ~107 ~33 ~104 end_stone
fill ~58 ~32 ~104 ~58 ~33 ~107 end_stone
fill ~80 ~32 ~104 ~84 ~52 ~104 stone
fill ~104 ~32 ~104 ~107 ~33 ~104 end_stone
setblock ~108 ~32 ~104 sandstone
fill ~57 ~32 ~105 ~58 ~33 ~105 end_stone
fill ~81 ~32 ~105 ~83 ~52 ~105 stone
fill ~105 ~32 ~105 ~105 ~35 ~105 end_stone
fill ~106 ~32 ~105 ~106 ~32 ~106 end_stone
fill ~56 ~32 ~106 ~58 ~32 ~106 end_stone
fill ~59 ~32 ~106 ~59 ~35 ~106 sandstone
fill ~59 ~32 ~107 ~59 ~33 ~107 end_stone
setblock ~58 ~32 ~108 sandstone
fill ~79 ~32 ~118 ~83 ~52 ~118 stone
fill ~80 ~32 ~131 ~81 ~50 ~131 stone
fill ~81 ~33 ~30 ~81 ~51 ~32 stone
fill ~82 ~33 ~32 ~82 ~52 ~32 stone
fill ~81 ~33 ~33 ~81 ~38 ~33 stone
fill ~78 ~33 ~44 ~83 ~52 ~44 stone
fill ~82 ~33 ~45 ~82 ~52 ~45 stone
fill ~81 ~33 ~46 ~81 ~52 ~46 stone
fill ~104 ~33 ~54 ~104 ~34 ~56 end_stone
fill ~105 ~33 ~55 ~105 ~33 ~56 sandstone
setblock ~102 ~33 ~56 stone
fill ~106 ~33 ~56 ~106 ~34 ~56 end_stone
fill ~55 ~33 ~57 ~56 ~33 ~57 sandstone
fill ~57 ~33 ~57 ~57 ~35 ~57 end_stone
fill ~54 ~33 ~58 ~56 ~34 ~58 end_stone
setblock ~56 ~33 ~60 stone
fill ~79 ~33 ~60 ~80 ~52 ~60 stone
fill ~82 ~33 ~71 ~83 ~43 ~91 stone
fill ~85 ~33 ~72 ~85 ~43 ~90 stone
fill ~75 ~33 ~73 ~86 ~43 ~88 stone
fill ~74 ~33 ~74 ~88 ~33 ~74 stone
fill ~118 ~33 ~78 ~118 ~52 ~83 stone
fill ~91 ~33 ~79 ~91 ~51 ~86 stone
fill ~102 ~33 ~79 ~105 ~52 ~80 stone
fill ~32 ~33 ~80 ~32 ~52 ~81 stone
fill ~45 ~33 ~80 ~45 ~52 ~82 stone
fill ~92 ~33 ~80 ~92 ~51 ~86 stone
fill ~30 ~33 ~81 ~32 ~51 ~81 stone
fill ~33 ~33 ~81 ~33 ~38 ~81 stone
fill ~46 ~33 ~81 ~46 ~52 ~81 stone
fill ~116 ~33 ~81 ~120 ~52 ~81 stone
fill ~129 ~33 ~81 ~132 ~38 ~81 stone
fill ~71 ~33 ~82 ~93 ~35 ~82 stone
fill ~117 ~33 ~82 ~119 ~52 ~82 stone
fill ~130 ~33 ~82 ~131 ~50 ~82 stone
fill ~60 ~33 ~83 ~60 ~52 ~83 stone
fill ~72 ~33 ~83 ~93 ~36 ~83 stone
fill ~44 ~33 ~84 ~44 ~52 ~84 stone
fill ~93 ~33 ~84 ~93 ~52 ~84 stone
fill ~73 ~33 ~85 ~93 ~36 ~85 stone
fill ~90 ~33 ~86 ~92 ~51 ~86 stone
fill ~90 ~33 ~87 ~90 ~52 ~87 stone
fill ~74 ~33 ~88 ~89 ~51 ~88 stone
fill ~88 ~33 ~89 ~88 ~56 ~89 stone
fill ~87 ~33 ~90 ~87 ~57 ~90 stone
fill ~79 ~33 ~92 ~79 ~53 ~92 stone
fill ~83 ~33 ~102 ~83 ~52 ~105 stone
setblock ~106 ~33 ~102 stone
fill ~108 ~33 ~104 ~108 ~34 ~104 end_stone
fill ~106 ~33 ~105 ~107 ~33 ~105 sandstone
fill ~56 ~33 ~106 ~56 ~34 ~106 end_stone
fill ~57 ~33 ~106 ~57 ~34 ~106 sandstone
setblock ~60 ~33 ~106 stone
fill ~106 ~33 ~106 ~106 ~34 ~106 end_stone
setblock ~57 ~33 ~107 sandstone
fill ~58 ~33 ~108 ~58 ~34 ~108 end_stone
fill ~81 ~33 ~116 ~81 ~52 ~120 stone
fill ~80 ~33 ~117 ~82 ~52 ~119 stone
fill ~84 ~33 ~118 ~84 ~52 ~118 stone
fill ~81 ~33 ~129 ~81 ~38 ~132 stone
fill ~80 ~33 ~130 ~81 ~50 ~131 stone
fill ~80 ~34 ~31 ~82 ~50 ~32 stone
fill ~79 ~34 ~42 ~81 ~34 ~45 stone
fill ~83 ~34 ~45 ~83 ~52 ~45 stone
fill ~103 ~34 ~55 ~103 ~35 ~56 sandstone
setblock ~105 ~34 ~55 end_stone
fill ~81 ~34 ~56 ~81 ~34 ~60 stone
setblock ~102 ~34 ~56 end_stone
setblock ~105 ~34 ~56 sandstone
fill ~55 ~34 ~57 ~55 ~34 ~58 end_stone
setblock ~56 ~34 ~57 sandstone
fill ~58 ~34 ~57 ~58 ~35 ~57 end_stone
fill ~78 ~34 ~57 ~82 ~52 ~58 stone
fill ~104 ~34 ~57 ~104 ~35 ~57 sandstone
fill ~57 ~34 ~58 ~57 ~35 ~58 sandstone
setblock ~58 ~34 ~58 end_stone
fill ~83 ~34 ~58 ~83 ~52 ~58 stone
setblock ~103 ~34 ~58 sandstone
fill ~104 ~34 ~58 ~105 ~34 ~58 end_stone
fill ~55 ~34 ~59 ~58 ~34 ~59 sandstone
fill ~82 ~34 ~59 ~82 ~52 ~59 stone
setblock ~56 ~34 ~60 end_stone
fill ~76 ~34 ~72 ~85 ~43 ~89 stone
fill ~87 ~34 ~73 ~87 ~44 ~90 stone
fill ~73 ~34 ~76 ~89 ~43 ~88 stone
fill ~45 ~34 ~79 ~45 ~52 ~83 stone
fill ~58 ~34 ~79 ~58 ~52 ~84 stone
fill ~117 ~34 ~79 ~120 ~52 ~81 stone
fill ~57 ~34 ~80 ~59 ~52 ~83 stone
fill ~130 ~34 ~80 ~131 ~50 ~82 stone
fill ~56 ~34 ~81 ~60 ~34 ~82 stone
fill ~71 ~34 ~81 ~92 ~43 ~82 stone
fill ~102 ~34 ~81 ~102 ~53 ~81 stone
setblock ~106 ~34 ~81 stone
fill ~31 ~34 ~82 ~32 ~50 ~82 stone
fill ~103 ~34 ~82 ~105 ~52 ~82 stone
fill ~42 ~34 ~83 ~45 ~34 ~83 stone
fill ~104 ~34 ~83 ~104 ~52 ~83 stone
fill ~117 ~34 ~83 ~118 ~52 ~83 stone
fill ~72 ~34 ~84 ~93 ~43 ~84 stone
fill ~72 ~34 ~86 ~91 ~43 ~87 stone
fill ~90 ~34 ~88 ~90 ~52 ~88 stone
fill ~74 ~34 ~89 ~88 ~51 ~89 stone
fill ~77 ~34 ~91 ~85 ~52 ~91 stone
fill ~78 ~34 ~92 ~81 ~52 ~92 stone
fill ~81 ~34 ~102 ~83 ~52 ~105 stone
setblock ~106 ~34 ~102 end_stone
fill ~80 ~34 ~103 ~83 ~52 ~105 stone
fill ~104 ~34 ~103 ~107 ~34 ~103 sandstone
fill ~57 ~34 ~104 ~57 ~35 ~105 end_stone
setblock ~58 ~34 ~104 end_stone
fill ~59 ~34 ~104 ~59 ~34 ~107 sandstone
fill ~79 ~34 ~104 ~84 ~52 ~104 stone
fill ~104 ~34 ~104 ~104 ~34 ~105 end_stone
fill ~105 ~34 ~104 ~105 ~35 ~104 sandstone
fill ~107 ~34 ~104 ~108 ~34 ~104 end_stone
fill ~58 ~34 ~105 ~59 ~34 ~105 sandstone
setblock ~106 ~34 ~105 sandstone
setblock ~107 ~34 ~105 end_stone
setblock ~60 ~34 ~106 end_stone
fill ~81 ~34 ~106 ~82 ~34 ~106 stone
fill ~57 ~34 ~107 ~58 ~34 ~107 end_stone
fill ~79 ~34 ~117 ~83 ~52 ~118 stone
fill ~83 ~34 ~120 ~83 ~52 ~120 stone
fill ~82 ~34 ~130 ~82 ~50 ~131 stone
fill ~82 ~35 ~30 ~82 ~50 ~33 stone
fill ~79 ~35 ~32 ~83 ~51 ~32 stone
fill ~79 ~35 ~45 ~83 ~52 ~45 stone
fill ~80 ~35 ~46 ~81 ~52 ~46 stone
fill ~104 ~35 ~54 ~105 ~36 ~54 sandstone
fill ~106 ~35 ~54 ~106 ~36 ~54 end_stone
fill ~80 ~35 ~55 ~80 ~52 ~60 stone
fill ~102 ~35 ~55 ~102 ~36 ~55 stone
fill ~104 ~35 ~55 ~104 ~37 ~55 sandstone
setblock ~105 ~35 ~55 sandstone
setblock ~106 ~35 ~55 end_stone
fill ~54 ~35 ~56 ~55 ~35 ~56 end_stone
setblock ~56 ~35 ~56 sandstone
fill ~79 ~35 ~56 ~80 ~52 ~60 stone
fill ~102 ~35 ~56 ~103 ~35 ~56 sandstone
fill ~104 ~35 ~56 ~104 ~37 ~56 end_stone
fill ~105 ~35 ~56 ~105 ~35 ~58 end_stone
setblock ~106 ~35 ~56 sandstone
fill ~54 ~35 ~57 ~54 ~43 ~57 sandstone
fill ~55 ~35 ~57 ~55 ~35 ~59 sandstone
fill ~56 ~35 ~57 ~58 ~35 ~57 end_stone
fill ~102 ~35 ~57 ~102 ~36 ~57 sandstone
fill ~103 ~35 ~57 ~103 ~36 ~58 end_stone
fill ~54 ~35 ~58 ~55 ~36 ~58 sandstone
setblock ~58 ~35 ~58 sandstone
setblock ~59 ~35 ~58 end_stone
setblock ~104 ~35 ~58 sandstone
fill ~56 ~35 ~59 ~56 ~35 ~60 sandstone
fill ~57 ~35 ~59 ~58 ~36 ~59 end_stone
setblock ~104 ~35 ~59 end_stone
fill ~55 ~35 ~60 ~55 ~36 ~60 stone
fill ~57 ~35 ~60 ~57 ~36 ~60 sandstone
fill ~81 ~35 ~60 ~81 ~53 ~60 stone
fill ~80 ~35 ~71 ~83 ~43 ~91 stone
fill ~86 ~35 ~72 ~86 ~43 ~91 stone
fill ~88 ~35 ~73 ~88 ~51 ~90 stone
fill ~74 ~35 ~74 ~88 ~43 ~90 stone
fill ~73 ~35 ~75 ~89 ~43 ~89 stone
fill ~72 ~35 ~76 ~90 ~37 ~88 stone
fill ~91 ~35 ~78 ~91 ~52 ~85 stone
fill ~32 ~35 ~79 ~32 ~51 ~82 stone
fill ~71 ~35 ~79 ~91 ~37 ~82 stone
fill ~106 ~35 ~79 ~106 ~52 ~80 stone
fill ~30 ~35 ~80 ~32 ~50 ~81 stone
fill ~33 ~35 ~80 ~33 ~52 ~80 stone
fill ~107 ~35 ~80 ~107 ~52 ~80 stone
fill ~116 ~35 ~80 ~120 ~52 ~81 stone
fill ~60 ~35 ~81 ~60 ~52 ~83 stone
fill ~46 ~35 ~82 ~46 ~52 ~82 stone
fill ~55 ~35 ~82 ~60 ~52 ~82 stone
fill ~129 ~35 ~82 ~132 ~50 ~82 stone
fill ~56 ~35 ~83 ~60 ~52 ~83 stone
fill ~130 ~35 ~83 ~130 ~51 ~83 stone
fill ~71 ~35 ~87 ~91 ~44 ~87 stone
setblock ~91 ~35 ~88 stone
fill ~90 ~35 ~89 ~90 ~52 ~89 stone
fill ~76 ~35 ~91 ~87 ~51 ~91 stone
fill ~82 ~35 ~92 ~82 ~52 ~92 stone
fill ~80 ~35 ~93 ~81 ~52 ~93 stone
fill ~105 ~35 ~102 ~106 ~35 ~102 sandstone
fill ~107 ~35 ~102 ~107 ~36 ~102 stone
setblock ~58 ~35 ~103 end_stone
fill ~104 ~35 ~103 ~105 ~36 ~103 end_stone
fill ~107 ~35 ~103 ~107 ~35 ~105 sandstone
fill ~58 ~35 ~104 ~58 ~35 ~105 sandstone
fill ~59 ~35 ~104 ~59 ~36 ~105 end_stone
setblock ~103 ~35 ~104 end_stone
fill ~104 ~35 ~104 ~105 ~35 ~104 sandstone
fill ~108 ~35 ~104 ~108 ~36 ~105 sandstone
fill ~60 ~35 ~105 ~60 ~36 ~105 sandstone
fill ~104 ~35 ~105 ~106 ~35 ~105 end_stone
setblock ~56 ~35 ~106 sandstone
fill ~57 ~35 ~106 ~58 ~35 ~106 end_stone
setblock ~60 ~35 ~106 sandstone
fill ~83 ~35 ~106 ~83 ~52 ~106 stone
setblock ~106 ~35 ~106 sandstone
fill ~107 ~35 ~106 ~108 ~35 ~106 end_stone
fill ~56 ~35 ~107 ~56 ~35 ~108 end_stone
fill ~57 ~35 ~107 ~58 ~35 ~108 sandstone
setblock ~59 ~35 ~107 sandstone
fill ~60 ~35 ~107 ~60 ~36 ~107 stone
fill ~82 ~35 ~107 ~82 ~52 ~107 stone
fill ~82 ~35 ~116 ~82 ~52 ~120 stone
fill ~80 ~35 ~129 ~80 ~50 ~132 stone
fill ~79 ~35 ~130 ~82 ~51 ~130 stone
fill ~83 ~36 ~31 ~83 ~51 ~32 stone
fill ~80 ~36 ~33 ~80 ~52 ~33 stone
fill ~80 ~36 ~41 ~81 ~52 ~46 stone
fill ~79 ~36 ~42 ~82 ~52 ~46 stone
fill ~78 ~36 ~43 ~83 ~51 ~44 stone
fill ~84 ~36 ~44 ~84 ~51 ~44 stone
fill ~78 ~36 ~45 ~83 ~36 ~45 stone
fill ~83 ~36 ~46 ~83 ~52 ~46 stone
fill ~104 ~36 ~53 ~104 ~36 ~55 sandstone
fill ~102 ~36 ~54 ~102 ~37 ~54 stone
fill ~103 ~36 ~54 ~103 ~36 ~58 end_stone
fill ~55 ~36 ~55 ~55 ~36 ~56 sandstone
fill ~101 ~36 ~55 ~102 ~36 ~55 stone
setblock ~105 ~36 ~55 end_stone
fill ~106 ~36 ~55 ~107 ~36 ~55 sandstone
setblock ~54 ~36 ~56 end_stone
setblock ~56 ~36 ~56 end_stone
fill ~81 ~36 ~56 ~81 ~52 ~61 stone
fill ~102 ~36 ~56 ~104 ~36 ~56 end_stone
fill ~105 ~36 ~56 ~105 ~41 ~56 sandstone
setblock ~106 ~36 ~56 end_stone
setblock ~55 ~36 ~57 end_stone
fill ~56 ~36 ~57 ~56 ~41 ~57 sandstone
fill ~57 ~36 ~57 ~57 ~38 ~57 sandstone
setblock ~58 ~36 ~57 sandstone
fill ~104 ~36 ~57 ~104 ~36 ~58 end_stone
fill ~105 ~36 ~57 ~105 ~38 ~57 sandstone
fill ~53 ~36 ~58 ~55 ~36 ~58 sandstone
fill ~57 ~36 ~58 ~58 ~36 ~59 end_stone
fill ~59 ~36 ~58 ~59 ~37 ~58 sandstone
fill ~77 ~36 ~58 ~84 ~52 ~58 stone
setblock ~105 ~36 ~58 sandstone
fill ~54 ~36 ~59 ~58 ~36 ~59 end_stone
fill ~78 ~36 ~59 ~82 ~52 ~59 stone
fill ~104 ~36 ~59 ~104 ~37 ~59 sandstone
fill ~54 ~36 ~60 ~55 ~36 ~60 stone
setblock ~56 ~36 ~60 end_stone
fill ~82 ~36 ~60 ~82 ~52 ~60 stone
setblock ~55 ~36 ~61 stone
fill ~80 ~36 ~70 ~83 ~43 ~92 stone
fill ~76 ~36 ~71 ~84 ~43 ~91 stone
fill ~75 ~36 ~72 ~86 ~43 ~91 stone
fill ~73 ~36 ~74 ~89 ~43 ~90 stone
fill ~72 ~36 ~75 ~89 ~43 ~89 stone
fill ~91 ~36 ~76 ~91 ~51 ~87 stone
fill ~104 ~36 ~77 ~104 ~52 ~84 stone
fill ~44 ~36 ~78 ~44 ~51 ~84 stone
fill ~58 ~36 ~78 ~58 ~52 ~85 stone
fill ~71 ~36 ~78 ~91 ~37 ~87 stone
fill ~103 ~36 ~78 ~104 ~52 ~82 stone
fill ~119 ~36 ~78 ~119 ~51 ~83 stone
fill ~31 ~36 ~79 ~32 ~50 ~82 stone
fill ~43 ~36 ~79 ~46 ~52 ~83 stone
fill ~92 ~36 ~79 ~92 ~51 ~86 stone
fill ~116 ~36 ~79 ~120 ~52 ~82 stone
fill ~130 ~36 ~79 ~130 ~51 ~83 stone
fill ~42 ~36 ~80 ~46 ~52 ~83 stone
fill ~60 ~36 ~80 ~60 ~52 ~83 stone
fill ~70 ~36 ~80 ~92 ~37 ~81 stone
fill ~121 ~36 ~80 ~121 ~52 ~81 stone
fill ~129 ~36 ~80 ~131 ~50 ~80 stone
fill ~41 ~36 ~81 ~46 ~52 ~82 stone
fill ~56 ~36 ~81 ~60 ~52 ~83 stone
fill ~61 ~36 ~81 ~61 ~52 ~81 stone
fill ~69 ~36 ~81 ~92 ~51 ~81 stone
fill ~101 ~36 ~81 ~106 ~52 ~81 stone
fill ~33 ~36 ~82 ~33 ~52 ~82 stone
fill ~102 ~36 ~82 ~105 ~52 ~82 stone
fill ~32 ~36 ~83 ~32 ~51 ~83 stone
fill ~116 ~36 ~83 ~119 ~52 ~83 stone
fill ~131 ~36 ~83 ~131 ~51 ~83 stone
fill ~43 ~36 ~84 ~44 ~51 ~84 stone
setblock ~45 ~36 ~84 stone
fill ~59 ~36 ~84 ~59 ~52 ~84 stone
fill ~118 ~36 ~84 ~118 ~51 ~84 stone
fill ~71 ~36 ~88 ~90 ~36 ~88 stone
fill ~74 ~36 ~91 ~88 ~51 ~91 stone
fill ~77 ~36 ~92 ~85 ~51 ~92 stone
fill ~82 ~36 ~93 ~82 ~52 ~93 stone
fill ~81 ~36 ~101 ~81 ~52 ~106 stone
fill ~107 ~36 ~101 ~107 ~36 ~102 stone
fill ~80 ~36 ~102 ~83 ~52 ~105 stone
setblock ~105 ~36 ~102 sandstone
fill ~106 ~36 ~102 ~106 ~36 ~104 end_stone
fill ~108 ~36 ~102 ~108 ~37 ~102 stone
fill ~58 ~36 ~103 ~58 ~37 ~103 sandstone
fill ~84 ~36 ~103 ~84 ~52 ~104 stone
fill ~107 ~36 ~103 ~108 ~36 ~103 end_stone
fill ~57 ~36 ~104 ~57 ~36 ~106 sandstone
fill ~58 ~36 ~104 ~59 ~36 ~106 end_stone
fill ~78 ~36 ~104 ~85 ~52 ~104 stone
fill ~103 ~36 ~104 ~103 ~37 ~104 sandstone
fill ~104 ~36 ~104 ~106 ~36 ~104 end_stone
fill ~107 ~36 ~104 ~109 ~36 ~104 sandstone
fill ~104 ~36 ~105 ~106 ~36 ~105 sandstone
setblock ~107 ~36 ~105 end_stone
setblock ~56 ~36 ~106 end_stone
setblock ~60 ~36 ~106 end_stone
setblock ~106 ~36 ~106 end_stone
fill ~107 ~36 ~106 ~107 ~36 ~107 sandstone
setblock ~108 ~36 ~106 end_stone
fill ~55 ~36 ~107 ~56 ~36 ~107 sandstone
setblock ~57 ~36 ~107 end_stone
fill ~58 ~36 ~107 ~58 ~36 ~109 sandstone
fill ~59 ~36 ~107 ~59 ~36 ~108 end_stone
setblock ~61 ~36 ~107 stone
setblock ~56 ~36 ~108 end_stone
fill ~57 ~36 ~108 ~57 ~43 ~108 sandstone
fill ~60 ~36 ~108 ~60 ~37 ~108 stone
fill ~79 ~36 ~116 ~83 ~52 ~119 stone
fill ~84 ~36 ~117 ~84 ~51 ~119 stone
fill ~78 ~36 ~118 ~84 ~51 ~118 stone
fill ~80 ~36 ~120 ~83 ~52 ~120 stone
fill ~81 ~36 ~121 ~82 ~52 ~121 stone
fill ~82 ~36 ~129 ~82 ~50 ~131 stone
fill ~83 ~36 ~130 ~83 ~51 ~130 stone
fill ~79 ~36 ~131 ~82 ~50 ~131 stone
fill ~83 ~37 ~9 ~83 ~40 ~9 stone
fill ~65 ~37 ~16 ~65 ~40 ~16 stone
fill ~97 ~37 ~20 ~97 ~40 ~20 stone
fill ~80 ~37 ~30 ~83 ~50 ~32 stone
fill ~79 ~37 ~31 ~83 ~50 ~32 stone
fill ~81 ~37 ~34 ~81 ~52 ~34 stone
fill ~79 ~37 ~41 ~82 ~52 ~46 stone
fill ~78 ~37 ~42 ~83 ~51 ~44 stone
fill ~81 ~37 ~47 ~81 ~52 ~47 stone
fill ~102 ~37 ~53 ~103 ~48 ~53 stone
setblock ~104 ~37 ~53 sandstone
setblock ~105 ~37 ~53 end_stone
setblock ~103 ~37 ~54 stone
setblock ~104 ~37 ~54 end_stone
fill ~105 ~37 ~54 ~106 ~42 ~54 sandstone
fill ~55 ~37 ~55 ~55 ~37 ~56 end_stone
fill ~78 ~37 ~55 ~81 ~52 ~55 stone
fill ~101 ~37 ~55 ~105 ~37 ~55 sandstone
fill ~106 ~37 ~55 ~106 ~39 ~55 end_stone
setblock ~107 ~37 ~55 end_stone
fill ~54 ~37 ~56 ~54 ~42 ~57 sandstone
fill ~56 ~37 ~56 ~56 ~37 ~57 sandstone
fill ~57 ~37 ~56 ~57 ~38 ~56 end_stone
fill ~82 ~37 ~56 ~82 ~52 ~60 stone
fill ~102 ~37 ~56 ~102 ~38 ~56 sandstone
fill ~103 ~37 ~56 ~104 ~37 ~56 end_stone
setblock ~106 ~37 ~56 sandstone
setblock ~53 ~37 ~57 end_stone
fill ~55 ~37 ~57 ~55 ~37 ~61 sandstone
fill ~58 ~37 ~57 ~58 ~37 ~58 end_stone
fill ~83 ~37 ~57 ~83 ~52 ~59 stone
setblock ~102 ~37 ~57 end_stone
fill ~103 ~37 ~57 ~105 ~38 ~57 sandstone
fill ~106 ~37 ~57 ~106 ~38 ~57 end_stone
setblock ~53 ~37 ~58 sandstone
setblock ~54 ~37 ~58 end_stone
fill ~57 ~37 ~58 ~57 ~38 ~59 sandstone
fill ~103 ~37 ~58 ~103 ~38 ~58 sandstone
fill ~104 ~37 ~58 ~105 ~37 ~58 end_stone
fill ~53 ~37 ~59 ~53 ~48 ~60 stone
fill ~54 ~37 ~59 ~54 ~37 ~60 stone
fill ~56 ~37 ~59 ~56 ~38 ~59 end_stone
fill ~58 ~37 ~59 ~58 ~38 ~59 sandstone
fill ~56 ~37 ~60 ~56 ~38 ~60 sandstone
setblock ~57 ~37 ~60 end_stone
fill ~20 ~37 ~65 ~20 ~40 ~65 stone
fill ~146 ~37 ~65 ~146 ~40 ~65 stone
fill ~79 ~37 ~70 ~84 ~43 ~93 stone
fill ~75 ~37 ~71 ~85 ~43 ~91 stone
fill ~87 ~37 ~72 ~87 ~44 ~91 stone
fill ~74 ~37 ~73 ~88 ~43 ~91 stone
fill ~72 ~37 ~74 ~89 ~43 ~89 stone
fill ~90 ~37 ~74 ~90 ~56 ~74 stone
fill ~71 ~37 ~76 ~89 ~39 ~87 stone
fill ~92 ~37 ~76 ~92 ~37 ~87 stone
fill ~93 ~37 ~77 ~93 ~37 ~79 stone
fill ~70 ~37 ~78 ~71 ~52 ~84 stone
fill ~105 ~37 ~78 ~105 ~52 ~83 stone
fill ~107 ~37 ~78 ~107 ~42 ~81 stone
fill ~117 ~37 ~78 ~120 ~51 ~83 stone
fill ~9 ~37 ~79 ~9 ~40 ~79 stone
fill ~30 ~37 ~79 ~32 ~50 ~82 stone
fill ~42 ~37 ~79 ~46 ~52 ~83 stone
fill ~57 ~37 ~79 ~59 ~52 ~84 stone
fill ~121 ~37 ~79 ~121 ~52 ~82 stone
fill ~131 ~37 ~79 ~131 ~50 ~83 stone
fill ~41 ~37 ~80 ~46 ~52 ~83 stone
fill ~56 ~37 ~80 ~60 ~52 ~83 stone
fill ~69 ~37 ~80 ~71 ~52 ~81 stone
fill ~132 ~37 ~80 ~132 ~50 ~83 stone
fill ~34 ~37 ~81 ~34 ~52 ~81 stone
fill ~47 ~37 ~81 ~47 ~52 ~81 stone
fill ~55 ~37 ~81 ~60 ~52 ~83 stone
fill ~115 ~37 ~81 ~121 ~52 ~81 stone
fill ~128 ~37 ~81 ~128 ~52 ~81 stone
fill ~106 ~37 ~82 ~106 ~52 ~82 stone
fill ~31 ~37 ~83 ~32 ~51 ~83 stone
fill ~103 ~37 ~83 ~105 ~52 ~83 stone
fill ~153 ~37 ~83 ~153 ~40 ~83 stone
fill ~42 ~37 ~84 ~44 ~37 ~84 stone
fill ~55 ~37 ~84 ~55 ~42 ~84 stone
fill ~91 ~37 ~88 ~91 ~51 ~88 stone
fill ~90 ~37 ~90 ~90 ~52 ~90 stone
fill ~73 ~37 ~91 ~88 ~51 ~91 stone
fill ~86 ~37 ~92 ~86 ~54 ~92 stone
fill ~78 ~37 ~93 ~84 ~52 ~93 stone
fill ~16 ~37 ~97 ~16 ~40 ~97 stone
fill ~142 ~37 ~97 ~142 ~40 ~97 stone
fill ~107 ~37 ~101 ~107 ~41 ~101 sandstone
setblock ~105 ~37 ~102 end_stone
fill ~106 ~37 ~102 ~107 ~37 ~102 sandstone
fill ~109 ~37 ~102 ~109 ~48 ~103 stone
fill ~79 ~37 ~103 ~84 ~52 ~105 stone
fill ~104 ~37 ~103 ~105 ~38 ~103 sandstone
fill ~106 ~37 ~103 ~106 ~38 ~103 end_stone
fill ~107 ~37 ~103 ~107 ~37 ~105 sandstone
fill ~108 ~37 ~103 ~109 ~37 ~103 stone
fill ~57 ~37 ~104 ~58 ~37 ~104 end_stone
fill ~59 ~37 ~104 ~59 ~38 ~105 sandstone
fill ~104 ~37 ~104 ~104 ~38 ~104 end_stone
fill ~105 ~37 ~104 ~105 ~38 ~105 sandstone
setblock ~108 ~37 ~104 end_stone
setblock ~109 ~37 ~104 sandstone
fill ~56 ~37 ~105 ~56 ~38 ~105 end_stone
fill ~57 ~37 ~105 ~59 ~38 ~105 sandstone
setblock ~60 ~37 ~105 end_stone
setblock ~104 ~37 ~105 end_stone
fill ~106 ~37 ~105 ~106 ~41 ~105 sandstone
fill ~108 ~37 ~105 ~108 ~42 ~106 sandstone
setblock ~109 ~37 ~105 end_stone
fill ~56 ~37 ~106 ~57 ~37 ~106 sandstone
fill ~59 ~37 ~106 ~59 ~38 ~106 end_stone
fill ~60 ~37 ~106 ~60 ~38 ~106 sandstone
fill ~80 ~37 ~106 ~83 ~52 ~106 stone
fill ~105 ~37 ~106 ~105 ~38 ~106 end_stone
setblock ~106 ~37 ~106 sandstone
fill ~107 ~37 ~106 ~107 ~39 ~106 end_stone
fill ~55 ~37 ~107 ~56 ~37 ~107 end_stone
fill ~57 ~37 ~107 ~61 ~37 ~107 sandstone
fill ~81 ~37 ~107 ~83 ~52 ~107 stone
fill ~84 ~37 ~107 ~84 ~42 ~107 stone
setblock ~107 ~37 ~107 end_stone
fill ~56 ~37 ~108 ~57 ~42 ~108 sandstone
setblock ~58 ~37 ~108 end_stone
fill ~59 ~37 ~108 ~60 ~37 ~109 stone
setblock ~57 ~37 ~109 end_stone
setblock ~58 ~37 ~109 sandstone
fill ~81 ~37 ~115 ~81 ~52 ~121 stone
fill ~85 ~37 ~118 ~85 ~51 ~118 stone
fill ~79 ~37 ~120 ~84 ~51 ~120 stone
fill ~80 ~37 ~121 ~83 ~52 ~121 stone
fill ~81 ~37 ~128 ~81 ~52 ~128 stone
fill ~83 ~37 ~131 ~83 ~51 ~131 stone
fill ~79 ~37 ~132 ~82 ~50 ~132 stone
fill ~65 ~37 ~142 ~65 ~40 ~142 stone
fill ~97 ~37 ~146 ~97 ~40 ~146 stone
fill ~79 ~37 ~153 ~79 ~40 ~153 stone
fill ~80 ~38 ~29 ~82 ~50 ~32 stone
fill ~79 ~38 ~30 ~83 ~50 ~32 stone
fill ~84 ~38 ~31 ~84 ~50 ~31 stone
fill ~83 ~38 ~33 ~83 ~51 ~33 stone
fill ~80 ~38 ~40 ~80 ~52 ~47 stone
fill ~77 ~38 ~43 ~83 ~51 ~43 stone
fill ~84 ~38 ~43 ~84 ~45 ~46 stone
fill ~82 ~38 ~47 ~82 ~52 ~47 stone
fill ~104 ~38 ~52 ~104 ~39 ~54 stone
fill ~105 ~38 ~53 ~106 ~38 ~54 sandstone
fill ~101 ~38 ~54 ~101 ~40 ~55 sandstone
fill ~102 ~38 ~54 ~103 ~38 ~54 end_stone
setblock ~107 ~38 ~54 end_stone
setblock ~54 ~38 ~55 end_stone
setblock ~55 ~38 ~55 sandstone
fill ~56 ~38 ~55 ~56 ~38 ~56 end_stone
fill ~102 ~38 ~55 ~102 ~40 ~55 end_stone
setblock ~103 ~38 ~55 sandstone
fill ~104 ~38 ~55 ~106 ~38 ~55 end_stone
setblock ~107 ~38 ~55 sandstone
fill ~53 ~38 ~56 ~54 ~38 ~57 sandstone
fill ~55 ~38 ~56 ~55 ~39 ~57 end_stone
fill ~58 ~38 ~56 ~58 ~40 ~56 sandstone
fill ~78 ~38 ~56 ~82 ~52 ~60 stone
fill ~101 ~38 ~56 ~102 ~38 ~56 sandstone
setblock ~103 ~38 ~56 end_stone
fill ~104 ~38 ~56 ~105 ~39 ~56 sandstone
fill ~106 ~38 ~56 ~107 ~38 ~56 end_stone
setblock ~58 ~38 ~57 sandstone
fill ~77 ~38 ~57 ~83 ~52 ~58 stone
fill ~102 ~38 ~57 ~105 ~38 ~57 sandstone
fill ~52 ~38 ~58 ~54 ~39 ~58 stone
setblock ~55 ~38 ~58 end_stone
fill ~56 ~38 ~58 ~57 ~38 ~58 sandstone
fill ~58 ~38 ~58 ~59 ~38 ~58 end_stone
fill ~102 ~38 ~58 ~102 ~39 ~58 end_stone
fill ~104 ~38 ~58 ~104 ~38 ~59 end_stone
fill ~105 ~38 ~58 ~106 ~38 ~58 sandstone
fill ~54 ~38 ~59 ~54 ~38 ~60 end_stone
setblock ~55 ~38 ~59 sandstone
setblock ~59 ~38 ~59 end_stone
fill ~103 ~38 ~59 ~104 ~38 ~59 end_stone
fill ~55 ~38 ~60 ~55 ~40 ~60 end_stone
setblock ~57 ~38 ~60 sandstone
fill ~58 ~38 ~60 ~58 ~39 ~60 end_stone
fill ~54 ~38 ~61 ~56 ~39 ~61 sandstone
fill ~79 ~38 ~61 ~81 ~52 ~61 stone
fill ~78 ~38 ~69 ~78 ~43 ~94 stone
fill ~81 ~38 ~69 ~83 ~43 ~93 stone
fill ~75 ~38 ~70 ~85 ~43 ~92 stone
fill ~86 ~38 ~71 ~87 ~43 ~91 stone
fill ~74 ~38 ~72 ~88 ~43 ~91 stone
fill ~73 ~38 ~73 ~86 ~43 ~92 stone
fill ~89 ~38 ~73 ~89 ~51 ~91 stone
fill ~90 ~38 ~73 ~90 ~52 ~79 stone
fill ~91 ~38 ~74 ~91 ~56 ~74 stone
fill ~71 ~38 ~75 ~74 ~51 ~85 stone
fill ~70 ~38 ~76 ~91 ~43 ~76 stone
fill ~92 ~38 ~77 ~92 ~50 ~87 stone
fill ~105 ~38 ~77 ~105 ~52 ~83 stone
fill ~119 ~38 ~77 ~119 ~51 ~83 stone
fill ~31 ~38 ~78 ~31 ~50 ~83 stone
fill ~43 ~38 ~78 ~46 ~45 ~83 stone
fill ~69 ~38 ~78 ~89 ~43 ~84 stone
fill ~102 ~38 ~78 ~106 ~52 ~82 stone
fill ~33 ~38 ~79 ~33 ~51 ~80 stone
fill ~68 ~38 ~79 ~89 ~43 ~80 stone
fill ~101 ~38 ~79 ~107 ~52 ~81 stone
fill ~132 ~38 ~79 ~132 ~50 ~83 stone
fill ~29 ~38 ~80 ~32 ~50 ~82 stone
fill ~47 ~38 ~80 ~47 ~52 ~82 stone
fill ~93 ~38 ~80 ~93 ~52 ~84 stone
fill ~115 ~38 ~80 ~121 ~52 ~82 stone
fill ~122 ~38 ~80 ~122 ~52 ~80 stone
fill ~133 ~38 ~80 ~133 ~50 ~82 stone
fill ~40 ~38 ~82 ~47 ~52 ~82 stone
fill ~61 ~38 ~82 ~61 ~52 ~83 stone
fill ~30 ~38 ~83 ~32 ~50 ~83 stone
fill ~129 ~38 ~83 ~132 ~50 ~83 stone
fill ~56 ~38 ~84 ~60 ~52 ~84 stone
fill ~116 ~38 ~84 ~119 ~45 ~84 stone
fill ~131 ~38 ~84 ~131 ~50 ~84 stone
fill ~43 ~38 ~85 ~43 ~51 ~85 stone
fill ~57 ~38 ~85 ~58 ~52 ~85 stone
fill ~70 ~38 ~85 ~92 ~43 ~85 stone
fill ~71 ~38 ~88 ~91 ~51 ~88 stone
fill ~91 ~38 ~89 ~91 ~38 ~90 stone
fill ~74 ~38 ~93 ~84 ~43 ~93 stone
fill ~77 ~38 ~94 ~80 ~51 ~94 stone
fill ~82 ~38 ~101 ~83 ~52 ~107 stone
fill ~106 ~38 ~101 ~108 ~39 ~101 sandstone
fill ~84 ~38 ~102 ~84 ~52 ~106 stone
fill ~104 ~38 ~102 ~104 ~39 ~102 end_stone
fill ~105 ~38 ~102 ~105 ~38 ~105 sandstone
setblock ~106 ~38 ~102 sandstone
fill ~107 ~38 ~102 ~107 ~40 ~102 end_stone
fill ~108 ~38 ~102 ~108 ~38 ~103 end_stone
fill ~58 ~38 ~103 ~59 ~38 ~103 end_stone
fill ~103 ~38 ~103 ~103 ~38 ~104 end_stone
setblock ~107 ~38 ~103 sandstone
fill ~56 ~38 ~104 ~56 ~40 ~104 sandstone
fill ~57 ~38 ~104 ~57 ~38 ~106 sandstone
setblock ~58 ~38 ~104 end_stone
fill ~60 ~38 ~104 ~60 ~39 ~104 end_stone
fill ~106 ~38 ~104 ~106 ~39 ~105 sandstone
fill ~107 ~38 ~104 ~107 ~38 ~106 end_stone
fill ~108 ~38 ~104 ~108 ~49 ~104 stone
fill ~109 ~38 ~104 ~110 ~39 ~104 stone
fill ~60 ~38 ~105 ~60 ~38 ~106 sandstone
fill ~85 ~38 ~105 ~85 ~52 ~105 stone
fill ~104 ~38 ~105 ~106 ~38 ~105 sandstone
fill ~109 ~38 ~105 ~109 ~38 ~106 sandstone
fill ~55 ~38 ~106 ~56 ~38 ~106 end_stone
fill ~58 ~38 ~106 ~58 ~39 ~106 sandstone
fill ~61 ~38 ~106 ~61 ~39 ~108 sandstone
fill ~104 ~38 ~106 ~104 ~40 ~106 sandstone
fill ~106 ~38 ~106 ~107 ~38 ~106 end_stone
setblock ~55 ~38 ~107 sandstone
fill ~56 ~38 ~107 ~57 ~39 ~107 end_stone
setblock ~58 ~38 ~107 end_stone
setblock ~59 ~38 ~107 sandstone
fill ~60 ~38 ~107 ~60 ~40 ~107 end_stone
setblock ~106 ~38 ~107 end_stone
setblock ~107 ~38 ~107 sandstone
setblock ~108 ~38 ~107 end_stone
setblock ~55 ~38 ~108 end_stone
fill ~58 ~38 ~108 ~58 ~49 ~108 stone
fill ~59 ~38 ~108 ~60 ~38 ~108 end_stone
fill ~56 ~38 ~109 ~57 ~38 ~109 sandstone
fill ~58 ~38 ~109 ~60 ~39 ~109 stone
fill ~58 ~38 ~110 ~58 ~39 ~110 stone
fill ~80 ~38 ~115 ~82 ~52 ~121 stone
fill ~78 ~38 ~116 ~83 ~45 ~119 stone
fill ~85 ~38 ~119 ~85 ~51 ~119 stone
fill ~82 ~38 ~122 ~82 ~52 ~122 stone
fill ~79 ~38 ~129 ~80 ~50 ~132 stone
fill ~78 ~38 ~131 ~83 ~50 ~131 stone
fill ~83 ~38 ~132 ~83 ~50 ~132 stone
fill ~80 ~38 ~133 ~82 ~50 ~133 stone
fill ~78 ~39 ~9 ~78 ~40 ~9 sandstone
fill ~82 ~39 ~9 ~82 ~42 ~9 sandstone
fill ~97 ~39 ~15 ~97 ~40 ~15 sandstone
fill ~65 ~39 ~17 ~65 ~42 ~17 sandstone
fill ~97 ~39 ~19 ~97 ~42 ~19 sandstone
fill ~65 ~39 ~21 ~65 ~40 ~21 sandstone
fill ~81 ~39 ~26 ~81 ~49 ~26 stone
fill ~81 ~39 ~28 ~81 ~50 ~32 stone
fill ~83 ~39 ~29 ~83 ~50 ~33 stone
fill ~84 ~39 ~30 ~84 ~50 ~32 stone
fill ~78 ~39 ~31 ~84 ~50 ~31 stone
fill ~82 ~39 ~34 ~82 ~52 ~34 stone
fill ~80 ~39 ~39 ~80 ~52 ~47 stone
fill ~79 ~39 ~40 ~82 ~52 ~46 stone
fill ~77 ~39 ~41 ~83 ~51 ~45 stone
fill ~84 ~39 ~42 ~84 ~40 ~46 stone
fill ~76 ~39 ~43 ~83 ~51 ~43 stone
fill ~85 ~39 ~43 ~85 ~51 ~45 stone
fill ~81 ~39 ~48 ~81 ~52 ~49 stone
fill ~105 ~39 ~52 ~105 ~40 ~53 end_stone
setblock ~106 ~39 ~53 end_stone
setblock ~55 ~39 ~54 stone
fill ~102 ~39 ~54 ~103 ~39 ~54 sandstone
fill ~107 ~39 ~54 ~107 ~40 ~54 stone
fill ~54 ~39 ~55 ~54 ~40 ~55 stone
fill ~55 ~39 ~55 ~55 ~39 ~57 end_stone
fill ~56 ~39 ~55 ~56 ~39 ~59 sandstone
fill ~57 ~39 ~55 ~57 ~40 ~55 sandstone
fill ~100 ~39 ~55 ~101 ~41 ~55 sandstone
setblock ~103 ~39 ~55 end_stone
fill ~104 ~39 ~55 ~104 ~39 ~56 sandstone
fill ~105 ~39 ~55 ~107 ~39 ~55 end_stone
setblock ~108 ~39 ~55 stone
fill ~53 ~39 ~56 ~53 ~39 ~57 end_stone
fill ~57 ~39 ~56 ~58 ~39 ~56 sandstone
fill ~77 ~39 ~56 ~82 ~52 ~60 stone
setblock ~101 ~39 ~56 sandstone
fill ~102 ~39 ~56 ~102 ~39 ~58 end_stone
fill ~103 ~39 ~56 ~107 ~39 ~56 sandstone
fill ~52 ~39 ~57 ~53 ~40 ~57 end_stone
fill ~57 ~39 ~57 ~58 ~40 ~57 end_stone
fill ~59 ~39 ~57 ~59 ~39 ~59 sandstone
fill ~103 ~39 ~57 ~105 ~39 ~57 end_stone
fill ~106 ~39 ~57 ~107 ~39 ~57 sandstone
fill ~55 ~39 ~58 ~56 ~39 ~58 sandstone
fill ~57 ~39 ~58 ~57 ~39 ~60 end_stone
fill ~58 ~39 ~58 ~59 ~39 ~58 sandstone
fill ~60 ~39 ~58 ~60 ~41 ~58 stone
fill ~103 ~39 ~58 ~103 ~42 ~58 end_stone
fill ~104 ~39 ~58 ~104 ~39 ~59 sandstone
fill ~105 ~39 ~58 ~105 ~40 ~58 end_stone
fill ~106 ~39 ~58 ~106 ~40 ~58 sandstone
fill ~54 ~39 ~59 ~54 ~39 ~61 sandstone
fill ~55 ~39 ~59 ~55 ~39 ~60 end_stone
fill ~58 ~39 ~59 ~58 ~42 ~59 end_stone
fill ~103 ~39 ~59 ~104 ~41 ~59 sandstone
setblock ~105 ~39 ~59 sandstone
fill ~56 ~39 ~60 ~58 ~39 ~60 end_stone
fill ~83 ~39 ~60 ~83 ~52 ~60 stone
fill ~104 ~39 ~60 ~104 ~41 ~60 stone
fill ~78 ~39 ~61 ~81 ~52 ~61 stone
fill ~55 ~39 ~62 ~55 ~41 ~62 sandstone
fill ~15 ~39 ~65 ~15 ~40 ~65 sandstone
fill ~19 ~39 ~65 ~19 ~42 ~65 sandstone
fill ~141 ~39 ~65 ~141 ~40 ~65 sandstone
fill ~145 ~39 ~65 ~145 ~42 ~65 sandstone
fill ~77 ~39 ~69 ~83 ~43 ~93 stone
fill ~74 ~39 ~70 ~87 ~43 ~91 stone
fill ~88 ~39 ~71 ~88 ~51 ~91 stone
fill ~89 ~39 ~72 ~90 ~51 ~91 stone
fill ~91 ~39 ~73 ~91 ~51 ~88 stone
fill ~92 ~39 ~74 ~92 ~50 ~88 stone
fill ~70 ~39 ~75 ~92 ~43 ~85 stone
fill ~43 ~39 ~77 ~44 ~45 ~85 stone
fill ~45 ~39 ~77 ~45 ~51 ~84 stone
fill ~69 ~39 ~77 ~92 ~43 ~84 stone
fill ~93 ~39 ~77 ~93 ~53 ~77 stone
fill ~102 ~39 ~77 ~106 ~52 ~82 stone
fill ~118 ~39 ~77 ~120 ~51 ~83 stone
fill ~30 ~39 ~78 ~32 ~50 ~83 stone
fill ~42 ~39 ~78 ~46 ~40 ~83 stone
fill ~68 ~39 ~78 ~92 ~43 ~81 stone
fill ~101 ~39 ~78 ~106 ~52 ~81 stone
fill ~121 ~39 ~78 ~121 ~52 ~83 stone
fill ~131 ~39 ~78 ~131 ~50 ~84 stone
fill ~153 ~39 ~78 ~153 ~40 ~78 sandstone
fill ~29 ~39 ~79 ~32 ~50 ~82 stone
fill ~41 ~39 ~79 ~46 ~52 ~83 stone
fill ~60 ~39 ~79 ~60 ~52 ~85 stone
fill ~93 ~39 ~79 ~93 ~52 ~84 stone
fill ~122 ~39 ~79 ~122 ~52 ~82 stone
fill ~9 ~39 ~80 ~9 ~42 ~80 sandstone
fill ~34 ~39 ~80 ~34 ~52 ~81 stone
fill ~40 ~39 ~80 ~46 ~52 ~83 stone
fill ~67 ~39 ~80 ~93 ~43 ~81 stone
fill ~123 ~39 ~80 ~123 ~52 ~80 stone
fill ~26 ~39 ~81 ~26 ~49 ~81 stone
fill ~28 ~39 ~81 ~32 ~50 ~81 stone
fill ~48 ~39 ~81 ~49 ~52 ~81 stone
fill ~113 ~39 ~81 ~122 ~52 ~81 stone
fill ~134 ~39 ~81 ~134 ~50 ~81 stone
fill ~136 ~39 ~81 ~136 ~49 ~81 stone
fill ~39 ~39 ~82 ~47 ~52 ~82 stone
fill ~128 ~39 ~82 ~133 ~50 ~82 stone
fill ~153 ~39 ~82 ~153 ~42 ~82 sandstone
fill ~102 ~39 ~83 ~105 ~52 ~83 stone
fill ~133 ~39 ~83 ~133 ~50 ~83 stone
fill ~9 ~39 ~84 ~9 ~40 ~84 sandstone
fill ~31 ~39 ~84 ~31 ~50 ~84 stone
fill ~41 ~39 ~84 ~45 ~51 ~84 stone
fill ~61 ~39 ~84 ~61 ~52 ~84 stone
fill ~120 ~39 ~84 ~120 ~40 ~84 stone
fill ~130 ~39 ~84 ~132 ~50 ~84 stone
fill ~41 ~39 ~85 ~44 ~40 ~85 stone
setblock ~45 ~39 ~85 stone
fill ~56 ~39 ~85 ~60 ~52 ~85 stone
fill ~117 ~39 ~85 ~119 ~51 ~85 stone
fill ~70 ~39 ~88 ~92 ~39 ~88 stone
fill ~71 ~39 ~89 ~90 ~51 ~90 stone
fill ~72 ~39 ~91 ~90 ~51 ~91 stone
fill ~72 ~39 ~92 ~86 ~43 ~92 stone
fill ~85 ~39 ~93 ~85 ~53 ~93 stone
fill ~75 ~39 ~94 ~81 ~50 ~94 stone
fill ~17 ~39 ~97 ~17 ~42 ~97 sandstone
fill ~21 ~39 ~97 ~21 ~40 ~97 sandstone
fill ~143 ~39 ~97 ~143 ~42 ~97 sandstone
fill ~147 ~39 ~97 ~147 ~40 ~97 sandstone
fill ~107 ~39 ~100 ~107 ~41 ~101 sandstone
fill ~84 ~39 ~101 ~84 ~52 ~106 stone
fill ~58 ~39 ~102 ~58 ~41 ~102 stone
fill ~79 ~39 ~102 ~85 ~52 ~105 stone
fill ~105 ~39 ~102 ~105 ~39 ~105 end_stone
fill ~106 ~39 ~102 ~107 ~39 ~102 end_stone
fill ~108 ~39 ~102 ~108 ~39 ~103 sandstone
fill ~57 ~39 ~103 ~59 ~39 ~103 sandstone
fill ~103 ~39 ~103 ~103 ~41 ~104 sandstone
fill ~104 ~39 ~103 ~104 ~42 ~103 end_stone
fill ~106 ~39 ~103 ~106 ~39 ~107 sandstone
setblock ~107 ~39 ~103 end_stone
fill ~57 ~39 ~104 ~57 ~40 ~105 end_stone
setblock ~58 ~39 ~104 sandstone
fill ~59 ~39 ~104 ~60 ~39 ~105 end_stone
fill ~102 ~39 ~104 ~102 ~41 ~104 stone
setblock ~104 ~39 ~104 sandstone
setblock ~107 ~39 ~104 sandstone
fill ~55 ~39 ~105 ~56 ~39 ~106 sandstone
fill ~58 ~39 ~105 ~60 ~39 ~105 end_stone
setblock ~103 ~39 ~105 sandstone
fill ~104 ~39 ~105 ~105 ~40 ~105 end_stone
fill ~107 ~39 ~105 ~107 ~39 ~107 end_stone
fill ~109 ~39 ~105 ~110 ~40 ~105 end_stone
fill ~57 ~39 ~106 ~59 ~39 ~106 sandstone
fill ~60 ~39 ~106 ~60 ~39 ~107 end_stone
fill ~85 ~39 ~106 ~85 ~52 ~106 stone
fill ~105 ~39 ~106 ~106 ~39 ~107 sandstone
setblock ~109 ~39 ~106 end_stone
setblock ~54 ~39 ~107 stone
fill ~55 ~39 ~107 ~57 ~39 ~107 end_stone
setblock ~58 ~39 ~107 sandstone
fill ~59 ~39 ~107 ~60 ~39 ~107 end_stone
fill ~62 ~39 ~107 ~62 ~41 ~107 sandstone
fill ~108 ~39 ~107 ~108 ~40 ~107 stone
fill ~55 ~39 ~108 ~55 ~40 ~108 stone
fill ~59 ~39 ~108 ~61 ~39 ~108 sandstone
setblock ~107 ~39 ~108 stone
fill ~56 ~39 ~109 ~57 ~39 ~109 end_stone
fill ~57 ~39 ~110 ~57 ~40 ~110 end_stone
fill ~81 ~39 ~113 ~81 ~52 ~122 stone
fill ~77 ~39 ~117 ~85 ~51 ~118 stone
fill ~77 ~39 ~119 ~85 ~45 ~119 stone
fill ~78 ~39 ~120 ~85 ~40 ~120 stone
fill ~79 ~39 ~121 ~85 ~51 ~121 stone
fill ~80 ~39 ~122 ~83 ~52 ~122 stone
fill ~82 ~39 ~123 ~82 ~52 ~123 stone
fill ~80 ~39 ~128 ~80 ~50 ~133 stone
fill ~78 ~39 ~130 ~83 ~50 ~132 stone
fill ~84 ~39 ~131 ~84 ~50 ~131 stone
fill ~79 ~39 ~133 ~82 ~50 ~133 stone
fill ~81 ~39 ~134 ~81 ~50 ~134 stone
fill ~81 ~39 ~136 ~81 ~49 ~136 stone
fill ~97 ~39 ~141 ~97 ~40 ~141 sandstone
fill ~65 ~39 ~143 ~65 ~42 ~143 sandstone
fill ~97 ~39 ~145 ~97 ~42 ~145 sandstone
fill ~65 ~39 ~147 ~65 ~40 ~147 sandstone
fill ~80 ~39 ~153 ~80 ~42 ~153 sandstone
fill ~84 ~39 ~153 ~84 ~40 ~153 sandstone
fill ~83 ~40 ~8 ~83 ~42 ~8 stone
fill ~83 ~40 ~10 ~83 ~43 ~10 sandstone
fill ~64 ~40 ~16 ~64 ~42 ~16 stone
fill ~66 ~40 ~16 ~66 ~43 ~16 sandstone
fill ~96 ~40 ~20 ~96 ~43 ~20 sandstone
fill ~98 ~40 ~20 ~98 ~42 ~20 stone
fill ~82 ~40 ~28 ~82 ~50 ~35 stone
fill ~79 ~40 ~29 ~83 ~50 ~33 stone
fill ~85 ~40 ~31 ~85 ~50 ~31 stone
fill ~84 ~40 ~33 ~84 ~51 ~33 stone
fill ~80 ~40 ~34 ~83 ~52 ~34 stone
fill ~81 ~40 ~35 ~82 ~52 ~35 stone
fill ~80 ~40 ~38 ~81 ~52 ~49 stone
fill ~78 ~40 ~40 ~83 ~51 ~46 stone
fill ~84 ~40 ~41 ~84 ~52 ~41 stone
fill ~76 ~40 ~44 ~86 ~51 ~44 stone
fill ~79 ~40 ~47 ~83 ~52 ~47 stone
fill ~82 ~40 ~48 ~82 ~52 ~49 stone
fill ~103 ~40 ~52 ~103 ~42 ~53 stone
setblock ~104 ~40 ~52 sandstone
fill ~101 ~40 ~53 ~103 ~48 ~53 stone
fill ~104 ~40 ~53 ~105 ~40 ~53 end_stone
fill ~106 ~40 ~53 ~107 ~40 ~53 stone
fill ~54 ~40 ~54 ~54 ~40 ~55 stone
fill ~55 ~40 ~54 ~56 ~40 ~54 end_stone
fill ~57 ~40 ~54 ~57 ~45 ~54 sandstone
fill ~79 ~40 ~54 ~80 ~52 ~61 stone
fill ~100 ~40 ~54 ~100 ~48 ~54 stone
fill ~102 ~40 ~54 ~102 ~40 ~55 end_stone
fill ~103 ~40 ~54 ~103 ~40 ~57 sandstone
fill ~104 ~40 ~54 ~104 ~49 ~54 stone
setblock ~108 ~40 ~54 stone
fill ~53 ~40 ~55 ~54 ~40 ~55 stone
fill ~55 ~40 ~55 ~55 ~42 ~56 sandstone
fill ~56 ~40 ~55 ~56 ~40 ~56 end_stone
fill ~58 ~40 ~55 ~58 ~42 ~55 end_stone
fill ~82 ~40 ~55 ~82 ~52 ~60 stone
fill ~104 ~40 ~55 ~104 ~40 ~58 end_stone
fill ~105 ~40 ~55 ~107 ~40 ~55 sandstone
fill ~108 ~40 ~55 ~108 ~40 ~56 end_stone
setblock ~53 ~40 ~56 stone
fill ~57 ~40 ~56 ~57 ~42 ~56 end_stone
fill ~59 ~40 ~56 ~59 ~41 ~56 sandstone
setblock ~101 ~40 ~56 end_stone
fill ~102 ~40 ~56 ~102 ~42 ~56 sandstone
fill ~106 ~40 ~56 ~108 ~40 ~56 end_stone
fill ~55 ~40 ~57 ~56 ~40 ~57 sandstone
fill ~59 ~40 ~57 ~59 ~41 ~57 end_stone
fill ~101 ~40 ~57 ~101 ~41 ~57 sandstone
setblock ~102 ~40 ~57 end_stone
fill ~105 ~40 ~57 ~105 ~40 ~59 end_stone
fill ~106 ~40 ~57 ~106 ~42 ~57 end_stone
fill ~107 ~40 ~57 ~108 ~40 ~57 sandstone
setblock ~52 ~40 ~58 sandstone
setblock ~53 ~40 ~58 end_stone
fill ~54 ~40 ~58 ~54 ~49 ~58 stone
fill ~55 ~40 ~58 ~58 ~40 ~58 end_stone
fill ~59 ~40 ~58 ~59 ~44 ~58 sandstone
fill ~76 ~40 ~58 ~84 ~52 ~59 stone
setblock ~102 ~40 ~58 sandstone
fill ~107 ~40 ~58 ~107 ~42 ~58 end_stone
fill ~52 ~40 ~59 ~53 ~42 ~59 stone
fill ~54 ~40 ~59 ~57 ~40 ~59 sandstone
fill ~59 ~40 ~59 ~59 ~41 ~59 sandstone
setblock ~102 ~40 ~59 end_stone
fill ~106 ~40 ~59 ~106 ~41 ~59 sandstone
fill ~54 ~40 ~60 ~55 ~40 ~60 end_stone
fill ~56 ~40 ~60 ~56 ~42 ~60 sandstone
setblock ~57 ~40 ~60 end_stone
setblock ~58 ~40 ~60 sandstone
setblock ~59 ~40 ~60 end_stone
fill ~53 ~40 ~61 ~53 ~48 ~61 stone
fill ~54 ~40 ~61 ~55 ~40 ~61 sandstone
setblock ~56 ~40 ~61 end_stone
fill ~57 ~40 ~61 ~57 ~41 ~61 sandstone
fill ~54 ~40 ~62 ~54 ~48 ~62 stone
fill ~20 ~40 ~64 ~20 ~42 ~64 stone
fill ~146 ~40 ~64 ~146 ~42 ~64 stone
fill ~20 ~40 ~66 ~20 ~43 ~66 sandstone
fill ~146 ~40 ~66 ~146 ~43 ~66 sandstone
fill ~78 ~40 ~68 ~79 ~43 ~95 stone
fill ~75 ~40 ~69 ~83 ~43 ~94 stone
fill ~73 ~40 ~70 ~88 ~41 ~92 stone
fill ~89 ~40 ~71 ~89 ~51 ~92 stone
fill ~91 ~40 ~72 ~91 ~52 ~85 stone
fill ~72 ~40 ~73 ~89 ~43 ~92 stone
fill ~92 ~40 ~73 ~92 ~50 ~89 stone
fill ~93 ~40 ~74 ~93 ~43 ~88 stone
fill ~44 ~40 ~76 ~44 ~51 ~85 stone
fill ~94 ~40 ~76 ~94 ~52 ~81 stone
fill ~103 ~40 ~76 ~104 ~52 ~84 stone
fill ~119 ~40 ~76 ~120 ~51 ~83 stone
fill ~31 ~40 ~77 ~31 ~50 ~84 stone
fill ~117 ~40 ~77 ~121 ~51 ~83 stone
fill ~33 ~40 ~78 ~33 ~51 ~83 stone
fill ~41 ~40 ~78 ~41 ~52 ~84 stone
fill ~59 ~40 ~78 ~59 ~52 ~86 stone
fill ~116 ~40 ~78 ~122 ~51 ~83 stone
fill ~8 ~40 ~79 ~8 ~42 ~79 stone
fill ~10 ~40 ~79 ~10 ~43 ~79 sandstone
fill ~34 ~40 ~79 ~34 ~52 ~82 stone
fill ~40 ~40 ~79 ~47 ~52 ~83 stone
fill ~67 ~40 ~79 ~93 ~43 ~82 stone
fill ~95 ~40 ~79 ~95 ~52 ~79 stone
fill ~108 ~40 ~79 ~108 ~52 ~80 stone
fill ~115 ~40 ~79 ~122 ~52 ~83 stone
fill ~129 ~40 ~79 ~133 ~50 ~83 stone
fill ~28 ~40 ~80 ~35 ~50 ~81 stone
fill ~48 ~40 ~80 ~49 ~52 ~82 stone
fill ~55 ~40 ~80 ~60 ~52 ~83 stone
fill ~66 ~40 ~80 ~94 ~43 ~81 stone
fill ~113 ~40 ~80 ~122 ~52 ~82 stone
fill ~124 ~40 ~80 ~124 ~52 ~81 stone
fill ~128 ~40 ~80 ~133 ~50 ~83 stone
fill ~38 ~40 ~81 ~49 ~52 ~82 stone
fill ~123 ~40 ~81 ~124 ~52 ~81 stone
fill ~127 ~40 ~81 ~134 ~50 ~82 stone
fill ~54 ~40 ~82 ~61 ~52 ~83 stone
fill ~107 ~40 ~82 ~107 ~52 ~82 stone
fill ~29 ~40 ~83 ~33 ~50 ~83 stone
fill ~68 ~40 ~83 ~93 ~43 ~84 stone
fill ~152 ~40 ~83 ~152 ~43 ~83 sandstone
fill ~154 ~40 ~83 ~154 ~42 ~83 stone
fill ~40 ~40 ~84 ~46 ~51 ~84 stone
fill ~121 ~40 ~84 ~121 ~52 ~84 stone
fill ~129 ~40 ~84 ~132 ~50 ~84 stone
fill ~69 ~40 ~85 ~93 ~43 ~85 stone
fill ~131 ~40 ~85 ~131 ~50 ~85 stone
fill ~58 ~40 ~86 ~59 ~52 ~86 stone
fill ~70 ~40 ~86 ~70 ~54 ~86 stone
fill ~118 ~40 ~86 ~118 ~51 ~86 stone
fill ~91 ~40 ~89 ~91 ~51 ~90 stone
fill ~91 ~40 ~91 ~91 ~43 ~91 stone
fill ~73 ~40 ~93 ~86 ~43 ~93 stone
fill ~74 ~40 ~94 ~84 ~43 ~94 stone
fill ~76 ~40 ~95 ~81 ~50 ~95 stone
fill ~16 ~40 ~96 ~16 ~43 ~96 sandstone
fill ~142 ~40 ~96 ~142 ~43 ~96 sandstone
fill ~16 ~40 ~98 ~16 ~42 ~98 stone
fill ~142 ~40 ~98 ~142 ~42 ~98 stone
fill ~108 ~40 ~100 ~108 ~48 ~100 stone
fill ~105 ~40 ~101 ~105 ~41 ~101 sandstone
setblock ~106 ~40 ~101 end_stone
setblock ~108 ~40 ~101 sandstone
fill ~109 ~40 ~101 ~109 ~48 ~103 stone
setblock ~103 ~40 ~102 end_stone
setblock ~104 ~40 ~102 sandstone
setblock ~105 ~40 ~102 end_stone
fill ~106 ~40 ~102 ~106 ~42 ~102 sandstone
setblock ~108 ~40 ~102 end_stone
fill ~56 ~40 ~103 ~56 ~41 ~103 sandstone
fill ~57 ~40 ~103 ~57 ~40 ~105 end_stone
fill ~58 ~40 ~103 ~58 ~44 ~103 sandstone
fill ~59 ~40 ~103 ~59 ~41 ~103 sandstone
setblock ~60 ~40 ~103 end_stone
fill ~78 ~40 ~103 ~86 ~52 ~104 stone
fill ~105 ~40 ~103 ~108 ~40 ~103 sandstone
fill ~110 ~40 ~103 ~110 ~42 ~103 stone
fill ~55 ~40 ~104 ~55 ~42 ~104 end_stone
fill ~58 ~40 ~104 ~59 ~41 ~104 end_stone
setblock ~60 ~40 ~104 sandstone
fill ~104 ~40 ~104 ~107 ~40 ~104 end_stone
fill ~109 ~40 ~104 ~109 ~40 ~105 end_stone
setblock ~110 ~40 ~104 sandstone
fill ~54 ~40 ~105 ~54 ~45 ~105 sandstone
setblock ~55 ~40 ~105 sandstone
fill ~56 ~40 ~105 ~58 ~40 ~105 end_stone
fill ~59 ~40 ~105 ~59 ~40 ~108 sandstone
setblock ~60 ~40 ~105 end_stone
fill ~61 ~40 ~105 ~61 ~41 ~105 sandstone
fill ~103 ~40 ~105 ~105 ~40 ~105 end_stone
fill ~107 ~40 ~105 ~108 ~40 ~106 sandstone
fill ~54 ~40 ~106 ~56 ~40 ~106 end_stone
fill ~57 ~40 ~106 ~57 ~40 ~108 sandstone
fill ~58 ~40 ~106 ~58 ~40 ~107 end_stone
fill ~60 ~40 ~106 ~60 ~42 ~106 sandstone
setblock ~61 ~40 ~106 end_stone
fill ~103 ~40 ~106 ~104 ~40 ~106 sandstone
fill ~105 ~40 ~106 ~105 ~42 ~106 end_stone
fill ~106 ~40 ~106 ~106 ~40 ~108 end_stone
fill ~109 ~40 ~106 ~109 ~40 ~107 stone
setblock ~54 ~40 ~107 end_stone
fill ~55 ~40 ~107 ~56 ~42 ~107 sandstone
fill ~61 ~40 ~107 ~62 ~41 ~107 sandstone
fill ~80 ~40 ~107 ~83 ~52 ~107 stone
fill ~104 ~40 ~107 ~104 ~42 ~107 end_stone
fill ~105 ~40 ~107 ~105 ~40 ~108 sandstone
fill ~107 ~40 ~107 ~107 ~42 ~107 sandstone
fill ~54 ~40 ~108 ~55 ~40 ~108 stone
setblock ~60 ~40 ~108 end_stone
setblock ~61 ~40 ~108 sandstone
fill ~62 ~40 ~108 ~62 ~48 ~108 stone
fill ~82 ~40 ~108 ~83 ~52 ~108 stone
setblock ~107 ~40 ~108 end_stone
setblock ~108 ~40 ~108 stone
fill ~55 ~40 ~109 ~56 ~40 ~109 stone
fill ~57 ~40 ~109 ~58 ~40 ~109 end_stone
fill ~59 ~40 ~109 ~61 ~48 ~109 stone
setblock ~58 ~40 ~110 sandstone
fill ~59 ~40 ~110 ~59 ~42 ~110 stone
fill ~80 ~40 ~113 ~82 ~52 ~122 stone
fill ~79 ~40 ~115 ~83 ~52 ~122 stone
fill ~84 ~40 ~116 ~84 ~51 ~122 stone
fill ~76 ~40 ~118 ~85 ~51 ~118 stone
fill ~86 ~40 ~119 ~86 ~51 ~119 stone
fill ~78 ~40 ~121 ~85 ~51 ~121 stone
fill ~81 ~40 ~123 ~82 ~52 ~124 stone
fill ~80 ~40 ~127 ~81 ~50 ~134 stone
fill ~79 ~40 ~128 ~82 ~50 ~133 stone
fill ~78 ~40 ~129 ~83 ~50 ~132 stone
fill ~77 ~40 ~131 ~84 ~50 ~131 stone
fill ~83 ~40 ~133 ~83 ~50 ~133 stone
fill ~64 ~40 ~142 ~64 ~42 ~142 stone
fill ~66 ~40 ~142 ~66 ~43 ~142 sandstone
fill ~96 ~40 ~146 ~96 ~43 ~146 sandstone
fill ~98 ~40 ~146 ~98 ~42 ~146 stone
fill ~79 ~40 ~152 ~79 ~43 ~152 sandstone
fill ~79 ~40 ~154 ~79 ~42 ~154 stone
fill ~82 ~41 ~8 ~82 ~42 ~10 sandstone
fill ~78 ~41 ~9 ~78 ~42 ~9 stone
fill ~79 ~41 ~9 ~79 ~43 ~10 sandstone
fill ~83 ~41 ~9 ~83 ~43 ~10 sandstone
fill ~84 ~41 ~9 ~84 ~43 ~9 stone
fill ~81 ~41 ~12 ~81 ~42 ~12 sandstone
fill ~65 ~41 ~15 ~65 ~43 ~15 stone
fill ~97 ~41 ~15 ~97 ~42 ~15 stone
fill ~65 ~41 ~16 ~66 ~42 ~17 sandstone
fill ~96 ~41 ~16 ~97 ~43 ~16 sandstone
fill ~64 ~41 ~17 ~66 ~42 ~17 sandstone
fill ~68 ~41 ~18 ~68 ~42 ~18 sandstone
fill ~94 ~41 ~18 ~94 ~42 ~18 sandstone
fill ~96 ~41 ~19 ~97 ~42 ~20 sandstone
fill ~98 ~41 ~19 ~98 ~43 ~19 sandstone
fill ~65 ~41 ~20 ~66 ~43 ~20 sandstone
fill ~65 ~41 ~21 ~65 ~42 ~21 stone
fill ~97 ~41 ~21 ~97 ~43 ~21 stone
fill ~81 ~41 ~25 ~81 ~48 ~26 stone
fill ~80 ~41 ~26 ~81 ~49 ~26 stone
fill ~80 ~41 ~28 ~82 ~50 ~50 stone
fill ~78 ~41 ~30 ~84 ~50 ~33 stone
fill ~77 ~41 ~31 ~85 ~50 ~31 stone
fill ~79 ~41 ~34 ~83 ~52 ~34 stone
fill ~79 ~41 ~37 ~82 ~52 ~48 stone
fill ~83 ~41 ~37 ~83 ~52 ~38 stone
fill ~78 ~41 ~39 ~82 ~51 ~46 stone
fill ~77 ~41 ~40 ~83 ~51 ~46 stone
fill ~84 ~41 ~40 ~84 ~52 ~41 stone
fill ~76 ~41 ~42 ~83 ~51 ~44 stone
fill ~85 ~41 ~42 ~85 ~51 ~46 stone
fill ~84 ~41 ~47 ~84 ~52 ~47 stone
fill ~83 ~41 ~48 ~83 ~52 ~49 stone
fill ~84 ~41 ~49 ~84 ~52 ~49 stone
fill ~82 ~41 ~51 ~82 ~52 ~51 stone
fill ~102 ~41 ~52 ~102 ~47 ~54 stone
fill ~104 ~41 ~52 ~104 ~44 ~52 end_stone
fill ~105 ~41 ~52 ~106 ~41 ~54 sandstone
fill ~107 ~41 ~52 ~107 ~42 ~52 stone
fill ~56 ~41 ~53 ~56 ~41 ~58 sandstone
fill ~57 ~41 ~53 ~59 ~41 ~53 end_stone
fill ~80 ~41 ~53 ~80 ~52 ~62 stone
fill ~100 ~41 ~53 ~103 ~48 ~54 stone
fill ~104 ~41 ~53 ~107 ~41 ~53 sandstone
setblock ~108 ~41 ~53 stone
setblock ~53 ~41 ~54 stone
setblock ~54 ~41 ~54 end_stone
fill ~55 ~41 ~54 ~56 ~41 ~56 sandstone
fill ~58 ~41 ~54 ~58 ~42 ~56 end_stone
fill ~81 ~41 ~54 ~81 ~52 ~62 stone
fill ~107 ~41 ~54 ~107 ~41 ~56 sandstone
setblock ~108 ~41 ~54 end_stone
fill ~52 ~41 ~55 ~52 ~42 ~55 stone
fill ~53 ~41 ~55 ~56 ~41 ~56 sandstone
fill ~57 ~41 ~55 ~58 ~42 ~56 end_stone
fill ~102 ~41 ~55 ~102 ~41 ~57 sandstone
setblock ~103 ~41 ~55 sandstone
fill ~104 ~41 ~55 ~105 ~41 ~55 end_stone
fill ~106 ~41 ~55 ~107 ~42 ~56 sandstone
fill ~108 ~41 ~55 ~108 ~44 ~55 sandstone
fill ~52 ~41 ~56 ~54 ~41 ~57 sandstone
fill ~83 ~41 ~56 ~83 ~52 ~60 stone
setblock ~100 ~41 ~56 end_stone
fill ~101 ~41 ~56 ~102 ~41 ~57 sandstone
setblock ~103 ~41 ~56 end_stone
fill ~104 ~41 ~56 ~109 ~41 ~56 sandstone
fill ~55 ~41 ~57 ~55 ~41 ~58 end_stone
fill ~57 ~41 ~57 ~57 ~41 ~62 sandstone
setblock ~58 ~41 ~57 sandstone
fill ~60 ~41 ~57 ~60 ~48 ~57 stone
fill ~75 ~41 ~57 ~75 ~50 ~57 stone
fill ~84 ~41 ~57 ~84 ~52 ~60 stone
fill ~100 ~41 ~57 ~105 ~41 ~57 sandstone
fill ~107 ~41 ~57 ~107 ~44 ~57 end_stone
fill ~108 ~41 ~57 ~108 ~45 ~57 sandstone
fill ~109 ~41 ~57 ~109 ~41 ~59 end_stone
fill ~52 ~41 ~58 ~52 ~44 ~58 end_stone
setblock ~53 ~41 ~58 sandstone
fill ~58 ~41 ~58 ~58 ~41 ~61 end_stone
setblock ~61 ~41 ~58 stone
fill ~101 ~41 ~58 ~104 ~41 ~58 end_stone
setblock ~105 ~41 ~58 sandstone
fill ~106 ~41 ~58 ~108 ~42 ~58 end_stone
fill ~54 ~41 ~59 ~54 ~48 ~62 stone
fill ~55 ~41 ~59 ~55 ~41 ~62 sandstone
setblock ~56 ~41 ~59 end_stone
fill ~60 ~41 ~59 ~60 ~41 ~60 sandstone
fill ~85 ~41 ~59 ~85 ~52 ~59 stone
fill ~102 ~41 ~59 ~103 ~41 ~60 sandstone
setblock ~105 ~41 ~59 end_stone
fill ~52 ~41 ~60 ~54 ~47 ~60 stone
fill ~59 ~41 ~60 ~60 ~41 ~60 sandstone
fill ~105 ~41 ~60 ~105 ~48 ~60 stone
fill ~56 ~41 ~61 ~57 ~41 ~61 sandstone
fill ~77 ~41 ~61 ~82 ~52 ~61 stone
setblock ~104 ~41 ~61 stone
fill ~53 ~41 ~62 ~54 ~48 ~62 stone
setblock ~56 ~41 ~62 end_stone
fill ~79 ~41 ~62 ~81 ~52 ~62 stone
fill ~19 ~41 ~64 ~19 ~42 ~66 sandstone
fill ~145 ~41 ~64 ~145 ~42 ~66 sandstone
fill ~15 ~41 ~65 ~15 ~42 ~65 stone
fill ~16 ~41 ~65 ~16 ~43 ~66 sandstone
fill ~20 ~41 ~65 ~20 ~43 ~66 sandstone
fill ~21 ~41 ~65 ~21 ~43 ~65 stone
fill ~141 ~41 ~65 ~141 ~42 ~65 stone
fill ~142 ~41 ~65 ~142 ~43 ~66 sandstone
fill ~146 ~41 ~65 ~146 ~43 ~66 sandstone
fill ~147 ~41 ~65 ~147 ~43 ~65 stone
fill ~77 ~41 ~67 ~79 ~52 ~75 stone
fill ~18 ~41 ~68 ~18 ~42 ~68 sandstone
fill ~80 ~41 ~68 ~81 ~43 ~95 stone
fill ~144 ~41 ~68 ~144 ~42 ~68 sandstone
fill ~84 ~41 ~69 ~84 ~43 ~94 stone
fill ~87 ~41 ~69 ~87 ~50 ~83 stone
fill ~88 ~41 ~69 ~88 ~41 ~92 stone
fill ~89 ~41 ~70 ~89 ~50 ~92 stone
fill ~90 ~41 ~71 ~90 ~51 ~91 stone
fill ~72 ~41 ~72 ~90 ~43 ~92 stone
fill ~92 ~41 ~72 ~92 ~43 ~89 stone
fill ~70 ~41 ~74 ~92 ~41 ~89 stone
fill ~94 ~41 ~75 ~94 ~52 ~83 stone
fill ~105 ~41 ~75 ~105 ~50 ~75 stone
fill ~69 ~41 ~76 ~93 ~43 ~86 stone
fill ~95 ~41 ~76 ~95 ~44 ~82 stone
fill ~118 ~41 ~76 ~121 ~51 ~83 stone
fill ~42 ~41 ~77 ~46 ~51 ~77 stone
fill ~59 ~41 ~77 ~59 ~52 ~86 stone
fill ~68 ~41 ~77 ~93 ~43 ~85 stone
fill ~101 ~41 ~77 ~106 ~52 ~82 stone
fill ~116 ~41 ~77 ~122 ~51 ~83 stone
fill ~131 ~41 ~77 ~131 ~50 ~85 stone
fill ~9 ~41 ~78 ~9 ~43 ~78 stone
fill ~40 ~41 ~78 ~41 ~52 ~84 stone
fill ~47 ~41 ~78 ~47 ~52 ~83 stone
fill ~49 ~41 ~78 ~49 ~52 ~82 stone
fill ~57 ~41 ~78 ~60 ~52 ~85 stone
fill ~67 ~41 ~78 ~93 ~43 ~84 stone
fill ~123 ~41 ~78 ~123 ~52 ~82 stone
fill ~129 ~41 ~78 ~132 ~50 ~84 stone
fill ~153 ~41 ~78 ~153 ~42 ~78 stone
fill ~9 ~41 ~79 ~10 ~42 ~80 sandstone
fill ~37 ~41 ~79 ~37 ~52 ~83 stone
fill ~48 ~41 ~79 ~49 ~52 ~82 stone
fill ~56 ~41 ~79 ~60 ~52 ~85 stone
fill ~66 ~41 ~79 ~95 ~43 ~82 stone
fill ~100 ~41 ~79 ~108 ~52 ~81 stone
fill ~114 ~41 ~79 ~125 ~52 ~82 stone
fill ~128 ~41 ~79 ~133 ~50 ~83 stone
fill ~152 ~41 ~79 ~153 ~43 ~79 sandstone
fill ~8 ~41 ~80 ~10 ~42 ~80 sandstone
fill ~36 ~41 ~80 ~50 ~52 ~82 stone
fill ~51 ~41 ~80 ~51 ~52 ~80 stone
fill ~61 ~41 ~80 ~61 ~52 ~85 stone
fill ~65 ~41 ~80 ~96 ~43 ~81 stone
fill ~109 ~41 ~80 ~109 ~52 ~80 stone
fill ~112 ~41 ~80 ~134 ~50 ~82 stone
fill ~136 ~41 ~80 ~136 ~49 ~81 stone
fill ~12 ~41 ~81 ~12 ~42 ~81 sandstone
fill ~25 ~41 ~81 ~26 ~48 ~81 stone
fill ~54 ~41 ~81 ~62 ~52 ~83 stone
fill ~137 ~41 ~81 ~137 ~48 ~81 stone
fill ~150 ~41 ~81 ~150 ~42 ~81 sandstone
fill ~26 ~41 ~82 ~26 ~49 ~82 stone
fill ~28 ~41 ~82 ~50 ~50 ~82 stone
fill ~53 ~41 ~82 ~62 ~52 ~82 stone
fill ~111 ~41 ~82 ~134 ~50 ~82 stone
fill ~152 ~41 ~82 ~153 ~42 ~83 sandstone
fill ~154 ~41 ~82 ~154 ~43 ~82 sandstone
fill ~9 ~41 ~83 ~10 ~43 ~83 sandstone
fill ~34 ~41 ~83 ~34 ~52 ~83 stone
fill ~38 ~41 ~83 ~48 ~52 ~83 stone
fill ~106 ~41 ~83 ~106 ~52 ~83 stone
fill ~113 ~41 ~83 ~122 ~52 ~83 stone
fill ~125 ~41 ~83 ~125 ~52 ~83 stone
fill ~9 ~41 ~84 ~9 ~42 ~84 stone
fill ~30 ~41 ~84 ~33 ~50 ~84 stone
fill ~39 ~41 ~84 ~46 ~51 ~84 stone
fill ~102 ~41 ~84 ~105 ~52 ~84 stone
fill ~113 ~41 ~84 ~113 ~52 ~84 stone
fill ~115 ~41 ~84 ~117 ~52 ~84 stone
fill ~122 ~41 ~84 ~122 ~52 ~84 stone
fill ~153 ~41 ~84 ~153 ~43 ~84 stone
fill ~31 ~41 ~85 ~31 ~50 ~85 stone
fill ~40 ~41 ~85 ~40 ~51 ~85 stone
fill ~42 ~41 ~85 ~44 ~51 ~85 stone
fill ~46 ~41 ~85 ~46 ~51 ~85 stone
fill ~103 ~41 ~85 ~103 ~52 ~85 stone
fill ~116 ~41 ~85 ~120 ~51 ~85 stone
fill ~43 ~41 ~86 ~43 ~51 ~86 stone
fill ~57 ~41 ~87 ~57 ~50 ~87 stone
setblock ~92 ~41 ~90 stone
fill ~71 ~41 ~91 ~91 ~43 ~91 stone
fill ~87 ~41 ~93 ~87 ~54 ~93 stone
fill ~18 ~41 ~94 ~18 ~42 ~94 sandstone
fill ~73 ~41 ~94 ~85 ~43 ~94 stone
fill ~144 ~41 ~94 ~144 ~42 ~94 sandstone
fill ~74 ~41 ~95 ~83 ~43 ~95 stone
fill ~17 ~41 ~96 ~17 ~42 ~98 sandstone
fill ~20 ~41 ~96 ~20 ~43 ~97 sandstone
fill ~75 ~41 ~96 ~80 ~43 ~96 stone
fill ~143 ~41 ~96 ~143 ~42 ~98 sandstone
fill ~146 ~41 ~96 ~146 ~43 ~97 sandstone
fill ~15 ~41 ~97 ~15 ~43 ~97 stone
fill ~16 ~41 ~97 ~17 ~42 ~97 sandstone
fill ~21 ~41 ~97 ~21 ~42 ~97 stone
fill ~141 ~41 ~97 ~141 ~43 ~97 stone
fill ~142 ~41 ~97 ~143 ~42 ~97 sandstone
fill ~147 ~41 ~97 ~147 ~42 ~97 stone
fill ~81 ~41 ~100 ~83 ~52 ~108 stone
fill ~105 ~41 ~100 ~105 ~41 ~105 sandstone
setblock ~106 ~41 ~100 end_stone
fill ~109 ~41 ~100 ~109 ~48 ~103 stone
fill ~58 ~41 ~101 ~58 ~41 ~102 stone
fill ~80 ~41 ~101 ~85 ~52 ~106 stone
fill ~104 ~41 ~101 ~104 ~41 ~104 end_stone
fill ~106 ~41 ~101 ~107 ~41 ~102 sandstone
fill ~108 ~41 ~101 ~109 ~48 ~103 stone
fill ~57 ~41 ~102 ~57 ~48 ~102 stone
fill ~59 ~41 ~102 ~60 ~41 ~103 sandstone
fill ~78 ~41 ~102 ~85 ~52 ~105 stone
fill ~102 ~41 ~102 ~103 ~41 ~103 sandstone
fill ~110 ~41 ~102 ~110 ~47 ~102 stone
fill ~53 ~41 ~103 ~53 ~41 ~105 end_stone
setblock ~57 ~41 ~103 end_stone
fill ~77 ~41 ~103 ~86 ~52 ~103 stone
setblock ~106 ~41 ~103 end_stone
setblock ~107 ~41 ~103 sandstone
fill ~54 ~41 ~104 ~56 ~42 ~104 end_stone
fill ~57 ~41 ~104 ~57 ~41 ~106 sandstone
fill ~60 ~41 ~104 ~61 ~41 ~104 end_stone
fill ~101 ~41 ~104 ~102 ~41 ~104 stone
fill ~106 ~41 ~104 ~106 ~41 ~109 sandstone
fill ~107 ~41 ~104 ~107 ~41 ~105 end_stone
fill ~109 ~41 ~104 ~109 ~41 ~107 sandstone
fill ~110 ~41 ~104 ~110 ~44 ~104 end_stone
fill ~55 ~41 ~105 ~56 ~42 ~105 end_stone
fill ~58 ~41 ~105 ~62 ~41 ~105 sandstone
fill ~87 ~41 ~105 ~87 ~50 ~105 stone
fill ~102 ~41 ~105 ~102 ~48 ~105 stone
setblock ~103 ~41 ~105 end_stone
fill ~104 ~41 ~105 ~106 ~41 ~105 sandstone
fill ~110 ~41 ~105 ~110 ~45 ~105 sandstone
fill ~53 ~41 ~106 ~58 ~41 ~106 sandstone
setblock ~59 ~41 ~106 end_stone
fill ~61 ~41 ~106 ~61 ~41 ~107 sandstone
setblock ~62 ~41 ~106 end_stone
fill ~79 ~41 ~106 ~85 ~52 ~106 stone
setblock ~103 ~41 ~106 sandstone
fill ~104 ~41 ~106 ~105 ~42 ~107 end_stone
fill ~107 ~41 ~106 ~107 ~42 ~108 sandstone
setblock ~110 ~41 ~106 sandstone
fill ~54 ~41 ~107 ~56 ~42 ~107 sandstone
fill ~57 ~41 ~107 ~58 ~41 ~107 end_stone
fill ~59 ~41 ~107 ~62 ~41 ~107 sandstone
fill ~108 ~41 ~107 ~109 ~41 ~107 sandstone
fill ~110 ~41 ~107 ~110 ~42 ~107 stone
setblock ~54 ~41 ~108 end_stone
fill ~55 ~41 ~108 ~57 ~41 ~109 sandstone
fill ~59 ~41 ~108 ~62 ~48 ~109 stone
fill ~104 ~41 ~108 ~104 ~42 ~108 end_stone
fill ~105 ~41 ~108 ~105 ~45 ~108 sandstone
setblock ~108 ~41 ~108 end_stone
setblock ~109 ~41 ~108 stone
setblock ~54 ~41 ~109 stone
setblock ~58 ~41 ~109 sandstone
fill ~82 ~41 ~109 ~82 ~52 ~109 stone
fill ~103 ~41 ~109 ~105 ~41 ~109 end_stone
fill ~55 ~41 ~110 ~55 ~42 ~110 stone
fill ~56 ~41 ~110 ~57 ~41 ~110 sandstone
fill ~58 ~41 ~110 ~58 ~44 ~110 end_stone
fill ~60 ~41 ~110 ~60 ~47 ~110 stone
fill ~80 ~41 ~111 ~80 ~52 ~130 stone
fill ~81 ~41 ~112 ~82 ~50 ~134 stone
fill ~78 ~41 ~113 ~82 ~52 ~113 stone
fill ~79 ~41 ~114 ~83 ~52 ~122 stone
fill ~78 ~41 ~115 ~83 ~52 ~117 stone
fill ~77 ~41 ~116 ~85 ~51 ~118 stone
fill ~86 ~41 ~118 ~86 ~51 ~120 stone
fill ~77 ~41 ~120 ~77 ~51 ~120 stone
fill ~85 ~41 ~120 ~85 ~51 ~122 stone
fill ~78 ~41 ~122 ~85 ~51 ~122 stone
fill ~83 ~41 ~123 ~83 ~52 ~125 stone
fill ~84 ~41 ~123 ~84 ~52 ~123 stone
fill ~79 ~41 ~125 ~83 ~52 ~125 stone
fill ~83 ~41 ~128 ~83 ~50 ~133 stone
fill ~84 ~41 ~129 ~84 ~50 ~132 stone
fill ~85 ~41 ~131 ~85 ~50 ~131 stone
fill ~82 ~41 ~136 ~82 ~49 ~136 stone
fill ~81 ~41 ~137 ~81 ~48 ~137 stone
fill ~65 ~41 ~141 ~65 ~43 ~141 stone
fill ~97 ~41 ~141 ~97 ~42 ~141 stone
fill ~65 ~41 ~142 ~66 ~42 ~143 sandstone
fill ~96 ~41 ~142 ~97 ~43 ~142 sandstone
fill ~64 ~41 ~143 ~66 ~42 ~143 sandstone
fill ~68 ~41 ~144 ~68 ~42 ~144 sandstone
fill ~94 ~41 ~144 ~94 ~42 ~144 sandstone
fill ~96 ~41 ~145 ~97 ~42 ~146 sandstone
fill ~98 ~41 ~145 ~98 ~43 ~145 sandstone
fill ~65 ~41 ~146 ~66 ~43 ~146 sandstone
fill ~65 ~41 ~147 ~65 ~42 ~147 stone
fill ~97 ~41 ~147 ~97 ~43 ~147 stone
fill ~81 ~41 ~150 ~81 ~42 ~150 sandstone
fill ~80 ~41 ~152 ~80 ~42 ~154 sandstone
fill ~83 ~41 ~152 ~83 ~43 ~153 sandstone
fill ~78 ~41 ~153 ~78 ~43 ~153 stone
fill ~79 ~41 ~153 ~80 ~42 ~153 sandstone
fill ~84 ~41 ~153 ~84 ~42 ~153 stone
fill ~81 ~42 ~6 ~81 ~42 ~10 quartz_block
fill ~78 ~42 ~8 ~78 ~44 ~8 sandstone
fill ~84 ~42 ~8 ~84 ~46 ~8 sandstone
fill ~64 ~42 ~15 ~64 ~46 ~15 sandstone
fill ~98 ~42 ~15 ~98 ~44 ~15 sandstone
fill ~62 ~42 ~18 ~66 ~42 ~18 quartz_block
fill ~96 ~42 ~18 ~99 ~42 ~18 quartz_block
fill ~64 ~42 ~21 ~64 ~44 ~21 sandstone
fill ~98 ~42 ~21 ~98 ~46 ~21 sandstone
fill ~84 ~42 ~26 ~84 ~48 ~26 stone
fill ~81 ~42 ~27 ~81 ~49 ~51 stone
fill ~79 ~42 ~28 ~83 ~49 ~50 stone
fill ~78 ~42 ~29 ~84 ~49 ~33 stone
fill ~85 ~42 ~30 ~85 ~49 ~32 stone
fill ~78 ~42 ~37 ~83 ~51 ~48 stone
fill ~84 ~42 ~37 ~84 ~51 ~38 stone
fill ~77 ~42 ~39 ~83 ~51 ~47 stone
fill ~76 ~42 ~40 ~83 ~51 ~46 stone
fill ~75 ~42 ~42 ~83 ~50 ~44 stone
fill ~84 ~42 ~42 ~85 ~45 ~48 stone
fill ~86 ~42 ~43 ~86 ~51 ~46 stone
fill ~84 ~42 ~50 ~85 ~52 ~50 stone
fill ~80 ~42 ~51 ~80 ~52 ~62 stone
fill ~83 ~42 ~51 ~83 ~52 ~61 stone
fill ~84 ~42 ~51 ~84 ~52 ~51 stone
fill ~104 ~42 ~51 ~104 ~43 ~51 sandstone
fill ~105 ~42 ~51 ~105 ~43 ~51 end_stone
setblock ~57 ~42 ~52 end_stone
fill ~58 ~42 ~52 ~59 ~43 ~52 sandstone
fill ~79 ~42 ~52 ~80 ~52 ~62 stone
fill ~82 ~42 ~52 ~83 ~52 ~61 stone
fill ~100 ~42 ~52 ~102 ~45 ~54 stone
fill ~105 ~42 ~52 ~105 ~45 ~52 sandstone
fill ~106 ~42 ~52 ~106 ~43 ~53 end_stone
fill ~56 ~42 ~53 ~56 ~43 ~54 end_stone
fill ~57 ~42 ~53 ~58 ~42 ~53 sandstone
fill ~59 ~42 ~53 ~59 ~42 ~54 end_stone
fill ~60 ~42 ~53 ~60 ~43 ~53 sandstone
fill ~81 ~42 ~53 ~83 ~52 ~61 stone
fill ~99 ~42 ~53 ~103 ~42 ~55 stone
fill ~104 ~42 ~53 ~107 ~42 ~53 end_stone
fill ~108 ~42 ~53 ~108 ~42 ~55 sandstone
fill ~53 ~42 ~54 ~55 ~42 ~54 sandstone
fill ~60 ~42 ~54 ~60 ~42 ~55 stone
fill ~78 ~42 ~54 ~83 ~52 ~61 stone
fill ~98 ~42 ~54 ~98 ~46 ~54 sandstone
fill ~107 ~42 ~54 ~107 ~43 ~54 end_stone
fill ~53 ~42 ~55 ~53 ~42 ~58 end_stone
fill ~54 ~42 ~55 ~54 ~43 ~55 end_stone
fill ~56 ~42 ~55 ~56 ~42 ~56 sandstone
setblock ~98 ~42 ~55 end_stone
fill ~104 ~42 ~55 ~105 ~47 ~58 stone
fill ~52 ~42 ~56 ~53 ~43 ~56 end_stone
fill ~59 ~42 ~56 ~59 ~47 ~57 stone
fill ~61 ~42 ~56 ~61 ~42 ~57 stone
fill ~84 ~42 ~56 ~84 ~52 ~60 stone
fill ~99 ~42 ~56 ~99 ~43 ~56 end_stone
setblock ~100 ~42 ~56 stone
fill ~101 ~42 ~56 ~101 ~42 ~57 end_stone
setblock ~103 ~42 ~56 sandstone
fill ~108 ~42 ~56 ~109 ~43 ~56 end_stone
fill ~51 ~42 ~57 ~51 ~43 ~57 end_stone
fill ~52 ~42 ~57 ~52 ~45 ~57 sandstone
fill ~55 ~42 ~57 ~60 ~48 ~57 stone
fill ~76 ~42 ~57 ~84 ~52 ~59 stone
fill ~100 ~42 ~57 ~101 ~42 ~57 end_stone
fill ~102 ~42 ~57 ~102 ~43 ~57 sandstone
fill ~103 ~42 ~57 ~103 ~42 ~61 end_stone
fill ~109 ~42 ~57 ~109 ~42 ~58 sandstone
setblock ~110 ~42 ~57 end_stone
fill ~51 ~42 ~58 ~51 ~43 ~58 sandstone
fill ~55 ~42 ~58 ~55 ~48 ~61 stone
fill ~56 ~42 ~58 ~58 ~47 ~58 stone
fill ~60 ~42 ~58 ~61 ~42 ~58 sandstone
fill ~75 ~42 ~58 ~85 ~51 ~58 stone
fill ~101 ~42 ~58 ~102 ~42 ~58 sandstone
fill ~110 ~42 ~58 ~110 ~43 ~59 sandstone
fill ~56 ~42 ~59 ~56 ~42 ~60 sandstone
fill ~57 ~42 ~59 ~61 ~42 ~59 end_stone
fill ~86 ~42 ~59 ~86 ~52 ~59 stone
fill ~101 ~42 ~59 ~103 ~42 ~59 end_stone
fill ~104 ~42 ~59 ~104 ~44 ~59 sandstone
fill ~105 ~42 ~59 ~105 ~48 ~60 stone
fill ~106 ~42 ~59 ~106 ~47 ~59 stone
fill ~108 ~42 ~59 ~109 ~42 ~59 end_stone
fill ~57 ~42 ~60 ~58 ~42 ~60 sandstone
fill ~59 ~42 ~60 ~60 ~42 ~60 end_stone
fill ~85 ~42 ~60 ~85 ~52 ~60 stone
fill ~102 ~42 ~60 ~103 ~42 ~60 end_stone
fill ~104 ~42 ~60 ~104 ~42 ~61 sandstone
fill ~107 ~42 ~60 ~108 ~42 ~60 stone
fill ~109 ~42 ~60 ~109 ~43 ~60 sandstone
fill ~52 ~42 ~61 ~54 ~45 ~62 stone
fill ~56 ~42 ~61 ~57 ~42 ~61 end_stone
setblock ~58 ~42 ~61 sandstone
fill ~59 ~42 ~61 ~59 ~43 ~61 end_stone
fill ~105 ~42 ~61 ~106 ~42 ~61 stone
fill ~55 ~42 ~62 ~56 ~42 ~62 stone
setblock ~57 ~42 ~62 end_stone
fill ~144 ~42 ~62 ~144 ~42 ~66 quartz_block
fill ~18 ~42 ~63 ~18 ~42 ~66 quartz_block
fill ~53 ~42 ~63 ~55 ~42 ~63 stone
fill ~56 ~42 ~63 ~56 ~43 ~63 end_stone
fill ~80 ~42 ~63 ~80 ~45 ~63 stone
fill ~15 ~42 ~64 ~15 ~44 ~64 sandstone
fill ~21 ~42 ~64 ~21 ~46 ~64 sandstone
fill ~54 ~42 ~64 ~54 ~46 ~64 sandstone
setblock ~55 ~42 ~64 end_stone
fill ~141 ~42 ~64 ~141 ~44 ~64 sandstone
fill ~147 ~42 ~64 ~147 ~46 ~64 sandstone
fill ~78 ~42 ~66 ~79 ~43 ~96 stone
fill ~80 ~42 ~67 ~80 ~52 ~72 stone
fill ~75 ~42 ~68 ~83 ~43 ~95 stone
fill ~74 ~42 ~69 ~84 ~43 ~94 stone
fill ~86 ~42 ~69 ~87 ~50 ~77 stone
fill ~88 ~42 ~70 ~89 ~50 ~92 stone
fill ~73 ~42 ~71 ~90 ~43 ~92 stone
fill ~93 ~42 ~73 ~93 ~44 ~87 stone
fill ~71 ~42 ~74 ~90 ~43 ~92 stone
fill ~94 ~42 ~74 ~94 ~43 ~84 stone
fill ~69 ~42 ~75 ~74 ~50 ~86 stone
fill ~95 ~42 ~75 ~95 ~43 ~83 stone
fill ~104 ~42 ~75 ~105 ~50 ~84 stone
fill ~118 ~42 ~75 ~120 ~50 ~83 stone
fill ~43 ~42 ~76 ~46 ~45 ~86 stone
fill ~59 ~42 ~76 ~59 ~52 ~86 stone
fill ~67 ~42 ~76 ~74 ~50 ~85 stone
fill ~96 ~42 ~76 ~96 ~43 ~82 stone
fill ~116 ~42 ~76 ~122 ~51 ~83 stone
fill ~30 ~42 ~77 ~31 ~49 ~84 stone
fill ~47 ~42 ~77 ~48 ~51 ~84 stone
fill ~50 ~42 ~77 ~50 ~52 ~83 stone
fill ~58 ~42 ~77 ~60 ~52 ~85 stone
fill ~66 ~42 ~77 ~94 ~43 ~84 stone
fill ~115 ~42 ~77 ~123 ~51 ~83 stone
fill ~8 ~42 ~78 ~8 ~46 ~78 sandstone
fill ~26 ~42 ~78 ~26 ~48 ~78 stone
fill ~29 ~42 ~78 ~33 ~49 ~84 stone
fill ~37 ~42 ~78 ~37 ~51 ~84 stone
fill ~42 ~42 ~78 ~51 ~45 ~82 stone
fill ~56 ~42 ~78 ~60 ~52 ~85 stone
fill ~65 ~42 ~78 ~96 ~43 ~82 stone
fill ~97 ~42 ~78 ~97 ~43 ~78 stone
fill ~108 ~42 ~78 ~108 ~52 ~83 stone
fill ~114 ~42 ~78 ~125 ~51 ~83 stone
fill ~133 ~42 ~78 ~133 ~49 ~84 stone
fill ~154 ~42 ~78 ~154 ~44 ~78 sandstone
fill ~28 ~42 ~79 ~50 ~49 ~83 stone
fill ~52 ~42 ~79 ~61 ~52 ~80 stone
fill ~109 ~42 ~79 ~109 ~52 ~83 stone
fill ~110 ~42 ~79 ~110 ~52 ~80 stone
fill ~112 ~42 ~79 ~128 ~52 ~83 stone
fill ~134 ~42 ~79 ~134 ~49 ~83 stone
fill ~98 ~42 ~80 ~134 ~43 ~80 stone
fill ~6 ~42 ~81 ~10 ~42 ~81 quartz_block
fill ~27 ~42 ~81 ~51 ~49 ~81 stone
fill ~53 ~42 ~81 ~62 ~52 ~83 stone
fill ~64 ~42 ~81 ~96 ~44 ~81 stone
fill ~111 ~42 ~81 ~130 ~52 ~82 stone
fill ~135 ~42 ~81 ~137 ~48 ~81 stone
fill ~152 ~42 ~81 ~156 ~42 ~81 quartz_block
fill ~52 ~42 ~82 ~62 ~52 ~83 stone
fill ~63 ~42 ~82 ~63 ~45 ~82 stone
fill ~110 ~42 ~82 ~128 ~52 ~83 stone
fill ~101 ~42 ~83 ~128 ~52 ~83 stone
fill ~8 ~42 ~84 ~8 ~44 ~84 sandstone
fill ~38 ~42 ~84 ~48 ~51 ~84 stone
fill ~54 ~42 ~84 ~54 ~52 ~84 stone
fill ~106 ~42 ~84 ~106 ~52 ~84 stone
fill ~111 ~42 ~84 ~117 ~52 ~84 stone
fill ~120 ~42 ~84 ~122 ~51 ~84 stone
fill ~125 ~42 ~84 ~125 ~51 ~84 stone
fill ~136 ~42 ~84 ~136 ~48 ~84 stone
fill ~154 ~42 ~84 ~154 ~46 ~84 sandstone
fill ~39 ~42 ~85 ~47 ~51 ~85 stone
fill ~102 ~42 ~85 ~104 ~52 ~85 stone
fill ~112 ~42 ~85 ~112 ~52 ~85 stone
fill ~114 ~42 ~85 ~120 ~51 ~85 stone
fill ~132 ~42 ~85 ~132 ~49 ~85 stone
fill ~40 ~42 ~86 ~46 ~51 ~86 stone
fill ~57 ~42 ~86 ~58 ~50 ~87 stone
fill ~68 ~42 ~86 ~93 ~43 ~86 stone
fill ~103 ~42 ~86 ~103 ~52 ~86 stone
fill ~116 ~42 ~86 ~119 ~51 ~86 stone
fill ~42 ~42 ~87 ~44 ~50 ~87 stone
fill ~70 ~42 ~87 ~91 ~43 ~91 stone
fill ~69 ~42 ~88 ~92 ~44 ~89 stone
fill ~93 ~42 ~89 ~93 ~43 ~89 stone
fill ~72 ~42 ~93 ~88 ~43 ~93 stone
fill ~86 ~42 ~94 ~86 ~53 ~94 stone
fill ~18 ~42 ~96 ~18 ~42 ~100 quartz_block
fill ~74 ~42 ~96 ~81 ~43 ~96 stone
fill ~144 ~42 ~96 ~144 ~42 ~99 quartz_block
setblock ~78 ~42 ~97 stone
fill ~15 ~42 ~98 ~15 ~46 ~98 sandstone
fill ~21 ~42 ~98 ~21 ~44 ~98 sandstone
setblock ~107 ~42 ~98 end_stone
fill ~108 ~42 ~98 ~108 ~46 ~98 sandstone
fill ~141 ~42 ~98 ~141 ~46 ~98 sandstone
fill ~147 ~42 ~98 ~147 ~44 ~98 sandstone
fill ~82 ~42 ~99 ~82 ~45 ~134 stone
fill ~106 ~42 ~99 ~106 ~43 ~99 end_stone
fill ~107 ~42 ~99 ~109 ~42 ~103 stone
fill ~105 ~42 ~100 ~105 ~42 ~101 end_stone
fill ~106 ~42 ~100 ~110 ~42 ~100 stone
fill ~56 ~42 ~101 ~57 ~42 ~101 stone
fill ~58 ~42 ~101 ~58 ~42 ~103 sandstone
fill ~59 ~42 ~101 ~59 ~42 ~105 end_stone
fill ~79 ~42 ~101 ~80 ~52 ~128 stone
fill ~103 ~42 ~101 ~103 ~42 ~103 end_stone
fill ~104 ~42 ~101 ~104 ~42 ~102 sandstone
setblock ~106 ~42 ~101 end_stone
fill ~110 ~42 ~101 ~110 ~45 ~102 stone
fill ~53 ~42 ~102 ~53 ~43 ~102 sandstone
fill ~54 ~42 ~102 ~55 ~42 ~102 stone
fill ~60 ~42 ~102 ~60 ~42 ~103 end_stone
fill ~77 ~42 ~102 ~85 ~52 ~104 stone
fill ~102 ~42 ~102 ~103 ~42 ~103 end_stone
fill ~105 ~42 ~102 ~106 ~42 ~102 sandstone
fill ~52 ~42 ~103 ~52 ~43 ~104 sandstone
fill ~53 ~42 ~103 ~54 ~42 ~103 end_stone
fill ~56 ~42 ~103 ~57 ~47 ~103 stone
fill ~61 ~42 ~103 ~61 ~43 ~103 end_stone
fill ~76 ~42 ~103 ~86 ~52 ~103 stone
fill ~101 ~42 ~103 ~105 ~42 ~103 end_stone
setblock ~106 ~42 ~103 sandstone
fill ~53 ~42 ~104 ~53 ~42 ~105 sandstone
fill ~57 ~42 ~104 ~58 ~47 ~107 stone
fill ~60 ~42 ~104 ~60 ~42 ~106 sandstone
setblock ~61 ~42 ~104 sandstone
fill ~87 ~42 ~104 ~87 ~50 ~105 stone
fill ~101 ~42 ~104 ~103 ~42 ~104 sandstone
fill ~104 ~42 ~104 ~107 ~47 ~105 stone
fill ~109 ~42 ~104 ~109 ~42 ~107 end_stone
fill ~111 ~42 ~104 ~111 ~43 ~104 sandstone
setblock ~52 ~42 ~105 end_stone
fill ~61 ~42 ~105 ~62 ~42 ~105 end_stone
fill ~86 ~42 ~105 ~87 ~50 ~105 stone
fill ~101 ~42 ~105 ~107 ~42 ~105 stone
fill ~111 ~42 ~105 ~111 ~43 ~105 end_stone
fill ~53 ~42 ~106 ~54 ~43 ~106 end_stone
fill ~55 ~42 ~106 ~56 ~42 ~107 sandstone
fill ~59 ~42 ~106 ~60 ~42 ~106 sandstone
setblock ~61 ~42 ~106 end_stone
fill ~62 ~42 ~106 ~62 ~42 ~110 stone
fill ~63 ~42 ~106 ~63 ~43 ~106 end_stone
fill ~78 ~42 ~106 ~85 ~52 ~106 stone
setblock ~101 ~42 ~106 stone
fill ~103 ~42 ~106 ~103 ~47 ~106 stone
fill ~106 ~42 ~106 ~107 ~42 ~107 sandstone
fill ~110 ~42 ~106 ~110 ~43 ~106 end_stone
fill ~59 ~42 ~107 ~61 ~48 ~109 stone
fill ~63 ~42 ~107 ~63 ~42 ~109 stone
setblock ~64 ~42 ~107 end_stone
fill ~102 ~42 ~107 ~102 ~43 ~107 stone
fill ~108 ~42 ~107 ~109 ~42 ~107 end_stone
fill ~54 ~42 ~108 ~54 ~42 ~109 sandstone
fill ~55 ~42 ~108 ~55 ~43 ~108 end_stone
fill ~64 ~42 ~108 ~64 ~46 ~108 sandstone
fill ~84 ~42 ~108 ~84 ~52 ~108 stone
setblock ~102 ~42 ~108 stone
fill ~103 ~42 ~108 ~104 ~42 ~108 end_stone
fill ~106 ~42 ~108 ~106 ~43 ~109 end_stone
fill ~108 ~42 ~108 ~109 ~42 ~108 sandstone
fill ~55 ~42 ~109 ~58 ~42 ~109 end_stone
fill ~81 ~42 ~109 ~83 ~52 ~109 stone
fill ~102 ~42 ~109 ~102 ~43 ~109 sandstone
setblock ~103 ~42 ~109 end_stone
fill ~104 ~42 ~109 ~105 ~42 ~109 sandstone
fill ~56 ~42 ~110 ~56 ~43 ~110 end_stone
fill ~57 ~42 ~110 ~57 ~45 ~110 sandstone
fill ~61 ~42 ~110 ~62 ~45 ~110 stone
fill ~83 ~42 ~110 ~83 ~52 ~110 stone
fill ~103 ~42 ~110 ~104 ~43 ~110 sandstone
setblock ~105 ~42 ~110 end_stone
fill ~57 ~42 ~111 ~57 ~43 ~111 end_stone
fill ~58 ~42 ~111 ~58 ~43 ~111 sandstone
fill ~78 ~42 ~111 ~82 ~52 ~117 stone
fill ~77 ~42 ~112 ~83 ~52 ~112 stone
fill ~83 ~42 ~113 ~83 ~52 ~128 stone
fill ~77 ~42 ~114 ~84 ~45 ~120 stone
fill ~85 ~42 ~115 ~85 ~51 ~123 stone
fill ~76 ~42 ~116 ~86 ~51 ~118 stone
fill ~76 ~42 ~119 ~87 ~45 ~119 stone
fill ~87 ~42 ~120 ~87 ~50 ~120 stone
fill ~86 ~42 ~121 ~86 ~51 ~122 stone
fill ~84 ~42 ~124 ~84 ~51 ~125 stone
fill ~78 ~42 ~125 ~84 ~51 ~125 stone
fill ~77 ~42 ~132 ~84 ~49 ~132 stone
fill ~78 ~42 ~133 ~84 ~49 ~133 stone
fill ~79 ~42 ~134 ~83 ~49 ~134 stone
fill ~81 ~42 ~135 ~81 ~48 ~137 stone
fill ~78 ~42 ~136 ~78 ~48 ~136 stone
fill ~64 ~42 ~141 ~64 ~46 ~141 sandstone
fill ~98 ~42 ~141 ~98 ~44 ~141 sandstone
fill ~63 ~42 ~144 ~66 ~42 ~144 quartz_block
fill ~96 ~42 ~144 ~100 ~42 ~144 quartz_block
fill ~64 ~42 ~147 ~64 ~44 ~147 sandstone
fill ~98 ~42 ~147 ~98 ~46 ~147 sandstone
fill ~81 ~42 ~152 ~81 ~42 ~156 quartz_block
fill ~78 ~42 ~154 ~78 ~46 ~154 sandstone
fill ~84 ~42 ~154 ~84 ~44 ~154 sandstone
fill ~81 ~43 ~5 ~81 ~49 ~5 quartz_block
fill ~81 ~43 ~6 ~81 ~44 ~7 quartz_block
fill ~80 ~43 ~7 ~80 ~46 ~7 sandstone
fill ~82 ~43 ~7 ~82 ~45 ~7 sandstone
fill ~83 ~43 ~7 ~83 ~45 ~7 stone
fill ~79 ~43 ~8 ~84 ~43 ~8 sandstone
fill ~77 ~43 ~9 ~78 ~44 ~9 sandstone
fill ~80 ~43 ~9 ~82 ~43 ~9 stone
setblock ~78 ~43 ~10 stone
setblock ~80 ~43 ~10 sandstone
fill ~81 ~43 ~10 ~81 ~43 ~11 stone
fill ~82 ~43 ~10 ~83 ~43 ~10 sandstone
fill ~84 ~43 ~10 ~84 ~44 ~10 stone
fill ~79 ~43 ~11 ~81 ~43 ~11 stone
setblock ~82 ~43 ~11 sandstone
fill ~83 ~43 ~11 ~83 ~44 ~11 stone
setblock ~81 ~43 ~12 diamond_ore
fill ~81 ~43 ~13 ~81 ~45 ~13 stone
fill ~97 ~43 ~14 ~97 ~44 ~15 sandstone
fill ~66 ~43 ~15 ~66 ~44 ~15 stone
setblock ~96 ~43 ~15 stone
fill ~63 ~43 ~16 ~63 ~45 ~16 stone
fill ~64 ~43 ~16 ~64 ~43 ~21 sandstone
fill ~65 ~43 ~16 ~66 ~43 ~16 sandstone
fill ~67 ~43 ~16 ~67 ~44 ~16 stone
fill ~95 ~43 ~16 ~95 ~43 ~18 stone
fill ~98 ~43 ~16 ~98 ~43 ~21 sandstone
fill ~63 ~43 ~17 ~63 ~45 ~17 sandstone
fill ~65 ~43 ~17 ~65 ~43 ~19 stone
fill ~66 ~43 ~17 ~67 ~43 ~17 sandstone
setblock ~96 ~43 ~17 sandstone
fill ~97 ~43 ~17 ~97 ~43 ~19 stone
fill ~61 ~43 ~18 ~61 ~49 ~18 quartz_block
fill ~62 ~43 ~18 ~63 ~44 ~18 quartz_block
fill ~66 ~43 ~18 ~67 ~43 ~18 stone
setblock ~68 ~43 ~18 diamond_ore
fill ~69 ~43 ~18 ~69 ~45 ~18 stone
fill ~93 ~43 ~18 ~93 ~45 ~18 stone
setblock ~94 ~43 ~18 diamond_ore
fill ~96 ~43 ~18 ~97 ~43 ~18 stone
fill ~99 ~43 ~18 ~100 ~44 ~18 quartz_block
fill ~63 ~43 ~19 ~64 ~44 ~19 sandstone
fill ~66 ~43 ~19 ~66 ~43 ~20 sandstone
fill ~67 ~43 ~19 ~67 ~43 ~20 stone
fill ~95 ~43 ~19 ~96 ~43 ~19 sandstone
fill ~95 ~43 ~20 ~95 ~44 ~20 stone
fill ~97 ~43 ~20 ~98 ~43 ~20 sandstone
fill ~99 ~43 ~20 ~99 ~45 ~20 stone
fill ~65 ~43 ~21 ~65 ~44 ~22 sandstone
setblock ~66 ~43 ~21 stone
fill ~96 ~43 ~21 ~97 ~43 ~21 stone
fill ~81 ~43 ~24 ~81 ~48 ~62 stone
fill ~80 ~43 ~25 ~81 ~48 ~62 stone
fill ~82 ~43 ~26 ~82 ~49 ~61 stone
fill ~85 ~43 ~29 ~85 ~48 ~33 stone
fill ~77 ~43 ~30 ~85 ~49 ~31 stone
fill ~86 ~43 ~31 ~86 ~50 ~31 stone
fill ~77 ~43 ~33 ~85 ~50 ~33 stone
fill ~78 ~43 ~34 ~83 ~51 ~48 stone
fill ~84 ~43 ~34 ~84 ~51 ~42 stone
fill ~77 ~43 ~37 ~85 ~51 ~37 stone
fill ~75 ~43 ~41 ~83 ~48 ~46 stone
fill ~85 ~43 ~41 ~86 ~51 ~47 stone
fill ~87 ~43 ~44 ~87 ~51 ~44 stone
fill ~85 ~43 ~49 ~85 ~52 ~51 stone
fill ~104 ~43 ~50 ~104 ~44 ~50 end_stone
fill ~60 ~43 ~51 ~60 ~43 ~54 sandstone
fill ~79 ~43 ~51 ~81 ~52 ~62 stone
fill ~99 ~43 ~51 ~99 ~44 ~52 stone
fill ~103 ~43 ~51 ~103 ~45 ~51 end_stone
fill ~106 ~43 ~51 ~106 ~43 ~54 end_stone
fill ~56 ~43 ~52 ~62 ~43 ~52 sandstone
fill ~78 ~43 ~52 ~81 ~52 ~62 stone
fill ~84 ~43 ~52 ~84 ~52 ~54 stone
fill ~103 ~43 ~52 ~104 ~43 ~52 end_stone
fill ~107 ~43 ~52 ~107 ~44 ~53 sandstone
fill ~54 ~43 ~53 ~54 ~44 ~54 end_stone
fill ~55 ~43 ~53 ~55 ~43 ~54 sandstone
fill ~57 ~43 ~53 ~57 ~45 ~53 end_stone
setblock ~58 ~43 ~53 end_stone
fill ~59 ~43 ~53 ~60 ~43 ~54 sandstone
setblock ~61 ~43 ~53 end_stone
setblock ~62 ~43 ~53 sandstone
setblock ~98 ~43 ~53 end_stone
fill ~99 ~43 ~53 ~99 ~43 ~55 sandstone
fill ~104 ~43 ~53 ~104 ~43 ~58 stone
fill ~105 ~43 ~53 ~105 ~44 ~53 sandstone
setblock ~108 ~43 ~53 stone
setblock ~53 ~43 ~54 stone
fill ~58 ~43 ~54 ~61 ~43 ~54 sandstone
fill ~77 ~43 ~54 ~81 ~52 ~62 stone
fill ~97 ~43 ~54 ~97 ~45 ~55 end_stone
setblock ~105 ~43 ~54 sandstone
fill ~108 ~43 ~54 ~109 ~44 ~54 end_stone
fill ~52 ~43 ~55 ~53 ~44 ~55 sandstone
fill ~55 ~43 ~55 ~57 ~43 ~55 end_stone
fill ~58 ~43 ~55 ~58 ~44 ~55 sandstone
fill ~59 ~43 ~55 ~59 ~47 ~57 stone
fill ~60 ~43 ~55 ~60 ~43 ~57 stone
fill ~61 ~43 ~55 ~61 ~45 ~55 end_stone
setblock ~62 ~43 ~55 end_stone
fill ~76 ~43 ~55 ~83 ~51 ~61 stone
fill ~98 ~43 ~55 ~99 ~44 ~55 sandstone
fill ~100 ~43 ~55 ~100 ~44 ~55 end_stone
fill ~101 ~43 ~55 ~106 ~48 ~55 stone
fill ~107 ~43 ~55 ~107 ~43 ~57 end_stone
setblock ~109 ~43 ~55 sandstone
fill ~51 ~43 ~56 ~54 ~43 ~56 end_stone
fill ~55 ~43 ~56 ~57 ~48 ~57 stone
fill ~58 ~43 ~56 ~59 ~47 ~57 stone
fill ~61 ~43 ~56 ~62 ~44 ~56 sandstone
fill ~75 ~43 ~56 ~84 ~50 ~60 stone
fill ~98 ~43 ~56 ~99 ~43 ~56 end_stone
fill ~100 ~43 ~56 ~100 ~43 ~58 sandstone
fill ~101 ~43 ~56 ~106 ~43 ~56 stone
fill ~110 ~43 ~56 ~110 ~43 ~62 sandstone
fill ~53 ~43 ~57 ~54 ~43 ~57 sandstone
setblock ~61 ~43 ~57 end_stone
setblock ~62 ~43 ~57 sandstone
fill ~85 ~43 ~57 ~85 ~52 ~61 stone
fill ~98 ~43 ~57 ~98 ~44 ~57 sandstone
setblock ~99 ~43 ~57 end_stone
fill ~101 ~43 ~57 ~102 ~43 ~57 sandstone
fill ~103 ~43 ~57 ~106 ~47 ~57 stone
fill ~109 ~43 ~57 ~109 ~45 ~57 end_stone
fill ~50 ~43 ~58 ~50 ~44 ~58 end_stone
fill ~53 ~43 ~58 ~54 ~43 ~62 stone
fill ~60 ~43 ~58 ~60 ~44 ~58 end_stone
fill ~61 ~43 ~58 ~61 ~43 ~59 sandstone
fill ~86 ~43 ~58 ~86 ~52 ~60 stone
fill ~101 ~43 ~58 ~101 ~43 ~60 end_stone
setblock ~102 ~43 ~58 end_stone
setblock ~103 ~43 ~58 sandstone
fill ~106 ~43 ~58 ~106 ~47 ~59 stone
fill ~107 ~43 ~58 ~108 ~44 ~58 sandstone
setblock ~109 ~43 ~58 end_stone
fill ~51 ~43 ~59 ~51 ~45 ~59 end_stone
setblock ~52 ~43 ~59 end_stone
fill ~56 ~43 ~59 ~57 ~47 ~59 stone
setblock ~58 ~43 ~59 sandstone
setblock ~59 ~43 ~59 end_stone
fill ~60 ~43 ~59 ~61 ~43 ~59 sandstone
fill ~100 ~43 ~59 ~101 ~43 ~59 end_stone
fill ~102 ~43 ~59 ~102 ~44 ~59 sandstone
setblock ~103 ~43 ~59 end_stone
fill ~107 ~43 ~59 ~107 ~47 ~59 stone
fill ~108 ~43 ~59 ~110 ~43 ~60 sandstone
fill ~56 ~43 ~60 ~56 ~47 ~60 stone
fill ~57 ~43 ~60 ~57 ~43 ~62 sandstone
fill ~58 ~43 ~60 ~58 ~43 ~61 end_stone
fill ~59 ~43 ~60 ~60 ~43 ~60 sandstone
setblock ~61 ~43 ~60 end_stone
fill ~102 ~43 ~60 ~103 ~43 ~60 sandstone
fill ~104 ~43 ~60 ~104 ~44 ~60 end_stone
fill ~106 ~43 ~60 ~107 ~43 ~60 stone
setblock ~111 ~43 ~60 sandstone
setblock ~56 ~43 ~61 stone
setblock ~60 ~43 ~61 end_stone
fill ~84 ~43 ~61 ~85 ~52 ~61 stone
setblock ~102 ~43 ~61 end_stone
fill ~103 ~43 ~61 ~104 ~43 ~61 sandstone
setblock ~105 ~43 ~61 end_stone
fill ~106 ~43 ~61 ~106 ~44 ~62 sandstone
fill ~107 ~43 ~61 ~107 ~45 ~61 end_stone
setblock ~108 ~43 ~61 sandstone
setblock ~109 ~43 ~61 end_stone
fill ~144 ~43 ~61 ~144 ~49 ~61 quartz_block
fill ~18 ~43 ~62 ~18 ~44 ~63 quartz_block
fill ~55 ~43 ~62 ~55 ~44 ~62 end_stone
fill ~56 ~43 ~62 ~58 ~43 ~62 sandstone
setblock ~59 ~43 ~62 end_stone
fill ~76 ~43 ~62 ~81 ~52 ~62 stone
fill ~83 ~43 ~62 ~83 ~52 ~62 stone
fill ~105 ~43 ~62 ~106 ~43 ~62 sandstone
setblock ~107 ~43 ~62 end_stone
fill ~109 ~43 ~62 ~110 ~43 ~62 sandstone
fill ~144 ~43 ~62 ~144 ~44 ~63 quartz_block
fill ~20 ~43 ~63 ~20 ~45 ~63 stone
fill ~51 ~43 ~63 ~52 ~44 ~63 stone
fill ~53 ~43 ~63 ~55 ~43 ~63 sandstone
setblock ~57 ~43 ~63 end_stone
fill ~143 ~43 ~63 ~143 ~46 ~63 sandstone
fill ~145 ~43 ~63 ~145 ~45 ~63 sandstone
fill ~146 ~43 ~63 ~146 ~45 ~63 stone
fill ~16 ~43 ~64 ~21 ~43 ~64 sandstone
setblock ~53 ~43 ~64 end_stone
fill ~55 ~43 ~64 ~55 ~44 ~64 sandstone
fill ~56 ~43 ~64 ~56 ~44 ~64 end_stone
fill ~57 ~43 ~64 ~57 ~44 ~64 sandstone
setblock ~80 ~43 ~64 stone
fill ~142 ~43 ~64 ~147 ~43 ~64 sandstone
fill ~14 ~43 ~65 ~15 ~44 ~65 sandstone
fill ~17 ~43 ~65 ~19 ~43 ~65 stone
fill ~54 ~43 ~65 ~55 ~45 ~65 end_stone
fill ~140 ~43 ~65 ~141 ~44 ~65 sandstone
fill ~143 ~43 ~65 ~145 ~43 ~65 stone
setblock ~15 ~43 ~66 stone
setblock ~17 ~43 ~66 sandstone
fill ~18 ~43 ~66 ~18 ~43 ~67 stone
fill ~19 ~43 ~66 ~20 ~43 ~66 sandstone
fill ~21 ~43 ~66 ~21 ~44 ~66 stone
fill ~77 ~43 ~66 ~79 ~43 ~96 stone
setblock ~141 ~43 ~66 stone
setblock ~143 ~43 ~66 sandstone
fill ~144 ~43 ~66 ~144 ~43 ~67 stone
fill ~145 ~43 ~66 ~146 ~43 ~66 sandstone
fill ~147 ~43 ~66 ~147 ~44 ~66 stone
fill ~16 ~43 ~67 ~18 ~43 ~67 stone
setblock ~19 ~43 ~67 sandstone
fill ~20 ~43 ~67 ~20 ~44 ~67 stone
fill ~76 ~43 ~67 ~83 ~43 ~95 stone
fill ~142 ~43 ~67 ~144 ~43 ~67 stone
setblock ~145 ~43 ~67 sandstone
fill ~146 ~43 ~67 ~146 ~44 ~67 stone
setblock ~18 ~43 ~68 diamond_ore
fill ~74 ~43 ~68 ~86 ~43 ~94 stone
setblock ~144 ~43 ~68 diamond_ore
fill ~18 ~43 ~69 ~18 ~45 ~69 stone
fill ~88 ~43 ~69 ~88 ~43 ~94 stone
fill ~144 ~43 ~69 ~144 ~45 ~69 stone
fill ~73 ~43 ~70 ~90 ~43 ~93 stone
fill ~91 ~43 ~71 ~91 ~43 ~92 stone
fill ~93 ~43 ~72 ~93 ~43 ~89 stone
fill ~71 ~43 ~73 ~74 ~51 ~90 stone
fill ~70 ~43 ~74 ~74 ~50 ~89 stone
fill ~44 ~43 ~75 ~44 ~51 ~87 stone
fill ~67 ~43 ~75 ~94 ~43 ~86 stone
fill ~102 ~43 ~75 ~106 ~50 ~84 stone
fill ~116 ~43 ~75 ~122 ~48 ~83 stone
fill ~31 ~43 ~76 ~31 ~50 ~85 stone
fill ~41 ~43 ~76 ~46 ~45 ~87 stone
fill ~47 ~43 ~76 ~47 ~51 ~85 stone
fill ~58 ~43 ~76 ~60 ~52 ~86 stone
fill ~66 ~43 ~76 ~96 ~43 ~84 stone
fill ~100 ~43 ~76 ~106 ~51 ~81 stone
fill ~107 ~43 ~76 ~107 ~51 ~77 stone
fill ~29 ~43 ~77 ~31 ~48 ~84 stone
fill ~33 ~43 ~77 ~33 ~50 ~85 stone
fill ~37 ~43 ~77 ~37 ~51 ~85 stone
fill ~49 ~43 ~77 ~51 ~52 ~83 stone
fill ~57 ~43 ~77 ~61 ~52 ~86 stone
fill ~97 ~43 ~77 ~97 ~43 ~80 stone
fill ~108 ~43 ~77 ~108 ~52 ~84 stone
fill ~125 ~43 ~77 ~125 ~51 ~85 stone
fill ~129 ~43 ~77 ~129 ~50 ~85 stone
fill ~132 ~43 ~77 ~132 ~49 ~85 stone
fill ~153 ~43 ~77 ~153 ~44 ~78 sandstone
fill ~10 ~43 ~78 ~10 ~44 ~78 stone
fill ~34 ~43 ~78 ~42 ~51 ~84 stone
fill ~52 ~43 ~78 ~54 ~52 ~84 stone
fill ~109 ~43 ~78 ~110 ~52 ~84 stone
fill ~126 ~43 ~78 ~133 ~49 ~84 stone
setblock ~152 ~43 ~78 stone
fill ~7 ~43 ~79 ~7 ~45 ~79 stone
fill ~8 ~43 ~79 ~8 ~43 ~84 sandstone
fill ~9 ~43 ~79 ~10 ~43 ~79 sandstone
fill ~11 ~43 ~79 ~11 ~44 ~79 stone
fill ~62 ~43 ~79 ~62 ~52 ~79 stone
fill ~64 ~43 ~79 ~79 ~52 ~79 stone
fill ~99 ~43 ~79 ~134 ~43 ~81 stone
fill ~151 ~43 ~79 ~151 ~43 ~81 stone
fill ~154 ~43 ~79 ~154 ~43 ~84 sandstone
fill ~7 ~43 ~80 ~7 ~45 ~80 sandstone
fill ~9 ~43 ~80 ~9 ~43 ~82 stone
fill ~10 ~43 ~80 ~11 ~43 ~80 sandstone
fill ~26 ~43 ~80 ~61 ~49 ~82 stone
fill ~135 ~43 ~80 ~136 ~49 ~82 stone
fill ~137 ~43 ~80 ~137 ~48 ~81 stone
setblock ~152 ~43 ~80 sandstone
fill ~153 ~43 ~80 ~153 ~43 ~82 stone
fill ~155 ~43 ~80 ~155 ~46 ~80 sandstone
fill ~5 ~43 ~81 ~5 ~49 ~81 quartz_block
fill ~6 ~43 ~81 ~7 ~44 ~81 quartz_block
fill ~10 ~43 ~81 ~11 ~43 ~81 stone
setblock ~12 ~43 ~81 diamond_ore
fill ~13 ~43 ~81 ~13 ~45 ~81 stone
fill ~24 ~43 ~81 ~62 ~48 ~81 stone
fill ~98 ~43 ~81 ~138 ~45 ~81 stone
fill ~149 ~43 ~81 ~149 ~45 ~81 stone
setblock ~150 ~43 ~81 diamond_ore
fill ~152 ~43 ~81 ~153 ~43 ~81 stone
fill ~155 ~43 ~81 ~157 ~44 ~81 quartz_block
fill ~7 ~43 ~82 ~8 ~44 ~82 sandstone
fill ~10 ~43 ~82 ~10 ~43 ~83 sandstone
fill ~11 ~43 ~82 ~11 ~43 ~83 stone
fill ~25 ~43 ~82 ~62 ~48 ~82 stone
fill ~151 ~43 ~82 ~152 ~43 ~82 sandstone
fill ~155 ~43 ~82 ~155 ~45 ~82 sandstone
fill ~65 ~43 ~83 ~96 ~43 ~83 stone
fill ~100 ~43 ~83 ~128 ~52 ~83 stone
fill ~151 ~43 ~83 ~151 ~44 ~83 stone
fill ~153 ~43 ~83 ~154 ~43 ~83 sandstone
fill ~155 ~43 ~83 ~155 ~45 ~83 stone
fill ~9 ~43 ~84 ~9 ~44 ~85 sandstone
setblock ~10 ~43 ~84 stone
fill ~62 ~43 ~84 ~62 ~52 ~86 stone
fill ~101 ~43 ~84 ~105 ~52 ~85 stone
fill ~123 ~43 ~84 ~133 ~49 ~84 stone
fill ~152 ~43 ~84 ~153 ~43 ~84 stone
fill ~30 ~43 ~85 ~31 ~49 ~85 stone
fill ~54 ~43 ~85 ~62 ~52 ~85 stone
fill ~95 ~43 ~85 ~95 ~51 ~85 stone
fill ~111 ~43 ~85 ~121 ~51 ~85 stone
fill ~133 ~43 ~85 ~133 ~48 ~85 stone
fill ~55 ~43 ~86 ~62 ~51 ~86 stone
fill ~102 ~43 ~86 ~104 ~52 ~86 stone
fill ~115 ~43 ~86 ~121 ~51 ~86 stone
fill ~131 ~43 ~86 ~131 ~50 ~86 stone
fill ~40 ~43 ~87 ~46 ~48 ~87 stone
fill ~56 ~43 ~87 ~60 ~50 ~87 stone
fill ~94 ~43 ~87 ~94 ~50 ~87 stone
fill ~118 ~43 ~87 ~118 ~51 ~87 stone
setblock ~94 ~43 ~88 stone
fill ~69 ~43 ~90 ~92 ~43 ~90 stone
setblock ~92 ~43 ~91 stone
fill ~70 ~43 ~92 ~91 ~43 ~92 stone
fill ~18 ~43 ~93 ~18 ~45 ~93 stone
fill ~71 ~43 ~93 ~90 ~43 ~93 stone
fill ~144 ~43 ~93 ~144 ~45 ~93 stone
setblock ~18 ~43 ~94 diamond_ore
fill ~72 ~43 ~94 ~89 ~43 ~94 stone
setblock ~144 ~43 ~94 diamond_ore
fill ~16 ~43 ~95 ~16 ~44 ~95 stone
fill ~17 ~43 ~95 ~17 ~43 ~96 sandstone
fill ~18 ~43 ~95 ~20 ~43 ~95 stone
fill ~85 ~43 ~95 ~85 ~52 ~95 stone
fill ~86 ~43 ~95 ~87 ~43 ~95 stone
fill ~142 ~43 ~95 ~142 ~44 ~95 stone
fill ~143 ~43 ~95 ~143 ~43 ~96 sandstone
fill ~144 ~43 ~95 ~146 ~43 ~95 stone
fill ~15 ~43 ~96 ~15 ~44 ~96 stone
fill ~18 ~43 ~96 ~18 ~43 ~97 stone
fill ~19 ~43 ~96 ~20 ~43 ~96 sandstone
setblock ~21 ~43 ~96 stone
fill ~141 ~43 ~96 ~141 ~44 ~96 stone
fill ~144 ~43 ~96 ~144 ~43 ~97 stone
fill ~145 ~43 ~96 ~146 ~43 ~96 sandstone
setblock ~147 ~43 ~96 stone
fill ~16 ~43 ~97 ~16 ~43 ~98 sandstone
fill ~17 ~43 ~97 ~19 ~43 ~97 stone
fill ~21 ~43 ~97 ~22 ~44 ~97 sandstone
setblock ~75 ~43 ~97 stone
fill ~79 ~43 ~97 ~80 ~52 ~97 stone
fill ~107 ~43 ~97 ~108 ~45 ~97 end_stone
fill ~142 ~43 ~97 ~142 ~43 ~98 sandstone
fill ~143 ~43 ~97 ~145 ~43 ~97 stone
fill ~147 ~43 ~97 ~148 ~44 ~97 sandstone
fill ~17 ~43 ~98 ~21 ~43 ~98 sandstone
fill ~105 ~43 ~98 ~105 ~44 ~98 sandstone
fill ~106 ~43 ~98 ~106 ~44 ~98 end_stone
fill ~107 ~43 ~98 ~108 ~44 ~98 sandstone
setblock ~109 ~43 ~98 end_stone
fill ~143 ~43 ~98 ~147 ~43 ~98 sandstone
fill ~16 ~43 ~99 ~16 ~45 ~99 stone
fill ~17 ~43 ~99 ~17 ~45 ~99 sandstone
fill ~18 ~43 ~99 ~18 ~44 ~101 quartz_block
fill ~19 ~43 ~99 ~19 ~46 ~99 sandstone
fill ~105 ~43 ~99 ~106 ~43 ~99 end_stone
fill ~107 ~43 ~99 ~107 ~47 ~99 sandstone
fill ~108 ~43 ~99 ~109 ~43 ~99 sandstone
fill ~110 ~43 ~99 ~110 ~45 ~102 stone
fill ~111 ~43 ~99 ~111 ~44 ~99 stone
fill ~142 ~43 ~99 ~142 ~45 ~99 stone
fill ~144 ~43 ~99 ~144 ~44 ~100 quartz_block
fill ~52 ~43 ~100 ~52 ~43 ~106 sandstone
setblock ~53 ~43 ~100 sandstone
fill ~55 ~43 ~100 ~55 ~43 ~101 end_stone
fill ~56 ~43 ~100 ~56 ~47 ~100 sandstone
setblock ~57 ~43 ~100 sandstone
fill ~79 ~43 ~100 ~79 ~52 ~128 stone
fill ~84 ~43 ~100 ~86 ~51 ~106 stone
fill ~103 ~43 ~100 ~103 ~43 ~101 end_stone
fill ~104 ~43 ~100 ~106 ~43 ~100 sandstone
fill ~107 ~43 ~100 ~107 ~44 ~100 end_stone
setblock ~53 ~43 ~101 end_stone
fill ~54 ~43 ~101 ~54 ~43 ~105 sandstone
fill ~56 ~43 ~101 ~56 ~44 ~101 sandstone
setblock ~57 ~43 ~101 end_stone
fill ~58 ~43 ~101 ~59 ~43 ~101 sandstone
setblock ~60 ~43 ~101 end_stone
fill ~77 ~43 ~101 ~86 ~52 ~105 stone
fill ~102 ~43 ~101 ~104 ~43 ~101 end_stone
fill ~105 ~43 ~101 ~105 ~43 ~102 sandstone
fill ~106 ~43 ~101 ~107 ~43 ~106 stone
fill ~51 ~43 ~102 ~54 ~43 ~102 sandstone
fill ~55 ~43 ~102 ~57 ~43 ~103 stone
fill ~58 ~43 ~102 ~58 ~44 ~102 end_stone
fill ~59 ~43 ~102 ~60 ~43 ~102 sandstone
fill ~61 ~43 ~102 ~61 ~43 ~104 end_stone
fill ~76 ~43 ~102 ~86 ~52 ~104 stone
fill ~87 ~43 ~102 ~87 ~50 ~106 stone
setblock ~101 ~43 ~102 end_stone
fill ~102 ~43 ~102 ~103 ~43 ~102 sandstone
setblock ~104 ~43 ~102 end_stone
fill ~53 ~43 ~103 ~54 ~44 ~103 sandstone
setblock ~59 ~43 ~103 end_stone
fill ~60 ~43 ~103 ~60 ~44 ~103 sandstone
setblock ~62 ~43 ~103 end_stone
fill ~101 ~43 ~103 ~102 ~43 ~103 sandstone
setblock ~103 ~43 ~103 end_stone
setblock ~104 ~43 ~103 sandstone
fill ~105 ~43 ~103 ~107 ~47 ~106 stone
fill ~110 ~43 ~103 ~111 ~43 ~103 end_stone
fill ~53 ~43 ~104 ~53 ~43 ~106 end_stone
fill ~55 ~43 ~104 ~55 ~44 ~104 sandstone
fill ~56 ~43 ~104 ~58 ~47 ~107 stone
setblock ~59 ~43 ~104 sandstone
fill ~60 ~43 ~104 ~61 ~43 ~104 end_stone
fill ~62 ~43 ~104 ~62 ~45 ~104 sandstone
setblock ~101 ~43 ~104 sandstone
fill ~102 ~43 ~104 ~102 ~44 ~104 end_stone
fill ~103 ~43 ~104 ~103 ~44 ~104 sandstone
setblock ~109 ~43 ~104 stone
fill ~112 ~43 ~104 ~112 ~44 ~104 end_stone
fill ~55 ~43 ~105 ~55 ~43 ~108 end_stone
fill ~59 ~43 ~105 ~59 ~47 ~109 stone
fill ~60 ~43 ~105 ~62 ~43 ~105 sandstone
fill ~63 ~43 ~105 ~63 ~43 ~106 end_stone
fill ~64 ~43 ~105 ~64 ~44 ~105 sandstone
fill ~100 ~43 ~105 ~100 ~43 ~106 sandstone
setblock ~101 ~43 ~105 end_stone
fill ~103 ~43 ~105 ~107 ~47 ~106 stone
fill ~108 ~43 ~105 ~110 ~43 ~105 sandstone
fill ~60 ~43 ~106 ~60 ~47 ~110 stone
fill ~61 ~43 ~106 ~61 ~43 ~110 stone
setblock ~62 ~43 ~106 sandstone
fill ~64 ~43 ~106 ~64 ~44 ~106 end_stone
fill ~101 ~43 ~106 ~101 ~44 ~106 sandstone
fill ~102 ~43 ~106 ~107 ~43 ~106 stone
fill ~108 ~43 ~106 ~111 ~43 ~106 end_stone
fill ~53 ~43 ~107 ~54 ~43 ~107 sandstone
fill ~62 ~43 ~107 ~62 ~44 ~107 end_stone
fill ~63 ~43 ~107 ~63 ~47 ~107 sandstone
fill ~64 ~43 ~107 ~64 ~44 ~108 sandstone
fill ~65 ~43 ~107 ~65 ~45 ~108 end_stone
fill ~85 ~43 ~107 ~85 ~52 ~108 stone
fill ~86 ~43 ~107 ~86 ~51 ~107 stone
fill ~100 ~43 ~107 ~101 ~43 ~107 end_stone
fill ~103 ~43 ~107 ~103 ~47 ~107 stone
fill ~104 ~43 ~107 ~104 ~44 ~108 sandstone
fill ~105 ~43 ~107 ~108 ~43 ~107 end_stone
fill ~109 ~43 ~107 ~110 ~44 ~107 sandstone
fill ~53 ~43 ~108 ~56 ~43 ~108 end_stone
fill ~63 ~43 ~108 ~64 ~43 ~108 sandstone
fill ~78 ~43 ~108 ~83 ~52 ~117 stone
fill ~101 ~43 ~108 ~105 ~43 ~108 sandstone
fill ~107 ~43 ~108 ~107 ~44 ~108 sandstone
fill ~108 ~43 ~108 ~108 ~44 ~109 end_stone
setblock ~109 ~43 ~108 stone
setblock ~54 ~43 ~109 stone
fill ~55 ~43 ~109 ~55 ~46 ~109 sandstone
fill ~56 ~43 ~109 ~56 ~43 ~111 end_stone
fill ~57 ~43 ~109 ~57 ~44 ~110 sandstone
fill ~58 ~43 ~109 ~62 ~43 ~109 stone
setblock ~63 ~43 ~109 sandstone
setblock ~64 ~43 ~109 end_stone
fill ~84 ~43 ~109 ~84 ~52 ~110 stone
fill ~100 ~43 ~109 ~100 ~43 ~110 sandstone
setblock ~101 ~43 ~109 end_stone
fill ~103 ~43 ~109 ~103 ~44 ~109 sandstone
fill ~104 ~43 ~109 ~106 ~43 ~109 end_stone
setblock ~107 ~43 ~109 sandstone
fill ~55 ~43 ~110 ~55 ~44 ~110 sandstone
fill ~59 ~43 ~110 ~59 ~43 ~111 end_stone
fill ~63 ~43 ~110 ~63 ~44 ~111 stone
fill ~101 ~43 ~110 ~106 ~43 ~110 sandstone
fill ~77 ~43 ~111 ~83 ~52 ~114 stone
setblock ~102 ~43 ~111 sandstone
fill ~58 ~43 ~112 ~58 ~44 ~112 end_stone
fill ~76 ~43 ~115 ~85 ~51 ~118 stone
fill ~87 ~43 ~117 ~87 ~48 ~121 stone
fill ~75 ~43 ~118 ~87 ~51 ~118 stone
fill ~88 ~43 ~119 ~88 ~48 ~119 stone
fill ~76 ~43 ~120 ~86 ~51 ~121 stone
fill ~78 ~43 ~123 ~84 ~49 ~133 stone
fill ~77 ~43 ~125 ~85 ~51 ~125 stone
fill ~77 ~43 ~129 ~85 ~50 ~129 stone
fill ~76 ~43 ~131 ~85 ~50 ~131 stone
fill ~85 ~43 ~132 ~85 ~49 ~132 stone
fill ~77 ~43 ~133 ~84 ~48 ~133 stone
fill ~80 ~43 ~135 ~82 ~49 ~136 stone
fill ~82 ~43 ~137 ~82 ~48 ~137 stone
fill ~81 ~43 ~138 ~81 ~48 ~138 stone
fill ~97 ~43 ~140 ~97 ~44 ~141 sandstone
fill ~66 ~43 ~141 ~66 ~44 ~141 stone
setblock ~96 ~43 ~141 stone
fill ~63 ~43 ~142 ~63 ~45 ~142 stone
fill ~64 ~43 ~142 ~64 ~43 ~147 sandstone
fill ~65 ~43 ~142 ~66 ~43 ~142 sandstone
fill ~67 ~43 ~142 ~67 ~44 ~142 stone
fill ~95 ~43 ~142 ~95 ~43 ~144 stone
fill ~98 ~43 ~142 ~98 ~43 ~147 sandstone
fill ~65 ~43 ~143 ~65 ~43 ~145 stone
fill ~66 ~43 ~143 ~67 ~43 ~143 sandstone
setblock ~96 ~43 ~143 sandstone
fill ~97 ~43 ~143 ~97 ~43 ~145 stone
fill ~99 ~43 ~143 ~99 ~46 ~143 sandstone
fill ~62 ~43 ~144 ~63 ~44 ~144 quartz_block
fill ~66 ~43 ~144 ~67 ~43 ~144 stone
setblock ~68 ~43 ~144 diamond_ore
fill ~69 ~43 ~144 ~69 ~45 ~144 stone
fill ~93 ~43 ~144 ~93 ~45 ~144 stone
setblock ~94 ~43 ~144 diamond_ore
fill ~96 ~43 ~144 ~97 ~43 ~144 stone
fill ~99 ~43 ~144 ~101 ~44 ~144 quartz_block
fill ~66 ~43 ~145 ~66 ~43 ~146 sandstone
fill ~67 ~43 ~145 ~67 ~43 ~146 stone
fill ~95 ~43 ~145 ~96 ~43 ~145 sandstone
fill ~99 ~43 ~145 ~99 ~45 ~145 sandstone
fill ~95 ~43 ~146 ~95 ~44 ~146 stone
fill ~97 ~43 ~146 ~98 ~43 ~146 sandstone
fill ~99 ~43 ~146 ~99 ~45 ~146 stone
fill ~65 ~43 ~147 ~65 ~44 ~148 sandstone
setblock ~66 ~43 ~147 stone
fill ~96 ~43 ~147 ~97 ~43 ~147 stone
fill ~81 ~43 ~149 ~81 ~45 ~149 stone
setblock ~81 ~43 ~150 diamond_ore
fill ~79 ~43 ~151 ~79 ~44 ~151 stone
fill ~80 ~43 ~151 ~80 ~43 ~152 sandstone
fill ~81 ~43 ~151 ~83 ~43 ~151 stone
fill ~78 ~43 ~152 ~78 ~44 ~152 stone
fill ~81 ~43 ~152 ~81 ~43 ~153 stone
fill ~82 ~43 ~152 ~83 ~43 ~152 sandstone
setblock ~84 ~43 ~152 stone
fill ~79 ~43 ~153 ~79 ~43 ~154 sandstone
fill ~80 ~43 ~153 ~82 ~43 ~153 stone
fill ~84 ~43 ~153 ~85 ~44 ~153 sandstone
fill ~80 ~43 ~154 ~84 ~43 ~154 sandstone
fill ~79 ~43 ~155 ~79 ~45 ~155 stone
fill ~80 ~43 ~155 ~80 ~45 ~155 sandstone
fill ~81 ~43 ~155 ~81 ~44 ~157 quartz_block
fill ~82 ~43 ~155 ~82 ~46 ~155 sandstone
fill ~81 ~44 ~4 ~81 ~47 ~5 quartz_block
fill ~80 ~44 ~5 ~82 ~45 ~6 quartz_block
fill ~79 ~44 ~7 ~80 ~44 ~8 sandstone
fill ~77 ~44 ~8 ~80 ~44 ~8 sandstone
setblock ~81 ~44 ~8 iron_ore
fill ~82 ~44 ~8 ~82 ~45 ~8 stone
fill ~83 ~44 ~8 ~84 ~44 ~8 sandstone
setblock ~79 ~44 ~9 activator_rail 2
setblock ~80 ~44 ~9 dropper 10
setblock ~83 ~44 ~9 furnace 3
fill ~84 ~44 ~9 ~85 ~44 ~9 sandstone
setblock ~77 ~44 ~10 sandstone
setblock ~79 ~44 ~10 dropper 2
fill ~85 ~44 ~10 ~85 ~45 ~10 sandstone
fill ~78 ~44 ~11 ~78 ~45 ~11 stone
fill ~82 ~44 ~11 ~84 ~44 ~11 stone
setblock ~79 ~44 ~12 stone
setblock ~80 ~44 ~12 coal_ore
fill ~82 ~44 ~12 ~82 ~44 ~13 sandstone
fill ~80 ~44 ~13 ~81 ~45 ~13 stone
fill ~65 ~44 ~14 ~66 ~44 ~14 sandstone
fill ~96 ~44 ~14 ~98 ~44 ~14 sandstone
setblock ~65 ~44 ~15 sandstone
fill ~67 ~44 ~15 ~67 ~44 ~17 stone
fill ~95 ~44 ~15 ~95 ~45 ~15 stone
setblock ~64 ~44 ~16 sandstone
setblock ~65 ~44 ~16 furnace 5
setblock ~94 ~44 ~16 stone
setblock ~96 ~44 ~16 dropper 2
setblock ~97 ~44 ~16 activator_rail 2
fill ~98 ~44 ~16 ~99 ~44 ~17 sandstone
fill ~61 ~44 ~17 ~62 ~45 ~19 quartz_block
fill ~64 ~44 ~17 ~64 ~45 ~17 stone
fill ~68 ~44 ~17 ~69 ~44 ~17 sandstone
fill ~93 ~44 ~17 ~93 ~45 ~18 stone
setblock ~94 ~44 ~17 coal_ore
setblock ~97 ~44 ~17 dropper 10
fill ~100 ~44 ~17 ~101 ~45 ~19 quartz_block
fill ~60 ~44 ~18 ~61 ~47 ~18 quartz_block
setblock ~64 ~44 ~18 iron_ore
setblock ~98 ~44 ~18 iron_ore
fill ~102 ~44 ~18 ~102 ~47 ~18 quartz_block
setblock ~65 ~44 ~19 dropper 10
setblock ~68 ~44 ~19 coal_ore
fill ~69 ~44 ~19 ~69 ~46 ~19 stone
fill ~93 ~44 ~19 ~94 ~44 ~19 sandstone
fill ~95 ~44 ~19 ~95 ~44 ~21 stone
fill ~98 ~44 ~19 ~98 ~45 ~19 stone
fill ~99 ~44 ~19 ~99 ~45 ~19 sandstone
fill ~63 ~44 ~20 ~64 ~44 ~20 sandstone
setblock ~65 ~44 ~20 activator_rail 2
setblock ~66 ~44 ~20 dropper 2
setblock ~68 ~44 ~20 stone
setblock ~97 ~44 ~20 furnace 4
fill ~98 ~44 ~20 ~98 ~44 ~21 sandstone
fill ~67 ~44 ~21 ~67 ~45 ~21 stone
setblock ~96 ~44 ~21 stone
fill ~97 ~44 ~21 ~98 ~44 ~21 sandstone
fill ~64 ~44 ~22 ~66 ~44 ~22 sandstone
fill ~96 ~44 ~22 ~97 ~44 ~22 sandstone
fill ~80 ~44 ~24 ~81 ~48 ~62 stone
fill ~82 ~44 ~25 ~83 ~48 ~62 stone
fill ~79 ~44 ~26 ~83 ~49 ~62 stone
fill ~78 ~44 ~27 ~83 ~49 ~49 stone
fill ~84 ~44 ~27 ~84 ~49 ~42 stone
fill ~77 ~44 ~28 ~85 ~48 ~34 stone
fill ~86 ~44 ~29 ~86 ~48 ~31 stone
