#Function file to spawn structure aquarius
gamerule commandBlockOutput false
fill ~1 ~46 ~1 ~97 ~45 ~97 air
fill ~1 ~45 ~1 ~97 ~44 ~97 air
fill ~1 ~44 ~1 ~97 ~43 ~97 air
fill ~1 ~43 ~1 ~97 ~42 ~97 air
fill ~1 ~42 ~1 ~97 ~41 ~97 air
fill ~1 ~41 ~1 ~97 ~40 ~97 air
fill ~1 ~40 ~1 ~97 ~39 ~97 air
fill ~1 ~39 ~1 ~97 ~38 ~97 air
fill ~1 ~38 ~1 ~97 ~37 ~97 air
fill ~1 ~37 ~1 ~97 ~36 ~97 air
fill ~1 ~36 ~1 ~97 ~35 ~97 air
fill ~1 ~35 ~1 ~97 ~34 ~97 air
fill ~1 ~34 ~1 ~97 ~33 ~97 air
fill ~1 ~33 ~1 ~97 ~32 ~97 air
fill ~1 ~32 ~1 ~97 ~31 ~97 air
fill ~1 ~31 ~1 ~97 ~30 ~97 air
fill ~1 ~30 ~1 ~97 ~29 ~97 air
fill ~1 ~29 ~1 ~97 ~28 ~97 air
fill ~1 ~28 ~1 ~97 ~27 ~97 air
fill ~1 ~27 ~1 ~97 ~26 ~97 air
fill ~1 ~26 ~1 ~97 ~25 ~97 air
fill ~1 ~25 ~1 ~97 ~24 ~97 air
fill ~1 ~24 ~1 ~97 ~23 ~97 air
fill ~1 ~23 ~1 ~97 ~22 ~97 air
fill ~1 ~22 ~1 ~97 ~21 ~97 air
fill ~1 ~21 ~1 ~97 ~20 ~97 air
fill ~1 ~20 ~1 ~97 ~19 ~97 air
fill ~1 ~19 ~1 ~97 ~18 ~97 air
fill ~1 ~18 ~1 ~97 ~17 ~97 air
fill ~1 ~17 ~1 ~97 ~16 ~97 air
fill ~1 ~16 ~1 ~97 ~15 ~97 air
fill ~1 ~15 ~1 ~97 ~14 ~97 air
fill ~1 ~14 ~1 ~97 ~13 ~97 air
fill ~1 ~13 ~1 ~97 ~12 ~97 air
fill ~1 ~12 ~1 ~97 ~11 ~97 air
fill ~1 ~11 ~1 ~97 ~10 ~97 air
fill ~1 ~10 ~1 ~97 ~9 ~97 air
fill ~1 ~9 ~1 ~97 ~8 ~97 air
fill ~1 ~8 ~1 ~97 ~7 ~97 air
fill ~1 ~7 ~1 ~97 ~6 ~97 air
fill ~1 ~6 ~1 ~97 ~5 ~97 air
fill ~1 ~5 ~1 ~97 ~4 ~97 air
fill ~1 ~4 ~1 ~97 ~3 ~97 air
fill ~1 ~3 ~1 ~97 ~2 ~97 air
fill ~1 ~2 ~1 ~97 ~1 ~97 air
fill ~1 ~1 ~1 ~97 ~0 ~97 air
fill ~26 ~0 ~7 ~26 ~7 ~7 stone
fill ~72 ~0 ~7 ~72 ~7 ~7 stone
fill ~17 ~0 ~17 ~17 ~7 ~17 stone
fill ~81 ~0 ~17 ~81 ~7 ~17 stone
fill ~7 ~0 ~26 ~7 ~7 ~26 stone
fill ~91 ~0 ~26 ~91 ~7 ~26 stone
fill ~63 ~0 ~32 ~63 ~12 ~32 stone
fill ~32 ~0 ~35 ~32 ~12 ~35 stone
fill ~66 ~0 ~63 ~66 ~12 ~63 stone
fill ~35 ~0 ~66 ~35 ~12 ~66 stone
fill ~7 ~0 ~72 ~7 ~7 ~72 stone
fill ~91 ~0 ~72 ~91 ~7 ~72 stone
fill ~17 ~0 ~81 ~17 ~7 ~81 stone
fill ~81 ~0 ~81 ~81 ~7 ~81 stone
fill ~26 ~0 ~91 ~26 ~7 ~91 stone
fill ~72 ~0 ~91 ~72 ~7 ~91 stone
fill ~64 ~1 ~32 ~64 ~12 ~32 stone
fill ~32 ~1 ~34 ~32 ~12 ~35 stone
fill ~58 ~1 ~37 ~58 ~10 ~37 stone
fill ~37 ~1 ~40 ~37 ~10 ~40 stone
fill ~61 ~1 ~58 ~61 ~10 ~58 stone
fill ~40 ~1 ~61 ~40 ~10 ~61 stone
fill ~66 ~1 ~64 ~66 ~12 ~64 stone
fill ~34 ~1 ~66 ~35 ~12 ~66 stone
fill ~72 ~2 ~6 ~72 ~7 ~7 stone
fill ~25 ~2 ~7 ~26 ~7 ~7 stone
fill ~27 ~2 ~8 ~27 ~7 ~8 stone
fill ~71 ~2 ~8 ~71 ~7 ~8 stone
fill ~81 ~2 ~16 ~81 ~7 ~17 stone
fill ~16 ~2 ~17 ~17 ~7 ~17 stone
fill ~18 ~2 ~18 ~18 ~7 ~18 stone
fill ~80 ~2 ~18 ~80 ~7 ~18 stone
fill ~91 ~2 ~25 ~91 ~7 ~26 stone
fill ~6 ~2 ~26 ~7 ~7 ~26 stone
fill ~8 ~2 ~27 ~8 ~7 ~27 stone
fill ~90 ~2 ~27 ~90 ~7 ~27 stone
fill ~57 ~2 ~37 ~58 ~10 ~37 stone
fill ~37 ~2 ~41 ~37 ~10 ~41 stone
fill ~61 ~2 ~57 ~61 ~10 ~58 stone
fill ~41 ~2 ~61 ~41 ~10 ~61 stone
fill ~8 ~2 ~71 ~8 ~7 ~71 stone
fill ~90 ~2 ~71 ~90 ~7 ~71 stone
fill ~92 ~2 ~72 ~92 ~7 ~72 stone
fill ~7 ~2 ~73 ~7 ~7 ~73 stone
fill ~18 ~2 ~80 ~18 ~7 ~80 stone
fill ~80 ~2 ~80 ~80 ~7 ~80 stone
fill ~82 ~2 ~81 ~82 ~7 ~81 stone
fill ~17 ~2 ~82 ~17 ~7 ~82 stone
fill ~27 ~2 ~90 ~27 ~7 ~90 stone
fill ~71 ~2 ~90 ~71 ~7 ~90 stone
fill ~73 ~2 ~91 ~73 ~7 ~91 stone
fill ~26 ~2 ~92 ~26 ~7 ~92 stone
fill ~27 ~3 ~7 ~27 ~7 ~8 stone
fill ~71 ~3 ~7 ~72 ~7 ~8 stone
fill ~26 ~3 ~8 ~27 ~7 ~8 stone
fill ~18 ~3 ~17 ~18 ~7 ~18 stone
fill ~36 ~3 ~17 ~36 ~11 ~17 stone
fill ~80 ~3 ~17 ~81 ~7 ~18 stone
fill ~17 ~3 ~18 ~18 ~7 ~18 stone
fill ~8 ~3 ~26 ~8 ~7 ~27 stone
fill ~90 ~3 ~26 ~91 ~7 ~27 stone
fill ~7 ~3 ~27 ~8 ~7 ~27 stone
fill ~63 ~3 ~31 ~63 ~11 ~33 stone
fill ~31 ~3 ~35 ~33 ~11 ~35 stone
fill ~81 ~3 ~36 ~81 ~11 ~36 stone
fill ~58 ~3 ~38 ~58 ~11 ~38 stone
fill ~38 ~3 ~40 ~38 ~11 ~40 stone
fill ~60 ~3 ~58 ~61 ~10 ~58 stone
fill ~40 ~3 ~60 ~40 ~10 ~61 stone
fill ~17 ~3 ~62 ~17 ~11 ~62 stone
fill ~65 ~3 ~63 ~67 ~11 ~63 stone
fill ~35 ~3 ~65 ~35 ~11 ~67 stone
fill ~7 ~3 ~71 ~8 ~7 ~72 stone
fill ~91 ~3 ~71 ~91 ~7 ~72 stone
fill ~90 ~3 ~72 ~92 ~7 ~72 stone
fill ~17 ~3 ~80 ~18 ~7 ~81 stone
fill ~81 ~3 ~80 ~81 ~7 ~81 stone
fill ~62 ~3 ~81 ~62 ~11 ~81 stone
fill ~80 ~3 ~81 ~82 ~7 ~81 stone
fill ~26 ~3 ~90 ~27 ~7 ~91 stone
fill ~72 ~3 ~90 ~72 ~7 ~91 stone
fill ~71 ~3 ~91 ~73 ~7 ~91 stone
fill ~26 ~4 ~6 ~27 ~7 ~8 stone
fill ~71 ~4 ~6 ~72 ~7 ~8 stone
fill ~73 ~4 ~7 ~73 ~7 ~8 stone
fill ~25 ~4 ~8 ~28 ~7 ~8 stone
fill ~70 ~4 ~8 ~73 ~7 ~8 stone
fill ~27 ~4 ~9 ~27 ~7 ~9 stone
fill ~71 ~4 ~9 ~71 ~7 ~9 stone
fill ~17 ~4 ~16 ~18 ~7 ~18 stone
fill ~80 ~4 ~16 ~81 ~7 ~18 stone
fill ~82 ~4 ~17 ~82 ~7 ~18 stone
fill ~16 ~4 ~18 ~19 ~7 ~18 stone
fill ~79 ~4 ~18 ~82 ~7 ~18 stone
fill ~18 ~4 ~19 ~18 ~7 ~19 stone
fill ~80 ~4 ~19 ~80 ~7 ~19 stone
fill ~7 ~4 ~25 ~8 ~7 ~27 stone
fill ~90 ~4 ~25 ~91 ~7 ~27 stone
fill ~92 ~4 ~26 ~92 ~7 ~27 stone
fill ~6 ~4 ~27 ~9 ~7 ~27 stone
fill ~89 ~4 ~27 ~92 ~7 ~27 stone
fill ~8 ~4 ~28 ~8 ~7 ~28 stone
fill ~28 ~4 ~28 ~28 ~11 ~28 stone
fill ~70 ~4 ~28 ~70 ~11 ~28 stone
fill ~90 ~4 ~28 ~90 ~7 ~28 stone
fill ~64 ~4 ~31 ~64 ~12 ~32 stone
fill ~62 ~4 ~32 ~64 ~11 ~32 stone
fill ~31 ~4 ~34 ~32 ~12 ~35 stone
fill ~32 ~4 ~36 ~32 ~11 ~36 stone
fill ~57 ~4 ~38 ~58 ~11 ~38 stone
fill ~38 ~4 ~41 ~38 ~11 ~41 stone
fill ~49 ~4 ~49 ~49 ~11 ~49 stone
fill ~60 ~4 ~57 ~61 ~10 ~58 stone
fill ~41 ~4 ~60 ~41 ~10 ~61 stone
fill ~66 ~4 ~62 ~66 ~11 ~64 stone
fill ~67 ~4 ~64 ~67 ~12 ~64 stone
fill ~36 ~4 ~66 ~36 ~11 ~66 stone
fill ~34 ~4 ~67 ~35 ~12 ~67 stone
fill ~8 ~4 ~70 ~8 ~7 ~73 stone
fill ~28 ~4 ~70 ~28 ~11 ~70 stone
fill ~70 ~4 ~70 ~70 ~11 ~70 stone
fill ~90 ~4 ~70 ~90 ~7 ~73 stone
fill ~6 ~4 ~71 ~8 ~7 ~72 stone
fill ~9 ~4 ~71 ~9 ~7 ~71 stone
fill ~89 ~4 ~71 ~92 ~7 ~71 stone
fill ~91 ~4 ~73 ~91 ~7 ~73 stone
fill ~18 ~4 ~79 ~18 ~7 ~82 stone
fill ~80 ~4 ~79 ~80 ~7 ~82 stone
fill ~16 ~4 ~80 ~18 ~7 ~81 stone
fill ~19 ~4 ~80 ~19 ~7 ~80 stone
fill ~79 ~4 ~80 ~82 ~7 ~80 stone
fill ~81 ~4 ~82 ~81 ~7 ~82 stone
fill ~27 ~4 ~89 ~27 ~7 ~92 stone
fill ~71 ~4 ~89 ~71 ~7 ~92 stone
fill ~25 ~4 ~90 ~27 ~7 ~91 stone
fill ~28 ~4 ~90 ~28 ~7 ~90 stone
fill ~70 ~4 ~90 ~73 ~7 ~90 stone
fill ~72 ~4 ~92 ~72 ~7 ~92 stone
fill ~26 ~5 ~5 ~26 ~7 ~8 stone
fill ~72 ~5 ~5 ~72 ~7 ~8 stone
fill ~25 ~5 ~6 ~27 ~7 ~8 stone
fill ~73 ~5 ~6 ~73 ~7 ~8 stone
fill ~24 ~5 ~7 ~27 ~7 ~7 stone
fill ~74 ~5 ~7 ~74 ~9 ~7 stone
fill ~17 ~5 ~15 ~17 ~7 ~18 stone
fill ~81 ~5 ~15 ~81 ~7 ~18 stone
fill ~16 ~5 ~16 ~18 ~7 ~18 stone
fill ~82 ~5 ~16 ~82 ~7 ~18 stone
fill ~15 ~5 ~17 ~18 ~7 ~17 stone
fill ~83 ~5 ~17 ~83 ~9 ~17 stone
fill ~49 ~5 ~23 ~49 ~13 ~23 stone
fill ~7 ~5 ~24 ~7 ~7 ~27 stone
fill ~91 ~5 ~24 ~91 ~7 ~27 stone
fill ~6 ~5 ~25 ~8 ~7 ~27 stone
fill ~92 ~5 ~25 ~92 ~7 ~27 stone
fill ~5 ~5 ~26 ~8 ~7 ~26 stone
fill ~93 ~5 ~26 ~93 ~9 ~26 stone
fill ~29 ~5 ~28 ~29 ~11 ~28 stone
fill ~70 ~5 ~29 ~70 ~11 ~29 stone
fill ~63 ~5 ~30 ~63 ~11 ~33 stone
fill ~65 ~5 ~32 ~65 ~12 ~32 stone
fill ~32 ~5 ~33 ~32 ~11 ~36 stone
fill ~62 ~5 ~33 ~64 ~10 ~33 stone
fill ~33 ~5 ~34 ~33 ~10 ~36 stone
fill ~62 ~5 ~34 ~62 ~11 ~34 stone_bricks
fill ~30 ~5 ~35 ~33 ~11 ~35 stone
fill ~34 ~5 ~36 ~34 ~11 ~36 stone_bricks
fill ~56 ~5 ~37 ~58 ~10 ~37 stone
fill ~38 ~5 ~38 ~38 ~11 ~38 stone_bricks
fill ~59 ~5 ~38 ~59 ~11 ~38 stone
fill ~60 ~5 ~38 ~60 ~11 ~38 stone_bricks
fill ~38 ~5 ~39 ~38 ~11 ~41 stone
fill ~58 ~5 ~39 ~58 ~12 ~39 stone
fill ~39 ~5 ~40 ~39 ~12 ~40 stone
fill ~37 ~5 ~42 ~37 ~10 ~42 stone
fill ~23 ~5 ~49 ~23 ~13 ~49 stone
fill ~75 ~5 ~49 ~75 ~13 ~49 stone
fill ~61 ~5 ~56 ~61 ~10 ~58 stone
fill ~59 ~5 ~58 ~61 ~10 ~58 stone
fill ~40 ~5 ~59 ~40 ~10 ~61 stone
fill ~60 ~5 ~59 ~60 ~11 ~59 stone
fill ~38 ~5 ~60 ~38 ~11 ~60 stone_bricks
fill ~39 ~5 ~60 ~41 ~11 ~60 stone
fill ~60 ~5 ~60 ~60 ~11 ~60 stone_bricks
fill ~42 ~5 ~61 ~42 ~10 ~61 stone
fill ~64 ~5 ~62 ~64 ~11 ~62 stone_bricks
fill ~65 ~5 ~62 ~66 ~10 ~64 stone
fill ~68 ~5 ~63 ~68 ~12 ~63 stone
fill ~36 ~5 ~64 ~36 ~11 ~64 stone_bricks
fill ~34 ~5 ~65 ~35 ~11 ~67 stone
fill ~36 ~5 ~65 ~36 ~10 ~66 stone
fill ~66 ~5 ~65 ~66 ~12 ~65 stone
fill ~33 ~5 ~66 ~36 ~11 ~66 stone
fill ~35 ~5 ~68 ~35 ~12 ~68 stone
fill ~28 ~5 ~69 ~28 ~11 ~70 stone
fill ~69 ~5 ~70 ~70 ~11 ~70 stone
fill ~5 ~5 ~72 ~8 ~7 ~72 stone
fill ~93 ~5 ~72 ~93 ~11 ~72 stone
fill ~6 ~5 ~73 ~8 ~7 ~73 stone
fill ~92 ~5 ~73 ~92 ~7 ~73 stone
fill ~7 ~5 ~74 ~7 ~11 ~74 stone
fill ~91 ~5 ~74 ~91 ~9 ~74 stone
fill ~49 ~5 ~75 ~49 ~13 ~75 stone
fill ~15 ~5 ~81 ~18 ~7 ~81 stone
fill ~83 ~5 ~81 ~83 ~11 ~81 stone
fill ~16 ~5 ~82 ~18 ~7 ~82 stone
fill ~82 ~5 ~82 ~82 ~7 ~82 stone
fill ~17 ~5 ~83 ~17 ~11 ~83 stone
fill ~81 ~5 ~83 ~81 ~9 ~83 stone
fill ~24 ~5 ~91 ~27 ~7 ~91 stone
fill ~74 ~5 ~91 ~74 ~11 ~91 stone
fill ~25 ~5 ~92 ~27 ~7 ~92 stone
fill ~73 ~5 ~92 ~73 ~7 ~92 stone
fill ~26 ~5 ~93 ~26 ~11 ~93 stone
fill ~72 ~5 ~93 ~72 ~9 ~93 stone
fill ~25 ~6 ~5 ~26 ~7 ~8 stone
fill ~74 ~6 ~6 ~74 ~8 ~7 stone
fill ~29 ~6 ~8 ~29 ~7 ~8 stone
fill ~69 ~6 ~8 ~73 ~7 ~8 stone
fill ~28 ~6 ~9 ~28 ~7 ~9 stone
fill ~70 ~6 ~9 ~71 ~7 ~9 stone
fill ~27 ~6 ~10 ~27 ~7 ~10 stone
fill ~71 ~6 ~10 ~71 ~7 ~10 stone
fill ~16 ~6 ~15 ~17 ~7 ~18 stone
fill ~62 ~6 ~16 ~62 ~11 ~16 stone
fill ~83 ~6 ~16 ~83 ~8 ~17 stone
fill ~20 ~6 ~18 ~20 ~7 ~18 stone
fill ~36 ~6 ~18 ~36 ~11 ~18 stone
fill ~78 ~6 ~18 ~82 ~7 ~18 stone
fill ~19 ~6 ~19 ~19 ~7 ~19 stone
fill ~79 ~6 ~19 ~80 ~7 ~19 stone
fill ~18 ~6 ~20 ~18 ~7 ~20 stone
fill ~80 ~6 ~20 ~80 ~7 ~20 stone
fill ~6 ~6 ~24 ~7 ~7 ~27 stone
fill ~93 ~6 ~25 ~93 ~8 ~26 stone
fill ~10 ~6 ~27 ~10 ~7 ~27 stone
fill ~27 ~6 ~27 ~27 ~11 ~27 stone
fill ~63 ~6 ~27 ~63 ~11 ~34 stone
fill ~71 ~6 ~27 ~71 ~11 ~27 stone
fill ~88 ~6 ~27 ~92 ~7 ~27 stone
fill ~9 ~6 ~28 ~9 ~7 ~28 stone
fill ~62 ~6 ~28 ~63 ~10 ~33 stone
fill ~69 ~6 ~28 ~70 ~11 ~28 stone
fill ~89 ~6 ~28 ~90 ~7 ~28 stone
fill ~8 ~6 ~29 ~8 ~7 ~29 stone
fill ~28 ~6 ~29 ~28 ~11 ~29 stone
fill ~64 ~6 ~29 ~64 ~12 ~33 stone
fill ~90 ~6 ~29 ~90 ~7 ~29 stone
fill ~61 ~6 ~30 ~65 ~12 ~31 stone
fill ~66 ~6 ~31 ~66 ~12 ~32 stone
fill ~31 ~6 ~32 ~32 ~11 ~36 stone
fill ~30 ~6 ~33 ~33 ~10 ~36 stone
fill ~65 ~6 ~33 ~65 ~12 ~33 stone
fill ~29 ~6 ~34 ~33 ~10 ~36 stone
fill ~27 ~6 ~35 ~34 ~11 ~35 stone
fill ~35 ~6 ~35 ~35 ~12 ~35 stone_bricks
fill ~56 ~6 ~35 ~57 ~10 ~38 stone
fill ~63 ~6 ~35 ~63 ~12 ~35 stone_bricks
fill ~16 ~6 ~36 ~16 ~11 ~36 stone
fill ~28 ~6 ~36 ~33 ~10 ~36 stone
fill ~55 ~6 ~36 ~58 ~10 ~37 stone
fill ~80 ~6 ~36 ~81 ~11 ~36 stone
fill ~30 ~6 ~37 ~31 ~12 ~37 stone
fill ~54 ~6 ~37 ~58 ~10 ~37 stone
fill ~59 ~6 ~37 ~59 ~10 ~37 stone_bricks
fill ~39 ~6 ~38 ~42 ~11 ~38 stone
fill ~37 ~6 ~39 ~37 ~10 ~39 stone_bricks
fill ~39 ~6 ~39 ~39 ~12 ~41 stone
fill ~40 ~6 ~39 ~40 ~12 ~39 stone
fill ~57 ~6 ~39 ~60 ~11 ~39 stone
fill ~36 ~6 ~40 ~39 ~10 ~41 stone
fill ~59 ~6 ~40 ~60 ~11 ~40 stone
fill ~35 ~6 ~41 ~38 ~10 ~42 stone
fill ~60 ~6 ~41 ~60 ~11 ~42 stone
fill ~36 ~6 ~43 ~37 ~10 ~43 stone
fill ~37 ~6 ~44 ~37 ~10 ~44 stone
fill ~49 ~6 ~48 ~49 ~11 ~49 stone
fill ~61 ~6 ~54 ~61 ~10 ~58 stone
fill ~62 ~6 ~55 ~62 ~10 ~58 stone
fill ~38 ~6 ~56 ~38 ~11 ~59 stone
fill ~60 ~6 ~56 ~63 ~10 ~57 stone
fill ~59 ~6 ~57 ~63 ~10 ~57 stone
fill ~39 ~6 ~58 ~39 ~11 ~60 stone
fill ~41 ~6 ~59 ~41 ~10 ~63 stone
fill ~58 ~6 ~59 ~59 ~11 ~60 stone
fill ~61 ~6 ~59 ~61 ~10 ~59 stone_bricks
fill ~42 ~6 ~60 ~42 ~10 ~63 stone
fill ~56 ~6 ~60 ~59 ~11 ~60 stone
fill ~39 ~6 ~61 ~39 ~10 ~61 stone_bricks
fill ~43 ~6 ~61 ~44 ~10 ~61 stone
fill ~67 ~6 ~61 ~68 ~12 ~65 stone
fill ~18 ~6 ~62 ~18 ~11 ~62 stone
fill ~40 ~6 ~62 ~43 ~10 ~62 stone
fill ~69 ~6 ~62 ~70 ~12 ~63 stone
fill ~82 ~6 ~62 ~82 ~11 ~62 stone
fill ~35 ~6 ~63 ~35 ~12 ~63 stone_bricks
fill ~63 ~6 ~63 ~63 ~12 ~63 stone_bricks
fill ~64 ~6 ~63 ~71 ~11 ~63 stone
fill ~35 ~6 ~64 ~35 ~11 ~71 stone
fill ~69 ~6 ~64 ~69 ~12 ~64 stone
fill ~33 ~6 ~65 ~36 ~10 ~68 stone
fill ~65 ~6 ~65 ~68 ~12 ~65 stone
fill ~32 ~6 ~66 ~36 ~11 ~67 stone
fill ~66 ~6 ~66 ~67 ~12 ~66 stone
fill ~37 ~6 ~67 ~37 ~12 ~68 stone
fill ~8 ~6 ~69 ~8 ~7 ~73 stone
fill ~34 ~6 ~69 ~36 ~12 ~69 stone
fill ~70 ~6 ~69 ~70 ~11 ~70 stone
fill ~90 ~6 ~69 ~90 ~7 ~73 stone
fill ~9 ~6 ~70 ~9 ~7 ~71 stone
fill ~29 ~6 ~70 ~29 ~11 ~70 stone
fill ~36 ~6 ~70 ~36 ~12 ~70 stone
fill ~89 ~6 ~70 ~90 ~7 ~71 stone
fill ~10 ~6 ~71 ~10 ~7 ~71 stone
fill ~27 ~6 ~71 ~27 ~11 ~71 stone
fill ~71 ~6 ~71 ~71 ~11 ~71 stone
fill ~88 ~6 ~71 ~92 ~7 ~71 stone
fill ~5 ~6 ~73 ~8 ~7 ~73 stone
fill ~92 ~6 ~74 ~92 ~8 ~74 stone
fill ~18 ~6 ~78 ~18 ~7 ~82 stone
fill ~80 ~6 ~78 ~80 ~7 ~82 stone
fill ~19 ~6 ~79 ~19 ~7 ~80 stone
fill ~79 ~6 ~79 ~80 ~7 ~80 stone
fill ~20 ~6 ~80 ~20 ~7 ~80 stone
fill ~62 ~6 ~80 ~62 ~11 ~81 stone
fill ~78 ~6 ~80 ~82 ~7 ~80 stone
fill ~15 ~6 ~82 ~18 ~7 ~82 stone
fill ~36 ~6 ~82 ~36 ~11 ~82 stone
fill ~82 ~6 ~83 ~82 ~8 ~83 stone
fill ~27 ~6 ~88 ~27 ~7 ~92 stone
fill ~71 ~6 ~88 ~71 ~7 ~92 stone
fill ~28 ~6 ~89 ~28 ~7 ~90 stone
fill ~70 ~6 ~89 ~71 ~7 ~90 stone
fill ~29 ~6 ~90 ~29 ~7 ~90 stone
fill ~69 ~6 ~90 ~73 ~7 ~90 stone
fill ~24 ~6 ~92 ~27 ~7 ~92 stone
fill ~73 ~6 ~93 ~73 ~8 ~93 stone
fill ~26 ~7 ~4 ~26 ~10 ~4 stone_bricks
fill ~72 ~7 ~4 ~72 ~10 ~4 stone_bricks
fill ~27 ~7 ~5 ~27 ~7 ~10 stone
fill ~71 ~7 ~5 ~73 ~7 ~8 stone
fill ~24 ~7 ~6 ~27 ~7 ~8 stone
fill ~23 ~7 ~7 ~23 ~10 ~7 stone_bricks
fill ~28 ~7 ~7 ~28 ~7 ~10 stone
fill ~70 ~7 ~7 ~74 ~7 ~8 stone
fill ~75 ~7 ~7 ~75 ~10 ~7 stone_bricks
fill ~26 ~7 ~9 ~29 ~7 ~9 stone
fill ~69 ~7 ~9 ~72 ~7 ~9 stone
fill ~70 ~7 ~10 ~70 ~11 ~10 stone
fill ~17 ~7 ~14 ~17 ~10 ~14 stone_bricks
fill ~81 ~7 ~14 ~81 ~10 ~14 stone_bricks
fill ~18 ~7 ~15 ~18 ~7 ~20 stone
fill ~80 ~7 ~15 ~82 ~7 ~18 stone
fill ~15 ~7 ~16 ~18 ~7 ~18 stone
fill ~14 ~7 ~17 ~14 ~10 ~17 stone_bricks
fill ~19 ~7 ~17 ~19 ~7 ~20 stone
fill ~35 ~7 ~17 ~37 ~11 ~17 stone
fill ~62 ~7 ~17 ~62 ~11 ~17 stone
fill ~79 ~7 ~17 ~83 ~7 ~18 stone
fill ~84 ~7 ~17 ~84 ~10 ~17 stone_bricks
fill ~17 ~7 ~19 ~20 ~7 ~19 stone
fill ~78 ~7 ~19 ~81 ~7 ~19 stone
fill ~79 ~7 ~20 ~79 ~11 ~20 stone
fill ~62 ~7 ~21 ~62 ~11 ~32 stone
fill ~7 ~7 ~23 ~7 ~10 ~23 stone_bricks
fill ~91 ~7 ~23 ~91 ~10 ~23 stone_bricks
fill ~8 ~7 ~24 ~8 ~7 ~29 stone
fill ~35 ~7 ~24 ~35 ~12 ~32 stone
fill ~63 ~7 ~24 ~63 ~11 ~34 stone
fill ~90 ~7 ~24 ~92 ~7 ~27 stone
fill ~5 ~7 ~25 ~8 ~7 ~27 stone
fill ~34 ~7 ~25 ~35 ~12 ~32 stone
fill ~4 ~7 ~26 ~4 ~10 ~26 stone_bricks
fill ~9 ~7 ~26 ~9 ~7 ~29 stone
fill ~61 ~7 ~26 ~64 ~12 ~31 stone
fill ~89 ~7 ~26 ~93 ~7 ~27 stone
fill ~94 ~7 ~26 ~94 ~10 ~26 stone_bricks
fill ~33 ~7 ~27 ~35 ~12 ~32 stone
fill ~65 ~7 ~27 ~65 ~12 ~34 stone
fill ~70 ~7 ~27 ~70 ~11 ~29 stone
fill ~7 ~7 ~28 ~10 ~7 ~28 stone
fill ~27 ~7 ~28 ~29 ~11 ~28 stone
fill ~32 ~7 ~28 ~36 ~11 ~32 stone
fill ~66 ~7 ~28 ~67 ~11 ~36 stone
fill ~88 ~7 ~28 ~91 ~7 ~28 stone
fill ~29 ~7 ~29 ~32 ~11 ~38 stone
fill ~60 ~7 ~29 ~66 ~12 ~31 stone
fill ~68 ~7 ~29 ~69 ~11 ~36 stone
fill ~89 ~7 ~29 ~89 ~11 ~29 stone
fill ~28 ~7 ~31 ~32 ~11 ~37 stone
fill ~60 ~7 ~32 ~70 ~10 ~33 stone
fill ~27 ~7 ~33 ~31 ~12 ~37 stone
fill ~34 ~7 ~33 ~34 ~11 ~35 stone
fill ~35 ~7 ~33 ~35 ~11 ~33 stone
fill ~58 ~7 ~33 ~71 ~10 ~33 stone
fill ~26 ~7 ~34 ~31 ~12 ~37 stone
fill ~56 ~7 ~34 ~58 ~10 ~39 stone
fill ~59 ~7 ~34 ~60 ~11 ~34 stone
fill ~61 ~7 ~34 ~62 ~10 ~34 stone_bricks
fill ~64 ~7 ~34 ~73 ~12 ~34 stone
fill ~24 ~7 ~35 ~31 ~12 ~36 stone
fill ~54 ~7 ~35 ~58 ~10 ~37 stone
fill ~59 ~7 ~35 ~59 ~11 ~35 stone
fill ~65 ~7 ~35 ~74 ~11 ~35 stone
fill ~81 ~7 ~35 ~81 ~11 ~37 stone
fill ~17 ~7 ~36 ~17 ~11 ~36 stone
fill ~21 ~7 ~36 ~32 ~11 ~36 stone
fill ~53 ~7 ~36 ~58 ~10 ~37 stone
fill ~70 ~7 ~36 ~70 ~12 ~36 stone
fill ~33 ~7 ~37 ~33 ~10 ~40 stone
fill ~34 ~7 ~37 ~34 ~10 ~37 stone_bricks
fill ~39 ~7 ~37 ~39 ~10 ~37 stone_bricks
fill ~40 ~7 ~37 ~41 ~10 ~40 stone
fill ~34 ~7 ~38 ~34 ~11 ~42 stone
fill ~43 ~7 ~38 ~45 ~11 ~38 stone
fill ~55 ~7 ~38 ~59 ~11 ~38 stone
fill ~35 ~7 ~39 ~35 ~11 ~44 stone
fill ~42 ~7 ~39 ~43 ~12 ~39 stone
fill ~61 ~7 ~39 ~61 ~10 ~39 stone_bricks
fill ~57 ~7 ~40 ~61 ~10 ~40 stone
fill ~40 ~7 ~41 ~40 ~12 ~41 stone
fill ~58 ~7 ~41 ~61 ~10 ~41 stone
fill ~39 ~7 ~42 ~39 ~12 ~42 stone
fill ~59 ~7 ~42 ~60 ~11 ~43 stone
fill ~38 ~7 ~43 ~38 ~11 ~43 stone
fill ~36 ~7 ~44 ~37 ~10 ~45 stone
setblock ~44 ~7 ~44 polished_diorite
setblock ~54 ~7 ~44 polished_diorite
fill ~60 ~7 ~44 ~60 ~11 ~45 stone
fill ~48 ~7 ~49 ~50 ~11 ~49 stone
fill ~38 ~7 ~53 ~38 ~11 ~59 stone
fill ~61 ~7 ~53 ~62 ~10 ~58 stone
setblock ~44 ~7 ~54 polished_diorite
setblock ~54 ~7 ~54 polished_diorite
fill ~63 ~7 ~54 ~63 ~11 ~59 stone
fill ~39 ~7 ~55 ~39 ~12 ~59 stone
fill ~60 ~7 ~55 ~63 ~10 ~58 stone
fill ~59 ~7 ~56 ~64 ~10 ~58 stone
fill ~37 ~7 ~57 ~40 ~10 ~58 stone
fill ~58 ~7 ~57 ~64 ~10 ~58 stone
fill ~41 ~7 ~58 ~41 ~10 ~64 stone
fill ~57 ~7 ~58 ~65 ~10 ~58 stone
fill ~37 ~7 ~59 ~37 ~10 ~59 stone_bricks
fill ~42 ~7 ~59 ~42 ~10 ~64 stone
fill ~55 ~7 ~59 ~59 ~11 ~60 stone
fill ~64 ~7 ~59 ~65 ~11 ~60 stone
fill ~43 ~7 ~60 ~43 ~10 ~63 stone
fill ~53 ~7 ~60 ~59 ~11 ~60 stone
fill ~66 ~7 ~60 ~69 ~11 ~69 stone
fill ~17 ~7 ~61 ~17 ~11 ~63 stone
fill ~45 ~7 ~61 ~45 ~10 ~62 stone
fill ~57 ~7 ~61 ~58 ~10 ~61 stone
fill ~59 ~7 ~61 ~59 ~10 ~61 stone_bricks
fill ~64 ~7 ~61 ~64 ~10 ~62 stone_bricks
fill ~65 ~7 ~61 ~72 ~10 ~64 stone
fill ~28 ~7 ~62 ~32 ~11 ~66 stone
fill ~44 ~7 ~62 ~45 ~10 ~62 stone
fill ~73 ~7 ~62 ~77 ~11 ~62 stone
fill ~81 ~7 ~62 ~82 ~11 ~62 stone
fill ~24 ~7 ~63 ~32 ~12 ~63 stone
fill ~33 ~7 ~63 ~33 ~11 ~71 stone
fill ~39 ~7 ~63 ~44 ~11 ~63 stone
fill ~73 ~7 ~63 ~74 ~12 ~63 stone
fill ~25 ~7 ~64 ~34 ~12 ~64 stone
fill ~37 ~7 ~64 ~37 ~10 ~64 stone_bricks
fill ~38 ~7 ~64 ~38 ~11 ~69 stone
fill ~39 ~7 ~64 ~42 ~13 ~64 stone
fill ~64 ~7 ~64 ~64 ~12 ~73 stone
fill ~27 ~7 ~65 ~40 ~10 ~65 stone
fill ~63 ~7 ~65 ~63 ~11 ~74 stone
fill ~70 ~7 ~65 ~70 ~11 ~67 stone
fill ~71 ~7 ~65 ~71 ~12 ~65 stone
fill ~37 ~7 ~66 ~38 ~11 ~69 stone
fill ~62 ~7 ~66 ~66 ~11 ~70 stone
fill ~29 ~7 ~67 ~38 ~11 ~69 stone
fill ~9 ~7 ~69 ~9 ~11 ~69 stone
fill ~89 ~7 ~69 ~90 ~7 ~72 stone
fill ~7 ~7 ~70 ~8 ~7 ~74 stone
fill ~10 ~7 ~70 ~10 ~9 ~70 stone
fill ~31 ~7 ~70 ~37 ~11 ~70 stone
fill ~71 ~7 ~70 ~71 ~11 ~71 stone
fill ~88 ~7 ~70 ~91 ~7 ~71 stone
fill ~5 ~7 ~71 ~8 ~7 ~73 stone
fill ~28 ~7 ~71 ~28 ~11 ~71 stone
fill ~34 ~7 ~71 ~37 ~12 ~72 stone
fill ~65 ~7 ~71 ~65 ~12 ~71 stone
fill ~93 ~7 ~71 ~93 ~11 ~72 stone
fill ~4 ~7 ~72 ~4 ~10 ~72 stone_bricks
setblock ~9 ~7 ~72 stone
fill ~94 ~7 ~72 ~94 ~10 ~72 stone_bricks
fill ~35 ~7 ~73 ~36 ~12 ~74 stone
fill ~93 ~7 ~73 ~93 ~8 ~73 stone
fill ~6 ~7 ~74 ~8 ~8 ~74 stone
fill ~90 ~7 ~74 ~92 ~8 ~74 stone
fill ~7 ~7 ~75 ~7 ~10 ~75 stone_bricks
fill ~36 ~7 ~75 ~36 ~11 ~77 stone
fill ~91 ~7 ~75 ~91 ~10 ~75 stone_bricks
fill ~19 ~7 ~78 ~19 ~11 ~78 stone
fill ~79 ~7 ~78 ~80 ~7 ~81 stone
fill ~17 ~7 ~79 ~18 ~7 ~83 stone
fill ~20 ~7 ~79 ~20 ~9 ~79 stone
fill ~78 ~7 ~79 ~81 ~7 ~80 stone
fill ~15 ~7 ~80 ~18 ~7 ~82 stone
fill ~83 ~7 ~80 ~83 ~11 ~81 stone
fill ~14 ~7 ~81 ~14 ~10 ~81 stone_bricks
setblock ~19 ~7 ~81 stone
fill ~36 ~7 ~81 ~36 ~11 ~82 stone
fill ~61 ~7 ~81 ~63 ~11 ~81 stone
fill ~84 ~7 ~81 ~84 ~10 ~81 stone_bricks
fill ~83 ~7 ~82 ~83 ~8 ~82 stone
fill ~16 ~7 ~83 ~18 ~8 ~83 stone
fill ~80 ~7 ~83 ~82 ~8 ~83 stone
fill ~17 ~7 ~84 ~17 ~10 ~84 stone_bricks
fill ~81 ~7 ~84 ~81 ~10 ~84 stone_bricks
fill ~28 ~7 ~88 ~28 ~11 ~88 stone
fill ~70 ~7 ~88 ~71 ~7 ~91 stone
fill ~26 ~7 ~89 ~27 ~7 ~93 stone
fill ~29 ~7 ~89 ~29 ~9 ~89 stone
fill ~69 ~7 ~89 ~72 ~7 ~90 stone
fill ~24 ~7 ~90 ~27 ~7 ~92 stone
fill ~74 ~7 ~90 ~74 ~11 ~91 stone
fill ~23 ~7 ~91 ~23 ~10 ~91 stone_bricks
setblock ~28 ~7 ~91 stone
fill ~75 ~7 ~91 ~75 ~10 ~91 stone_bricks
fill ~74 ~7 ~92 ~74 ~8 ~92 stone
fill ~25 ~7 ~93 ~27 ~8 ~93 stone
fill ~71 ~7 ~93 ~73 ~8 ~93 stone
fill ~26 ~7 ~94 ~26 ~10 ~94 stone_bricks
fill ~72 ~7 ~94 ~72 ~10 ~94 stone_bricks
fill ~28 ~8 ~4 ~28 ~9 ~4 birch_leaves[persistent=false]
fill ~70 ~8 ~4 ~70 ~9 ~4 birch_leaves[persistent=false]
fill ~25 ~8 ~5 ~27 ~8 ~5 stone
fill ~71 ~8 ~5 ~72 ~11 ~5 stone
setblock ~73 ~8 ~5 stone
fill ~24 ~8 ~6 ~24 ~8 ~8 stone
setblock ~25 ~8 ~6 stone_slab[type=double]
fill ~26 ~8 ~6 ~27 ~8 ~8 stone_slab[type=bottom]
setblock ~28 ~8 ~6 stone
fill ~70 ~8 ~6 ~70 ~11 ~6 stone
fill ~71 ~8 ~6 ~72 ~8 ~8 stone_slab[type=bottom]
setblock ~73 ~8 ~6 stone_slab[type=double]
fill ~25 ~8 ~7 ~27 ~8 ~8 stone_slab[type=bottom]
setblock ~28 ~8 ~7 iron_ore
setblock ~70 ~8 ~7 iron_ore
fill ~73 ~8 ~7 ~73 ~8 ~8 stone_slab[type=bottom]
fill ~28 ~8 ~8 ~28 ~8 ~9 stone_slab[type=bottom]
setblock ~29 ~8 ~8 stone_slab[type=double]
fill ~30 ~8 ~8 ~30 ~11 ~8 stone
fill ~68 ~8 ~8 ~68 ~11 ~8 stone
fill ~70 ~8 ~8 ~73 ~8 ~8 stone_slab[type=bottom]
fill ~74 ~8 ~8 ~74 ~11 ~8 stone
fill ~23 ~8 ~9 ~23 ~9 ~9 birch_leaves[persistent=false]
fill ~25 ~8 ~9 ~25 ~11 ~9 stone
setblock ~26 ~8 ~9 iron_ore
fill ~27 ~8 ~9 ~28 ~8 ~9 stone_slab[type=bottom]
fill ~29 ~8 ~9 ~29 ~11 ~9 stone
fill ~69 ~8 ~9 ~69 ~9 ~9 stone
fill ~70 ~8 ~9 ~71 ~8 ~9 stone_slab[type=bottom]
setblock ~72 ~8 ~9 iron_ore
setblock ~73 ~8 ~9 stone
fill ~75 ~8 ~9 ~75 ~9 ~9 birch_leaves[persistent=false]
fill ~28 ~8 ~10 ~28 ~9 ~10 stone
setblock ~71 ~8 ~10 stone_slab[type=double]
fill ~27 ~8 ~11 ~27 ~11 ~11 stone
fill ~71 ~8 ~11 ~71 ~11 ~11 stone
fill ~19 ~8 ~14 ~19 ~9 ~14 birch_leaves[persistent=false]
fill ~79 ~8 ~14 ~79 ~9 ~14 birch_leaves[persistent=false]
fill ~16 ~8 ~15 ~18 ~8 ~15 stone
fill ~80 ~8 ~15 ~81 ~11 ~15 stone
setblock ~82 ~8 ~15 stone
fill ~15 ~8 ~16 ~15 ~8 ~18 stone
setblock ~16 ~8 ~16 stone_slab[type=double]
fill ~17 ~8 ~16 ~18 ~8 ~18 stone_slab[type=bottom]
setblock ~19 ~8 ~16 stone
fill ~36 ~8 ~16 ~36 ~11 ~32 stone
fill ~61 ~8 ~16 ~62 ~11 ~16 stone
fill ~79 ~8 ~16 ~79 ~11 ~16 stone
fill ~80 ~8 ~16 ~81 ~8 ~18 stone_slab[type=bottom]
setblock ~82 ~8 ~16 stone_slab[type=double]
fill ~16 ~8 ~17 ~18 ~8 ~18 stone_slab[type=bottom]
setblock ~19 ~8 ~17 iron_ore
setblock ~79 ~8 ~17 iron_ore
fill ~82 ~8 ~17 ~82 ~8 ~18 stone_slab[type=bottom]
fill ~19 ~8 ~18 ~19 ~8 ~19 stone_slab[type=bottom]
setblock ~20 ~8 ~18 stone_slab[type=double]
fill ~21 ~8 ~18 ~21 ~11 ~18 stone
fill ~35 ~8 ~18 ~36 ~11 ~18 stone
fill ~62 ~8 ~18 ~62 ~11 ~32 stone
fill ~77 ~8 ~18 ~77 ~11 ~18 stone
fill ~79 ~8 ~18 ~82 ~8 ~18 stone_slab[type=bottom]
fill ~83 ~8 ~18 ~83 ~11 ~18 stone
fill ~14 ~8 ~19 ~14 ~9 ~19 birch_leaves[persistent=false]
fill ~16 ~8 ~19 ~16 ~11 ~19 stone
setblock ~17 ~8 ~19 iron_ore
fill ~18 ~8 ~19 ~19 ~8 ~19 stone_slab[type=bottom]
fill ~20 ~8 ~19 ~20 ~11 ~19 stone
fill ~78 ~8 ~19 ~78 ~9 ~19 stone
fill ~79 ~8 ~19 ~80 ~8 ~19 stone_slab[type=bottom]
setblock ~81 ~8 ~19 iron_ore
setblock ~82 ~8 ~19 stone
fill ~84 ~8 ~19 ~84 ~9 ~19 birch_leaves[persistent=false]
fill ~19 ~8 ~20 ~19 ~9 ~20 stone
fill ~35 ~8 ~20 ~36 ~11 ~32 stone
setblock ~80 ~8 ~20 stone_slab[type=double]
fill ~18 ~8 ~21 ~18 ~11 ~21 stone
fill ~80 ~8 ~21 ~80 ~11 ~21 stone
fill ~61 ~8 ~22 ~63 ~11 ~32 stone
fill ~9 ~8 ~23 ~9 ~9 ~23 birch_leaves[persistent=false]
fill ~34 ~8 ~23 ~36 ~12 ~31 stone
fill ~48 ~8 ~23 ~50 ~13 ~23 stone
fill ~89 ~8 ~23 ~89 ~9 ~23 birch_leaves[persistent=false]
fill ~6 ~8 ~24 ~8 ~8 ~24 stone
fill ~64 ~8 ~24 ~64 ~12 ~34 stone
fill ~90 ~8 ~24 ~91 ~11 ~24 stone
setblock ~92 ~8 ~24 stone
fill ~5 ~8 ~25 ~5 ~8 ~27 stone
setblock ~6 ~8 ~25 stone_slab[type=double]
fill ~7 ~8 ~25 ~8 ~8 ~27 stone_slab[type=bottom]
setblock ~9 ~8 ~25 stone
fill ~33 ~8 ~25 ~36 ~12 ~31 stone
fill ~60 ~8 ~25 ~65 ~12 ~31 stone
fill ~89 ~8 ~25 ~89 ~11 ~25 stone
fill ~90 ~8 ~25 ~91 ~8 ~27 stone_slab[type=bottom]
setblock ~92 ~8 ~25 stone_slab[type=double]
fill ~6 ~8 ~26 ~8 ~8 ~27 stone_slab[type=bottom]
setblock ~9 ~8 ~26 iron_ore
fill ~32 ~8 ~26 ~37 ~12 ~31 stone
fill ~66 ~8 ~26 ~66 ~11 ~38 stone
setblock ~89 ~8 ~26 iron_ore
fill ~92 ~8 ~26 ~92 ~8 ~27 stone_slab[type=bottom]
fill ~9 ~8 ~27 ~9 ~8 ~28 stone_slab[type=bottom]
setblock ~10 ~8 ~27 stone_slab[type=double]
fill ~11 ~8 ~27 ~11 ~11 ~27 stone
fill ~28 ~8 ~27 ~28 ~11 ~38 stone
fill ~31 ~8 ~27 ~37 ~11 ~32 stone
fill ~67 ~8 ~27 ~68 ~11 ~38 stone
fill ~69 ~8 ~27 ~70 ~11 ~37 stone
fill ~87 ~8 ~27 ~87 ~11 ~27 stone
fill ~89 ~8 ~27 ~92 ~8 ~27 stone_slab[type=bottom]
fill ~93 ~8 ~27 ~93 ~11 ~27 stone
fill ~4 ~8 ~28 ~4 ~9 ~28 birch_leaves[persistent=false]
fill ~6 ~8 ~28 ~6 ~11 ~28 stone
setblock ~7 ~8 ~28 iron_ore
fill ~8 ~8 ~28 ~9 ~8 ~28 stone_slab[type=bottom]
fill ~10 ~8 ~28 ~10 ~11 ~28 stone
fill ~30 ~8 ~28 ~37 ~11 ~32 stone
fill ~71 ~8 ~28 ~71 ~11 ~28 stone
fill ~88 ~8 ~28 ~88 ~9 ~28 stone
fill ~89 ~8 ~28 ~90 ~8 ~28 stone_slab[type=bottom]
setblock ~91 ~8 ~28 iron_ore
setblock ~92 ~8 ~28 stone
fill ~94 ~8 ~28 ~94 ~9 ~28 birch_leaves[persistent=false]
fill ~9 ~8 ~29 ~9 ~9 ~29 stone
fill ~27 ~8 ~29 ~32 ~11 ~38 stone
setblock ~90 ~8 ~29 stone_slab[type=double]
fill ~8 ~8 ~30 ~8 ~11 ~30 stone
fill ~38 ~8 ~30 ~38 ~12 ~32 stone
fill ~55 ~8 ~30 ~55 ~10 ~30 birch_leaves[persistent=false]
fill ~59 ~8 ~30 ~70 ~11 ~32 stone
fill ~90 ~8 ~30 ~90 ~11 ~30 stone
fill ~71 ~8 ~31 ~71 ~11 ~37 stone
fill ~26 ~8 ~32 ~31 ~12 ~38 stone
fill ~58 ~8 ~32 ~72 ~10 ~33 stone
fill ~25 ~8 ~33 ~31 ~12 ~38 stone
fill ~36 ~8 ~33 ~37 ~10 ~33 stone
fill ~39 ~8 ~33 ~39 ~13 ~34 stone
fill ~55 ~8 ~33 ~58 ~10 ~41 stone
fill ~73 ~8 ~33 ~73 ~12 ~36 stone
fill ~24 ~8 ~34 ~31 ~12 ~37 stone
fill ~35 ~8 ~34 ~35 ~11 ~34 stone
fill ~36 ~8 ~34 ~37 ~10 ~34 stone_bricks
fill ~40 ~8 ~34 ~41 ~10 ~43 stone
fill ~53 ~8 ~34 ~58 ~10 ~40 stone
fill ~74 ~8 ~34 ~75 ~12 ~36 stone
fill ~22 ~8 ~35 ~32 ~11 ~37 stone
setblock ~38 ~8 ~35 mossy_stone_bricks
fill ~39 ~8 ~35 ~42 ~11 ~35 stone
fill ~50 ~8 ~35 ~58 ~10 ~37 stone
setblock ~60 ~8 ~35 stone_bricks
fill ~64 ~8 ~35 ~78 ~11 ~35 stone
fill ~80 ~8 ~35 ~81 ~11 ~36 stone
fill ~18 ~8 ~36 ~32 ~11 ~36 stone
fill ~42 ~8 ~36 ~44 ~10 ~40 stone
fill ~48 ~8 ~36 ~58 ~10 ~37 stone
fill ~59 ~8 ~36 ~59 ~10 ~37 stone_bricks
fill ~64 ~8 ~36 ~64 ~10 ~37 stone_bricks
fill ~65 ~8 ~36 ~82 ~10 ~36 stone
fill ~16 ~8 ~37 ~16 ~12 ~37 stone
fill ~45 ~8 ~37 ~58 ~10 ~37 stone
fill ~65 ~8 ~37 ~72 ~10 ~37 stone
setblock ~35 ~8 ~38 stone_bricks
fill ~46 ~8 ~38 ~47 ~10 ~39 stone
fill ~48 ~8 ~38 ~48 ~10 ~38 stone
fill ~51 ~8 ~38 ~59 ~10 ~38 stone
setblock ~63 ~8 ~38 mossy_stone_bricks
fill ~30 ~8 ~39 ~34 ~13 ~39 stone
fill ~36 ~8 ~39 ~37 ~10 ~39 stone_bricks
fill ~45 ~8 ~39 ~47 ~10 ~39 stone
fill ~63 ~8 ~39 ~63 ~11 ~42 stone
fill ~64 ~8 ~39 ~64 ~13 ~41 stone
fill ~65 ~8 ~39 ~65 ~13 ~39 stone
fill ~32 ~8 ~40 ~44 ~10 ~40 stone
fill ~62 ~8 ~40 ~64 ~10 ~41 stone
fill ~33 ~8 ~41 ~41 ~10 ~43 stone
fill ~42 ~8 ~41 ~42 ~12 ~41 stone
fill ~57 ~8 ~42 ~63 ~10 ~42 stone
fill ~30 ~8 ~43 ~30 ~10 ~43 birch_leaves[persistent=false]
fill ~58 ~8 ~43 ~62 ~10 ~44 stone
fill ~34 ~8 ~44 ~38 ~10 ~46 stone
fill ~39 ~8 ~44 ~40 ~11 ~45 stone
setblock ~44 ~8 ~44 diorite
setblock ~54 ~8 ~44 diorite
fill ~59 ~8 ~45 ~61 ~10 ~47 stone
fill ~35 ~8 ~47 ~37 ~10 ~48 stone
fill ~38 ~8 ~47 ~38 ~10 ~47 stone
fill ~62 ~8 ~47 ~62 ~10 ~58 stone
fill ~23 ~8 ~48 ~23 ~13 ~50 stone
fill ~48 ~8 ~48 ~49 ~11 ~49 stone
fill ~60 ~8 ~48 ~62 ~10 ~48 stone
fill ~75 ~8 ~48 ~75 ~13 ~50 stone
fill ~36 ~8 ~49 ~37 ~10 ~51 stone
fill ~61 ~8 ~49 ~63 ~10 ~58 stone
fill ~38 ~8 ~50 ~38 ~10 ~59 stone
fill ~49 ~8 ~50 ~49 ~11 ~50 stone
fill ~39 ~8 ~51 ~39 ~10 ~60 stone
fill ~60 ~8 ~51 ~63 ~10 ~58 stone
fill ~37 ~8 ~52 ~39 ~10 ~58 stone
fill ~58 ~8 ~53 ~64 ~10 ~58 stone
fill ~36 ~8 ~54 ~40 ~10 ~58 stone
setblock ~44 ~8 ~54 diorite
setblock ~54 ~8 ~54 diorite
fill ~57 ~8 ~55 ~65 ~10 ~58 stone
fill ~68 ~8 ~55 ~68 ~10 ~55 birch_leaves[persistent=false]
fill ~35 ~8 ~56 ~41 ~10 ~58 stone
fill ~34 ~8 ~57 ~43 ~10 ~58 stone
fill ~56 ~8 ~57 ~58 ~10 ~63 stone
fill ~44 ~8 ~58 ~45 ~10 ~64 stone
fill ~54 ~8 ~58 ~58 ~10 ~62 stone
fill ~66 ~8 ~58 ~66 ~11 ~72 stone
fill ~33 ~8 ~59 ~35 ~11 ~59 stone
fill ~43 ~8 ~59 ~45 ~10 ~64 stone
fill ~51 ~8 ~59 ~58 ~10 ~61 stone
fill ~62 ~8 ~59 ~62 ~10 ~59 stone_bricks
fill ~67 ~8 ~59 ~68 ~11 ~70 stone
fill ~30 ~8 ~60 ~32 ~11 ~71 stone
setblock ~35 ~8 ~60 mossy_stone_bricks
fill ~46 ~8 ~60 ~47 ~10 ~63 stone
fill ~49 ~8 ~60 ~59 ~10 ~60 stone
setblock ~63 ~8 ~60 stone_bricks
fill ~70 ~8 ~60 ~73 ~12 ~65 stone
fill ~26 ~8 ~61 ~31 ~12 ~66 stone
fill ~33 ~8 ~61 ~33 ~10 ~73 stone
fill ~34 ~8 ~61 ~34 ~10 ~62 stone_bricks
fill ~48 ~8 ~61 ~58 ~10 ~61 stone
fill ~74 ~8 ~61 ~76 ~11 ~63 stone
fill ~82 ~8 ~61 ~82 ~11 ~62 stone
fill ~16 ~8 ~62 ~32 ~11 ~62 stone
fill ~39 ~8 ~62 ~39 ~10 ~62 stone_bricks
fill ~48 ~8 ~62 ~50 ~10 ~62 stone
fill ~78 ~8 ~62 ~82 ~11 ~62 stone
fill ~18 ~8 ~63 ~18 ~11 ~63 stone
fill ~20 ~8 ~63 ~34 ~11 ~63 stone
setblock ~38 ~8 ~63 stone_bricks
fill ~48 ~8 ~63 ~48 ~11 ~63 stone
fill ~59 ~8 ~63 ~59 ~11 ~65 stone
setblock ~60 ~8 ~63 mossy_stone_bricks
fill ~23 ~8 ~64 ~34 ~12 ~64 stone
fill ~57 ~8 ~64 ~59 ~13 ~64 stone
fill ~61 ~8 ~64 ~62 ~10 ~64 stone_bricks
fill ~63 ~8 ~64 ~63 ~11 ~78 stone
fill ~74 ~8 ~64 ~74 ~12 ~64 stone
fill ~25 ~8 ~65 ~43 ~10 ~65 stone
fill ~61 ~8 ~65 ~66 ~10 ~72 stone
fill ~39 ~8 ~66 ~39 ~13 ~68 stone
fill ~40 ~8 ~66 ~40 ~13 ~66 stone
fill ~60 ~8 ~66 ~71 ~11 ~68 stone
fill ~72 ~8 ~66 ~72 ~12 ~66 stone
fill ~27 ~8 ~67 ~39 ~11 ~67 stone
fill ~8 ~8 ~68 ~8 ~11 ~68 stone
fill ~28 ~8 ~68 ~38 ~11 ~71 stone
fill ~43 ~8 ~68 ~43 ~10 ~68 birch_leaves[persistent=false]
fill ~90 ~8 ~68 ~90 ~11 ~68 stone
setblock ~8 ~8 ~69 stone_slab[type=double]
fill ~71 ~8 ~69 ~71 ~11 ~71 stone
fill ~89 ~8 ~69 ~89 ~9 ~69 stone
fill ~4 ~8 ~70 ~4 ~9 ~70 birch_leaves[persistent=false]
setblock ~6 ~8 ~70 stone
setblock ~7 ~8 ~70 iron_ore
fill ~8 ~8 ~70 ~9 ~8 ~71 stone_slab[type=bottom]
fill ~27 ~8 ~70 ~38 ~11 ~71 stone
fill ~88 ~8 ~70 ~88 ~11 ~70 stone
fill ~89 ~8 ~70 ~90 ~8 ~71 stone_slab[type=bottom]
setblock ~91 ~8 ~70 iron_ore
fill ~92 ~8 ~70 ~92 ~11 ~70 stone
fill ~94 ~8 ~70 ~94 ~9 ~70 birch_leaves[persistent=false]
fill ~5 ~8 ~71 ~5 ~11 ~71 stone
fill ~6 ~8 ~71 ~8 ~8 ~72 stone_slab[type=bottom]
fill ~11 ~8 ~71 ~11 ~11 ~71 stone
fill ~67 ~8 ~71 ~67 ~11 ~71 stone
fill ~70 ~8 ~71 ~71 ~11 ~71 stone
fill ~87 ~8 ~71 ~87 ~11 ~71 stone
setblock ~88 ~8 ~71 stone_slab[type=double]
fill ~91 ~8 ~71 ~92 ~8 ~72 stone_slab[type=bottom]
fill ~5 ~8 ~72 ~5 ~9 ~72 stone
setblock ~9 ~8 ~72 iron_ore
fill ~32 ~8 ~72 ~38 ~12 ~72 stone
setblock ~89 ~8 ~72 iron_ore
fill ~90 ~8 ~72 ~91 ~8 ~73 stone_slab[type=bottom]
setblock ~5 ~8 ~73 stone
setblock ~6 ~8 ~73 stone_slab[type=double]
fill ~7 ~8 ~73 ~8 ~8 ~73 stone_slab[type=bottom]
fill ~9 ~8 ~73 ~9 ~11 ~73 stone
fill ~34 ~8 ~73 ~37 ~12 ~74 stone
fill ~38 ~8 ~73 ~38 ~13 ~73 stone
fill ~62 ~8 ~73 ~64 ~12 ~75 stone
fill ~65 ~8 ~73 ~65 ~12 ~73 stone
setblock ~89 ~8 ~73 stone
setblock ~92 ~8 ~73 stone_slab[type=double]
fill ~9 ~8 ~75 ~9 ~9 ~75 birch_leaves[persistent=false]
fill ~35 ~8 ~75 ~37 ~11 ~76 stone
fill ~48 ~8 ~75 ~50 ~13 ~75 stone
fill ~89 ~8 ~75 ~89 ~9 ~75 birch_leaves[persistent=false]
fill ~62 ~8 ~76 ~62 ~11 ~82 stone
fill ~18 ~8 ~77 ~18 ~11 ~77 stone
fill ~80 ~8 ~77 ~80 ~11 ~77 stone
setblock ~18 ~8 ~78 stone_slab[type=double]
fill ~36 ~8 ~78 ~36 ~11 ~82 stone
fill ~79 ~8 ~78 ~79 ~9 ~78 stone
fill ~14 ~8 ~79 ~14 ~9 ~79 birch_leaves[persistent=false]
setblock ~16 ~8 ~79 stone
setblock ~17 ~8 ~79 iron_ore
fill ~18 ~8 ~79 ~19 ~8 ~80 stone_slab[type=bottom]
fill ~78 ~8 ~79 ~78 ~11 ~79 stone
fill ~79 ~8 ~79 ~80 ~8 ~80 stone_slab[type=bottom]
setblock ~81 ~8 ~79 iron_ore
fill ~82 ~8 ~79 ~82 ~11 ~79 stone
fill ~84 ~8 ~79 ~84 ~9 ~79 birch_leaves[persistent=false]
fill ~15 ~8 ~80 ~15 ~11 ~80 stone
fill ~16 ~8 ~80 ~18 ~8 ~81 stone_slab[type=bottom]
fill ~21 ~8 ~80 ~21 ~11 ~80 stone
fill ~63 ~8 ~80 ~63 ~11 ~81 stone
fill ~77 ~8 ~80 ~77 ~11 ~80 stone
setblock ~78 ~8 ~80 stone_slab[type=double]
fill ~81 ~8 ~80 ~82 ~8 ~81 stone_slab[type=bottom]
fill ~15 ~8 ~81 ~15 ~9 ~81 stone
setblock ~19 ~8 ~81 iron_ore
setblock ~79 ~8 ~81 iron_ore
fill ~80 ~8 ~81 ~81 ~8 ~82 stone_slab[type=bottom]
setblock ~15 ~8 ~82 stone
setblock ~16 ~8 ~82 stone_slab[type=double]
fill ~17 ~8 ~82 ~18 ~8 ~82 stone_slab[type=bottom]
fill ~19 ~8 ~82 ~19 ~11 ~82 stone
fill ~37 ~8 ~82 ~37 ~12 ~82 stone
setblock ~79 ~8 ~82 stone
setblock ~82 ~8 ~82 stone_slab[type=double]
fill ~19 ~8 ~84 ~19 ~9 ~84 birch_leaves[persistent=false]
fill ~79 ~8 ~84 ~79 ~9 ~84 birch_leaves[persistent=false]
fill ~27 ~8 ~87 ~27 ~11 ~87 stone
fill ~71 ~8 ~87 ~71 ~11 ~87 stone
setblock ~27 ~8 ~88 stone_slab[type=double]
fill ~70 ~8 ~88 ~70 ~9 ~88 stone
fill ~23 ~8 ~89 ~23 ~9 ~89 birch_leaves[persistent=false]
setblock ~25 ~8 ~89 stone
setblock ~26 ~8 ~89 iron_ore
fill ~27 ~8 ~89 ~28 ~8 ~90 stone_slab[type=bottom]
fill ~69 ~8 ~89 ~69 ~11 ~89 stone
fill ~70 ~8 ~89 ~71 ~8 ~90 stone_slab[type=bottom]
setblock ~72 ~8 ~89 iron_ore
fill ~73 ~8 ~89 ~73 ~11 ~89 stone
fill ~75 ~8 ~89 ~75 ~9 ~89 birch_leaves[persistent=false]
fill ~24 ~8 ~90 ~24 ~11 ~90 stone
fill ~25 ~8 ~90 ~27 ~8 ~91 stone_slab[type=bottom]
fill ~30 ~8 ~90 ~30 ~11 ~90 stone
fill ~68 ~8 ~90 ~68 ~11 ~90 stone
setblock ~69 ~8 ~90 stone_slab[type=double]
fill ~72 ~8 ~90 ~73 ~8 ~91 stone_slab[type=bottom]
fill ~24 ~8 ~91 ~24 ~9 ~91 stone
setblock ~28 ~8 ~91 iron_ore
setblock ~70 ~8 ~91 iron_ore
fill ~71 ~8 ~91 ~72 ~8 ~92 stone_slab[type=bottom]
setblock ~24 ~8 ~92 stone
setblock ~25 ~8 ~92 stone_slab[type=double]
fill ~26 ~8 ~92 ~27 ~8 ~92 stone_slab[type=bottom]
fill ~28 ~8 ~92 ~28 ~11 ~92 stone
setblock ~70 ~8 ~92 stone
setblock ~73 ~8 ~92 stone_slab[type=double]
fill ~28 ~8 ~94 ~28 ~9 ~94 birch_leaves[persistent=false]
fill ~70 ~8 ~94 ~70 ~9 ~94 birch_leaves[persistent=false]
fill ~28 ~9 ~3 ~28 ~11 ~3 birch_leaves[persistent=false]
setblock ~25 ~9 ~4 stone
fill ~69 ~9 ~4 ~69 ~11 ~4 birch_leaves[persistent=false]
setblock ~73 ~9 ~4 stone
fill ~25 ~9 ~5 ~25 ~12 ~5 stone_bricks
fill ~26 ~9 ~5 ~27 ~9 ~5 stone
fill ~28 ~9 ~5 ~28 ~13 ~5 stone_bricks
fill ~70 ~9 ~5 ~70 ~13 ~5 stone_bricks
fill ~73 ~9 ~5 ~73 ~12 ~5 stone_bricks
setblock ~23 ~9 ~6 stone
fill ~24 ~9 ~6 ~24 ~12 ~6 stone_bricks
setblock ~28 ~9 ~6 iron_ore
fill ~74 ~9 ~6 ~74 ~12 ~6 stone_bricks
setblock ~75 ~9 ~6 stone
fill ~24 ~9 ~7 ~24 ~11 ~8 stone
setblock ~28 ~9 ~7 chest[type=single,facing=west]{isMovable:1}
setblock ~29 ~9 ~7 coal_ore
fill ~31 ~9 ~7 ~31 ~10 ~7 birch_leaves[persistent=false]
setblock ~69 ~9 ~7 coal_ore
setblock ~29 ~9 ~8 furnace[lit=false,facing=west]{isMovable:1}
setblock ~69 ~9 ~8 crafting_table
fill ~24 ~9 ~9 ~24 ~13 ~9 stone_bricks
fill ~30 ~9 ~9 ~30 ~10 ~10 stone
fill ~68 ~9 ~9 ~69 ~9 ~10 stone
setblock ~72 ~9 ~9 chest[type=single,facing=north]{isMovable:1}
setblock ~73 ~9 ~9 iron_ore
fill ~74 ~9 ~9 ~74 ~13 ~9 stone_bricks
fill ~76 ~9 ~9 ~76 ~11 ~9 birch_leaves[persistent=false]
fill ~23 ~9 ~10 ~23 ~11 ~10 birch_leaves[persistent=false]
setblock ~26 ~9 ~10 coal_ore
setblock ~27 ~9 ~10 crafting_table
fill ~29 ~9 ~10 ~30 ~10 ~10 stone
setblock ~71 ~9 ~10 furnace[lit=false,facing=north]{isMovable:1}
setblock ~72 ~9 ~10 coal_ore
fill ~28 ~9 ~11 ~29 ~10 ~11 stone
fill ~69 ~9 ~11 ~71 ~10 ~11 stone
fill ~72 ~9 ~12 ~72 ~10 ~12 birch_leaves[persistent=false]
fill ~19 ~9 ~13 ~19 ~11 ~13 birch_leaves[persistent=false]
setblock ~16 ~9 ~14 stone
fill ~78 ~9 ~14 ~78 ~11 ~14 birch_leaves[persistent=false]
setblock ~82 ~9 ~14 stone
fill ~16 ~9 ~15 ~16 ~12 ~15 stone_bricks
fill ~17 ~9 ~15 ~18 ~9 ~15 stone
fill ~19 ~9 ~15 ~19 ~13 ~15 stone_bricks
fill ~37 ~9 ~15 ~37 ~11 ~18 stone
fill ~61 ~9 ~15 ~61 ~17 ~15 stone
fill ~79 ~9 ~15 ~79 ~13 ~15 stone_bricks
fill ~82 ~9 ~15 ~82 ~12 ~15 stone_bricks
setblock ~14 ~9 ~16 stone
fill ~15 ~9 ~16 ~15 ~12 ~16 stone_bricks
setblock ~19 ~9 ~16 iron_ore
fill ~63 ~9 ~16 ~63 ~11 ~16 stone
fill ~83 ~9 ~16 ~83 ~12 ~16 stone_bricks
setblock ~84 ~9 ~16 stone
fill ~15 ~9 ~17 ~15 ~11 ~18 stone
setblock ~19 ~9 ~17 chest[type=single,facing=west]{isMovable:1}
setblock ~20 ~9 ~17 coal_ore
fill ~22 ~9 ~17 ~22 ~10 ~17 birch_leaves[persistent=false]
setblock ~78 ~9 ~17 coal_ore
setblock ~20 ~9 ~18 furnace[lit=false,facing=west]{isMovable:1}
setblock ~78 ~9 ~18 crafting_table
fill ~15 ~9 ~19 ~15 ~13 ~19 stone_bricks
fill ~21 ~9 ~19 ~21 ~10 ~20 stone
fill ~61 ~9 ~19 ~62 ~11 ~32 stone
fill ~77 ~9 ~19 ~78 ~9 ~20 stone
setblock ~81 ~9 ~19 chest[type=single,facing=north]{isMovable:1}
setblock ~82 ~9 ~19 iron_ore
fill ~83 ~9 ~19 ~83 ~13 ~19 stone_bricks
fill ~85 ~9 ~19 ~85 ~11 ~19 birch_leaves[persistent=false]
fill ~14 ~9 ~20 ~14 ~11 ~20 birch_leaves[persistent=false]
setblock ~17 ~9 ~20 coal_ore
setblock ~18 ~9 ~20 crafting_table
fill ~20 ~9 ~20 ~21 ~10 ~20 stone
fill ~37 ~9 ~20 ~37 ~11 ~32 stone
fill ~60 ~9 ~20 ~63 ~11 ~32 stone
setblock ~80 ~9 ~20 furnace[lit=false,facing=north]{isMovable:1}
setblock ~81 ~9 ~20 coal_ore
fill ~19 ~9 ~21 ~20 ~10 ~21 stone
fill ~34 ~9 ~21 ~37 ~11 ~32 stone
fill ~64 ~9 ~21 ~64 ~11 ~35 stone
fill ~78 ~9 ~21 ~80 ~10 ~21 stone
fill ~9 ~9 ~22 ~9 ~11 ~22 birch_leaves[persistent=false]
fill ~49 ~9 ~22 ~49 ~13 ~24 stone
fill ~81 ~9 ~22 ~81 ~10 ~22 birch_leaves[persistent=false]
setblock ~6 ~9 ~23 stone
fill ~33 ~9 ~23 ~37 ~12 ~31 stone
fill ~47 ~9 ~23 ~51 ~13 ~23 stone
fill ~65 ~9 ~23 ~65 ~12 ~34 stone
fill ~88 ~9 ~23 ~88 ~11 ~23 birch_leaves[persistent=false]
setblock ~92 ~9 ~23 stone
fill ~6 ~9 ~24 ~6 ~12 ~24 stone_bricks
fill ~7 ~9 ~24 ~8 ~9 ~24 stone
fill ~9 ~9 ~24 ~9 ~13 ~24 stone_bricks
fill ~32 ~9 ~24 ~37 ~9 ~33 stone
fill ~89 ~9 ~24 ~89 ~13 ~24 stone_bricks
fill ~92 ~9 ~24 ~92 ~12 ~24 stone_bricks
setblock ~4 ~9 ~25 stone
fill ~5 ~9 ~25 ~5 ~12 ~25 stone_bricks
setblock ~9 ~9 ~25 iron_ore
fill ~31 ~9 ~25 ~31 ~11 ~25 polished_andesite
fill ~38 ~9 ~25 ~38 ~11 ~34 stone
fill ~66 ~9 ~25 ~66 ~11 ~41 stone
fill ~67 ~9 ~25 ~67 ~11 ~25 polished_andesite
fill ~93 ~9 ~25 ~93 ~12 ~25 stone_bricks
setblock ~94 ~9 ~25 stone
fill ~5 ~9 ~26 ~5 ~11 ~27 stone
setblock ~9 ~9 ~26 chest[type=single,facing=west]{isMovable:1}
setblock ~10 ~9 ~26 coal_ore
fill ~12 ~9 ~26 ~12 ~10 ~26 birch_leaves[persistent=false]
fill ~30 ~9 ~26 ~38 ~10 ~33 stone
fill ~59 ~9 ~26 ~69 ~10 ~33 stone
setblock ~88 ~9 ~26 coal_ore
setblock ~10 ~9 ~27 furnace[lit=false,facing=west]{isMovable:1}
fill ~29 ~9 ~27 ~38 ~11 ~32 stone
setblock ~88 ~9 ~27 crafting_table
fill ~5 ~9 ~28 ~5 ~13 ~28 stone_bricks
fill ~11 ~9 ~28 ~11 ~10 ~29 stone
fill ~39 ~9 ~28 ~39 ~13 ~34 stone
fill ~87 ~9 ~28 ~88 ~9 ~29 stone
setblock ~91 ~9 ~28 chest[type=single,facing=north]{isMovable:1}
setblock ~92 ~9 ~28 iron_ore
fill ~93 ~9 ~28 ~93 ~13 ~28 stone_bricks
fill ~95 ~9 ~28 ~95 ~11 ~28 birch_leaves[persistent=false]
fill ~4 ~9 ~29 ~4 ~11 ~29 birch_leaves[persistent=false]
setblock ~7 ~9 ~29 coal_ore
setblock ~8 ~9 ~29 crafting_table
fill ~10 ~9 ~29 ~11 ~10 ~29 stone
fill ~26 ~9 ~29 ~33 ~10 ~39 stone
fill ~58 ~9 ~29 ~71 ~11 ~32 stone
setblock ~90 ~9 ~29 furnace[lit=false,facing=north]{isMovable:1}
setblock ~91 ~9 ~29 coal_ore
fill ~9 ~9 ~30 ~10 ~10 ~30 stone
fill ~43 ~9 ~30 ~43 ~10 ~30 birch_leaves[persistent=false]
fill ~72 ~9 ~30 ~72 ~10 ~38 stone
fill ~88 ~9 ~30 ~90 ~10 ~30 stone
fill ~25 ~9 ~31 ~25 ~11 ~31 polished_andesite
fill ~40 ~9 ~31 ~40 ~10 ~69 stone
fill ~57 ~9 ~31 ~72 ~11 ~32 stone
fill ~73 ~9 ~31 ~73 ~11 ~31 polished_andesite
fill ~91 ~9 ~31 ~91 ~10 ~31 birch_leaves[persistent=false]
fill ~25 ~9 ~32 ~31 ~12 ~38 stone
fill ~41 ~9 ~32 ~41 ~13 ~34 stone
fill ~55 ~9 ~32 ~58 ~10 ~43 stone
fill ~73 ~9 ~32 ~73 ~11 ~38 stone
fill ~74 ~9 ~32 ~74 ~9 ~37 stone
fill ~23 ~9 ~33 ~31 ~12 ~38 stone
fill ~42 ~9 ~33 ~43 ~10 ~43 stone
fill ~52 ~9 ~33 ~59 ~13 ~34 stone
fill ~75 ~9 ~33 ~75 ~12 ~37 stone
fill ~21 ~9 ~34 ~32 ~11 ~38 stone
fill ~44 ~9 ~34 ~45 ~10 ~41 stone
fill ~49 ~9 ~34 ~58 ~10 ~40 stone
fill ~76 ~9 ~34 ~77 ~11 ~37 stone
fill ~16 ~9 ~35 ~16 ~11 ~37 stone
fill ~20 ~9 ~35 ~32 ~11 ~38 stone
fill ~38 ~9 ~35 ~38 ~10 ~35 stone_bricks
fill ~46 ~9 ~35 ~59 ~11 ~35 stone
fill ~60 ~9 ~35 ~60 ~11 ~35 mossy_stone_bricks
fill ~39 ~9 ~36 ~39 ~10 ~37 stone_bricks
fill ~46 ~9 ~36 ~58 ~10 ~40 stone
fill ~15 ~9 ~37 ~15 ~17 ~37 stone
fill ~19 ~9 ~37 ~32 ~11 ~37 stone
fill ~78 ~9 ~37 ~78 ~11 ~37 stone
fill ~80 ~9 ~37 ~83 ~11 ~37 stone
fill ~35 ~9 ~38 ~35 ~11 ~38 mossy_stone_bricks
fill ~63 ~9 ~38 ~63 ~10 ~38 stone_bricks
fill ~64 ~9 ~38 ~73 ~11 ~38 stone
fill ~62 ~9 ~39 ~62 ~11 ~39 stone_bricks
fill ~67 ~9 ~39 ~70 ~13 ~39 stone
fill ~29 ~9 ~40 ~67 ~10 ~40 stone
fill ~31 ~9 ~41 ~34 ~13 ~41 stone
setblock ~46 ~9 ~41 stone
fill ~52 ~9 ~41 ~66 ~9 ~41 stone
fill ~32 ~9 ~42 ~43 ~10 ~43 stone
fill ~44 ~9 ~42 ~44 ~10 ~42 stone
fill ~54 ~9 ~42 ~65 ~10 ~42 stone
fill ~63 ~9 ~43 ~63 ~11 ~59 stone
fill ~64 ~9 ~43 ~64 ~13 ~45 stone
fill ~65 ~9 ~43 ~65 ~13 ~43 stone
fill ~68 ~9 ~43 ~68 ~10 ~43 birch_leaves[persistent=false]
fill ~33 ~9 ~44 ~41 ~10 ~45 stone
fill ~42 ~9 ~44 ~42 ~10 ~44 stone
fill ~44 ~9 ~44 ~44 ~10 ~44 polished_diorite
fill ~54 ~9 ~44 ~54 ~10 ~44 polished_diorite
fill ~56 ~9 ~44 ~64 ~10 ~44 stone
setblock ~45 ~9 ~45 polished_diorite
setblock ~53 ~9 ~45 polished_diorite
fill ~57 ~9 ~45 ~64 ~10 ~45 stone
fill ~39 ~9 ~46 ~40 ~10 ~60 stone
setblock ~41 ~9 ~46 stone
fill ~57 ~9 ~46 ~63 ~9 ~46 stone
fill ~23 ~9 ~47 ~23 ~13 ~51 stone
fill ~34 ~9 ~47 ~40 ~10 ~47 stone
fill ~58 ~9 ~47 ~63 ~10 ~58 stone
fill ~75 ~9 ~47 ~75 ~13 ~51 stone
fill ~38 ~9 ~48 ~40 ~10 ~59 stone
fill ~50 ~9 ~48 ~50 ~11 ~50 stone
fill ~22 ~9 ~49 ~24 ~13 ~49 stone
fill ~35 ~9 ~49 ~40 ~10 ~58 stone
fill ~74 ~9 ~49 ~76 ~13 ~49 stone
fill ~64 ~9 ~50 ~64 ~11 ~60 stone
fill ~41 ~9 ~52 ~41 ~9 ~67 stone
fill ~57 ~9 ~52 ~65 ~9 ~58 stone
fill ~34 ~9 ~53 ~41 ~10 ~58 stone
setblock ~45 ~9 ~53 polished_diorite
setblock ~53 ~9 ~53 polished_diorite
fill ~42 ~9 ~54 ~42 ~10 ~66 stone
fill ~44 ~9 ~54 ~44 ~10 ~54 polished_diorite
fill ~54 ~9 ~54 ~54 ~10 ~54 polished_diorite
fill ~56 ~9 ~54 ~65 ~10 ~58 stone
fill ~30 ~9 ~55 ~30 ~10 ~55 birch_leaves[persistent=false]
fill ~33 ~9 ~55 ~43 ~10 ~58 stone
fill ~55 ~9 ~55 ~66 ~10 ~58 stone
fill ~44 ~9 ~56 ~44 ~10 ~65 stone
fill ~54 ~9 ~56 ~58 ~10 ~64 stone
fill ~32 ~9 ~57 ~33 ~10 ~73 stone
fill ~45 ~9 ~57 ~46 ~9 ~65 stone
fill ~52 ~9 ~57 ~58 ~9 ~63 stone
fill ~67 ~9 ~57 ~67 ~11 ~72 stone
fill ~31 ~9 ~58 ~33 ~10 ~72 stone
fill ~47 ~9 ~58 ~69 ~10 ~58 stone
fill ~28 ~9 ~59 ~32 ~11 ~71 stone
fill ~36 ~9 ~59 ~37 ~10 ~59 stone_bricks
fill ~47 ~9 ~59 ~60 ~10 ~59 stone
fill ~69 ~9 ~59 ~71 ~11 ~71 stone
fill ~72 ~9 ~59 ~72 ~10 ~69 stone
fill ~25 ~9 ~60 ~32 ~11 ~66 stone
fill ~34 ~9 ~60 ~34 ~11 ~60 stone
fill ~35 ~9 ~60 ~35 ~10 ~60 stone_bricks
fill ~48 ~9 ~60 ~58 ~10 ~63 stone
fill ~63 ~9 ~60 ~63 ~11 ~60 mossy_stone_bricks
fill ~74 ~9 ~60 ~78 ~11 ~63 stone
fill ~15 ~9 ~61 ~18 ~11 ~61 stone
fill ~20 ~9 ~61 ~32 ~11 ~63 stone
fill ~79 ~9 ~61 ~79 ~11 ~62 stone
fill ~83 ~9 ~61 ~83 ~17 ~61 stone
fill ~59 ~9 ~62 ~59 ~11 ~62 stone_bricks
fill ~38 ~9 ~63 ~38 ~11 ~63 mossy_stone_bricks
fill ~60 ~9 ~63 ~60 ~10 ~63 stone_bricks
fill ~82 ~9 ~63 ~82 ~11 ~63 stone
fill ~21 ~9 ~64 ~35 ~11 ~64 stone
fill ~47 ~9 ~64 ~47 ~13 ~64 stone
fill ~53 ~9 ~64 ~59 ~13 ~64 stone
fill ~60 ~9 ~64 ~60 ~11 ~73 stone
fill ~75 ~9 ~64 ~77 ~11 ~64 stone
fill ~23 ~9 ~65 ~46 ~10 ~65 stone
fill ~55 ~9 ~65 ~75 ~10 ~65 stone
fill ~24 ~9 ~66 ~43 ~9 ~66 stone
fill ~57 ~9 ~66 ~73 ~11 ~66 stone
fill ~7 ~9 ~67 ~7 ~10 ~67 birch_leaves[persistent=false]
fill ~25 ~9 ~67 ~25 ~11 ~67 polished_andesite
fill ~26 ~9 ~67 ~40 ~10 ~68 stone
fill ~58 ~9 ~67 ~72 ~11 ~67 stone
fill ~73 ~9 ~67 ~73 ~11 ~67 polished_andesite
fill ~9 ~9 ~68 ~10 ~10 ~69 stone
fill ~55 ~9 ~68 ~55 ~10 ~68 birch_leaves[persistent=false]
fill ~59 ~9 ~68 ~71 ~11 ~70 stone
fill ~88 ~9 ~68 ~90 ~10 ~68 stone
setblock ~7 ~9 ~69 coal_ore
setblock ~8 ~9 ~69 furnace[lit=false,facing=south]{isMovable:1}
fill ~11 ~9 ~69 ~11 ~10 ~71 stone
fill ~27 ~9 ~69 ~39 ~11 ~71 stone
fill ~87 ~9 ~69 ~88 ~10 ~70 stone
setblock ~90 ~9 ~69 crafting_table
setblock ~91 ~9 ~69 coal_ore
fill ~94 ~9 ~69 ~94 ~11 ~69 birch_leaves[persistent=false]
fill ~3 ~9 ~70 ~3 ~11 ~70 birch_leaves[persistent=false]
fill ~5 ~9 ~70 ~5 ~13 ~70 stone_bricks
setblock ~6 ~9 ~70 iron_ore
setblock ~7 ~9 ~70 chest[type=single,facing=south]{isMovable:1}
fill ~93 ~9 ~70 ~93 ~13 ~70 stone_bricks
setblock ~10 ~9 ~71 crafting_table
fill ~68 ~9 ~71 ~71 ~11 ~71 stone
setblock ~88 ~9 ~71 furnace[lit=false,facing=east]{isMovable:1}
setblock ~10 ~9 ~72 coal_ore
fill ~29 ~9 ~72 ~39 ~10 ~72 stone
fill ~68 ~9 ~72 ~68 ~10 ~72 stone
fill ~86 ~9 ~72 ~86 ~10 ~72 birch_leaves[persistent=false]
setblock ~88 ~9 ~72 coal_ore
setblock ~89 ~9 ~72 chest[type=single,facing=east]{isMovable:1}
setblock ~4 ~9 ~73 stone
fill ~5 ~9 ~73 ~5 ~12 ~73 stone_bricks
fill ~31 ~9 ~73 ~31 ~11 ~73 polished_andesite
fill ~61 ~9 ~73 ~65 ~12 ~75 stone
fill ~66 ~9 ~73 ~66 ~11 ~73 stone
fill ~67 ~9 ~73 ~67 ~11 ~73 polished_andesite
setblock ~89 ~9 ~73 iron_ore
fill ~93 ~9 ~73 ~93 ~12 ~73 stone_bricks
setblock ~94 ~9 ~73 stone
fill ~6 ~9 ~74 ~6 ~12 ~74 stone_bricks
fill ~8 ~9 ~74 ~8 ~11 ~74 stone
fill ~9 ~9 ~74 ~9 ~13 ~74 stone_bricks
fill ~33 ~9 ~74 ~38 ~12 ~75 stone
fill ~49 ~9 ~74 ~49 ~13 ~76 stone
setblock ~66 ~9 ~74 stone
fill ~89 ~9 ~74 ~89 ~13 ~74 stone_bricks
fill ~90 ~9 ~74 ~90 ~11 ~74 stone
fill ~92 ~9 ~74 ~92 ~12 ~74 stone_bricks
setblock ~6 ~9 ~75 stone
fill ~10 ~9 ~75 ~10 ~11 ~75 birch_leaves[persistent=false]
fill ~47 ~9 ~75 ~51 ~13 ~75 stone
setblock ~92 ~9 ~75 stone
fill ~17 ~9 ~76 ~17 ~10 ~76 birch_leaves[persistent=false]
fill ~34 ~9 ~76 ~38 ~11 ~77 stone
fill ~61 ~9 ~76 ~63 ~11 ~78 stone
fill ~64 ~9 ~76 ~64 ~11 ~77 stone
fill ~89 ~9 ~76 ~89 ~11 ~76 birch_leaves[persistent=false]
fill ~19 ~9 ~77 ~20 ~10 ~78 stone
fill ~78 ~9 ~77 ~80 ~10 ~77 stone
setblock ~17 ~9 ~78 coal_ore
setblock ~18 ~9 ~78 furnace[lit=false,facing=south]{isMovable:1}
fill ~21 ~9 ~78 ~21 ~10 ~80 stone
fill ~35 ~9 ~78 ~38 ~11 ~78 stone
fill ~77 ~9 ~78 ~78 ~10 ~79 stone
setblock ~80 ~9 ~78 crafting_table
setblock ~81 ~9 ~78 coal_ore
fill ~84 ~9 ~78 ~84 ~11 ~78 birch_leaves[persistent=false]
fill ~13 ~9 ~79 ~13 ~11 ~79 birch_leaves[persistent=false]
fill ~15 ~9 ~79 ~15 ~13 ~79 stone_bricks
setblock ~16 ~9 ~79 iron_ore
setblock ~17 ~9 ~79 chest[type=single,facing=south]{isMovable:1}
fill ~37 ~9 ~79 ~37 ~11 ~79 stone
fill ~83 ~9 ~79 ~83 ~13 ~79 stone_bricks
setblock ~20 ~9 ~80 crafting_table
fill ~61 ~9 ~80 ~63 ~11 ~81 stone
setblock ~78 ~9 ~80 furnace[lit=false,facing=east]{isMovable:1}
setblock ~20 ~9 ~81 coal_ore
fill ~76 ~9 ~81 ~76 ~10 ~81 birch_leaves[persistent=false]
setblock ~78 ~9 ~81 coal_ore
setblock ~79 ~9 ~81 chest[type=single,facing=east]{isMovable:1}
setblock ~14 ~9 ~82 stone
fill ~15 ~9 ~82 ~15 ~12 ~82 stone_bricks
fill ~35 ~9 ~82 ~37 ~11 ~82 stone
fill ~61 ~9 ~82 ~61 ~12 ~83 stone
setblock ~79 ~9 ~82 iron_ore
fill ~83 ~9 ~82 ~83 ~12 ~82 stone_bricks
setblock ~84 ~9 ~82 stone
fill ~16 ~9 ~83 ~16 ~12 ~83 stone_bricks
fill ~18 ~9 ~83 ~18 ~11 ~83 stone
fill ~19 ~9 ~83 ~19 ~13 ~83 stone_bricks
fill ~37 ~9 ~83 ~37 ~17 ~83 stone
fill ~79 ~9 ~83 ~79 ~13 ~83 stone_bricks
fill ~80 ~9 ~83 ~80 ~11 ~83 stone
fill ~82 ~9 ~83 ~82 ~12 ~83 stone_bricks
setblock ~16 ~9 ~84 stone
fill ~20 ~9 ~84 ~20 ~11 ~84 birch_leaves[persistent=false]
setblock ~82 ~9 ~84 stone
fill ~79 ~9 ~85 ~79 ~11 ~85 birch_leaves[persistent=false]
fill ~26 ~9 ~86 ~26 ~10 ~86 birch_leaves[persistent=false]
fill ~28 ~9 ~87 ~29 ~10 ~88 stone
fill ~69 ~9 ~87 ~71 ~10 ~87 stone
setblock ~26 ~9 ~88 coal_ore
setblock ~27 ~9 ~88 furnace[lit=false,facing=south]{isMovable:1}
fill ~30 ~9 ~88 ~30 ~10 ~90 stone
fill ~68 ~9 ~88 ~69 ~10 ~89 stone
setblock ~71 ~9 ~88 crafting_table
setblock ~72 ~9 ~88 coal_ore
fill ~75 ~9 ~88 ~75 ~11 ~88 birch_leaves[persistent=false]
fill ~22 ~9 ~89 ~22 ~11 ~89 birch_leaves[persistent=false]
fill ~24 ~9 ~89 ~24 ~13 ~89 stone_bricks
setblock ~25 ~9 ~89 iron_ore
setblock ~26 ~9 ~89 chest[type=single,facing=south]{isMovable:1}
fill ~74 ~9 ~89 ~74 ~13 ~89 stone_bricks
setblock ~29 ~9 ~90 crafting_table
setblock ~69 ~9 ~90 furnace[lit=false,facing=east]{isMovable:1}
setblock ~29 ~9 ~91 coal_ore
fill ~67 ~9 ~91 ~67 ~10 ~91 birch_leaves[persistent=false]
setblock ~69 ~9 ~91 coal_ore
setblock ~70 ~9 ~91 chest[type=single,facing=east]{isMovable:1}
setblock ~23 ~9 ~92 stone
fill ~24 ~9 ~92 ~24 ~12 ~92 stone_bricks
setblock ~70 ~9 ~92 iron_ore
fill ~74 ~9 ~92 ~74 ~12 ~92 stone_bricks
setblock ~75 ~9 ~92 stone
fill ~25 ~9 ~93 ~25 ~12 ~93 stone_bricks
fill ~27 ~9 ~93 ~27 ~11 ~93 stone
fill ~28 ~9 ~93 ~28 ~13 ~93 stone_bricks
fill ~70 ~9 ~93 ~70 ~13 ~93 stone_bricks
fill ~71 ~9 ~93 ~71 ~11 ~93 stone
fill ~73 ~9 ~93 ~73 ~12 ~93 stone_bricks
setblock ~25 ~9 ~94 stone
fill ~29 ~9 ~94 ~29 ~11 ~94 birch_leaves[persistent=false]
setblock ~73 ~9 ~94 stone
fill ~70 ~9 ~95 ~70 ~11 ~95 birch_leaves[persistent=false]
fill ~70 ~10 ~3 ~70 ~12 ~3 birch_leaves[persistent=false]
setblock ~25 ~10 ~4 dirt
fill ~27 ~10 ~4 ~27 ~14 ~4 stone_bricks
setblock ~28 ~10 ~4 stone
fill ~29 ~10 ~4 ~29 ~12 ~4 birch_leaves[persistent=false]
setblock ~70 ~10 ~4 stone
fill ~71 ~10 ~4 ~71 ~14 ~4 stone_bricks
setblock ~73 ~10 ~4 dirt
setblock ~26 ~10 ~5 gold_ore
fill ~27 ~10 ~5 ~27 ~11 ~5 stone
setblock ~23 ~10 ~6 dirt
fill ~28 ~10 ~6 ~29 ~11 ~6 stone
fill ~69 ~10 ~6 ~70 ~11 ~6 stone
setblock ~75 ~10 ~6 dirt
setblock ~29 ~10 ~7 iron_ore
fill ~69 ~10 ~7 ~69 ~11 ~7 stone
setblock ~74 ~10 ~7 gold_ore
fill ~23 ~10 ~8 ~23 ~14 ~8 stone_bricks
fill ~31 ~10 ~8 ~31 ~11 ~8 stone_bricks
fill ~67 ~10 ~8 ~67 ~11 ~8 stone_bricks
fill ~75 ~10 ~8 ~75 ~14 ~8 stone_bricks
fill ~22 ~10 ~9 ~22 ~12 ~9 birch_leaves[persistent=false]
setblock ~23 ~10 ~9 stone
fill ~68 ~10 ~9 ~68 ~11 ~9 stone
setblock ~69 ~10 ~9 gold_ore
fill ~73 ~10 ~9 ~73 ~11 ~10 stone
setblock ~75 ~10 ~9 stone
fill ~25 ~10 ~10 ~26 ~11 ~10 stone
setblock ~28 ~10 ~10 gold_ore
fill ~68 ~10 ~10 ~70 ~10 ~10 stone
setblock ~72 ~10 ~10 iron_ore
fill ~75 ~10 ~10 ~75 ~12 ~10 birch_leaves[persistent=false]
fill ~27 ~10 ~12 ~27 ~11 ~12 stone_bricks
fill ~71 ~10 ~12 ~71 ~11 ~12 stone_bricks
fill ~79 ~10 ~13 ~79 ~12 ~13 birch_leaves[persistent=false]
setblock ~16 ~10 ~14 dirt
fill ~18 ~10 ~14 ~18 ~14 ~14 stone_bricks
setblock ~19 ~10 ~14 stone
fill ~20 ~10 ~14 ~20 ~12 ~14 birch_leaves[persistent=false]
fill ~37 ~10 ~14 ~37 ~10 ~33 stone
fill ~61 ~10 ~14 ~61 ~10 ~33 stone
setblock ~79 ~10 ~14 stone
fill ~80 ~10 ~14 ~80 ~14 ~14 stone_bricks
setblock ~82 ~10 ~14 dirt
setblock ~17 ~10 ~15 gold_ore
fill ~18 ~10 ~15 ~18 ~11 ~15 stone
fill ~62 ~10 ~15 ~62 ~10 ~33 stone
setblock ~14 ~10 ~16 dirt
fill ~19 ~10 ~16 ~20 ~11 ~16 stone
fill ~35 ~10 ~16 ~37 ~11 ~32 stone
fill ~78 ~10 ~16 ~79 ~11 ~16 stone
setblock ~84 ~10 ~16 dirt
setblock ~20 ~10 ~17 iron_ore
fill ~34 ~10 ~17 ~37 ~11 ~18 stone
fill ~63 ~10 ~17 ~63 ~11 ~17 stone
fill ~78 ~10 ~17 ~78 ~11 ~17 stone
setblock ~83 ~10 ~17 gold_ore
fill ~14 ~10 ~18 ~14 ~14 ~18 stone_bricks
fill ~22 ~10 ~18 ~22 ~11 ~18 stone_bricks
fill ~59 ~10 ~18 ~59 ~12 ~18 birch_leaves[persistent=false]
fill ~76 ~10 ~18 ~76 ~11 ~18 stone_bricks
fill ~84 ~10 ~18 ~84 ~14 ~18 stone_bricks
fill ~13 ~10 ~19 ~13 ~12 ~19 birch_leaves[persistent=false]
setblock ~14 ~10 ~19 stone
fill ~39 ~10 ~19 ~39 ~12 ~19 birch_leaves[persistent=false]
fill ~77 ~10 ~19 ~77 ~11 ~19 stone
setblock ~78 ~10 ~19 gold_ore
fill ~82 ~10 ~19 ~82 ~11 ~20 stone
setblock ~84 ~10 ~19 stone
fill ~16 ~10 ~20 ~17 ~11 ~20 stone
setblock ~19 ~10 ~20 gold_ore
fill ~77 ~10 ~20 ~79 ~10 ~20 stone
setblock ~81 ~10 ~20 iron_ore
fill ~84 ~10 ~20 ~84 ~12 ~20 birch_leaves[persistent=false]
fill ~18 ~10 ~22 ~18 ~11 ~22 stone_bricks
fill ~33 ~10 ~22 ~37 ~11 ~32 stone
fill ~50 ~10 ~22 ~50 ~13 ~23 stone
fill ~65 ~10 ~22 ~65 ~12 ~34 stone
fill ~80 ~10 ~22 ~80 ~11 ~22 stone_bricks
fill ~89 ~10 ~22 ~89 ~12 ~22 birch_leaves[persistent=false]
setblock ~6 ~10 ~23 dirt
fill ~8 ~10 ~23 ~8 ~14 ~23 stone_bricks
setblock ~9 ~10 ~23 stone
fill ~10 ~10 ~23 ~10 ~12 ~23 birch_leaves[persistent=false]
fill ~38 ~10 ~23 ~38 ~12 ~32 stone
setblock ~89 ~10 ~23 stone
fill ~90 ~10 ~23 ~90 ~14 ~23 stone_bricks
setblock ~92 ~10 ~23 dirt
setblock ~7 ~10 ~24 gold_ore
fill ~8 ~10 ~24 ~8 ~11 ~24 stone
fill ~32 ~10 ~24 ~32 ~13 ~24 polished_andesite
fill ~48 ~10 ~24 ~49 ~13 ~24 stone
fill ~59 ~10 ~24 ~65 ~12 ~31 stone
fill ~66 ~10 ~24 ~66 ~13 ~24 polished_andesite
setblock ~4 ~10 ~25 dirt
fill ~9 ~10 ~25 ~10 ~11 ~25 stone
fill ~32 ~10 ~25 ~38 ~11 ~32 stone
fill ~88 ~10 ~25 ~89 ~11 ~25 stone
setblock ~94 ~10 ~25 dirt
setblock ~10 ~10 ~26 iron_ore
fill ~28 ~10 ~26 ~39 ~10 ~33 stone
fill ~70 ~10 ~26 ~71 ~11 ~39 stone
fill ~88 ~10 ~26 ~88 ~11 ~26 stone
setblock ~93 ~10 ~26 gold_ore
fill ~4 ~10 ~27 ~4 ~14 ~27 stone_bricks
fill ~12 ~10 ~27 ~12 ~11 ~27 stone_bricks
fill ~26 ~10 ~27 ~33 ~10 ~39 stone
fill ~58 ~10 ~27 ~71 ~11 ~32 stone
fill ~86 ~10 ~27 ~86 ~11 ~27 stone_bricks
fill ~94 ~10 ~27 ~94 ~14 ~27 stone_bricks
fill ~3 ~10 ~28 ~3 ~12 ~28 birch_leaves[persistent=false]
setblock ~4 ~10 ~28 stone
fill ~57 ~10 ~28 ~66 ~12 ~31 stone
fill ~72 ~10 ~28 ~72 ~10 ~39 stone
fill ~87 ~10 ~28 ~87 ~11 ~28 stone
setblock ~88 ~10 ~28 gold_ore
fill ~92 ~10 ~28 ~92 ~11 ~29 stone
setblock ~94 ~10 ~28 stone
fill ~6 ~10 ~29 ~7 ~11 ~29 stone
setblock ~9 ~10 ~29 gold_ore
fill ~40 ~10 ~29 ~40 ~10 ~71 stone
fill ~54 ~10 ~29 ~54 ~11 ~29 birch_leaves[persistent=false]
fill ~87 ~10 ~29 ~89 ~10 ~29 stone
setblock ~91 ~10 ~29 iron_ore
fill ~94 ~10 ~29 ~94 ~12 ~29 birch_leaves[persistent=false]
fill ~41 ~10 ~30 ~41 ~13 ~34 stone
fill ~8 ~10 ~31 ~8 ~11 ~31 stone_bricks
fill ~55 ~10 ~31 ~59 ~13 ~34 stone
fill ~90 ~10 ~31 ~90 ~11 ~31 stone_bricks
fill ~24 ~10 ~32 ~24 ~13 ~32 polished_andesite
fill ~42 ~10 ~32 ~42 ~10 ~44 stone
fill ~53 ~10 ~32 ~59 ~13 ~34 stone
fill ~74 ~10 ~32 ~74 ~13 ~32 polished_andesite
fill ~22 ~10 ~33 ~32 ~11 ~38 stone
fill ~44 ~10 ~33 ~46 ~13 ~34 stone
fill ~51 ~10 ~33 ~59 ~13 ~34 stone
fill ~74 ~10 ~33 ~75 ~12 ~38 stone
fill ~76 ~10 ~33 ~76 ~11 ~37 stone
fill ~47 ~10 ~34 ~58 ~10 ~40 stone
fill ~80 ~10 ~34 ~81 ~11 ~37 stone
fill ~17 ~10 ~35 ~17 ~11 ~37 stone
fill ~79 ~10 ~35 ~82 ~11 ~37 stone
fill ~15 ~10 ~36 ~33 ~10 ~37 stone
fill ~14 ~10 ~37 ~33 ~10 ~37 stone
fill ~84 ~10 ~37 ~84 ~13 ~37 stone
fill ~18 ~10 ~39 ~18 ~12 ~39 birch_leaves[persistent=false]
fill ~24 ~10 ~39 ~34 ~13 ~39 stone
fill ~79 ~10 ~39 ~79 ~12 ~39 birch_leaves[persistent=false]
fill ~27 ~10 ~40 ~69 ~10 ~40 stone
fill ~28 ~10 ~41 ~34 ~12 ~41 stone
setblock ~46 ~10 ~41 stone_bricks
setblock ~47 ~10 ~41 mossy_stone_bricks
setblock ~49 ~10 ~41 stone_brick_stairs[facing=north,half=top]
fill ~51 ~10 ~41 ~52 ~11 ~41 stone_bricks
fill ~53 ~10 ~41 ~68 ~10 ~41 stone
fill ~31 ~10 ~42 ~34 ~13 ~43 stone
fill ~45 ~10 ~42 ~45 ~11 ~42 stone_bricks
setblock ~53 ~10 ~42 mossy_stone_bricks
fill ~66 ~10 ~42 ~66 ~13 ~42 stone
setblock ~44 ~10 ~43 mossy_stone_bricks
fill ~54 ~10 ~43 ~54 ~11 ~43 stone_bricks
fill ~29 ~10 ~44 ~29 ~11 ~44 birch_leaves[persistent=false]
fill ~32 ~10 ~44 ~34 ~13 ~45 stone
fill ~43 ~10 ~44 ~43 ~11 ~44 stone_bricks
setblock ~55 ~10 ~44 mossy_stone_bricks
fill ~65 ~10 ~44 ~65 ~13 ~46 stone
setblock ~42 ~10 ~45 mossy_stone_bricks
fill ~45 ~10 ~45 ~45 ~12 ~45 diorite
fill ~53 ~10 ~45 ~53 ~12 ~45 diorite
fill ~56 ~10 ~45 ~56 ~11 ~45 stone_bricks
fill ~33 ~10 ~46 ~40 ~10 ~46 stone
fill ~41 ~10 ~46 ~41 ~11 ~47 stone_bricks
setblock ~57 ~10 ~46 stone_bricks
fill ~58 ~10 ~46 ~58 ~10 ~69 stone
fill ~62 ~10 ~46 ~64 ~10 ~58 stone
fill ~49 ~10 ~47 ~49 ~11 ~50 stone
setblock ~57 ~10 ~47 mossy_stone_bricks
fill ~22 ~10 ~48 ~23 ~13 ~49 stone
fill ~34 ~10 ~48 ~40 ~10 ~58 stone
fill ~74 ~10 ~48 ~75 ~13 ~49 stone
setblock ~41 ~10 ~49 stone_brick_stairs[facing=west,half=top]
fill ~47 ~10 ~49 ~51 ~11 ~49 stone
setblock ~57 ~10 ~49 stone_brick_stairs[facing=east,half=top]
fill ~65 ~10 ~49 ~65 ~13 ~59 stone
fill ~24 ~10 ~50 ~24 ~13 ~50 stone
fill ~48 ~10 ~50 ~50 ~11 ~50 stone
fill ~76 ~10 ~50 ~76 ~13 ~50 stone
setblock ~41 ~10 ~51 mossy_stone_bricks
fill ~57 ~10 ~51 ~57 ~11 ~52 stone_bricks
fill ~33 ~10 ~52 ~34 ~13 ~59 stone
setblock ~41 ~10 ~52 stone_bricks
fill ~42 ~10 ~53 ~42 ~11 ~53 stone_bricks
fill ~45 ~10 ~53 ~45 ~12 ~53 diorite
fill ~53 ~10 ~53 ~53 ~12 ~53 diorite
setblock ~56 ~10 ~53 mossy_stone_bricks
fill ~57 ~10 ~53 ~66 ~10 ~58 stone
setblock ~43 ~10 ~54 mossy_stone_bricks
fill ~55 ~10 ~54 ~55 ~11 ~54 stone_bricks
fill ~69 ~10 ~54 ~69 ~11 ~54 birch_leaves[persistent=false]
fill ~44 ~10 ~55 ~44 ~11 ~55 stone_bricks
setblock ~54 ~10 ~55 mossy_stone_bricks
fill ~67 ~10 ~55 ~67 ~11 ~72 stone
fill ~32 ~10 ~56 ~34 ~13 ~59 stone
setblock ~45 ~10 ~56 mossy_stone_bricks
fill ~53 ~10 ~56 ~53 ~11 ~56 stone_bricks
fill ~30 ~10 ~57 ~33 ~10 ~72 stone
fill ~45 ~10 ~57 ~45 ~10 ~66 stone
fill ~46 ~10 ~57 ~47 ~11 ~57 stone_bricks
setblock ~49 ~10 ~57 stone_brick_stairs[facing=south,half=top]
setblock ~51 ~10 ~57 mossy_stone_bricks
setblock ~52 ~10 ~57 stone_bricks
fill ~53 ~10 ~57 ~58 ~10 ~65 stone
fill ~68 ~10 ~57 ~70 ~12 ~66 stone
fill ~29 ~10 ~58 ~33 ~10 ~72 stone
fill ~46 ~10 ~58 ~71 ~10 ~58 stone
fill ~19 ~10 ~59 ~19 ~12 ~59 birch_leaves[persistent=false]
fill ~26 ~10 ~59 ~33 ~10 ~70 stone
fill ~46 ~10 ~59 ~60 ~10 ~59 stone
fill ~73 ~10 ~59 ~74 ~12 ~65 stone
fill ~80 ~10 ~59 ~80 ~12 ~59 birch_leaves[persistent=false]
fill ~23 ~10 ~60 ~31 ~12 ~65 stone
fill ~14 ~10 ~61 ~33 ~10 ~61 stone
fill ~80 ~10 ~61 ~83 ~11 ~62 stone
fill ~84 ~10 ~61 ~84 ~13 ~61 stone
fill ~16 ~10 ~63 ~34 ~11 ~63 stone
fill ~81 ~10 ~63 ~82 ~11 ~63 stone
fill ~17 ~10 ~64 ~18 ~11 ~64 stone
fill ~46 ~10 ~64 ~60 ~11 ~64 stone
fill ~22 ~10 ~65 ~34 ~12 ~65 stone
fill ~52 ~10 ~65 ~59 ~13 ~65 stone
fill ~76 ~10 ~65 ~76 ~12 ~65 stone
fill ~24 ~10 ~66 ~24 ~13 ~66 polished_andesite
fill ~41 ~10 ~66 ~45 ~13 ~66 stone
fill ~56 ~10 ~66 ~73 ~11 ~66 stone
fill ~74 ~10 ~66 ~74 ~13 ~66 polished_andesite
fill ~8 ~10 ~67 ~8 ~11 ~67 stone_bricks
fill ~41 ~10 ~67 ~43 ~13 ~67 stone
fill ~57 ~10 ~67 ~72 ~11 ~67 stone
fill ~90 ~10 ~67 ~90 ~11 ~67 stone_bricks
fill ~41 ~10 ~68 ~41 ~12 ~70 stone
fill ~57 ~10 ~68 ~72 ~10 ~68 stone
fill ~4 ~10 ~69 ~4 ~12 ~69 birch_leaves[persistent=false]
fill ~6 ~10 ~69 ~6 ~11 ~70 stone
setblock ~7 ~10 ~69 iron_ore
fill ~44 ~10 ~69 ~44 ~11 ~69 birch_leaves[persistent=false]
setblock ~89 ~10 ~69 gold_ore
fill ~91 ~10 ~69 ~92 ~11 ~69 stone
setblock ~4 ~10 ~70 stone
setblock ~10 ~10 ~70 gold_ore
fill ~72 ~10 ~70 ~72 ~11 ~71 stone
setblock ~94 ~10 ~70 stone
fill ~95 ~10 ~70 ~95 ~12 ~70 birch_leaves[persistent=false]
fill ~4 ~10 ~71 ~4 ~14 ~71 stone_bricks
fill ~12 ~10 ~71 ~12 ~11 ~71 stone_bricks
fill ~59 ~10 ~71 ~72 ~11 ~71 stone
fill ~86 ~10 ~71 ~86 ~11 ~71 stone_bricks
fill ~94 ~10 ~71 ~94 ~14 ~71 stone_bricks
setblock ~5 ~10 ~72 gold_ore
fill ~10 ~10 ~72 ~10 ~11 ~73 stone
fill ~27 ~10 ~72 ~39 ~10 ~72 stone
fill ~59 ~10 ~72 ~70 ~10 ~72 stone
setblock ~88 ~10 ~72 iron_ore
setblock ~4 ~10 ~73 dirt
fill ~39 ~10 ~73 ~39 ~13 ~74 stone
fill ~88 ~10 ~73 ~89 ~11 ~73 stone
setblock ~94 ~10 ~73 dirt
fill ~32 ~10 ~74 ~32 ~13 ~74 polished_andesite
fill ~50 ~10 ~74 ~50 ~13 ~75 stone
fill ~60 ~10 ~74 ~65 ~12 ~75 stone
fill ~66 ~10 ~74 ~66 ~13 ~74 polished_andesite
setblock ~91 ~10 ~74 gold_ore
setblock ~6 ~10 ~75 dirt
fill ~8 ~10 ~75 ~8 ~14 ~75 stone_bricks
setblock ~9 ~10 ~75 stone
fill ~88 ~10 ~75 ~88 ~12 ~75 birch_leaves[persistent=false]
setblock ~89 ~10 ~75 stone
fill ~90 ~10 ~75 ~90 ~14 ~75 stone_bricks
setblock ~92 ~10 ~75 dirt
fill ~9 ~10 ~76 ~9 ~12 ~76 birch_leaves[persistent=false]
fill ~18 ~10 ~76 ~18 ~11 ~76 stone_bricks
fill ~33 ~10 ~76 ~38 ~11 ~76 stone
fill ~48 ~10 ~76 ~49 ~13 ~76 stone
fill ~65 ~10 ~76 ~65 ~12 ~76 stone
fill ~80 ~10 ~76 ~80 ~11 ~76 stone_bricks
fill ~14 ~10 ~78 ~14 ~12 ~78 birch_leaves[persistent=false]
fill ~16 ~10 ~78 ~16 ~11 ~79 stone
setblock ~17 ~10 ~78 iron_ore
setblock ~79 ~10 ~78 gold_ore
fill ~81 ~10 ~78 ~82 ~11 ~78 stone
setblock ~14 ~10 ~79 stone
setblock ~20 ~10 ~79 gold_ore
fill ~59 ~10 ~79 ~59 ~12 ~79 birch_leaves[persistent=false]
fill ~61 ~10 ~79 ~63 ~11 ~82 stone
setblock ~84 ~10 ~79 stone
fill ~85 ~10 ~79 ~85 ~12 ~79 birch_leaves[persistent=false]
fill ~14 ~10 ~80 ~14 ~14 ~80 stone_bricks
fill ~22 ~10 ~80 ~22 ~11 ~80 stone_bricks
fill ~37 ~10 ~80 ~37 ~11 ~84 stone
fill ~39 ~10 ~80 ~39 ~12 ~80 birch_leaves[persistent=false]
fill ~64 ~10 ~80 ~64 ~11 ~81 stone
fill ~76 ~10 ~80 ~76 ~11 ~80 stone_bricks
fill ~84 ~10 ~80 ~84 ~14 ~80 stone_bricks
setblock ~15 ~10 ~81 gold_ore
fill ~20 ~10 ~81 ~20 ~11 ~82 stone
fill ~35 ~10 ~81 ~37 ~11 ~82 stone
setblock ~78 ~10 ~81 iron_ore
setblock ~14 ~10 ~82 dirt
fill ~78 ~10 ~82 ~79 ~11 ~82 stone
setblock ~84 ~10 ~82 dirt
fill ~36 ~10 ~83 ~37 ~14 ~83 stone
setblock ~81 ~10 ~83 gold_ore
setblock ~16 ~10 ~84 dirt
fill ~18 ~10 ~84 ~18 ~14 ~84 stone_bricks
setblock ~19 ~10 ~84 stone
fill ~61 ~10 ~84 ~61 ~13 ~84 stone
fill ~78 ~10 ~84 ~78 ~12 ~84 birch_leaves[persistent=false]
setblock ~79 ~10 ~84 stone
fill ~80 ~10 ~84 ~80 ~14 ~84 stone_bricks
setblock ~82 ~10 ~84 dirt
fill ~19 ~10 ~85 ~19 ~12 ~85 birch_leaves[persistent=false]
fill ~27 ~10 ~86 ~27 ~11 ~86 stone_bricks
fill ~71 ~10 ~86 ~71 ~11 ~86 stone_bricks
fill ~23 ~10 ~88 ~23 ~12 ~88 birch_leaves[persistent=false]
fill ~25 ~10 ~88 ~25 ~11 ~89 stone
setblock ~26 ~10 ~88 iron_ore
setblock ~70 ~10 ~88 gold_ore
fill ~72 ~10 ~88 ~73 ~11 ~88 stone
setblock ~23 ~10 ~89 stone
setblock ~29 ~10 ~89 gold_ore
setblock ~75 ~10 ~89 stone
fill ~76 ~10 ~89 ~76 ~12 ~89 birch_leaves[persistent=false]
fill ~23 ~10 ~90 ~23 ~14 ~90 stone_bricks
fill ~31 ~10 ~90 ~31 ~11 ~90 stone_bricks
fill ~67 ~10 ~90 ~67 ~11 ~90 stone_bricks
fill ~75 ~10 ~90 ~75 ~14 ~90 stone_bricks
setblock ~24 ~10 ~91 gold_ore
fill ~29 ~10 ~91 ~29 ~11 ~92 stone
setblock ~69 ~10 ~91 iron_ore
setblock ~23 ~10 ~92 dirt
fill ~69 ~10 ~92 ~70 ~11 ~92 stone
setblock ~75 ~10 ~92 dirt
setblock ~72 ~10 ~93 gold_ore
setblock ~25 ~10 ~94 dirt
fill ~27 ~10 ~94 ~27 ~14 ~94 stone_bricks
setblock ~28 ~10 ~94 stone
fill ~69 ~10 ~94 ~69 ~12 ~94 birch_leaves[persistent=false]
setblock ~70 ~10 ~94 stone
fill ~71 ~10 ~94 ~71 ~14 ~94 stone_bricks
setblock ~73 ~10 ~94 dirt
fill ~28 ~10 ~95 ~28 ~12 ~95 birch_leaves[persistent=false]
fill ~23 ~11 ~4 ~23 ~13 ~4 birch_leaves[persistent=false]
setblock ~25 ~11 ~4 grass_block
setblock ~26 ~11 ~4 dirt
setblock ~28 ~11 ~4 dirt
setblock ~70 ~11 ~4 dirt
fill ~72 ~11 ~4 ~72 ~11 ~5 stone
setblock ~73 ~11 ~4 grass_block
fill ~75 ~11 ~4 ~75 ~13 ~4 birch_leaves[persistent=false]
fill ~24 ~11 ~5 ~25 ~12 ~5 stone_bricks
fill ~26 ~11 ~5 ~27 ~11 ~5 stone
setblock ~29 ~11 ~5 stone_slab[type=top]
setblock ~69 ~11 ~5 stone_slab[type=top]
fill ~74 ~11 ~5 ~74 ~12 ~6 stone_bricks
setblock ~23 ~11 ~6 grass_block
setblock ~27 ~11 ~6 stone_slab[type=top]
setblock ~30 ~11 ~6 stone_slab[type=top]
setblock ~68 ~11 ~6 stone_slab[type=top]
setblock ~71 ~11 ~6 stone_slab[type=top]
setblock ~75 ~11 ~6 grass_block
fill ~23 ~11 ~7 ~24 ~11 ~7 stone
fill ~26 ~11 ~7 ~27 ~11 ~7 stone_brick_slab[type=top]
setblock ~28 ~11 ~7 stone_brick_slab[type=double]
setblock ~29 ~11 ~7 stone
fill ~30 ~11 ~7 ~30 ~13 ~7 stone_bricks
fill ~32 ~11 ~7 ~32 ~12 ~7 birch_leaves[persistent=false]
fill ~68 ~11 ~7 ~68 ~11 ~9 stone
setblock ~70 ~11 ~7 stone_brick_slab[type=double]
fill ~71 ~11 ~7 ~72 ~11 ~7 stone_brick_slab[type=top]
fill ~74 ~11 ~7 ~74 ~11 ~8 stone
setblock ~75 ~11 ~7 dirt
setblock ~25 ~11 ~8 stone_slab[type=top]
setblock ~26 ~11 ~8 stone_brick_slab[type=top]
setblock ~27 ~11 ~8 stone_brick_slab[type=double]
setblock ~28 ~11 ~8 stone_brick_slab[type=top]
setblock ~29 ~11 ~8 stone_slab[type=top]
fill ~32 ~11 ~8 ~32 ~13 ~8 stone_bricks
fill ~66 ~11 ~8 ~66 ~13 ~8 stone_bricks
setblock ~69 ~11 ~8 stone_slab[type=top]
setblock ~70 ~11 ~8 stone_brick_slab[type=top]
setblock ~71 ~11 ~8 stone_brick_slab[type=double]
setblock ~72 ~11 ~8 stone_brick_slab[type=top]
setblock ~73 ~11 ~8 stone_slab[type=top]
setblock ~23 ~11 ~9 dirt
setblock ~26 ~11 ~9 stone_brick_slab[type=double]
setblock ~27 ~11 ~9 stone_brick_slab[type=top]
setblock ~28 ~11 ~9 diamond_ore
setblock ~30 ~11 ~9 stone
setblock ~31 ~11 ~9 dirt
fill ~67 ~11 ~9 ~69 ~11 ~9 stone
setblock ~70 ~11 ~9 diamond_ore
setblock ~71 ~11 ~9 stone_brick_slab[type=top]
setblock ~72 ~11 ~9 stone_brick_slab[type=double]
setblock ~75 ~11 ~9 dirt
setblock ~24 ~11 ~10 stone_slab[type=top]
setblock ~27 ~11 ~10 stone_slab[type=top]
fill ~28 ~11 ~10 ~28 ~11 ~12 stone
setblock ~29 ~11 ~10 stone
setblock ~30 ~11 ~10 stone_slab[type=double]
setblock ~68 ~11 ~10 stone_slab[type=double]
fill ~69 ~11 ~10 ~70 ~11 ~10 stone
setblock ~71 ~11 ~10 stone_slab[type=top]
fill ~72 ~11 ~10 ~73 ~11 ~10 stone
setblock ~74 ~11 ~10 stone_slab[type=top]
setblock ~25 ~11 ~11 stone_slab[type=top]
fill ~26 ~11 ~11 ~28 ~11 ~11 stone
setblock ~29 ~11 ~11 stone_slab[type=double]
setblock ~69 ~11 ~11 stone_slab[type=double]
fill ~70 ~11 ~11 ~71 ~11 ~11 stone
fill ~72 ~11 ~11 ~72 ~13 ~11 stone_bricks
setblock ~73 ~11 ~11 stone_slab[type=top]
setblock ~70 ~11 ~12 dirt
fill ~27 ~11 ~13 ~27 ~13 ~13 stone_bricks
fill ~71 ~11 ~13 ~71 ~13 ~13 stone_bricks
fill ~72 ~11 ~13 ~72 ~12 ~13 birch_leaves[persistent=false]
fill ~14 ~11 ~14 ~14 ~13 ~14 birch_leaves[persistent=false]
setblock ~16 ~11 ~14 grass_block
setblock ~17 ~11 ~14 dirt
setblock ~19 ~11 ~14 dirt
fill ~37 ~11 ~14 ~37 ~11 ~32 stone
fill ~61 ~11 ~14 ~61 ~11 ~32 stone
setblock ~79 ~11 ~14 dirt
fill ~81 ~11 ~14 ~81 ~11 ~15 stone
setblock ~82 ~11 ~14 grass_block
fill ~84 ~11 ~14 ~84 ~13 ~14 birch_leaves[persistent=false]
fill ~15 ~11 ~15 ~15 ~12 ~15 diorite
fill ~17 ~11 ~15 ~18 ~11 ~15 stone
setblock ~20 ~11 ~15 stone_slab[type=top]
fill ~35 ~11 ~15 ~37 ~11 ~32 stone
fill ~62 ~11 ~15 ~63 ~11 ~32 stone
setblock ~78 ~11 ~15 stone_slab[type=top]
fill ~83 ~11 ~15 ~83 ~12 ~15 diorite
setblock ~14 ~11 ~16 grass_block
setblock ~18 ~11 ~16 stone_slab[type=top]
setblock ~21 ~11 ~16 stone_slab[type=top]
fill ~34 ~11 ~16 ~37 ~11 ~32 stone
fill ~64 ~11 ~16 ~64 ~11 ~35 stone
setblock ~77 ~11 ~16 stone_slab[type=top]
setblock ~80 ~11 ~16 stone_slab[type=top]
setblock ~84 ~11 ~16 grass_block
fill ~14 ~11 ~17 ~15 ~11 ~17 stone
fill ~17 ~11 ~17 ~18 ~11 ~17 stone_brick_slab[type=top]
setblock ~19 ~11 ~17 stone_brick_slab[type=double]
setblock ~20 ~11 ~17 stone
setblock ~21 ~11 ~17 mossy_stone_bricks
fill ~23 ~11 ~17 ~23 ~12 ~17 birch_leaves[persistent=false]
fill ~38 ~11 ~17 ~38 ~12 ~17 polished_andesite
fill ~77 ~11 ~17 ~77 ~11 ~19 stone
setblock ~79 ~11 ~17 stone_brick_slab[type=double]
fill ~80 ~11 ~17 ~81 ~11 ~17 stone_brick_slab[type=top]
fill ~83 ~11 ~17 ~83 ~11 ~18 stone
setblock ~84 ~11 ~17 dirt
setblock ~16 ~11 ~18 stone_slab[type=top]
setblock ~17 ~11 ~18 stone_brick_slab[type=top]
setblock ~18 ~11 ~18 stone_brick_slab[type=double]
setblock ~19 ~11 ~18 stone_brick_slab[type=top]
setblock ~20 ~11 ~18 stone_slab[type=top]
fill ~23 ~11 ~18 ~23 ~12 ~18 stone_bricks
fill ~75 ~11 ~18 ~75 ~13 ~18 stone_bricks
setblock ~78 ~11 ~18 stone_slab[type=top]
setblock ~79 ~11 ~18 stone_brick_slab[type=top]
setblock ~80 ~11 ~18 stone_brick_slab[type=double]
setblock ~81 ~11 ~18 stone_brick_slab[type=top]
setblock ~82 ~11 ~18 stone_slab[type=top]
setblock ~14 ~11 ~19 dirt
setblock ~17 ~11 ~19 stone_brick_slab[type=double]
setblock ~18 ~11 ~19 stone_brick_slab[type=top]
setblock ~19 ~11 ~19 diamond_ore
setblock ~21 ~11 ~19 stone
setblock ~22 ~11 ~19 dirt
fill ~38 ~11 ~19 ~38 ~12 ~32 stone
fill ~60 ~11 ~19 ~64 ~11 ~32 stone
fill ~76 ~11 ~19 ~78 ~11 ~19 stone
setblock ~79 ~11 ~19 diamond_ore
setblock ~80 ~11 ~19 stone_brick_slab[type=top]
setblock ~81 ~11 ~19 stone_brick_slab[type=double]
setblock ~84 ~11 ~19 dirt
setblock ~15 ~11 ~20 stone_slab[type=top]
setblock ~18 ~11 ~20 stone_slab[type=top]
fill ~19 ~11 ~20 ~19 ~11 ~22 stone
setblock ~20 ~11 ~20 stone
setblock ~21 ~11 ~20 stone_slab[type=double]
fill ~33 ~11 ~20 ~38 ~11 ~32 stone
fill ~65 ~11 ~20 ~65 ~11 ~35 stone
setblock ~77 ~11 ~20 stone_slab[type=double]
fill ~78 ~11 ~20 ~79 ~11 ~20 stone
setblock ~80 ~11 ~20 stone_slab[type=top]
fill ~81 ~11 ~20 ~82 ~11 ~20 stone
setblock ~83 ~11 ~20 stone_slab[type=top]
setblock ~16 ~11 ~21 stone_slab[type=top]
fill ~17 ~11 ~21 ~19 ~11 ~21 stone
setblock ~20 ~11 ~21 stone_slab[type=double]
setblock ~78 ~11 ~21 stone_slab[type=double]
fill ~79 ~11 ~21 ~80 ~11 ~21 stone
setblock ~81 ~11 ~21 mossy_stone_bricks
setblock ~82 ~11 ~21 stone_slab[type=top]
fill ~39 ~11 ~22 ~39 ~11 ~35 stone
fill ~48 ~11 ~22 ~50 ~13 ~23 stone
fill ~59 ~11 ~22 ~65 ~11 ~32 stone
setblock ~79 ~11 ~22 dirt
fill ~4 ~11 ~23 ~4 ~13 ~23 birch_leaves[persistent=false]
setblock ~6 ~11 ~23 grass_block
setblock ~7 ~11 ~23 dirt
setblock ~9 ~11 ~23 dirt
fill ~18 ~11 ~23 ~18 ~13 ~23 stone_bricks
fill ~32 ~11 ~23 ~39 ~11 ~23 stone
fill ~46 ~11 ~23 ~52 ~13 ~23 stone
setblock ~66 ~11 ~23 stone
fill ~80 ~11 ~23 ~80 ~12 ~23 stone_bricks
fill ~81 ~11 ~23 ~81 ~12 ~23 birch_leaves[persistent=false]
setblock ~89 ~11 ~23 dirt
fill ~91 ~11 ~23 ~91 ~11 ~24 stone
setblock ~92 ~11 ~23 grass_block
fill ~94 ~11 ~23 ~94 ~13 ~23 birch_leaves[persistent=false]
fill ~5 ~11 ~24 ~6 ~12 ~24 stone_bricks
fill ~7 ~11 ~24 ~8 ~11 ~24 stone
setblock ~10 ~11 ~24 stone_slab[type=top]
fill ~47 ~11 ~24 ~49 ~13 ~24 stone
fill ~58 ~11 ~24 ~65 ~12 ~31 stone
setblock ~88 ~11 ~24 stone_slab[type=top]
fill ~93 ~11 ~24 ~93 ~12 ~25 stone_bricks
setblock ~4 ~11 ~25 grass_block
setblock ~8 ~11 ~25 stone_slab[type=top]
setblock ~11 ~11 ~25 stone_slab[type=top]
fill ~26 ~11 ~25 ~29 ~11 ~29 stone
fill ~40 ~11 ~25 ~40 ~11 ~35 stone
fill ~49 ~11 ~25 ~49 ~13 ~25 stone
fill ~69 ~11 ~25 ~72 ~11 ~29 stone
setblock ~87 ~11 ~25 stone_slab[type=top]
setblock ~90 ~11 ~25 stone_slab[type=top]
setblock ~94 ~11 ~25 grass_block
fill ~4 ~11 ~26 ~5 ~11 ~26 stone
fill ~7 ~11 ~26 ~8 ~11 ~26 stone_brick_slab[type=top]
setblock ~9 ~11 ~26 stone_brick_slab[type=double]
setblock ~10 ~11 ~26 stone
fill ~11 ~11 ~26 ~11 ~13 ~26 stone_bricks
fill ~13 ~11 ~26 ~13 ~12 ~26 birch_leaves[persistent=false]
fill ~25 ~11 ~26 ~29 ~11 ~29 stone
fill ~30 ~11 ~26 ~30 ~14 ~26 polished_andesite
fill ~31 ~11 ~26 ~40 ~11 ~32 stone
fill ~67 ~11 ~26 ~67 ~11 ~44 stone
fill ~68 ~11 ~26 ~68 ~14 ~26 polished_andesite
fill ~73 ~11 ~26 ~73 ~11 ~29 stone
fill ~87 ~11 ~26 ~87 ~11 ~28 stone
setblock ~89 ~11 ~26 stone_brick_slab[type=double]
fill ~90 ~11 ~26 ~91 ~11 ~26 stone_brick_slab[type=top]
fill ~93 ~11 ~26 ~93 ~11 ~27 stone
setblock ~94 ~11 ~26 dirt
setblock ~6 ~11 ~27 stone_slab[type=top]
setblock ~7 ~11 ~27 stone_brick_slab[type=top]
setblock ~8 ~11 ~27 stone_brick_slab[type=double]
setblock ~9 ~11 ~27 stone_brick_slab[type=top]
setblock ~10 ~11 ~27 stone_slab[type=top]
fill ~13 ~11 ~27 ~13 ~13 ~27 stone_bricks
fill ~41 ~11 ~27 ~41 ~11 ~35 stone
fill ~57 ~11 ~27 ~73 ~11 ~29 stone
fill ~85 ~11 ~27 ~85 ~13 ~27 stone_bricks
setblock ~88 ~11 ~27 stone_slab[type=top]
setblock ~89 ~11 ~27 stone_brick_slab[type=top]
setblock ~90 ~11 ~27 stone_brick_slab[type=double]
setblock ~91 ~11 ~27 stone_brick_slab[type=top]
setblock ~92 ~11 ~27 stone_slab[type=top]
setblock ~4 ~11 ~28 dirt
setblock ~7 ~11 ~28 stone_brick_slab[type=double]
setblock ~8 ~11 ~28 stone_brick_slab[type=top]
setblock ~9 ~11 ~28 diamond_ore
setblock ~11 ~11 ~28 stone
setblock ~12 ~11 ~28 dirt
fill ~86 ~11 ~28 ~88 ~11 ~28 stone
setblock ~89 ~11 ~28 diamond_ore
setblock ~90 ~11 ~28 stone_brick_slab[type=top]
setblock ~91 ~11 ~28 stone_brick_slab[type=double]
setblock ~94 ~11 ~28 dirt
setblock ~5 ~11 ~29 stone_slab[type=top]
setblock ~8 ~11 ~29 stone_slab[type=top]
fill ~9 ~11 ~29 ~9 ~11 ~31 stone
setblock ~10 ~11 ~29 stone
setblock ~11 ~11 ~29 stone_slab[type=double]
fill ~42 ~11 ~29 ~42 ~11 ~35 stone
fill ~43 ~11 ~29 ~43 ~13 ~29 birch_leaves[persistent=false]
fill ~56 ~11 ~29 ~59 ~11 ~35 stone
setblock ~87 ~11 ~29 stone_slab[type=double]
fill ~88 ~11 ~29 ~89 ~11 ~29 stone
setblock ~90 ~11 ~29 stone_slab[type=top]
fill ~91 ~11 ~29 ~92 ~11 ~29 stone
setblock ~93 ~11 ~29 stone_slab[type=top]
setblock ~6 ~11 ~30 stone_slab[type=top]
fill ~7 ~11 ~30 ~9 ~11 ~30 stone
setblock ~10 ~11 ~30 stone_slab[type=double]
fill ~26 ~11 ~30 ~26 ~14 ~30 polished_andesite
setblock ~44 ~11 ~30 birch_leaves[persistent=false]
fill ~49 ~11 ~30 ~49 ~13 ~35 stone
fill ~72 ~11 ~30 ~72 ~14 ~30 polished_andesite
setblock ~88 ~11 ~30 stone_slab[type=double]
fill ~89 ~11 ~30 ~90 ~11 ~30 stone
fill ~91 ~11 ~30 ~91 ~13 ~30 stone_bricks
setblock ~92 ~11 ~30 stone_slab[type=top]
fill ~26 ~11 ~31 ~32 ~11 ~40 stone
fill ~43 ~11 ~31 ~44 ~13 ~34 stone
fill ~48 ~11 ~31 ~49 ~13 ~33 stone
fill ~54 ~11 ~31 ~59 ~12 ~34 stone
setblock ~89 ~11 ~31 dirt
fill ~8 ~11 ~32 ~8 ~13 ~32 stone_bricks
fill ~23 ~11 ~32 ~23 ~11 ~39 stone
fill ~45 ~11 ~32 ~49 ~13 ~33 stone
fill ~51 ~11 ~32 ~59 ~13 ~34 stone
fill ~75 ~11 ~32 ~75 ~11 ~39 stone
fill ~90 ~11 ~32 ~90 ~13 ~32 stone_bricks
fill ~91 ~11 ~32 ~91 ~12 ~32 birch_leaves[persistent=false]
fill ~20 ~11 ~33 ~32 ~11 ~38 stone
fill ~33 ~11 ~33 ~34 ~12 ~34 stone
fill ~36 ~11 ~33 ~37 ~11 ~33 stone_bricks
fill ~50 ~11 ~33 ~59 ~13 ~33 stone
fill ~60 ~11 ~33 ~60 ~11 ~34 stone
fill ~61 ~11 ~33 ~61 ~11 ~34 mossy_stone_bricks
fill ~62 ~11 ~33 ~62 ~11 ~34 stone_bricks
fill ~72 ~11 ~33 ~78 ~11 ~38 stone
fill ~16 ~11 ~34 ~32 ~11 ~37 stone
setblock ~36 ~11 ~34 mossy_stone_bricks
setblock ~37 ~11 ~34 stone_bricks
fill ~47 ~11 ~34 ~59 ~11 ~35 stone
fill ~79 ~11 ~34 ~82 ~11 ~37 stone
fill ~15 ~11 ~35 ~32 ~11 ~37 stone
fill ~36 ~11 ~35 ~37 ~11 ~35 stone_slab[type=top]
fill ~38 ~11 ~35 ~38 ~12 ~35 mossy_stone_bricks
fill ~43 ~11 ~35 ~59 ~11 ~35 stone
fill ~61 ~11 ~35 ~62 ~11 ~35 stone_slab[type=top]
fill ~83 ~11 ~35 ~83 ~11 ~37 stone
fill ~33 ~11 ~36 ~34 ~11 ~36 stone_bricks
fill ~35 ~11 ~36 ~35 ~11 ~37 stone_slab[type=top]
fill ~38 ~11 ~36 ~38 ~11 ~37 stone_slab[type=top]
setblock ~39 ~11 ~36 stone_bricks
fill ~40 ~11 ~36 ~41 ~11 ~36 mossy_stone_bricks
fill ~42 ~11 ~36 ~45 ~11 ~36 stone_bricks
setblock ~46 ~11 ~36 cracked_stone_bricks
fill ~47 ~11 ~36 ~48 ~11 ~36 stone_bricks
fill ~49 ~11 ~36 ~49 ~11 ~40 stone
fill ~50 ~11 ~36 ~51 ~11 ~37 stone_bricks
fill ~52 ~11 ~36 ~52 ~11 ~37 mossy_stone_bricks
fill ~53 ~11 ~36 ~53 ~11 ~37 stone_bricks
fill ~54 ~11 ~36 ~55 ~11 ~36 cracked_stone_bricks
fill ~56 ~11 ~36 ~56 ~11 ~37 stone_bricks
setblock ~57 ~11 ~36 mossy_stone_bricks
fill ~58 ~11 ~36 ~58 ~11 ~37 stone_bricks
fill ~59 ~11 ~36 ~59 ~11 ~37 mossy_stone_bricks
fill ~60 ~11 ~36 ~60 ~11 ~37 stone_slab[type=top]
fill ~63 ~11 ~36 ~63 ~11 ~37 stone_slab[type=top]
setblock ~64 ~11 ~36 mossy_stone_bricks
fill ~65 ~11 ~36 ~65 ~11 ~37 stone_bricks
fill ~14 ~11 ~37 ~32 ~11 ~37 stone
fill ~33 ~11 ~37 ~34 ~11 ~37 mossy_stone_bricks
setblock ~39 ~11 ~37 mossy_stone_bricks
setblock ~40 ~11 ~37 cracked_stone_bricks
setblock ~41 ~11 ~37 mossy_stone_bricks
fill ~42 ~11 ~37 ~43 ~11 ~37 stone_bricks
setblock ~44 ~11 ~37 mossy_stone_bricks
fill ~45 ~11 ~37 ~46 ~11 ~37 stone_bricks
fill ~47 ~11 ~37 ~48 ~11 ~37 mossy_stone_bricks
setblock ~54 ~11 ~37 stone_bricks
setblock ~55 ~11 ~37 mossy_stone_bricks
fill ~57 ~11 ~37 ~58 ~11 ~37 stone_bricks
fill ~64 ~11 ~37 ~65 ~11 ~37 stone_bricks
fill ~19 ~11 ~38 ~34 ~11 ~38 stone
fill ~36 ~11 ~38 ~37 ~11 ~38 stone_slab[type=top]
fill ~46 ~11 ~38 ~46 ~11 ~40 stone
fill ~47 ~11 ~38 ~48 ~11 ~39 stone_bricks
setblock ~50 ~11 ~38 cracked_stone_bricks
fill ~51 ~11 ~38 ~51 ~11 ~42 stone_bricks
fill ~52 ~11 ~38 ~59 ~11 ~40 stone
fill ~61 ~11 ~38 ~62 ~11 ~38 stone_slab[type=top]
fill ~63 ~11 ~38 ~63 ~12 ~38 mossy_stone_bricks
fill ~79 ~11 ~38 ~79 ~12 ~38 stone
fill ~81 ~11 ~38 ~81 ~12 ~38 polished_andesite
fill ~22 ~11 ~39 ~35 ~11 ~39 stone
fill ~36 ~11 ~39 ~37 ~11 ~39 mossy_stone_bricks
fill ~41 ~11 ~39 ~42 ~12 ~42 stone
fill ~44 ~11 ~39 ~46 ~11 ~40 stone
setblock ~50 ~11 ~39 mossy_stone_bricks
setblock ~61 ~11 ~39 mossy_stone_bricks
fill ~72 ~11 ~39 ~76 ~13 ~39 stone
fill ~24 ~11 ~40 ~34 ~13 ~40 stone
fill ~36 ~11 ~40 ~37 ~11 ~40 stone_bricks
fill ~40 ~11 ~40 ~43 ~12 ~40 stone
setblock ~47 ~11 ~40 mossy_stone_bricks
fill ~48 ~11 ~40 ~48 ~11 ~41 stone_bricks
fill ~50 ~11 ~40 ~51 ~11 ~40 stone_bricks
setblock ~61 ~11 ~40 cracked_stone_bricks
fill ~62 ~11 ~40 ~62 ~11 ~41 mossy_stone_bricks
fill ~65 ~11 ~40 ~65 ~13 ~59 stone
fill ~68 ~11 ~40 ~73 ~13 ~40 stone
fill ~27 ~11 ~41 ~35 ~11 ~41 stone
setblock ~36 ~11 ~41 mossy_stone_bricks
fill ~37 ~11 ~41 ~37 ~11 ~42 stone_bricks
fill ~43 ~11 ~41 ~43 ~11 ~42 stone
setblock ~44 ~11 ~41 cracked_stone_bricks
fill ~45 ~11 ~41 ~45 ~11 ~43 stone_bricks
fill ~46 ~11 ~41 ~46 ~11 ~42 mossy_stone_bricks
fill ~47 ~11 ~41 ~49 ~11 ~41 stone_bricks
setblock ~50 ~11 ~41 mossy_stone_bricks
setblock ~53 ~11 ~41 mossy_stone_bricks
fill ~54 ~11 ~41 ~54 ~11 ~43 stone_bricks
fill ~55 ~11 ~41 ~60 ~11 ~42 stone
fill ~61 ~11 ~41 ~62 ~11 ~41 mossy_stone_bricks
fill ~68 ~11 ~41 ~71 ~12 ~41 stone
fill ~29 ~11 ~42 ~35 ~11 ~42 stone
fill ~36 ~11 ~42 ~37 ~11 ~42 stone_bricks
fill ~38 ~11 ~42 ~40 ~11 ~46 stone
fill ~44 ~11 ~42 ~45 ~11 ~43 stone_bricks
setblock ~47 ~11 ~42 stone_bricks
fill ~48 ~11 ~42 ~48 ~11 ~43 stone_brick_slab[type=top]
fill ~49 ~11 ~42 ~49 ~11 ~43 stone_brick_slab[type=double]
fill ~50 ~11 ~42 ~50 ~11 ~43 stone_brick_slab[type=top]
fill ~52 ~11 ~42 ~54 ~11 ~42 stone_bricks
fill ~61 ~11 ~42 ~62 ~11 ~43 stone_bricks
fill ~64 ~11 ~42 ~66 ~13 ~47 stone
fill ~68 ~11 ~42 ~68 ~13 ~42 stone
setblock ~69 ~11 ~42 stone
fill ~36 ~11 ~43 ~36 ~11 ~44 cracked_stone_bricks
setblock ~37 ~11 ~43 mossy_stone_bricks
fill ~41 ~11 ~43 ~42 ~11 ~43 stone
fill ~43 ~11 ~43 ~45 ~11 ~43 stone_bricks
setblock ~46 ~11 ~43 stone_brick_slab[type=top]
setblock ~52 ~11 ~43 stone_brick_slab[type=top]
fill ~53 ~11 ~43 ~55 ~11 ~43 stone_bricks
fill ~56 ~11 ~43 ~60 ~11 ~43 stone
fill ~69 ~11 ~43 ~69 ~13 ~43 birch_leaves[persistent=false]
fill ~31 ~11 ~44 ~34 ~12 ~44 stone
fill ~37 ~11 ~44 ~37 ~11 ~45 stone_bricks
fill ~41 ~11 ~44 ~43 ~11 ~44 stone_bricks
setblock ~44 ~11 ~44 cracked_stone_bricks
setblock ~45 ~11 ~44 stone_brick_slab[type=top]
setblock ~49 ~11 ~44 stone_brick_slab[type=top]
setblock ~53 ~11 ~44 stone_brick_slab[type=top]
setblock ~54 ~11 ~44 cracked_stone_bricks
fill ~55 ~11 ~44 ~56 ~11 ~45 stone_bricks
setblock ~57 ~11 ~44 cracked_stone_bricks
fill ~58 ~11 ~44 ~60 ~11 ~46 stone
setblock ~61 ~11 ~44 mossy_stone_bricks
fill ~62 ~11 ~44 ~62 ~11 ~45 stone_bricks
setblock ~68 ~11 ~44 birch_leaves[persistent=false]
fill ~35 ~11 ~45 ~35 ~11 ~59 stone
fill ~36 ~11 ~45 ~37 ~11 ~45 stone_bricks
setblock ~41 ~11 ~45 mossy_stone_bricks
fill ~42 ~11 ~45 ~42 ~11 ~47 stone_bricks
setblock ~43 ~11 ~45 stone_bricks
setblock ~44 ~11 ~45 stone_brick_slab[type=top]
setblock ~54 ~11 ~45 stone_brick_slab[type=top]
setblock ~57 ~11 ~45 stone_bricks
fill ~61 ~11 ~45 ~62 ~11 ~45 stone_bricks
fill ~23 ~11 ~46 ~23 ~13 ~52 stone
fill ~33 ~11 ~46 ~35 ~11 ~59 stone
fill ~36 ~11 ~46 ~37 ~11 ~46 mossy_stone_bricks
setblock ~43 ~11 ~46 stone_brick_slab[type=top]
setblock ~49 ~11 ~46 stone_brick_slab[type=top]
setblock ~55 ~11 ~46 stone_brick_slab[type=top]
fill ~56 ~11 ~46 ~57 ~11 ~46 mossy_stone_bricks
setblock ~61 ~11 ~46 stone_bricks
setblock ~62 ~11 ~46 cracked_stone_bricks
fill ~75 ~11 ~46 ~75 ~13 ~52 stone
fill ~36 ~11 ~47 ~42 ~11 ~47 stone_bricks
fill ~56 ~11 ~47 ~57 ~11 ~47 stone_bricks
setblock ~58 ~11 ~47 mossy_stone_bricks
fill ~59 ~11 ~47 ~60 ~11 ~48 stone_bricks
fill ~61 ~11 ~47 ~61 ~11 ~48 mossy_stone_bricks
fill ~62 ~11 ~47 ~62 ~11 ~48 stone_bricks
fill ~74 ~11 ~47 ~75 ~13 ~49 stone
fill ~36 ~11 ~48 ~37 ~11 ~48 stone_bricks
setblock ~38 ~11 ~48 cracked_stone_bricks
setblock ~39 ~11 ~48 mossy_stone_bricks
setblock ~40 ~11 ~48 stone_bricks
setblock ~41 ~11 ~48 mossy_stone_bricks
fill ~42 ~11 ~48 ~43 ~11 ~48 stone_brick_slab[type=top]
setblock ~56 ~11 ~48 stone_brick_slab[type=top]
fill ~57 ~11 ~48 ~60 ~11 ~48 stone_bricks
fill ~64 ~11 ~48 ~65 ~11 ~60 stone
fill ~66 ~11 ~48 ~67 ~13 ~49 stone
fill ~76 ~11 ~48 ~76 ~13 ~50 stone
fill ~25 ~11 ~49 ~25 ~13 ~49 stone
fill ~30 ~11 ~49 ~35 ~13 ~49 stone
fill ~36 ~11 ~49 ~40 ~11 ~49 stone
fill ~41 ~11 ~49 ~41 ~11 ~51 stone_bricks
fill ~42 ~11 ~49 ~43 ~11 ~49 stone_brick_slab[type=double]
setblock ~44 ~11 ~49 stone_brick_slab[type=top]
setblock ~46 ~11 ~49 stone_brick_slab[type=top]
setblock ~52 ~11 ~49 stone_brick_slab[type=top]
setblock ~55 ~11 ~49 stone_brick_slab[type=top]
setblock ~56 ~11 ~49 stone_brick_slab[type=double]
setblock ~57 ~11 ~49 stone_bricks
fill ~58 ~11 ~49 ~68 ~11 ~49 stone
fill ~73 ~11 ~49 ~76 ~13 ~49 stone
fill ~22 ~11 ~50 ~24 ~13 ~50 stone
fill ~31 ~11 ~50 ~33 ~13 ~50 stone
fill ~36 ~11 ~50 ~36 ~11 ~51 stone_bricks
fill ~37 ~11 ~50 ~37 ~11 ~51 mossy_stone_bricks
fill ~38 ~11 ~50 ~41 ~11 ~50 stone_bricks
fill ~42 ~11 ~50 ~43 ~11 ~50 stone_brick_slab[type=top]
setblock ~51 ~11 ~50 stone
setblock ~56 ~11 ~50 stone_brick_slab[type=top]
setblock ~57 ~11 ~50 mossy_stone_bricks
fill ~58 ~11 ~50 ~58 ~11 ~51 stone_bricks
setblock ~59 ~11 ~50 mossy_stone_bricks
setblock ~60 ~11 ~50 cracked_stone_bricks
fill ~61 ~11 ~50 ~62 ~11 ~51 stone_bricks
fill ~24 ~11 ~51 ~24 ~13 ~51 stone
fill ~32 ~11 ~51 ~34 ~13 ~59 stone
fill ~38 ~11 ~51 ~39 ~11 ~51 stone_bricks
setblock ~40 ~11 ~51 mossy_stone_bricks
setblock ~42 ~11 ~51 stone_bricks
setblock ~49 ~11 ~51 stone
fill ~56 ~11 ~51 ~62 ~11 ~51 stone_bricks
fill ~66 ~11 ~51 ~66 ~13 ~60 stone
setblock ~36 ~11 ~52 cracked_stone_bricks
fill ~37 ~11 ~52 ~37 ~11 ~53 stone_bricks
fill ~38 ~11 ~52 ~40 ~11 ~59 stone
fill ~41 ~11 ~52 ~42 ~11 ~52 mossy_stone_bricks
setblock ~43 ~11 ~52 stone_brick_slab[type=top]
setblock ~49 ~11 ~52 stone_brick_slab[type=top]
setblock ~55 ~11 ~52 stone_brick_slab[type=top]
fill ~56 ~11 ~52 ~56 ~11 ~54 stone_bricks
fill ~58 ~11 ~52 ~60 ~11 ~59 stone
fill ~61 ~11 ~52 ~62 ~11 ~52 mossy_stone_bricks
fill ~36 ~11 ~53 ~36 ~11 ~56 stone_bricks
fill ~41 ~11 ~53 ~43 ~11 ~53 stone_bricks
setblock ~44 ~11 ~53 stone_brick_slab[type=top]
setblock ~54 ~11 ~53 stone_brick_slab[type=top]
fill ~55 ~11 ~53 ~56 ~11 ~54 stone_bricks
setblock ~57 ~11 ~53 mossy_stone_bricks
fill ~61 ~11 ~53 ~62 ~11 ~53 stone_bricks
setblock ~30 ~11 ~54 birch_leaves[persistent=false]
fill ~31 ~11 ~54 ~34 ~13 ~59 stone
setblock ~37 ~11 ~54 mossy_stone_bricks
setblock ~41 ~11 ~54 cracked_stone_bricks
fill ~42 ~11 ~54 ~43 ~11 ~54 stone_bricks
setblock ~44 ~11 ~54 cracked_stone_bricks
setblock ~45 ~11 ~54 stone_brick_slab[type=top]
fill ~49 ~11 ~54 ~49 ~11 ~55 stone_brick_slab[type=top]
setblock ~53 ~11 ~54 stone_brick_slab[type=top]
setblock ~54 ~11 ~54 cracked_stone_bricks
setblock ~57 ~11 ~54 stone_bricks
setblock ~61 ~11 ~54 stone_bricks
fill ~62 ~11 ~54 ~62 ~11 ~55 cracked_stone_bricks
fill ~67 ~11 ~54 ~67 ~12 ~68 stone
fill ~29 ~11 ~55 ~29 ~13 ~55 birch_leaves[persistent=false]
fill ~37 ~11 ~55 ~37 ~11 ~56 stone_bricks
fill ~41 ~11 ~55 ~42 ~11 ~60 stone
fill ~43 ~11 ~55 ~45 ~11 ~55 stone_bricks
setblock ~46 ~11 ~55 stone_brick_slab[type=top]
setblock ~52 ~11 ~55 stone_brick_slab[type=top]
fill ~53 ~11 ~55 ~55 ~11 ~55 stone_bricks
fill ~56 ~11 ~55 ~60 ~11 ~59 stone
setblock ~61 ~11 ~55 mossy_stone_bricks
fill ~29 ~11 ~56 ~35 ~11 ~59 stone
fill ~43 ~11 ~56 ~43 ~11 ~60 stone
fill ~44 ~11 ~56 ~47 ~11 ~56 stone_bricks
setblock ~48 ~11 ~56 stone_brick_slab[type=top]
setblock ~49 ~11 ~56 stone_brick_slab[type=double]
setblock ~50 ~11 ~56 stone_brick_slab[type=top]
fill ~51 ~11 ~56 ~51 ~11 ~57 stone_bricks
fill ~52 ~11 ~56 ~52 ~11 ~57 mossy_stone_bricks
setblock ~54 ~11 ~56 stone_bricks
fill ~55 ~11 ~56 ~59 ~11 ~60 stone
fill ~61 ~11 ~56 ~61 ~11 ~58 stone_bricks
setblock ~62 ~11 ~56 stone_bricks
fill ~68 ~11 ~56 ~69 ~11 ~71 stone
fill ~27 ~11 ~57 ~29 ~11 ~73 stone
fill ~36 ~11 ~57 ~37 ~11 ~57 mossy_stone_bricks
setblock ~44 ~11 ~57 stone_bricks
setblock ~45 ~11 ~57 mossy_stone_bricks
setblock ~48 ~11 ~57 mossy_stone_bricks
fill ~49 ~11 ~57 ~51 ~11 ~57 stone_bricks
setblock ~53 ~11 ~57 stone_bricks
setblock ~54 ~11 ~57 cracked_stone_bricks
setblock ~62 ~11 ~57 mossy_stone_bricks
fill ~71 ~11 ~57 ~71 ~11 ~73 stone
fill ~25 ~11 ~58 ~32 ~11 ~66 stone
setblock ~36 ~11 ~58 mossy_stone_bricks
setblock ~37 ~11 ~58 cracked_stone_bricks
fill ~44 ~11 ~58 ~46 ~11 ~60 stone
fill ~47 ~11 ~58 ~47 ~11 ~62 stone_bricks
setblock ~48 ~11 ~58 stone_bricks
fill ~49 ~11 ~58 ~49 ~11 ~68 stone
fill ~50 ~11 ~58 ~50 ~11 ~60 stone_bricks
setblock ~51 ~11 ~58 mossy_stone_bricks
fill ~52 ~11 ~58 ~59 ~11 ~60 stone
setblock ~62 ~11 ~58 stone_bricks
fill ~72 ~11 ~58 ~74 ~12 ~65 stone
fill ~22 ~11 ~59 ~32 ~11 ~65 stone
setblock ~36 ~11 ~59 stone_bricks
setblock ~37 ~11 ~59 mossy_stone_bricks
setblock ~48 ~11 ~59 mossy_stone_bricks
fill ~51 ~11 ~59 ~51 ~11 ~60 stone_bricks
fill ~61 ~11 ~59 ~62 ~11 ~59 mossy_stone_bricks
fill ~75 ~11 ~59 ~76 ~11 ~65 stone
fill ~17 ~11 ~60 ~17 ~12 ~60 polished_andesite
fill ~19 ~11 ~60 ~32 ~11 ~64 stone
fill ~33 ~11 ~60 ~34 ~11 ~60 stone
fill ~35 ~11 ~60 ~35 ~12 ~60 mossy_stone_bricks
fill ~36 ~11 ~60 ~37 ~11 ~60 stone_slab[type=top]
setblock ~48 ~11 ~60 cracked_stone_bricks
fill ~61 ~11 ~60 ~62 ~11 ~60 stone_slab[type=top]
fill ~79 ~11 ~60 ~79 ~11 ~64 stone
fill ~14 ~11 ~61 ~32 ~11 ~61 stone
fill ~33 ~11 ~61 ~34 ~11 ~61 stone_bricks
fill ~35 ~11 ~61 ~35 ~11 ~62 stone_slab[type=top]
fill ~38 ~11 ~61 ~38 ~11 ~62 stone_slab[type=top]
fill ~39 ~11 ~61 ~39 ~11 ~62 mossy_stone_bricks
fill ~40 ~11 ~61 ~42 ~11 ~61 stone_bricks
setblock ~43 ~11 ~61 mossy_stone_bricks
fill ~44 ~11 ~61 ~45 ~11 ~61 stone_bricks
fill ~46 ~11 ~61 ~46 ~11 ~62 mossy_stone_bricks
fill ~48 ~11 ~61 ~48 ~11 ~62 stone_bricks
fill ~50 ~11 ~61 ~51 ~11 ~61 mossy_stone_bricks
fill ~52 ~11 ~61 ~53 ~11 ~61 stone_bricks
setblock ~54 ~11 ~61 mossy_stone_bricks
fill ~55 ~11 ~61 ~56 ~11 ~62 stone_bricks
fill ~57 ~11 ~61 ~57 ~11 ~62 mossy_stone_bricks
setblock ~58 ~11 ~61 cracked_stone_bricks
setblock ~59 ~11 ~61 mossy_stone_bricks
fill ~60 ~11 ~61 ~60 ~11 ~62 stone_slab[type=top]
fill ~63 ~11 ~61 ~63 ~11 ~62 stone_slab[type=top]
fill ~64 ~11 ~61 ~65 ~11 ~61 mossy_stone_bricks
fill ~15 ~11 ~62 ~32 ~11 ~63 stone
setblock ~33 ~11 ~62 stone_bricks
setblock ~34 ~11 ~62 mossy_stone_bricks
setblock ~40 ~11 ~62 stone_bricks
setblock ~41 ~11 ~62 mossy_stone_bricks
setblock ~42 ~11 ~62 stone_bricks
fill ~43 ~11 ~62 ~44 ~11 ~62 cracked_stone_bricks
setblock ~45 ~11 ~62 stone_bricks
fill ~50 ~11 ~62 ~51 ~11 ~62 stone_bricks
setblock ~52 ~11 ~62 cracked_stone_bricks
fill ~53 ~11 ~62 ~56 ~11 ~62 stone_bricks
setblock ~58 ~11 ~62 mossy_stone_bricks
setblock ~65 ~11 ~62 stone_bricks
fill ~36 ~11 ~63 ~37 ~11 ~63 stone_slab[type=top]
fill ~45 ~11 ~63 ~59 ~11 ~65 stone
fill ~60 ~11 ~63 ~60 ~12 ~63 mossy_stone_bricks
fill ~61 ~11 ~63 ~62 ~11 ~63 stone_slab[type=top]
fill ~80 ~11 ~63 ~82 ~11 ~64 stone
setblock ~83 ~11 ~63 stone
fill ~16 ~11 ~64 ~35 ~11 ~64 stone
fill ~37 ~11 ~64 ~37 ~11 ~65 mossy_stone_bricks
fill ~43 ~11 ~64 ~47 ~13 ~66 stone
fill ~61 ~11 ~64 ~61 ~11 ~65 stone_bricks
setblock ~62 ~11 ~64 mossy_stone_bricks
fill ~65 ~11 ~64 ~76 ~12 ~65 stone
fill ~78 ~11 ~64 ~82 ~11 ~64 stone
fill ~20 ~11 ~65 ~35 ~11 ~65 stone
setblock ~36 ~11 ~65 stone_bricks
fill ~39 ~11 ~65 ~59 ~13 ~65 stone
setblock ~62 ~11 ~65 stone_bricks
fill ~77 ~11 ~65 ~78 ~11 ~65 stone
fill ~7 ~11 ~66 ~7 ~12 ~66 birch_leaves[persistent=false]
fill ~8 ~11 ~66 ~8 ~13 ~66 stone_bricks
setblock ~23 ~11 ~66 stone
fill ~50 ~11 ~66 ~59 ~13 ~66 stone
setblock ~75 ~11 ~66 stone
fill ~90 ~11 ~66 ~90 ~13 ~66 stone_bricks
setblock ~9 ~11 ~67 dirt
fill ~26 ~11 ~67 ~44 ~11 ~67 stone
fill ~50 ~11 ~67 ~50 ~13 ~67 stone
fill ~54 ~11 ~67 ~60 ~13 ~67 stone
fill ~89 ~11 ~67 ~89 ~11 ~69 stone
setblock ~6 ~11 ~68 stone_slab[type=top]
fill ~7 ~11 ~68 ~7 ~13 ~68 stone_bricks
fill ~9 ~11 ~68 ~9 ~11 ~69 stone
setblock ~10 ~11 ~68 stone_slab[type=double]
fill ~26 ~11 ~68 ~26 ~14 ~68 polished_andesite
fill ~40 ~11 ~68 ~40 ~13 ~74 stone
fill ~42 ~11 ~68 ~42 ~13 ~68 stone
setblock ~54 ~11 ~68 birch_leaves[persistent=false]
fill ~56 ~11 ~68 ~71 ~11 ~69 stone
fill ~72 ~11 ~68 ~72 ~14 ~68 polished_andesite
setblock ~88 ~11 ~68 stone_slab[type=double]
fill ~91 ~11 ~68 ~91 ~12 ~68 stone
setblock ~92 ~11 ~68 stone_slab[type=top]
setblock ~5 ~11 ~69 stone_slab[type=top]
setblock ~7 ~11 ~69 stone
setblock ~8 ~11 ~69 stone_slab[type=top]
fill ~10 ~11 ~69 ~10 ~11 ~70 stone
setblock ~11 ~11 ~69 stone_slab[type=double]
fill ~25 ~11 ~69 ~29 ~11 ~72 stone
setblock ~42 ~11 ~69 stone
fill ~55 ~11 ~69 ~55 ~13 ~69 birch_leaves[persistent=false]
fill ~72 ~11 ~69 ~73 ~11 ~72 stone
setblock ~87 ~11 ~69 stone_slab[type=double]
fill ~88 ~11 ~69 ~89 ~11 ~69 stone
setblock ~90 ~11 ~69 stone_slab[type=top]
setblock ~93 ~11 ~69 stone_slab[type=top]
setblock ~4 ~11 ~70 dirt
setblock ~7 ~11 ~70 stone_brick_slab[type=double]
setblock ~8 ~11 ~70 stone_brick_slab[type=top]
setblock ~9 ~11 ~70 diamond_ore
fill ~11 ~11 ~70 ~11 ~11 ~72 stone
setblock ~12 ~11 ~70 stone
fill ~57 ~11 ~70 ~66 ~12 ~71 stone
setblock ~86 ~11 ~70 dirt
fill ~87 ~11 ~70 ~88 ~11 ~70 stone
setblock ~89 ~11 ~70 diamond_ore
setblock ~90 ~11 ~70 stone_brick_slab[type=top]
setblock ~91 ~11 ~70 stone_brick_slab[type=double]
setblock ~94 ~11 ~70 dirt
setblock ~6 ~11 ~71 stone_slab[type=top]
fill ~7 ~11 ~71 ~7 ~11 ~72 stone_brick_slab[type=top]
setblock ~8 ~11 ~71 stone_brick_slab[type=double]
setblock ~9 ~11 ~71 stone_brick_slab[type=top]
setblock ~10 ~11 ~71 stone_slab[type=top]
fill ~13 ~11 ~71 ~13 ~13 ~71 stone_bricks
fill ~41 ~11 ~71 ~41 ~13 ~71 stone
fill ~85 ~11 ~71 ~85 ~13 ~71 stone_bricks
setblock ~88 ~11 ~71 stone_slab[type=top]
setblock ~89 ~11 ~71 stone_brick_slab[type=top]
setblock ~90 ~11 ~71 stone_brick_slab[type=double]
fill ~91 ~11 ~71 ~91 ~11 ~72 stone_brick_slab[type=top]
setblock ~92 ~11 ~71 stone_slab[type=top]
setblock ~4 ~11 ~72 dirt
setblock ~5 ~11 ~72 stone
setblock ~8 ~11 ~72 stone_brick_slab[type=top]
setblock ~9 ~11 ~72 stone_brick_slab[type=double]
fill ~30 ~11 ~72 ~30 ~14 ~72 polished_andesite
fill ~31 ~11 ~72 ~40 ~11 ~72 stone
fill ~58 ~11 ~72 ~60 ~13 ~73 stone
fill ~61 ~11 ~72 ~65 ~12 ~75 stone
fill ~68 ~11 ~72 ~68 ~14 ~72 polished_andesite
fill ~69 ~11 ~72 ~72 ~11 ~73 stone
fill ~85 ~11 ~72 ~85 ~12 ~72 birch_leaves[persistent=false]
fill ~87 ~11 ~72 ~87 ~13 ~72 stone_bricks
fill ~88 ~11 ~72 ~88 ~11 ~73 stone
setblock ~89 ~11 ~72 stone_brick_slab[type=double]
fill ~90 ~11 ~72 ~91 ~11 ~72 stone_brick_slab[type=top]
setblock ~94 ~11 ~72 stone
setblock ~4 ~11 ~73 grass_block
setblock ~8 ~11 ~73 stone_slab[type=top]
setblock ~11 ~11 ~73 stone_slab[type=top]
fill ~26 ~11 ~73 ~29 ~11 ~73 stone
fill ~32 ~11 ~73 ~40 ~11 ~73 stone
fill ~49 ~11 ~73 ~49 ~13 ~76 stone
setblock ~87 ~11 ~73 stone_slab[type=top]
setblock ~90 ~11 ~73 stone_slab[type=top]
setblock ~94 ~11 ~73 grass_block
fill ~5 ~11 ~74 ~6 ~12 ~74 stone_bricks
setblock ~10 ~11 ~74 stone_slab[type=top]
fill ~51 ~11 ~74 ~51 ~13 ~75 stone
fill ~59 ~11 ~74 ~65 ~12 ~75 stone
setblock ~88 ~11 ~74 stone_slab[type=top]
setblock ~91 ~11 ~74 stone
fill ~93 ~11 ~74 ~93 ~12 ~74 stone_bricks
fill ~4 ~11 ~75 ~4 ~13 ~75 birch_leaves[persistent=false]
setblock ~6 ~11 ~75 grass_block
setblock ~7 ~11 ~75 stone
setblock ~9 ~11 ~75 dirt
fill ~17 ~11 ~75 ~17 ~12 ~75 birch_leaves[persistent=false]
fill ~18 ~11 ~75 ~18 ~12 ~75 stone_bricks
fill ~32 ~11 ~75 ~39 ~11 ~75 stone
fill ~46 ~11 ~75 ~52 ~13 ~75 stone
setblock ~66 ~11 ~75 stone
fill ~80 ~11 ~75 ~80 ~13 ~75 stone_bricks
setblock ~89 ~11 ~75 dirt
setblock ~91 ~11 ~75 dirt
setblock ~92 ~11 ~75 grass_block
fill ~94 ~11 ~75 ~94 ~13 ~75 birch_leaves[persistent=false]
setblock ~19 ~11 ~76 dirt
setblock ~39 ~11 ~76 stone
fill ~50 ~11 ~76 ~50 ~13 ~76 stone
fill ~59 ~11 ~76 ~65 ~11 ~76 stone
fill ~79 ~11 ~76 ~79 ~11 ~78 stone
setblock ~16 ~11 ~77 stone_slab[type=top]
setblock ~17 ~11 ~77 mossy_stone_bricks
fill ~19 ~11 ~77 ~19 ~11 ~78 stone
setblock ~20 ~11 ~77 stone_slab[type=double]
fill ~33 ~11 ~77 ~38 ~11 ~78 stone
fill ~60 ~11 ~77 ~64 ~11 ~79 stone
fill ~65 ~11 ~77 ~65 ~11 ~78 stone
setblock ~78 ~11 ~77 stone_slab[type=double]
fill ~81 ~11 ~77 ~81 ~12 ~77 stone
setblock ~82 ~11 ~77 stone_slab[type=top]
setblock ~15 ~11 ~78 stone_slab[type=top]
setblock ~17 ~11 ~78 stone
setblock ~18 ~11 ~78 stone_slab[type=top]
fill ~20 ~11 ~78 ~20 ~11 ~79 stone
setblock ~21 ~11 ~78 stone_slab[type=double]
setblock ~77 ~11 ~78 stone_slab[type=double]
fill ~78 ~11 ~78 ~79 ~11 ~78 stone
setblock ~80 ~11 ~78 stone_slab[type=top]
setblock ~83 ~11 ~78 stone_slab[type=top]
setblock ~14 ~11 ~79 dirt
setblock ~17 ~11 ~79 stone_brick_slab[type=double]
setblock ~18 ~11 ~79 stone_brick_slab[type=top]
setblock ~19 ~11 ~79 diamond_ore
fill ~21 ~11 ~79 ~21 ~11 ~81 stone
setblock ~22 ~11 ~79 stone
fill ~34 ~11 ~79 ~37 ~11 ~82 stone
setblock ~38 ~11 ~79 stone
setblock ~76 ~11 ~79 dirt
fill ~77 ~11 ~79 ~78 ~11 ~79 stone
setblock ~79 ~11 ~79 diamond_ore
setblock ~80 ~11 ~79 stone_brick_slab[type=top]
setblock ~81 ~11 ~79 stone_brick_slab[type=double]
setblock ~84 ~11 ~79 dirt
setblock ~16 ~11 ~80 stone_slab[type=top]
fill ~17 ~11 ~80 ~17 ~11 ~81 stone_brick_slab[type=top]
setblock ~18 ~11 ~80 stone_brick_slab[type=double]
setblock ~19 ~11 ~80 stone_brick_slab[type=top]
setblock ~20 ~11 ~80 stone_slab[type=top]
fill ~23 ~11 ~80 ~23 ~13 ~80 stone_bricks
fill ~75 ~11 ~80 ~76 ~11 ~80 stone_bricks
setblock ~78 ~11 ~80 stone_slab[type=top]
setblock ~79 ~11 ~80 stone_brick_slab[type=top]
setblock ~80 ~11 ~80 stone_brick_slab[type=double]
fill ~81 ~11 ~80 ~81 ~11 ~81 stone_brick_slab[type=top]
setblock ~82 ~11 ~80 stone_slab[type=top]
setblock ~14 ~11 ~81 dirt
setblock ~15 ~11 ~81 stone
setblock ~18 ~11 ~81 stone_brick_slab[type=top]
setblock ~19 ~11 ~81 stone_brick_slab[type=double]
fill ~60 ~11 ~81 ~60 ~12 ~81 polished_andesite
fill ~75 ~11 ~81 ~75 ~12 ~81 birch_leaves[persistent=false]
setblock ~77 ~11 ~81 mossy_stone_bricks
fill ~78 ~11 ~81 ~78 ~11 ~82 stone
setblock ~79 ~11 ~81 stone_brick_slab[type=double]
fill ~80 ~11 ~81 ~81 ~11 ~81 stone_brick_slab[type=top]
setblock ~84 ~11 ~81 stone
setblock ~14 ~11 ~82 grass_block
setblock ~18 ~11 ~82 stone_slab[type=top]
setblock ~21 ~11 ~82 stone_slab[type=top]
setblock ~64 ~11 ~82 stone
setblock ~77 ~11 ~82 stone_slab[type=top]
setblock ~80 ~11 ~82 stone_slab[type=top]
setblock ~84 ~11 ~82 grass_block
fill ~15 ~11 ~83 ~15 ~12 ~83 diorite
setblock ~20 ~11 ~83 stone_slab[type=top]
fill ~35 ~11 ~83 ~37 ~11 ~83 stone
fill ~62 ~11 ~83 ~62 ~14 ~83 stone
setblock ~63 ~11 ~83 stone
setblock ~78 ~11 ~83 stone_slab[type=top]
setblock ~81 ~11 ~83 stone
fill ~83 ~11 ~83 ~83 ~12 ~83 diorite
fill ~14 ~11 ~84 ~14 ~13 ~84 birch_leaves[persistent=false]
setblock ~16 ~11 ~84 grass_block
setblock ~17 ~11 ~84 stone
setblock ~19 ~11 ~84 dirt
setblock ~79 ~11 ~84 dirt
setblock ~81 ~11 ~84 dirt
setblock ~82 ~11 ~84 grass_block
fill ~84 ~11 ~84 ~84 ~13 ~84 birch_leaves[persistent=false]
fill ~26 ~11 ~85 ~26 ~12 ~85 birch_leaves[persistent=false]
fill ~27 ~11 ~85 ~27 ~13 ~85 stone_bricks
fill ~71 ~11 ~85 ~71 ~13 ~85 stone_bricks
setblock ~28 ~11 ~86 dirt
fill ~70 ~11 ~86 ~70 ~11 ~88 stone
setblock ~25 ~11 ~87 stone_slab[type=top]
fill ~26 ~11 ~87 ~26 ~13 ~87 stone_bricks
fill ~28 ~11 ~87 ~28 ~11 ~88 stone
setblock ~29 ~11 ~87 stone_slab[type=double]
setblock ~69 ~11 ~87 stone_slab[type=double]
fill ~72 ~11 ~87 ~72 ~12 ~87 stone
setblock ~73 ~11 ~87 stone_slab[type=top]
setblock ~24 ~11 ~88 stone_slab[type=top]
setblock ~26 ~11 ~88 stone
setblock ~27 ~11 ~88 stone_slab[type=top]
fill ~29 ~11 ~88 ~29 ~11 ~89 stone
setblock ~30 ~11 ~88 stone_slab[type=double]
setblock ~68 ~11 ~88 stone_slab[type=double]
fill ~69 ~11 ~88 ~70 ~11 ~88 stone
setblock ~71 ~11 ~88 stone_slab[type=top]
setblock ~74 ~11 ~88 stone_slab[type=top]
setblock ~23 ~11 ~89 dirt
setblock ~26 ~11 ~89 stone_brick_slab[type=double]
setblock ~27 ~11 ~89 stone_brick_slab[type=top]
setblock ~28 ~11 ~89 diamond_ore
fill ~30 ~11 ~89 ~30 ~11 ~91 stone
setblock ~31 ~11 ~89 stone
setblock ~67 ~11 ~89 dirt
fill ~68 ~11 ~89 ~69 ~11 ~89 stone
setblock ~70 ~11 ~89 diamond_ore
setblock ~71 ~11 ~89 stone_brick_slab[type=top]
setblock ~72 ~11 ~89 stone_brick_slab[type=double]
setblock ~75 ~11 ~89 dirt
setblock ~25 ~11 ~90 stone_slab[type=top]
fill ~26 ~11 ~90 ~26 ~11 ~91 stone_brick_slab[type=top]
setblock ~27 ~11 ~90 stone_brick_slab[type=double]
setblock ~28 ~11 ~90 stone_brick_slab[type=top]
setblock ~29 ~11 ~90 stone_slab[type=top]
fill ~32 ~11 ~90 ~32 ~13 ~90 stone_bricks
fill ~66 ~11 ~90 ~66 ~13 ~90 stone_bricks
setblock ~69 ~11 ~90 stone_slab[type=top]
setblock ~70 ~11 ~90 stone_brick_slab[type=top]
setblock ~71 ~11 ~90 stone_brick_slab[type=double]
fill ~72 ~11 ~90 ~72 ~11 ~91 stone_brick_slab[type=top]
setblock ~73 ~11 ~90 stone_slab[type=top]
setblock ~23 ~11 ~91 dirt
setblock ~24 ~11 ~91 stone
setblock ~27 ~11 ~91 stone_brick_slab[type=top]
setblock ~28 ~11 ~91 stone_brick_slab[type=double]
fill ~66 ~11 ~91 ~66 ~12 ~91 birch_leaves[persistent=false]
fill ~68 ~11 ~91 ~68 ~13 ~91 stone_bricks
fill ~69 ~11 ~91 ~69 ~11 ~92 stone
setblock ~70 ~11 ~91 stone_brick_slab[type=double]
fill ~71 ~11 ~91 ~72 ~11 ~91 stone_brick_slab[type=top]
setblock ~75 ~11 ~91 stone
setblock ~23 ~11 ~92 grass_block
setblock ~27 ~11 ~92 stone_slab[type=top]
setblock ~30 ~11 ~92 stone_slab[type=top]
setblock ~68 ~11 ~92 stone_slab[type=top]
setblock ~71 ~11 ~92 stone_slab[type=top]
setblock ~75 ~11 ~92 grass_block
fill ~24 ~11 ~93 ~25 ~12 ~93 stone_bricks
setblock ~29 ~11 ~93 stone_slab[type=top]
setblock ~69 ~11 ~93 stone_slab[type=top]
setblock ~72 ~11 ~93 stone
fill ~74 ~11 ~93 ~74 ~12 ~93 stone_bricks
fill ~23 ~11 ~94 ~23 ~13 ~94 birch_leaves[persistent=false]
setblock ~25 ~11 ~94 grass_block
setblock ~26 ~11 ~94 stone
setblock ~28 ~11 ~94 dirt
setblock ~70 ~11 ~94 dirt
setblock ~72 ~11 ~94 dirt
setblock ~73 ~11 ~94 grass_block
fill ~75 ~11 ~94 ~75 ~13 ~94 birch_leaves[persistent=false]
fill ~25 ~12 ~2 ~25 ~15 ~2 birch_leaves[persistent=false]
fill ~26 ~12 ~4 ~26 ~12 ~5 grass_block
setblock ~28 ~12 ~4 grass_block
setblock ~70 ~12 ~4 grass_block
fill ~72 ~12 ~4 ~72 ~12 ~5 grass_block
fill ~27 ~12 ~5 ~27 ~13 ~5 oak_log[axis=y]
fill ~71 ~12 ~5 ~71 ~13 ~5 oak_log[axis=y]
fill ~26 ~12 ~6 ~26 ~12 ~7 stone_bricks
setblock ~27 ~12 ~6 grass_block
fill ~28 ~12 ~6 ~28 ~12 ~8 stone_bricks
setblock ~29 ~12 ~6 stone_slab[type=bottom]
setblock ~69 ~12 ~6 stone_slab[type=bottom]
fill ~70 ~12 ~6 ~70 ~12 ~8 stone_bricks
setblock ~71 ~12 ~6 grass_block
fill ~72 ~12 ~6 ~72 ~12 ~7 stone_bricks
fill ~77 ~12 ~6 ~77 ~15 ~6 birch_leaves[persistent=false]
fill ~23 ~12 ~7 ~24 ~12 ~7 grass_block
fill ~25 ~12 ~7 ~26 ~12 ~7 stone_bricks
fill ~27 ~12 ~7 ~27 ~12 ~8 polished_andesite
fill ~29 ~12 ~7 ~30 ~12 ~7 stone_bricks
fill ~31 ~12 ~7 ~31 ~12 ~9 grass_block
fill ~67 ~12 ~7 ~67 ~12 ~9 grass_block
setblock ~68 ~12 ~7 stone
fill ~69 ~12 ~7 ~70 ~12 ~7 stone_bricks
fill ~71 ~12 ~7 ~71 ~12 ~8 polished_andesite
setblock ~73 ~12 ~7 stone_bricks
fill ~74 ~12 ~7 ~75 ~12 ~7 grass_block
fill ~24 ~12 ~8 ~24 ~13 ~8 oak_log[axis=y]
setblock ~25 ~12 ~8 grass_block
fill ~26 ~12 ~8 ~27 ~12 ~8 polished_andesite
fill ~29 ~12 ~8 ~31 ~12 ~8 grass_block
fill ~68 ~12 ~8 ~69 ~12 ~8 grass_block
setblock ~72 ~12 ~8 polished_andesite
setblock ~73 ~12 ~8 grass_block
fill ~74 ~12 ~8 ~74 ~13 ~8 oak_log[axis=y]
setblock ~23 ~12 ~9 grass_block
fill ~25 ~12 ~9 ~27 ~12 ~9 stone_bricks
setblock ~28 ~12 ~9 polished_andesite
setblock ~29 ~12 ~9 stone_bricks
fill ~30 ~12 ~9 ~31 ~12 ~9 grass_block
setblock ~68 ~12 ~9 grass_block
setblock ~69 ~12 ~9 stone_bricks
setblock ~70 ~12 ~9 polished_andesite
fill ~71 ~12 ~9 ~74 ~12 ~9 stone_bricks
setblock ~75 ~12 ~9 grass_block
setblock ~25 ~12 ~10 stone_slab[type=bottom]
setblock ~26 ~12 ~10 stone_bricks
fill ~27 ~12 ~10 ~27 ~12 ~12 grass_block
setblock ~28 ~12 ~10 stone_bricks
fill ~29 ~12 ~10 ~30 ~12 ~10 stone_slab[type=bottom]
fill ~68 ~12 ~10 ~69 ~12 ~10 stone_slab[type=bottom]
setblock ~70 ~12 ~10 stone_bricks
fill ~71 ~12 ~10 ~71 ~12 ~12 grass_block
fill ~72 ~12 ~10 ~72 ~12 ~11 stone_bricks
setblock ~73 ~12 ~10 stone_slab[type=bottom]
setblock ~26 ~12 ~11 stone
fill ~28 ~12 ~11 ~28 ~12 ~12 grass_block
setblock ~29 ~12 ~11 stone_slab[type=bottom]
setblock ~69 ~12 ~11 stone_slab[type=bottom]
fill ~70 ~12 ~11 ~71 ~12 ~12 grass_block
fill ~16 ~12 ~12 ~16 ~15 ~12 birch_leaves[persistent=false]
fill ~26 ~12 ~12 ~28 ~12 ~12 grass_block
setblock ~72 ~12 ~12 grass_block
fill ~17 ~12 ~14 ~17 ~12 ~15 grass_block
setblock ~19 ~12 ~14 grass_block
fill ~37 ~12 ~14 ~37 ~13 ~15 stone
fill ~61 ~12 ~14 ~61 ~13 ~15 stone
setblock ~79 ~12 ~14 grass_block
fill ~81 ~12 ~14 ~81 ~12 ~15 grass_block
fill ~18 ~12 ~15 ~18 ~13 ~15 oak_log[axis=y]
fill ~35 ~12 ~15 ~35 ~12 ~16 stone_slab[type=bottom]
fill ~36 ~12 ~15 ~38 ~14 ~15 stone
fill ~62 ~12 ~15 ~62 ~14 ~15 stone
fill ~63 ~12 ~15 ~63 ~12 ~16 stone_slab[type=bottom]
fill ~80 ~12 ~15 ~80 ~13 ~15 oak_log[axis=y]
fill ~17 ~12 ~16 ~17 ~12 ~17 stone_bricks
setblock ~18 ~12 ~16 grass_block
fill ~19 ~12 ~16 ~19 ~12 ~18 stone_bricks
setblock ~20 ~12 ~16 stone_slab[type=bottom]
fill ~34 ~12 ~16 ~35 ~12 ~16 stone_slab[type=bottom]
fill ~36 ~12 ~16 ~36 ~12 ~17 stone_bricks
setblock ~37 ~12 ~16 stone
setblock ~61 ~12 ~16 stone
fill ~62 ~12 ~16 ~62 ~12 ~17 stone_bricks
fill ~64 ~12 ~16 ~64 ~12 ~17 stone_slab[type=bottom]
setblock ~78 ~12 ~16 stone_slab[type=bottom]
fill ~79 ~12 ~16 ~79 ~12 ~18 stone_bricks
setblock ~80 ~12 ~16 grass_block
fill ~81 ~12 ~16 ~81 ~12 ~17 stone_bricks
fill ~86 ~12 ~16 ~86 ~15 ~16 birch_leaves[persistent=false]
fill ~14 ~12 ~17 ~15 ~12 ~17 grass_block
fill ~16 ~12 ~17 ~17 ~12 ~17 stone_bricks
