fill ~81 ~0 ~82 ~81 ~19 ~82 stone
fill ~81 ~19 ~71 ~81 ~19 ~82 stone
fill ~61 ~16 ~82 ~61 ~19 ~82 stone
fill ~6 ~19 ~82 ~7 ~19 ~82 sandstone
fill ~7 ~18 ~82 ~7 ~19 ~82 sandstone
fill ~7 ~19 ~81 ~7 ~19 ~82 sandstone
fill ~148 ~19 ~81 ~149 ~19 ~81 sandstone
fill ~98 ~19 ~79 ~98 ~19 ~81 stone
fill ~85 ~0 ~81 ~85 ~19 ~81 stone
fill ~62 ~17 ~81 ~62 ~19 ~81 stone
fill ~62 ~19 ~78 ~62 ~19 ~81 stone
fill ~53 ~15 ~81 ~53 ~19 ~81 stone
fill ~154 ~17 ~80 ~154 ~19 ~80 quartz_block
fill ~136 ~16 ~80 ~136 ~19 ~80 stone
fill ~136 ~19 ~79 ~136 ~19 ~80 stone
fill ~96 ~19 ~80 ~97 ~19 ~80 stone
fill ~97 ~18 ~80 ~97 ~19 ~80 stone
fill ~88 ~1 ~80 ~88 ~19 ~80 stone
fill ~88 ~19 ~79 ~88 ~19 ~80 stone
fill ~86 ~0 ~80 ~86 ~19 ~80 stone
fill ~86 ~19 ~77 ~86 ~19 ~80 stone
fill ~84 ~0 ~80 ~84 ~19 ~80 stone
fill ~76 ~0 ~80 ~76 ~19 ~80 stone
fill ~76 ~19 ~76 ~76 ~19 ~80 stone
fill ~74 ~0 ~80 ~74 ~19 ~80 stone
fill ~74 ~19 ~77 ~74 ~19 ~80 stone
fill ~63 ~19 ~80 ~64 ~19 ~80 stone
fill ~64 ~16 ~80 ~64 ~19 ~80 stone
fill ~12 ~18 ~80 ~12 ~19 ~80 stone
fill ~5 ~19 ~80 ~6 ~19 ~80 quartz_block
fill ~6 ~17 ~80 ~6 ~19 ~80 quartz_block
fill ~153 ~18 ~79 ~153 ~19 ~79 sandstone
fill ~153 ~19 ~76 ~153 ~19 ~79 sandstone
fill ~24 ~19 ~78 ~24 ~19 ~79 stone
fill ~11 ~19 ~79 ~12 ~19 ~79 sandstone
fill ~10 ~19 ~78 ~10 ~19 ~79 stone
fill ~6 ~18 ~79 ~6 ~19 ~79 sandstone
fill ~134 ~19 ~77 ~134 ~19 ~78 stone
fill ~72 ~1 ~78 ~72 ~19 ~78 stone
fill ~72 ~19 ~74 ~72 ~19 ~78 stone
fill ~7 ~18 ~78 ~7 ~19 ~78 sandstone
fill ~152 ~18 ~77 ~152 ~19 ~77 sandstone
fill ~152 ~19 ~76 ~152 ~19 ~77 sandstone
fill ~85 ~0 ~77 ~85 ~19 ~77 stone
fill ~71 ~10 ~77 ~71 ~19 ~77 stone
fill ~71 ~19 ~74 ~71 ~19 ~77 stone
fill ~68 ~13 ~77 ~68 ~19 ~77 stone
fill ~68 ~19 ~74 ~68 ~19 ~77 stone
fill ~66 ~16 ~77 ~66 ~19 ~77 stone
fill ~66 ~19 ~75 ~66 ~19 ~77 stone
fill ~42 ~13 ~77 ~42 ~19 ~77 stone
fill ~9 ~18 ~77 ~9 ~19 ~77 stone
fill ~8 ~19 ~76 ~8 ~19 ~77 sandstone
fill ~95 ~17 ~76 ~95 ~19 ~76 stone
fill ~84 ~0 ~76 ~84 ~19 ~76 stone
fill ~84 ~19 ~75 ~84 ~19 ~76 stone
fill ~75 ~0 ~76 ~75 ~19 ~76 stone
fill ~43 ~14 ~76 ~43 ~19 ~76 stone
fill ~43 ~19 ~74 ~43 ~19 ~76 stone
fill ~116 ~17 ~75 ~116 ~19 ~75 stone
fill ~116 ~19 ~74 ~116 ~19 ~75 stone
fill ~104 ~17 ~75 ~104 ~19 ~75 stone
fill ~104 ~19 ~74 ~104 ~19 ~75 stone
fill ~102 ~15 ~75 ~102 ~19 ~75 stone
fill ~102 ~19 ~74 ~102 ~19 ~75 stone
fill ~94 ~16 ~75 ~94 ~19 ~75 stone
fill ~77 ~0 ~75 ~77 ~19 ~75 stone
fill ~74 ~3 ~75 ~74 ~19 ~75 stone
fill ~70 ~12 ~75 ~70 ~19 ~75 stone
fill ~70 ~19 ~71 ~70 ~19 ~75 stone
fill ~121 ~18 ~74 ~121 ~19 ~74 stone
fill ~115 ~18 ~74 ~115 ~19 ~74 stone
fill ~83 ~0 ~74 ~83 ~19 ~74 stone
fill ~79 ~0 ~73 ~79 ~19 ~73 stone
fill ~79 ~19 ~71 ~79 ~19 ~73 stone
fill ~92 ~17 ~72 ~92 ~19 ~72 stone
fill ~78 ~11 ~70 ~78 ~19 ~70 stone
fill ~87 ~15 ~69 ~87 ~19 ~69 stone
fill ~144 ~19 ~67 ~144 ~19 ~68 sandstone
fill ~86 ~16 ~68 ~86 ~19 ~68 stone
fill ~86 ~19 ~67 ~86 ~19 ~68 stone
fill ~18 ~19 ~67 ~18 ~19 ~68 sandstone
fill ~85 ~18 ~67 ~85 ~19 ~67 stone
fill ~85 ~19 ~66 ~85 ~19 ~67 stone
fill ~144 ~19 ~66 ~145 ~19 ~66 stone
fill ~145 ~18 ~66 ~145 ~19 ~66 stone
fill ~84 ~19 ~65 ~84 ~19 ~66 stone
fill ~75 ~18 ~66 ~75 ~19 ~66 stone
fill ~18 ~19 ~66 ~19 ~19 ~66 stone
fill ~19 ~18 ~66 ~19 ~19 ~66 stone
fill ~146 ~18 ~65 ~146 ~19 ~65 stone
fill ~139 ~19 ~63 ~139 ~19 ~65 sandstone
fill ~76 ~18 ~65 ~76 ~19 ~65 stone
fill ~20 ~18 ~65 ~20 ~19 ~65 stone
fill ~13 ~19 ~63 ~13 ~19 ~65 sandstone
fill ~146 ~19 ~64 ~147 ~19 ~64 sandstone
fill ~140 ~18 ~64 ~140 ~19 ~64 sandstone
fill ~140 ~19 ~63 ~140 ~19 ~64 sandstone
fill ~55 ~19 ~63 ~55 ~19 ~64 end_stone
fill ~20 ~19 ~64 ~21 ~19 ~64 sandstone
fill ~14 ~18 ~64 ~14 ~19 ~64 sandstone
fill ~14 ~19 ~63 ~14 ~19 ~64 sandstone
fill ~145 ~18 ~63 ~145 ~19 ~63 sandstone
fill ~141 ~19 ~63 ~142 ~19 ~63 sandstone
fill ~142 ~18 ~63 ~142 ~19 ~63 sandstone
fill ~56 ~18 ~63 ~56 ~19 ~63 sandstone
fill ~56 ~19 ~62 ~56 ~19 ~63 sandstone
fill ~54 ~18 ~63 ~54 ~19 ~63 sandstone
fill ~51 ~19 ~63 ~52 ~19 ~63 sandstone
fill ~50 ~19 ~60 ~50 ~19 ~63 stone
fill ~19 ~18 ~63 ~19 ~19 ~63 sandstone
fill ~15 ~19 ~63 ~16 ~19 ~63 sandstone
fill ~16 ~18 ~63 ~16 ~19 ~63 sandstone
fill ~143 ~17 ~62 ~143 ~19 ~62 quartz_block
fill ~143 ~19 ~61 ~143 ~19 ~62 quartz_block
fill ~79 ~17 ~62 ~79 ~19 ~62 stone
fill ~17 ~17 ~62 ~17 ~19 ~62 quartz_block
fill ~17 ~19 ~61 ~17 ~19 ~62 quartz_block
fill ~109 ~18 ~61 ~109 ~19 ~61 sandstone
fill ~109 ~19 ~59 ~109 ~19 ~61 sandstone
fill ~102 ~19 ~61 ~103 ~19 ~61 end_stone
fill ~103 ~19 ~59 ~103 ~19 ~61 end_stone
fill ~76 ~19 ~61 ~77 ~19 ~61 stone
fill ~77 ~18 ~61 ~77 ~19 ~61 stone
fill ~58 ~19 ~57 ~58 ~19 ~61 sandstone
fill ~54 ~18 ~61 ~54 ~19 ~61 end_stone
fill ~51 ~17 ~61 ~51 ~19 ~61 stone
fill ~51 ~19 ~60 ~51 ~19 ~61 stone
fill ~107 ~19 ~59 ~107 ~19 ~60 end_stone
fill ~105 ~18 ~60 ~105 ~19 ~60 sandstone
fill ~75 ~19 ~60 ~76 ~19 ~60 stone
fill ~76 ~16 ~60 ~76 ~19 ~60 stone
fill ~57 ~18 ~60 ~57 ~19 ~60 end_stone
fill ~101 ~19 ~59 ~102 ~19 ~59 end_stone
fill ~100 ~19 ~58 ~100 ~19 ~59 sandstone
fill ~81 ~11 ~59 ~81 ~19 ~59 stone
fill ~81 ~19 ~37 ~81 ~19 ~59 stone
fill ~79 ~7 ~59 ~79 ~19 ~59 stone
fill ~79 ~19 ~37 ~79 ~19 ~59 stone
fill ~74 ~19 ~59 ~75 ~19 ~59 stone
fill ~75 ~18 ~59 ~75 ~19 ~59 stone
fill ~59 ~19 ~57 ~59 ~19 ~59 end_stone
fill ~107 ~19 ~58 ~108 ~19 ~58 sandstone
fill ~108 ~18 ~58 ~108 ~19 ~58 sandstone
fill ~104 ~17 ~58 ~104 ~19 ~58 stone
fill ~101 ~19 ~58 ~103 ~19 ~58 sandstone
fill ~103 ~14 ~58 ~103 ~19 ~58 sandstone
fill ~99 ~19 ~57 ~99 ~19 ~58 sandstone
fill ~85 ~17 ~58 ~85 ~19 ~58 stone
fill ~78 ~5 ~58 ~78 ~19 ~58 stone
fill ~78 ~19 ~25 ~78 ~19 ~58 stone
fill ~76 ~14 ~58 ~76 ~19 ~58 stone
fill ~76 ~19 ~52 ~76 ~19 ~58 stone
fill ~74 ~18 ~58 ~74 ~19 ~58 stone
fill ~61 ~19 ~57 ~61 ~19 ~58 end_stone
fill ~50 ~18 ~58 ~50 ~19 ~58 end_stone
fill ~50 ~19 ~57 ~50 ~19 ~58 end_stone
fill ~109 ~17 ~57 ~109 ~19 ~57 sandstone
fill ~106 ~19 ~57 ~107 ~19 ~57 sandstone
fill ~107 ~18 ~57 ~107 ~19 ~57 sandstone
fill ~100 ~18 ~57 ~100 ~19 ~57 end_stone
fill ~84 ~17 ~57 ~84 ~19 ~57 stone
fill ~77 ~7 ~57 ~77 ~19 ~57 stone
fill ~77 ~19 ~51 ~77 ~19 ~57 stone
fill ~75 ~15 ~57 ~75 ~19 ~57 stone
fill ~75 ~19 ~54 ~75 ~19 ~57 stone
fill ~56 ~17 ~57 ~56 ~19 ~57 stone
fill ~56 ~19 ~56 ~56 ~19 ~57 stone
fill ~51 ~16 ~57 ~51 ~19 ~57 end_stone
fill ~49 ~18 ~57 ~49 ~19 ~57 end_stone
fill ~109 ~19 ~56 ~110 ~19 ~56 end_stone
fill ~106 ~16 ~56 ~106 ~19 ~56 end_stone
fill ~102 ~18 ~56 ~102 ~19 ~56 stone
fill ~97 ~19 ~56 ~98 ~19 ~56 sandstone
fill ~82 ~19 ~56 ~83 ~19 ~56 stone
fill ~83 ~16 ~56 ~83 ~19 ~56 stone
fill ~74 ~16 ~56 ~74 ~19 ~56 stone
fill ~74 ~19 ~55 ~74 ~19 ~56 stone
fill ~55 ~17 ~56 ~55 ~19 ~56 stone
fill ~55 ~19 ~55 ~55 ~19 ~56 stone
fill ~52 ~18 ~56 ~52 ~19 ~56 sandstone
fill ~52 ~19 ~55 ~52 ~19 ~56 sandstone
fill ~108 ~19 ~55 ~109 ~19 ~55 end_stone
fill ~109 ~19 ~54 ~109 ~19 ~55 end_stone
fill ~106 ~19 ~55 ~107 ~19 ~55 sandstone
fill ~107 ~19 ~54 ~107 ~19 ~55 sandstone
fill ~101 ~18 ~55 ~101 ~19 ~55 stone
fill ~96 ~19 ~55 ~97 ~19 ~55 end_stone
fill ~97 ~18 ~55 ~97 ~19 ~55 end_stone
fill ~82 ~16 ~55 ~82 ~19 ~55 stone
fill ~82 ~19 ~24 ~82 ~19 ~55 stone
fill ~60 ~18 ~55 ~60 ~19 ~55 sandstone
fill ~54 ~18 ~55 ~54 ~19 ~55 stone
fill ~50 ~18 ~55 ~50 ~19 ~55 end_stone
fill ~50 ~19 ~54 ~50 ~19 ~55 end_stone
fill ~108 ~19 ~53 ~108 ~19 ~54 end_stone
fill ~106 ~18 ~54 ~106 ~19 ~54 end_stone
fill ~102 ~17 ~54 ~102 ~19 ~54 stone
fill ~99 ~18 ~54 ~99 ~19 ~54 end_stone
fill ~97 ~18 ~54 ~97 ~19 ~54 sandstone
fill ~58 ~18 ~54 ~58 ~19 ~54 stone
fill ~57 ~18 ~54 ~57 ~19 ~54 sandstone
fill ~57 ~19 ~53 ~57 ~19 ~54 sandstone
fill ~56 ~16 ~54 ~56 ~19 ~54 end_stone
fill ~55 ~19 ~53 ~55 ~19 ~54 sandstone
fill ~54 ~18 ~54 ~54 ~19 ~54 end_stone
fill ~51 ~18 ~54 ~51 ~19 ~54 sandstone
fill ~107 ~18 ~53 ~107 ~19 ~53 end_stone
fill ~105 ~19 ~53 ~106 ~19 ~53 sandstone
fill ~101 ~16 ~53 ~101 ~19 ~53 stone
fill ~58 ~18 ~53 ~58 ~19 ~53 sandstone
fill ~58 ~19 ~52 ~58 ~19 ~53 sandstone
fill ~54 ~16 ~53 ~54 ~19 ~53 sandstone
fill ~53 ~18 ~53 ~53 ~19 ~53 end_stone
fill ~53 ~19 ~52 ~53 ~19 ~53 end_stone
fill ~104 ~19 ~52 ~105 ~19 ~52 sandstone
fill ~100 ~15 ~52 ~100 ~19 ~52 stone
fill ~100 ~19 ~50 ~100 ~19 ~52 stone
fill ~97 ~19 ~51 ~97 ~19 ~52 sandstone
fill ~84 ~19 ~51 ~84 ~19 ~52 stone
fill ~60 ~19 ~51 ~60 ~19 ~52 sandstone
fill ~54 ~19 ~52 ~55 ~19 ~52 end_stone
fill ~55 ~17 ~52 ~55 ~19 ~52 end_stone
fill ~106 ~18 ~51 ~106 ~19 ~51 sandstone
fill ~103 ~16 ~51 ~103 ~19 ~51 end_stone
fill ~103 ~19 ~49 ~103 ~19 ~51 end_stone
fill ~98 ~18 ~51 ~98 ~19 ~51 stone
fill ~98 ~19 ~50 ~98 ~19 ~51 stone
fill ~83 ~18 ~51 ~83 ~19 ~51 stone
fill ~83 ~19 ~42 ~83 ~19 ~51 stone
fill ~61 ~19 ~51 ~62 ~19 ~51 sandstone
fill ~59 ~18 ~51 ~59 ~19 ~51 sandstone
fill ~57 ~17 ~51 ~57 ~19 ~51 sandstone
fill ~105 ~19 ~50 ~106 ~19 ~50 end_stone
fill ~102 ~18 ~50 ~102 ~19 ~50 end_stone
fill ~77 ~19 ~41 ~77 ~19 ~48 stone
fill ~86 ~19 ~46 ~86 ~19 ~47 stone
fill ~80 ~12 ~46 ~80 ~19 ~46 stone
fill ~80 ~19 ~36 ~80 ~19 ~46 stone
fill ~85 ~17 ~44 ~85 ~19 ~44 stone
fill ~85 ~19 ~40 ~85 ~19 ~44 stone
fill ~75 ~17 ~44 ~75 ~19 ~44 stone
fill ~75 ~19 ~37 ~75 ~19 ~44 stone
fill ~84 ~14 ~42 ~84 ~19 ~42 stone
fill ~84 ~19 ~39 ~84 ~19 ~42 stone
fill ~76 ~13 ~42 ~76 ~19 ~42 stone
fill ~76 ~19 ~35 ~76 ~19 ~42 stone
fill ~84 ~19 ~37 ~85 ~19 ~37 stone
fill ~84 ~18 ~36 ~84 ~19 ~36 stone
fill ~84 ~19 ~35 ~84 ~19 ~36 stone
fill ~84 ~19 ~27 ~84 ~19 ~33 stone
fill ~76 ~19 ~27 ~76 ~19 ~33 stone
fill ~81 ~15 ~27 ~81 ~19 ~27 stone
fill ~81 ~19 ~24 ~81 ~19 ~27 stone
fill ~79 ~16 ~27 ~79 ~19 ~27 stone
fill ~79 ~19 ~23 ~79 ~19 ~27 stone
fill ~83 ~19 ~25 ~83 ~19 ~26 stone
fill ~80 ~17 ~26 ~80 ~19 ~26 stone
fill ~80 ~19 ~23 ~80 ~19 ~26 stone
fill ~96 ~19 ~20 ~96 ~19 ~21 sandstone
fill ~63 ~19 ~21 ~65 ~19 ~21 sandstone
fill ~95 ~18 ~20 ~95 ~19 ~20 stone
fill ~63 ~19 ~20 ~64 ~19 ~20 sandstone
fill ~64 ~18 ~20 ~64 ~19 ~20 sandstone
fill ~98 ~18 ~19 ~98 ~19 ~19 stone
fill ~97 ~18 ~19 ~97 ~19 ~19 sandstone
fill ~94 ~18 ~19 ~94 ~19 ~19 stone
fill ~94 ~19 ~18 ~94 ~19 ~19 stone
fill ~62 ~19 ~19 ~63 ~19 ~19 sandstone
fill ~63 ~18 ~19 ~63 ~19 ~19 sandstone
fill ~63 ~19 ~18 ~63 ~19 ~19 sandstone
fill ~92 ~19 ~18 ~93 ~19 ~18 sandstone
fill ~98 ~17 ~17 ~98 ~19 ~17 quartz_block
fill ~68 ~18 ~17 ~68 ~19 ~17 stone
fill ~61 ~19 ~17 ~62 ~19 ~17 quartz_block
fill ~62 ~17 ~17 ~62 ~19 ~17 quartz_block
fill ~97 ~18 ~16 ~97 ~19 ~16 sandstone
fill ~97 ~19 ~13 ~97 ~19 ~16 sandstone
fill ~67 ~19 ~16 ~68 ~19 ~16 sandstone
fill ~66 ~19 ~15 ~66 ~19 ~16 stone
fill ~62 ~18 ~16 ~62 ~19 ~16 sandstone
fill ~63 ~18 ~15 ~63 ~19 ~15 sandstone
fill ~96 ~18 ~14 ~96 ~19 ~14 sandstone
fill ~96 ~19 ~13 ~96 ~19 ~14 sandstone
fill ~65 ~18 ~14 ~65 ~19 ~14 stone
fill ~64 ~19 ~13 ~64 ~19 ~14 sandstone
fill ~81 ~19 ~11 ~81 ~19 ~12 sandstone
fill ~81 ~19 ~10 ~82 ~19 ~10 stone
fill ~82 ~18 ~10 ~82 ~19 ~10 stone
fill ~83 ~18 ~9 ~83 ~19 ~9 stone
fill ~76 ~19 ~7 ~76 ~19 ~9 sandstone
fill ~83 ~19 ~8 ~84 ~19 ~8 sandstone
fill ~77 ~18 ~8 ~77 ~19 ~8 sandstone
fill ~77 ~19 ~7 ~77 ~19 ~8 sandstone
fill ~82 ~18 ~7 ~82 ~19 ~7 sandstone
fill ~78 ~19 ~7 ~79 ~19 ~7 sandstone
fill ~79 ~18 ~7 ~79 ~19 ~7 sandstone
fill ~80 ~17 ~6 ~80 ~19 ~6 quartz_block
fill ~80 ~19 ~5 ~80 ~19 ~6 quartz_block
fill ~82 ~18 ~153 ~83 ~18 ~153 sandstone
fill ~83 ~17 ~153 ~83 ~18 ~153 sandstone
fill ~79 ~18 ~153 ~80 ~18 ~153 sandstone
fill ~82 ~16 ~152 ~82 ~18 ~152 sandstone
fill ~82 ~18 ~151 ~82 ~18 ~152 sandstone
fill ~79 ~18 ~152 ~81 ~18 ~152 stone
fill ~78 ~16 ~152 ~78 ~18 ~152 sandstone
fill ~78 ~18 ~151 ~78 ~18 ~152 sandstone
fill ~77 ~16 ~152 ~77 ~18 ~152 stone
fill ~80 ~18 ~150 ~80 ~18 ~151 stone
fill ~79 ~16 ~151 ~79 ~18 ~151 sandstone
fill ~79 ~18 ~150 ~79 ~18 ~151 sandstone
fill ~81 ~18 ~150 ~82 ~18 ~150 stone
fill ~96 ~16 ~146 ~96 ~18 ~146 stone
fill ~63 ~17 ~146 ~63 ~18 ~146 sandstone
fill ~95 ~18 ~145 ~96 ~18 ~145 sandstone
fill ~96 ~16 ~145 ~96 ~18 ~145 sandstone
fill ~66 ~18 ~143 ~66 ~18 ~145 stone
fill ~64 ~18 ~145 ~65 ~18 ~145 sandstone
fill ~65 ~16 ~145 ~65 ~18 ~145 sandstone
fill ~65 ~18 ~144 ~65 ~18 ~145 sandstone
fill ~97 ~16 ~144 ~97 ~18 ~144 sandstone
fill ~97 ~18 ~143 ~97 ~18 ~144 sandstone
fill ~96 ~18 ~142 ~96 ~18 ~144 stone
fill ~94 ~18 ~144 ~95 ~18 ~144 sandstone
fill ~95 ~16 ~144 ~95 ~18 ~144 sandstone
fill ~64 ~18 ~142 ~64 ~18 ~144 stone
fill ~63 ~18 ~142 ~63 ~18 ~144 sandstone
fill ~94 ~18 ~143 ~95 ~18 ~143 stone
fill ~95 ~18 ~141 ~95 ~18 ~142 sandstone
fill ~94 ~18 ~141 ~94 ~18 ~142 stone
fill ~65 ~18 ~142 ~66 ~18 ~142 sandstone
fill ~96 ~18 ~141 ~97 ~18 ~141 sandstone
fill ~97 ~18 ~140 ~97 ~18 ~141 sandstone
fill ~64 ~18 ~141 ~65 ~18 ~141 sandstone
fill ~65 ~15 ~141 ~65 ~18 ~141 sandstone
fill ~64 ~16 ~140 ~64 ~18 ~140 stone
fill ~80 ~6 ~119 ~80 ~18 ~119 stone
fill ~80 ~18 ~106 ~80 ~18 ~119 stone
fill ~76 ~16 ~119 ~76 ~18 ~119 stone
fill ~76 ~18 ~114 ~76 ~18 ~119 stone
fill ~84 ~12 ~117 ~84 ~18 ~117 stone
fill ~84 ~18 ~114 ~84 ~18 ~117 stone
fill ~82 ~4 ~117 ~82 ~18 ~117 stone
fill ~82 ~18 ~99 ~82 ~18 ~117 stone
fill ~78 ~7 ~117 ~78 ~18 ~117 stone
fill ~78 ~18 ~99 ~78 ~18 ~117 stone
fill ~85 ~17 ~115 ~85 ~18 ~115 stone
fill ~81 ~10 ~115 ~81 ~18 ~115 stone
fill ~81 ~18 ~98 ~81 ~18 ~115 stone
fill ~75 ~17 ~115 ~75 ~18 ~115 stone
fill ~75 ~18 ~114 ~75 ~18 ~115 stone
fill ~79 ~13 ~114 ~79 ~18 ~114 stone
fill ~79 ~18 ~100 ~79 ~18 ~114 stone
fill ~57 ~17 ~110 ~57 ~18 ~110 sandstone
fill ~56 ~17 ~110 ~56 ~18 ~110 end_stone
fill ~104 ~18 ~109 ~105 ~18 ~109 sandstone
fill ~102 ~17 ~109 ~102 ~18 ~109 sandstone
fill ~99 ~18 ~109 ~100 ~18 ~109 sandstone
fill ~60 ~17 ~109 ~60 ~18 ~109 stone
fill ~57 ~18 ~109 ~58 ~18 ~109 end_stone
fill ~55 ~17 ~109 ~55 ~18 ~109 end_stone
fill ~55 ~18 ~107 ~55 ~18 ~109 end_stone
fill ~105 ~17 ~108 ~105 ~18 ~108 end_stone
fill ~105 ~18 ~106 ~105 ~18 ~108 end_stone
fill ~101 ~17 ~108 ~101 ~18 ~108 sandstone
fill ~101 ~18 ~107 ~101 ~18 ~108 sandstone
fill ~83 ~18 ~107 ~83 ~18 ~108 stone
fill ~62 ~18 ~107 ~62 ~18 ~108 sandstone
fill ~107 ~18 ~105 ~107 ~18 ~107 end_stone
fill ~56 ~10 ~107 ~56 ~18 ~107 sandstone
fill ~54 ~17 ~107 ~54 ~18 ~107 end_stone
fill ~101 ~17 ~106 ~101 ~18 ~106 stone
fill ~101 ~18 ~105 ~101 ~18 ~106 stone
fill ~108 ~18 ~105 ~110 ~18 ~105 end_stone
fill ~110 ~18 ~104 ~110 ~18 ~105 end_stone
fill ~83 ~13 ~105 ~83 ~18 ~105 stone
fill ~83 ~18 ~99 ~83 ~18 ~105 stone
fill ~62 ~18 ~105 ~63 ~18 ~105 end_stone
fill ~61 ~18 ~104 ~61 ~18 ~105 sandstone
fill ~52 ~18 ~105 ~54 ~18 ~105 end_stone
fill ~51 ~18 ~104 ~51 ~18 ~105 sandstone
fill ~107 ~18 ~104 ~108 ~18 ~104 sandstone
fill ~59 ~18 ~104 ~60 ~18 ~104 sandstone
fill ~110 ~17 ~103 ~110 ~18 ~103 sandstone
fill ~109 ~16 ~103 ~109 ~18 ~103 end_stone
fill ~109 ~18 ~102 ~109 ~18 ~103 end_stone
fill ~100 ~17 ~103 ~100 ~18 ~103 sandstone
fill ~100 ~18 ~102 ~100 ~18 ~103 sandstone
fill ~57 ~17 ~103 ~57 ~18 ~103 stone
fill ~102 ~17 ~102 ~102 ~18 ~102 end_stone
fill ~101 ~18 ~101 ~101 ~18 ~102 sandstone
fill ~77 ~15 ~102 ~77 ~18 ~102 stone
fill ~77 ~18 ~100 ~77 ~18 ~102 stone
fill ~60 ~18 ~102 ~61 ~18 ~102 end_stone
fill ~59 ~18 ~101 ~59 ~18 ~102 sandstone
fill ~58 ~17 ~102 ~58 ~18 ~102 end_stone
fill ~57 ~14 ~102 ~57 ~18 ~102 sandstone
fill ~51 ~18 ~102 ~52 ~18 ~102 sandstone
fill ~52 ~18 ~101 ~52 ~18 ~102 sandstone
fill ~104 ~16 ~101 ~104 ~18 ~101 sandstone
fill ~104 ~18 ~99 ~104 ~18 ~101 sandstone
fill ~58 ~18 ~100 ~58 ~18 ~101 sandstone
fill ~54 ~18 ~101 ~55 ~18 ~101 stone
fill ~53 ~18 ~100 ~53 ~18 ~101 sandstone
fill ~105 ~18 ~100 ~106 ~18 ~100 stone
fill ~106 ~17 ~100 ~106 ~18 ~100 stone
fill ~101 ~18 ~100 ~102 ~18 ~100 end_stone
fill ~102 ~17 ~100 ~102 ~18 ~100 end_stone
fill ~102 ~18 ~99 ~102 ~18 ~100 end_stone
fill ~57 ~17 ~100 ~57 ~18 ~100 sandstone
fill ~51 ~18 ~99 ~51 ~18 ~100 sandstone
fill ~108 ~16 ~99 ~108 ~18 ~99 stone
fill ~109 ~18 ~98 ~110 ~18 ~98 stone
fill ~107 ~18 ~98 ~108 ~18 ~98 sandstone
fill ~104 ~18 ~98 ~105 ~18 ~98 end_stone
fill ~105 ~17 ~98 ~105 ~18 ~98 end_stone
fill ~145 ~18 ~97 ~146 ~18 ~97 sandstone
fill ~146 ~17 ~97 ~146 ~18 ~97 sandstone
fill ~142 ~18 ~97 ~143 ~18 ~97 sandstone
fill ~106 ~18 ~97 ~107 ~18 ~97 sandstone
fill ~107 ~17 ~97 ~107 ~18 ~97 sandstone
fill ~19 ~18 ~97 ~20 ~18 ~97 sandstone
fill ~20 ~17 ~97 ~20 ~18 ~97 sandstone
fill ~16 ~18 ~97 ~17 ~18 ~97 sandstone
fill ~145 ~16 ~96 ~145 ~18 ~96 sandstone
fill ~145 ~18 ~95 ~145 ~18 ~96 sandstone
fill ~142 ~18 ~96 ~144 ~18 ~96 stone
fill ~141 ~16 ~96 ~141 ~18 ~96 sandstone
fill ~141 ~18 ~95 ~141 ~18 ~96 sandstone
fill ~140 ~16 ~96 ~140 ~18 ~96 stone
fill ~74 ~18 ~94 ~74 ~18 ~96 stone
fill ~19 ~16 ~96 ~19 ~18 ~96 sandstone
fill ~19 ~18 ~95 ~19 ~18 ~96 sandstone
fill ~16 ~18 ~96 ~18 ~18 ~96 stone
fill ~15 ~16 ~96 ~15 ~18 ~96 sandstone
fill ~15 ~18 ~95 ~15 ~18 ~96 sandstone
fill ~14 ~16 ~96 ~14 ~18 ~96 stone
fill ~143 ~18 ~94 ~143 ~18 ~95 stone
fill ~142 ~16 ~95 ~142 ~18 ~95 sandstone
fill ~142 ~18 ~94 ~142 ~18 ~95 sandstone
fill ~80 ~17 ~95 ~80 ~18 ~95 stone
fill ~77 ~16 ~95 ~77 ~18 ~95 stone
fill ~77 ~18 ~86 ~77 ~18 ~95 stone
fill ~75 ~16 ~95 ~75 ~18 ~95 stone
fill ~73 ~17 ~95 ~73 ~18 ~95 stone
fill ~73 ~18 ~92 ~73 ~18 ~95 stone
fill ~17 ~18 ~94 ~17 ~18 ~95 stone
fill ~16 ~16 ~95 ~16 ~18 ~95 sandstone
fill ~16 ~18 ~94 ~16 ~18 ~95 sandstone
fill ~144 ~18 ~94 ~145 ~18 ~94 stone
fill ~81 ~18 ~94 ~82 ~18 ~94 stone
fill ~82 ~16 ~94 ~82 ~18 ~94 stone
fill ~76 ~15 ~94 ~76 ~18 ~94 stone
fill ~76 ~18 ~91 ~76 ~18 ~94 stone
fill ~18 ~18 ~94 ~19 ~18 ~94 stone
fill ~87 ~18 ~93 ~88 ~18 ~93 stone
fill ~83 ~15 ~93 ~83 ~18 ~93 stone
fill ~83 ~18 ~84 ~83 ~18 ~93 stone
fill ~81 ~15 ~93 ~81 ~18 ~93 stone
fill ~75 ~14 ~93 ~75 ~18 ~93 stone
fill ~75 ~18 ~92 ~75 ~18 ~93 stone
fill ~71 ~18 ~93 ~72 ~18 ~93 stone
fill ~72 ~16 ~93 ~72 ~18 ~93 stone
fill ~72 ~18 ~92 ~72 ~18 ~93 stone
fill ~89 ~18 ~91 ~89 ~18 ~92 stone
fill ~84 ~14 ~92 ~84 ~18 ~92 stone
fill ~82 ~12 ~92 ~82 ~18 ~92 stone
fill ~82 ~18 ~84 ~82 ~18 ~92 stone
fill ~79 ~10 ~92 ~79 ~18 ~92 stone
fill ~79 ~18 ~75 ~79 ~18 ~92 stone
fill ~70 ~18 ~92 ~71 ~18 ~92 stone
fill ~71 ~17 ~92 ~71 ~18 ~92 stone
fill ~71 ~18 ~91 ~71 ~18 ~92 stone
fill ~90 ~18 ~90 ~90 ~18 ~91 stone
fill ~81 ~10 ~91 ~81 ~18 ~91 stone
fill ~81 ~18 ~84 ~81 ~18 ~91 stone
fill ~69 ~18 ~91 ~70 ~18 ~91 stone
fill ~70 ~17 ~91 ~70 ~18 ~91 stone
fill ~70 ~18 ~90 ~70 ~18 ~91 stone
fill ~91 ~18 ~89 ~91 ~18 ~90 stone
fill ~73 ~11 ~90 ~73 ~18 ~90 stone
fill ~69 ~17 ~90 ~69 ~18 ~90 stone
fill ~69 ~18 ~89 ~69 ~18 ~90 stone
fill ~92 ~17 ~88 ~92 ~18 ~88 stone
fill ~92 ~18 ~87 ~92 ~18 ~88 stone
fill ~92 ~15 ~84 ~92 ~18 ~84 stone
fill ~92 ~18 ~83 ~92 ~18 ~84 stone
fill ~84 ~0 ~84 ~84 ~18 ~84 stone
fill ~78 ~0 ~84 ~78 ~18 ~84 stone
fill ~78 ~18 ~79 ~78 ~18 ~84 stone
fill ~76 ~0 ~84 ~76 ~18 ~84 stone
fill ~76 ~18 ~81 ~76 ~18 ~84 stone
fill ~152 ~16 ~83 ~152 ~18 ~83 stone
fill ~77 ~0 ~83 ~77 ~18 ~83 stone
fill ~77 ~18 ~81 ~77 ~18 ~83 stone
fill ~7 ~17 ~83 ~7 ~18 ~83 sandstone
fill ~151 ~18 ~82 ~152 ~18 ~82 sandstone
fill ~152 ~16 ~82 ~152 ~18 ~82 sandstone
fill ~82 ~0 ~82 ~82 ~18 ~82 stone
fill ~82 ~18 ~73 ~82 ~18 ~82 stone
fill ~75 ~0 ~82 ~75 ~18 ~82 stone
fill ~75 ~18 ~81 ~75 ~18 ~82 stone
fill ~64 ~18 ~82 ~65 ~18 ~82 stone
fill ~65 ~17 ~82 ~65 ~18 ~82 stone
fill ~65 ~18 ~81 ~65 ~18 ~82 stone
fill ~10 ~18 ~80 ~10 ~18 ~82 stone
fill ~8 ~18 ~82 ~9 ~18 ~82 sandstone
fill ~9 ~16 ~82 ~9 ~18 ~82 sandstone
fill ~9 ~18 ~81 ~9 ~18 ~82 sandstone
fill ~153 ~16 ~81 ~153 ~18 ~81 sandstone
fill ~153 ~18 ~80 ~153 ~18 ~81 sandstone
fill ~152 ~18 ~79 ~152 ~18 ~81 stone
fill ~150 ~18 ~81 ~151 ~18 ~81 sandstone
fill ~151 ~16 ~81 ~151 ~18 ~81 sandstone
fill ~89 ~3 ~81 ~89 ~18 ~81 stone
fill ~83 ~0 ~81 ~83 ~18 ~81 stone
fill ~81 ~0 ~81 ~81 ~18 ~81 stone
fill ~81 ~18 ~71 ~81 ~18 ~81 stone
fill ~64 ~17 ~81 ~64 ~18 ~81 stone
fill ~8 ~18 ~79 ~8 ~18 ~81 stone
fill ~7 ~18 ~79 ~7 ~18 ~81 sandstone
fill ~150 ~18 ~80 ~151 ~18 ~80 stone
fill ~98 ~18 ~78 ~98 ~18 ~80 stone
fill ~63 ~17 ~80 ~63 ~18 ~80 stone
fill ~5 ~17 ~80 ~5 ~18 ~80 quartz_block
fill ~151 ~18 ~78 ~151 ~18 ~79 sandstone
fill ~150 ~18 ~78 ~150 ~18 ~79 stone
fill ~95 ~18 ~79 ~97 ~18 ~79 stone
fill ~97 ~17 ~79 ~97 ~18 ~79 stone
fill ~88 ~1 ~79 ~88 ~18 ~79 stone
fill ~84 ~18 ~79 ~86 ~18 ~79 stone
fill ~86 ~0 ~79 ~86 ~18 ~79 stone
fill ~86 ~18 ~77 ~86 ~18 ~79 stone
fill ~76 ~0 ~79 ~76 ~18 ~79 stone
fill ~76 ~18 ~76 ~76 ~18 ~79 stone
fill ~74 ~0 ~79 ~74 ~18 ~79 stone
fill ~74 ~18 ~77 ~74 ~18 ~79 stone
fill ~9 ~18 ~79 ~10 ~18 ~79 sandstone
fill ~152 ~18 ~78 ~153 ~18 ~78 sandstone
fill ~153 ~18 ~77 ~153 ~18 ~78 sandstone
fill ~95 ~18 ~78 ~96 ~18 ~78 stone
fill ~96 ~18 ~76 ~96 ~18 ~78 stone
fill ~84 ~18 ~78 ~85 ~18 ~78 stone
fill ~85 ~0 ~78 ~85 ~18 ~78 stone
fill ~8 ~18 ~78 ~9 ~18 ~78 sandstone
fill ~9 ~15 ~78 ~9 ~18 ~78 sandstone
fill ~84 ~0 ~77 ~84 ~18 ~77 stone
fill ~72 ~4 ~77 ~72 ~18 ~77 stone
fill ~72 ~18 ~74 ~72 ~18 ~77 stone
fill ~8 ~16 ~77 ~8 ~18 ~77 stone
fill ~80 ~0 ~76 ~80 ~18 ~76 stone
fill ~80 ~18 ~75 ~80 ~18 ~76 stone
fill ~77 ~18 ~76 ~78 ~18 ~76 stone
fill ~78 ~0 ~76 ~78 ~18 ~76 stone
fill ~78 ~18 ~75 ~78 ~18 ~76 stone
fill ~71 ~10 ~76 ~71 ~18 ~76 stone
fill ~71 ~18 ~74 ~71 ~18 ~76 stone
fill ~68 ~14 ~76 ~68 ~18 ~76 stone
fill ~68 ~18 ~74 ~68 ~18 ~76 stone
fill ~66 ~17 ~76 ~66 ~18 ~76 stone
fill ~66 ~18 ~74 ~66 ~18 ~76 stone
fill ~95 ~17 ~75 ~95 ~18 ~75 stone
fill ~84 ~0 ~75 ~84 ~18 ~75 stone
fill ~43 ~15 ~75 ~43 ~18 ~75 stone
fill ~43 ~18 ~74 ~43 ~18 ~75 stone
fill ~104 ~16 ~74 ~104 ~18 ~74 stone
fill ~94 ~17 ~74 ~94 ~18 ~74 stone
fill ~70 ~13 ~74 ~70 ~18 ~74 stone
fill ~70 ~18 ~72 ~70 ~18 ~74 stone
fill ~93 ~17 ~73 ~93 ~18 ~73 stone
fill ~79 ~4 ~72 ~79 ~18 ~72 stone
fill ~79 ~18 ~71 ~79 ~18 ~72 stone
fill ~91 ~18 ~71 ~92 ~18 ~71 stone
fill ~144 ~18 ~65 ~144 ~18 ~66 sandstone
fill ~141 ~18 ~66 ~143 ~18 ~66 stone
fill ~143 ~18 ~64 ~143 ~18 ~66 stone
fill ~18 ~18 ~65 ~18 ~18 ~66 sandstone
fill ~15 ~18 ~66 ~17 ~18 ~66 stone
fill ~17 ~18 ~64 ~17 ~18 ~66 stone
fill ~145 ~15 ~65 ~145 ~18 ~65 sandstone
fill ~145 ~18 ~64 ~145 ~18 ~65 sandstone
fill ~141 ~18 ~65 ~142 ~18 ~65 sandstone
fill ~78 ~17 ~65 ~78 ~18 ~65 stone
fill ~19 ~15 ~65 ~19 ~18 ~65 sandstone
fill ~19 ~18 ~64 ~19 ~18 ~65 sandstone
fill ~15 ~18 ~65 ~16 ~18 ~65 sandstone
fill ~146 ~16 ~64 ~146 ~18 ~64 stone
fill ~141 ~16 ~64 ~141 ~18 ~64 sandstone
fill ~141 ~18 ~63 ~141 ~18 ~64 sandstone
fill ~20 ~16 ~64 ~20 ~18 ~64 stone
fill ~15 ~16 ~64 ~15 ~18 ~64 sandstone
fill ~15 ~18 ~63 ~15 ~18 ~64 sandstone
fill ~143 ~18 ~63 ~144 ~18 ~63 sandstone
fill ~144 ~16 ~63 ~144 ~18 ~63 sandstone
fill ~140 ~17 ~63 ~140 ~18 ~63 sandstone
fill ~55 ~18 ~62 ~55 ~18 ~63 end_stone
fill ~17 ~18 ~63 ~18 ~18 ~63 sandstone
fill ~18 ~16 ~63 ~18 ~18 ~63 sandstone
fill ~14 ~17 ~63 ~14 ~18 ~63 sandstone
fill ~52 ~18 ~62 ~53 ~18 ~62 sandstone
fill ~143 ~17 ~61 ~143 ~18 ~61 quartz_block
fill ~58 ~18 ~60 ~58 ~18 ~61 end_stone
fill ~55 ~18 ~61 ~56 ~18 ~61 sandstone
fill ~56 ~18 ~59 ~56 ~18 ~61 sandstone
fill ~109 ~18 ~58 ~109 ~18 ~60 sandstone
fill ~107 ~18 ~58 ~107 ~18 ~60 sandstone
fill ~102 ~18 ~60 ~103 ~18 ~60 sandstone
fill ~103 ~17 ~60 ~103 ~18 ~60 sandstone
fill ~51 ~17 ~60 ~51 ~18 ~60 stone
fill ~108 ~17 ~59 ~108 ~18 ~59 sandstone
fill ~105 ~18 ~59 ~106 ~18 ~59 stone
fill ~106 ~17 ~59 ~106 ~18 ~59 stone
fill ~101 ~18 ~59 ~102 ~18 ~59 sandstone
fill ~100 ~18 ~58 ~100 ~18 ~59 end_stone
fill ~58 ~18 ~59 ~59 ~18 ~59 sandstone
fill ~59 ~18 ~58 ~59 ~18 ~59 sandstone
fill ~102 ~17 ~58 ~102 ~18 ~58 end_stone
fill ~81 ~9 ~58 ~81 ~18 ~58 stone
fill ~81 ~18 ~37 ~81 ~18 ~58 stone
fill ~79 ~4 ~58 ~79 ~18 ~58 stone
fill ~79 ~18 ~37 ~79 ~18 ~58 stone
fill ~60 ~18 ~57 ~60 ~18 ~58 sandstone
fill ~58 ~17 ~58 ~58 ~18 ~58 end_stone
fill ~99 ~18 ~55 ~99 ~18 ~57 sandstone
fill ~78 ~5 ~57 ~78 ~18 ~57 stone
fill ~78 ~18 ~27 ~78 ~18 ~57 stone
fill ~76 ~11 ~57 ~76 ~18 ~57 stone
fill ~76 ~18 ~53 ~76 ~18 ~57 stone
fill ~58 ~14 ~57 ~58 ~18 ~57 sandstone
fill ~50 ~17 ~57 ~50 ~18 ~57 sandstone
fill ~109 ~18 ~55 ~109 ~18 ~56 sandstone
fill ~100 ~18 ~56 ~101 ~18 ~56 sandstone
fill ~101 ~16 ~56 ~101 ~18 ~56 sandstone
fill ~98 ~18 ~55 ~98 ~18 ~56 end_stone
fill ~82 ~12 ~56 ~82 ~18 ~56 stone
fill ~77 ~9 ~56 ~77 ~18 ~56 stone
fill ~77 ~18 ~51 ~77 ~18 ~56 stone
fill ~75 ~17 ~56 ~75 ~18 ~56 stone
fill ~75 ~18 ~54 ~75 ~18 ~56 stone
fill ~56 ~17 ~56 ~56 ~18 ~56 stone
fill ~53 ~10 ~56 ~53 ~18 ~56 sandstone
fill ~50 ~17 ~56 ~50 ~18 ~56 end_stone
fill ~106 ~18 ~55 ~108 ~18 ~55 end_stone
fill ~108 ~17 ~55 ~108 ~18 ~55 end_stone
fill ~59 ~18 ~54 ~59 ~18 ~55 stone
fill ~51 ~18 ~55 ~53 ~18 ~55 end_stone
fill ~53 ~18 ~54 ~53 ~18 ~55 end_stone
fill ~107 ~18 ~54 ~108 ~18 ~54 sandstone
fill ~82 ~17 ~54 ~82 ~18 ~54 stone
fill ~82 ~18 ~27 ~82 ~18 ~54 stone
fill ~55 ~18 ~53 ~55 ~18 ~54 end_stone
fill ~105 ~18 ~53 ~106 ~18 ~53 end_stone
fill ~106 ~17 ~53 ~106 ~18 ~53 end_stone
fill ~104 ~10 ~53 ~104 ~18 ~53 sandstone
fill ~104 ~18 ~52 ~104 ~18 ~53 sandstone
fill ~98 ~18 ~52 ~98 ~18 ~53 sandstone
fill ~59 ~18 ~53 ~60 ~18 ~53 sandstone
fill ~105 ~17 ~52 ~105 ~18 ~52 end_stone
fill ~105 ~18 ~50 ~105 ~18 ~52 end_stone
fill ~61 ~18 ~51 ~61 ~18 ~52 sandstone
fill ~58 ~18 ~52 ~59 ~18 ~52 sandstone
fill ~59 ~17 ~52 ~59 ~18 ~52 sandstone
fill ~100 ~17 ~51 ~100 ~18 ~51 stone
fill ~58 ~17 ~51 ~58 ~18 ~51 sandstone
fill ~55 ~18 ~51 ~56 ~18 ~51 sandstone
fill ~104 ~17 ~50 ~104 ~18 ~50 end_stone
fill ~103 ~17 ~50 ~103 ~18 ~50 sandstone
fill ~83 ~17 ~50 ~83 ~18 ~50 stone
fill ~83 ~18 ~42 ~83 ~18 ~50 stone
fill ~77 ~17 ~47 ~77 ~18 ~47 stone
fill ~77 ~18 ~41 ~77 ~18 ~47 stone
fill ~80 ~8 ~45 ~80 ~18 ~45 stone
fill ~80 ~18 ~36 ~80 ~18 ~45 stone
fill ~85 ~15 ~43 ~85 ~18 ~43 stone
fill ~85 ~18 ~40 ~85 ~18 ~43 stone
fill ~75 ~15 ~43 ~75 ~18 ~43 stone
fill ~75 ~18 ~39 ~75 ~18 ~43 stone
fill ~84 ~16 ~41 ~84 ~18 ~41 stone
fill ~84 ~18 ~40 ~84 ~18 ~41 stone
fill ~76 ~14 ~41 ~76 ~18 ~41 stone
fill ~76 ~18 ~38 ~76 ~18 ~41 stone
fill ~84 ~18 ~28 ~84 ~18 ~32 stone
fill ~76 ~16 ~30 ~76 ~18 ~30 stone
fill ~76 ~18 ~29 ~76 ~18 ~30 stone
fill ~81 ~18 ~25 ~81 ~18 ~26 stone
fill ~79 ~18 ~24 ~79 ~18 ~26 stone
fill ~83 ~17 ~25 ~83 ~18 ~25 stone
fill ~80 ~14 ~25 ~80 ~18 ~25 stone
fill ~80 ~18 ~23 ~80 ~18 ~25 stone
fill ~96 ~16 ~20 ~96 ~18 ~20 stone
fill ~63 ~17 ~20 ~63 ~18 ~20 sandstone
fill ~95 ~18 ~19 ~96 ~18 ~19 sandstone
fill ~96 ~16 ~19 ~96 ~18 ~19 sandstone
fill ~66 ~18 ~17 ~66 ~18 ~19 stone
fill ~64 ~18 ~19 ~65 ~18 ~19 sandstone
fill ~65 ~16 ~19 ~65 ~18 ~19 sandstone
fill ~65 ~18 ~18 ~65 ~18 ~19 sandstone
fill ~97 ~16 ~18 ~97 ~18 ~18 sandstone
fill ~97 ~18 ~17 ~97 ~18 ~18 sandstone
fill ~96 ~18 ~16 ~96 ~18 ~18 stone
fill ~94 ~18 ~18 ~95 ~18 ~18 sandstone
fill ~95 ~16 ~18 ~95 ~18 ~18 sandstone
fill ~64 ~18 ~16 ~64 ~18 ~18 stone
fill ~63 ~18 ~16 ~63 ~18 ~18 sandstone
fill ~94 ~18 ~17 ~95 ~18 ~17 stone
fill ~61 ~17 ~17 ~61 ~18 ~17 quartz_block
fill ~95 ~18 ~15 ~95 ~18 ~16 sandstone
fill ~94 ~18 ~15 ~94 ~18 ~16 stone
fill ~65 ~18 ~16 ~66 ~18 ~16 sandstone
fill ~96 ~18 ~15 ~97 ~18 ~15 sandstone
fill ~97 ~18 ~14 ~97 ~18 ~15 sandstone
fill ~64 ~18 ~15 ~65 ~18 ~15 sandstone
fill ~65 ~15 ~15 ~65 ~18 ~15 sandstone
fill ~64 ~16 ~14 ~64 ~18 ~14 stone
fill ~81 ~18 ~9 ~81 ~18 ~10 sandstone
fill ~78 ~18 ~10 ~80 ~18 ~10 stone
fill ~80 ~18 ~8 ~80 ~18 ~10 stone
fill ~82 ~15 ~9 ~82 ~18 ~9 sandstone
fill ~82 ~18 ~8 ~82 ~18 ~9 sandstone
fill ~78 ~18 ~9 ~79 ~18 ~9 sandstone
fill ~83 ~16 ~8 ~83 ~18 ~8 stone
fill ~78 ~16 ~8 ~78 ~18 ~8 sandstone
fill ~78 ~18 ~7 ~78 ~18 ~8 sandstone
fill ~80 ~18 ~7 ~81 ~18 ~7 sandstone
fill ~81 ~16 ~7 ~81 ~18 ~7 sandstone
fill ~77 ~17 ~7 ~77 ~18 ~7 sandstone
fill ~80 ~17 ~5 ~80 ~18 ~5 quartz_block
fill ~80 ~17 ~151 ~80 ~17 ~153 quartz_block
fill ~79 ~16 ~153 ~79 ~17 ~153 sandstone
fill ~79 ~17 ~152 ~79 ~17 ~153 sandstone
fill ~78 ~15 ~153 ~78 ~17 ~153 stone
fill ~83 ~16 ~152 ~83 ~17 ~152 stone
fill ~82 ~16 ~151 ~82 ~17 ~151 sandstone
fill ~78 ~15 ~151 ~78 ~17 ~151 sandstone
fill ~80 ~16 ~149 ~80 ~17 ~149 sandstone
fill ~64 ~16 ~146 ~64 ~17 ~146 stone
fill ~97 ~15 ~145 ~97 ~17 ~145 stone
fill ~95 ~15 ~145 ~95 ~17 ~145 sandstone
fill ~64 ~16 ~145 ~64 ~17 ~145 sandstone
fill ~96 ~14 ~144 ~96 ~17 ~144 sandstone
fill ~95 ~17 ~143 ~97 ~17 ~143 quartz_block
fill ~93 ~16 ~143 ~93 ~17 ~143 sandstone
fill ~67 ~16 ~143 ~67 ~17 ~143 sandstone
fill ~63 ~17 ~143 ~65 ~17 ~143 quartz_block
fill ~63 ~17 ~142 ~65 ~17 ~142 sandstone
fill ~65 ~16 ~142 ~65 ~17 ~142 sandstone
fill ~95 ~17 ~141 ~96 ~17 ~141 sandstone
fill ~96 ~16 ~141 ~96 ~17 ~141 sandstone
fill ~64 ~16 ~141 ~64 ~17 ~141 sandstone
fill ~63 ~15 ~141 ~63 ~17 ~141 stone
fill ~96 ~16 ~140 ~96 ~17 ~140 stone
fill ~80 ~3 ~118 ~80 ~17 ~118 stone
fill ~80 ~17 ~110 ~80 ~17 ~118 stone
fill ~76 ~14 ~118 ~76 ~17 ~118 stone
fill ~76 ~17 ~114 ~76 ~17 ~118 stone
fill ~84 ~14 ~116 ~84 ~17 ~116 stone
fill ~84 ~17 ~114 ~84 ~17 ~116 stone
fill ~82 ~9 ~116 ~82 ~17 ~116 stone
fill ~82 ~17 ~111 ~82 ~17 ~116 stone
fill ~78 ~9 ~116 ~78 ~17 ~116 stone
fill ~78 ~17 ~100 ~78 ~17 ~116 stone
fill ~81 ~13 ~114 ~81 ~17 ~114 stone
fill ~81 ~17 ~98 ~81 ~17 ~114 stone
fill ~79 ~15 ~113 ~79 ~17 ~113 stone
fill ~79 ~17 ~100 ~79 ~17 ~113 stone
fill ~82 ~17 ~99 ~82 ~17 ~109 stone
fill ~58 ~15 ~109 ~58 ~17 ~109 stone
fill ~57 ~16 ~109 ~57 ~17 ~109 end_stone
fill ~57 ~17 ~108 ~57 ~17 ~109 end_stone
fill ~54 ~16 ~109 ~54 ~17 ~109 stone
fill ~103 ~17 ~108 ~104 ~17 ~108 sandstone
fill ~102 ~16 ~108 ~102 ~17 ~108 end_stone
fill ~102 ~17 ~107 ~102 ~17 ~108 end_stone
fill ~80 ~17 ~106 ~80 ~17 ~108 stone
fill ~62 ~17 ~106 ~62 ~17 ~108 stone
fill ~54 ~17 ~108 ~56 ~17 ~108 end_stone
fill ~53 ~17 ~107 ~53 ~17 ~108 sandstone
fill ~107 ~17 ~107 ~108 ~17 ~107 sandstone
fill ~103 ~16 ~107 ~103 ~17 ~107 end_stone
fill ~103 ~17 ~105 ~103 ~17 ~107 end_stone
fill ~83 ~17 ~106 ~83 ~17 ~107 stone
fill ~55 ~12 ~107 ~55 ~17 ~107 sandstone
fill ~55 ~17 ~105 ~55 ~17 ~107 sandstone
fill ~109 ~16 ~106 ~109 ~17 ~106 stone
fill ~107 ~17 ~106 ~108 ~17 ~106 end_stone
fill ~108 ~17 ~103 ~108 ~17 ~106 end_stone
fill ~105 ~17 ~106 ~106 ~17 ~106 sandstone
fill ~106 ~15 ~106 ~106 ~17 ~106 sandstone
fill ~106 ~17 ~105 ~106 ~17 ~106 sandstone
fill ~61 ~17 ~105 ~61 ~17 ~106 stone
fill ~54 ~15 ~106 ~54 ~17 ~106 sandstone
fill ~54 ~17 ~105 ~54 ~17 ~106 sandstone
fill ~107 ~12 ~105 ~107 ~17 ~105 sandstone
fill ~107 ~17 ~104 ~107 ~17 ~105 sandstone
fill ~105 ~16 ~105 ~105 ~17 ~105 sandstone
fill ~104 ~15 ~105 ~104 ~17 ~105 end_stone
fill ~100 ~17 ~104 ~100 ~17 ~105 stone
fill ~60 ~17 ~104 ~60 ~17 ~105 end_stone
fill ~58 ~17 ~105 ~59 ~17 ~105 sandstone
fill ~59 ~15 ~105 ~59 ~17 ~105 sandstone
fill ~59 ~17 ~103 ~59 ~17 ~105 sandstone
fill ~52 ~17 ~105 ~53 ~17 ~105 end_stone
fill ~83 ~12 ~104 ~83 ~17 ~104 stone
fill ~83 ~17 ~100 ~83 ~17 ~104 stone
fill ~58 ~17 ~103 ~58 ~17 ~104 end_stone
fill ~55 ~15 ~104 ~55 ~17 ~104 end_stone
fill ~55 ~17 ~103 ~55 ~17 ~104 end_stone
fill ~52 ~17 ~103 ~52 ~17 ~104 sandstone
fill ~53 ~17 ~103 ~54 ~17 ~103 end_stone
fill ~54 ~15 ~103 ~54 ~17 ~103 end_stone
fill ~109 ~15 ~102 ~109 ~17 ~102 stone
fill ~105 ~17 ~101 ~105 ~17 ~102 sandstone
fill ~103 ~17 ~102 ~104 ~17 ~102 end_stone
fill ~100 ~17 ~102 ~101 ~17 ~102 end_stone
fill ~101 ~17 ~101 ~101 ~17 ~102 end_stone
fill ~59 ~17 ~102 ~60 ~17 ~102 end_stone
fill ~52 ~17 ~102 ~53 ~17 ~102 end_stone
fill ~103 ~17 ~100 ~103 ~17 ~101 sandstone
fill ~77 ~16 ~101 ~77 ~17 ~101 stone
fill ~58 ~17 ~101 ~59 ~17 ~101 end_stone
fill ~53 ~17 ~101 ~54 ~17 ~101 stone
fill ~104 ~17 ~100 ~105 ~17 ~100 end_stone
fill ~55 ~17 ~100 ~56 ~17 ~100 stone
fill ~105 ~17 ~99 ~106 ~17 ~99 stone
fill ~106 ~17 ~98 ~106 ~17 ~99 stone
fill ~107 ~17 ~98 ~108 ~17 ~98 stone
fill ~143 ~17 ~95 ~143 ~17 ~97 quartz_block
fill ~142 ~16 ~97 ~142 ~17 ~97 sandstone
fill ~142 ~17 ~96 ~142 ~17 ~97 sandstone
fill ~141 ~15 ~97 ~141 ~17 ~97 stone
fill ~17 ~17 ~95 ~17 ~17 ~97 quartz_block
fill ~16 ~16 ~97 ~16 ~17 ~97 sandstone
fill ~16 ~17 ~96 ~16 ~17 ~97 sandstone
fill ~15 ~15 ~97 ~15 ~17 ~97 stone
fill ~146 ~16 ~96 ~146 ~17 ~96 stone
fill ~20 ~16 ~96 ~20 ~17 ~96 stone
fill ~145 ~16 ~95 ~145 ~17 ~95 sandstone
fill ~141 ~15 ~95 ~141 ~17 ~95 sandstone
fill ~74 ~16 ~95 ~74 ~17 ~95 stone
fill ~74 ~17 ~94 ~74 ~17 ~95 stone
fill ~19 ~16 ~95 ~19 ~17 ~95 sandstone
fill ~15 ~15 ~95 ~15 ~17 ~95 sandstone
fill ~81 ~16 ~94 ~81 ~17 ~94 stone
fill ~77 ~15 ~94 ~77 ~17 ~94 stone
fill ~77 ~17 ~86 ~77 ~17 ~94 stone
fill ~73 ~16 ~94 ~73 ~17 ~94 stone
fill ~73 ~17 ~92 ~73 ~17 ~94 stone
fill ~143 ~16 ~93 ~143 ~17 ~93 sandstone
fill ~76 ~13 ~93 ~76 ~17 ~93 stone
fill ~76 ~17 ~91 ~76 ~17 ~93 stone
fill ~17 ~16 ~93 ~17 ~17 ~93 sandstone
fill ~83 ~12 ~92 ~83 ~17 ~92 stone
fill ~83 ~17 ~84 ~83 ~17 ~92 stone
fill ~75 ~13 ~92 ~75 ~17 ~92 stone
fill ~72 ~15 ~92 ~72 ~17 ~92 stone
fill ~89 ~16 ~91 ~89 ~17 ~91 stone
fill ~82 ~11 ~91 ~82 ~17 ~91 stone
fill ~82 ~17 ~84 ~82 ~17 ~91 stone
fill ~79 ~7 ~91 ~79 ~17 ~91 stone
fill ~79 ~17 ~75 ~79 ~17 ~91 stone
fill ~71 ~14 ~91 ~71 ~17 ~91 stone
fill ~90 ~15 ~90 ~90 ~17 ~90 stone
fill ~81 ~6 ~90 ~81 ~17 ~90 stone
fill ~81 ~17 ~84 ~81 ~17 ~90 stone
fill ~70 ~16 ~90 ~70 ~17 ~90 stone
fill ~92 ~15 ~87 ~92 ~17 ~87 stone
fill ~92 ~8 ~83 ~92 ~17 ~83 stone
fill ~78 ~0 ~83 ~78 ~17 ~83 stone
fill ~78 ~17 ~79 ~78 ~17 ~83 stone
fill ~76 ~0 ~83 ~76 ~17 ~83 stone
fill ~76 ~17 ~81 ~76 ~17 ~83 stone
fill ~54 ~12 ~83 ~54 ~17 ~83 stone
fill ~8 ~16 ~83 ~8 ~17 ~83 stone
fill ~153 ~15 ~82 ~153 ~17 ~82 stone
fill ~151 ~15 ~82 ~151 ~17 ~82 sandstone
fill ~77 ~0 ~82 ~77 ~17 ~82 stone
fill ~77 ~17 ~81 ~77 ~17 ~82 stone
fill ~8 ~16 ~82 ~8 ~17 ~82 sandstone
fill ~152 ~14 ~81 ~152 ~17 ~81 sandstone
fill ~82 ~0 ~81 ~82 ~17 ~81 stone
fill ~82 ~17 ~73 ~82 ~17 ~81 stone
fill ~75 ~0 ~81 ~75 ~17 ~81 stone
fill ~65 ~16 ~81 ~65 ~17 ~81 stone
fill ~151 ~17 ~80 ~153 ~17 ~80 quartz_block
fill ~149 ~16 ~80 ~149 ~17 ~80 sandstone
fill ~81 ~0 ~80 ~81 ~17 ~80 stone
fill ~81 ~17 ~71 ~81 ~17 ~80 stone
fill ~11 ~16 ~80 ~11 ~17 ~80 sandstone
fill ~7 ~17 ~80 ~9 ~17 ~80 quartz_block
fill ~95 ~16 ~79 ~95 ~17 ~79 stone
fill ~95 ~17 ~78 ~95 ~17 ~79 stone
fill ~84 ~17 ~79 ~85 ~17 ~79 stone
fill ~85 ~0 ~79 ~85 ~17 ~79 stone
fill ~7 ~17 ~79 ~9 ~17 ~79 sandstone
fill ~9 ~16 ~79 ~9 ~17 ~79 sandstone
fill ~151 ~17 ~78 ~152 ~17 ~78 sandstone
fill ~152 ~16 ~78 ~152 ~17 ~78 sandstone
fill ~86 ~0 ~78 ~86 ~17 ~78 stone
fill ~86 ~17 ~77 ~86 ~17 ~78 stone
fill ~84 ~0 ~78 ~84 ~17 ~78 stone
fill ~76 ~0 ~78 ~76 ~17 ~78 stone
fill ~76 ~17 ~76 ~76 ~17 ~78 stone
fill ~74 ~0 ~78 ~74 ~17 ~78 stone
fill ~74 ~17 ~77 ~74 ~17 ~78 stone
fill ~8 ~16 ~78 ~8 ~17 ~78 sandstone
fill ~7 ~15 ~78 ~7 ~17 ~78 stone
fill ~152 ~16 ~77 ~152 ~17 ~77 stone
fill ~106 ~12 ~77 ~106 ~17 ~77 stone
fill ~77 ~0 ~76 ~77 ~17 ~76 stone
fill ~72 ~7 ~76 ~72 ~17 ~76 stone
fill ~72 ~17 ~74 ~72 ~17 ~76 stone
fill ~80 ~0 ~75 ~80 ~17 ~75 stone
fill ~78 ~0 ~75 ~78 ~17 ~75 stone
fill ~71 ~10 ~75 ~71 ~17 ~75 stone
fill ~71 ~17 ~74 ~71 ~17 ~75 stone
fill ~68 ~16 ~75 ~68 ~17 ~75 stone
fill ~68 ~17 ~74 ~68 ~17 ~75 stone
fill ~70 ~16 ~73 ~70 ~17 ~73 stone
fill ~91 ~16 ~71 ~91 ~17 ~71 stone
fill ~79 ~4 ~71 ~79 ~17 ~71 stone
fill ~143 ~16 ~67 ~143 ~17 ~67 sandstone
fill ~17 ~16 ~67 ~17 ~17 ~67 sandstone
fill ~144 ~16 ~65 ~144 ~17 ~65 sandstone
fill ~144 ~17 ~64 ~144 ~17 ~65 sandstone
fill ~143 ~17 ~63 ~143 ~17 ~65 quartz_block
fill ~141 ~16 ~65 ~141 ~17 ~65 sandstone
fill ~18 ~16 ~65 ~18 ~17 ~65 sandstone
fill ~18 ~17 ~64 ~18 ~17 ~65 sandstone
fill ~17 ~17 ~63 ~17 ~17 ~65 quartz_block
fill ~15 ~16 ~65 ~15 ~17 ~65 sandstone
fill ~145 ~16 ~64 ~145 ~17 ~64 sandstone
fill ~140 ~16 ~64 ~140 ~17 ~64 stone
fill ~19 ~16 ~64 ~19 ~17 ~64 sandstone
fill ~14 ~16 ~64 ~14 ~17 ~64 stone
fill ~145 ~15 ~63 ~145 ~17 ~63 stone
fill ~19 ~15 ~63 ~19 ~17 ~63 stone
fill ~52 ~17 ~62 ~54 ~17 ~62 stone
fill ~54 ~17 ~61 ~54 ~17 ~62 stone
fill ~56 ~17 ~60 ~56 ~17 ~61 end_stone
fill ~104 ~17 ~60 ~105 ~17 ~60 stone
fill ~102 ~17 ~59 ~102 ~17 ~60 end_stone
fill ~58 ~17 ~59 ~58 ~17 ~60 end_stone
fill ~57 ~17 ~59 ~57 ~17 ~60 sandstone
fill ~101 ~17 ~58 ~101 ~17 ~59 end_stone
fill ~59 ~17 ~58 ~59 ~17 ~59 end_stone
fill ~55 ~17 ~59 ~56 ~17 ~59 sandstone
fill ~56 ~16 ~59 ~56 ~17 ~59 sandstone
fill ~107 ~17 ~58 ~108 ~17 ~58 end_stone
fill ~108 ~16 ~58 ~108 ~17 ~58 end_stone
fill ~56 ~17 ~58 ~57 ~17 ~58 end_stone
fill ~57 ~14 ~58 ~57 ~17 ~58 end_stone
fill ~51 ~15 ~58 ~51 ~17 ~58 stone
fill ~108 ~17 ~56 ~108 ~17 ~57 sandstone
fill ~105 ~17 ~57 ~107 ~17 ~57 end_stone
fill ~107 ~16 ~57 ~107 ~17 ~57 end_stone
fill ~102 ~14 ~57 ~102 ~17 ~57 end_stone
fill ~102 ~17 ~56 ~102 ~17 ~57 end_stone
fill ~100 ~17 ~57 ~101 ~17 ~57 sandstone
fill ~81 ~7 ~57 ~81 ~17 ~57 stone
fill ~81 ~17 ~37 ~81 ~17 ~57 stone
fill ~79 ~1 ~57 ~79 ~17 ~57 stone
fill ~79 ~17 ~37 ~79 ~17 ~57 stone
fill ~59 ~17 ~57 ~60 ~17 ~57 sandstone
fill ~52 ~17 ~54 ~52 ~17 ~57 end_stone
fill ~105 ~15 ~56 ~105 ~17 ~56 end_stone
fill ~99 ~17 ~56 ~100 ~17 ~56 end_stone
fill ~100 ~17 ~55 ~100 ~17 ~56 end_stone
fill ~78 ~7 ~56 ~78 ~17 ~56 stone
fill ~78 ~17 ~51 ~78 ~17 ~56 stone
fill ~76 ~13 ~56 ~76 ~17 ~56 stone
fill ~76 ~17 ~55 ~76 ~17 ~56 stone
fill ~60 ~17 ~55 ~60 ~17 ~56 stone
fill ~105 ~17 ~55 ~106 ~17 ~55 sandstone
fill ~106 ~16 ~55 ~106 ~17 ~55 sandstone
fill ~106 ~17 ~54 ~106 ~17 ~55 sandstone
fill ~101 ~17 ~55 ~102 ~17 ~55 sandstone
fill ~99 ~17 ~54 ~99 ~17 ~55 stone
fill ~77 ~13 ~55 ~77 ~17 ~55 stone
fill ~77 ~17 ~53 ~77 ~17 ~55 stone
fill ~56 ~17 ~55 ~57 ~17 ~55 end_stone
fill ~57 ~16 ~55 ~57 ~17 ~55 end_stone
fill ~57 ~17 ~53 ~57 ~17 ~55 end_stone
fill ~53 ~17 ~55 ~55 ~17 ~55 sandstone
fill ~55 ~16 ~55 ~55 ~17 ~55 sandstone
fill ~55 ~17 ~54 ~55 ~17 ~55 sandstone
fill ~107 ~16 ~54 ~107 ~17 ~54 sandstone
fill ~107 ~17 ~52 ~107 ~17 ~54 sandstone
fill ~105 ~15 ~54 ~105 ~17 ~54 sandstone
fill ~105 ~17 ~53 ~105 ~17 ~54 sandstone
fill ~98 ~17 ~52 ~98 ~17 ~54 stone
fill ~59 ~17 ~53 ~59 ~17 ~54 stone
fill ~54 ~15 ~54 ~54 ~17 ~54 sandstone
fill ~51 ~16 ~54 ~51 ~17 ~54 stone
fill ~82 ~17 ~27 ~82 ~17 ~53 stone
fill ~58 ~17 ~52 ~58 ~17 ~53 end_stone
fill ~52 ~17 ~53 ~53 ~17 ~53 sandstone
fill ~103 ~17 ~52 ~104 ~17 ~52 end_stone
fill ~56 ~17 ~52 ~57 ~17 ~52 sandstone
fill ~106 ~16 ~51 ~106 ~17 ~51 stone
fill ~102 ~15 ~51 ~102 ~17 ~51 stone
fill ~83 ~17 ~42 ~83 ~17 ~49 stone
fill ~78 ~17 ~27 ~78 ~17 ~49 stone
fill ~77 ~17 ~41 ~77 ~17 ~46 stone
fill ~80 ~6 ~44 ~80 ~17 ~44 stone
fill ~80 ~17 ~36 ~80 ~17 ~44 stone
fill ~75 ~14 ~42 ~75 ~17 ~42 stone
fill ~75 ~17 ~39 ~75 ~17 ~42 stone
fill ~76 ~14 ~40 ~76 ~17 ~40 stone
fill ~76 ~17 ~38 ~76 ~17 ~40 stone
fill ~84 ~17 ~29 ~84 ~17 ~31 stone
fill ~79 ~16 ~25 ~79 ~17 ~25 stone
fill ~80 ~16 ~24 ~80 ~17 ~24 stone
fill ~64 ~16 ~20 ~64 ~17 ~20 stone
fill ~97 ~15 ~19 ~97 ~17 ~19 stone
fill ~95 ~15 ~19 ~95 ~17 ~19 sandstone
fill ~64 ~16 ~19 ~64 ~17 ~19 sandstone
fill ~96 ~14 ~18 ~96 ~17 ~18 sandstone
fill ~95 ~17 ~17 ~97 ~17 ~17 quartz_block
fill ~93 ~16 ~17 ~93 ~17 ~17 sandstone
fill ~67 ~16 ~17 ~67 ~17 ~17 sandstone
fill ~63 ~17 ~17 ~65 ~17 ~17 quartz_block
fill ~63 ~17 ~16 ~65 ~17 ~16 sandstone
fill ~65 ~16 ~16 ~65 ~17 ~16 sandstone
fill ~95 ~17 ~15 ~96 ~17 ~15 sandstone
fill ~96 ~16 ~15 ~96 ~17 ~15 sandstone
fill ~64 ~16 ~15 ~64 ~17 ~15 sandstone
fill ~63 ~15 ~15 ~63 ~17 ~15 stone
fill ~96 ~16 ~14 ~96 ~17 ~14 stone
fill ~80 ~16 ~11 ~80 ~17 ~11 sandstone
fill ~81 ~16 ~9 ~81 ~17 ~9 sandstone
fill ~81 ~17 ~8 ~81 ~17 ~9 sandstone
fill ~80 ~17 ~7 ~80 ~17 ~9 quartz_block
fill ~78 ~16 ~9 ~78 ~17 ~9 sandstone
fill ~82 ~16 ~8 ~82 ~17 ~8 sandstone
fill ~77 ~16 ~8 ~77 ~17 ~8 stone
fill ~82 ~15 ~7 ~82 ~17 ~7 stone
fill ~79 ~14 ~152 ~79 ~16 ~152 sandstone
fill ~63 ~16 ~142 ~64 ~16 ~142 sandstone
fill ~64 ~14 ~142 ~64 ~16 ~142 sandstone
fill ~80 ~2 ~117 ~80 ~16 ~117 stone
fill ~80 ~16 ~111 ~80 ~16 ~117 stone
fill ~76 ~14 ~117 ~76 ~16 ~117 stone
fill ~76 ~16 ~115 ~76 ~16 ~117 stone
fill ~82 ~11 ~115 ~82 ~16 ~115 stone
fill ~82 ~16 ~113 ~82 ~16 ~115 stone
fill ~78 ~11 ~115 ~78 ~16 ~115 stone
fill ~78 ~16 ~112 ~78 ~16 ~115 stone
fill ~81 ~15 ~113 ~81 ~16 ~113 stone
fill ~81 ~16 ~111 ~81 ~16 ~113 stone
fill ~79 ~15 ~112 ~79 ~16 ~112 stone
fill ~79 ~16 ~110 ~79 ~16 ~112 stone
fill ~55 ~16 ~108 ~55 ~16 ~109 sandstone
fill ~105 ~16 ~106 ~105 ~16 ~108 sandstone
fill ~103 ~16 ~108 ~104 ~16 ~108 end_stone
fill ~81 ~16 ~99 ~81 ~16 ~108 stone
fill ~56 ~16 ~108 ~57 ~16 ~108 sandstone
fill ~54 ~16 ~107 ~54 ~16 ~108 sandstone
fill ~82 ~15 ~107 ~82 ~16 ~107 stone
fill ~82 ~16 ~99 ~82 ~16 ~107 stone
fill ~80 ~16 ~106 ~80 ~16 ~107 stone
fill ~107 ~16 ~106 ~108 ~16 ~106 sandstone
fill ~108 ~16 ~103 ~108 ~16 ~106 sandstone
fill ~103 ~15 ~106 ~103 ~16 ~106 end_stone
fill ~103 ~16 ~105 ~103 ~16 ~106 end_stone
fill ~83 ~12 ~106 ~83 ~16 ~106 stone
fill ~79 ~15 ~106 ~79 ~16 ~106 stone
fill ~79 ~16 ~100 ~79 ~16 ~106 stone
fill ~58 ~16 ~106 ~61 ~16 ~106 sandstone
fill ~61 ~14 ~106 ~61 ~16 ~106 sandstone
fill ~56 ~16 ~106 ~57 ~16 ~106 end_stone
fill ~57 ~15 ~106 ~57 ~16 ~106 end_stone
fill ~55 ~15 ~106 ~55 ~16 ~106 sandstone
fill ~55 ~16 ~105 ~55 ~16 ~106 sandstone
fill ~106 ~15 ~105 ~106 ~16 ~105 sandstone
fill ~102 ~15 ~105 ~102 ~16 ~105 sandstone
fill ~78 ~16 ~101 ~78 ~16 ~105 stone
fill ~60 ~16 ~104 ~60 ~16 ~105 sandstone
fill ~56 ~16 ~105 ~57 ~16 ~105 sandstone
fill ~57 ~16 ~104 ~57 ~16 ~105 sandstone
fill ~52 ~16 ~105 ~54 ~16 ~105 sandstone
fill ~107 ~10 ~104 ~107 ~16 ~104 sandstone
fill ~106 ~16 ~103 ~106 ~16 ~104 end_stone
fill ~103 ~16 ~104 ~105 ~16 ~104 sandstone
fill ~105 ~11 ~104 ~105 ~16 ~104 sandstone
fill ~105 ~16 ~103 ~105 ~16 ~104 sandstone
fill ~102 ~15 ~104 ~102 ~16 ~104 end_stone
fill ~58 ~16 ~104 ~59 ~16 ~104 sandstone
fill ~56 ~16 ~103 ~56 ~16 ~104 sandstone
fill ~52 ~16 ~102 ~52 ~16 ~104 end_stone
fill ~104 ~16 ~102 ~104 ~16 ~103 sandstone
fill ~103 ~15 ~103 ~103 ~16 ~103 end_stone
fill ~103 ~16 ~100 ~103 ~16 ~103 end_stone
fill ~100 ~16 ~103 ~101 ~16 ~103 stone
fill ~101 ~14 ~103 ~101 ~16 ~103 stone
fill ~83 ~7 ~103 ~83 ~16 ~103 stone
fill ~83 ~16 ~100 ~83 ~16 ~103 stone
fill ~57 ~16 ~103 ~60 ~16 ~103 end_stone
fill ~106 ~15 ~102 ~106 ~16 ~102 sandstone
fill ~106 ~16 ~99 ~106 ~16 ~102 sandstone
fill ~101 ~16 ~102 ~102 ~16 ~102 sandstone
fill ~102 ~14 ~102 ~102 ~16 ~102 sandstone
fill ~102 ~16 ~101 ~102 ~16 ~102 sandstone
fill ~58 ~16 ~102 ~59 ~16 ~102 sandstone
fill ~59 ~16 ~101 ~59 ~16 ~102 sandstone
fill ~56 ~15 ~102 ~56 ~16 ~102 end_stone
fill ~55 ~15 ~102 ~55 ~16 ~102 sandstone
fill ~105 ~15 ~101 ~105 ~16 ~101 sandstone
fill ~105 ~16 ~100 ~105 ~16 ~101 sandstone
fill ~57 ~14 ~101 ~57 ~16 ~101 stone
fill ~57 ~16 ~100 ~57 ~16 ~101 stone
fill ~104 ~15 ~100 ~104 ~16 ~100 sandstone
fill ~104 ~16 ~99 ~104 ~16 ~100 sandstone
fill ~142 ~14 ~96 ~142 ~16 ~96 sandstone
fill ~16 ~14 ~96 ~16 ~16 ~96 sandstone
fill ~77 ~13 ~93 ~77 ~16 ~93 stone
fill ~77 ~16 ~86 ~77 ~16 ~93 stone
fill ~73 ~15 ~93 ~73 ~16 ~93 stone
fill ~73 ~16 ~92 ~73 ~16 ~93 stone
fill ~76 ~13 ~92 ~76 ~16 ~92 stone
fill ~76 ~16 ~91 ~76 ~16 ~92 stone
fill ~83 ~11 ~91 ~83 ~16 ~91 stone
fill ~83 ~16 ~84 ~83 ~16 ~91 stone
fill ~82 ~6 ~90 ~82 ~16 ~90 stone
fill ~82 ~16 ~84 ~82 ~16 ~90 stone
fill ~79 ~6 ~90 ~79 ~16 ~90 stone
fill ~79 ~16 ~75 ~79 ~16 ~90 stone
fill ~81 ~2 ~89 ~81 ~16 ~89 stone
fill ~81 ~16 ~84 ~81 ~16 ~89 stone
fill ~78 ~0 ~82 ~78 ~16 ~82 stone
fill ~78 ~16 ~79 ~78 ~16 ~82 stone
fill ~76 ~0 ~82 ~76 ~16 ~82 stone
fill ~76 ~16 ~81 ~76 ~16 ~82 stone
fill ~77 ~0 ~81 ~77 ~16 ~81 stone
fill ~82 ~0 ~80 ~82 ~16 ~80 stone
fill ~82 ~16 ~73 ~82 ~16 ~80 stone
fill ~84 ~0 ~79 ~84 ~16 ~79 stone
fill ~81 ~0 ~79 ~81 ~16 ~79 stone
fill ~81 ~16 ~71 ~81 ~16 ~79 stone
fill ~7 ~16 ~79 ~8 ~16 ~79 sandstone
fill ~8 ~14 ~79 ~8 ~16 ~79 sandstone
fill ~86 ~0 ~77 ~86 ~16 ~77 stone
fill ~76 ~0 ~77 ~76 ~16 ~77 stone
fill ~76 ~16 ~76 ~76 ~16 ~77 stone
fill ~74 ~0 ~77 ~74 ~16 ~77 stone
fill ~72 ~9 ~75 ~72 ~16 ~75 stone
fill ~72 ~16 ~74 ~72 ~16 ~75 stone
fill ~71 ~11 ~74 ~71 ~16 ~74 stone
fill ~72 ~15 ~69 ~72 ~16 ~69 stone
fill ~144 ~14 ~64 ~144 ~16 ~64 sandstone
fill ~18 ~14 ~64 ~18 ~16 ~64 sandstone
fill ~56 ~16 ~60 ~56 ~16 ~61 sandstone
fill ~54 ~14 ~61 ~54 ~16 ~61 sandstone
fill ~54 ~16 ~58 ~54 ~16 ~61 sandstone
fill ~103 ~16 ~59 ~103 ~16 ~60 stone
fill ~57 ~16 ~59 ~57 ~16 ~60 end_stone
fill ~55 ~16 ~59 ~55 ~16 ~60 sandstone
fill ~101 ~16 ~59 ~102 ~16 ~59 sandstone
fill ~102 ~16 ~58 ~102 ~16 ~59 sandstone
fill ~58 ~16 ~59 ~59 ~16 ~59 sandstone
fill ~59 ~16 ~58 ~59 ~16 ~59 sandstone
fill ~105 ~15 ~58 ~105 ~16 ~58 sandstone
fill ~104 ~15 ~58 ~104 ~16 ~58 end_stone
fill ~58 ~14 ~58 ~58 ~16 ~58 sandstone
fill ~56 ~15 ~58 ~56 ~16 ~58 sandstone
fill ~56 ~16 ~56 ~56 ~16 ~58 sandstone
fill ~108 ~16 ~56 ~108 ~16 ~57 end_stone
fill ~105 ~16 ~57 ~106 ~16 ~57 end_stone
fill ~106 ~15 ~57 ~106 ~16 ~57 end_stone
fill ~104 ~16 ~55 ~104 ~16 ~57 sandstone
fill ~103 ~15 ~57 ~103 ~16 ~57 end_stone
fill ~100 ~16 ~57 ~101 ~16 ~57 end_stone
fill ~59 ~16 ~57 ~60 ~16 ~57 stone
fill ~57 ~15 ~57 ~57 ~16 ~57 end_stone
fill ~55 ~16 ~56 ~55 ~16 ~57 sandstone
fill ~54 ~15 ~57 ~54 ~16 ~57 end_stone
fill ~54 ~16 ~56 ~54 ~16 ~57 end_stone
fill ~52 ~16 ~54 ~52 ~16 ~57 sandstone
fill ~102 ~16 ~56 ~103 ~16 ~56 sandstone
fill ~103 ~16 ~55 ~103 ~16 ~56 sandstone
fill ~99 ~16 ~56 ~100 ~16 ~56 sandstone
fill ~100 ~15 ~56 ~100 ~16 ~56 sandstone
fill ~100 ~16 ~54 ~100 ~16 ~56 sandstone
fill ~81 ~9 ~56 ~81 ~16 ~56 stone
fill ~81 ~16 ~54 ~81 ~16 ~56 stone
fill ~79 ~6 ~56 ~79 ~16 ~56 stone
fill ~79 ~16 ~52 ~79 ~16 ~56 stone
fill ~58 ~15 ~56 ~58 ~16 ~56 end_stone
fill ~107 ~16 ~55 ~108 ~16 ~55 sandstone
fill ~101 ~15 ~55 ~101 ~16 ~55 sandstone
fill ~101 ~16 ~54 ~101 ~16 ~55 sandstone
fill ~78 ~10 ~55 ~78 ~16 ~55 stone
fill ~78 ~16 ~53 ~78 ~16 ~55 stone
fill ~76 ~14 ~55 ~76 ~16 ~55 stone
fill ~58 ~15 ~55 ~58 ~16 ~55 sandstone
fill ~56 ~15 ~55 ~56 ~16 ~55 end_stone
fill ~53 ~16 ~55 ~54 ~16 ~55 sandstone
fill ~54 ~15 ~55 ~54 ~16 ~55 sandstone
fill ~106 ~15 ~54 ~106 ~16 ~54 sandstone
fill ~106 ~16 ~52 ~106 ~16 ~54 sandstone
fill ~103 ~16 ~54 ~104 ~16 ~54 end_stone
fill ~102 ~15 ~54 ~102 ~16 ~54 sandstone
fill ~99 ~14 ~54 ~99 ~16 ~54 sandstone
fill ~77 ~12 ~54 ~77 ~16 ~54 stone
fill ~57 ~15 ~54 ~57 ~16 ~54 end_stone
fill ~57 ~16 ~52 ~57 ~16 ~54 end_stone
fill ~55 ~16 ~52 ~55 ~16 ~54 sandstone
fill ~105 ~12 ~53 ~105 ~16 ~53 sandstone
fill ~105 ~16 ~51 ~105 ~16 ~53 sandstone
fill ~103 ~16 ~52 ~104 ~16 ~52 sandstone
fill ~81 ~16 ~37 ~81 ~16 ~50 stone
fill ~79 ~16 ~37 ~79 ~16 ~49 stone
fill ~82 ~16 ~48 ~83 ~16 ~48 stone
fill ~82 ~16 ~39 ~82 ~16 ~47 stone
fill ~78 ~16 ~36 ~78 ~16 ~47 stone
fill ~83 ~16 ~42 ~83 ~16 ~46 stone
fill ~77 ~15 ~45 ~77 ~16 ~45 stone
fill ~77 ~16 ~41 ~77 ~16 ~45 stone
fill ~80 ~2 ~43 ~80 ~16 ~43 stone
fill ~80 ~16 ~36 ~80 ~16 ~43 stone
fill ~82 ~16 ~36 ~82 ~16 ~37 stone
fill ~82 ~15 ~33 ~82 ~16 ~33 stone
fill ~82 ~16 ~28 ~82 ~16 ~33 stone
fill ~78 ~16 ~28 ~78 ~16 ~33 stone
fill ~84 ~15 ~30 ~84 ~16 ~30 stone
fill ~63 ~16 ~16 ~64 ~16 ~16 sandstone
fill ~64 ~14 ~16 ~64 ~16 ~16 sandstone
fill ~81 ~14 ~8 ~81 ~16 ~8 sandstone
fill ~83 ~14 ~152 ~83 ~15 ~152 sandstone
fill ~78 ~12 ~152 ~78 ~15 ~152 stone
fill ~64 ~14 ~146 ~64 ~15 ~146 sandstone
fill ~96 ~12 ~145 ~96 ~15 ~145 stone
fill ~64 ~12 ~141 ~64 ~15 ~141 stone
fill ~96 ~14 ~140 ~96 ~15 ~140 sandstone
fill ~77 ~14 ~119 ~77 ~15 ~119 stone
fill ~80 ~6 ~116 ~80 ~15 ~116 stone
fill ~80 ~15 ~112 ~80 ~15 ~116 stone
fill ~76 ~14 ~116 ~76 ~15 ~116 stone
fill ~56 ~14 ~109 ~56 ~15 ~109 end_stone
fill ~56 ~15 ~108 ~56 ~15 ~109 end_stone
fill ~54 ~15 ~108 ~55 ~15 ~108 stone
fill ~107 ~15 ~106 ~107 ~15 ~107 stone
fill ~105 ~15 ~107 ~106 ~15 ~107 end_stone
fill ~81 ~15 ~100 ~81 ~15 ~107 stone
fill ~60 ~13 ~107 ~60 ~15 ~107 sandstone
fill ~60 ~15 ~106 ~60 ~15 ~107 sandstone
fill ~59 ~15 ~106 ~59 ~15 ~107 end_stone
fill ~58 ~14 ~107 ~58 ~15 ~107 sandstone
fill ~58 ~15 ~104 ~58 ~15 ~107 sandstone
fill ~53 ~15 ~107 ~54 ~15 ~107 stone
fill ~54 ~14 ~107 ~54 ~15 ~107 stone
fill ~108 ~15 ~105 ~108 ~15 ~106 stone
fill ~105 ~15 ~105 ~105 ~15 ~106 end_stone
fill ~104 ~14 ~106 ~104 ~15 ~106 sandstone
fill ~82 ~12 ~106 ~82 ~15 ~106 stone
fill ~82 ~15 ~100 ~82 ~15 ~106 stone
fill ~80 ~12 ~106 ~80 ~15 ~106 stone
fill ~56 ~15 ~105 ~56 ~15 ~106 sandstone
fill ~53 ~15 ~105 ~53 ~15 ~106 end_stone
fill ~103 ~13 ~105 ~103 ~15 ~105 sandstone
fill ~79 ~12 ~105 ~79 ~15 ~105 stone
fill ~79 ~15 ~101 ~79 ~15 ~105 stone
fill ~57 ~15 ~103 ~57 ~15 ~105 end_stone
fill ~54 ~15 ~105 ~55 ~15 ~105 end_stone
fill ~108 ~15 ~104 ~109 ~15 ~104 end_stone
fill ~109 ~14 ~104 ~109 ~15 ~104 end_stone
fill ~103 ~15 ~104 ~104 ~15 ~104 end_stone
fill ~104 ~14 ~104 ~104 ~15 ~104 end_stone
fill ~104 ~15 ~103 ~104 ~15 ~104 end_stone
fill ~78 ~12 ~104 ~78 ~15 ~104 stone
fill ~78 ~15 ~101 ~78 ~15 ~104 stone
fill ~59 ~14 ~104 ~59 ~15 ~104 end_stone
fill ~56 ~14 ~104 ~56 ~15 ~104 end_stone
fill ~56 ~15 ~103 ~56 ~15 ~104 end_stone
fill ~54 ~14 ~104 ~54 ~15 ~104 sandstone
fill ~105 ~15 ~103 ~106 ~15 ~103 end_stone
fill ~58 ~14 ~103 ~58 ~15 ~103 end_stone
fill ~55 ~13 ~103 ~55 ~15 ~103 sandstone
fill ~107 ~14 ~102 ~107 ~15 ~102 sandstone
fill ~104 ~15 ~102 ~105 ~15 ~102 sandstone
fill ~105 ~14 ~102 ~105 ~15 ~102 sandstone
fill ~103 ~14 ~102 ~103 ~15 ~102 end_stone
fill ~83 ~11 ~102 ~83 ~15 ~102 stone
fill ~83 ~15 ~100 ~83 ~15 ~102 stone
fill ~58 ~14 ~102 ~58 ~15 ~102 sandstone
fill ~106 ~15 ~101 ~107 ~15 ~101 end_stone
fill ~104 ~14 ~101 ~104 ~15 ~101 end_stone
fill ~106 ~15 ~100 ~107 ~15 ~100 sandstone
fill ~107 ~13 ~100 ~107 ~15 ~100 sandstone
fill ~106 ~14 ~99 ~106 ~15 ~99 sandstone
fill ~146 ~14 ~96 ~146 ~15 ~96 sandstone
fill ~141 ~12 ~96 ~141 ~15 ~96 stone
fill ~20 ~14 ~96 ~20 ~15 ~96 sandstone
fill ~15 ~12 ~96 ~15 ~15 ~96 stone
fill ~77 ~12 ~92 ~77 ~15 ~92 stone
fill ~77 ~15 ~86 ~77 ~15 ~92 stone
fill ~73 ~13 ~92 ~73 ~15 ~92 stone
fill ~76 ~11 ~91 ~76 ~15 ~91 stone
fill ~83 ~6 ~90 ~83 ~15 ~90 stone
fill ~83 ~15 ~84 ~83 ~15 ~90 stone
fill ~82 ~1 ~89 ~82 ~15 ~89 stone
fill ~82 ~15 ~84 ~82 ~15 ~89 stone
fill ~79 ~2 ~89 ~79 ~15 ~89 stone
fill ~79 ~15 ~75 ~79 ~15 ~89 stone
fill ~81 ~0 ~88 ~81 ~15 ~88 stone
fill ~81 ~15 ~84 ~81 ~15 ~88 stone
fill ~40 ~14 ~84 ~40 ~15 ~84 stone
fill ~119 ~14 ~83 ~119 ~15 ~83 stone
fill ~8 ~14 ~83 ~8 ~15 ~83 sandstone
fill ~152 ~12 ~82 ~152 ~15 ~82 stone
fill ~78 ~0 ~81 ~78 ~15 ~81 stone
fill ~78 ~15 ~79 ~78 ~15 ~81 stone
fill ~76 ~0 ~81 ~76 ~15 ~81 stone
fill ~82 ~0 ~79 ~82 ~15 ~79 stone
fill ~82 ~15 ~73 ~82 ~15 ~79 stone
fill ~81 ~0 ~78 ~81 ~15 ~78 stone
fill ~81 ~15 ~71 ~81 ~15 ~78 stone
fill ~8 ~12 ~78 ~8 ~15 ~78 stone
fill ~152 ~14 ~77 ~152 ~15 ~77 sandstone
fill ~41 ~14 ~77 ~41 ~15 ~77 stone
fill ~76 ~0 ~76 ~76 ~15 ~76 stone
fill ~72 ~10 ~74 ~72 ~15 ~74 stone
fill ~145 ~12 ~64 ~145 ~15 ~64 stone
fill ~140 ~14 ~64 ~140 ~15 ~64 sandstone
fill ~19 ~12 ~64 ~19 ~15 ~64 stone
fill ~14 ~14 ~64 ~14 ~15 ~64 sandstone
fill ~53 ~15 ~60 ~54 ~15 ~60 sandstone
fill ~54 ~12 ~60 ~54 ~15 ~60 sandstone
fill ~103 ~14 ~59 ~103 ~15 ~59 stone
fill ~56 ~14 ~59 ~56 ~15 ~59 end_stone
fill ~55 ~15 ~58 ~55 ~15 ~59 sandstone
fill ~53 ~15 ~59 ~54 ~15 ~59 end_stone
fill ~54 ~13 ~59 ~54 ~15 ~59 end_stone
fill ~102 ~14 ~58 ~102 ~15 ~58 sandstone
fill ~53 ~15 ~58 ~54 ~15 ~58 sandstone
fill ~105 ~13 ~57 ~105 ~15 ~57 sandstone
fill ~104 ~14 ~57 ~104 ~15 ~57 end_stone
fill ~104 ~15 ~56 ~104 ~15 ~57 end_stone
fill ~59 ~14 ~57 ~59 ~15 ~57 stone
fill ~55 ~15 ~57 ~56 ~15 ~57 end_stone
fill ~56 ~14 ~57 ~56 ~15 ~57 end_stone
fill ~56 ~15 ~56 ~56 ~15 ~57 end_stone
fill ~52 ~15 ~56 ~52 ~15 ~57 end_stone
fill ~106 ~14 ~56 ~106 ~15 ~56 sandstone
fill ~103 ~14 ~56 ~103 ~15 ~56 end_stone
fill ~103 ~15 ~54 ~103 ~15 ~56 end_stone
fill ~102 ~15 ~55 ~102 ~15 ~56 sandstone
fill ~101 ~14 ~56 ~101 ~15 ~56 end_stone
fill ~57 ~14 ~56 ~57 ~15 ~56 end_stone
fill ~54 ~15 ~56 ~55 ~15 ~56 sandstone
fill ~55 ~11 ~56 ~55 ~15 ~56 sandstone
fill ~51 ~14 ~56 ~51 ~15 ~56 end_stone
fill ~105 ~15 ~55 ~107 ~15 ~55 end_stone
fill ~107 ~15 ~54 ~107 ~15 ~55 end_stone
fill ~104 ~11 ~55 ~104 ~15 ~55 sandstone
fill ~104 ~15 ~54 ~104 ~15 ~55 sandstone
fill ~81 ~12 ~55 ~81 ~15 ~55 stone
fill ~81 ~15 ~54 ~81 ~15 ~55 stone
fill ~79 ~7 ~55 ~79 ~15 ~55 stone
fill ~79 ~15 ~53 ~79 ~15 ~55 stone
fill ~57 ~13 ~55 ~57 ~15 ~55 sandstone
fill ~55 ~15 ~53 ~55 ~15 ~55 end_stone
fill ~53 ~12 ~55 ~53 ~15 ~55 sandstone
fill ~52 ~15 ~54 ~52 ~15 ~55 stone
fill ~101 ~13 ~54 ~101 ~15 ~54 end_stone
fill ~101 ~15 ~53 ~101 ~15 ~54 end_stone
fill ~100 ~12 ~54 ~100 ~15 ~54 sandstone
fill ~100 ~15 ~53 ~100 ~15 ~54 sandstone
fill ~78 ~12 ~54 ~78 ~15 ~54 stone
fill ~78 ~15 ~53 ~78 ~15 ~54 stone
fill ~56 ~14 ~54 ~56 ~15 ~54 sandstone
fill ~53 ~14 ~54 ~53 ~15 ~54 stone
fill ~53 ~15 ~53 ~53 ~15 ~54 stone
fill ~106 ~15 ~53 ~107 ~15 ~53 stone
fill ~102 ~14 ~53 ~102 ~15 ~53 sandstone
fill ~105 ~15 ~52 ~106 ~15 ~52 stone
fill ~103 ~15 ~52 ~104 ~15 ~52 end_stone
fill ~104 ~14 ~52 ~104 ~15 ~52 end_stone
fill ~104 ~15 ~51 ~104 ~15 ~52 end_stone
fill ~81 ~15 ~39 ~81 ~15 ~48 stone
fill ~79 ~15 ~37 ~79 ~15 ~48 stone
fill ~82 ~15 ~39 ~82 ~15 ~46 stone
fill ~78 ~15 ~39 ~78 ~15 ~46 stone
fill ~83 ~13 ~45 ~83 ~15 ~45 stone
fill ~83 ~15 ~41 ~83 ~15 ~45 stone
fill ~77 ~14 ~44 ~77 ~15 ~44 stone
fill ~77 ~15 ~41 ~77 ~15 ~44 stone
fill ~80 ~3 ~42 ~80 ~15 ~42 stone
fill ~80 ~15 ~37 ~80 ~15 ~42 stone
fill ~82 ~13 ~32 ~82 ~15 ~32 stone
fill ~82 ~15 ~28 ~82 ~15 ~32 stone
fill ~78 ~15 ~28 ~78 ~15 ~32 stone
fill ~64 ~14 ~20 ~64 ~15 ~20 sandstone
fill ~96 ~12 ~19 ~96 ~15 ~19 stone
fill ~64 ~12 ~15 ~64 ~15 ~15 stone
fill ~96 ~14 ~14 ~96 ~15 ~14 sandstone
fill ~82 ~12 ~8 ~82 ~15 ~8 stone
fill ~77 ~14 ~8 ~77 ~15 ~8 sandstone
fill ~80 ~8 ~115 ~80 ~14 ~115 stone
fill ~80 ~14 ~112 ~80 ~14 ~115 stone
fill ~57 ~13 ~109 ~57 ~14 ~109 stone
fill ~57 ~14 ~108 ~57 ~14 ~109 stone
fill ~55 ~14 ~108 ~56 ~14 ~108 end_stone
fill ~106 ~14 ~104 ~106 ~14 ~106 end_stone
fill ~105 ~14 ~105 ~105 ~14 ~106 sandstone
fill ~81 ~10 ~106 ~81 ~14 ~106 stone
fill ~81 ~14 ~100 ~81 ~14 ~106 stone
fill ~60 ~12 ~106 ~60 ~14 ~106 sandstone
fill ~60 ~14 ~105 ~60 ~14 ~106 sandstone
fill ~58 ~14 ~106 ~59 ~14 ~106 end_stone
fill ~59 ~13 ~106 ~59 ~14 ~106 end_stone
fill ~59 ~14 ~105 ~59 ~14 ~106 end_stone
fill ~57 ~14 ~105 ~57 ~14 ~106 sandstone
fill ~54 ~14 ~106 ~56 ~14 ~106 end_stone
fill ~56 ~13 ~106 ~56 ~14 ~106 end_stone
fill ~108 ~14 ~104 ~108 ~14 ~105 end_stone
fill ~82 ~10 ~105 ~82 ~14 ~105 stone
fill ~82 ~14 ~100 ~82 ~14 ~105 stone
fill ~54 ~14 ~105 ~56 ~14 ~105 sandstone
fill ~56 ~11 ~105 ~56 ~14 ~105 sandstone
fill ~79 ~9 ~104 ~79 ~14 ~104 stone
fill ~79 ~14 ~101 ~79 ~14 ~104 stone
fill ~57 ~14 ~104 ~58 ~14 ~104 end_stone
fill ~108 ~14 ~103 ~109 ~14 ~103 stone
fill ~109 ~13 ~103 ~109 ~14 ~103 stone
fill ~105 ~14 ~103 ~106 ~14 ~103 sandstone
fill ~104 ~14 ~102 ~104 ~14 ~103 end_stone
fill ~78 ~9 ~103 ~78 ~14 ~103 stone
fill ~78 ~14 ~101 ~78 ~14 ~103 stone
fill ~59 ~13 ~103 ~59 ~14 ~103 end_stone
fill ~106 ~14 ~101 ~106 ~14 ~102 end_stone
fill ~103 ~13 ~101 ~103 ~14 ~101 end_stone
fill ~83 ~13 ~101 ~83 ~14 ~101 stone
fill ~83 ~14 ~100 ~83 ~14 ~101 stone
fill ~105 ~14 ~100 ~106 ~14 ~100 sandstone
fill ~106 ~12 ~100 ~106 ~14 ~100 sandstone
fill ~77 ~9 ~91 ~77 ~14 ~91 stone
fill ~77 ~14 ~86 ~77 ~14 ~91 stone
fill ~83 ~1 ~89 ~83 ~14 ~89 stone
fill ~83 ~14 ~84 ~83 ~14 ~89 stone
fill ~82 ~0 ~88 ~82 ~14 ~88 stone
fill ~82 ~14 ~84 ~82 ~14 ~88 stone
fill ~79 ~1 ~88 ~79 ~14 ~88 stone
fill ~79 ~14 ~75 ~79 ~14 ~88 stone
fill ~81 ~0 ~87 ~81 ~14 ~87 stone
fill ~81 ~14 ~84 ~81 ~14 ~87 stone
fill ~70 ~11 ~85 ~70 ~14 ~85 stone
fill ~78 ~0 ~80 ~78 ~14 ~80 stone
fill ~78 ~14 ~79 ~78 ~14 ~80 stone
fill ~82 ~0 ~78 ~82 ~14 ~78 stone
fill ~82 ~14 ~73 ~82 ~14 ~78 stone
fill ~81 ~0 ~77 ~81 ~14 ~77 stone
fill ~81 ~14 ~71 ~81 ~14 ~77 stone
fill ~55 ~13 ~60 ~55 ~14 ~60 sandstone
fill ~53 ~13 ~60 ~53 ~14 ~60 sandstone
fill ~53 ~14 ~58 ~53 ~14 ~60 sandstone
fill ~57 ~13 ~59 ~57 ~14 ~59 end_stone
fill ~55 ~14 ~57 ~55 ~14 ~58 sandstone
fill ~101 ~13 ~57 ~101 ~14 ~57 end_stone
fill ~51 ~14 ~57 ~52 ~14 ~57 stone
fill ~52 ~13 ~57 ~52 ~14 ~57 stone
fill ~105 ~14 ~55 ~105 ~14 ~56 sandstone
fill ~54 ~13 ~56 ~54 ~14 ~56 end_stone
fill ~54 ~14 ~54 ~54 ~14 ~56 end_stone
fill ~52 ~14 ~55 ~52 ~14 ~56 end_stone
fill ~102 ~14 ~55 ~103 ~14 ~55 sandstone
fill ~103 ~13 ~55 ~103 ~14 ~55 sandstone
fill ~103 ~14 ~54 ~103 ~14 ~55 sandstone
fill ~100 ~13 ~55 ~100 ~14 ~55 sandstone
fill ~55 ~14 ~55 ~56 ~14 ~55 sandstone
fill ~104 ~14 ~54 ~106 ~14 ~54 end_stone
fill ~79 ~10 ~54 ~79 ~14 ~54 stone
fill ~100 ~14 ~53 ~101 ~14 ~53 sandstone
fill ~103 ~13 ~52 ~103 ~14 ~52 stone
fill ~103 ~14 ~51 ~103 ~14 ~52 stone
fill ~81 ~13 ~46 ~81 ~14 ~46 stone
fill ~81 ~14 ~39 ~81 ~14 ~46 stone
fill ~79 ~13 ~46 ~79 ~14 ~46 stone
fill ~79 ~14 ~38 ~79 ~14 ~46 stone
fill ~82 ~11 ~45 ~82 ~14 ~45 stone
fill ~82 ~14 ~40 ~82 ~14 ~45 stone
fill ~78 ~11 ~45 ~78 ~14 ~45 stone
fill ~78 ~14 ~39 ~78 ~14 ~45 stone
fill ~83 ~13 ~44 ~83 ~14 ~44 stone
fill ~83 ~14 ~41 ~83 ~14 ~44 stone
fill ~77 ~8 ~43 ~77 ~14 ~43 stone
fill ~77 ~14 ~41 ~77 ~14 ~43 stone
fill ~80 ~6 ~41 ~80 ~14 ~41 stone
fill ~80 ~14 ~39 ~80 ~14 ~41 stone
fill ~82 ~10 ~31 ~82 ~14 ~31 stone
fill ~82 ~14 ~28 ~82 ~14 ~31 stone
fill ~78 ~10 ~31 ~78 ~14 ~31 stone
fill ~78 ~14 ~29 ~78 ~14 ~31 stone
fill ~80 ~8 ~128 ~80 ~13 ~128 stone
fill ~80 ~12 ~114 ~80 ~13 ~114 stone
fill ~55 ~13 ~108 ~56 ~13 ~108 sandstone
fill ~58 ~13 ~107 ~59 ~13 ~107 end_stone
fill ~105 ~13 ~105 ~105 ~13 ~106 end_stone
fill ~58 ~12 ~106 ~58 ~13 ~106 sandstone
fill ~55 ~12 ~106 ~55 ~13 ~106 end_stone
fill ~55 ~13 ~104 ~55 ~13 ~106 end_stone
fill ~108 ~13 ~104 ~108 ~13 ~105 sandstone
fill ~106 ~12 ~105 ~106 ~13 ~105 end_stone
fill ~106 ~13 ~103 ~106 ~13 ~105 end_stone
fill ~104 ~12 ~105 ~104 ~13 ~105 end_stone
fill ~81 ~7 ~105 ~81 ~13 ~105 stone
fill ~81 ~13 ~100 ~81 ~13 ~105 stone
fill ~59 ~13 ~105 ~60 ~13 ~105 sandstone
fill ~58 ~11 ~105 ~58 ~13 ~105 end_stone
fill ~57 ~13 ~104 ~57 ~13 ~105 sandstone
fill ~103 ~13 ~104 ~104 ~13 ~104 sandstone
fill ~104 ~11 ~104 ~104 ~13 ~104 sandstone
fill ~104 ~13 ~101 ~104 ~13 ~104 sandstone
fill ~82 ~7 ~104 ~82 ~13 ~104 stone
fill ~82 ~13 ~100 ~82 ~13 ~104 stone
fill ~58 ~13 ~104 ~59 ~13 ~104 sandstone
fill ~56 ~11 ~104 ~56 ~13 ~104 sandstone
fill ~56 ~13 ~103 ~56 ~13 ~104 sandstone
fill ~102 ~13 ~103 ~103 ~13 ~103 end_stone
fill ~103 ~11 ~103 ~103 ~13 ~103 end_stone
fill ~79 ~7 ~103 ~79 ~13 ~103 stone
fill ~79 ~13 ~101 ~79 ~13 ~103 stone
fill ~58 ~12 ~103 ~58 ~13 ~103 sandstone
fill ~57 ~11 ~103 ~57 ~13 ~103 end_stone
fill ~57 ~13 ~102 ~57 ~13 ~103 end_stone
fill ~107 ~13 ~101 ~107 ~13 ~102 end_stone
fill ~106 ~12 ~102 ~106 ~13 ~102 sandstone
fill ~105 ~11 ~102 ~105 ~13 ~102 end_stone
fill ~103 ~12 ~102 ~103 ~13 ~102 sandstone
fill ~78 ~12 ~102 ~78 ~13 ~102 stone
fill ~105 ~12 ~101 ~105 ~13 ~101 sandstone
fill ~105 ~13 ~100 ~105 ~13 ~101 sandstone
fill ~77 ~7 ~90 ~77 ~13 ~90 stone
fill ~77 ~13 ~86 ~77 ~13 ~90 stone
fill ~90 ~13 ~88 ~90 ~13 ~89 stone
fill ~83 ~1 ~88 ~83 ~13 ~88 stone
fill ~83 ~13 ~84 ~83 ~13 ~88 stone
fill ~82 ~0 ~87 ~82 ~13 ~87 stone
fill ~82 ~13 ~84 ~82 ~13 ~87 stone
fill ~79 ~0 ~87 ~79 ~13 ~87 stone
fill ~79 ~13 ~75 ~79 ~13 ~87 stone
fill ~81 ~0 ~86 ~81 ~13 ~86 stone
fill ~81 ~13 ~84 ~81 ~13 ~86 stone
fill ~128 ~8 ~80 ~128 ~13 ~80 stone
fill ~32 ~8 ~80 ~32 ~13 ~80 stone
fill ~78 ~0 ~79 ~78 ~13 ~79 stone
fill ~82 ~0 ~77 ~82 ~13 ~77 stone
fill ~82 ~13 ~73 ~82 ~13 ~77 stone
fill ~81 ~0 ~76 ~81 ~13 ~76 stone
fill ~81 ~13 ~71 ~81 ~13 ~76 stone
fill ~55 ~13 ~59 ~56 ~13 ~59 sandstone
fill ~56 ~13 ~56 ~56 ~13 ~59 sandstone
fill ~53 ~13 ~58 ~53 ~13 ~59 end_stone
fill ~102 ~13 ~58 ~103 ~13 ~58 end_stone
fill ~103 ~13 ~57 ~103 ~13 ~58 end_stone
fill ~58 ~13 ~57 ~58 ~13 ~58 end_stone
fill ~57 ~12 ~58 ~57 ~13 ~58 sandstone
fill ~55 ~11 ~58 ~55 ~13 ~58 end_stone
fill ~54 ~12 ~58 ~54 ~13 ~58 sandstone
fill ~104 ~13 ~56 ~104 ~13 ~57 sandstone
fill ~102 ~12 ~57 ~102 ~13 ~57 sandstone
fill ~102 ~13 ~56 ~102 ~13 ~57 sandstone
fill ~57 ~11 ~57 ~57 ~13 ~57 end_stone
fill ~105 ~12 ~56 ~105 ~13 ~56 end_stone
fill ~105 ~13 ~54 ~105 ~13 ~56 end_stone
fill ~103 ~12 ~56 ~103 ~13 ~56 sandstone
fill ~101 ~13 ~55 ~101 ~13 ~56 sandstone
fill ~52 ~13 ~55 ~52 ~13 ~56 sandstone
fill ~102 ~11 ~55 ~102 ~13 ~55 end_stone
fill ~54 ~13 ~55 ~56 ~13 ~55 end_stone
fill ~56 ~12 ~55 ~56 ~13 ~55 end_stone
fill ~103 ~13 ~54 ~104 ~13 ~54 end_stone
fill ~102 ~12 ~54 ~102 ~13 ~54 sandstone
fill ~101 ~13 ~53 ~102 ~13 ~53 end_stone
fill ~104 ~13 ~52 ~105 ~13 ~52 sandstone
fill ~81 ~11 ~45 ~81 ~13 ~45 stone
fill ~81 ~13 ~40 ~81 ~13 ~45 stone
fill ~79 ~10 ~45 ~79 ~13 ~45 stone
fill ~79 ~13 ~39 ~79 ~13 ~45 stone
fill ~82 ~9 ~44 ~82 ~13 ~44 stone
fill ~82 ~13 ~41 ~82 ~13 ~44 stone
fill ~78 ~9 ~44 ~78 ~13 ~44 stone
fill ~78 ~13 ~40 ~78 ~13 ~44 stone
fill ~83 ~11 ~43 ~83 ~13 ~43 stone
fill ~83 ~13 ~42 ~83 ~13 ~43 stone
fill ~77 ~11 ~42 ~77 ~13 ~42 stone
fill ~77 ~13 ~41 ~77 ~13 ~42 stone
fill ~80 ~11 ~40 ~80 ~13 ~40 stone
fill ~80 ~8 ~32 ~80 ~13 ~32 stone
fill ~82 ~11 ~30 ~82 ~13 ~30 stone
fill ~82 ~13 ~29 ~82 ~13 ~30 stone
fill ~78 ~12 ~30 ~78 ~13 ~30 stone
fill ~78 ~13 ~29 ~78 ~13 ~30 stone
fill ~57 ~11 ~108 ~57 ~12 ~108 sandstone
fill ~58 ~12 ~107 ~59 ~12 ~107 stone
fill ~59 ~11 ~107 ~59 ~12 ~107 stone
fill ~59 ~12 ~105 ~59 ~12 ~106 sandstone
fill ~56 ~12 ~106 ~57 ~12 ~106 sandstone
fill ~57 ~10 ~106 ~57 ~12 ~106 sandstone
fill ~57 ~6 ~105 ~57 ~12 ~105 end_stone
fill ~106 ~12 ~103 ~106 ~12 ~104 sandstone
fill ~81 ~6 ~104 ~81 ~12 ~104 stone
fill ~81 ~12 ~101 ~81 ~12 ~104 stone
fill ~57 ~12 ~104 ~58 ~12 ~104 sandstone
fill ~108 ~11 ~103 ~108 ~12 ~103 sandstone
fill ~105 ~6 ~103 ~105 ~12 ~103 end_stone
fill ~104 ~12 ~102 ~104 ~12 ~103 sandstone
fill ~102 ~11 ~103 ~102 ~12 ~103 sandstone
fill ~82 ~5 ~103 ~82 ~12 ~103 stone
fill ~82 ~12 ~101 ~82 ~12 ~103 stone
fill ~107 ~12 ~101 ~107 ~12 ~102 stone
fill ~79 ~9 ~102 ~79 ~12 ~102 stone
fill ~79 ~12 ~101 ~79 ~12 ~102 stone
fill ~57 ~11 ~102 ~57 ~12 ~102 sandstone
fill ~77 ~5 ~89 ~77 ~12 ~89 stone
fill ~77 ~12 ~86 ~77 ~12 ~89 stone
fill ~83 ~1 ~87 ~83 ~12 ~87 stone
fill ~83 ~12 ~84 ~83 ~12 ~87 stone
fill ~82 ~0 ~86 ~82 ~12 ~86 stone
fill ~82 ~12 ~84 ~82 ~12 ~86 stone
fill ~79 ~0 ~86 ~79 ~12 ~86 stone
fill ~79 ~12 ~75 ~79 ~12 ~86 stone
fill ~81 ~0 ~85 ~81 ~12 ~85 stone
fill ~81 ~12 ~84 ~81 ~12 ~85 stone
fill ~89 ~3 ~79 ~89 ~12 ~79 stone
fill ~92 ~12 ~76 ~92 ~12 ~78 stone
fill ~82 ~0 ~76 ~82 ~12 ~76 stone
fill ~82 ~12 ~73 ~82 ~12 ~76 stone
fill ~81 ~0 ~75 ~81 ~12 ~75 stone
fill ~81 ~12 ~71 ~81 ~12 ~75 stone
fill ~54 ~12 ~59 ~55 ~12 ~59 sandstone
fill ~53 ~11 ~59 ~53 ~12 ~59 stone
fill ~53 ~12 ~58 ~53 ~12 ~59 stone
fill ~103 ~11 ~58 ~103 ~12 ~58 sandstone
fill ~56 ~12 ~56 ~56 ~12 ~58 sandstone
fill ~103 ~12 ~57 ~104 ~12 ~57 end_stone
fill ~58 ~11 ~57 ~58 ~12 ~57 sandstone
fill ~55 ~6 ~57 ~55 ~12 ~57 end_stone
fill ~54 ~10 ~57 ~54 ~12 ~57 sandstone
fill ~54 ~12 ~56 ~54 ~12 ~57 sandstone
fill ~52 ~11 ~57 ~52 ~12 ~57 sandstone
fill ~104 ~11 ~56 ~104 ~12 ~56 sandstone
fill ~103 ~6 ~55 ~103 ~12 ~55 end_stone
fill ~101 ~12 ~54 ~101 ~12 ~55 sandstone
fill ~54 ~12 ~54 ~54 ~12 ~55 end_stone
fill ~105 ~12 ~54 ~106 ~12 ~54 end_stone
fill ~103 ~12 ~54 ~104 ~12 ~54 sandstone
fill ~101 ~12 ~53 ~102 ~12 ~53 stone
fill ~103 ~11 ~52 ~103 ~12 ~52 sandstone
fill ~81 ~8 ~44 ~81 ~12 ~44 stone
fill ~81 ~12 ~40 ~81 ~12 ~44 stone
fill ~79 ~6 ~44 ~79 ~12 ~44 stone
fill ~79 ~12 ~40 ~79 ~12 ~44 stone
fill ~82 ~7 ~43 ~82 ~12 ~43 stone
fill ~82 ~12 ~41 ~82 ~12 ~43 stone
fill ~78 ~4 ~43 ~78 ~12 ~43 stone
fill ~78 ~12 ~40 ~78 ~12 ~43 stone
fill ~58 ~11 ~106 ~58 ~11 ~107 end_stone
fill ~57 ~10 ~107 ~57 ~11 ~107 sandstone
fill ~55 ~10 ~107 ~55 ~11 ~107 end_stone
fill ~106 ~11 ~105 ~106 ~11 ~106 sandstone
fill ~59 ~11 ~106 ~60 ~11 ~106 stone
fill ~54 ~11 ~106 ~55 ~11 ~106 sandstone
fill ~107 ~10 ~105 ~107 ~11 ~105 end_stone
fill ~59 ~10 ~104 ~59 ~11 ~104 sandstone
fill ~57 ~11 ~104 ~58 ~11 ~104 end_stone
fill ~58 ~10 ~104 ~58 ~11 ~104 end_stone
fill ~58 ~11 ~103 ~58 ~11 ~104 end_stone
fill ~106 ~11 ~103 ~107 ~11 ~103 sandstone
fill ~107 ~10 ~103 ~107 ~11 ~103 sandstone
fill ~104 ~11 ~102 ~104 ~11 ~103 end_stone
fill ~81 ~1 ~103 ~81 ~11 ~103 stone
fill ~81 ~11 ~101 ~81 ~11 ~103 stone
fill ~106 ~11 ~102 ~107 ~11 ~102 end_stone
fill ~103 ~10 ~102 ~103 ~11 ~102 end_stone
fill ~82 ~5 ~102 ~82 ~11 ~102 stone
fill ~82 ~11 ~101 ~82 ~11 ~102 stone
fill ~106 ~11 ~101 ~107 ~11 ~101 stone
fill ~104 ~10 ~101 ~104 ~11 ~101 sandstone
fill ~77 ~3 ~88 ~77 ~11 ~88 stone
fill ~77 ~11 ~86 ~77 ~11 ~88 stone
fill ~83 ~0 ~86 ~83 ~11 ~86 stone
fill ~83 ~11 ~84 ~83 ~11 ~86 stone
fill ~82 ~0 ~85 ~82 ~11 ~85 stone
fill ~82 ~11 ~84 ~82 ~11 ~85 stone
fill ~79 ~0 ~85 ~79 ~11 ~85 stone
fill ~79 ~11 ~75 ~79 ~11 ~85 stone
fill ~92 ~8 ~84 ~92 ~11 ~84 stone
fill ~81 ~0 ~84 ~81 ~11 ~84 stone
fill ~92 ~8 ~82 ~92 ~11 ~82 stone
fill ~82 ~0 ~75 ~82 ~11 ~75 stone
fill ~82 ~11 ~73 ~82 ~11 ~75 stone
fill ~81 ~0 ~74 ~81 ~11 ~74 stone
fill ~81 ~11 ~71 ~81 ~11 ~74 stone
fill ~54 ~11 ~59 ~54 ~11 ~60 stone
fill ~56 ~10 ~59 ~56 ~11 ~59 sandstone
fill ~56 ~11 ~58 ~57 ~11 ~58 end_stone
fill ~57 ~10 ~58 ~57 ~11 ~58 end_stone
fill ~53 ~11 ~58 ~54 ~11 ~58 end_stone
fill ~102 ~11 ~57 ~103 ~11 ~57 end_stone
fill ~103 ~11 ~56 ~103 ~11 ~57 end_stone
fill ~53 ~10 ~57 ~53 ~11 ~57 sandstone
fill ~102 ~10 ~56 ~102 ~11 ~56 end_stone
fill ~101 ~10 ~56 ~101 ~11 ~56 sandstone
fill ~56 ~11 ~56 ~57 ~11 ~56 sandstone
fill ~54 ~11 ~54 ~54 ~11 ~55 sandstone
fill ~53 ~10 ~55 ~53 ~11 ~55 end_stone
fill ~105 ~11 ~54 ~106 ~11 ~54 sandstone
fill ~103 ~10 ~54 ~103 ~11 ~54 sandstone
fill ~103 ~11 ~53 ~103 ~11 ~54 sandstone
fill ~102 ~11 ~53 ~102 ~11 ~54 end_stone
fill ~100 ~11 ~54 ~101 ~11 ~54 stone
fill ~101 ~10 ~54 ~101 ~11 ~54 stone
fill ~101 ~11 ~53 ~101 ~11 ~54 stone
fill ~105 ~10 ~53 ~105 ~11 ~53 end_stone
fill ~81 ~4 ~43 ~81 ~11 ~43 stone
fill ~81 ~11 ~41 ~81 ~11 ~43 stone
fill ~79 ~0 ~43 ~79 ~11 ~43 stone
fill ~79 ~11 ~40 ~79 ~11 ~43 stone
fill ~78 ~6 ~42 ~78 ~11 ~42 stone
fill ~78 ~11 ~41 ~78 ~11 ~42 stone
fill ~58 ~9 ~106 ~58 ~10 ~106 sandstone
fill ~58 ~10 ~105 ~58 ~10 ~106 sandstone
fill ~56 ~10 ~103 ~56 ~10 ~105 end_stone
fill ~106 ~10 ~102 ~106 ~10 ~104 sandstone
fill ~103 ~10 ~104 ~105 ~10 ~104 end_stone
fill ~57 ~9 ~104 ~57 ~10 ~104 sandstone
fill ~57 ~10 ~103 ~57 ~10 ~104 sandstone
fill ~103 ~10 ~103 ~104 ~10 ~103 sandstone
fill ~104 ~9 ~103 ~104 ~10 ~103 sandstone
fill ~105 ~7 ~102 ~105 ~10 ~102 sandstone
fill ~105 ~10 ~101 ~105 ~10 ~102 sandstone
fill ~81 ~4 ~102 ~81 ~10 ~102 stone
fill ~81 ~10 ~101 ~81 ~10 ~102 stone
fill ~82 ~8 ~101 ~82 ~10 ~101 stone
fill ~77 ~2 ~87 ~77 ~10 ~87 stone
fill ~77 ~10 ~86 ~77 ~10 ~87 stone
fill ~83 ~0 ~85 ~83 ~10 ~85 stone
fill ~83 ~10 ~84 ~83 ~10 ~85 stone
fill ~82 ~0 ~84 ~82 ~10 ~84 stone
fill ~79 ~0 ~84 ~79 ~10 ~84 stone
fill ~79 ~10 ~75 ~79 ~10 ~84 stone
fill ~92 ~8 ~81 ~92 ~10 ~81 stone
fill ~82 ~0 ~74 ~82 ~10 ~74 stone
fill ~82 ~10 ~73 ~82 ~10 ~74 stone
fill ~81 ~0 ~73 ~81 ~10 ~73 stone
fill ~81 ~10 ~71 ~81 ~10 ~73 stone
fill ~55 ~10 ~58 ~55 ~10 ~59 sandstone
fill ~54 ~9 ~58 ~54 ~10 ~58 sandstone
fill ~104 ~9 ~57 ~104 ~10 ~57 end_stone
fill ~104 ~10 ~55 ~104 ~10 ~57 end_stone
fill ~103 ~10 ~56 ~103 ~10 ~57 sandstone
fill ~56 ~10 ~57 ~57 ~10 ~57 sandstone
fill ~55 ~10 ~56 ~57 ~10 ~56 end_stone
fill ~57 ~9 ~56 ~57 ~10 ~56 end_stone
fill ~101 ~10 ~55 ~102 ~10 ~55 sandstone
fill ~102 ~7 ~55 ~102 ~10 ~55 sandstone
fill ~102 ~10 ~54 ~102 ~10 ~55 sandstone
fill ~81 ~6 ~42 ~81 ~10 ~42 stone
fill ~79 ~4 ~42 ~79 ~10 ~42 stone
fill ~79 ~10 ~41 ~79 ~10 ~42 stone
fill ~57 ~8 ~107 ~57 ~9 ~107 end_stone
fill ~57 ~9 ~106 ~57 ~9 ~107 end_stone
fill ~105 ~7 ~105 ~105 ~9 ~105 end_stone
fill ~58 ~7 ~105 ~58 ~9 ~105 sandstone
fill ~58 ~9 ~103 ~58 ~9 ~105 sandstone
fill ~56 ~8 ~105 ~56 ~9 ~105 sandstone
fill ~55 ~7 ~105 ~55 ~9 ~105 end_stone
fill ~106 ~9 ~103 ~106 ~9 ~104 end_stone
fill ~105 ~8 ~104 ~105 ~9 ~104 sandstone
fill ~103 ~9 ~104 ~104 ~9 ~104 end_stone
fill ~104 ~7 ~104 ~104 ~9 ~104 end_stone
fill ~56 ~7 ~104 ~56 ~9 ~104 end_stone
fill ~56 ~9 ~103 ~56 ~9 ~104 end_stone
fill ~107 ~8 ~103 ~107 ~9 ~103 end_stone
fill ~103 ~7 ~103 ~103 ~9 ~103 end_stone
fill ~57 ~7 ~103 ~57 ~9 ~103 end_stone
fill ~103 ~9 ~102 ~104 ~9 ~102 sandstone
fill ~104 ~6 ~102 ~104 ~9 ~102 sandstone
fill ~81 ~7 ~101 ~81 ~9 ~101 stone
fill ~77 ~0 ~86 ~77 ~9 ~86 stone
fill ~83 ~0 ~84 ~83 ~9 ~84 stone
fill ~79 ~0 ~83 ~79 ~9 ~83 stone
fill ~79 ~9 ~75 ~79 ~9 ~83 stone
fill ~82 ~0 ~73 ~82 ~9 ~73 stone
fill ~81 ~0 ~72 ~81 ~9 ~72 stone
fill ~81 ~9 ~71 ~81 ~9 ~72 stone
fill ~55 ~9 ~58 ~57 ~9 ~58 sandstone
fill ~103 ~7 ~57 ~103 ~9 ~57 end_stone
fill ~102 ~9 ~56 ~102 ~9 ~57 sandstone
fill ~57 ~7 ~57 ~57 ~9 ~57 end_stone
fill ~53 ~9 ~57 ~54 ~9 ~57 end_stone
fill ~54 ~7 ~57 ~54 ~9 ~57 end_stone
fill ~54 ~9 ~56 ~54 ~9 ~57 end_stone
fill ~104 ~7 ~56 ~104 ~9 ~56 end_stone
fill ~56 ~7 ~56 ~56 ~9 ~56 end_stone
fill ~55 ~8 ~56 ~55 ~9 ~56 sandstone
fill ~105 ~7 ~55 ~105 ~9 ~55 end_stone
fill ~104 ~8 ~55 ~104 ~9 ~55 sandstone
fill ~55 ~7 ~55 ~55 ~9 ~55 end_stone
fill ~103 ~9 ~54 ~104 ~9 ~54 end_stone
fill ~103 ~8 ~53 ~103 ~9 ~53 end_stone
fill ~78 ~9 ~41 ~79 ~9 ~41 stone
fill ~79 ~6 ~41 ~79 ~9 ~41 stone
fill ~57 ~8 ~106 ~58 ~8 ~106 end_stone
fill ~58 ~6 ~106 ~58 ~8 ~106 end_stone
fill ~58 ~6 ~104 ~58 ~8 ~104 sandstone
fill ~57 ~4 ~104 ~57 ~8 ~104 end_stone
fill ~106 ~7 ~103 ~106 ~8 ~103 end_stone
fill ~106 ~8 ~102 ~106 ~8 ~103 end_stone
fill ~104 ~4 ~103 ~104 ~8 ~103 end_stone
fill ~81 ~6 ~91 ~81 ~8 ~91 stone
fill ~79 ~0 ~82 ~79 ~8 ~82 stone
fill ~79 ~8 ~75 ~79 ~8 ~82 stone
fill ~81 ~0 ~71 ~81 ~8 ~71 stone
fill ~55 ~8 ~58 ~56 ~8 ~58 sandstone
fill ~56 ~6 ~58 ~56 ~8 ~58 sandstone
fill ~54 ~6 ~58 ~54 ~8 ~58 end_stone
fill ~56 ~4 ~57 ~56 ~8 ~57 end_stone
fill ~103 ~4 ~56 ~103 ~8 ~56 end_stone
fill ~102 ~6 ~56 ~102 ~8 ~56 sandstone
fill ~102 ~8 ~54 ~103 ~8 ~54 end_stone
fill ~103 ~7 ~54 ~103 ~8 ~54 end_stone
fill ~106 ~6 ~102 ~106 ~7 ~102 end_stone
fill ~79 ~0 ~81 ~79 ~7 ~81 stone
fill ~79 ~7 ~75 ~79 ~7 ~81 stone
fill ~79 ~5 ~70 ~79 ~7 ~70 stone
fill ~102 ~6 ~54 ~102 ~7 ~54 end_stone
fill ~56 ~5 ~105 ~56 ~6 ~105 sandstone
fill ~56 ~6 ~104 ~56 ~6 ~105 sandstone
fill ~104 ~6 ~104 ~105 ~6 ~104 sandstone
fill ~105 ~5 ~104 ~105 ~6 ~104 sandstone
fill ~79 ~0 ~80 ~79 ~6 ~80 stone
fill ~79 ~6 ~75 ~79 ~6 ~80 stone
fill ~82 ~4 ~70 ~82 ~6 ~70 stone
fill ~104 ~6 ~55 ~104 ~6 ~56 sandstone
fill ~55 ~6 ~56 ~56 ~6 ~56 sandstone
fill ~57 ~5 ~105 ~58 ~5 ~105 sandstone
fill ~105 ~3 ~103 ~105 ~5 ~103 sandstone
fill ~105 ~5 ~102 ~105 ~5 ~103 sandstone
fill ~79 ~0 ~79 ~79 ~5 ~79 stone
fill ~79 ~5 ~75 ~79 ~5 ~79 stone
fill ~55 ~5 ~56 ~55 ~5 ~58 sandstone
fill ~102 ~5 ~55 ~104 ~5 ~55 sandstone
fill ~57 ~3 ~105 ~57 ~4 ~105 sandstone
fill ~81 ~2 ~90 ~81 ~4 ~90 stone
fill ~79 ~3 ~90 ~79 ~4 ~90 stone
fill ~79 ~0 ~78 ~79 ~4 ~78 stone
fill ~79 ~4 ~75 ~79 ~4 ~78 stone
fill ~55 ~3 ~57 ~55 ~4 ~57 sandstone
fill ~103 ~3 ~55 ~103 ~4 ~55 sandstone
fill ~79 ~0 ~77 ~79 ~3 ~77 stone
fill ~79 ~3 ~75 ~79 ~3 ~77 stone
fill ~57 ~1 ~105 ~57 ~2 ~105 stone
fill ~105 ~1 ~103 ~105 ~2 ~103 stone
fill ~79 ~0 ~76 ~79 ~2 ~76 stone
fill ~79 ~2 ~75 ~79 ~2 ~76 stone
fill ~55 ~1 ~57 ~55 ~2 ~57 stone
fill ~103 ~1 ~55 ~103 ~2 ~55 stone
fill ~79 ~0 ~75 ~79 ~1 ~75 stone
setblock ~93 ~20 ~16 torch 4
setblock ~142 ~20 ~67 torch 2
setblock ~143 ~20 ~93 torch 4
setblock ~93 ~20 ~142 torch 4
setblock ~98 ~21 ~18 sand
setblock ~144 ~21 ~62 sand
setblock ~142 ~21 ~98 sand
setblock ~98 ~21 ~144 sand
setblock ~83 ~22 ~7 sand
setblock ~80 ~22 ~11 sand
setblock ~66 ~22 ~15 sand
setblock ~94 ~22 ~19 sand
setblock ~20 ~22 ~63 sand
setblock ~19 ~22 ~66 sand
setblock ~17 ~22 ~67 sand
setblock ~7 ~22 ~77 sand
setblock ~11 ~22 ~80 sand
setblock ~150 ~22 ~82 sand
setblock ~17 ~22 ~93 sand
setblock ~15 ~22 ~94 sand
setblock ~14 ~22 ~97 sand
setblock ~63 ~22 ~140 sand
setblock ~67 ~22 ~143 sand
setblock ~97 ~22 ~146 sand
setblock ~78 ~22 ~150 sand
setblock ~81 ~23 ~5 sand
setblock ~96 ~23 ~13 sand
setblock ~145 ~23 ~61 sand
setblock ~13 ~23 ~64 sand
setblock ~5 ~23 ~79 sand
setblock ~6 ~23 ~82 sand
setblock ~146 ~23 ~97 sand
setblock ~99 ~23 ~145 sand
setblock ~82 ~23 ~154 sand
setblock ~77 ~25 ~4 torch 4
setblock ~60 ~25 ~13 torch 2
setblock ~14 ~25 ~60 torch 4
setblock ~140 ~25 ~60 torch 4
setblock ~4 ~25 ~76 torch 2
setblock ~4 ~25 ~83 torch 2
setblock ~140 ~25 ~100 torch 3
setblock ~60 ~25 ~139 torch 2
setblock ~77 ~25 ~156 torch 3
setblock ~58 ~26 ~50 sand
setblock ~104 ~26 ~51 sand
setblock ~100 ~26 ~54 sand
setblock ~98 ~26 ~55 sand
setblock ~96 ~26 ~57 sand
setblock ~109 ~26 ~57 sand
setblock ~110 ~26 ~58 sand
setblock ~54 ~26 ~60 sand
setblock ~56 ~26 ~61 sand
setblock ~57 ~26 ~62 sand
setblock ~57 ~26 ~64 sand
setblock ~102 ~26 ~97 sand
setblock ~103 ~26 ~98 sand
setblock ~13 ~26 ~100 torch 3
setblock ~100 ~26 ~100 sand
setblock ~108 ~26 ~101 sand
setblock ~63 ~26 ~102 sand
setblock ~62 ~26 ~103 sand
setblock ~61 ~26 ~104 sand
setblock ~60 ~26 ~106 sand
setblock ~103 ~26 ~109 sand
setblock ~100 ~28 ~52 torch 4
setblock ~80 ~28 ~71 rail 4
setblock ~89 ~28 ~80 rail 2
setblock ~69 ~28 ~91 torch 4
setblock ~102 ~28 ~108 torch 2
setblock ~75 ~29 ~83 torch 3
setblock ~85 ~31 ~84 torch 2
setblock ~53 ~36 ~55 torch 4
setblock ~104 ~37 ~102 torch 2
setblock ~57 ~43 ~105 torch 2
fill ~80 ~29 ~90 ~80 ~29 ~102 rail 0
fill ~58 ~29 ~80 ~70 ~29 ~80 rail 1
fill ~80 ~29 ~53 ~80 ~29 ~55 rail 0
fill ~83 ~28 ~80 ~88 ~28 ~80 rail 1
fill ~54 ~26 ~109 ~56 ~26 ~109 sand
fill ~52 ~26 ~107 ~53 ~26 ~107 sand
fill ~62 ~26 ~105 ~63 ~26 ~105 sand
fill ~105 ~26 ~97 ~105 ~26 ~98 sand
fill ~108 ~26 ~55 ~108 ~26 ~56 sand
fill ~51 ~26 ~54 ~51 ~26 ~56 sand
fill ~53 ~26 ~52 ~53 ~26 ~53 sand
fill ~55 ~26 ~52 ~56 ~26 ~52 sand
fill ~98 ~22 ~143 ~98 ~23 ~143 sand
fill ~154 ~22 ~82 ~154 ~23 ~82 sand
fill ~143 ~22 ~62 ~143 ~23 ~62 sand
fill ~82 ~22 ~6 ~82 ~23 ~6 sand
fill ~98 ~22 ~144 ~98 ~22 ~145 sand
fill ~141 ~22 ~98 ~143 ~22 ~98 sand
fill ~154 ~21 ~81 ~154 ~22 ~81 sand
fill ~144 ~22 ~62 ~145 ~22 ~62 sand
fill ~98 ~22 ~17 ~98 ~22 ~19 sand
fill ~80 ~22 ~6 ~81 ~22 ~6 sand
setblock ~16 ~20 ~67 torch 2
setblock ~19 ~20 ~94 torch 1
setblock ~18 ~21 ~62 sand
setblock ~62 ~21 ~142 sand
setblock ~82 ~22 ~10 sand
setblock ~67 ~22 ~17 sand
setblock ~146 ~22 ~63 sand
setblock ~143 ~22 ~67 sand
setblock ~149 ~22 ~80 sand
setblock ~143 ~22 ~93 sand
setblock ~140 ~22 ~97 sand
setblock ~94 ~22 ~145 sand
setblock ~77 ~22 ~153 sand
setblock ~97 ~23 ~14 sand
setblock ~154 ~23 ~78 sand
setblock ~147 ~23 ~96 sand
setblock ~64 ~23 ~147 sand
setblock ~84 ~25 ~4 torch 4
setblock ~21 ~25 ~60 torch 4
setblock ~156 ~25 ~77 torch 1
setblock ~146 ~25 ~100 torch 3
setblock ~83 ~25 ~156 torch 3
setblock ~101 ~26 ~52 sand
setblock ~99 ~26 ~56 sand
setblock ~97 ~26 ~58 sand
setblock ~100 ~26 ~60 sand
setblock ~58 ~26 ~63 sand
setblock ~104 ~26 ~97 sand
setblock ~60 ~26 ~100 sand
setblock ~50 ~26 ~102 sand
setblock ~64 ~26 ~103 sand
setblock ~55 ~26 ~108 sand
setblock ~52 ~28 ~60 torch 2
setblock ~80 ~28 ~89 rail 5
setblock ~84 ~29 ~74 torch 3
setblock ~76 ~31 ~85 torch 4
setblock ~105 ~43 ~55 torch 2
fill ~105 ~29 ~80 ~107 ~29 ~80 rail 1
fill ~80 ~28 ~83 ~80 ~28 ~87 rail 0
fill ~107 ~26 ~107 ~107 ~26 ~108 sand
fill ~52 ~26 ~104 ~52 ~26 ~105 sand
fill ~97 ~26 ~55 ~97 ~26 ~56 sand
fill ~105 ~26 ~51 ~105 ~26 ~52 sand
fill ~17 ~22 ~98 ~17 ~23 ~98 sand
fill ~62 ~22 ~17 ~62 ~23 ~17 sand
fill ~62 ~22 ~141 ~62 ~22 ~143 sand
fill ~6 ~22 ~79 ~6 ~22 ~80 sand
fill ~62 ~21 ~16 ~62 ~22 ~16 sand
setblock ~149 ~20 ~79 torch 4
setblock ~6 ~21 ~79 sand
setblock ~63 ~22 ~14 sand
setblock ~145 ~22 ~66 sand
setblock ~153 ~22 ~83 sand
setblock ~66 ~22 ~141 sand
setblock ~78 ~23 ~6 sand
setblock ~155 ~23 ~81 sand
setblock ~79 ~23 ~155 sand
setblock ~147 ~25 ~60 torch 4
setblock ~60 ~25 ~146 torch 2
setblock ~52 ~26 ~55 sand
setblock ~52 ~26 ~59 sand
setblock ~103 ~26 ~96 sand
setblock ~106 ~26 ~100 sand
setblock ~108 ~26 ~105 sand
setblock ~71 ~28 ~80 rail 3
setblock ~76 ~30 ~74 torch 3
fill ~80 ~29 ~105 ~80 ~29 ~107 rail 0
fill ~80 ~28 ~72 ~80 ~28 ~77 rail 0
fill ~55 ~26 ~63 ~56 ~26 ~63 sand
fill ~78 ~22 ~154 ~78 ~23 ~154 sand
fill ~79 ~22 ~154 ~80 ~22 ~154 sand
fill ~17 ~22 ~62 ~19 ~22 ~62 sand
setblock ~82 ~20 ~150 torch 4
setblock ~97 ~22 ~20 sand
setblock ~141 ~22 ~94 sand
setblock ~14 ~23 ~63 sand
setblock ~60 ~25 ~20 torch 2
setblock ~57 ~26 ~51 sand
setblock ~55 ~26 ~62 sand
setblock ~51 ~26 ~103 sand
setblock ~108 ~28 ~100 torch 1
fill ~80 ~29 ~58 ~80 ~29 ~70 rail 0
fill ~107 ~26 ~53 ~108 ~26 ~53 sand
fill ~15 ~22 ~98 ~16 ~22 ~98 sand
setblock ~79 ~21 ~154 sand
setblock ~80 ~22 ~149 sand
setblock ~20 ~25 ~100 torch 3
setblock ~104 ~26 ~99 sand
setblock ~55 ~36 ~107 torch 2
fill ~6 ~22 ~78 ~6 ~23 ~78 sand
setblock ~10 ~22 ~78 sand
setblock ~98 ~26 ~57 sand
fill ~109 ~26 ~104 ~109 ~26 ~106 sand
setblock ~15 ~23 ~99 sand
setblock ~79 ~20 ~11 torch 2
setblock ~102 ~26 ~110 sand
