fill ~33 ~28 ~82 ~33 ~30 ~82 wood
fill ~126 ~28 ~80 ~126 ~30 ~80 wood
fill ~34 ~28 ~80 ~34 ~30 ~80 wood
fill ~127 ~28 ~78 ~127 ~30 ~78 wood
fill ~33 ~28 ~78 ~33 ~30 ~78 wood
fill ~96 ~29 ~77 ~96 ~30 ~77 stone 6
fill ~94 ~28 ~77 ~94 ~30 ~77 stone 3
fill ~90 ~30 ~75 ~90 ~30 ~77 stone
fill ~84 ~28 ~77 ~84 ~30 ~77 wood
fill ~66 ~28 ~77 ~66 ~30 ~77 stone 3
fill ~66 ~30 ~75 ~66 ~30 ~77 stone 3
fill ~85 ~28 ~76 ~85 ~30 ~76 wood
fill ~77 ~28 ~76 ~77 ~30 ~76 wood
fill ~75 ~28 ~76 ~75 ~30 ~76 wood
fill ~65 ~27 ~76 ~65 ~30 ~76 stone 3
fill ~113 ~28 ~75 ~113 ~30 ~75 stone 6
fill ~94 ~28 ~75 ~94 ~30 ~75 stone 3
fill ~84 ~28 ~75 ~84 ~30 ~75 wood
fill ~76 ~28 ~75 ~76 ~30 ~75 wood
fill ~55 ~28 ~75 ~55 ~30 ~75 stone 6
fill ~156 ~29 ~74 ~156 ~30 ~74 fence 0
fill ~156 ~30 ~73 ~156 ~30 ~74 fence 0
fill ~91 ~14 ~74 ~91 ~30 ~74 stone
fill ~71 ~28 ~74 ~71 ~30 ~74 stone 3
fill ~4 ~29 ~74 ~4 ~30 ~74 fence 0
fill ~4 ~30 ~73 ~4 ~30 ~74 fence 0
fill ~157 ~29 ~73 ~157 ~30 ~73 fence 0
fill ~92 ~15 ~73 ~92 ~30 ~73 stone
fill ~90 ~13 ~73 ~90 ~30 ~73 stone
fill ~90 ~30 ~72 ~90 ~30 ~73 stone
fill ~88 ~11 ~73 ~88 ~30 ~73 stone
fill ~72 ~29 ~73 ~72 ~30 ~73 stone 3
fill ~3 ~29 ~73 ~3 ~30 ~73 fence 0
fill ~91 ~15 ~72 ~91 ~30 ~72 stone
fill ~87 ~29 ~72 ~87 ~30 ~72 stone 3
fill ~86 ~28 ~71 ~86 ~30 ~71 stone 3
fill ~73 ~30 ~71 ~74 ~30 ~71 stone
fill ~74 ~11 ~71 ~74 ~30 ~71 stone
fill ~75 ~30 ~70 ~77 ~30 ~70 stone
fill ~72 ~30 ~70 ~73 ~30 ~70 stone
fill ~73 ~14 ~70 ~73 ~30 ~70 stone
fill ~73 ~30 ~68 ~73 ~30 ~70 stone
fill ~74 ~13 ~69 ~74 ~30 ~69 stone
fill ~72 ~18 ~69 ~72 ~30 ~69 stone
fill ~85 ~26 ~66 ~85 ~30 ~66 stone 3
fill ~82 ~29 ~66 ~82 ~30 ~66 stone 3
fill ~77 ~28 ~66 ~77 ~30 ~66 stone 3
fill ~75 ~28 ~66 ~75 ~30 ~66 stone 3
fill ~83 ~30 ~65 ~84 ~30 ~65 stone 3
fill ~84 ~27 ~65 ~84 ~30 ~65 stone 3
fill ~75 ~30 ~65 ~76 ~30 ~65 stone 6
fill ~77 ~29 ~64 ~77 ~30 ~64 stone 6
fill ~76 ~30 ~63 ~77 ~30 ~63 gold_ore
fill ~149 ~30 ~60 ~150 ~30 ~60 fence 0
fill ~150 ~30 ~59 ~150 ~30 ~60 fence 0
fill ~136 ~30 ~60 ~137 ~30 ~60 fence 0
fill ~137 ~29 ~60 ~137 ~30 ~60 fence 0
fill ~59 ~26 ~60 ~59 ~30 ~60 log 0
fill ~51 ~26 ~60 ~51 ~30 ~60 log 0
fill ~23 ~30 ~60 ~24 ~30 ~60 fence 0
fill ~24 ~30 ~59 ~24 ~30 ~60 fence 0
fill ~10 ~30 ~60 ~11 ~30 ~60 fence 0
fill ~11 ~29 ~60 ~11 ~30 ~60 fence 0
fill ~136 ~29 ~59 ~136 ~30 ~59 fence 0
fill ~108 ~26 ~59 ~108 ~30 ~59 log 0
fill ~100 ~26 ~59 ~100 ~30 ~59 log 0
fill ~10 ~29 ~59 ~10 ~30 ~59 fence 0
fill ~85 ~28 ~55 ~85 ~30 ~55 stone 6
fill ~59 ~26 ~52 ~59 ~30 ~52 log 0
fill ~51 ~26 ~52 ~51 ~30 ~52 log 0
fill ~108 ~26 ~51 ~108 ~30 ~51 log 0
fill ~100 ~26 ~51 ~100 ~30 ~51 log 0
fill ~75 ~28 ~47 ~75 ~30 ~47 stone 6
fill ~80 ~28 ~34 ~80 ~30 ~34 wood
fill ~82 ~28 ~33 ~82 ~30 ~33 wood
fill ~78 ~28 ~33 ~78 ~30 ~33 wood
fill ~100 ~30 ~24 ~101 ~30 ~24 fence 0
fill ~101 ~29 ~24 ~101 ~30 ~24 fence 0
fill ~59 ~30 ~24 ~60 ~30 ~24 fence 0
fill ~60 ~30 ~23 ~60 ~30 ~24 fence 0
fill ~100 ~29 ~23 ~100 ~30 ~23 fence 0
fill ~100 ~29 ~11 ~100 ~30 ~11 fence 0
fill ~100 ~30 ~10 ~100 ~30 ~11 fence 0
fill ~60 ~29 ~11 ~60 ~30 ~11 fence 0
fill ~60 ~30 ~10 ~60 ~30 ~11 fence 0
fill ~101 ~29 ~10 ~101 ~30 ~10 fence 0
fill ~59 ~29 ~10 ~59 ~30 ~10 fence 0
fill ~86 ~30 ~4 ~87 ~30 ~4 fence 0
fill ~87 ~30 ~3 ~87 ~30 ~4 fence 0
fill ~73 ~30 ~4 ~74 ~30 ~4 fence 0
fill ~74 ~29 ~4 ~74 ~30 ~4 fence 0
fill ~73 ~29 ~3 ~73 ~30 ~3 fence 0
fill ~79 ~29 ~160 ~81 ~29 ~160 double_wooden_slab 2
fill ~81 ~29 ~159 ~81 ~29 ~160 double_wooden_slab 2
fill ~82 ~27 ~159 ~82 ~29 ~159 fence 0
fill ~78 ~27 ~159 ~78 ~29 ~159 fence 0
fill ~84 ~29 ~158 ~86 ~29 ~158 fence 0
fill ~86 ~29 ~157 ~86 ~29 ~158 fence 0
fill ~80 ~20 ~158 ~80 ~29 ~158 quartz_block
fill ~74 ~29 ~158 ~76 ~29 ~158 fence 0
fill ~87 ~25 ~156 ~87 ~29 ~156 wood
fill ~73 ~25 ~156 ~73 ~29 ~156 wood
fill ~100 ~26 ~150 ~100 ~29 ~150 wood
fill ~60 ~25 ~150 ~60 ~29 ~150 wood
fill ~59 ~29 ~149 ~59 ~29 ~150 fence 0
fill ~101 ~29 ~149 ~102 ~29 ~149 fence 0
fill ~102 ~29 ~147 ~102 ~29 ~149 fence 0
fill ~58 ~29 ~147 ~58 ~29 ~149 fence 0
fill ~103 ~27 ~145 ~103 ~29 ~145 fence 0
fill ~57 ~27 ~145 ~57 ~29 ~145 fence 0
fill ~103 ~29 ~144 ~104 ~29 ~144 double_wooden_slab 2
fill ~104 ~29 ~142 ~104 ~29 ~144 double_wooden_slab 2
fill ~56 ~29 ~144 ~57 ~29 ~144 double_wooden_slab 2
fill ~102 ~20 ~143 ~102 ~29 ~143 quartz_block
fill ~58 ~20 ~143 ~58 ~29 ~143 quartz_block
fill ~56 ~29 ~142 ~56 ~29 ~143 double_wooden_slab 2
fill ~103 ~27 ~141 ~103 ~29 ~141 fence 0
fill ~57 ~27 ~141 ~57 ~29 ~141 fence 0
fill ~102 ~29 ~137 ~102 ~29 ~139 fence 0
fill ~58 ~29 ~137 ~58 ~29 ~139 fence 0
fill ~100 ~26 ~136 ~100 ~29 ~136 wood
fill ~60 ~25 ~136 ~60 ~29 ~136 wood
fill ~79 ~29 ~130 ~80 ~29 ~130 leaves
fill ~81 ~28 ~129 ~81 ~29 ~129 wood
fill ~79 ~28 ~129 ~79 ~29 ~129 wood
fill ~89 ~26 ~127 ~89 ~29 ~127 stone 6
fill ~71 ~26 ~127 ~71 ~29 ~127 stone 6
fill ~82 ~28 ~126 ~82 ~29 ~126 wood
fill ~78 ~28 ~126 ~78 ~29 ~126 wood
fill ~79 ~29 ~125 ~81 ~29 ~125 grass
fill ~81 ~29 ~124 ~81 ~29 ~125 grass
fill ~84 ~28 ~113 ~84 ~29 ~113 stone 6
fill ~76 ~28 ~105 ~76 ~29 ~105 stone 6
fill ~142 ~29 ~104 ~144 ~29 ~104 double_wooden_slab 2
fill ~144 ~29 ~103 ~144 ~29 ~104 double_wooden_slab 2
fill ~81 ~29 ~103 ~81 ~29 ~104 iron_trapdoor 1
fill ~79 ~29 ~103 ~79 ~29 ~104 iron_trapdoor 0
fill ~16 ~29 ~104 ~18 ~29 ~104 double_wooden_slab 2
fill ~18 ~29 ~103 ~18 ~29 ~104 double_wooden_slab 2
fill ~145 ~27 ~103 ~145 ~29 ~103 fence 0
fill ~141 ~27 ~103 ~141 ~29 ~103 fence 0
fill ~19 ~27 ~103 ~19 ~29 ~103 fence 0
fill ~15 ~27 ~103 ~15 ~29 ~103 fence 0
fill ~147 ~29 ~102 ~149 ~29 ~102 fence 0
fill ~149 ~29 ~101 ~149 ~29 ~102 fence 0
fill ~143 ~20 ~102 ~143 ~29 ~102 quartz_block
fill ~137 ~29 ~102 ~139 ~29 ~102 fence 0
fill ~21 ~29 ~102 ~23 ~29 ~102 fence 0
fill ~23 ~29 ~101 ~23 ~29 ~102 fence 0
fill ~17 ~20 ~102 ~17 ~29 ~102 quartz_block
fill ~11 ~29 ~102 ~13 ~29 ~102 fence 0
fill ~150 ~25 ~100 ~150 ~29 ~100 wood
fill ~136 ~25 ~100 ~136 ~29 ~100 wood
fill ~24 ~26 ~100 ~24 ~29 ~100 wood
fill ~10 ~26 ~100 ~10 ~29 ~100 wood
fill ~83 ~29 ~97 ~84 ~29 ~97 stone 6
fill ~84 ~29 ~96 ~84 ~29 ~97 stone 6
fill ~84 ~28 ~95 ~84 ~29 ~95 stone 3
fill ~82 ~28 ~95 ~82 ~29 ~95 stone 3
fill ~78 ~16 ~95 ~78 ~29 ~95 stone
fill ~75 ~28 ~95 ~75 ~29 ~95 stone 3
fill ~74 ~26 ~94 ~74 ~29 ~94 stone 3
fill ~86 ~16 ~92 ~86 ~29 ~92 stone
fill ~83 ~29 ~91 ~85 ~29 ~91 stone
fill ~85 ~12 ~91 ~85 ~29 ~91 stone
fill ~88 ~13 ~90 ~88 ~29 ~90 stone
fill ~88 ~29 ~89 ~88 ~29 ~90 stone
fill ~84 ~9 ~90 ~84 ~29 ~90 stone
fill ~127 ~26 ~89 ~127 ~29 ~89 stone 6
fill ~87 ~10 ~89 ~87 ~29 ~89 stone
fill ~87 ~29 ~88 ~87 ~29 ~89 stone
fill ~33 ~26 ~89 ~33 ~29 ~89 stone 6
fill ~71 ~11 ~88 ~71 ~29 ~88 stone
fill ~69 ~16 ~88 ~69 ~29 ~88 stone
fill ~156 ~25 ~87 ~156 ~29 ~87 wood
fill ~70 ~13 ~87 ~70 ~29 ~87 stone
fill ~70 ~29 ~86 ~70 ~29 ~87 stone
fill ~68 ~17 ~87 ~68 ~29 ~87 stone
fill ~68 ~29 ~86 ~68 ~29 ~87 stone
fill ~4 ~25 ~87 ~4 ~29 ~87 wood
fill ~3 ~29 ~86 ~3 ~29 ~87 fence 0
fill ~157 ~29 ~86 ~158 ~29 ~86 fence 0
fill ~158 ~29 ~84 ~158 ~29 ~86 fence 0
fill ~94 ~26 ~86 ~94 ~29 ~86 stone 3
fill ~69 ~16 ~86 ~69 ~29 ~86 stone
fill ~69 ~29 ~83 ~69 ~29 ~86 stone
fill ~2 ~29 ~84 ~2 ~29 ~86 fence 0
fill ~95 ~28 ~85 ~95 ~29 ~85 stone 3
fill ~64 ~29 ~84 ~64 ~29 ~85 stone 6
fill ~105 ~28 ~84 ~105 ~29 ~84 stone 6
fill ~77 ~28 ~84 ~77 ~29 ~84 wood
fill ~70 ~11 ~84 ~70 ~29 ~84 stone
fill ~65 ~28 ~84 ~65 ~29 ~84 stone 3
fill ~63 ~29 ~83 ~63 ~29 ~84 stone 6
fill ~47 ~28 ~84 ~47 ~29 ~84 stone 6
fill ~84 ~28 ~83 ~84 ~29 ~83 wood
fill ~159 ~27 ~82 ~159 ~29 ~82 fence 0
fill ~126 ~28 ~82 ~126 ~29 ~82 wood
fill ~95 ~18 ~82 ~95 ~29 ~82 stone
fill ~65 ~28 ~82 ~65 ~29 ~82 stone 3
fill ~34 ~28 ~82 ~34 ~29 ~82 wood
fill ~1 ~27 ~82 ~1 ~29 ~82 fence 0
fill ~159 ~29 ~81 ~160 ~29 ~81 double_wooden_slab 2
fill ~160 ~29 ~79 ~160 ~29 ~81 double_wooden_slab 2
fill ~130 ~29 ~80 ~130 ~29 ~81 leaves
fill ~129 ~28 ~81 ~129 ~29 ~81 wood
fill ~124 ~29 ~81 ~125 ~29 ~81 grass
fill ~125 ~29 ~79 ~125 ~29 ~81 grass
fill ~103 ~29 ~81 ~104 ~29 ~81 iron_trapdoor 3
fill ~56 ~29 ~81 ~57 ~29 ~81 iron_trapdoor 3
fill ~35 ~29 ~81 ~36 ~29 ~81 grass
fill ~31 ~28 ~81 ~31 ~29 ~81 wood
fill ~0 ~29 ~81 ~1 ~29 ~81 double_wooden_slab 2
fill ~158 ~20 ~80 ~158 ~29 ~80 quartz_block
fill ~90 ~29 ~80 ~102 ~29 ~80 rail 1
fill ~53 ~29 ~80 ~55 ~29 ~80 rail 1
fill ~35 ~29 ~79 ~35 ~29 ~80 grass
fill ~30 ~29 ~79 ~30 ~29 ~80 leaves
fill ~2 ~20 ~80 ~2 ~29 ~80 quartz_block
fill ~0 ~29 ~79 ~0 ~29 ~80 double_wooden_slab 2
fill ~129 ~28 ~79 ~129 ~29 ~79 wood
fill ~103 ~29 ~79 ~104 ~29 ~79 iron_trapdoor 2
fill ~56 ~29 ~79 ~57 ~29 ~79 iron_trapdoor 2
fill ~31 ~28 ~79 ~31 ~29 ~79 wood
fill ~159 ~27 ~78 ~159 ~29 ~78 fence 0
fill ~126 ~28 ~78 ~126 ~29 ~78 wood
fill ~95 ~28 ~78 ~95 ~29 ~78 stone 3
fill ~65 ~16 ~78 ~65 ~29 ~78 stone
fill ~34 ~28 ~78 ~34 ~29 ~78 wood
fill ~1 ~27 ~78 ~1 ~29 ~78 fence 0
fill ~97 ~29 ~76 ~97 ~29 ~77 stone 6
fill ~91 ~12 ~77 ~91 ~29 ~77 stone
fill ~91 ~29 ~75 ~91 ~29 ~77 stone
fill ~76 ~28 ~77 ~76 ~29 ~77 wood
fill ~158 ~29 ~74 ~158 ~29 ~76 fence 0
fill ~113 ~28 ~76 ~113 ~29 ~76 stone 6
fill ~96 ~29 ~75 ~96 ~29 ~76 stone 6
fill ~95 ~28 ~76 ~95 ~29 ~76 stone 3
fill ~90 ~11 ~76 ~90 ~29 ~76 stone
fill ~83 ~28 ~76 ~83 ~29 ~76 wood
fill ~66 ~27 ~76 ~66 ~29 ~76 stone 3
fill ~66 ~29 ~74 ~66 ~29 ~76 stone 3
fill ~55 ~28 ~76 ~55 ~29 ~76 stone 6
fill ~2 ~29 ~74 ~2 ~29 ~76 fence 0
fill ~65 ~28 ~75 ~65 ~29 ~75 stone 3
fill ~92 ~15 ~74 ~92 ~29 ~74 stone
fill ~156 ~25 ~73 ~156 ~29 ~73 wood
fill ~4 ~25 ~73 ~4 ~29 ~73 wood
fill ~89 ~29 ~72 ~90 ~29 ~72 stone
fill ~90 ~14 ~72 ~90 ~29 ~72 stone
fill ~127 ~26 ~71 ~127 ~29 ~71 stone 6
fill ~72 ~29 ~71 ~73 ~29 ~71 stone
fill ~73 ~13 ~71 ~73 ~29 ~71 stone
fill ~33 ~26 ~71 ~33 ~29 ~71 stone 6
fill ~76 ~11 ~70 ~76 ~29 ~70 stone
fill ~76 ~29 ~69 ~76 ~29 ~70 stone
fill ~72 ~15 ~70 ~72 ~29 ~70 stone
fill ~77 ~13 ~69 ~77 ~29 ~69 stone
fill ~75 ~13 ~69 ~75 ~29 ~69 stone
fill ~73 ~14 ~69 ~73 ~29 ~69 stone
fill ~73 ~29 ~68 ~73 ~29 ~69 stone
fill ~74 ~15 ~68 ~74 ~29 ~68 stone
fill ~86 ~26 ~66 ~86 ~29 ~66 stone 3
fill ~85 ~28 ~65 ~85 ~29 ~65 stone 3
fill ~83 ~28 ~65 ~83 ~29 ~65 stone 3
fill ~83 ~29 ~64 ~83 ~29 ~65 stone 3
fill ~82 ~19 ~65 ~82 ~29 ~65 stone
fill ~78 ~28 ~65 ~78 ~29 ~65 stone 3
fill ~76 ~28 ~65 ~76 ~29 ~65 stone 3
fill ~75 ~29 ~64 ~75 ~29 ~65 stone 6
fill ~76 ~29 ~63 ~76 ~29 ~64 stone 6
fill ~150 ~26 ~60 ~150 ~29 ~60 wood
fill ~149 ~29 ~58 ~149 ~29 ~60 fence 0
fill ~136 ~26 ~60 ~136 ~29 ~60 wood
fill ~24 ~25 ~60 ~24 ~29 ~60 wood
fill ~23 ~29 ~58 ~23 ~29 ~60 fence 0
fill ~10 ~25 ~60 ~10 ~29 ~60 wood
fill ~137 ~29 ~58 ~137 ~29 ~59 fence 0
fill ~11 ~29 ~58 ~11 ~29 ~59 fence 0
fill ~147 ~29 ~58 ~148 ~29 ~58 fence 0
fill ~148 ~27 ~58 ~148 ~29 ~58 fence 0
fill ~143 ~20 ~58 ~143 ~29 ~58 quartz_block
fill ~138 ~29 ~58 ~139 ~29 ~58 fence 0
fill ~21 ~29 ~58 ~22 ~29 ~58 fence 0
fill ~22 ~27 ~58 ~22 ~29 ~58 fence 0
fill ~17 ~20 ~58 ~17 ~29 ~58 quartz_block
fill ~12 ~29 ~58 ~13 ~29 ~58 fence 0
fill ~145 ~27 ~57 ~145 ~29 ~57 fence 0
fill ~144 ~29 ~56 ~144 ~29 ~57 double_wooden_slab 2
fill ~142 ~29 ~56 ~142 ~29 ~57 double_wooden_slab 2
fill ~141 ~27 ~57 ~141 ~29 ~57 fence 0
fill ~81 ~29 ~56 ~81 ~29 ~57 iron_trapdoor 1
fill ~79 ~29 ~56 ~79 ~29 ~57 iron_trapdoor 0
fill ~19 ~27 ~57 ~19 ~29 ~57 fence 0
fill ~18 ~29 ~56 ~18 ~29 ~57 double_wooden_slab 2
fill ~16 ~29 ~56 ~16 ~29 ~57 double_wooden_slab 2
fill ~15 ~27 ~57 ~15 ~29 ~57 fence 0
fill ~84 ~28 ~55 ~84 ~29 ~55 stone 6
fill ~76 ~28 ~47 ~76 ~29 ~47 stone 6
fill ~81 ~29 ~35 ~81 ~29 ~36 grass
fill ~79 ~29 ~35 ~79 ~29 ~36 grass
fill ~82 ~28 ~34 ~82 ~29 ~34 wood
fill ~78 ~28 ~34 ~78 ~29 ~34 wood
fill ~89 ~26 ~33 ~89 ~29 ~33 stone 6
fill ~71 ~26 ~33 ~71 ~29 ~33 stone 6
fill ~81 ~28 ~31 ~81 ~29 ~31 wood
fill ~79 ~28 ~31 ~79 ~29 ~31 wood
fill ~80 ~29 ~30 ~81 ~29 ~30 leaves
fill ~100 ~25 ~24 ~100 ~29 ~24 wood
fill ~60 ~26 ~24 ~60 ~29 ~24 wood
fill ~59 ~29 ~23 ~59 ~29 ~24 fence 0
fill ~101 ~29 ~23 ~102 ~29 ~23 fence 0
fill ~102 ~29 ~21 ~102 ~29 ~23 fence 0
fill ~58 ~29 ~21 ~58 ~29 ~23 fence 0
fill ~103 ~27 ~19 ~103 ~29 ~19 fence 0
fill ~57 ~27 ~19 ~57 ~29 ~19 fence 0
fill ~103 ~29 ~18 ~104 ~29 ~18 double_wooden_slab 2
fill ~104 ~29 ~16 ~104 ~29 ~18 double_wooden_slab 2
fill ~56 ~29 ~18 ~57 ~29 ~18 double_wooden_slab 2
fill ~102 ~20 ~17 ~102 ~29 ~17 quartz_block
fill ~58 ~20 ~17 ~58 ~29 ~17 quartz_block
fill ~56 ~29 ~16 ~56 ~29 ~17 double_wooden_slab 2
fill ~103 ~27 ~15 ~103 ~29 ~15 fence 0
fill ~57 ~27 ~15 ~57 ~29 ~15 fence 0
fill ~102 ~29 ~11 ~102 ~29 ~13 fence 0
fill ~58 ~29 ~11 ~58 ~29 ~13 fence 0
fill ~100 ~25 ~10 ~100 ~29 ~10 wood
fill ~60 ~26 ~10 ~60 ~29 ~10 wood
fill ~87 ~25 ~4 ~87 ~29 ~4 wood
fill ~86 ~29 ~2 ~86 ~29 ~4 fence 0
fill ~73 ~25 ~4 ~73 ~29 ~4 wood
fill ~74 ~29 ~2 ~74 ~29 ~3 fence 0
fill ~84 ~29 ~2 ~85 ~29 ~2 fence 0
fill ~85 ~27 ~2 ~85 ~29 ~2 fence 0
fill ~80 ~20 ~2 ~80 ~29 ~2 quartz_block
fill ~75 ~29 ~2 ~76 ~29 ~2 fence 0
fill ~82 ~27 ~1 ~82 ~29 ~1 fence 0
fill ~81 ~29 ~0 ~81 ~29 ~1 double_wooden_slab 2
fill ~79 ~29 ~0 ~79 ~29 ~1 double_wooden_slab 2
fill ~78 ~27 ~1 ~78 ~29 ~1 fence 0
fill ~80 ~27 ~160 ~80 ~28 ~160 quartz_block
fill ~81 ~23 ~159 ~81 ~28 ~159 quartz_block
fill ~81 ~28 ~158 ~81 ~28 ~159 quartz_block
fill ~79 ~23 ~159 ~79 ~28 ~159 quartz_block
fill ~79 ~28 ~158 ~79 ~28 ~159 quartz_block
fill ~85 ~27 ~158 ~85 ~28 ~158 fence 0
fill ~84 ~26 ~158 ~84 ~28 ~158 wood
fill ~82 ~28 ~158 ~83 ~28 ~158 fence 0
fill ~77 ~28 ~158 ~78 ~28 ~158 fence 0
fill ~76 ~26 ~158 ~76 ~28 ~158 wood
fill ~75 ~27 ~158 ~75 ~28 ~158 fence 0
fill ~102 ~27 ~148 ~102 ~28 ~148 fence 0
fill ~58 ~27 ~148 ~58 ~28 ~148 fence 0
fill ~102 ~26 ~147 ~102 ~28 ~147 wood
fill ~58 ~26 ~147 ~58 ~28 ~147 wood
fill ~102 ~28 ~145 ~102 ~28 ~146 fence 0
fill ~58 ~28 ~145 ~58 ~28 ~146 fence 0
fill ~102 ~28 ~144 ~103 ~28 ~144 quartz_block
fill ~103 ~23 ~144 ~103 ~28 ~144 quartz_block
fill ~57 ~28 ~144 ~58 ~28 ~144 quartz_block
fill ~58 ~21 ~144 ~58 ~28 ~144 quartz_block
fill ~104 ~27 ~143 ~104 ~28 ~143 quartz_block
fill ~56 ~27 ~143 ~56 ~28 ~143 quartz_block
fill ~102 ~28 ~142 ~103 ~28 ~142 quartz_block
fill ~103 ~23 ~142 ~103 ~28 ~142 quartz_block
fill ~57 ~28 ~142 ~58 ~28 ~142 quartz_block
fill ~58 ~21 ~142 ~58 ~28 ~142 quartz_block
fill ~102 ~28 ~140 ~102 ~28 ~141 fence 0
fill ~58 ~28 ~140 ~58 ~28 ~141 fence 0
fill ~102 ~26 ~139 ~102 ~28 ~139 wood
fill ~58 ~26 ~139 ~58 ~28 ~139 wood
fill ~102 ~27 ~138 ~102 ~28 ~138 fence 0
fill ~58 ~27 ~138 ~58 ~28 ~138 fence 0
fill ~80 ~27 ~130 ~80 ~28 ~130 wood
fill ~82 ~27 ~129 ~82 ~28 ~129 wood
fill ~78 ~27 ~129 ~78 ~28 ~129 wood
fill ~83 ~28 ~125 ~83 ~28 ~126 wood
fill ~77 ~28 ~125 ~77 ~28 ~126 wood
fill ~79 ~28 ~125 ~81 ~28 ~125 stone
fill ~81 ~16 ~125 ~81 ~28 ~125 stone
fill ~81 ~28 ~124 ~81 ~28 ~125 stone
fill ~82 ~28 ~103 ~82 ~28 ~124 grass
fill ~80 ~28 ~119 ~80 ~28 ~124 grass
fill ~79 ~16 ~124 ~79 ~28 ~124 stone
fill ~78 ~28 ~97 ~78 ~28 ~124 grass
fill ~83 ~28 ~120 ~83 ~28 ~122 grass
fill ~81 ~28 ~121 ~81 ~28 ~122 grass
fill ~77 ~28 ~97 ~77 ~28 ~122 grass
fill ~79 ~28 ~119 ~79 ~28 ~121 grass
fill ~81 ~28 ~111 ~81 ~28 ~119 grass
fill ~79 ~28 ~118 ~80 ~28 ~118 dirt 1
fill ~83 ~28 ~99 ~83 ~28 ~117 grass
fill ~79 ~28 ~117 ~80 ~28 ~117 grass
fill ~80 ~28 ~110 ~80 ~28 ~117 grass
fill ~79 ~28 ~106 ~79 ~28 ~113 grass
fill ~76 ~28 ~110 ~76 ~28 ~113 grass
fill ~84 ~28 ~110 ~84 ~28 ~111 grass
fill ~81 ~28 ~108 ~81 ~28 ~109 grass
fill ~80 ~28 ~108 ~80 ~28 ~109 dirt 1
fill ~84 ~28 ~100 ~84 ~28 ~107 grass
fill ~81 ~28 ~106 ~81 ~28 ~107 double_wooden_slab 1
fill ~80 ~11 ~105 ~80 ~28 ~105 stone
fill ~79 ~28 ~90 ~79 ~28 ~105 double_wooden_slab 1
fill ~143 ~27 ~104 ~143 ~28 ~104 quartz_block
fill ~85 ~28 ~97 ~85 ~28 ~104 grass
fill ~81 ~28 ~90 ~81 ~28 ~104 double_wooden_slab 1
fill ~75 ~28 ~97 ~75 ~28 ~104 grass
fill ~17 ~27 ~104 ~17 ~28 ~104 quartz_block
fill ~144 ~23 ~103 ~144 ~28 ~103 quartz_block
fill ~144 ~28 ~102 ~144 ~28 ~103 quartz_block
fill ~142 ~23 ~103 ~142 ~28 ~103 quartz_block
fill ~142 ~28 ~102 ~142 ~28 ~103 quartz_block
fill ~80 ~3 ~103 ~80 ~28 ~103 stone
fill ~76 ~28 ~97 ~76 ~28 ~103 grass
fill ~18 ~23 ~103 ~18 ~28 ~103 quartz_block
fill ~18 ~28 ~102 ~18 ~28 ~103 quartz_block
fill ~16 ~23 ~103 ~16 ~28 ~103 quartz_block
fill ~16 ~28 ~102 ~16 ~28 ~103 quartz_block
fill ~148 ~27 ~102 ~148 ~28 ~102 fence 0
fill ~147 ~26 ~102 ~147 ~28 ~102 wood
fill ~145 ~28 ~102 ~146 ~28 ~102 fence 0
fill ~140 ~28 ~102 ~141 ~28 ~102 fence 0
fill ~139 ~26 ~102 ~139 ~28 ~102 wood
fill ~138 ~27 ~102 ~138 ~28 ~102 fence 0
fill ~22 ~27 ~102 ~22 ~28 ~102 fence 0
fill ~21 ~26 ~102 ~21 ~28 ~102 wood
fill ~19 ~28 ~102 ~20 ~28 ~102 fence 0
fill ~14 ~28 ~102 ~15 ~28 ~102 fence 0
fill ~13 ~26 ~102 ~13 ~28 ~102 wood
fill ~12 ~27 ~102 ~12 ~28 ~102 fence 0
fill ~82 ~28 ~97 ~82 ~28 ~101 grass
fill ~80 ~9 ~101 ~80 ~28 ~101 stone
fill ~80 ~16 ~99 ~80 ~28 ~99 stone
fill ~83 ~28 ~97 ~84 ~28 ~97 stone 3
fill ~84 ~28 ~96 ~84 ~28 ~97 stone 3
fill ~80 ~22 ~97 ~80 ~28 ~97 stone
fill ~86 ~28 ~95 ~86 ~28 ~96 grass
fill ~85 ~28 ~95 ~85 ~28 ~96 stone 3
fill ~82 ~28 ~96 ~83 ~28 ~96 stone 3
fill ~77 ~28 ~96 ~78 ~28 ~96 stone
fill ~78 ~18 ~96 ~78 ~28 ~96 stone
fill ~75 ~28 ~96 ~76 ~28 ~96 stone 3
fill ~74 ~21 ~96 ~74 ~28 ~96 stone
fill ~74 ~28 ~95 ~74 ~28 ~96 stone
fill ~80 ~22 ~95 ~80 ~28 ~95 stone
fill ~78 ~15 ~94 ~78 ~28 ~94 stone
fill ~78 ~28 ~91 ~78 ~28 ~94 stone
fill ~85 ~28 ~93 ~86 ~28 ~93 stone
fill ~86 ~18 ~93 ~86 ~28 ~93 stone
fill ~80 ~14 ~93 ~80 ~28 ~93 stone
fill ~72 ~26 ~93 ~72 ~28 ~93 stone 3
fill ~82 ~28 ~92 ~85 ~28 ~92 stone
fill ~85 ~15 ~92 ~85 ~28 ~92 stone
fill ~89 ~27 ~91 ~89 ~28 ~91 wood
fill ~82 ~28 ~91 ~84 ~28 ~91 stone
fill ~84 ~11 ~91 ~84 ~28 ~91 stone
fill ~80 ~7 ~91 ~80 ~28 ~91 stone
fill ~85 ~10 ~90 ~85 ~28 ~90 stone
fill ~88 ~11 ~89 ~88 ~28 ~89 stone
fill ~88 ~28 ~87 ~88 ~28 ~89 stone
fill ~69 ~27 ~89 ~69 ~28 ~89 wood
fill ~93 ~26 ~88 ~93 ~28 ~88 stone 3
fill ~87 ~8 ~88 ~87 ~28 ~88 stone
fill ~72 ~28 ~88 ~73 ~28 ~88 stone
fill ~73 ~9 ~88 ~73 ~28 ~88 stone
fill ~95 ~28 ~86 ~96 ~28 ~86 stone
fill ~96 ~21 ~86 ~96 ~28 ~86 stone
fill ~70 ~10 ~86 ~70 ~28 ~86 stone
fill ~70 ~28 ~85 ~70 ~28 ~86 stone
fill ~67 ~28 ~86 ~68 ~28 ~86 stone
fill ~68 ~19 ~86 ~68 ~28 ~86 stone
fill ~68 ~28 ~82 ~68 ~28 ~86 stone
fill ~64 ~28 ~86 ~65 ~28 ~86 grass
fill ~158 ~27 ~85 ~158 ~28 ~85 fence 0
fill ~97 ~28 ~85 ~104 ~28 ~85 grass
fill ~96 ~28 ~84 ~96 ~28 ~85 stone 3
fill ~69 ~15 ~85 ~69 ~28 ~85 stone
fill ~69 ~28 ~82 ~69 ~28 ~85 stone
fill ~67 ~17 ~85 ~67 ~28 ~85 stone
fill ~64 ~28 ~85 ~65 ~28 ~85 stone 3
fill ~56 ~28 ~85 ~63 ~28 ~85 grass
fill ~2 ~27 ~85 ~2 ~28 ~85 fence 0
fill ~158 ~26 ~84 ~158 ~28 ~84 wood
fill ~110 ~28 ~84 ~113 ~28 ~84 grass
fill ~113 ~28 ~77 ~113 ~28 ~84 grass
fill ~107 ~28 ~80 ~107 ~28 ~84 grass
fill ~97 ~28 ~84 ~103 ~28 ~84 grass
fill ~103 ~28 ~82 ~103 ~28 ~84 grass
fill ~63 ~28 ~84 ~64 ~28 ~84 stone 3
fill ~64 ~28 ~82 ~64 ~28 ~84 stone 3
fill ~53 ~28 ~84 ~60 ~28 ~84 grass
fill ~60 ~28 ~82 ~60 ~28 ~84 grass
fill ~49 ~28 ~84 ~50 ~28 ~84 grass
fill ~50 ~28 ~82 ~50 ~28 ~84 grass
fill ~2 ~26 ~84 ~2 ~28 ~84 wood
fill ~158 ~28 ~82 ~158 ~28 ~83 fence 0
fill ~125 ~28 ~83 ~126 ~28 ~83 wood
fill ~114 ~28 ~83 ~122 ~28 ~83 grass
fill ~122 ~28 ~77 ~122 ~28 ~83 grass
fill ~108 ~28 ~83 ~112 ~28 ~83 grass
fill ~112 ~28 ~77 ~112 ~28 ~83 grass
fill ~104 ~28 ~83 ~106 ~28 ~83 grass
fill ~106 ~28 ~81 ~106 ~28 ~83 grass
fill ~97 ~28 ~83 ~102 ~28 ~83 grass
fill ~102 ~28 ~82 ~102 ~28 ~83 grass
fill ~96 ~19 ~83 ~96 ~28 ~83 stone
fill ~96 ~28 ~82 ~96 ~28 ~83 stone
fill ~61 ~28 ~82 ~61 ~28 ~83 grass
fill ~51 ~28 ~83 ~59 ~28 ~83 grass
fill ~59 ~28 ~82 ~59 ~28 ~83 grass
fill ~43 ~28 ~83 ~49 ~28 ~83 grass
fill ~49 ~28 ~76 ~49 ~28 ~83 grass
fill ~38 ~28 ~83 ~40 ~28 ~83 grass
fill ~40 ~28 ~77 ~40 ~28 ~83 grass
fill ~34 ~28 ~83 ~35 ~28 ~83 wood
fill ~35 ~27 ~83 ~35 ~28 ~83 wood
fill ~35 ~28 ~82 ~35 ~28 ~83 wood
fill ~2 ~28 ~82 ~2 ~28 ~83 fence 0
fill ~129 ~27 ~82 ~129 ~28 ~82 wood
fill ~123 ~28 ~82 ~124 ~28 ~82 grass
fill ~114 ~28 ~82 ~121 ~28 ~82 grass
fill ~121 ~28 ~81 ~121 ~28 ~82 grass
fill ~108 ~28 ~82 ~111 ~28 ~82 grass
fill ~111 ~28 ~76 ~111 ~28 ~82 grass
fill ~104 ~28 ~82 ~105 ~28 ~82 grass
fill ~97 ~28 ~82 ~101 ~28 ~82 grass
fill ~91 ~28 ~82 ~94 ~28 ~82 stone
fill ~94 ~17 ~82 ~94 ~28 ~82 stone
fill ~62 ~28 ~82 ~63 ~28 ~82 grass
fill ~51 ~28 ~82 ~57 ~28 ~82 grass
fill ~41 ~28 ~82 ~48 ~28 ~82 grass
fill ~48 ~28 ~76 ~48 ~28 ~82 grass
fill ~38 ~28 ~82 ~39 ~28 ~82 grass
fill ~39 ~28 ~77 ~39 ~28 ~82 grass
fill ~37 ~28 ~80 ~37 ~28 ~82 dirt 1
fill ~31 ~27 ~82 ~31 ~28 ~82 wood
fill ~158 ~28 ~81 ~159 ~28 ~81 quartz_block
fill ~159 ~23 ~81 ~159 ~28 ~81 quartz_block
fill ~124 ~28 ~81 ~125 ~28 ~81 stone
fill ~125 ~16 ~81 ~125 ~28 ~81 stone
fill ~125 ~28 ~79 ~125 ~28 ~81 stone
fill ~119 ~28 ~81 ~120 ~28 ~81 grass
fill ~120 ~28 ~77 ~120 ~28 ~81 grass
fill ~118 ~28 ~80 ~118 ~28 ~81 dirt 1
fill ~117 ~28 ~77 ~117 ~28 ~81 grass
fill ~115 ~28 ~77 ~115 ~28 ~81 grass
fill ~108 ~28 ~81 ~110 ~28 ~81 grass
fill ~110 ~28 ~80 ~110 ~28 ~81 grass
fill ~90 ~28 ~81 ~105 ~28 ~81 double_wooden_slab 1
fill ~56 ~28 ~81 ~70 ~28 ~81 double_wooden_slab 1
fill ~53 ~28 ~81 ~54 ~28 ~81 double_wooden_slab 1
fill ~51 ~28 ~81 ~52 ~28 ~81 grass
fill ~41 ~28 ~81 ~47 ~28 ~81 grass
fill ~47 ~28 ~76 ~47 ~28 ~81 grass
fill ~35 ~28 ~81 ~36 ~28 ~81 stone
fill ~36 ~16 ~81 ~36 ~28 ~81 stone
fill ~1 ~28 ~81 ~2 ~28 ~81 quartz_block
fill ~2 ~21 ~81 ~2 ~28 ~81 quartz_block
fill ~160 ~27 ~80 ~160 ~28 ~80 quartz_block
fill ~130 ~27 ~80 ~130 ~28 ~80 wood
fill ~123 ~28 ~79 ~123 ~28 ~80 dirt 1
fill ~119 ~28 ~78 ~119 ~28 ~80 grass
fill ~116 ~28 ~77 ~116 ~28 ~80 grass
fill ~114 ~28 ~77 ~114 ~28 ~80 grass
fill ~108 ~28 ~80 ~109 ~28 ~80 dirt 1
fill ~105 ~11 ~80 ~105 ~28 ~80 stone
fill ~103 ~3 ~80 ~103 ~28 ~80 stone
fill ~101 ~9 ~80 ~101 ~28 ~80 stone
fill ~99 ~16 ~80 ~99 ~28 ~80 stone
fill ~97 ~22 ~80 ~97 ~28 ~80 stone
fill ~95 ~22 ~80 ~95 ~28 ~80 stone
fill ~93 ~15 ~80 ~93 ~28 ~80 stone
fill ~91 ~8 ~80 ~91 ~28 ~80 stone
fill ~72 ~28 ~80 ~77 ~28 ~80 rail 1
fill ~69 ~11 ~80 ~69 ~28 ~80 stone
fill ~67 ~14 ~80 ~67 ~28 ~80 stone
fill ~65 ~22 ~80 ~65 ~28 ~80 stone
fill ~63 ~22 ~80 ~63 ~28 ~80 stone
fill ~61 ~16 ~80 ~61 ~28 ~80 stone
fill ~59 ~9 ~80 ~59 ~28 ~80 stone
fill ~57 ~3 ~80 ~57 ~28 ~80 stone
fill ~55 ~11 ~80 ~55 ~28 ~80 stone
fill ~53 ~28 ~76 ~53 ~28 ~80 grass
fill ~51 ~28 ~80 ~52 ~28 ~80 dirt 1
fill ~50 ~28 ~76 ~50 ~28 ~80 grass
fill ~43 ~28 ~80 ~46 ~28 ~80 grass
fill ~42 ~28 ~79 ~42 ~28 ~80 dirt 1
fill ~41 ~28 ~77 ~41 ~28 ~80 grass
fill ~38 ~28 ~77 ~38 ~28 ~80 grass
fill ~35 ~16 ~80 ~35 ~28 ~80 stone
fill ~35 ~28 ~79 ~35 ~28 ~80 stone
fill ~30 ~27 ~80 ~30 ~28 ~80 wood
fill ~0 ~27 ~80 ~0 ~28 ~80 quartz_block
fill ~158 ~28 ~79 ~159 ~28 ~79 quartz_block
fill ~159 ~23 ~79 ~159 ~28 ~79 quartz_block
fill ~124 ~16 ~79 ~124 ~28 ~79 stone
fill ~121 ~28 ~77 ~121 ~28 ~79 grass
fill ~118 ~28 ~78 ~118 ~28 ~79 grass
fill ~108 ~28 ~79 ~109 ~28 ~79 grass
fill ~109 ~28 ~77 ~109 ~28 ~79 grass
fill ~106 ~28 ~79 ~107 ~28 ~79 double_wooden_slab 1
fill ~105 ~28 ~76 ~105 ~28 ~79 grass
fill ~90 ~28 ~79 ~104 ~28 ~79 double_wooden_slab 1
fill ~55 ~28 ~79 ~70 ~28 ~79 double_wooden_slab 1
fill ~54 ~28 ~77 ~54 ~28 ~79 grass
fill ~51 ~28 ~79 ~52 ~28 ~79 grass
fill ~52 ~28 ~77 ~52 ~28 ~79 grass
fill ~45 ~28 ~77 ~45 ~28 ~79 grass
fill ~43 ~28 ~77 ~43 ~28 ~79 grass
fill ~37 ~28 ~78 ~37 ~28 ~79 grass
fill ~36 ~16 ~79 ~36 ~28 ~79 stone
fill ~1 ~28 ~79 ~2 ~28 ~79 quartz_block
fill ~2 ~21 ~79 ~2 ~28 ~79 quartz_block
fill ~158 ~28 ~77 ~158 ~28 ~78 fence 0
fill ~129 ~27 ~78 ~129 ~28 ~78 wood
fill ~125 ~28 ~77 ~125 ~28 ~78 wood
fill ~123 ~28 ~78 ~124 ~28 ~78 grass
fill ~110 ~28 ~76 ~110 ~28 ~78 grass
fill ~106 ~28 ~78 ~108 ~28 ~78 grass
fill ~108 ~28 ~77 ~108 ~28 ~78 grass
fill ~103 ~28 ~78 ~104 ~28 ~78 grass
fill ~104 ~28 ~75 ~104 ~28 ~78 grass
fill ~97 ~28 ~78 ~101 ~28 ~78 grass
fill ~101 ~28 ~75 ~101 ~28 ~78 grass
fill ~96 ~28 ~75 ~96 ~28 ~78 stone 3
fill ~91 ~28 ~78 ~92 ~28 ~78 stone
fill ~92 ~14 ~78 ~92 ~28 ~78 stone
fill ~92 ~28 ~75 ~92 ~28 ~78 stone
fill ~66 ~28 ~78 ~69 ~28 ~78 stone
fill ~69 ~12 ~78 ~69 ~28 ~78 stone
fill ~64 ~17 ~78 ~64 ~28 ~78 stone
fill ~64 ~28 ~77 ~64 ~28 ~78 stone
fill ~55 ~28 ~78 ~63 ~28 ~78 grass
fill ~63 ~28 ~75 ~63 ~28 ~78 grass
fill ~51 ~28 ~77 ~51 ~28 ~78 grass
fill ~46 ~28 ~77 ~46 ~28 ~78 grass
fill ~44 ~28 ~77 ~44 ~28 ~78 grass
fill ~42 ~28 ~77 ~42 ~28 ~78 grass
fill ~35 ~28 ~77 ~35 ~28 ~78 wood
fill ~31 ~27 ~78 ~31 ~28 ~78 wood
fill ~2 ~28 ~77 ~2 ~28 ~78 fence 0
fill ~106 ~28 ~77 ~107 ~28 ~77 grass
fill ~107 ~28 ~76 ~107 ~28 ~77 grass
fill ~102 ~28 ~77 ~103 ~28 ~77 grass
fill ~103 ~28 ~75 ~103 ~28 ~77 grass
fill ~99 ~28 ~77 ~100 ~28 ~77 grass
fill ~100 ~28 ~75 ~100 ~28 ~77 grass
fill ~97 ~28 ~76 ~97 ~28 ~77 stone 3
fill ~55 ~28 ~77 ~62 ~28 ~77 grass
fill ~62 ~28 ~75 ~62 ~28 ~77 grass
fill ~158 ~26 ~76 ~158 ~28 ~76 wood
fill ~102 ~28 ~75 ~102 ~28 ~76 grass
fill ~98 ~28 ~75 ~98 ~28 ~76 grass
fill ~91 ~12 ~76 ~91 ~28 ~76 stone
fill ~91 ~28 ~75 ~91 ~28 ~76 stone
fill ~64 ~28 ~75 ~64 ~28 ~76 stone 3
fill ~57 ~28 ~76 ~61 ~28 ~76 grass
fill ~61 ~28 ~75 ~61 ~28 ~76 grass
fill ~2 ~26 ~76 ~2 ~28 ~76 wood
fill ~158 ~27 ~75 ~158 ~28 ~75 fence 0
fill ~93 ~15 ~75 ~93 ~28 ~75 stone
fill ~93 ~28 ~74 ~93 ~28 ~75 stone
fill ~90 ~11 ~75 ~90 ~28 ~75 stone
fill ~66 ~26 ~75 ~66 ~28 ~75 stone 3
fill ~66 ~28 ~74 ~66 ~28 ~75 stone 3
fill ~56 ~28 ~75 ~60 ~28 ~75 grass
fill ~2 ~27 ~75 ~2 ~28 ~75 fence 0
fill ~95 ~28 ~74 ~96 ~28 ~74 grass
fill ~64 ~28 ~74 ~65 ~28 ~74 stone
fill ~65 ~21 ~74 ~65 ~28 ~74 stone
fill ~72 ~11 ~73 ~72 ~28 ~73 stone
fill ~72 ~28 ~71 ~72 ~28 ~73 stone
fill ~87 ~28 ~72 ~89 ~28 ~72 stone
fill ~89 ~13 ~72 ~89 ~28 ~72 stone
fill ~67 ~26 ~72 ~67 ~28 ~72 stone 3
fill ~91 ~27 ~71 ~91 ~28 ~71 wood
fill ~81 ~28 ~55 ~81 ~28 ~70 double_wooden_slab 1
fill ~79 ~28 ~56 ~79 ~28 ~70 double_wooden_slab 1
fill ~75 ~11 ~70 ~75 ~28 ~70 stone
fill ~82 ~11 ~69 ~82 ~28 ~69 stone
fill ~82 ~28 ~66 ~82 ~28 ~69 stone
fill ~80 ~11 ~69 ~80 ~28 ~69 stone
fill ~78 ~12 ~69 ~78 ~28 ~69 stone
fill ~78 ~28 ~68 ~78 ~28 ~69 stone
fill ~76 ~13 ~69 ~76 ~28 ~69 stone
fill ~76 ~28 ~68 ~76 ~28 ~69 stone
fill ~71 ~27 ~69 ~71 ~28 ~69 wood
fill ~77 ~13 ~68 ~77 ~28 ~68 stone
fill ~75 ~15 ~68 ~75 ~28 ~68 stone
fill ~75 ~28 ~67 ~75 ~28 ~68 stone
fill ~73 ~17 ~68 ~73 ~28 ~68 stone
fill ~88 ~26 ~67 ~88 ~28 ~67 stone 3
fill ~80 ~16 ~67 ~80 ~28 ~67 stone
fill ~74 ~17 ~67 ~74 ~28 ~67 stone
fill ~86 ~21 ~65 ~86 ~28 ~65 stone
fill ~86 ~28 ~64 ~86 ~28 ~65 stone
fill ~80 ~20 ~65 ~80 ~28 ~65 stone
fill ~75 ~28 ~64 ~75 ~28 ~65 stone 3
fill ~74 ~28 ~64 ~74 ~28 ~65 grass
fill ~84 ~28 ~64 ~85 ~28 ~64 stone 3
fill ~82 ~28 ~64 ~83 ~28 ~64 stone
fill ~83 ~19 ~64 ~83 ~28 ~64 stone
fill ~76 ~28 ~64 ~78 ~28 ~64 stone 3
fill ~82 ~28 ~63 ~85 ~28 ~63 grass
fill ~85 ~28 ~56 ~85 ~28 ~63 grass
fill ~80 ~22 ~63 ~80 ~28 ~63 stone
fill ~78 ~28 ~60 ~78 ~28 ~63 grass
fill ~76 ~28 ~63 ~77 ~28 ~63 stone 3
fill ~75 ~28 ~56 ~75 ~28 ~63 grass
fill ~82 ~28 ~62 ~84 ~28 ~62 grass
fill ~84 ~28 ~57 ~84 ~28 ~62 grass
fill ~82 ~28 ~61 ~83 ~28 ~61 grass
fill ~83 ~28 ~38 ~83 ~28 ~61 grass
fill ~80 ~16 ~61 ~80 ~28 ~61 stone
fill ~77 ~28 ~43 ~77 ~28 ~61 grass
fill ~82 ~28 ~36 ~82 ~28 ~60 grass
fill ~76 ~28 ~53 ~76 ~28 ~60 grass
fill ~80 ~9 ~59 ~80 ~28 ~59 stone
fill ~147 ~26 ~58 ~147 ~28 ~58 wood
fill ~145 ~28 ~58 ~146 ~28 ~58 fence 0
fill ~144 ~21 ~58 ~144 ~28 ~58 quartz_block
fill ~144 ~28 ~57 ~144 ~28 ~58 quartz_block
fill ~142 ~21 ~58 ~142 ~28 ~58 quartz_block
fill ~142 ~28 ~57 ~142 ~28 ~58 quartz_block
fill ~140 ~28 ~58 ~141 ~28 ~58 fence 0
fill ~139 ~26 ~58 ~139 ~28 ~58 wood
fill ~138 ~27 ~58 ~138 ~28 ~58 fence 0
fill ~21 ~26 ~58 ~21 ~28 ~58 wood
fill ~19 ~28 ~58 ~20 ~28 ~58 fence 0
fill ~18 ~21 ~58 ~18 ~28 ~58 quartz_block
fill ~18 ~28 ~57 ~18 ~28 ~58 quartz_block
fill ~16 ~21 ~58 ~16 ~28 ~58 quartz_block
fill ~16 ~28 ~57 ~16 ~28 ~58 quartz_block
fill ~14 ~28 ~58 ~15 ~28 ~58 fence 0
fill ~13 ~26 ~58 ~13 ~28 ~58 wood
fill ~12 ~27 ~58 ~12 ~28 ~58 fence 0
fill ~80 ~3 ~57 ~80 ~28 ~57 stone
fill ~78 ~28 ~36 ~78 ~28 ~57 grass
fill ~143 ~27 ~56 ~143 ~28 ~56 quartz_block
fill ~17 ~27 ~56 ~17 ~28 ~56 quartz_block
fill ~80 ~11 ~55 ~80 ~28 ~55 stone
fill ~81 ~28 ~47 ~81 ~28 ~54 grass
fill ~79 ~28 ~53 ~79 ~28 ~54 double_wooden_slab 1
fill ~80 ~28 ~51 ~80 ~28 ~52 dirt 1
fill ~79 ~28 ~51 ~79 ~28 ~52 grass
fill ~84 ~28 ~47 ~84 ~28 ~50 grass
fill ~80 ~28 ~43 ~80 ~28 ~50 grass
fill ~76 ~28 ~49 ~76 ~28 ~50 grass
fill ~79 ~28 ~39 ~79 ~28 ~49 grass
fill ~80 ~28 ~42 ~81 ~28 ~42 dirt 1
fill ~80 ~28 ~41 ~81 ~28 ~41 grass
fill ~81 ~28 ~39 ~81 ~28 ~41 grass
fill ~80 ~28 ~39 ~80 ~28 ~40 grass
fill ~77 ~28 ~38 ~77 ~28 ~40 grass
fill ~79 ~28 ~38 ~81 ~28 ~38 dirt 1
fill ~81 ~16 ~36 ~81 ~28 ~36 stone
fill ~81 ~28 ~35 ~81 ~28 ~36 stone
fill ~79 ~16 ~36 ~79 ~28 ~36 stone
fill ~79 ~28 ~35 ~79 ~28 ~36 stone
fill ~82 ~28 ~35 ~83 ~28 ~35 wood
fill ~83 ~27 ~35 ~83 ~28 ~35 wood
fill ~83 ~28 ~34 ~83 ~28 ~35 wood
fill ~80 ~16 ~35 ~80 ~28 ~35 stone
fill ~77 ~28 ~35 ~78 ~28 ~35 wood
fill ~82 ~27 ~31 ~82 ~28 ~31 wood
fill ~78 ~27 ~31 ~78 ~28 ~31 wood
fill ~80 ~27 ~30 ~80 ~28 ~30 wood
fill ~102 ~27 ~22 ~102 ~28 ~22 fence 0
fill ~58 ~27 ~22 ~58 ~28 ~22 fence 0
fill ~102 ~26 ~21 ~102 ~28 ~21 wood
fill ~58 ~26 ~21 ~58 ~28 ~21 wood
fill ~102 ~28 ~19 ~102 ~28 ~20 fence 0
fill ~58 ~28 ~19 ~58 ~28 ~20 fence 0
fill ~102 ~28 ~18 ~103 ~28 ~18 quartz_block
fill ~103 ~23 ~18 ~103 ~28 ~18 quartz_block
fill ~57 ~28 ~18 ~58 ~28 ~18 quartz_block
fill ~58 ~21 ~18 ~58 ~28 ~18 quartz_block
fill ~104 ~27 ~17 ~104 ~28 ~17 quartz_block
fill ~56 ~27 ~17 ~56 ~28 ~17 quartz_block
fill ~102 ~28 ~16 ~103 ~28 ~16 quartz_block
fill ~103 ~23 ~16 ~103 ~28 ~16 quartz_block
fill ~57 ~28 ~16 ~58 ~28 ~16 quartz_block
fill ~58 ~21 ~16 ~58 ~28 ~16 quartz_block
fill ~102 ~28 ~14 ~102 ~28 ~15 fence 0
fill ~58 ~28 ~14 ~58 ~28 ~15 fence 0
fill ~102 ~26 ~13 ~102 ~28 ~13 wood
fill ~58 ~26 ~13 ~58 ~28 ~13 wood
fill ~102 ~27 ~12 ~102 ~28 ~12 fence 0
fill ~58 ~27 ~12 ~58 ~28 ~12 fence 0
fill ~84 ~26 ~2 ~84 ~28 ~2 wood
fill ~82 ~28 ~2 ~83 ~28 ~2 fence 0
fill ~81 ~21 ~2 ~81 ~28 ~2 quartz_block
fill ~81 ~28 ~1 ~81 ~28 ~2 quartz_block
fill ~79 ~21 ~2 ~79 ~28 ~2 quartz_block
fill ~79 ~28 ~1 ~79 ~28 ~2 quartz_block
fill ~77 ~28 ~2 ~78 ~28 ~2 fence 0
fill ~76 ~26 ~2 ~76 ~28 ~2 wood
fill ~75 ~27 ~2 ~75 ~28 ~2 fence 0
fill ~80 ~27 ~0 ~80 ~28 ~0 quartz_block
fill ~86 ~27 ~157 ~86 ~27 ~158 fence 0
fill ~81 ~21 ~158 ~81 ~27 ~158 quartz_block
fill ~79 ~21 ~158 ~79 ~27 ~158 quartz_block
fill ~74 ~27 ~157 ~74 ~27 ~158 fence 0
fill ~80 ~24 ~157 ~80 ~27 ~157 quartz_block
fill ~101 ~27 ~149 ~102 ~27 ~149 fence 0
fill ~58 ~27 ~149 ~59 ~27 ~149 fence 0
fill ~59 ~26 ~149 ~59 ~27 ~149 fence 0
fill ~102 ~21 ~144 ~102 ~27 ~144 quartz_block
fill ~57 ~23 ~144 ~57 ~27 ~144 quartz_block
fill ~101 ~24 ~143 ~101 ~27 ~143 quartz_block
fill ~59 ~24 ~143 ~59 ~27 ~143 quartz_block
fill ~102 ~21 ~142 ~102 ~27 ~142 quartz_block
fill ~57 ~23 ~142 ~57 ~27 ~142 quartz_block
fill ~101 ~27 ~137 ~102 ~27 ~137 fence 0
fill ~58 ~27 ~137 ~59 ~27 ~137 fence 0
fill ~59 ~26 ~137 ~59 ~27 ~137 fence 0
fill ~79 ~27 ~129 ~81 ~27 ~129 stone
fill ~81 ~9 ~129 ~81 ~27 ~129 stone
fill ~81 ~27 ~126 ~81 ~27 ~129 stone
fill ~82 ~27 ~128 ~84 ~27 ~128 grass
fill ~84 ~27 ~126 ~84 ~27 ~128 grass
fill ~79 ~27 ~128 ~80 ~27 ~128 stone
fill ~80 ~15 ~128 ~80 ~27 ~128 stone
fill ~80 ~27 ~106 ~80 ~27 ~128 stone
fill ~76 ~27 ~128 ~78 ~27 ~128 grass
fill ~85 ~27 ~114 ~85 ~27 ~127 grass
fill ~82 ~16 ~127 ~82 ~27 ~127 stone
fill ~82 ~27 ~82 ~82 ~27 ~127 stone
fill ~78 ~27 ~127 ~79 ~27 ~127 stone
fill ~79 ~14 ~127 ~79 ~27 ~127 stone
fill ~79 ~27 ~125 ~79 ~27 ~127 stone
fill ~75 ~27 ~127 ~77 ~27 ~127 grass
fill ~83 ~18 ~126 ~83 ~27 ~126 stone
fill ~77 ~27 ~126 ~78 ~27 ~126 stone
fill ~78 ~17 ~126 ~78 ~27 ~126 stone
fill ~78 ~27 ~97 ~78 ~27 ~126 stone
fill ~75 ~27 ~126 ~76 ~27 ~126 grass
fill ~83 ~27 ~125 ~84 ~27 ~125 wood
fill ~76 ~27 ~125 ~77 ~27 ~125 wood
fill ~75 ~27 ~109 ~75 ~27 ~125 grass
fill ~83 ~27 ~124 ~84 ~27 ~124 grass
fill ~84 ~27 ~115 ~84 ~27 ~124 grass
fill ~81 ~16 ~124 ~81 ~27 ~124 stone
fill ~81 ~27 ~89 ~81 ~27 ~124 stone
fill ~76 ~27 ~124 ~77 ~27 ~124 grass
fill ~77 ~27 ~123 ~77 ~27 ~124 grass
fill ~79 ~16 ~123 ~79 ~27 ~123 stone
fill ~79 ~27 ~90 ~79 ~27 ~123 stone
fill ~76 ~27 ~114 ~76 ~27 ~123 grass
fill ~83 ~16 ~122 ~83 ~27 ~122 stone
fill ~83 ~27 ~120 ~83 ~27 ~122 stone
fill ~77 ~18 ~122 ~77 ~27 ~122 stone
fill ~77 ~27 ~120 ~77 ~27 ~122 stone
fill ~86 ~27 ~115 ~86 ~27 ~119 grass
fill ~83 ~27 ~118 ~83 ~27 ~119 grass
fill ~77 ~27 ~117 ~77 ~27 ~119 dirt
fill ~74 ~20 ~119 ~74 ~27 ~119 stone
fill ~74 ~27 ~115 ~74 ~27 ~118 grass
fill ~83 ~8 ~117 ~83 ~27 ~117 stone
fill ~83 ~27 ~82 ~83 ~27 ~117 stone
fill ~77 ~13 ~116 ~77 ~27 ~116 stone
fill ~77 ~27 ~82 ~77 ~27 ~116 stone
fill ~86 ~27 ~113 ~86 ~27 ~114 tallgrass 1
fill ~84 ~19 ~113 ~84 ~27 ~113 stone
fill ~84 ~27 ~110 ~84 ~27 ~113 stone
fill ~76 ~17 ~113 ~76 ~27 ~113 stone
fill ~76 ~27 ~110 ~76 ~27 ~113 stone
fill ~85 ~27 ~109 ~85 ~27 ~112 grass
fill ~84 ~27 ~108 ~84 ~27 ~109 grass
fill ~76 ~27 ~108 ~76 ~27 ~109 grass
fill ~85 ~27 ~105 ~85 ~27 ~107 grass
fill ~84 ~18 ~107 ~84 ~27 ~107 stone
fill ~84 ~27 ~92 ~84 ~27 ~107 stone
fill ~76 ~27 ~106 ~76 ~27 ~107 dirt
fill ~74 ~27 ~107 ~75 ~27 ~107 grass
fill ~75 ~27 ~106 ~75 ~27 ~107 grass
fill ~74 ~27 ~105 ~74 ~27 ~106 tallgrass 1
fill ~86 ~27 ~97 ~86 ~27 ~105 grass
fill ~76 ~19 ~105 ~76 ~27 ~105 stone
fill ~76 ~27 ~96 ~76 ~27 ~105 stone
fill ~75 ~27 ~104 ~75 ~27 ~105 dirt
fill ~85 ~17 ~104 ~85 ~27 ~104 stone
fill ~85 ~27 ~93 ~85 ~27 ~104 stone
fill ~80 ~7 ~104 ~80 ~27 ~104 stone
fill ~74 ~27 ~97 ~74 ~27 ~104 grass
fill ~75 ~18 ~103 ~75 ~27 ~103 stone
fill ~75 ~27 ~95 ~75 ~27 ~103 stone
fill ~149 ~27 ~101 ~149 ~27 ~102 fence 0
fill ~144 ~21 ~102 ~144 ~27 ~102 quartz_block
fill ~142 ~21 ~102 ~142 ~27 ~102 quartz_block
fill ~137 ~27 ~101 ~137 ~27 ~102 fence 0
fill ~80 ~6 ~102 ~80 ~27 ~102 stone
fill ~23 ~27 ~101 ~23 ~27 ~102 fence 0
fill ~18 ~21 ~102 ~18 ~27 ~102 quartz_block
fill ~16 ~21 ~102 ~16 ~27 ~102 quartz_block
fill ~11 ~27 ~101 ~11 ~27 ~102 fence 0
fill ~143 ~24 ~101 ~143 ~27 ~101 quartz_block
fill ~17 ~24 ~101 ~17 ~27 ~101 quartz_block
fill ~80 ~11 ~100 ~80 ~27 ~100 stone
fill ~87 ~27 ~94 ~87 ~27 ~99 grass
fill ~73 ~27 ~95 ~73 ~27 ~99 grass
fill ~80 ~23 ~98 ~80 ~27 ~98 stone
fill ~86 ~22 ~96 ~86 ~27 ~96 stone
fill ~86 ~27 ~94 ~86 ~27 ~96 stone
fill ~80 ~21 ~96 ~80 ~27 ~96 stone
fill ~74 ~21 ~95 ~74 ~27 ~95 stone
fill ~80 ~15 ~94 ~80 ~27 ~94 stone
fill ~73 ~26 ~94 ~73 ~27 ~94 stone 3
fill ~78 ~13 ~93 ~78 ~27 ~93 stone
fill ~78 ~27 ~82 ~78 ~27 ~93 stone
fill ~80 ~10 ~92 ~80 ~27 ~92 stone
fill ~89 ~14 ~90 ~89 ~27 ~90 stone
fill ~89 ~27 ~82 ~89 ~27 ~90 stone
fill ~80 ~3 ~90 ~80 ~27 ~90 stone
fill ~80 ~27 ~89 ~80 ~27 ~90 stone
fill ~76 ~9 ~90 ~76 ~27 ~90 stone
fill ~76 ~27 ~82 ~76 ~27 ~90 stone
fill ~84 ~27 ~89 ~85 ~27 ~89 stone
fill ~85 ~4 ~89 ~85 ~27 ~89 stone
fill ~85 ~27 ~82 ~85 ~27 ~89 stone
fill ~79 ~27 ~72 ~79 ~27 ~89 double_wooden_slab 1
fill ~70 ~27 ~89 ~75 ~27 ~89 stone
fill ~75 ~10 ~89 ~75 ~27 ~89 stone
fill ~75 ~27 ~82 ~75 ~27 ~89 stone
fill ~88 ~10 ~88 ~88 ~27 ~88 stone
fill ~88 ~27 ~82 ~88 ~27 ~88 stone
fill ~86 ~4 ~88 ~86 ~27 ~88 stone
fill ~86 ~27 ~82 ~86 ~27 ~88 stone
fill ~84 ~1 ~88 ~84 ~27 ~88 stone
fill ~84 ~27 ~82 ~84 ~27 ~88 stone
fill ~81 ~27 ~71 ~81 ~27 ~88 double_wooden_slab 1
fill ~74 ~9 ~88 ~74 ~27 ~88 stone
fill ~74 ~27 ~82 ~74 ~27 ~88 stone
fill ~72 ~10 ~88 ~72 ~27 ~88 stone
fill ~95 ~27 ~87 ~99 ~27 ~87 grass
fill ~99 ~27 ~86 ~99 ~27 ~87 grass
fill ~94 ~26 ~87 ~94 ~27 ~87 stone 3
fill ~87 ~7 ~87 ~87 ~27 ~87 stone
fill ~87 ~27 ~82 ~87 ~27 ~87 stone
fill ~80 ~0 ~87 ~80 ~27 ~87 stone
fill ~73 ~8 ~87 ~73 ~27 ~87 stone
fill ~73 ~27 ~82 ~73 ~27 ~87 stone
fill ~61 ~27 ~87 ~66 ~27 ~87 grass
fill ~157 ~27 ~86 ~158 ~27 ~86 fence 0
fill ~120 ~27 ~84 ~120 ~27 ~86 grass
fill ~119 ~20 ~86 ~119 ~27 ~86 stone
fill ~115 ~27 ~86 ~118 ~27 ~86 grass
fill ~118 ~27 ~84 ~118 ~27 ~86 grass
fill ~107 ~27 ~85 ~107 ~27 ~86 grass
fill ~105 ~27 ~86 ~106 ~27 ~86 tallgrass 1
fill ~100 ~27 ~86 ~104 ~27 ~86 grass
fill ~97 ~27 ~86 ~98 ~27 ~86 grass
fill ~95 ~21 ~86 ~95 ~27 ~86 stone
fill ~95 ~27 ~85 ~95 ~27 ~86 stone
fill ~72 ~9 ~86 ~72 ~27 ~86 stone
fill ~72 ~27 ~82 ~72 ~27 ~86 stone
fill ~64 ~27 ~86 ~67 ~27 ~86 stone
fill ~67 ~19 ~86 ~67 ~27 ~86 stone
fill ~55 ~27 ~86 ~63 ~27 ~86 grass
fill ~46 ~27 ~86 ~47 ~27 ~86 tallgrass 1
fill ~41 ~27 ~86 ~45 ~27 ~86 grass
fill ~45 ~27 ~84 ~45 ~27 ~86 grass
fill ~2 ~27 ~86 ~3 ~27 ~86 fence 0
fill ~3 ~26 ~86 ~3 ~27 ~86 fence 0
fill ~121 ~27 ~85 ~127 ~27 ~85 grass
fill ~127 ~27 ~83 ~127 ~27 ~85 grass
fill ~119 ~27 ~84 ~119 ~27 ~85 grass
fill ~109 ~27 ~85 ~117 ~27 ~85 grass
fill ~117 ~27 ~84 ~117 ~27 ~85 grass
fill ~104 ~27 ~85 ~105 ~27 ~85 dirt
fill ~96 ~27 ~85 ~103 ~27 ~85 stone
fill ~103 ~18 ~85 ~103 ~27 ~85 stone
fill ~103 ~27 ~81 ~103 ~27 ~85 stone
fill ~80 ~0 ~85 ~80 ~27 ~85 stone
fill ~70 ~27 ~85 ~71 ~27 ~85 stone
fill ~71 ~9 ~85 ~71 ~27 ~85 stone
fill ~71 ~27 ~80 ~71 ~27 ~85 stone
fill ~68 ~16 ~85 ~68 ~27 ~85 stone
fill ~68 ~27 ~77 ~68 ~27 ~85 stone
fill ~56 ~27 ~85 ~66 ~27 ~85 stone
fill ~66 ~22 ~85 ~66 ~27 ~85 stone
fill ~66 ~27 ~77 ~66 ~27 ~85 stone
fill ~53 ~27 ~85 ~55 ~27 ~85 grass
fill ~48 ~27 ~85 ~51 ~27 ~85 grass
fill ~51 ~27 ~84 ~51 ~27 ~85 grass
fill ~33 ~27 ~85 ~44 ~27 ~85 grass
fill ~44 ~27 ~84 ~44 ~27 ~85 grass
fill ~128 ~27 ~82 ~128 ~27 ~84 grass
fill ~125 ~27 ~83 ~125 ~27 ~84 wood
fill ~121 ~27 ~84 ~124 ~27 ~84 grass
fill ~124 ~27 ~83 ~124 ~27 ~84 grass
fill ~114 ~27 ~84 ~116 ~27 ~84 grass
fill ~110 ~27 ~84 ~113 ~27 ~84 stone
fill ~113 ~17 ~84 ~113 ~27 ~84 stone
fill ~113 ~27 ~76 ~113 ~27 ~84 stone
fill ~108 ~27 ~84 ~109 ~27 ~84 grass
fill ~106 ~27 ~84 ~107 ~27 ~84 dirt
fill ~104 ~27 ~84 ~105 ~27 ~84 stone
fill ~105 ~19 ~84 ~105 ~27 ~84 stone
fill ~105 ~27 ~81 ~105 ~27 ~84 stone
fill ~96 ~27 ~84 ~102 ~27 ~84 stone
fill ~102 ~16 ~84 ~102 ~27 ~84 stone
fill ~102 ~27 ~75 ~102 ~27 ~84 stone
fill ~90 ~6 ~84 ~90 ~27 ~84 stone
fill ~90 ~27 ~77 ~90 ~27 ~84 stone
fill ~69 ~13 ~84 ~69 ~27 ~84 stone
fill ~69 ~27 ~81 ~69 ~27 ~84 stone
fill ~67 ~16 ~84 ~67 ~27 ~84 stone
fill ~67 ~27 ~81 ~67 ~27 ~84 stone
fill ~53 ~27 ~84 ~65 ~27 ~84 stone
fill ~65 ~21 ~84 ~65 ~27 ~84 stone
fill ~65 ~27 ~81 ~65 ~27 ~84 stone
fill ~47 ~27 ~84 ~50 ~27 ~84 stone
fill ~50 ~21 ~84 ~50 ~27 ~84 stone
fill ~50 ~27 ~76 ~50 ~27 ~84 stone
fill ~36 ~27 ~84 ~43 ~27 ~84 grass
fill ~32 ~27 ~84 ~34 ~27 ~84 grass
fill ~126 ~18 ~83 ~126 ~27 ~83 stone
fill ~126 ~27 ~77 ~126 ~27 ~83 stone
fill ~120 ~27 ~83 ~122 ~27 ~83 stone
fill ~122 ~18 ~83 ~122 ~27 ~83 stone
fill ~122 ~27 ~77 ~122 ~27 ~83 stone
fill ~117 ~27 ~83 ~119 ~27 ~83 dirt
fill ~114 ~27 ~83 ~116 ~27 ~83 stone
fill ~116 ~13 ~83 ~116 ~27 ~83 stone
fill ~116 ~27 ~77 ~116 ~27 ~83 stone
fill ~106 ~27 ~83 ~112 ~27 ~83 stone
fill ~112 ~16 ~83 ~112 ~27 ~83 stone
fill ~112 ~27 ~76 ~112 ~27 ~83 stone
fill ~104 ~16 ~83 ~104 ~27 ~83 stone
fill ~104 ~27 ~75 ~104 ~27 ~83 stone
fill ~97 ~27 ~83 ~101 ~27 ~83 stone
fill ~101 ~16 ~83 ~101 ~27 ~83 stone
fill ~101 ~27 ~81 ~101 ~27 ~83 stone
fill ~91 ~27 ~83 ~95 ~27 ~83 stone
fill ~95 ~18 ~83 ~95 ~27 ~83 stone
fill ~80 ~0 ~83 ~80 ~27 ~83 stone
fill ~70 ~11 ~83 ~70 ~27 ~83 stone
fill ~70 ~27 ~76 ~70 ~27 ~83 stone
fill ~51 ~27 ~83 ~64 ~27 ~83 stone
fill ~64 ~21 ~83 ~64 ~27 ~83 stone
fill ~64 ~27 ~79 ~64 ~27 ~83 stone
fill ~43 ~27 ~83 ~49 ~27 ~83 stone
fill ~49 ~20 ~83 ~49 ~27 ~83 stone
fill ~49 ~27 ~76 ~49 ~27 ~83 stone
fill ~41 ~27 ~83 ~42 ~27 ~83 grass
fill ~38 ~27 ~83 ~40 ~27 ~83 stone
fill ~40 ~14 ~83 ~40 ~27 ~83 stone
fill ~40 ~27 ~77 ~40 ~27 ~83 stone
fill ~36 ~27 ~83 ~37 ~27 ~83 grass
fill ~34 ~18 ~83 ~34 ~27 ~83 stone
fill ~34 ~27 ~77 ~34 ~27 ~83 stone
fill ~32 ~27 ~83 ~33 ~27 ~83 grass
fill ~127 ~15 ~82 ~127 ~27 ~82 stone
fill ~127 ~27 ~78 ~127 ~27 ~82 stone
fill ~123 ~27 ~82 ~125 ~27 ~82 stone
fill ~125 ~17 ~82 ~125 ~27 ~82 stone
fill ~117 ~27 ~82 ~121 ~27 ~82 stone
fill ~121 ~15 ~82 ~121 ~27 ~82 stone
fill ~121 ~27 ~77 ~121 ~27 ~82 stone
fill ~114 ~27 ~82 ~115 ~27 ~82 stone
fill ~115 ~11 ~82 ~115 ~27 ~82 stone
fill ~115 ~27 ~77 ~115 ~27 ~82 stone
fill ~106 ~27 ~82 ~111 ~27 ~82 stone
fill ~111 ~17 ~82 ~111 ~27 ~82 stone
fill ~111 ~27 ~76 ~111 ~27 ~82 stone
fill ~96 ~27 ~82 ~100 ~27 ~82 stone
fill ~100 ~17 ~82 ~100 ~27 ~82 stone
fill ~100 ~27 ~75 ~100 ~27 ~82 stone
fill ~91 ~27 ~82 ~93 ~27 ~82 stone
fill ~93 ~16 ~82 ~93 ~27 ~82 stone
fill ~93 ~27 ~81 ~93 ~27 ~82 stone
fill ~51 ~27 ~82 ~63 ~27 ~82 stone
fill ~63 ~21 ~82 ~63 ~27 ~82 stone
fill ~63 ~27 ~81 ~63 ~27 ~82 stone
fill ~41 ~27 ~82 ~48 ~27 ~82 stone
fill ~48 ~17 ~82 ~48 ~27 ~82 stone
fill ~48 ~27 ~76 ~48 ~27 ~82 stone
fill ~35 ~27 ~82 ~39 ~27 ~82 stone
fill ~39 ~14 ~82 ~39 ~27 ~82 stone
fill ~39 ~27 ~77 ~39 ~27 ~82 stone
fill ~33 ~16 ~82 ~33 ~27 ~82 stone
fill ~33 ~27 ~78 ~33 ~27 ~82 stone
fill ~158 ~21 ~81 ~158 ~27 ~81 quartz_block
fill ~128 ~27 ~81 ~129 ~27 ~81 stone
fill ~129 ~8 ~81 ~129 ~27 ~81 stone
fill ~129 ~27 ~79 ~129 ~27 ~81 stone
fill ~123 ~27 ~81 ~124 ~27 ~81 stone
fill ~124 ~16 ~81 ~124 ~27 ~81 stone
fill ~124 ~27 ~80 ~124 ~27 ~81 stone
fill ~117 ~27 ~81 ~120 ~27 ~81 stone
fill ~120 ~12 ~81 ~120 ~27 ~81 stone
fill ~120 ~27 ~77 ~120 ~27 ~81 stone
fill ~114 ~13 ~81 ~114 ~27 ~81 stone
fill ~114 ~27 ~77 ~114 ~27 ~81 stone
fill ~106 ~27 ~81 ~110 ~27 ~81 stone
fill ~110 ~16 ~81 ~110 ~27 ~81 stone
fill ~110 ~27 ~76 ~110 ~27 ~81 stone
fill ~94 ~27 ~81 ~99 ~27 ~81 stone
fill ~99 ~19 ~81 ~99 ~27 ~81 stone
fill ~91 ~27 ~81 ~92 ~27 ~81 stone
fill ~92 ~13 ~81 ~92 ~27 ~81 stone
fill ~92 ~27 ~79 ~92 ~27 ~81 stone
fill ~82 ~27 ~81 ~89 ~27 ~81 double_wooden_slab 1
fill ~80 ~27 ~79 ~80 ~27 ~81 double_wooden_slab 1
fill ~72 ~27 ~81 ~78 ~27 ~81 double_wooden_slab 1
fill ~51 ~27 ~81 ~62 ~27 ~81 stone
fill ~62 ~22 ~81 ~62 ~27 ~81 stone
fill ~62 ~27 ~75 ~62 ~27 ~81 stone
fill ~41 ~27 ~81 ~47 ~27 ~81 stone
fill ~47 ~15 ~81 ~47 ~27 ~81 stone
fill ~47 ~27 ~76 ~47 ~27 ~81 stone
fill ~37 ~27 ~81 ~38 ~27 ~81 stone
fill ~38 ~14 ~81 ~38 ~27 ~81 stone
fill ~38 ~27 ~77 ~38 ~27 ~81 stone
fill ~35 ~16 ~81 ~35 ~27 ~81 stone
fill ~31 ~27 ~81 ~32 ~27 ~81 stone
fill ~32 ~11 ~81 ~32 ~27 ~81 stone
fill ~32 ~27 ~79 ~32 ~27 ~81 stone
fill ~1 ~23 ~81 ~1 ~27 ~81 quartz_block
fill ~157 ~24 ~80 ~157 ~27 ~80 quartz_block
fill ~128 ~15 ~80 ~128 ~27 ~80 stone
fill ~128 ~27 ~79 ~128 ~27 ~80 stone
fill ~125 ~16 ~80 ~125 ~27 ~80 stone
fill ~125 ~27 ~78 ~125 ~27 ~80 stone
fill ~123 ~15 ~80 ~123 ~27 ~80 stone
fill ~123 ~27 ~78 ~123 ~27 ~80 stone
fill ~117 ~27 ~80 ~119 ~27 ~80 stone
fill ~119 ~6 ~80 ~119 ~27 ~80 stone
fill ~119 ~27 ~78 ~119 ~27 ~80 stone
fill ~106 ~27 ~80 ~109 ~27 ~80 stone
fill ~109 ~18 ~80 ~109 ~27 ~80 stone
fill ~109 ~27 ~77 ~109 ~27 ~80 stone
fill ~98 ~23 ~80 ~98 ~27 ~80 stone
fill ~98 ~27 ~75 ~98 ~27 ~80 stone
fill ~96 ~21 ~80 ~96 ~27 ~80 stone
fill ~96 ~27 ~74 ~96 ~27 ~80 stone
fill ~94 ~16 ~80 ~94 ~27 ~80 stone
fill ~94 ~27 ~74 ~94 ~27 ~80 stone
fill ~89 ~4 ~80 ~89 ~27 ~80 stone
fill ~89 ~27 ~75 ~89 ~27 ~80 stone
fill ~87 ~0 ~80 ~87 ~27 ~80 stone
fill ~85 ~0 ~80 ~85 ~27 ~80 stone
fill ~83 ~0 ~80 ~83 ~27 ~80 stone
fill ~77 ~0 ~80 ~77 ~27 ~80 stone
fill ~75 ~0 ~80 ~75 ~27 ~80 stone
fill ~73 ~0 ~80 ~73 ~27 ~80 stone
fill ~60 ~11 ~80 ~60 ~27 ~80 stone
fill ~60 ~27 ~75 ~60 ~27 ~80 stone
fill ~58 ~6 ~80 ~58 ~27 ~80 stone
fill ~58 ~27 ~75 ~58 ~27 ~80 stone
fill ~56 ~7 ~80 ~56 ~27 ~80 stone
fill ~56 ~27 ~76 ~56 ~27 ~80 stone
fill ~51 ~27 ~80 ~54 ~27 ~80 stone
fill ~54 ~12 ~80 ~54 ~27 ~80 stone
fill ~54 ~27 ~77 ~54 ~27 ~80 stone
fill ~41 ~27 ~80 ~46 ~27 ~80 stone
fill ~46 ~12 ~80 ~46 ~27 ~80 stone
fill ~46 ~27 ~77 ~46 ~27 ~80 stone
fill ~36 ~27 ~80 ~37 ~27 ~80 stone
fill ~37 ~15 ~80 ~37 ~27 ~80 stone
fill ~37 ~27 ~78 ~37 ~27 ~80 stone
fill ~31 ~3 ~80 ~31 ~27 ~80 stone
fill ~31 ~27 ~79 ~31 ~27 ~80 stone
fill ~3 ~24 ~80 ~3 ~27 ~80 quartz_block
fill ~158 ~21 ~79 ~158 ~27 ~79 quartz_block
fill ~117 ~27 ~79 ~118 ~27 ~79 stone
fill ~118 ~4 ~79 ~118 ~27 ~79 stone
fill ~118 ~27 ~78 ~118 ~27 ~79 stone
fill ~105 ~27 ~79 ~108 ~27 ~79 stone
fill ~108 ~16 ~79 ~108 ~27 ~79 stone
fill ~108 ~27 ~77 ~108 ~27 ~79 stone
fill ~103 ~1 ~79 ~103 ~27 ~79 stone
fill ~103 ~27 ~75 ~103 ~27 ~79 stone
fill ~101 ~7 ~79 ~101 ~27 ~79 stone
fill ~101 ~27 ~75 ~101 ~27 ~79 stone
fill ~99 ~16 ~79 ~99 ~27 ~79 stone
fill ~99 ~27 ~75 ~99 ~27 ~79 stone
fill ~97 ~22 ~79 ~97 ~27 ~79 stone
fill ~97 ~27 ~75 ~97 ~27 ~79 stone
fill ~95 ~20 ~79 ~95 ~27 ~79 stone
fill ~95 ~27 ~74 ~95 ~27 ~79 stone
fill ~93 ~15 ~79 ~93 ~27 ~79 stone
fill ~93 ~27 ~76 ~93 ~27 ~79 stone
fill ~91 ~8 ~79 ~91 ~27 ~79 stone
fill ~91 ~27 ~78 ~91 ~27 ~79 stone
fill ~82 ~27 ~79 ~88 ~27 ~79 double_wooden_slab 1
fill ~71 ~27 ~79 ~78 ~27 ~79 double_wooden_slab 1
fill ~69 ~11 ~79 ~69 ~27 ~79 stone
fill ~67 ~13 ~79 ~67 ~27 ~79 stone
fill ~67 ~27 ~77 ~67 ~27 ~79 stone
fill ~65 ~15 ~79 ~65 ~27 ~79 stone
fill ~63 ~22 ~79 ~63 ~27 ~79 stone
fill ~63 ~27 ~75 ~63 ~27 ~79 stone
fill ~61 ~19 ~79 ~61 ~27 ~79 stone
fill ~61 ~27 ~75 ~61 ~27 ~79 stone
fill ~59 ~11 ~79 ~59 ~27 ~79 stone
fill ~59 ~27 ~75 ~59 ~27 ~79 stone
fill ~57 ~7 ~79 ~57 ~27 ~79 stone
fill ~57 ~27 ~75 ~57 ~27 ~79 stone
fill ~55 ~12 ~79 ~55 ~27 ~79 stone
fill ~55 ~27 ~76 ~55 ~27 ~79 stone
fill ~51 ~27 ~79 ~53 ~27 ~79 stone
fill ~53 ~17 ~79 ~53 ~27 ~79 stone
fill ~53 ~27 ~77 ~53 ~27 ~79 stone
fill ~41 ~27 ~79 ~45 ~27 ~79 stone
fill ~45 ~11 ~79 ~45 ~27 ~79 stone
fill ~45 ~27 ~77 ~45 ~27 ~79 stone
fill ~35 ~16 ~79 ~35 ~27 ~79 stone
fill ~35 ~27 ~78 ~35 ~27 ~79 stone
fill ~1 ~23 ~79 ~1 ~27 ~79 quartz_block
fill ~128 ~27 ~76 ~128 ~27 ~78 grass
fill ~124 ~16 ~78 ~124 ~27 ~78 stone
fill ~117 ~4 ~78 ~117 ~27 ~78 stone
fill ~117 ~27 ~77 ~117 ~27 ~78 stone
fill ~105 ~27 ~78 ~107 ~27 ~78 stone
fill ~107 ~15 ~78 ~107 ~27 ~78 stone
fill ~107 ~27 ~76 ~107 ~27 ~78 stone
fill ~82 ~27 ~78 ~88 ~27 ~78 stone
fill ~88 ~0 ~78 ~88 ~27 ~78 stone
fill ~88 ~27 ~74 ~88 ~27 ~78 stone
fill ~71 ~27 ~78 ~78 ~27 ~78 stone
fill ~78 ~0 ~78 ~78 ~27 ~78 stone
fill ~78 ~27 ~70 ~78 ~27 ~78 stone
fill ~51 ~27 ~78 ~52 ~27 ~78 stone
fill ~52 ~17 ~78 ~52 ~27 ~78 stone
fill ~52 ~27 ~77 ~52 ~27 ~78 stone
fill ~41 ~27 ~78 ~44 ~27 ~78 stone
fill ~44 ~9 ~78 ~44 ~27 ~78 stone
fill ~44 ~27 ~77 ~44 ~27 ~78 stone
fill ~36 ~16 ~78 ~36 ~27 ~78 stone
fill ~32 ~27 ~76 ~32 ~27 ~78 grass
fill ~127 ~27 ~75 ~127 ~27 ~77 grass
fill ~125 ~27 ~76 ~125 ~27 ~77 wood
fill ~123 ~27 ~77 ~124 ~27 ~77 grass
fill ~124 ~27 ~75 ~124 ~27 ~77 grass
fill ~118 ~27 ~77 ~119 ~27 ~77 grass
fill ~119 ~27 ~74 ~119 ~27 ~77 grass
fill ~105 ~27 ~77 ~106 ~27 ~77 stone
fill ~106 ~19 ~77 ~106 ~27 ~77 stone
fill ~106 ~27 ~76 ~106 ~27 ~77 stone
fill ~92 ~15 ~77 ~92 ~27 ~77 stone
fill ~92 ~27 ~75 ~92 ~27 ~77 stone
fill ~82 ~27 ~77 ~87 ~27 ~77 stone
fill ~87 ~0 ~77 ~87 ~27 ~77 stone
fill ~87 ~27 ~71 ~87 ~27 ~77 stone
fill ~80 ~0 ~77 ~80 ~27 ~77 stone
fill ~71 ~27 ~77 ~77 ~27 ~77 stone
fill ~77 ~0 ~77 ~77 ~27 ~77 stone
fill ~77 ~27 ~70 ~77 ~27 ~77 stone
fill ~69 ~12 ~77 ~69 ~27 ~77 stone
fill ~64 ~27 ~77 ~65 ~27 ~77 stone
fill ~65 ~17 ~77 ~65 ~27 ~77 stone
fill ~51 ~18 ~77 ~51 ~27 ~77 stone
fill ~41 ~27 ~77 ~43 ~27 ~77 dirt
fill ~36 ~27 ~77 ~37 ~27 ~77 grass
fill ~37 ~27 ~75 ~37 ~27 ~77 grass
fill ~35 ~27 ~76 ~35 ~27 ~77 wood
fill ~33 ~27 ~75 ~33 ~27 ~77 grass
fill ~126 ~27 ~75 ~126 ~27 ~76 grass
fill ~120 ~27 ~76 ~123 ~27 ~76 grass
fill ~123 ~27 ~75 ~123 ~27 ~76 grass
fill ~115 ~27 ~76 ~118 ~27 ~76 grass
fill ~118 ~27 ~74 ~118 ~27 ~76 grass
fill ~108 ~27 ~76 ~109 ~27 ~76 grass
fill ~109 ~27 ~75 ~109 ~27 ~76 grass
fill ~105 ~14 ~76 ~105 ~27 ~76 stone
fill ~82 ~27 ~76 ~86 ~27 ~76 stone
fill ~86 ~0 ~76 ~86 ~27 ~76 stone
fill ~86 ~27 ~71 ~86 ~27 ~76 stone
fill ~71 ~27 ~76 ~76 ~27 ~76 stone
fill ~76 ~21 ~76 ~76 ~27 ~76 stone
fill ~76 ~27 ~71 ~76 ~27 ~76 stone
fill ~64 ~20 ~76 ~64 ~27 ~76 stone
fill ~64 ~27 ~74 ~64 ~27 ~76 stone
fill ~53 ~27 ~76 ~54 ~27 ~76 dirt
fill ~51 ~27 ~76 ~52 ~27 ~76 grass
fill ~38 ~27 ~76 ~46 ~27 ~76 grass
fill ~46 ~27 ~75 ~46 ~27 ~76 grass
fill ~36 ~27 ~75 ~36 ~27 ~76 grass
fill ~34 ~27 ~75 ~34 ~27 ~76 grass
fill ~120 ~27 ~75 ~122 ~27 ~75 grass
fill ~114 ~27 ~75 ~117 ~27 ~75 grass
fill ~117 ~27 ~74 ~117 ~27 ~75 grass
fill ~110 ~27 ~75 ~112 ~27 ~75 grass
fill ~105 ~27 ~75 ~107 ~27 ~75 grass
fill ~91 ~14 ~75 ~91 ~27 ~75 stone
fill ~82 ~27 ~75 ~85 ~27 ~75 stone
fill ~85 ~0 ~75 ~85 ~27 ~75 stone
fill ~85 ~27 ~71 ~85 ~27 ~75 stone
fill ~80 ~21 ~75 ~80 ~27 ~75 stone
fill ~71 ~27 ~75 ~75 ~27 ~75 stone
fill ~75 ~0 ~75 ~75 ~27 ~75 stone
fill ~75 ~27 ~71 ~75 ~27 ~75 stone
fill ~65 ~20 ~75 ~65 ~27 ~75 stone
fill ~55 ~27 ~75 ~56 ~27 ~75 dirt
fill ~53 ~27 ~75 ~54 ~27 ~75 grass
fill ~47 ~27 ~75 ~51 ~27 ~75 grass
fill ~38 ~27 ~75 ~45 ~27 ~75 grass
fill ~45 ~27 ~74 ~45 ~27 ~75 grass
fill ~157 ~27 ~74 ~158 ~27 ~74 fence 0
fill ~115 ~27 ~74 ~116 ~27 ~74 grass
fill ~113 ~27 ~74 ~114 ~27 ~74 tallgrass 1
fill ~97 ~27 ~74 ~105 ~27 ~74 grass
fill ~93 ~16 ~74 ~93 ~27 ~74 stone
fill ~82 ~27 ~74 ~84 ~27 ~74 stone
fill ~84 ~0 ~74 ~84 ~27 ~74 stone
fill ~84 ~27 ~70 ~84 ~27 ~74 stone
fill ~71 ~27 ~74 ~74 ~27 ~74 stone
fill ~74 ~4 ~74 ~74 ~27 ~74 stone
fill ~74 ~27 ~72 ~74 ~27 ~74 stone
fill ~66 ~26 ~74 ~66 ~27 ~74 stone 3
fill ~66 ~27 ~73 ~66 ~27 ~74 stone 3
fill ~56 ~27 ~74 ~63 ~27 ~74 grass
fill ~63 ~27 ~73 ~63 ~27 ~74 grass
fill ~54 ~27 ~74 ~55 ~27 ~74 tallgrass 1
fill ~42 ~27 ~74 ~44 ~27 ~74 grass
fill ~41 ~20 ~74 ~41 ~27 ~74 stone
fill ~2 ~27 ~74 ~3 ~27 ~74 fence 0
fill ~3 ~26 ~74 ~3 ~27 ~74 fence 0
fill ~94 ~27 ~73 ~99 ~27 ~73 grass
fill ~82 ~27 ~73 ~83 ~27 ~73 stone
fill ~83 ~0 ~73 ~83 ~27 ~73 stone
fill ~83 ~27 ~65 ~83 ~27 ~73 stone
fill ~80 ~0 ~73 ~80 ~27 ~73 stone
fill ~73 ~10 ~73 ~73 ~27 ~73 stone
fill ~71 ~12 ~73 ~71 ~27 ~73 stone
fill ~71 ~27 ~70 ~71 ~27 ~73 stone
fill ~64 ~27 ~73 ~65 ~27 ~73 grass
fill ~61 ~27 ~73 ~62 ~27 ~73 grass
fill ~88 ~13 ~72 ~88 ~27 ~72 stone
fill ~88 ~27 ~71 ~88 ~27 ~72 stone
fill ~82 ~0 ~72 ~82 ~27 ~72 stone
fill ~82 ~27 ~70 ~82 ~27 ~72 stone
fill ~72 ~13 ~72 ~72 ~27 ~72 stone
fill ~72 ~27 ~71 ~72 ~27 ~72 stone
fill ~89 ~27 ~71 ~90 ~27 ~71 stone
fill ~90 ~15 ~71 ~90 ~27 ~71 stone
fill ~79 ~27 ~71 ~80 ~27 ~71 stone
fill ~80 ~2 ~71 ~80 ~27 ~71 stone
fill ~80 ~27 ~70 ~80 ~27 ~71 stone
fill ~81 ~4 ~70 ~81 ~27 ~70 stone
fill ~81 ~27 ~37 ~81 ~27 ~70 stone
fill ~79 ~10 ~70 ~79 ~27 ~70 stone
fill ~79 ~27 ~37 ~79 ~27 ~70 stone
fill ~82 ~13 ~68 ~82 ~27 ~68 stone
fill ~82 ~27 ~66 ~82 ~27 ~68 stone
fill ~80 ~13 ~68 ~80 ~27 ~68 stone
fill ~78 ~14 ~68 ~78 ~27 ~68 stone
fill ~78 ~27 ~33 ~78 ~27 ~68 stone
fill ~76 ~14 ~68 ~76 ~27 ~68 stone
fill ~76 ~27 ~53 ~76 ~27 ~68 stone
fill ~77 ~15 ~67 ~77 ~27 ~67 stone
fill ~77 ~27 ~43 ~77 ~27 ~67 stone
fill ~75 ~17 ~67 ~75 ~27 ~67 stone
fill ~75 ~27 ~56 ~75 ~27 ~67 stone
fill ~87 ~26 ~66 ~87 ~27 ~66 stone 3
fill ~80 ~18 ~66 ~80 ~27 ~66 stone
fill ~74 ~22 ~66 ~74 ~27 ~66 stone
fill ~74 ~27 ~64 ~74 ~27 ~66 stone
fill ~73 ~27 ~61 ~73 ~27 ~66 grass
fill ~87 ~27 ~61 ~87 ~27 ~65 grass
fill ~85 ~20 ~65 ~85 ~27 ~65 stone
fill ~85 ~27 ~57 ~85 ~27 ~65 stone
fill ~86 ~21 ~64 ~86 ~27 ~64 stone
fill ~84 ~20 ~64 ~84 ~27 ~64 stone
fill ~84 ~27 ~55 ~84 ~27 ~64 stone
fill ~82 ~19 ~64 ~82 ~27 ~64 stone
fill ~82 ~27 ~33 ~82 ~27 ~64 stone
fill ~80 ~19 ~64 ~80 ~27 ~64 stone
fill ~86 ~27 ~56 ~86 ~27 ~63 grass
fill ~83 ~20 ~63 ~83 ~27 ~63 stone
fill ~83 ~27 ~44 ~83 ~27 ~63 stone
fill ~74 ~27 ~55 ~74 ~27 ~63 grass
fill ~80 ~23 ~62 ~80 ~27 ~62 stone
fill ~80 ~11 ~60 ~80 ~27 ~60 stone
fill ~149 ~26 ~59 ~149 ~27 ~59 fence 0
fill ~149 ~27 ~58 ~149 ~27 ~59 fence 0
fill ~143 ~24 ~59 ~143 ~27 ~59 quartz_block
fill ~137 ~26 ~59 ~137 ~27 ~59 fence 0
fill ~137 ~27 ~58 ~137 ~27 ~59 fence 0
fill ~23 ~26 ~59 ~23 ~27 ~59 fence 0
fill ~23 ~27 ~58 ~23 ~27 ~59 fence 0
fill ~17 ~24 ~59 ~17 ~27 ~59 quartz_block
fill ~11 ~26 ~59 ~11 ~27 ~59 fence 0
fill ~11 ~27 ~58 ~11 ~27 ~59 fence 0
fill ~80 ~6 ~58 ~80 ~27 ~58 stone
fill ~144 ~23 ~57 ~144 ~27 ~57 quartz_block
fill ~142 ~23 ~57 ~142 ~27 ~57 quartz_block
fill ~18 ~23 ~57 ~18 ~27 ~57 quartz_block
fill ~16 ~23 ~57 ~16 ~27 ~57 quartz_block
fill ~85 ~27 ~55 ~85 ~27 ~56 dirt
fill ~80 ~7 ~56 ~80 ~27 ~56 stone
fill ~86 ~27 ~54 ~86 ~27 ~55 tallgrass 1
fill ~75 ~27 ~53 ~75 ~27 ~55 grass
fill ~85 ~27 ~53 ~85 ~27 ~54 grass
fill ~84 ~27 ~53 ~84 ~27 ~54 dirt
fill ~80 ~12 ~54 ~80 ~27 ~54 stone
fill ~80 ~27 ~36 ~80 ~27 ~54 stone
fill ~84 ~27 ~51 ~84 ~27 ~52 grass
fill ~76 ~27 ~51 ~76 ~27 ~52 grass
fill ~85 ~27 ~33 ~85 ~27 ~51 grass
fill ~75 ~27 ~48 ~75 ~27 ~51 grass
fill ~84 ~18 ~50 ~84 ~27 ~50 stone
fill ~84 ~27 ~47 ~84 ~27 ~50 stone
fill ~76 ~21 ~50 ~76 ~27 ~50 stone
fill ~76 ~27 ~47 ~76 ~27 ~50 stone
fill ~74 ~27 ~46 ~74 ~27 ~47 tallgrass 1
fill ~84 ~27 ~36 ~84 ~27 ~46 grass
fill ~75 ~27 ~33 ~75 ~27 ~46 grass
fill ~86 ~27 ~42 ~86 ~27 ~45 grass
fill ~76 ~27 ~36 ~76 ~27 ~45 grass
fill ~74 ~27 ~41 ~74 ~27 ~45 grass
fill ~83 ~27 ~41 ~83 ~27 ~43 dirt
fill ~77 ~27 ~41 ~77 ~27 ~42 grass
fill ~86 ~20 ~41 ~86 ~27 ~41 stone
fill ~83 ~15 ~40 ~83 ~27 ~40 stone
fill ~83 ~27 ~38 ~83 ~27 ~40 stone
fill ~77 ~14 ~40 ~77 ~27 ~40 stone
fill ~77 ~27 ~38 ~77 ~27 ~40 stone
fill ~83 ~27 ~36 ~83 ~27 ~37 grass
fill ~77 ~27 ~36 ~77 ~27 ~37 grass
fill ~81 ~16 ~35 ~81 ~27 ~35 stone
fill ~81 ~27 ~31 ~81 ~27 ~35 stone
fill ~79 ~16 ~35 ~79 ~27 ~35 stone
fill ~79 ~27 ~31 ~79 ~27 ~35 stone
fill ~76 ~27 ~35 ~77 ~27 ~35 wood
fill ~84 ~27 ~32 ~84 ~27 ~34 grass
fill ~83 ~18 ~34 ~83 ~27 ~34 stone
fill ~80 ~15 ~34 ~80 ~27 ~34 stone
fill ~80 ~27 ~31 ~80 ~27 ~34 stone
fill ~77 ~18 ~34 ~77 ~27 ~34 stone
fill ~76 ~27 ~32 ~76 ~27 ~34 grass
fill ~83 ~27 ~32 ~83 ~27 ~33 grass
fill ~77 ~27 ~32 ~77 ~27 ~33 grass
fill ~101 ~27 ~23 ~102 ~27 ~23 fence 0
fill ~58 ~27 ~23 ~59 ~27 ~23 fence 0
fill ~59 ~26 ~23 ~59 ~27 ~23 fence 0
fill ~102 ~21 ~18 ~102 ~27 ~18 quartz_block
fill ~57 ~23 ~18 ~57 ~27 ~18 quartz_block
fill ~101 ~24 ~17 ~101 ~27 ~17 quartz_block
fill ~59 ~24 ~17 ~59 ~27 ~17 quartz_block
fill ~102 ~21 ~16 ~102 ~27 ~16 quartz_block
fill ~57 ~23 ~16 ~57 ~27 ~16 quartz_block
fill ~101 ~27 ~11 ~102 ~27 ~11 fence 0
fill ~58 ~27 ~11 ~59 ~27 ~11 fence 0
fill ~59 ~26 ~11 ~59 ~27 ~11 fence 0
fill ~86 ~26 ~3 ~86 ~27 ~3 fence 0
fill ~86 ~27 ~2 ~86 ~27 ~3 fence 0
fill ~80 ~24 ~3 ~80 ~27 ~3 quartz_block
fill ~74 ~26 ~3 ~74 ~27 ~3 fence 0
fill ~74 ~27 ~2 ~74 ~27 ~3 fence 0
fill ~81 ~23 ~1 ~81 ~27 ~1 quartz_block
fill ~79 ~23 ~1 ~79 ~27 ~1 quartz_block
fill ~83 ~25 ~159 ~83 ~26 ~159 fence 0
fill ~82 ~25 ~159 ~82 ~26 ~159 quartz_block
fill ~78 ~25 ~159 ~78 ~26 ~159 quartz_block
fill ~77 ~25 ~159 ~77 ~26 ~159 fence 0
fill ~86 ~26 ~157 ~87 ~26 ~157 fence 0
fill ~84 ~25 ~157 ~84 ~26 ~157 wood
fill ~76 ~25 ~157 ~76 ~26 ~157 wood
fill ~73 ~26 ~157 ~74 ~26 ~157 fence 0
fill ~86 ~26 ~150 ~86 ~26 ~151 fence 0
fill ~74 ~26 ~150 ~74 ~26 ~151 fence 0
fill ~101 ~26 ~149 ~101 ~26 ~150 fence 0
fill ~87 ~25 ~150 ~87 ~26 ~150 wood
fill ~87 ~26 ~149 ~87 ~26 ~150 wood
fill ~73 ~25 ~150 ~73 ~26 ~150 wood
fill ~73 ~26 ~149 ~73 ~26 ~150 wood
fill ~101 ~25 ~147 ~101 ~26 ~147 wood
fill ~59 ~25 ~147 ~59 ~26 ~147 wood
fill ~103 ~25 ~146 ~103 ~26 ~146 fence 0
fill ~57 ~25 ~146 ~57 ~26 ~146 fence 0
fill ~103 ~25 ~145 ~103 ~26 ~145 quartz_block
fill ~57 ~25 ~145 ~57 ~26 ~145 quartz_block
fill ~103 ~25 ~141 ~103 ~26 ~141 quartz_block
fill ~57 ~25 ~141 ~57 ~26 ~141 quartz_block
fill ~103 ~25 ~140 ~103 ~26 ~140 fence 0
fill ~57 ~25 ~140 ~57 ~26 ~140 fence 0
fill ~101 ~25 ~139 ~101 ~26 ~139 wood
fill ~59 ~25 ~139 ~59 ~26 ~139 wood
fill ~101 ~26 ~136 ~101 ~26 ~137 fence 0
fill ~78 ~26 ~134 ~82 ~26 ~134 grass
fill ~82 ~26 ~131 ~82 ~26 ~134 grass
fill ~78 ~26 ~133 ~81 ~26 ~133 grass
fill ~81 ~26 ~130 ~81 ~26 ~133 grass
fill ~83 ~26 ~131 ~83 ~26 ~132 grass
fill ~77 ~26 ~132 ~80 ~26 ~132 grass
fill ~80 ~8 ~131 ~80 ~26 ~131 stone
fill ~80 ~26 ~129 ~80 ~26 ~131 stone
fill ~76 ~26 ~131 ~79 ~26 ~131 grass
fill ~79 ~26 ~130 ~79 ~26 ~131 grass
fill ~85 ~26 ~128 ~85 ~26 ~130 grass
fill ~83 ~26 ~130 ~84 ~26 ~130 wood
fill ~82 ~12 ~130 ~82 ~26 ~130 stone
fill ~82 ~26 ~128 ~82 ~26 ~130 stone
fill ~78 ~11 ~130 ~78 ~26 ~130 stone
fill ~78 ~26 ~127 ~78 ~26 ~130 stone
fill ~76 ~26 ~130 ~77 ~26 ~130 wood
fill ~75 ~26 ~128 ~75 ~26 ~130 grass
fill ~83 ~16 ~129 ~83 ~26 ~129 stone
fill ~83 ~26 ~127 ~83 ~26 ~129 stone
fill ~79 ~8 ~129 ~79 ~26 ~129 stone
fill ~79 ~26 ~128 ~79 ~26 ~129 stone
fill ~77 ~14 ~129 ~77 ~26 ~129 stone
fill ~77 ~26 ~123 ~77 ~26 ~129 stone
fill ~81 ~11 ~128 ~81 ~26 ~128 stone
fill ~81 ~26 ~126 ~81 ~26 ~128 stone
fill ~88 ~24 ~127 ~88 ~26 ~127 stone 6
fill ~84 ~26 ~127 ~85 ~26 ~127 stone
fill ~85 ~22 ~127 ~85 ~26 ~127 stone
fill ~85 ~26 ~125 ~85 ~26 ~127 stone
fill ~80 ~12 ~127 ~80 ~26 ~127 stone
fill ~80 ~26 ~106 ~80 ~26 ~127 stone
fill ~75 ~26 ~127 ~76 ~26 ~127 stone
fill ~76 ~19 ~127 ~76 ~26 ~127 stone
fill ~76 ~26 ~114 ~76 ~26 ~127 stone
fill ~72 ~24 ~127 ~72 ~26 ~127 stone 6
fill ~86 ~26 ~120 ~86 ~26 ~126 grass
fill ~84 ~20 ~126 ~84 ~26 ~126 stone
fill ~84 ~26 ~114 ~84 ~26 ~126 stone
fill ~82 ~17 ~126 ~82 ~26 ~126 stone
fill ~82 ~26 ~73 ~82 ~26 ~126 stone
fill ~79 ~15 ~126 ~79 ~26 ~126 stone
fill ~79 ~26 ~125 ~79 ~26 ~126 stone
fill ~75 ~21 ~126 ~75 ~26 ~126 stone
fill ~75 ~26 ~125 ~75 ~26 ~126 stone
fill ~74 ~26 ~121 ~74 ~26 ~126 grass
fill ~83 ~18 ~125 ~83 ~26 ~125 stone
fill ~83 ~26 ~123 ~83 ~26 ~125 stone
fill ~78 ~17 ~125 ~78 ~26 ~125 stone
fill ~78 ~26 ~97 ~78 ~26 ~125 stone
fill ~85 ~19 ~123 ~85 ~26 ~123 stone
fill ~85 ~26 ~109 ~85 ~26 ~123 stone
fill ~81 ~15 ~123 ~81 ~26 ~123 stone
fill ~81 ~26 ~71 ~81 ~26 ~123 stone
fill ~75 ~20 ~123 ~75 ~26 ~123 stone
fill ~75 ~26 ~109 ~75 ~26 ~123 stone
fill ~79 ~16 ~122 ~79 ~26 ~122 stone
fill ~79 ~26 ~71 ~79 ~26 ~122 stone
fill ~83 ~15 ~121 ~83 ~26 ~121 stone
fill ~83 ~26 ~118 ~83 ~26 ~121 stone
fill ~77 ~16 ~121 ~77 ~26 ~121 stone
fill ~77 ~26 ~117 ~77 ~26 ~121 stone
fill ~74 ~20 ~120 ~74 ~26 ~120 stone
fill ~87 ~26 ~116 ~87 ~26 ~118 grass
fill ~86 ~17 ~118 ~86 ~26 ~118 stone
fill ~86 ~26 ~116 ~86 ~26 ~118 stone
fill ~74 ~19 ~118 ~74 ~26 ~118 stone
fill ~74 ~26 ~115 ~74 ~26 ~118 stone
fill ~73 ~26 ~116 ~73 ~26 ~118 grass
fill ~83 ~11 ~116 ~83 ~26 ~116 stone
fill ~83 ~26 ~81 ~83 ~26 ~116 stone
fill ~77 ~13 ~115 ~77 ~26 ~115 stone
fill ~77 ~26 ~81 ~77 ~26 ~115 stone
fill ~86 ~26 ~106 ~86 ~26 ~114 grass
fill ~74 ~26 ~108 ~74 ~26 ~114 grass
fill ~66 ~24 ~113 ~66 ~26 ~113 end_stone
fill ~66 ~26 ~109 ~66 ~26 ~113 end_stone
fill ~64 ~26 ~113 ~65 ~26 ~113 sandstone
fill ~58 ~26 ~113 ~59 ~26 ~113 end_stone
fill ~59 ~26 ~112 ~59 ~26 ~113 end_stone
fill ~57 ~26 ~109 ~57 ~26 ~113 sandstone
fill ~98 ~26 ~112 ~99 ~26 ~112 sandstone
fill ~97 ~25 ~112 ~97 ~26 ~112 end_stone
fill ~84 ~19 ~112 ~84 ~26 ~112 stone
fill ~84 ~26 ~108 ~84 ~26 ~112 stone
fill ~76 ~18 ~112 ~76 ~26 ~112 stone
fill ~76 ~26 ~106 ~76 ~26 ~112 stone
fill ~67 ~25 ~112 ~67 ~26 ~112 sandstone
fill ~67 ~26 ~111 ~67 ~26 ~112 sandstone
fill ~64 ~26 ~112 ~65 ~26 ~112 end_stone
fill ~63 ~26 ~111 ~63 ~26 ~112 sandstone
fill ~61 ~26 ~112 ~62 ~26 ~112 grass
fill ~60 ~26 ~111 ~60 ~26 ~112 sandstone
fill ~56 ~25 ~112 ~56 ~26 ~112 sandstone
fill ~102 ~22 ~111 ~102 ~26 ~111 end_stone
fill ~101 ~25 ~111 ~101 ~26 ~111 sandstone
fill ~101 ~26 ~109 ~101 ~26 ~111 sandstone
fill ~99 ~26 ~111 ~100 ~26 ~111 end_stone
fill ~100 ~25 ~111 ~100 ~26 ~111 end_stone
fill ~96 ~26 ~111 ~98 ~26 ~111 sandstone
fill ~64 ~23 ~111 ~64 ~26 ~111 sandstone
fill ~62 ~26 ~110 ~62 ~26 ~111 sandstone
fill ~61 ~26 ~110 ~61 ~26 ~111 grass
fill ~59 ~26 ~109 ~59 ~26 ~111 sandstone
fill ~56 ~26 ~110 ~56 ~26 ~111 end_stone
fill ~53 ~25 ~111 ~53 ~26 ~111 sandstone
fill ~104 ~26 ~110 ~106 ~26 ~110 sandstone
fill ~106 ~24 ~110 ~106 ~26 ~110 sandstone
fill ~106 ~26 ~108 ~106 ~26 ~110 sandstone
fill ~100 ~26 ~108 ~100 ~26 ~110 grass
fill ~98 ~26 ~110 ~99 ~26 ~110 end_stone
fill ~99 ~26 ~108 ~99 ~26 ~110 end_stone
fill ~95 ~26 ~110 ~97 ~26 ~110 sandstone
fill ~67 ~26 ~109 ~67 ~26 ~110 end_stone
fill ~64 ~26 ~110 ~65 ~26 ~110 end_stone
fill ~65 ~26 ~109 ~65 ~26 ~110 end_stone
fill ~58 ~21 ~110 ~58 ~26 ~110 sandstone
fill ~54 ~20 ~110 ~54 ~26 ~110 sandstone
fill ~53 ~25 ~110 ~53 ~26 ~110 end_stone
fill ~52 ~25 ~110 ~52 ~26 ~110 sandstone
fill ~108 ~26 ~106 ~108 ~26 ~109 sandstone
fill ~104 ~26 ~109 ~105 ~26 ~109 sandstone
fill ~105 ~24 ~109 ~105 ~26 ~109 sandstone
fill ~102 ~24 ~109 ~102 ~26 ~109 sandstone
fill ~97 ~26 ~108 ~97 ~26 ~109 end_stone
fill ~64 ~26 ~108 ~64 ~26 ~109 grass
fill ~63 ~25 ~109 ~63 ~26 ~109 sandstone
fill ~63 ~26 ~108 ~63 ~26 ~109 sandstone
fill ~62 ~26 ~108 ~62 ~26 ~109 grass
fill ~61 ~25 ~109 ~61 ~26 ~109 end_stone
fill ~58 ~26 ~108 ~58 ~26 ~109 grass
fill ~53 ~25 ~109 ~53 ~26 ~109 sandstone
fill ~53 ~26 ~108 ~53 ~26 ~109 sandstone
fill ~110 ~25 ~108 ~110 ~26 ~108 sandstone
fill ~104 ~26 ~108 ~105 ~26 ~108 sand
fill ~102 ~25 ~108 ~102 ~26 ~108 end_stone
fill ~98 ~25 ~108 ~98 ~26 ~108 end_stone
fill ~94 ~26 ~108 ~96 ~26 ~108 end_stone
fill ~67 ~26 ~108 ~68 ~26 ~108 sandstone
fill ~68 ~26 ~107 ~68 ~26 ~108 sandstone
fill ~66 ~26 ~107 ~66 ~26 ~108 grass
fill ~60 ~24 ~108 ~60 ~26 ~108 sandstone
fill ~60 ~26 ~107 ~60 ~26 ~108 sandstone
fill ~57 ~26 ~107 ~57 ~26 ~108 grass
fill ~56 ~25 ~108 ~56 ~26 ~108 end_stone
fill ~51 ~26 ~108 ~52 ~26 ~108 sandstone
fill ~111 ~25 ~107 ~111 ~26 ~107 sandstone
fill ~110 ~25 ~107 ~110 ~26 ~107 end_stone
fill ~109 ~25 ~107 ~109 ~26 ~107 sandstone
fill ~104 ~26 ~107 ~105 ~26 ~107 grass
fill ~102 ~26 ~106 ~102 ~26 ~107 grass
fill ~101 ~25 ~107 ~101 ~26 ~107 end_stone
fill ~99 ~26 ~107 ~100 ~26 ~107 sandstone
fill ~100 ~25 ~107 ~100 ~26 ~107 sandstone
fill ~95 ~26 ~107 ~97 ~26 ~107 sandstone
fill ~97 ~24 ~107 ~97 ~26 ~107 sandstone
fill ~94 ~24 ~107 ~94 ~26 ~107 end_stone
fill ~85 ~20 ~107 ~85 ~26 ~107 stone
fill ~85 ~26 ~105 ~85 ~26 ~107 stone
fill ~75 ~21 ~107 ~75 ~26 ~107 stone
fill ~75 ~26 ~104 ~75 ~26 ~107 stone
fill ~65 ~26 ~106 ~65 ~26 ~107 grass
fill ~64 ~25 ~107 ~64 ~26 ~107 sandstone
fill ~64 ~26 ~106 ~64 ~26 ~107 sandstone
fill ~62 ~25 ~107 ~62 ~26 ~107 sandstone
fill ~58 ~26 ~107 ~59 ~26 ~107 sandstone
fill ~59 ~25 ~107 ~59 ~26 ~107 sandstone
fill ~56 ~24 ~107 ~56 ~26 ~107 sandstone
fill ~56 ~26 ~106 ~56 ~26 ~107 sandstone
fill ~55 ~26 ~104 ~55 ~26 ~107 end_stone
fill ~54 ~26 ~106 ~54 ~26 ~107 grass
fill ~110 ~20 ~106 ~110 ~26 ~106 sandstone
fill ~106 ~26 ~106 ~107 ~26 ~106 grass
fill ~105 ~25 ~106 ~105 ~26 ~106 sandstone
fill ~103 ~25 ~106 ~103 ~26 ~106 sandstone
fill ~103 ~26 ~105 ~103 ~26 ~106 sandstone
fill ~98 ~26 ~104 ~98 ~26 ~106 end_stone
fill ~97 ~26 ~105 ~97 ~26 ~106 grass
fill ~94 ~26 ~106 ~96 ~26 ~106 sandstone
fill ~96 ~24 ~106 ~96 ~26 ~106 sandstone
fill ~84 ~18 ~106 ~84 ~26 ~106 stone
fill ~84 ~26 ~92 ~84 ~26 ~106 stone
fill ~74 ~26 ~105 ~74 ~26 ~106 grass
fill ~66 ~26 ~106 ~68 ~26 ~106 end_stone
fill ~68 ~25 ~106 ~68 ~26 ~106 end_stone
fill ~62 ~26 ~106 ~63 ~26 ~106 end_stone
fill ~57 ~26 ~106 ~58 ~26 ~106 sandstone
fill ~50 ~26 ~106 ~52 ~26 ~106 sandstone
fill ~52 ~24 ~106 ~52 ~26 ~106 sandstone
fill ~110 ~26 ~104 ~110 ~26 ~105 end_stone
fill ~104 ~26 ~105 ~107 ~26 ~105 end_stone
fill ~102 ~25 ~105 ~102 ~26 ~105 sandstone
fill ~99 ~26 ~104 ~99 ~26 ~105 end_stone
fill ~95 ~26 ~105 ~96 ~26 ~105 end_stone
fill ~96 ~26 ~104 ~96 ~26 ~105 end_stone
fill ~86 ~26 ~104 ~86 ~26 ~105 dirt
fill ~66 ~26 ~105 ~67 ~26 ~105 end_stone
fill ~67 ~25 ~105 ~67 ~26 ~105 end_stone
fill ~65 ~25 ~105 ~65 ~26 ~105 sandstone
fill ~65 ~26 ~103 ~65 ~26 ~105 sandstone
fill ~63 ~26 ~104 ~63 ~26 ~105 sand
fill ~60 ~26 ~102 ~60 ~26 ~105 grass
fill ~57 ~26 ~105 ~58 ~26 ~105 end_stone
fill ~54 ~25 ~105 ~54 ~26 ~105 sandstone
fill ~53 ~26 ~104 ~53 ~26 ~105 grass
fill ~50 ~26 ~105 ~51 ~26 ~105 sandstone
fill ~51 ~24 ~105 ~51 ~26 ~105 sandstone
fill ~51 ~26 ~104 ~51 ~26 ~105 sandstone
fill ~112 ~25 ~104 ~112 ~26 ~104 sandstone
fill ~112 ~26 ~102 ~112 ~26 ~104 sandstone
fill ~108 ~25 ~104 ~108 ~26 ~104 end_stone
fill ~106 ~26 ~104 ~107 ~26 ~104 sandstone
fill ~107 ~24 ~104 ~107 ~26 ~104 sandstone
fill ~103 ~26 ~104 ~104 ~26 ~104 grass
fill ~104 ~26 ~103 ~104 ~26 ~104 grass
fill ~100 ~24 ~104 ~100 ~26 ~104 end_stone
fill ~87 ~26 ~100 ~87 ~26 ~104 grass
fill ~76 ~18 ~104 ~76 ~26 ~104 stone
fill ~76 ~26 ~91 ~76 ~26 ~104 stone
fill ~73 ~26 ~100 ~73 ~26 ~104 grass
fill ~66 ~26 ~103 ~66 ~26 ~104 end_stone
fill ~59 ~26 ~103 ~59 ~26 ~104 grass
fill ~56 ~26 ~104 ~57 ~26 ~104 grass
fill ~146 ~25 ~103 ~146 ~26 ~103 fence 0
fill ~145 ~25 ~103 ~145 ~26 ~103 quartz_block
fill ~141 ~25 ~103 ~141 ~26 ~103 quartz_block
fill ~140 ~25 ~103 ~140 ~26 ~103 fence 0
fill ~109 ~26 ~103 ~111 ~26 ~103 sandstone
fill ~107 ~26 ~103 ~108 ~26 ~103 grass
fill ~108 ~26 ~102 ~108 ~26 ~103 grass
fill ~106 ~26 ~102 ~106 ~26 ~103 sandstone
fill ~105 ~26 ~102 ~105 ~26 ~103 end_stone
fill ~103 ~23 ~103 ~103 ~26 ~103 end_stone
fill ~101 ~26 ~103 ~102 ~26 ~103 sandstone
fill ~102 ~25 ~103 ~102 ~26 ~103 sandstone
fill ~97 ~23 ~103 ~97 ~26 ~103 end_stone
fill ~97 ~26 ~101 ~97 ~26 ~103 end_stone
fill ~96 ~25 ~103 ~96 ~26 ~103 sandstone
fill ~95 ~26 ~102 ~95 ~26 ~103 end_stone
fill ~85 ~26 ~103 ~86 ~26 ~103 stone
fill ~86 ~17 ~103 ~86 ~26 ~103 stone
fill ~86 ~26 ~97 ~86 ~26 ~103 stone
fill ~74 ~20 ~103 ~74 ~26 ~103 stone
fill ~74 ~26 ~97 ~74 ~26 ~103 stone
fill ~61 ~26 ~102 ~61 ~26 ~103 sandstone
fill ~58 ~26 ~102 ~58 ~26 ~103 grass
fill ~57 ~23 ~103 ~57 ~26 ~103 end_stone
fill ~54 ~26 ~103 ~55 ~26 ~103 sandstone
fill ~55 ~24 ~103 ~55 ~26 ~103 sandstone
fill ~55 ~26 ~102 ~55 ~26 ~103 sandstone
fill ~20 ~25 ~103 ~20 ~26 ~103 fence 0
fill ~19 ~25 ~103 ~19 ~26 ~103 quartz_block
fill ~15 ~25 ~103 ~15 ~26 ~103 quartz_block
fill ~14 ~25 ~103 ~14 ~26 ~103 fence 0
fill ~113 ~26 ~101 ~113 ~26 ~102 end_stone
fill ~110 ~21 ~102 ~110 ~26 ~102 sandstone
fill ~110 ~26 ~101 ~110 ~26 ~102 sandstone
fill ~107 ~25 ~102 ~107 ~26 ~102 sandstone
fill ~107 ~26 ~100 ~107 ~26 ~102 sandstone
fill ~102 ~26 ~102 ~103 ~26 ~102 grass
fill ~103 ~26 ~100 ~103 ~26 ~102 grass
fill ~100 ~26 ~102 ~101 ~26 ~102 sandstone
fill ~99 ~23 ~102 ~99 ~26 ~102 end_stone
fill ~99 ~26 ~101 ~99 ~26 ~102 end_stone
fill ~98 ~25 ~102 ~98 ~26 ~102 sandstone
fill ~96 ~24 ~102 ~96 ~26 ~102 end_stone
fill ~85 ~15 ~102 ~85 ~26 ~102 stone
fill ~85 ~26 ~93 ~85 ~26 ~102 stone
fill ~75 ~17 ~102 ~75 ~26 ~102 stone
fill ~75 ~26 ~95 ~75 ~26 ~102 stone
fill ~64 ~25 ~102 ~64 ~26 ~102 sandstone
fill ~57 ~25 ~102 ~57 ~26 ~102 sandstone
fill ~57 ~26 ~101 ~57 ~26 ~102 sandstone
fill ~53 ~26 ~102 ~54 ~26 ~102 grass
fill ~54 ~26 ~101 ~54 ~26 ~102 grass
fill ~52 ~25 ~102 ~52 ~26 ~102 end_stone
fill ~51 ~24 ~102 ~51 ~26 ~102 sandstone
fill ~51 ~26 ~101 ~51 ~26 ~102 sandstone
fill ~49 ~22 ~102 ~49 ~26 ~102 end_stone
fill ~149 ~26 ~101 ~150 ~26 ~101 fence 0
fill ~147 ~25 ~101 ~147 ~26 ~101 wood
fill ~139 ~25 ~101 ~139 ~26 ~101 wood
fill ~136 ~26 ~101 ~137 ~26 ~101 fence 0
fill ~111 ~26 ~100 ~111 ~26 ~101 sandstone
fill ~104 ~26 ~100 ~104 ~26 ~101 grass
fill ~98 ~25 ~101 ~98 ~26 ~101 end_stone
fill ~62 ~26 ~101 ~63 ~26 ~101 sandstone
fill ~58 ~26 ~100 ~58 ~26 ~101 sandstone
fill ~53 ~25 ~101 ~53 ~26 ~101 end_stone
fill ~49 ~26 ~101 ~50 ~26 ~101 sandstone
fill ~23 ~26 ~101 ~24 ~26 ~101 fence 0
fill ~21 ~25 ~101 ~21 ~26 ~101 wood
fill ~13 ~25 ~101 ~13 ~26 ~101 wood
fill ~10 ~26 ~101 ~11 ~26 ~101 fence 0
fill ~108 ~24 ~100 ~108 ~26 ~100 sandstone
fill ~88 ~26 ~93 ~88 ~26 ~100 grass
fill ~72 ~26 ~94 ~72 ~26 ~100 grass
fill ~61 ~26 ~100 ~62 ~26 ~100 end_stone
fill ~56 ~24 ~100 ~56 ~26 ~100 end_stone
fill ~56 ~26 ~98 ~56 ~26 ~100 end_stone
fill ~53 ~25 ~100 ~53 ~26 ~100 sandstone
fill ~53 ~26 ~99 ~53 ~26 ~100 sandstone
fill ~50 ~26 ~100 ~52 ~26 ~100 grass
fill ~49 ~25 ~100 ~49 ~26 ~100 end_stone
fill ~49 ~26 ~99 ~49 ~26 ~100 end_stone
fill ~110 ~26 ~99 ~112 ~26 ~99 grass
fill ~112 ~26 ~98 ~112 ~26 ~99 grass
fill ~109 ~25 ~99 ~109 ~26 ~99 end_stone
fill ~108 ~26 ~98 ~108 ~26 ~99 grass
fill ~102 ~26 ~99 ~103 ~26 ~99 sandstone
fill ~99 ~26 ~99 ~100 ~26 ~99 end_stone
fill ~100 ~25 ~99 ~100 ~26 ~99 end_stone
fill ~100 ~26 ~98 ~100 ~26 ~99 end_stone
fill ~87 ~21 ~99 ~87 ~26 ~99 stone
fill ~87 ~26 ~93 ~87 ~26 ~99 stone
fill ~73 ~21 ~99 ~73 ~26 ~99 stone
fill ~73 ~26 ~95 ~73 ~26 ~99 stone
fill ~58 ~26 ~99 ~59 ~26 ~99 end_stone
fill ~59 ~26 ~97 ~59 ~26 ~99 end_stone
fill ~55 ~26 ~98 ~55 ~26 ~99 end_stone
fill ~50 ~26 ~99 ~52 ~26 ~99 end_stone
fill ~52 ~25 ~99 ~52 ~26 ~99 end_stone
fill ~52 ~26 ~94 ~52 ~26 ~99 end_stone
fill ~48 ~26 ~98 ~48 ~26 ~99 sandstone
fill ~110 ~26 ~98 ~111 ~26 ~98 sandstone
fill ~111 ~26 ~96 ~111 ~26 ~98 sandstone
fill ~107 ~25 ~98 ~107 ~26 ~98 sandstone
fill ~106 ~26 ~97 ~106 ~26 ~98 end_stone
fill ~101 ~25 ~98 ~101 ~26 ~98 sandstone
fill ~101 ~26 ~97 ~101 ~26 ~98 sandstone
fill ~58 ~25 ~98 ~58 ~26 ~98 sandstone
fill ~49 ~26 ~96 ~49 ~26 ~98 sandstone
fill ~108 ~26 ~97 ~109 ~26 ~97 sandstone
fill ~109 ~25 ~97 ~109 ~26 ~97 sandstone
fill ~57 ~26 ~97 ~58 ~26 ~97 end_stone
fill ~58 ~25 ~97 ~58 ~26 ~97 end_stone
fill ~58 ~26 ~95 ~58 ~26 ~97 end_stone
fill ~54 ~26 ~97 ~55 ~26 ~97 grass
fill ~53 ~24 ~97 ~53 ~26 ~97 sandstone
fill ~53 ~26 ~95 ~53 ~26 ~97 sandstone
fill ~50 ~26 ~95 ~50 ~26 ~97 sandstone
fill ~48 ~25 ~97 ~48 ~26 ~97 end_stone
fill ~113 ~25 ~96 ~113 ~26 ~96 sandstone
fill ~113 ~26 ~95 ~113 ~26 ~96 sandstone
fill ~112 ~25 ~96 ~112 ~26 ~96 end_stone
fill ~112 ~26 ~94 ~112 ~26 ~96 end_stone
fill ~110 ~26 ~93 ~110 ~26 ~96 end_stone
fill ~108 ~26 ~96 ~109 ~26 ~96 grass
fill ~106 ~26 ~96 ~107 ~26 ~96 sandstone
fill ~107 ~25 ~96 ~107 ~26 ~96 sandstone
fill ~102 ~25 ~96 ~102 ~26 ~96 sandstone
fill ~89 ~26 ~92 ~89 ~26 ~96 grass
fill ~71 ~26 ~92 ~71 ~26 ~96 grass
fill ~57 ~25 ~96 ~57 ~26 ~96 sandstone
fill ~55 ~26 ~96 ~56 ~26 ~96 end_stone
fill ~56 ~24 ~96 ~56 ~26 ~96 end_stone
fill ~54 ~24 ~96 ~54 ~26 ~96 sandstone
fill ~54 ~26 ~94 ~54 ~26 ~96 sandstone
fill ~109 ~24 ~95 ~109 ~26 ~95 end_stone
fill ~109 ~26 ~93 ~109 ~26 ~95 end_stone
fill ~106 ~26 ~95 ~107 ~26 ~95 grass
fill ~107 ~26 ~93 ~107 ~26 ~95 grass
fill ~103 ~26 ~95 ~105 ~26 ~95 sandstone
fill ~105 ~25 ~95 ~105 ~26 ~95 sandstone
fill ~90 ~26 ~95 ~91 ~26 ~95 grass
fill ~91 ~26 ~90 ~91 ~26 ~95 grass
fill ~86 ~22 ~95 ~86 ~26 ~95 stone
fill ~86 ~26 ~94 ~86 ~26 ~95 stone
fill ~69 ~26 ~95 ~70 ~26 ~95 grass
fill ~70 ~26 ~91 ~70 ~26 ~95 grass
fill ~55 ~24 ~95 ~55 ~26 ~95 end_stone
fill ~113 ~24 ~94 ~113 ~26 ~94 end_stone
fill ~111 ~24 ~94 ~111 ~26 ~94 end_stone
fill ~103 ~26 ~94 ~106 ~26 ~94 end_stone
fill ~106 ~26 ~92 ~106 ~26 ~94 end_stone
fill ~92 ~26 ~89 ~92 ~26 ~94 grass
fill ~90 ~26 ~91 ~90 ~26 ~94 grass
fill ~68 ~26 ~94 ~69 ~26 ~94 grass
fill ~69 ~26 ~90 ~69 ~26 ~94 grass
fill ~53 ~24 ~94 ~53 ~26 ~94 end_stone
fill ~111 ~26 ~93 ~112 ~26 ~93 sandstone
fill ~112 ~25 ~93 ~112 ~26 ~93 sandstone
fill ~108 ~26 ~92 ~108 ~26 ~93 sandstone
fill ~105 ~25 ~93 ~105 ~26 ~93 end_stone
fill ~93 ~26 ~89 ~93 ~26 ~93 grass
fill ~67 ~26 ~93 ~68 ~26 ~93 grass
fill ~68 ~26 ~89 ~68 ~26 ~93 grass
fill ~107 ~25 ~92 ~107 ~26 ~92 sandstone
fill ~94 ~26 ~88 ~94 ~26 ~92 grass
fill ~88 ~21 ~92 ~88 ~26 ~92 stone
fill ~78 ~12 ~92 ~78 ~26 ~92 stone
fill ~78 ~26 ~79 ~78 ~26 ~92 stone
fill ~66 ~26 ~92 ~67 ~26 ~92 grass
fill ~67 ~26 ~88 ~67 ~26 ~92 grass
fill ~95 ~26 ~88 ~95 ~26 ~91 grass
fill ~89 ~20 ~91 ~89 ~26 ~91 stone
fill ~75 ~13 ~91 ~75 ~26 ~91 stone
fill ~75 ~26 ~90 ~75 ~26 ~91 stone
fill ~71 ~20 ~91 ~71 ~26 ~91 stone
fill ~71 ~26 ~89 ~71 ~26 ~91 stone
fill ~65 ~26 ~91 ~66 ~26 ~91 grass
fill ~66 ~26 ~88 ~66 ~26 ~91 grass
fill ~90 ~20 ~90 ~90 ~26 ~90 stone
fill ~90 ~26 ~85 ~90 ~26 ~90 stone
fill ~72 ~26 ~90 ~74 ~26 ~90 stone
fill ~74 ~11 ~90 ~74 ~26 ~90 stone
fill ~74 ~26 ~89 ~74 ~26 ~90 stone
fill ~70 ~20 ~90 ~70 ~26 ~90 stone
fill ~70 ~26 ~89 ~70 ~26 ~90 stone
fill ~65 ~26 ~88 ~65 ~26 ~90 grass
fill ~99 ~26 ~88 ~99 ~26 ~89 grass
fill ~96 ~26 ~88 ~96 ~26 ~89 grass
fill ~91 ~20 ~89 ~91 ~26 ~89 stone
fill ~89 ~12 ~89 ~89 ~26 ~89 stone
fill ~89 ~26 ~81 ~89 ~26 ~89 stone
fill ~84 ~4 ~89 ~84 ~26 ~89 stone
fill ~80 ~1 ~89 ~80 ~26 ~89 stone
fill ~80 ~26 ~88 ~80 ~26 ~89 stone
fill ~76 ~6 ~89 ~76 ~26 ~89 stone
fill ~76 ~26 ~77 ~76 ~26 ~89 stone
fill ~72 ~26 ~89 ~73 ~26 ~89 stone
fill ~73 ~10 ~89 ~73 ~26 ~89 stone
fill ~69 ~20 ~89 ~69 ~26 ~89 stone
fill ~64 ~26 ~88 ~64 ~26 ~89 grass
fill ~61 ~26 ~88 ~61 ~26 ~89 grass
fill ~127 ~24 ~88 ~127 ~26 ~88 stone 6
fill ~100 ~26 ~87 ~100 ~26 ~88 grass
fill ~97 ~26 ~88 ~98 ~26 ~88 grass
fill ~85 ~3 ~88 ~85 ~26 ~88 stone
fill ~85 ~26 ~81 ~85 ~26 ~88 stone
fill ~75 ~7 ~88 ~75 ~26 ~88 stone
fill ~75 ~26 ~81 ~75 ~26 ~88 stone
fill ~68 ~21 ~88 ~68 ~26 ~88 stone
fill ~62 ~26 ~88 ~63 ~26 ~88 grass
fill ~60 ~26 ~87 ~60 ~26 ~88 grass
fill ~33 ~24 ~88 ~33 ~26 ~88 stone 6
fill ~157 ~26 ~86 ~157 ~26 ~87 fence 0
fill ~149 ~26 ~87 ~150 ~26 ~87 wood
fill ~150 ~25 ~87 ~150 ~26 ~87 wood
fill ~116 ~26 ~87 ~118 ~26 ~87 grass
fill ~101 ~26 ~87 ~104 ~26 ~87 grass
fill ~95 ~26 ~87 ~99 ~26 ~87 stone
fill ~99 ~21 ~87 ~99 ~26 ~87 stone
fill ~99 ~26 ~82 ~99 ~26 ~87 stone
fill ~88 ~7 ~87 ~88 ~26 ~87 stone
fill ~88 ~26 ~79 ~88 ~26 ~87 stone
fill ~86 ~2 ~87 ~86 ~26 ~87 stone
fill ~86 ~26 ~77 ~86 ~26 ~87 stone
fill ~84 ~1 ~87 ~84 ~26 ~87 stone
fill ~84 ~26 ~75 ~84 ~26 ~87 stone
fill ~74 ~7 ~87 ~74 ~26 ~87 stone
fill ~74 ~26 ~75 ~74 ~26 ~87 stone
fill ~61 ~26 ~87 ~67 ~26 ~87 stone
fill ~67 ~22 ~87 ~67 ~26 ~87 stone
fill ~56 ~26 ~87 ~59 ~26 ~87 grass
fill ~42 ~26 ~87 ~44 ~26 ~87 grass
fill ~10 ~26 ~87 ~11 ~26 ~87 wood
fill ~150 ~26 ~86 ~151 ~26 ~86 fence 0
fill ~121 ~26 ~86 ~126 ~26 ~86 grass
fill ~120 ~20 ~86 ~120 ~26 ~86 stone
fill ~120 ~26 ~82 ~120 ~26 ~86 stone
fill ~115 ~26 ~86 ~118 ~26 ~86 stone
fill ~118 ~19 ~86 ~118 ~26 ~86 stone
fill ~118 ~26 ~80 ~118 ~26 ~86 stone
fill ~108 ~26 ~86 ~114 ~26 ~86 grass
fill ~105 ~26 ~86 ~106 ~26 ~86 grass
fill ~100 ~26 ~86 ~103 ~26 ~86 stone
fill ~103 ~20 ~86 ~103 ~26 ~86 stone
fill ~97 ~26 ~86 ~98 ~26 ~86 stone
fill ~98 ~20 ~86 ~98 ~26 ~86 stone
fill ~98 ~26 ~81 ~98 ~26 ~86 stone
fill ~87 ~3 ~86 ~87 ~26 ~86 stone
fill ~87 ~26 ~81 ~87 ~26 ~86 stone
fill ~80 ~0 ~86 ~80 ~26 ~86 stone
fill ~73 ~7 ~86 ~73 ~26 ~86 stone
fill ~73 ~26 ~81 ~73 ~26 ~86 stone
fill ~57 ~26 ~86 ~66 ~26 ~86 stone
fill ~66 ~22 ~86 ~66 ~26 ~86 stone
fill ~55 ~26 ~86 ~56 ~26 ~86 dirt
fill ~46 ~26 ~86 ~54 ~26 ~86 grass
fill ~42 ~26 ~86 ~44 ~26 ~86 stone
fill ~44 ~18 ~86 ~44 ~26 ~86 stone
fill ~44 ~26 ~79 ~44 ~26 ~86 stone
fill ~34 ~26 ~86 ~40 ~26 ~86 grass
fill ~9 ~26 ~86 ~10 ~26 ~86 fence 0
fill ~128 ~26 ~85 ~130 ~26 ~85 grass
fill ~125 ~26 ~85 ~127 ~26 ~85 stone
fill ~127 ~22 ~85 ~127 ~26 ~85 stone
fill ~127 ~26 ~83 ~127 ~26 ~85 stone
fill ~121 ~26 ~85 ~123 ~26 ~85 stone
fill ~123 ~20 ~85 ~123 ~26 ~85 stone
fill ~123 ~26 ~81 ~123 ~26 ~85 stone
fill ~119 ~18 ~85 ~119 ~26 ~85 stone
fill ~119 ~26 ~81 ~119 ~26 ~85 stone
fill ~109 ~26 ~85 ~117 ~26 ~85 stone
fill ~117 ~15 ~85 ~117 ~26 ~85 stone
fill ~117 ~26 ~79 ~117 ~26 ~85 stone
fill ~104 ~26 ~85 ~107 ~26 ~85 stone
fill ~107 ~21 ~85 ~107 ~26 ~85 stone
fill ~107 ~26 ~79 ~107 ~26 ~85 stone
fill ~100 ~26 ~85 ~102 ~26 ~85 stone
fill ~102 ~17 ~85 ~102 ~26 ~85 stone
fill ~95 ~26 ~85 ~97 ~26 ~85 stone
fill ~97 ~20 ~85 ~97 ~26 ~85 stone
fill ~97 ~26 ~81 ~97 ~26 ~85 stone
fill ~91 ~7 ~85 ~91 ~26 ~85 stone
fill ~91 ~26 ~81 ~91 ~26 ~85 stone
fill ~72 ~9 ~85 ~72 ~26 ~85 stone
fill ~72 ~26 ~74 ~72 ~26 ~85 stone
fill ~70 ~16 ~85 ~70 ~26 ~85 stone
fill ~53 ~26 ~85 ~65 ~26 ~85 stone
fill ~65 ~22 ~85 ~65 ~26 ~85 stone
fill ~45 ~26 ~85 ~51 ~26 ~85 stone
fill ~51 ~22 ~85 ~51 ~26 ~85 stone
fill ~51 ~26 ~78 ~51 ~26 ~85 stone
fill ~37 ~26 ~85 ~43 ~26 ~85 stone
fill ~43 ~17 ~85 ~43 ~26 ~85 stone
fill ~43 ~26 ~74 ~43 ~26 ~85 stone
fill ~33 ~26 ~85 ~35 ~26 ~85 stone
fill ~35 ~20 ~85 ~35 ~26 ~85 stone
fill ~35 ~26 ~82 ~35 ~26 ~85 stone
fill ~30 ~26 ~85 ~32 ~26 ~85 grass
fill ~157 ~25 ~84 ~157 ~26 ~84 wood
fill ~131 ~26 ~81 ~131 ~26 ~84 grass
fill ~130 ~26 ~83 ~130 ~26 ~84 wood
fill ~124 ~26 ~84 ~126 ~26 ~84 stone
fill ~126 ~20 ~84 ~126 ~26 ~84 stone
fill ~121 ~26 ~84 ~122 ~26 ~84 stone
fill ~122 ~20 ~84 ~122 ~26 ~84 stone
fill ~114 ~26 ~84 ~116 ~26 ~84 stone
fill ~116 ~14 ~84 ~116 ~26 ~84 stone
fill ~108 ~26 ~84 ~112 ~26 ~84 stone
fill ~112 ~18 ~84 ~112 ~26 ~84 stone
fill ~106 ~21 ~84 ~106 ~26 ~84 stone
fill ~106 ~26 ~78 ~106 ~26 ~84 stone
fill ~103 ~26 ~84 ~104 ~26 ~84 stone
fill ~104 ~18 ~84 ~104 ~26 ~84 stone
fill ~100 ~26 ~84 ~101 ~26 ~84 stone
fill ~101 ~17 ~84 ~101 ~26 ~84 stone
fill ~92 ~26 ~84 ~96 ~26 ~84 stone
fill ~96 ~20 ~84 ~96 ~26 ~84 stone
fill ~80 ~0 ~84 ~80 ~26 ~84 stone
fill ~71 ~10 ~84 ~71 ~26 ~84 stone
fill ~71 ~26 ~74 ~71 ~26 ~84 stone
fill ~68 ~15 ~84 ~68 ~26 ~84 stone
fill ~68 ~26 ~76 ~68 ~26 ~84 stone
fill ~66 ~17 ~84 ~66 ~26 ~84 stone
fill ~66 ~26 ~76 ~66 ~26 ~84 stone
fill ~52 ~26 ~84 ~64 ~26 ~84 stone
fill ~64 ~21 ~84 ~64 ~26 ~84 stone
fill ~45 ~26 ~84 ~49 ~26 ~84 stone
fill ~49 ~19 ~84 ~49 ~26 ~84 stone
fill ~36 ~26 ~84 ~42 ~26 ~84 stone
fill ~42 ~13 ~84 ~42 ~26 ~84 stone
fill ~42 ~26 ~74 ~42 ~26 ~84 stone
fill ~33 ~26 ~84 ~34 ~26 ~84 stone
fill ~34 ~20 ~84 ~34 ~26 ~84 stone
fill ~30 ~26 ~83 ~30 ~26 ~84 wood
fill ~29 ~26 ~81 ~29 ~26 ~84 grass
fill ~3 ~25 ~84 ~3 ~26 ~84 wood
fill ~159 ~25 ~83 ~159 ~26 ~83 fence 0
fill ~132 ~26 ~77 ~132 ~26 ~83 grass
fill ~128 ~26 ~83 ~129 ~26 ~83 stone
fill ~129 ~14 ~83 ~129 ~26 ~83 stone
fill ~129 ~26 ~82 ~129 ~26 ~83 stone
fill ~124 ~26 ~83 ~125 ~26 ~83 stone
fill ~125 ~18 ~83 ~125 ~26 ~83 stone
fill ~121 ~16 ~83 ~121 ~26 ~83 stone
fill ~113 ~26 ~83 ~115 ~26 ~83 stone
fill ~115 ~13 ~83 ~115 ~26 ~83 stone
fill ~108 ~26 ~83 ~111 ~26 ~83 stone
fill ~111 ~17 ~83 ~111 ~26 ~83 stone
fill ~105 ~17 ~83 ~105 ~26 ~83 stone
fill ~105 ~26 ~81 ~105 ~26 ~83 stone
fill ~102 ~26 ~83 ~103 ~26 ~83 stone
fill ~103 ~11 ~83 ~103 ~26 ~83 stone
fill ~103 ~26 ~81 ~103 ~26 ~83 stone
fill ~100 ~18 ~83 ~100 ~26 ~83 stone
fill ~92 ~26 ~83 ~94 ~26 ~83 stone
fill ~94 ~18 ~83 ~94 ~26 ~83 stone
fill ~90 ~6 ~83 ~90 ~26 ~83 stone
fill ~90 ~26 ~77 ~90 ~26 ~83 stone
fill ~69 ~12 ~83 ~69 ~26 ~83 stone
fill ~69 ~26 ~81 ~69 ~26 ~83 stone
fill ~67 ~15 ~83 ~67 ~26 ~83 stone
fill ~67 ~26 ~81 ~67 ~26 ~83 stone
fill ~65 ~17 ~83 ~65 ~26 ~83 stone
fill ~65 ~26 ~81 ~65 ~26 ~83 stone
fill ~52 ~26 ~83 ~63 ~26 ~83 stone
fill ~63 ~21 ~83 ~63 ~26 ~83 stone
fill ~50 ~20 ~83 ~50 ~26 ~83 stone
fill ~50 ~26 ~75 ~50 ~26 ~83 stone
fill ~45 ~26 ~83 ~48 ~26 ~83 stone
fill ~48 ~19 ~83 ~48 ~26 ~83 stone
fill ~41 ~14 ~83 ~41 ~26 ~83 stone
fill ~41 ~26 ~75 ~41 ~26 ~83 stone
fill ~36 ~26 ~83 ~39 ~26 ~83 stone
fill ~39 ~15 ~83 ~39 ~26 ~83 stone
fill ~31 ~26 ~83 ~33 ~26 ~83 stone
fill ~33 ~18 ~83 ~33 ~26 ~83 stone
fill ~28 ~26 ~77 ~28 ~26 ~83 grass
fill ~1 ~25 ~83 ~1 ~26 ~83 fence 0
fill ~159 ~25 ~82 ~159 ~26 ~82 quartz_block
fill ~133 ~26 ~82 ~134 ~26 ~82 grass
fill ~134 ~26 ~78 ~134 ~26 ~82 grass
fill ~130 ~11 ~82 ~130 ~26 ~82 stone
fill ~128 ~13 ~82 ~128 ~26 ~82 stone
fill ~128 ~26 ~81 ~128 ~26 ~82 stone
fill ~126 ~17 ~82 ~126 ~26 ~82 stone
fill ~126 ~26 ~75 ~126 ~26 ~82 stone
fill ~124 ~16 ~82 ~124 ~26 ~82 stone
fill ~122 ~17 ~82 ~122 ~26 ~82 stone
fill ~122 ~26 ~75 ~122 ~26 ~82 stone
fill ~116 ~9 ~82 ~116 ~26 ~82 stone
fill ~116 ~26 ~74 ~116 ~26 ~82 stone
fill ~112 ~26 ~82 ~114 ~26 ~82 stone
fill ~114 ~15 ~82 ~114 ~26 ~82 stone
fill ~108 ~26 ~82 ~110 ~26 ~82 stone
fill ~110 ~17 ~82 ~110 ~26 ~82 stone
fill ~104 ~12 ~82 ~104 ~26 ~82 stone
fill ~104 ~26 ~75 ~104 ~26 ~82 stone
fill ~101 ~26 ~82 ~102 ~26 ~82 stone
fill ~102 ~12 ~82 ~102 ~26 ~82 stone
fill ~102 ~26 ~74 ~102 ~26 ~82 stone
fill ~96 ~19 ~82 ~96 ~26 ~82 stone
fill ~96 ~26 ~81 ~96 ~26 ~82 stone
fill ~92 ~13 ~82 ~92 ~26 ~82 stone
fill ~80 ~0 ~82 ~80 ~26 ~82 stone
fill ~80 ~26 ~78 ~80 ~26 ~82 stone
fill ~70 ~11 ~82 ~70 ~26 ~82 stone
fill ~70 ~26 ~70 ~70 ~26 ~82 stone
fill ~64 ~20 ~82 ~64 ~26 ~82 stone
fill ~64 ~26 ~79 ~64 ~26 ~82 stone
fill ~52 ~26 ~82 ~62 ~26 ~82 stone
fill ~62 ~22 ~82 ~62 ~26 ~82 stone
fill ~49 ~17 ~82 ~49 ~26 ~82 stone
fill ~49 ~26 ~75 ~49 ~26 ~82 stone
fill ~45 ~26 ~82 ~47 ~26 ~82 stone
fill ~47 ~16 ~82 ~47 ~26 ~82 stone
fill ~40 ~12 ~82 ~40 ~26 ~82 stone
fill ~40 ~26 ~74 ~40 ~26 ~82 stone
fill ~36 ~26 ~82 ~38 ~26 ~82 stone
fill ~38 ~16 ~82 ~38 ~26 ~82 stone
fill ~34 ~17 ~82 ~34 ~26 ~82 stone
fill ~34 ~26 ~75 ~34 ~26 ~82 stone
fill ~30 ~26 ~82 ~32 ~26 ~82 stone
fill ~32 ~15 ~82 ~32 ~26 ~82 stone
fill ~26 ~26 ~82 ~27 ~26 ~82 grass
fill ~27 ~26 ~78 ~27 ~26 ~82 grass
fill ~1 ~25 ~82 ~1 ~26 ~82 quartz_block
fill ~133 ~26 ~78 ~133 ~26 ~81 grass
fill ~127 ~14 ~81 ~127 ~26 ~81 stone
fill ~127 ~26 ~75 ~127 ~26 ~81 stone
fill ~121 ~14 ~81 ~121 ~26 ~81 stone
fill ~121 ~26 ~75 ~121 ~26 ~81 stone
fill ~115 ~11 ~81 ~115 ~26 ~81 stone
fill ~115 ~26 ~75 ~115 ~26 ~81 stone
fill ~111 ~26 ~81 ~113 ~26 ~81 stone
fill ~113 ~15 ~81 ~113 ~26 ~81 stone
fill ~113 ~26 ~75 ~113 ~26 ~81 stone
fill ~108 ~26 ~81 ~109 ~26 ~81 stone
fill ~109 ~17 ~81 ~109 ~26 ~81 stone
fill ~100 ~26 ~81 ~101 ~26 ~81 stone
fill ~101 ~11 ~81 ~101 ~26 ~81 stone
fill ~93 ~26 ~81 ~95 ~26 ~81 stone
fill ~95 ~17 ~81 ~95 ~26 ~81 stone
fill ~63 ~22 ~81 ~63 ~26 ~81 stone
fill ~52 ~26 ~81 ~61 ~26 ~81 stone
fill ~61 ~16 ~81 ~61 ~26 ~81 stone
fill ~48 ~15 ~81 ~48 ~26 ~81 stone
fill ~48 ~26 ~75 ~48 ~26 ~81 stone
fill ~45 ~26 ~81 ~46 ~26 ~81 stone
fill ~46 ~13 ~81 ~46 ~26 ~81 stone
fill ~39 ~13 ~81 ~39 ~26 ~81 stone
fill ~39 ~26 ~75 ~39 ~26 ~81 stone
fill ~37 ~15 ~81 ~37 ~26 ~81 stone
fill ~33 ~15 ~81 ~33 ~26 ~81 stone
fill ~33 ~26 ~75 ~33 ~26 ~81 stone
fill ~31 ~9 ~81 ~31 ~26 ~81 stone
fill ~26 ~26 ~78 ~26 ~26 ~81 grass
fill ~129 ~26 ~80 ~131 ~26 ~80 stone
fill ~131 ~8 ~80 ~131 ~26 ~80 stone
fill ~124 ~16 ~80 ~124 ~26 ~80 stone
fill ~120 ~11 ~80 ~120 ~26 ~80 stone
fill ~120 ~26 ~75 ~120 ~26 ~80 stone
fill ~114 ~12 ~80 ~114 ~26 ~80 stone
fill ~114 ~26 ~75 ~114 ~26 ~80 stone
fill ~110 ~26 ~80 ~112 ~26 ~80 stone
fill ~112 ~14 ~80 ~112 ~26 ~80 stone
fill ~112 ~26 ~75 ~112 ~26 ~80 stone
fill ~108 ~17 ~80 ~108 ~26 ~80 stone
fill ~100 ~11 ~80 ~100 ~26 ~80 stone
fill ~100 ~26 ~74 ~100 ~26 ~80 stone
fill ~92 ~13 ~80 ~92 ~26 ~80 stone
fill ~92 ~26 ~79 ~92 ~26 ~80 stone
fill ~62 ~23 ~80 ~62 ~26 ~80 stone
fill ~62 ~26 ~73 ~62 ~26 ~80 stone
fill ~52 ~26 ~80 ~53 ~26 ~80 stone
fill ~53 ~16 ~80 ~53 ~26 ~80 stone
fill ~47 ~14 ~80 ~47 ~26 ~80 stone
fill ~47 ~26 ~75 ~47 ~26 ~80 stone
fill ~45 ~8 ~80 ~45 ~26 ~80 stone
fill ~38 ~15 ~80 ~38 ~26 ~80 stone
fill ~38 ~26 ~75 ~38 ~26 ~80 stone
fill ~36 ~16 ~80 ~36 ~26 ~80 stone
fill ~32 ~15 ~80 ~32 ~26 ~80 stone
fill ~32 ~26 ~77 ~32 ~26 ~80 stone
fill ~29 ~26 ~80 ~30 ~26 ~80 stone
fill ~30 ~6 ~80 ~30 ~26 ~80 stone
fill ~130 ~26 ~79 ~131 ~26 ~79 grass
fill ~131 ~26 ~76 ~131 ~26 ~79 grass
fill ~128 ~26 ~79 ~129 ~26 ~79 stone
fill ~129 ~9 ~79 ~129 ~26 ~79 stone
fill ~129 ~26 ~77 ~129 ~26 ~79 stone
fill ~125 ~16 ~79 ~125 ~26 ~79 stone
fill ~125 ~26 ~75 ~125 ~26 ~79 stone
fill ~123 ~15 ~79 ~123 ~26 ~79 stone
fill ~123 ~26 ~75 ~123 ~26 ~79 stone
fill ~119 ~6 ~79 ~119 ~26 ~79 stone
fill ~119 ~26 ~75 ~119 ~26 ~79 stone
fill ~109 ~26 ~79 ~111 ~26 ~79 stone
fill ~111 ~16 ~79 ~111 ~26 ~79 stone
fill ~111 ~26 ~75 ~111 ~26 ~79 stone
fill ~105 ~7 ~79 ~105 ~26 ~79 stone
fill ~105 ~26 ~77 ~105 ~26 ~79 stone
fill ~98 ~22 ~79 ~98 ~26 ~79 stone
fill ~98 ~26 ~73 ~98 ~26 ~79 stone
fill ~96 ~20 ~79 ~96 ~26 ~79 stone
fill ~96 ~26 ~73 ~96 ~26 ~79 stone
fill ~94 ~16 ~79 ~94 ~26 ~79 stone
fill ~94 ~26 ~73 ~94 ~26 ~79 stone
fill ~89 ~14 ~79 ~89 ~26 ~79 stone
fill ~89 ~26 ~75 ~89 ~26 ~79 stone
fill ~87 ~0 ~79 ~87 ~26 ~79 stone
fill ~87 ~26 ~78 ~87 ~26 ~79 stone
fill ~85 ~21 ~79 ~85 ~26 ~79 stone
fill ~85 ~26 ~76 ~85 ~26 ~79 stone
fill ~83 ~0 ~79 ~83 ~26 ~79 stone
fill ~83 ~26 ~74 ~83 ~26 ~79 stone
fill ~77 ~0 ~79 ~77 ~26 ~79 stone
fill ~77 ~26 ~78 ~77 ~26 ~79 stone
fill ~75 ~0 ~79 ~75 ~26 ~79 stone
fill ~75 ~26 ~76 ~75 ~26 ~79 stone
fill ~73 ~0 ~79 ~73 ~26 ~79 stone
fill ~73 ~26 ~74 ~73 ~26 ~79 stone
fill ~60 ~16 ~79 ~60 ~26 ~79 stone
fill ~60 ~26 ~74 ~60 ~26 ~79 stone
fill ~58 ~9 ~79 ~58 ~26 ~79 stone
fill ~58 ~26 ~74 ~58 ~26 ~79 stone
fill ~56 ~9 ~79 ~56 ~26 ~79 stone
fill ~56 ~26 ~75 ~56 ~26 ~79 stone
fill ~54 ~15 ~79 ~54 ~26 ~79 stone
fill ~54 ~26 ~75 ~54 ~26 ~79 stone
fill ~52 ~17 ~79 ~52 ~26 ~79 stone
fill ~46 ~13 ~79 ~46 ~26 ~79 stone
fill ~46 ~26 ~75 ~46 ~26 ~79 stone
fill ~37 ~16 ~79 ~37 ~26 ~79 stone
fill ~37 ~26 ~75 ~37 ~26 ~79 stone
fill ~31 ~8 ~79 ~31 ~26 ~79 stone
fill ~31 ~26 ~77 ~31 ~26 ~79 stone
fill ~29 ~26 ~79 ~30 ~26 ~79 grass
fill ~159 ~25 ~78 ~159 ~26 ~78 quartz_block
fill ~130 ~12 ~78 ~130 ~26 ~78 stone
fill ~128 ~15 ~78 ~128 ~26 ~78 stone
fill ~128 ~26 ~77 ~128 ~26 ~78 stone
fill ~118 ~6 ~78 ~118 ~26 ~78 stone
fill ~118 ~26 ~74 ~118 ~26 ~78 stone
fill ~108 ~26 ~78 ~110 ~26 ~78 stone
fill ~110 ~18 ~78 ~110 ~26 ~78 stone
fill ~110 ~26 ~75 ~110 ~26 ~78 stone
fill ~103 ~5 ~78 ~103 ~26 ~78 stone
fill ~103 ~26 ~74 ~103 ~26 ~78 stone
fill ~101 ~8 ~78 ~101 ~26 ~78 stone
fill ~101 ~26 ~74 ~101 ~26 ~78 stone
fill ~99 ~16 ~78 ~99 ~26 ~78 stone
fill ~99 ~26 ~73 ~99 ~26 ~78 stone
fill ~97 ~21 ~78 ~97 ~26 ~78 stone
fill ~97 ~26 ~73 ~97 ~26 ~78 stone
fill ~95 ~20 ~78 ~95 ~26 ~78 stone
fill ~95 ~26 ~73 ~95 ~26 ~78 stone
fill ~93 ~15 ~78 ~93 ~26 ~78 stone
fill ~93 ~26 ~76 ~93 ~26 ~78 stone
fill ~91 ~11 ~78 ~91 ~26 ~78 stone
fill ~67 ~13 ~78 ~67 ~26 ~78 stone
fill ~67 ~26 ~76 ~67 ~26 ~78 stone
fill ~63 ~18 ~78 ~63 ~26 ~78 stone
fill ~63 ~26 ~73 ~63 ~26 ~78 stone
fill ~61 ~18 ~78 ~61 ~26 ~78 stone
fill ~61 ~26 ~73 ~61 ~26 ~78 stone
fill ~59 ~14 ~78 ~59 ~26 ~78 stone
fill ~59 ~26 ~74 ~59 ~26 ~78 stone
fill ~57 ~9 ~78 ~57 ~26 ~78 stone
fill ~57 ~26 ~74 ~57 ~26 ~78 stone
fill ~55 ~16 ~78 ~55 ~26 ~78 stone
fill ~55 ~26 ~75 ~55 ~26 ~78 stone
fill ~53 ~17 ~78 ~53 ~26 ~78 stone
fill ~53 ~26 ~75 ~53 ~26 ~78 stone
fill ~45 ~11 ~78 ~45 ~26 ~78 stone
fill ~45 ~26 ~74 ~45 ~26 ~78 stone
fill ~35 ~17 ~78 ~35 ~26 ~78 stone
fill ~35 ~26 ~75 ~35 ~26 ~78 stone
fill ~30 ~11 ~78 ~30 ~26 ~78 stone
fill ~29 ~26 ~76 ~29 ~26 ~78 grass
fill ~1 ~25 ~78 ~1 ~26 ~78 quartz_block
fill ~159 ~25 ~77 ~159 ~26 ~77 fence 0
fill ~130 ~26 ~76 ~130 ~26 ~77 wood
fill ~124 ~17 ~77 ~124 ~26 ~77 stone
fill ~124 ~26 ~76 ~124 ~26 ~77 stone
fill ~117 ~8 ~77 ~117 ~26 ~77 stone
fill ~117 ~26 ~74 ~117 ~26 ~77 stone
fill ~107 ~26 ~77 ~109 ~26 ~77 stone
fill ~109 ~18 ~77 ~109 ~26 ~77 stone
fill ~109 ~26 ~75 ~109 ~26 ~77 stone
fill ~88 ~0 ~77 ~88 ~26 ~77 stone
fill ~88 ~26 ~74 ~88 ~26 ~77 stone
fill ~78 ~0 ~77 ~78 ~26 ~77 stone
fill ~78 ~26 ~70 ~78 ~26 ~77 stone
fill ~64 ~17 ~77 ~64 ~26 ~77 stone
fill ~52 ~18 ~77 ~52 ~26 ~77 stone
fill ~52 ~26 ~76 ~52 ~26 ~77 stone
fill ~44 ~13 ~77 ~44 ~26 ~77 stone
fill ~44 ~26 ~74 ~44 ~26 ~77 stone
fill ~36 ~17 ~77 ~36 ~26 ~77 stone
fill ~36 ~26 ~76 ~36 ~26 ~77 stone
fill ~30 ~26 ~76 ~30 ~26 ~77 wood
fill ~1 ~25 ~77 ~1 ~26 ~77 fence 0
fill ~157 ~25 ~76 ~157 ~26 ~76 wood
fill ~129 ~26 ~75 ~129 ~26 ~76 grass
fill ~106 ~26 ~76 ~108 ~26 ~76 stone
fill ~108 ~19 ~76 ~108 ~26 ~76 stone
fill ~92 ~14 ~76 ~92 ~26 ~76 stone
fill ~92 ~26 ~75 ~92 ~26 ~76 stone
fill ~87 ~1 ~76 ~87 ~26 ~76 stone
fill ~87 ~26 ~70 ~87 ~26 ~76 stone
fill ~80 ~20 ~76 ~80 ~26 ~76 stone
fill ~77 ~21 ~76 ~77 ~26 ~76 stone
fill ~77 ~26 ~70 ~77 ~26 ~76 stone
fill ~69 ~14 ~76 ~69 ~26 ~76 stone
fill ~69 ~26 ~75 ~69 ~26 ~76 stone
fill ~65 ~17 ~76 ~65 ~26 ~76 stone
fill ~51 ~19 ~76 ~51 ~26 ~76 stone
fill ~51 ~26 ~75 ~51 ~26 ~76 stone
fill ~31 ~26 ~75 ~31 ~26 ~76 grass
fill ~3 ~25 ~76 ~3 ~26 ~76 wood
fill ~108 ~26 ~74 ~108 ~26 ~75 grass
fill ~105 ~26 ~75 ~107 ~26 ~75 stone
fill ~107 ~20 ~75 ~107 ~26 ~75 stone
fill ~86 ~1 ~75 ~86 ~26 ~75 stone
fill ~86 ~26 ~70 ~86 ~26 ~75 stone
fill ~76 ~0 ~75 ~76 ~26 ~75 stone
fill ~76 ~26 ~71 ~76 ~26 ~75 stone
fill ~64 ~21 ~75 ~64 ~26 ~75 stone
fill ~64 ~26 ~73 ~64 ~26 ~75 stone
fill ~52 ~26 ~74 ~52 ~26 ~75 grass
fill ~157 ~26 ~73 ~157 ~26 ~74 fence 0
fill ~150 ~26 ~74 ~151 ~26 ~74 fence 0
fill ~120 ~26 ~74 ~126 ~26 ~74 grass
fill ~109 ~26 ~74 ~114 ~26 ~74 grass
fill ~106 ~26 ~74 ~107 ~26 ~74 grass
fill ~104 ~26 ~74 ~105 ~26 ~74 dirt
fill ~85 ~1 ~74 ~85 ~26 ~74 stone
fill ~85 ~26 ~69 ~85 ~26 ~74 stone
fill ~80 ~0 ~74 ~80 ~26 ~74 stone
fill ~75 ~3 ~74 ~75 ~26 ~74 stone
fill ~75 ~26 ~71 ~75 ~26 ~74 stone
fill ~54 ~26 ~74 ~55 ~26 ~74 grass
fill ~46 ~26 ~74 ~51 ~26 ~74 grass
fill ~34 ~26 ~74 ~39 ~26 ~74 grass
fill ~9 ~26 ~74 ~10 ~26 ~74 fence 0
fill ~149 ~26 ~73 ~150 ~26 ~73 wood
fill ~150 ~25 ~73 ~150 ~26 ~73 wood
fill ~116 ~26 ~73 ~118 ~26 ~73 grass
fill ~100 ~26 ~73 ~104 ~26 ~73 grass
fill ~93 ~22 ~73 ~93 ~26 ~73 stone
fill ~84 ~0 ~73 ~84 ~26 ~73 stone
fill ~84 ~26 ~65 ~84 ~26 ~73 stone
fill ~74 ~7 ~73 ~74 ~26 ~73 stone
fill ~74 ~26 ~72 ~74 ~26 ~73 stone
fill ~65 ~21 ~73 ~65 ~26 ~73 stone
fill ~56 ~26 ~73 ~60 ~26 ~73 grass
fill ~60 ~26 ~72 ~60 ~26 ~73 grass
fill ~42 ~26 ~73 ~44 ~26 ~73 grass
fill ~10 ~26 ~73 ~11 ~26 ~73 wood
fill ~127 ~24 ~72 ~127 ~26 ~72 stone 6
fill ~93 ~26 ~72 ~100 ~26 ~72 grass
fill ~92 ~21 ~72 ~92 ~26 ~72 stone
fill ~83 ~0 ~72 ~83 ~26 ~72 stone
fill ~83 ~26 ~65 ~83 ~26 ~72 stone
fill ~80 ~0 ~72 ~80 ~26 ~72 stone
fill ~71 ~15 ~72 ~71 ~26 ~72 stone
fill ~71 ~26 ~69 ~71 ~26 ~72 stone
fill ~61 ~26 ~72 ~66 ~26 ~72 grass
fill ~66 ~26 ~68 ~66 ~26 ~72 grass
fill ~33 ~24 ~72 ~33 ~26 ~72 stone 6
fill ~92 ~26 ~71 ~96 ~26 ~71 grass
fill ~91 ~20 ~71 ~91 ~26 ~71 stone
fill ~88 ~26 ~71 ~89 ~26 ~71 stone
fill ~89 ~14 ~71 ~89 ~26 ~71 stone
fill ~89 ~26 ~69 ~89 ~26 ~71 stone
fill ~82 ~0 ~71 ~82 ~26 ~71 stone
fill ~82 ~26 ~70 ~82 ~26 ~71 stone
fill ~72 ~15 ~71 ~72 ~26 ~71 stone
fill ~69 ~20 ~71 ~69 ~26 ~71 stone
fill ~67 ~26 ~71 ~68 ~26 ~71 grass
fill ~68 ~26 ~66 ~68 ~26 ~71 grass
fill ~64 ~26 ~71 ~65 ~26 ~71 grass
fill ~65 ~26 ~69 ~65 ~26 ~71 grass
fill ~91 ~26 ~70 ~95 ~26 ~70 grass
fill ~95 ~26 ~69 ~95 ~26 ~70 grass
fill ~90 ~20 ~70 ~90 ~26 ~70 stone
fill ~88 ~15 ~70 ~88 ~26 ~70 stone
fill ~80 ~4 ~70 ~80 ~26 ~70 stone
fill ~69 ~26 ~65 ~69 ~26 ~70 grass
fill ~67 ~26 ~67 ~67 ~26 ~70 grass
fill ~90 ~26 ~69 ~94 ~26 ~69 grass
fill ~94 ~26 ~68 ~94 ~26 ~69 grass
fill ~81 ~11 ~69 ~81 ~26 ~69 stone
fill ~81 ~26 ~37 ~81 ~26 ~69 stone
fill ~79 ~11 ~69 ~79 ~26 ~69 stone
fill ~79 ~26 ~37 ~79 ~26 ~69 stone
fill ~70 ~26 ~65 ~70 ~26 ~69 grass
fill ~89 ~26 ~68 ~93 ~26 ~68 grass
fill ~93 ~26 ~67 ~93 ~26 ~68 grass
fill ~72 ~21 ~68 ~72 ~26 ~68 stone
fill ~71 ~26 ~64 ~71 ~26 ~68 grass
fill ~54 ~25 ~68 ~54 ~26 ~68 end_stone
fill ~54 ~26 ~66 ~54 ~26 ~68 end_stone
fill ~52 ~26 ~68 ~53 ~26 ~68 sandstone
fill ~53 ~25 ~68 ~53 ~26 ~68 sandstone
fill ~89 ~26 ~67 ~92 ~26 ~67 grass
fill ~92 ~26 ~66 ~92 ~26 ~67 grass
fill ~82 ~17 ~67 ~82 ~26 ~67 stone
fill ~82 ~26 ~66 ~82 ~26 ~67 stone
fill ~78 ~15 ~67 ~78 ~26 ~67 stone
fill ~78 ~26 ~30 ~78 ~26 ~67 stone
fill ~76 ~16 ~67 ~76 ~26 ~67 stone
fill ~76 ~26 ~51 ~76 ~26 ~67 stone
fill ~73 ~22 ~67 ~73 ~26 ~67 stone
fill ~73 ~26 ~61 ~73 ~26 ~67 stone
fill ~72 ~26 ~60 ~72 ~26 ~67 grass
fill ~55 ~25 ~67 ~55 ~26 ~67 end_stone
fill ~55 ~26 ~66 ~55 ~26 ~67 end_stone
fill ~53 ~26 ~65 ~53 ~26 ~67 grass
fill ~50 ~26 ~67 ~51 ~26 ~67 end_stone
fill ~51 ~25 ~67 ~51 ~26 ~67 end_stone
fill ~51 ~26 ~65 ~51 ~26 ~67 end_stone
fill ~48 ~26 ~67 ~49 ~26 ~67 sandstone
fill ~107 ~26 ~66 ~108 ~26 ~66 end_stone
fill ~108 ~25 ~66 ~108 ~26 ~66 end_stone
fill ~108 ~26 ~61 ~108 ~26 ~66 end_stone
fill ~106 ~25 ~66 ~106 ~26 ~66 sandstone
fill ~106 ~26 ~64 ~106 ~26 ~66 sandstone
fill ~88 ~26 ~66 ~91 ~26 ~66 grass
fill ~91 ~26 ~65 ~91 ~26 ~66 grass
fill ~77 ~16 ~66 ~77 ~26 ~66 stone
fill ~77 ~26 ~41 ~77 ~26 ~66 stone
fill ~75 ~22 ~66 ~75 ~26 ~66 stone
fill ~75 ~26 ~53 ~75 ~26 ~66 stone
fill ~56 ~26 ~66 ~57 ~26 ~66 end_stone
fill ~47 ~26 ~66 ~50 ~26 ~66 end_stone
fill ~50 ~26 ~64 ~50 ~26 ~66 end_stone
fill ~109 ~26 ~65 ~110 ~26 ~65 sandstone
fill ~110 ~26 ~63 ~110 ~26 ~65 sandstone
fill ~107 ~25 ~65 ~107 ~26 ~65 sandstone
fill ~107 ~26 ~63 ~107 ~26 ~65 sandstone
fill ~105 ~24 ~65 ~105 ~26 ~65 end_stone
fill ~105 ~26 ~64 ~105 ~26 ~65 end_stone
fill ~102 ~26 ~65 ~103 ~26 ~65 end_stone
fill ~88 ~26 ~65 ~90 ~26 ~65 grass
fill ~87 ~21 ~65 ~87 ~26 ~65 stone
fill ~87 ~26 ~61 ~87 ~26 ~65 stone
fill ~74 ~22 ~65 ~74 ~26 ~65 stone
fill ~74 ~26 ~57 ~74 ~26 ~65 stone
fill ~55 ~26 ~65 ~57 ~26 ~65 sandstone
fill ~57 ~25 ~65 ~57 ~26 ~65 sandstone
fill ~48 ~26 ~64 ~48 ~26 ~65 end_stone
fill ~47 ~26 ~64 ~47 ~26 ~65 sandstone
fill ~111 ~26 ~62 ~111 ~26 ~64 sandstone
fill ~104 ~24 ~64 ~104 ~26 ~64 end_stone
fill ~103 ~25 ~64 ~103 ~26 ~64 sandstone
fill ~102 ~24 ~64 ~102 ~26 ~64 end_stone
fill ~102 ~26 ~63 ~102 ~26 ~64 end_stone
fill ~88 ~26 ~64 ~89 ~26 ~64 grass
fill ~85 ~21 ~64 ~85 ~26 ~64 stone
fill ~85 ~26 ~53 ~85 ~26 ~64 stone
fill ~58 ~25 ~64 ~58 ~26 ~64 sandstone
fill ~53 ~26 ~64 ~54 ~26 ~64 sandstone
fill ~51 ~26 ~64 ~52 ~26 ~64 grass
fill ~49 ~23 ~64 ~49 ~26 ~64 sandstone
fill ~49 ~26 ~62 ~49 ~26 ~64 sandstone
fill ~112 ~25 ~63 ~112 ~26 ~63 end_stone
fill ~105 ~26 ~63 ~106 ~26 ~63 grass
fill ~103 ~23 ~63 ~103 ~26 ~63 end_stone
fill ~101 ~24 ~63 ~101 ~26 ~63 end_stone
fill ~101 ~26 ~61 ~101 ~26 ~63 end_stone
fill ~88 ~26 ~60 ~88 ~26 ~63 grass
fill ~86 ~21 ~63 ~86 ~26 ~63 stone
fill ~86 ~26 ~57 ~86 ~26 ~63 stone
fill ~84 ~20 ~63 ~84 ~26 ~63 stone
fill ~84 ~26 ~51 ~84 ~26 ~63 stone
fill ~82 ~19 ~63 ~82 ~26 ~63 stone
fill ~82 ~26 ~30 ~82 ~26 ~63 stone
fill ~59 ~26 ~62 ~59 ~26 ~63 sandstone
fill ~54 ~26 ~62 ~54 ~26 ~63 end_stone
fill ~51 ~26 ~63 ~52 ~26 ~63 sandstone
fill ~52 ~25 ~63 ~52 ~26 ~63 sandstone
fill ~112 ~26 ~61 ~112 ~26 ~62 sandstone
fill ~110 ~26 ~61 ~110 ~26 ~62 end_stone
fill ~104 ~26 ~62 ~106 ~26 ~62 end_stone
fill ~102 ~25 ~62 ~102 ~26 ~62 sandstone
fill ~83 ~19 ~62 ~83 ~26 ~62 stone
fill ~83 ~26 ~41 ~83 ~26 ~62 stone
fill ~60 ~26 ~61 ~60 ~26 ~62 end_stone
fill ~53 ~25 ~62 ~53 ~26 ~62 sandstone
fill ~51 ~26 ~62 ~52 ~26 ~62 grass
fill ~52 ~26 ~61 ~52 ~26 ~62 grass
fill ~48 ~26 ~61 ~48 ~26 ~62 grass
fill ~111 ~25 ~61 ~111 ~26 ~61 end_stone
fill ~111 ~26 ~60 ~111 ~26 ~61 end_stone
fill ~107 ~26 ~60 ~107 ~26 ~61 sandstone
fill ~104 ~26 ~61 ~105 ~26 ~61 end_stone
fill ~102 ~23 ~61 ~102 ~26 ~61 end_stone
fill ~99 ~26 ~60 ~99 ~26 ~61 end_stone
fill ~57 ~26 ~61 ~58 ~26 ~61 sandstone
fill ~51 ~25 ~61 ~51 ~26 ~61 end_stone
fill ~49 ~26 ~61 ~50 ~26 ~61 grass
fill ~108 ~26 ~60 ~110 ~26 ~60 grass
fill ~104 ~24 ~60 ~104 ~26 ~60 end_stone
fill ~101 ~26 ~60 ~102 ~26 ~60 sandstone
fill ~102 ~26 ~59 ~102 ~26 ~60 sandstone
fill ~87 ~26 ~56 ~87 ~26 ~60 grass
fill ~73 ~26 ~56 ~73 ~26 ~60 grass
fill ~55 ~26 ~60 ~58 ~26 ~60 grass
fill ~52 ~26 ~60 ~53 ~26 ~60 sandstone
fill ~53 ~25 ~60 ~53 ~26 ~60 sandstone
fill ~53 ~26 ~58 ~53 ~26 ~60 sandstone
fill ~48 ~26 ~60 ~49 ~26 ~60 sandstone
fill ~49 ~25 ~60 ~49 ~26 ~60 sandstone
fill ~49 ~26 ~59 ~49 ~26 ~60 sandstone
fill ~147 ~25 ~59 ~147 ~26 ~59 wood
fill ~139 ~25 ~59 ~139 ~26 ~59 wood
fill ~109 ~26 ~59 ~111 ~26 ~59 sandstone
fill ~111 ~25 ~59 ~111 ~26 ~59 sandstone
fill ~107 ~25 ~59 ~107 ~26 ~59 end_stone
fill ~106 ~26 ~58 ~106 ~26 ~59 grass
fill ~103 ~24 ~59 ~103 ~26 ~59 sandstone
fill ~103 ~26 ~58 ~103 ~26 ~59 sandstone
fill ~97 ~26 ~59 ~98 ~26 ~59 sandstone
fill ~98 ~25 ~59 ~98 ~26 ~59 sandstone
fill ~61 ~26 ~59 ~63 ~26 ~59 end_stone
fill ~63 ~24 ~59 ~63 ~26 ~59 end_stone
fill ~63 ~26 ~57 ~63 ~26 ~59 end_stone
fill ~60 ~26 ~58 ~60 ~26 ~59 sandstone
fill ~56 ~26 ~59 ~57 ~26 ~59 grass
fill ~57 ~26 ~58 ~57 ~26 ~59 grass
fill ~50 ~26 ~59 ~51 ~26 ~59 sandstone
fill ~47 ~26 ~59 ~48 ~26 ~59 end_stone
fill ~21 ~25 ~59 ~21 ~26 ~59 wood
fill ~13 ~25 ~59 ~13 ~26 ~59 wood
fill ~111 ~22 ~58 ~111 ~26 ~58 end_stone
fill ~109 ~24 ~58 ~109 ~26 ~58 sandstone
fill ~108 ~25 ~58 ~108 ~26 ~58 end_stone
fill ~105 ~25 ~58 ~105 ~26 ~58 sandstone
fill ~105 ~26 ~57 ~105 ~26 ~58 sandstone
fill ~102 ~26 ~57 ~102 ~26 ~58 grass
fill ~100 ~26 ~55 ~100 ~26 ~58 grass
fill ~99 ~26 ~57 ~99 ~26 ~58 sandstone
fill ~96 ~25 ~58 ~96 ~26 ~58 sandstone
fill ~64 ~26 ~58 ~65 ~26 ~58 end_stone
fill ~65 ~24 ~58 ~65 ~26 ~58 end_stone
fill ~65 ~26 ~57 ~65 ~26 ~58 end_stone
fill ~62 ~25 ~58 ~62 ~26 ~58 sandstone
fill ~61 ~23 ~58 ~61 ~26 ~58 end_stone
fill ~59 ~26 ~57 ~59 ~26 ~58 sandstone
fill ~55 ~26 ~57 ~55 ~26 ~58 end_stone
fill ~54 ~26 ~56 ~54 ~26 ~58 sandstone
fill ~51 ~26 ~58 ~52 ~26 ~58 grass
fill ~52 ~26 ~57 ~52 ~26 ~58 grass
fill ~50 ~21 ~58 ~50 ~26 ~58 sandstone
fill ~50 ~26 ~57 ~50 ~26 ~58 sandstone
fill ~48 ~26 ~56 ~48 ~26 ~58 sandstone
fill ~146 ~25 ~57 ~146 ~26 ~57 fence 0
fill ~145 ~25 ~57 ~145 ~26 ~57 quartz_block
fill ~141 ~25 ~57 ~141 ~26 ~57 quartz_block
fill ~140 ~25 ~57 ~140 ~26 ~57 fence 0
fill ~106 ~25 ~57 ~106 ~26 ~57 sandstone
fill ~104 ~26 ~56 ~104 ~26 ~57 grass
fill ~103 ~23 ~57 ~103 ~26 ~57 end_stone
fill ~101 ~26 ~56 ~101 ~26 ~57 grass
fill ~95 ~25 ~57 ~95 ~26 ~57 sandstone
fill ~95 ~26 ~55 ~95 ~26 ~57 sandstone
fill ~94 ~26 ~54 ~94 ~26 ~57 end_stone
fill ~64 ~25 ~57 ~64 ~26 ~57 sandstone
fill ~58 ~25 ~57 ~58 ~26 ~57 sandstone
fill ~57 ~23 ~57 ~57 ~26 ~57 end_stone
fill ~56 ~26 ~56 ~56 ~26 ~57 grass
fill ~51 ~20 ~57 ~51 ~26 ~57 sandstone
fill ~20 ~25 ~57 ~20 ~26 ~57 fence 0
fill ~19 ~25 ~57 ~19 ~26 ~57 quartz_block
fill ~15 ~25 ~57 ~15 ~26 ~57 quartz_block
fill ~14 ~25 ~57 ~14 ~26 ~57 fence 0
fill ~109 ~26 ~56 ~110 ~26 ~56 sandstone
fill ~110 ~26 ~54 ~110 ~26 ~56 sandstone
fill ~106 ~26 ~56 ~107 ~26 ~56 grass
fill ~107 ~26 ~55 ~107 ~26 ~56 grass
fill ~105 ~26 ~53 ~105 ~26 ~56 end_stone
fill ~74 ~26 ~55 ~74 ~26 ~56 dirt
fill ~64 ~24 ~56 ~64 ~26 ~56 end_stone
fill ~64 ~26 ~55 ~64 ~26 ~56 end_stone
fill ~60 ~26 ~56 ~62 ~26 ~56 end_stone
fill ~62 ~25 ~56 ~62 ~26 ~56 end_stone
fill ~62 ~26 ~54 ~62 ~26 ~56 end_stone
fill ~53 ~24 ~56 ~53 ~26 ~56 sandstone
fill ~52 ~25 ~56 ~52 ~26 ~56 end_stone
fill ~49 ~26 ~56 ~50 ~26 ~56 end_stone
fill ~50 ~26 ~55 ~50 ~26 ~56 end_stone
fill ~109 ~24 ~55 ~109 ~26 ~55 sandstone
fill ~109 ~26 ~54 ~109 ~26 ~55 sandstone
fill ~106 ~25 ~55 ~106 ~26 ~55 sandstone
fill ~102 ~26 ~55 ~103 ~26 ~55 end_stone
fill ~93 ~25 ~55 ~93 ~26 ~55 end_stone
fill ~93 ~26 ~54 ~93 ~26 ~55 end_stone
fill ~86 ~26 ~54 ~86 ~26 ~55 grass
fill ~65 ~24 ~55 ~65 ~26 ~55 end_stone
fill ~63 ~26 ~54 ~63 ~26 ~55 grass
fill ~57 ~26 ~55 ~58 ~26 ~55 sandstone
fill ~58 ~25 ~55 ~58 ~26 ~55 sandstone
fill ~53 ~26 ~55 ~56 ~26 ~55 end_stone
fill ~108 ~24 ~54 ~108 ~26 ~54 sandstone
fill ~106 ~26 ~53 ~106 ~26 ~54 grass
fill ~102 ~26 ~54 ~104 ~26 ~54 sandstone
fill ~104 ~26 ~53 ~104 ~26 ~54 sandstone
fill ~97 ~26 ~54 ~98 ~26 ~54 end_stone
fill ~96 ~26 ~53 ~96 ~26 ~54 sandstone
fill ~95 ~26 ~53 ~95 ~26 ~54 grass
fill ~92 ~25 ~54 ~92 ~26 ~54 end_stone
fill ~74 ~26 ~46 ~74 ~26 ~54 grass
fill ~64 ~26 ~54 ~66 ~26 ~54 sandstone
fill ~66 ~25 ~54 ~66 ~26 ~54 sandstone
fill ~58 ~26 ~54 ~59 ~26 ~54 grass
fill ~57 ~25 ~54 ~57 ~26 ~54 sandstone
fill ~56 ~26 ~53 ~56 ~26 ~54 grass
fill ~55 ~25 ~54 ~55 ~26 ~54 sandstone
fill ~53 ~26 ~54 ~54 ~26 ~54 grass
fill ~52 ~26 ~51 ~52 ~26 ~54 sandstone
fill ~50 ~20 ~54 ~50 ~26 ~54 sandstone
fill ~103 ~26 ~52 ~103 ~26 ~53 grass
fill ~100 ~26 ~53 ~102 ~26 ~53 sandstone
fill ~102 ~25 ~53 ~102 ~26 ~53 sandstone
fill ~98 ~25 ~53 ~98 ~26 ~53 sandstone
fill ~93 ~26 ~53 ~94 ~26 ~53 grass
fill ~94 ~26 ~52 ~94 ~26 ~53 grass
fill ~92 ~25 ~53 ~92 ~26 ~53 sandstone
fill ~92 ~26 ~52 ~92 ~26 ~53 sandstone
fill ~80 ~16 ~53 ~80 ~26 ~53 stone
fill ~80 ~26 ~36 ~80 ~26 ~53 stone
fill ~66 ~24 ~53 ~66 ~26 ~53 end_stone
fill ~66 ~26 ~52 ~66 ~26 ~53 end_stone
fill ~63 ~26 ~53 ~65 ~26 ~53 sandstone
fill ~65 ~25 ~53 ~65 ~26 ~53 sandstone
fill ~60 ~26 ~53 ~61 ~26 ~53 sandstone
fill ~59 ~25 ~53 ~59 ~26 ~53 end_stone
fill ~51 ~25 ~53 ~51 ~26 ~53 sandstone
fill ~50 ~25 ~53 ~50 ~26 ~53 end_stone
fill ~49 ~25 ~53 ~49 ~26 ~53 sandstone
fill ~106 ~26 ~52 ~109 ~26 ~52 sandstone
fill ~104 ~25 ~52 ~104 ~26 ~52 end_stone
fill ~102 ~26 ~51 ~102 ~26 ~52 grass
fill ~100 ~24 ~52 ~100 ~26 ~52 sandstone
fill ~98 ~26 ~52 ~99 ~26 ~52 grass
fill ~97 ~25 ~52 ~97 ~26 ~52 sandstone
fill ~97 ~26 ~51 ~97 ~26 ~52 sandstone
fill ~96 ~26 ~51 ~96 ~26 ~52 grass
fill ~85 ~26 ~52 ~86 ~26 ~52 grass
fill ~86 ~26 ~46 ~86 ~26 ~52 grass
fill ~61 ~26 ~52 ~65 ~26 ~52 end_stone
fill ~65 ~25 ~52 ~65 ~26 ~52 end_stone
fill ~60 ~26 ~50 ~60 ~26 ~52 grass
fill ~58 ~25 ~52 ~58 ~26 ~52 end_stone
fill ~54 ~24 ~52 ~54 ~26 ~52 sandstone
fill ~54 ~26 ~50 ~54 ~26 ~52 sandstone
fill ~50 ~25 ~52 ~50 ~26 ~52 sandstone
fill ~107 ~25 ~51 ~107 ~26 ~51 sandstone
fill ~103 ~20 ~51 ~103 ~26 ~51 sandstone
fill ~103 ~26 ~47 ~103 ~26 ~51 sandstone
fill ~101 ~26 ~49 ~101 ~26 ~51 sandstone
fill ~99 ~25 ~51 ~99 ~26 ~51 end_stone
fill ~93 ~26 ~51 ~95 ~26 ~51 end_stone
fill ~95 ~24 ~51 ~95 ~26 ~51 end_stone
fill ~95 ~26 ~50 ~95 ~26 ~51 end_stone
fill ~85 ~20 ~51 ~85 ~26 ~51 stone
fill ~85 ~26 ~37 ~85 ~26 ~51 stone
fill ~75 ~22 ~51 ~75 ~26 ~51 stone
fill ~75 ~26 ~37 ~75 ~26 ~51 stone
fill ~65 ~26 ~50 ~65 ~26 ~51 sandstone
fill ~61 ~26 ~49 ~61 ~26 ~51 end_stone
fill ~58 ~26 ~51 ~59 ~26 ~51 sandstone
fill ~59 ~26 ~49 ~59 ~26 ~51 sandstone
fill ~55 ~26 ~51 ~56 ~26 ~51 sandstone
fill ~56 ~26 ~50 ~56 ~26 ~51 sandstone
fill ~108 ~25 ~50 ~108 ~26 ~50 sandstone
